File: Data/2024_09_17_D2O_CHM343_DSC.txt
Filename	2024_09_17_D2O_CHM343_DSC
Instrument name	DSC2A-00468 (192.168.1.100)
Operator	CHM343
rundate	9/17/2024
Sample name	2024_09_17_D2O_CHM343_DSC
proceduresegments	Equilibrate -40.00 °C; Ramp 10.00 °C/min to 40.00 °C; Isothermal 1.0 min; Ramp 10.00 °C/min to -40.00 °C; Isothermal 1.0 min; Ramp 10.00 °C/min to 40.00 °C
[File Parameters]
Run date	9/17/2024 8:44:41 PM
Trios version	5.1.1.46572
Original File Name	C:\ProgramData\TA Instruments\TRIOS\Data\2024_09_17_D2O_CHM343_DSC.tri
Current File Name	D:\DSC2500\CHM343\2024_09_17_D2O_CHM343_DSC.tri
[Procedure]
Procedure Name	CHM343_Fall2024_Water
Sample Name	2024_09_17_D2O_CHM343_DSC
Sample Mass	3.98 mg
Reference Sample Mass	0 mg
Pan Mass	54.39 mg
Pan Number	27
Reference Pan Mass	54 mg
Reference Pan Number	19
Pan Type	Aluminum
Comments	Water - D2O - Al Hermetic Sealed Pan, with ref Al pan.
Project Name	Lab 4 - Fall 2024
Operator	CHM343
Test	Custom
Unload Max Temperature	30
Unload Min Temperature	30
Load Max Temperature	30
Load Min Temperature	30
Stop on Gas Flow Error	Yes
[Signal List]
Signal #1	Time (min)
Signal #2	Temperature (°C)
Signal #3	Heat Flow (mW)
Signal #4	Delta T (µV)
Signal #5	Delta Tzero (µV)
Signal #6	Tzero Temperature (°C)
Signal #7	Cell Purge (mL/min)
Signal #8	Heater Temp (°C)
Signal #9	Power Delivered (W)
Signal #10	Reference Junction Temperature (°C)
Signal #11	Flange Temperature (°C)
Signal #12	Heat Flow Phase (rad)
Signal #13	Total Heat Capacity (J/°C)
Signal #14	Heat Capacity (J/°C)
[Configuration]
Company Name	ASU
Instrument Name	DSC2A-00468
Instrument Type	DSC2500
Serial Number	DSC2A-00468
IP	192.168.1.100
Location of Instrument	MRRC
DisplayType	Unknown
Sample Interval 	0.1 s/pt
Selected Heat Flow	T4P
Exotherm Direction	Down
Cell Serial	DRC2-00792
Lid Type	Standard
Cooler	RCS 90
Leave Cooler on at End of Sequence	On
Gas 2	Nitrogen
Gas Selected	Channel 1
Flow Rate	50 mL/min
Secondary Purge	On
Licensed Heat Flow	Heat Flow T4P
Modulation Licensed	Yes
[Versions]
Common IDD Version	1
Cortex Version	VER 2.10.2.31
Driver	5.0.0.6
GDM Version	1.0.3.3
TouchscreenVersion	1.0.0.16145
FEP Version	1.2.1.21
FEP Bootloader	2.0.0.5
AutoSampler Version	2.1.1.26
Auto Sampler Bootloader	2.0.0.5
FCM Version	1.1.0.3
FCM Bootloader	2.0.0.5
[Experiment Logs]
Experiment Log Entry # 1	Equilibrate Segment -40 (C) Started
Experiment Log Entry # 3	Ramp Segment 10 C/min to 40 Started
Experiment Log Entry # 5	Isothermal Segment 1 min started
Experiment Log Entry # 7	Ramp Segment 10 C/min to -40 Started
Experiment Log Entry # 9	Isothermal Segment 1 min started
Experiment Log Entry # 11	Ramp Segment 10 C/min to 40 Started
[Method Log]
Method Log Entry # 1	Equilibrate -40 °C
Method Log Entry # 2	(Ramp 64520) Ramp 10 °C/minute to 40 °C
Method Log Entry # 3	Isothermal 1 minutes
Method Log Entry # 4	(Ramp 64522) Ramp 10 °C/minute to -40 °C
Method Log Entry # 5	Isothermal 1 minutes
Method Log Entry # 6	(Ramp 64524) Ramp 10 °C/minute to 40 °C
Cell Serial	DRC2-00792
[T1 Calibration]
Slope	-0.008529666
Offset	9.636258
Initial Temperature	98.23
GUID	f8bfdadc-4977-4fdf-ba6d-0ba9134940c3
[TZero Calibration]
Date Applied	11/29/2022 4:06:13 PM
Description	From -89.059 °C to 396.009 °C at 20.000°C/min
Gas Type	Nitrogen
Pan Type	None
Source Files 1	C:\Users\yargerlab\Desktop\DSC Data\General\TZero_calibration_11_29_22_2nd(2).tri
Source Files 2	C:\Users\yargerlab\Desktop\DSC Data\General\TZero_calibration_11_29_22_2nd(3).tri
Delta T Offset	13.05235
Delta T Slope	-0.007271007
Delta T0 Offset	-13.69128
Delta T0 Slope	0.06063341
[Temperature Calibration]
Date Applied	11/29/2022 7:12:28 PM
Description	From 106.590 °C to 186.590 °C at 10.000°C/min
Gas Type	Nitrogen
Pan Type	Tzero Aluminum Hermetic
Source Files 1	C:\Users\yargerlab\Desktop\DSC Data\General\Indium(6).tri
Measured 1	157.391
Known 1	156.598
[Cell Constant Calibration]
Date Applied	11/29/2022 7:12:29 PM
Description	From 106.590 °C to 186.590 °C at 10.000°C/min
Gas Type	Nitrogen
Pan Type	Tzero Aluminum Hermetic
Source Files 1	C:\Users\yargerlab\Desktop\DSC Data\General\Indium(6).tri
T4P KCell	1.006051
Onset Slope	63.26126 mW/°C
[Direct Cp Calibration]
Date Applied	11/30/2022 11:04:51 AM
Description	From -79.983 °C to 298.409 °C at 10.000°C/min
Gas Type	Nitrogen
Pan Type	Tzero Aluminum Hermetic
Source Files 1	C:\Users\yargerlab\Desktop\DSC Data\General\Sapphire_Heat_Capacity_11_30_22.tri
[Rev Cp Calibration]
Date Applied	11/30/2022 1:58:51 PM
Description	From -79.996 °C to 292.812 °C at 3.000°C/min
Gas Type	Nitrogen
Pan Type	Tzero Aluminum Hermetic
Source Files 1	C:\Users\yargerlab\Desktop\DSC Data\General\Sapphire_MDSC_Calibration_11_30_22.tri
[step]
Ramp 10.00 °C/min to 40.00 °C
Time	Temperature	Heat Flow (Normalized)
min	°C	W/g
0.00	-39.72	-0.112
0.01	-39.72	-0.116
0.01	-39.73	-0.111
0.02	-39.73	-0.106
0.03	-39.74	-0.102
0.03	-39.74	-0.098
0.04	-39.74	-0.094
0.05	-39.74	-0.092
0.05	-39.74	-0.092
0.06	-39.74	-0.092
0.07	-39.74	-0.092
0.07	-39.73	-0.096
0.08	-39.72	-0.098
0.09	-39.71	-0.102
0.09	-39.69	-0.109
0.10	-39.68	-0.117
0.11	-39.66	-0.124
0.11	-39.63	-0.130
0.12	-39.61	-0.133
0.13	-39.58	-0.134
0.13	-39.55	-0.135
0.14	-39.51	-0.133
0.15	-39.48	-0.132
0.15	-39.44	-0.129
0.16	-39.40	-0.114
0.17	-39.36	-0.099
0.17	-39.32	-0.084
0.18	-39.27	-0.069
0.19	-39.23	-0.054
0.19	-39.18	-0.040
0.20	-39.13	-0.025
0.21	-39.08	-0.010
0.21	-39.03	0.006
0.22	-38.98	0.021
0.23	-38.93	0.036
0.23	-38.88	0.048
0.24	-38.83	0.062
0.25	-38.78	0.074
0.25	-38.72	0.085
0.26	-38.67	0.097
0.27	-38.61	0.108
0.27	-38.56	0.117
0.28	-38.50	0.128
0.29	-38.45	0.138
0.29	-38.39	0.143
0.30	-38.33	0.152
0.31	-38.28	0.160
0.31	-38.22	0.167
0.32	-38.16	0.174
0.33	-38.10	0.180
0.33	-38.04	0.186
0.34	-37.98	0.192
0.35	-37.92	0.199
0.35	-37.86	0.204
0.36	-37.80	0.207
0.37	-37.74	0.213
0.37	-37.68	0.218
0.38	-37.62	0.224
0.39	-37.56	0.228
0.39	-37.50	0.232
0.40	-37.44	0.237
0.41	-37.37	0.238
0.41	-37.31	0.242
0.42	-37.25	0.248
0.43	-37.19	0.250
0.43	-37.13	0.255
0.44	-37.06	0.256
0.45	-37.00	0.257
0.45	-36.94	0.261
0.46	-36.87	0.264
0.47	-36.81	0.267
0.47	-36.75	0.268
0.48	-36.69	0.271
0.49	-36.62	0.274
0.49	-36.56	0.276
0.50	-36.50	0.277
0.51	-36.43	0.278
0.51	-36.37	0.280
0.52	-36.30	0.282
0.53	-36.24	0.284
0.53	-36.18	0.285
0.54	-36.11	0.286
0.55	-36.05	0.287
0.55	-35.98	0.288
0.56	-35.92	0.290
0.57	-35.85	0.291
0.57	-35.79	0.292
0.58	-35.73	0.293
0.59	-35.66	0.293
0.59	-35.60	0.294
0.60	-35.53	0.295
0.61	-35.47	0.295
0.61	-35.40	0.297
0.62	-35.34	0.298
0.63	-35.27	0.298
0.63	-35.21	0.299
0.64	-35.14	0.299
0.65	-35.08	0.300
0.65	-35.01	0.300
0.66	-34.95	0.301
0.67	-34.88	0.302
0.67	-34.82	0.302
0.68	-34.75	0.303
0.69	-34.69	0.303
0.69	-34.62	0.304
0.70	-34.56	0.304
0.71	-34.49	0.304
0.71	-34.43	0.304
0.72	-34.36	0.305
0.73	-34.30	0.305
0.73	-34.23	0.305
0.74	-34.17	0.305
0.75	-34.10	0.306
0.75	-34.04	0.306
0.76	-33.97	0.306
0.77	-33.90	0.306
0.77	-33.84	0.307
0.78	-33.77	0.307
0.79	-33.71	0.307
0.79	-33.64	0.307
0.80	-33.58	0.308
0.81	-33.51	0.308
0.81	-33.45	0.308
0.82	-33.38	0.308
0.83	-33.31	0.308
0.83	-33.25	0.309
0.84	-33.18	0.309
0.85	-33.12	0.309
0.85	-33.05	0.309
0.86	-32.99	0.310
0.87	-32.92	0.310
0.87	-32.85	0.310
0.88	-32.79	0.310
0.89	-32.72	0.311
0.89	-32.66	0.311
0.90	-32.59	0.311
0.91	-32.53	0.312
0.91	-32.46	0.312
0.92	-32.39	0.312
0.93	-32.33	0.312
0.93	-32.26	0.312
0.94	-32.19	0.313
0.95	-32.13	0.313
0.95	-32.06	0.313
0.96	-32.00	0.313
0.97	-31.93	0.313
0.97	-31.87	0.313
0.98	-31.80	0.313
0.99	-31.73	0.314
0.99	-31.67	0.314
1.00	-31.60	0.314
1.01	-31.54	0.314
1.01	-31.47	0.314
1.02	-31.40	0.314
1.03	-31.34	0.315
1.03	-31.27	0.315
1.04	-31.21	0.315
1.05	-31.14	0.315
1.05	-31.07	0.315
1.06	-31.01	0.315
1.07	-30.94	0.315
1.07	-30.88	0.316
1.08	-30.81	0.316
1.09	-30.74	0.316
1.09	-30.68	0.316
1.10	-30.61	0.316
1.11	-30.54	0.316
1.11	-30.48	0.317
1.12	-30.41	0.317
1.13	-30.35	0.317
1.13	-30.28	0.317
1.14	-30.21	0.317
1.15	-30.15	0.317
1.15	-30.08	0.317
1.16	-30.02	0.318
1.17	-29.95	0.318
1.17	-29.88	0.318
1.18	-29.82	0.318
1.19	-29.75	0.318
1.19	-29.68	0.318
1.20	-29.62	0.318
1.21	-29.55	0.318
1.21	-29.48	0.318
1.22	-29.42	0.319
1.23	-29.35	0.319
1.23	-29.29	0.319
1.24	-29.22	0.319
1.25	-29.15	0.319
1.25	-29.09	0.319
1.26	-29.02	0.320
1.27	-28.95	0.320
1.27	-28.89	0.320
1.28	-28.82	0.320
1.29	-28.76	0.320
1.29	-28.69	0.320
1.30	-28.62	0.320
1.31	-28.56	0.320
1.31	-28.49	0.320
1.32	-28.42	0.321
1.33	-28.36	0.321
1.33	-28.29	0.321
1.34	-28.22	0.321
1.35	-28.16	0.321
1.35	-28.09	0.321
1.36	-28.03	0.321
1.37	-27.96	0.321
1.37	-27.89	0.321
1.38	-27.83	0.321
1.39	-27.76	0.322
1.39	-27.69	0.322
1.40	-27.63	0.322
1.41	-27.56	0.322
1.41	-27.49	0.322
1.42	-27.43	0.322
1.43	-27.36	0.322
1.43	-27.29	0.322
1.44	-27.23	0.322
1.45	-27.16	0.322
1.45	-27.10	0.323
1.46	-27.03	0.323
1.47	-26.96	0.323
1.47	-26.90	0.323
1.48	-26.83	0.323
1.49	-26.76	0.323
1.49	-26.70	0.323
1.50	-26.63	0.323
1.51	-26.56	0.323
1.51	-26.50	0.323
1.52	-26.43	0.323
1.53	-26.36	0.324
1.53	-26.30	0.324
1.54	-26.23	0.324
1.55	-26.16	0.324
1.55	-26.10	0.324
1.56	-26.03	0.324
1.57	-25.96	0.324
1.57	-25.90	0.324
1.58	-25.83	0.324
1.59	-25.76	0.324
1.59	-25.70	0.324
1.60	-25.63	0.324
1.61	-25.57	0.324
1.61	-25.50	0.325
1.62	-25.43	0.325
1.63	-25.37	0.325
1.63	-25.30	0.325
1.64	-25.23	0.325
1.65	-25.17	0.325
1.65	-25.10	0.325
1.66	-25.03	0.325
1.67	-24.97	0.325
1.67	-24.90	0.325
1.68	-24.83	0.325
1.69	-24.77	0.325
1.69	-24.70	0.325
1.70	-24.63	0.325
1.71	-24.57	0.325
1.71	-24.50	0.326
1.72	-24.43	0.326
1.73	-24.37	0.326
1.73	-24.30	0.326
1.74	-24.23	0.326
1.75	-24.17	0.326
1.75	-24.10	0.326
1.76	-24.03	0.326
1.77	-23.97	0.326
1.77	-23.90	0.326
1.78	-23.83	0.326
1.79	-23.77	0.326
1.79	-23.70	0.326
1.80	-23.64	0.326
1.81	-23.57	0.327
1.81	-23.50	0.327
1.82	-23.43	0.327
1.83	-23.37	0.327
1.83	-23.30	0.327
1.84	-23.23	0.327
1.85	-23.17	0.327
1.85	-23.10	0.327
1.86	-23.04	0.327
1.87	-22.97	0.327
1.87	-22.90	0.327
1.88	-22.84	0.327
1.89	-22.77	0.327
1.89	-22.70	0.327
1.90	-22.63	0.327
1.91	-22.57	0.327
1.91	-22.50	0.328
1.92	-22.44	0.328
1.93	-22.37	0.328
1.93	-22.30	0.328
1.94	-22.24	0.328
1.95	-22.17	0.328
1.95	-22.10	0.328
1.96	-22.04	0.328
1.97	-21.97	0.328
1.97	-21.90	0.328
1.98	-21.84	0.328
1.99	-21.77	0.328
1.99	-21.70	0.328
2.00	-21.63	0.328
2.01	-21.57	0.328
2.01	-21.50	0.328
2.02	-21.44	0.328
2.03	-21.37	0.328
2.03	-21.30	0.328
2.04	-21.24	0.328
2.05	-21.17	0.329
2.05	-21.10	0.329
2.06	-21.03	0.329
2.07	-20.97	0.329
2.07	-20.90	0.329
2.08	-20.84	0.329
2.09	-20.77	0.329
2.09	-20.70	0.329
2.10	-20.64	0.329
2.11	-20.57	0.329
2.11	-20.50	0.329
2.12	-20.43	0.329
2.13	-20.37	0.329
2.13	-20.30	0.329
2.14	-20.24	0.329
2.15	-20.17	0.329
2.15	-20.10	0.329
2.16	-20.03	0.329
2.17	-19.97	0.330
2.17	-19.90	0.330
2.18	-19.83	0.330
2.19	-19.77	0.330
2.19	-19.70	0.330
2.20	-19.63	0.330
2.21	-19.57	0.330
2.21	-19.50	0.330
2.22	-19.43	0.330
2.23	-19.37	0.330
2.23	-19.30	0.330
2.24	-19.23	0.330
2.25	-19.17	0.330
2.25	-19.10	0.330
2.26	-19.03	0.330
2.27	-18.97	0.330
2.27	-18.90	0.330
2.28	-18.83	0.330
2.29	-18.77	0.330
2.29	-18.70	0.330
2.30	-18.63	0.330
2.31	-18.57	0.331
2.31	-18.50	0.331
2.32	-18.43	0.331
2.33	-18.37	0.331
2.33	-18.30	0.331
2.34	-18.24	0.331
2.35	-18.17	0.331
2.35	-18.10	0.331
2.36	-18.03	0.331
2.37	-17.97	0.331
2.37	-17.90	0.331
2.38	-17.83	0.331
2.39	-17.77	0.331
2.39	-17.70	0.331
2.40	-17.63	0.331
2.41	-17.57	0.331
2.41	-17.50	0.331
2.42	-17.43	0.331
2.43	-17.37	0.331
2.43	-17.30	0.331
2.44	-17.24	0.332
2.45	-17.17	0.332
2.45	-17.10	0.332
2.46	-17.03	0.332
2.47	-16.97	0.332
2.47	-16.90	0.332
2.48	-16.83	0.332
2.49	-16.77	0.332
2.49	-16.70	0.332
2.50	-16.63	0.332
2.51	-16.57	0.332
2.51	-16.50	0.332
2.52	-16.43	0.332
2.53	-16.37	0.332
2.53	-16.30	0.332
2.54	-16.23	0.332
2.55	-16.17	0.332
2.55	-16.10	0.332
2.56	-16.03	0.332
2.57	-15.97	0.333
2.57	-15.90	0.333
2.58	-15.83	0.333
2.59	-15.77	0.333
2.59	-15.70	0.333
2.60	-15.63	0.333
2.61	-15.57	0.333
2.61	-15.50	0.333
2.62	-15.43	0.333
2.63	-15.37	0.333
2.63	-15.30	0.333
2.64	-15.23	0.333
2.65	-15.17	0.333
2.65	-15.10	0.333
2.66	-15.03	0.333
2.67	-14.97	0.333
2.67	-14.90	0.333
2.68	-14.83	0.334
2.69	-14.76	0.334
2.69	-14.70	0.334
2.70	-14.63	0.334
2.71	-14.57	0.334
2.71	-14.50	0.334
2.72	-14.43	0.334
2.73	-14.37	0.334
2.73	-14.30	0.334
2.74	-14.23	0.334
2.75	-14.17	0.334
2.75	-14.10	0.334
2.76	-14.03	0.334
2.77	-13.97	0.334
2.77	-13.90	0.334
2.78	-13.83	0.334
2.79	-13.77	0.334
2.79	-13.70	0.334
2.80	-13.63	0.334
2.81	-13.57	0.335
2.81	-13.50	0.335
2.82	-13.43	0.335
2.83	-13.37	0.335
2.83	-13.30	0.335
2.84	-13.23	0.335
2.85	-13.17	0.335
2.85	-13.10	0.335
2.86	-13.03	0.335
2.87	-12.97	0.335
2.87	-12.90	0.335
2.88	-12.83	0.335
2.89	-12.77	0.335
2.89	-12.70	0.335
2.90	-12.63	0.335
2.91	-12.56	0.335
2.91	-12.50	0.336
2.92	-12.43	0.336
2.93	-12.36	0.336
2.93	-12.30	0.336
2.94	-12.23	0.336
2.95	-12.16	0.336
2.95	-12.10	0.336
2.96	-12.03	0.336
2.97	-11.96	0.336
2.97	-11.90	0.336
2.98	-11.83	0.336
2.99	-11.76	0.336
2.99	-11.70	0.336
3.00	-11.63	0.336
3.01	-11.56	0.336
3.01	-11.50	0.336
3.02	-11.43	0.336
3.03	-11.36	0.336
3.03	-11.30	0.337
3.04	-11.23	0.337
3.05	-11.16	0.337
3.05	-11.10	0.337
3.06	-11.03	0.337
3.07	-10.96	0.337
3.07	-10.90	0.337
3.08	-10.83	0.337
3.09	-10.76	0.337
3.09	-10.70	0.337
3.10	-10.63	0.337
3.11	-10.56	0.337
3.11	-10.50	0.337
3.12	-10.43	0.337
3.13	-10.36	0.337
3.13	-10.30	0.337
3.14	-10.23	0.337
3.15	-10.16	0.337
3.15	-10.10	0.338
3.16	-10.03	0.338
3.17	-9.96	0.338
3.17	-9.90	0.338
3.18	-9.83	0.338
3.19	-9.76	0.338
3.19	-9.70	0.338
3.20	-9.63	0.338
3.21	-9.56	0.338
3.21	-9.50	0.338
3.22	-9.43	0.338
3.23	-9.36	0.338
3.23	-9.30	0.338
3.24	-9.23	0.338
3.25	-9.16	0.338
3.25	-9.10	0.338
3.26	-9.03	0.338
3.27	-8.96	0.338
3.27	-8.90	0.339
3.28	-8.83	0.339
3.29	-8.76	0.339
3.29	-8.70	0.339
3.30	-8.63	0.339
3.31	-8.56	0.339
3.31	-8.50	0.339
3.32	-8.43	0.339
3.33	-8.36	0.339
3.33	-8.30	0.339
3.34	-8.23	0.339
3.35	-8.16	0.339
3.35	-8.10	0.339
3.36	-8.03	0.339
3.37	-7.96	0.339
3.37	-7.90	0.339
3.38	-7.83	0.339
3.39	-7.76	0.340
3.39	-7.70	0.340
3.40	-7.63	0.340
3.41	-7.56	0.340
3.41	-7.50	0.340
3.42	-7.43	0.340
3.43	-7.36	0.340
3.43	-7.30	0.340
3.44	-7.23	0.340
3.45	-7.16	0.340
3.45	-7.09	0.340
3.46	-7.03	0.340
3.47	-6.96	0.340
3.47	-6.90	0.340
3.48	-6.83	0.341
3.49	-6.76	0.341
3.49	-6.69	0.341
3.50	-6.63	0.341
3.51	-6.56	0.341
3.51	-6.49	0.341
3.52	-6.43	0.341
3.53	-6.36	0.341
3.53	-6.29	0.341
3.54	-6.23	0.341
3.55	-6.16	0.341
3.55	-6.09	0.341
3.56	-6.03	0.341
3.57	-5.96	0.342
3.57	-5.89	0.342
3.58	-5.83	0.342
3.59	-5.76	0.342
3.59	-5.69	0.342
3.60	-5.63	0.342
3.61	-5.56	0.342
3.61	-5.49	0.342
3.62	-5.43	0.342
3.63	-5.36	0.342
3.63	-5.29	0.342
3.64	-5.23	0.342
3.65	-5.16	0.343
3.65	-5.09	0.343
3.66	-5.03	0.343
3.67	-4.96	0.343
3.67	-4.89	0.343
3.68	-4.83	0.343
3.69	-4.76	0.343
3.69	-4.69	0.343
3.70	-4.63	0.343
3.71	-4.56	0.343
3.71	-4.49	0.343
3.72	-4.43	0.343
3.73	-4.36	0.344
3.73	-4.29	0.344
3.74	-4.23	0.344
3.75	-4.16	0.344
3.75	-4.09	0.344
3.76	-4.02	0.344
3.77	-3.96	0.344
3.77	-3.89	0.344
3.78	-3.83	0.344
3.79	-3.76	0.344
3.79	-3.69	0.344
3.80	-3.62	0.344
3.81	-3.56	0.345
3.81	-3.49	0.345
3.82	-3.43	0.345
3.83	-3.36	0.345
3.83	-3.29	0.345
3.84	-3.22	0.345
3.85	-3.16	0.345
3.85	-3.09	0.345
3.86	-3.02	0.345
3.87	-2.96	0.345
3.87	-2.89	0.345
3.88	-2.82	0.346
3.89	-2.76	0.346
3.89	-2.69	0.346
3.90	-2.63	0.346
3.91	-2.56	0.346
3.91	-2.49	0.346
3.92	-2.42	0.346
3.93	-2.36	0.346
3.93	-2.29	0.346
3.94	-2.22	0.347
3.95	-2.16	0.347
3.95	-2.09	0.347
3.96	-2.02	0.347
3.97	-1.96	0.347
3.97	-1.89	0.347
3.98	-1.82	0.347
3.99	-1.76	0.348
3.99	-1.69	0.348
4.00	-1.62	0.348
4.01	-1.56	0.348
4.01	-1.49	0.348
4.02	-1.42	0.348
4.03	-1.36	0.348
4.03	-1.29	0.349
4.04	-1.22	0.349
4.05	-1.16	0.349
4.05	-1.09	0.349
4.06	-1.02	0.349
4.07	-0.96	0.349
4.07	-0.89	0.350
4.08	-0.82	0.350
4.09	-0.76	0.350
4.09	-0.69	0.350
4.10	-0.62	0.351
4.11	-0.56	0.351
4.11	-0.49	0.351
4.12	-0.42	0.352
4.13	-0.36	0.352
4.13	-0.29	0.352
4.14	-0.22	0.353
4.15	-0.16	0.353
4.15	-0.09	0.354
4.16	-0.03	0.355
4.17	0.04	0.355
4.17	0.11	0.356
4.18	0.18	0.357
4.19	0.24	0.358
4.19	0.31	0.359
4.20	0.37	0.361
4.21	0.44	0.363
4.21	0.51	0.364
4.22	0.57	0.367
4.23	0.64	0.371
4.23	0.71	0.373
4.24	0.77	0.375
4.25	0.84	0.377
4.25	0.91	0.382
4.26	0.97	0.387
4.27	1.04	0.391
4.27	1.10	0.394
4.28	1.17	0.397
4.29	1.24	0.406
4.29	1.30	0.412
4.30	1.37	0.416
4.31	1.43	0.426
4.31	1.50	0.435
4.32	1.57	0.447
4.33	1.63	0.462
4.33	1.69	0.479
4.34	1.76	0.500
4.35	1.82	0.530
4.35	1.89	0.561
4.36	1.95	0.604
4.37	2.01	0.659
4.37	2.07	0.730
4.38	2.13	0.817
4.39	2.18	0.926
4.39	2.24	1.056
4.40	2.29	1.204
4.41	2.33	1.366
4.41	2.37	1.533
4.42	2.42	1.705
4.43	2.45	1.876
4.43	2.49	2.041
4.44	2.53	2.204
4.45	2.56	2.371
4.45	2.59	2.522
4.46	2.62	2.665
4.47	2.65	2.799
4.47	2.68	2.908
4.48	2.71	3.015
4.49	2.74	3.113
4.49	2.78	3.204
4.50	2.81	3.291
4.51	2.85	3.381
4.51	2.88	3.468
4.52	2.92	3.553
4.53	2.95	3.636
4.53	2.99	3.717
4.54	3.03	3.796
4.55	3.06	3.874
4.55	3.10	3.949
4.56	3.14	4.025
4.57	3.18	4.102
4.57	3.23	4.172
4.58	3.27	4.240
4.59	3.31	4.307
4.59	3.35	4.374
4.60	3.39	4.438
4.61	3.44	4.501
4.61	3.48	4.562
4.62	3.53	4.622
4.63	3.57	4.680
4.63	3.62	4.737
4.64	3.66	4.792
4.65	3.71	4.847
4.65	3.76	4.903
4.66	3.81	4.954
4.67	3.85	5.004
4.67	3.90	5.055
4.68	3.95	5.104
4.69	4.00	5.152
4.69	4.05	5.198
4.70	4.10	5.246
4.71	4.15	5.290
4.71	4.20	5.334
4.72	4.25	5.379
4.73	4.30	5.421
4.73	4.35	5.464
4.74	4.41	5.505
4.75	4.46	5.546
4.75	4.51	5.588
4.76	4.57	5.628
4.77	4.62	5.666
4.77	4.67	5.705
4.78	4.72	5.744
4.79	4.78	5.782
4.79	4.83	5.818
4.80	4.89	5.856
4.81	4.94	5.894
4.81	5.00	5.936
4.82	5.05	5.977
4.83	5.11	6.016
4.83	5.16	6.049
4.84	5.22	6.077
4.85	5.27	6.100
4.85	5.33	6.123
4.86	5.38	6.143
4.87	5.44	6.162
4.87	5.50	6.179
4.88	5.56	6.191
4.89	5.61	6.200
4.89	5.67	6.207
4.90	5.73	6.215
4.91	5.80	6.221
4.91	5.86	6.228
4.92	5.92	6.240
4.93	5.98	6.254
4.93	6.04	6.267
4.94	6.10	6.278
4.95	6.16	6.286
4.95	6.23	6.294
4.96	6.29	6.303
4.97	6.35	6.308
4.97	6.42	6.315
4.98	6.48	6.323
4.99	6.54	6.329
4.99	6.61	6.334
5.00	6.67	6.341
5.01	6.73	6.348
5.01	6.80	6.352
5.02	6.86	6.360
5.03	6.93	6.374
5.03	6.99	6.395
5.04	7.05	6.439
5.05	7.11	6.521
5.05	7.17	6.626
5.06	7.23	6.713
5.07	7.28	6.760
5.07	7.34	6.777
5.08	7.40	6.772
5.09	7.46	6.751
5.09	7.52	6.723
5.10	7.58	6.688
5.11	7.65	6.651
5.11	7.71	6.619
5.12	7.78	6.583
5.13	7.84	6.545
5.13	7.91	6.509
5.14	7.98	6.474
5.15	8.05	6.434
5.15	8.13	6.392
5.16	8.20	6.354
5.17	8.27	6.314
5.17	8.34	6.272
5.18	8.42	6.231
5.19	8.49	6.188
5.19	8.57	6.144
5.20	8.64	6.098
5.21	8.72	6.055
5.21	8.80	6.006
5.22	8.87	5.956
5.23	8.95	5.905
5.23	9.03	5.852
5.24	9.11	5.801
5.25	9.19	5.748
5.25	9.27	5.690
5.26	9.34	5.633
5.27	9.42	5.574
5.27	9.50	5.514
5.28	9.59	5.452
5.29	9.67	5.387
5.29	9.75	5.322
5.30	9.83	5.258
5.31	9.91	5.190
5.31	10.00	5.119
5.32	10.08	5.047
5.33	10.17	4.974
5.33	10.25	4.896
5.34	10.34	4.816
5.35	10.42	4.736
5.35	10.51	4.653
5.36	10.59	4.565
5.37	10.68	4.474
5.37	10.77	4.383
5.38	10.86	4.287
5.39	10.95	4.188
5.39	11.04	4.086
5.40	11.13	3.982
5.41	11.22	3.871
5.41	11.31	3.755
5.42	11.41	3.637
5.43	11.50	3.511
5.43	11.60	3.376
5.44	11.69	3.232
5.45	11.79	3.080
5.45	11.89	2.924
5.46	11.99	2.770
5.47	12.09	2.626
5.47	12.20	2.493
5.48	12.30	2.372
5.49	12.40	2.262
5.49	12.50	2.161
5.50	12.60	2.072
5.51	12.70	1.991
5.51	12.80	1.914
5.52	12.90	1.846
5.53	12.99	1.781
5.53	13.09	1.721
5.54	13.18	1.666
5.55	13.27	1.615
5.55	13.36	1.566
5.56	13.45	1.519
5.57	13.54	1.475
5.57	13.63	1.434
5.58	13.72	1.396
5.59	13.80	1.360
5.59	13.89	1.325
5.60	13.97	1.289
5.61	14.06	1.258
5.61	14.14	1.234
5.62	14.22	1.208
5.63	14.30	1.175
5.63	14.38	1.143
5.64	14.46	1.119
5.65	14.54	1.104
5.65	14.62	1.088
5.66	14.70	1.064
5.67	14.77	1.042
5.67	14.85	1.020
5.68	14.93	1.001
5.69	15.00	0.988
5.69	15.08	0.972
5.70	15.15	0.956
5.71	15.23	0.941
5.71	15.30	0.928
5.72	15.37	0.915
5.73	15.45	0.904
5.73	15.52	0.893
5.74	15.59	0.881
5.75	15.67	0.870
5.75	15.74	0.859
5.76	15.81	0.848
5.77	15.88	0.839
5.77	15.95	0.832
5.78	16.02	0.824
5.79	16.09	0.815
5.79	16.16	0.807
5.80	16.24	0.802
5.81	16.31	0.793
5.81	16.37	0.788
5.82	16.44	0.783
5.83	16.51	0.775
5.83	16.58	0.771
5.84	16.65	0.765
5.85	16.72	0.760
5.85	16.79	0.756
5.86	16.86	0.750
5.87	16.93	0.746
5.87	17.00	0.743
5.88	17.07	0.739
5.89	17.14	0.736
5.89	17.21	0.732
5.90	17.27	0.728
5.91	17.34	0.726
5.91	17.41	0.724
5.92	17.48	0.721
5.93	17.55	0.717
5.93	17.62	0.713
5.94	17.68	0.712
5.95	17.75	0.712
5.95	17.82	0.708
5.96	17.89	0.705
5.97	17.96	0.703
5.97	18.02	0.702
5.98	18.09	0.700
5.99	18.16	0.698
5.99	18.23	0.697
6.00	18.29	0.695
6.01	18.36	0.694
6.01	18.43	0.693
6.02	18.50	0.692
6.03	18.56	0.691
6.03	18.63	0.690
6.04	18.70	0.688
6.05	18.77	0.688
6.05	18.83	0.688
6.06	18.90	0.687
6.07	18.97	0.684
6.07	19.03	0.684
6.08	19.10	0.683
6.09	19.17	0.683
6.09	19.24	0.682
6.10	19.30	0.682
6.11	19.37	0.682
6.11	19.44	0.681
6.12	19.50	0.681
6.13	19.57	0.680
6.13	19.64	0.680
6.14	19.71	0.679
6.15	19.77	0.679
6.15	19.84	0.679
6.16	19.91	0.678
6.17	19.97	0.678
6.17	20.04	0.678
6.18	20.11	0.678
6.19	20.17	0.678
6.19	20.24	0.677
6.20	20.31	0.677
6.21	20.37	0.677
6.21	20.44	0.676
6.22	20.51	0.676
6.23	20.58	0.676
6.23	20.64	0.675
6.24	20.71	0.675
6.25	20.78	0.674
6.25	20.84	0.674
6.26	20.91	0.674
6.27	20.98	0.674
6.27	21.04	0.674
6.28	21.11	0.673
6.29	21.18	0.673
6.29	21.24	0.673
6.30	21.31	0.673
6.31	21.38	0.673
6.31	21.45	0.673
6.32	21.51	0.673
6.33	21.58	0.672
6.33	21.65	0.672
6.34	21.71	0.672
6.35	21.78	0.672
6.35	21.85	0.672
6.36	21.91	0.672
6.37	21.98	0.671
6.37	22.05	0.671
6.38	22.11	0.671
6.39	22.18	0.671
6.39	22.25	0.671
6.40	22.31	0.671
6.41	22.38	0.671
6.41	22.45	0.671
6.42	22.51	0.671
6.43	22.58	0.670
6.43	22.65	0.670
6.44	22.71	0.670
6.45	22.78	0.670
6.45	22.85	0.670
6.46	22.91	0.670
6.47	22.98	0.670
6.47	23.05	0.670
6.48	23.11	0.669
6.49	23.18	0.669
6.49	23.25	0.669
6.50	23.32	0.669
6.51	23.38	0.669
6.51	23.45	0.669
6.52	23.52	0.669
6.53	23.58	0.669
6.53	23.65	0.668
6.54	23.71	0.668
6.55	23.78	0.668
6.55	23.85	0.668
6.56	23.92	0.668
6.57	23.98	0.668
6.57	24.05	0.668
6.58	24.12	0.668
6.59	24.18	0.668
6.59	24.25	0.668
6.60	24.32	0.668
6.61	24.38	0.668
6.61	24.45	0.667
6.62	24.52	0.667
6.63	24.58	0.667
6.63	24.65	0.667
6.64	24.72	0.667
6.65	24.78	0.667
6.65	24.85	0.667
6.66	24.92	0.667
6.67	24.99	0.667
6.67	25.05	0.667
6.68	25.12	0.667
6.69	25.18	0.667
6.69	25.25	0.667
6.70	25.32	0.667
6.71	25.39	0.667
6.71	25.45	0.666
6.72	25.52	0.666
6.73	25.59	0.666
6.73	25.65	0.666
6.74	25.72	0.666
6.75	25.79	0.666
6.75	25.85	0.666
6.76	25.92	0.666
6.77	25.99	0.666
6.77	26.05	0.666
6.78	26.12	0.666
6.79	26.19	0.666
6.79	26.25	0.666
6.80	26.32	0.666
6.81	26.39	0.666
6.81	26.45	0.666
6.82	26.52	0.666
6.83	26.59	0.666
6.83	26.65	0.666
6.84	26.72	0.666
6.85	26.79	0.666
6.85	26.85	0.665
6.86	26.92	0.665
6.87	26.99	0.665
6.87	27.05	0.665
6.88	27.12	0.665
6.89	27.19	0.665
6.89	27.26	0.665
6.90	27.32	0.665
6.91	27.39	0.665
6.91	27.45	0.665
6.92	27.52	0.665
6.93	27.59	0.665
6.93	27.65	0.665
6.94	27.72	0.665
6.95	27.79	0.665
6.95	27.85	0.665
6.96	27.92	0.665
6.97	27.99	0.665
6.97	28.06	0.665
6.98	28.12	0.665
6.99	28.19	0.665
6.99	28.25	0.665
7.00	28.32	0.665
7.01	28.39	0.665
7.01	28.46	0.665
7.02	28.52	0.665
7.03	28.59	0.665
7.03	28.66	0.665
7.04	28.72	0.665
7.05	28.79	0.665
7.05	28.86	0.665
7.06	28.92	0.665
7.07	28.99	0.665
7.07	29.06	0.665
7.08	29.12	0.665
7.09	29.19	0.665
7.09	29.26	0.664
7.10	29.32	0.665
7.11	29.39	0.665
7.11	29.46	0.665
7.12	29.52	0.665
7.13	29.59	0.665
7.13	29.66	0.665
7.14	29.72	0.665
7.15	29.79	0.665
7.15	29.86	0.665
7.16	29.92	0.665
7.17	29.99	0.665
7.17	30.06	0.665
7.18	30.12	0.664
7.19	30.19	0.664
7.19	30.26	0.664
7.20	30.32	0.664
7.21	30.39	0.664
7.21	30.46	0.664
7.22	30.52	0.664
7.23	30.59	0.664
7.23	30.66	0.664
7.24	30.72	0.664
7.25	30.79	0.664
7.25	30.86	0.664
7.26	30.93	0.664
7.27	30.99	0.664
7.27	31.06	0.664
7.28	31.13	0.664
7.29	31.19	0.664
7.29	31.26	0.664
7.30	31.33	0.665
7.31	31.39	0.665
7.31	31.46	0.665
7.32	31.53	0.665
7.33	31.59	0.665
7.33	31.66	0.665
7.34	31.73	0.665
7.35	31.79	0.665
7.35	31.86	0.665
7.36	31.93	0.665
7.37	31.99	0.665
7.37	32.06	0.665
7.38	32.13	0.665
7.39	32.19	0.665
7.39	32.26	0.665
7.40	32.33	0.665
7.41	32.39	0.665
7.41	32.46	0.665
7.42	32.53	0.665
7.43	32.59	0.665
7.43	32.66	0.665
7.44	32.73	0.665
7.45	32.79	0.665
7.45	32.86	0.665
7.46	32.93	0.665
7.47	32.99	0.665
7.47	33.06	0.665
7.48	33.13	0.665
7.49	33.19	0.664
7.49	33.26	0.664
7.50	33.33	0.664
7.51	33.40	0.664
7.51	33.46	0.664
7.52	33.53	0.664
7.53	33.60	0.665
7.53	33.66	0.664
7.54	33.73	0.664
7.55	33.80	0.664
7.55	33.86	0.664
7.56	33.93	0.664
7.57	34.00	0.664
7.57	34.06	0.664
7.58	34.13	0.664
7.59	34.20	0.664
7.59	34.26	0.664
7.60	34.33	0.664
7.61	34.40	0.664
7.61	34.46	0.665
7.62	34.53	0.665
7.63	34.60	0.665
7.63	34.66	0.665
7.64	34.73	0.665
7.65	34.80	0.665
7.65	34.86	0.664
7.66	34.93	0.664
7.67	35.00	0.664
7.67	35.06	0.664
7.68	35.13	0.664
7.69	35.20	0.664
7.69	35.26	0.664
7.70	35.33	0.664
7.71	35.40	0.664
7.71	35.46	0.664
7.72	35.53	0.664
7.73	35.60	0.664
7.73	35.66	0.664
7.74	35.73	0.664
7.75	35.80	0.664
7.75	35.86	0.664
7.76	35.93	0.664
7.77	36.00	0.664
7.77	36.06	0.664
7.78	36.13	0.664
7.79	36.20	0.664
7.79	36.27	0.664
7.80	36.33	0.665
7.81	36.40	0.664
7.81	36.47	0.664
7.82	36.53	0.664
7.83	36.60	0.664
7.83	36.67	0.664
7.84	36.73	0.664
7.85	36.80	0.664
7.85	36.87	0.664
7.86	36.93	0.664
7.87	37.00	0.664
7.87	37.07	0.664
7.88	37.13	0.664
7.89	37.20	0.664
7.89	37.27	0.664
7.90	37.33	0.664
7.91	37.40	0.664
7.91	37.47	0.664
7.92	37.53	0.664
7.93	37.60	0.664
7.93	37.67	0.664
7.94	37.73	0.664
7.95	37.80	0.664
7.95	37.87	0.664
7.96	37.94	0.664
7.97	38.00	0.664
7.97	38.07	0.664
7.98	38.13	0.664
7.99	38.20	0.664
7.99	38.27	0.664
8.00	38.28	0.664

[step]
Ramp 10.00 °C/min to -40.00 °C
Time	Temperature	Heat Flow (Normalized)
min	°C	W/g
9.00	40.06	-0.017
9.00	40.07	-0.017
9.01	40.07	-0.018
9.02	40.07	-0.018
9.02	40.06	-0.018
9.03	40.06	-0.018
9.04	40.06	-0.018
9.04	40.06	-0.018
9.05	40.05	-0.013
9.06	40.04	-0.002
9.06	40.04	0.010
9.07	40.02	0.021
9.08	40.01	0.030
9.08	39.99	0.038
9.09	39.97	0.044
9.10	39.95	0.046
9.10	39.92	0.045
9.11	39.89	0.042
9.12	39.86	0.034
9.12	39.83	0.029
9.13	39.79	0.008
9.14	39.76	-0.012
9.14	39.72	-0.033
9.15	39.67	-0.058
9.16	39.63	-0.081
9.16	39.59	-0.107
9.17	39.54	-0.138
9.18	39.49	-0.163
9.18	39.45	-0.191
9.19	39.40	-0.219
9.20	39.35	-0.243
9.20	39.30	-0.270
9.21	39.25	-0.293
9.22	39.19	-0.314
9.22	39.14	-0.338
9.23	39.09	-0.358
9.24	39.04	-0.376
9.24	38.98	-0.393
9.25	38.93	-0.412
9.26	38.87	-0.428
9.26	38.82	-0.441
9.27	38.76	-0.455
9.28	38.70	-0.466
9.28	38.65	-0.480
9.29	38.59	-0.492
9.30	38.53	-0.502
9.30	38.47	-0.513
9.31	38.41	-0.524
9.32	38.36	-0.532
9.32	38.30	-0.539
9.33	38.24	-0.550
9.34	38.18	-0.558
9.34	38.12	-0.566
9.35	38.06	-0.574
9.36	38.00	-0.578
9.36	37.93	-0.586
9.37	37.87	-0.592
9.38	37.81	-0.598
9.38	37.75	-0.604
9.39	37.69	-0.611
9.40	37.63	-0.614
9.40	37.56	-0.620
9.41	37.50	-0.627
9.42	37.44	-0.631
9.42	37.38	-0.634
9.43	37.31	-0.637
9.44	37.25	-0.643
9.44	37.19	-0.646
9.45	37.12	-0.649
9.46	37.06	-0.652
9.46	37.00	-0.654
9.47	36.93	-0.659
9.48	36.87	-0.661
9.48	36.81	-0.665
9.49	36.74	-0.670
9.50	36.68	-0.671
9.50	36.61	-0.672
9.51	36.55	-0.674
9.52	36.49	-0.676
9.52	36.42	-0.678
9.53	36.36	-0.681
9.54	36.29	-0.683
9.54	36.23	-0.683
9.55	36.16	-0.685
9.56	36.10	-0.686
9.56	36.04	-0.689
9.57	35.97	-0.690
9.58	35.91	-0.691
9.58	35.84	-0.692
9.59	35.78	-0.693
9.60	35.71	-0.693
9.60	35.65	-0.694
9.61	35.58	-0.696
9.62	35.52	-0.697
9.62	35.45	-0.698
9.63	35.39	-0.699
9.64	35.32	-0.700
9.64	35.26	-0.700
9.65	35.19	-0.701
9.66	35.13	-0.702
9.66	35.06	-0.702
9.67	34.99	-0.703
9.68	34.93	-0.704
9.68	34.86	-0.705
9.69	34.80	-0.706
9.70	34.73	-0.706
9.70	34.67	-0.707
9.71	34.60	-0.707
9.72	34.54	-0.708
9.72	34.47	-0.708
9.73	34.40	-0.708
9.74	34.34	-0.708
9.74	34.27	-0.709
9.75	34.21	-0.709
9.76	34.14	-0.709
9.76	34.08	-0.709
9.77	34.01	-0.710
9.78	33.94	-0.710
9.78	33.88	-0.710
9.79	33.81	-0.711
9.80	33.75	-0.711
9.80	33.68	-0.711
9.81	33.62	-0.711
9.82	33.55	-0.712
9.82	33.49	-0.712
9.83	33.42	-0.712
9.84	33.35	-0.712
9.84	33.29	-0.712
9.85	33.22	-0.713
9.86	33.15	-0.713
9.86	33.09	-0.713
9.87	33.02	-0.713
9.88	32.96	-0.714
9.88	32.89	-0.714
9.89	32.83	-0.714
9.90	32.76	-0.715
9.90	32.69	-0.715
9.91	32.63	-0.715
9.92	32.56	-0.715
9.92	32.50	-0.716
9.93	32.43	-0.716
9.94	32.36	-0.716
9.94	32.30	-0.716
9.95	32.23	-0.716
9.96	32.16	-0.716
9.96	32.10	-0.716
9.97	32.03	-0.717
9.98	31.97	-0.717
9.98	31.90	-0.717
9.99	31.83	-0.717
10.00	31.77	-0.717
10.00	31.70	-0.717
10.01	31.64	-0.717
10.02	31.57	-0.718
10.02	31.50	-0.718
10.03	31.44	-0.718
10.04	31.37	-0.718
10.04	31.31	-0.718
10.05	31.24	-0.718
10.06	31.17	-0.718
10.06	31.11	-0.718
10.07	31.04	-0.719
10.08	30.97	-0.719
10.08	30.91	-0.719
10.09	30.84	-0.719
10.10	30.78	-0.719
10.10	30.71	-0.719
10.11	30.64	-0.719
10.12	30.58	-0.719
10.12	30.51	-0.720
10.13	30.44	-0.720
10.14	30.38	-0.720
10.14	30.31	-0.720
10.15	30.25	-0.720
10.16	30.18	-0.720
10.16	30.11	-0.720
10.17	30.05	-0.720
10.18	29.98	-0.721
10.18	29.91	-0.721
10.19	29.85	-0.721
10.20	29.78	-0.721
10.20	29.72	-0.721
10.21	29.65	-0.721
10.22	29.58	-0.721
10.22	29.51	-0.721
10.23	29.45	-0.721
10.24	29.38	-0.721
10.24	29.32	-0.721
10.25	29.25	-0.721
10.26	29.18	-0.722
10.26	29.12	-0.722
10.27	29.05	-0.722
10.28	28.98	-0.722
10.28	28.92	-0.722
10.29	28.85	-0.722
10.30	28.78	-0.722
10.30	28.72	-0.722
10.31	28.65	-0.722
10.32	28.59	-0.722
10.32	28.52	-0.722
10.33	28.45	-0.722
10.34	28.39	-0.722
10.34	28.32	-0.723
10.35	28.25	-0.723
10.36	28.19	-0.723
10.36	28.12	-0.723
10.37	28.06	-0.723
10.38	27.99	-0.723
10.38	27.92	-0.723
10.39	27.86	-0.723
10.40	27.79	-0.723
10.40	27.72	-0.723
10.41	27.66	-0.723
10.42	27.59	-0.723
10.42	27.52	-0.723
10.43	27.46	-0.723
10.44	27.39	-0.723
10.44	27.33	-0.723
10.45	27.26	-0.723
10.46	27.19	-0.723
10.46	27.12	-0.723
10.47	27.06	-0.723
10.48	26.99	-0.723
10.48	26.93	-0.723
10.49	26.86	-0.723
10.50	26.79	-0.723
10.50	26.73	-0.723
10.51	26.66	-0.723
10.52	26.59	-0.723
10.52	26.53	-0.723
10.53	26.46	-0.723
10.54	26.39	-0.723
10.54	26.33	-0.723
10.55	26.26	-0.723
10.56	26.20	-0.723
10.56	26.13	-0.723
10.57	26.06	-0.723
10.58	26.00	-0.723
10.58	25.93	-0.723
10.59	25.86	-0.723
10.60	25.80	-0.723
10.60	25.73	-0.723
10.61	25.67	-0.723
10.62	25.60	-0.723
10.62	25.53	-0.723
10.63	25.46	-0.723
10.64	25.40	-0.723
10.64	25.33	-0.723
10.65	25.27	-0.723
10.66	25.20	-0.724
10.66	25.13	-0.724
10.67	25.06	-0.724
10.68	25.00	-0.723
10.68	24.93	-0.723
10.69	24.87	-0.723
10.70	24.80	-0.723
10.70	24.73	-0.723
10.71	24.67	-0.723
10.72	24.60	-0.723
10.72	24.53	-0.723
10.73	24.47	-0.723
10.74	24.40	-0.723
10.74	24.33	-0.723
10.75	24.27	-0.723
10.76	24.20	-0.723
10.76	24.13	-0.723
10.77	24.07	-0.723
10.78	24.00	-0.723
10.78	23.93	-0.723
10.79	23.87	-0.723
10.80	23.80	-0.723
10.80	23.74	-0.723
10.81	23.67	-0.723
10.82	23.60	-0.723
10.82	23.54	-0.723
10.83	23.47	-0.723
10.84	23.40	-0.723
10.84	23.34	-0.723
10.85	23.27	-0.723
10.86	23.20	-0.723
10.86	23.14	-0.723
10.87	23.07	-0.723
10.88	23.00	-0.723
10.88	22.94	-0.723
10.89	22.87	-0.723
10.90	22.80	-0.723
10.90	22.74	-0.723
10.91	22.67	-0.723
10.92	22.61	-0.723
10.92	22.54	-0.723
10.93	22.47	-0.723
10.94	22.41	-0.723
10.94	22.34	-0.723
10.95	22.27	-0.723
10.96	22.20	-0.723
10.96	22.14	-0.723
10.97	22.07	-0.723
10.98	22.01	-0.723
10.98	21.94	-0.723
10.99	21.87	-0.722
11.00	21.80	-0.723
11.00	21.74	-0.722
11.01	21.67	-0.722
11.02	21.61	-0.722
11.02	21.54	-0.722
11.03	21.47	-0.722
11.04	21.41	-0.722
11.04	21.34	-0.722
11.05	21.28	-0.722
11.06	21.21	-0.722
11.06	21.14	-0.722
11.07	21.07	-0.722
11.08	21.01	-0.722
11.08	20.94	-0.722
11.09	20.88	-0.722
11.10	20.81	-0.722
11.10	20.74	-0.722
11.11	20.67	-0.722
11.12	20.61	-0.722
11.12	20.54	-0.722
11.13	20.48	-0.722
11.14	20.41	-0.722
11.14	20.34	-0.721
11.15	20.28	-0.721
11.16	20.21	-0.721
11.16	20.14	-0.721
11.17	20.08	-0.721
11.18	20.01	-0.721
11.18	19.94	-0.721
11.19	19.88	-0.721
11.20	19.81	-0.721
11.20	19.74	-0.721
11.21	19.68	-0.721
11.22	19.61	-0.721
11.22	19.54	-0.721
11.23	19.48	-0.721
11.24	19.41	-0.721
11.24	19.34	-0.721
11.25	19.28	-0.721
11.26	19.21	-0.721
11.26	19.14	-0.721
11.27	19.08	-0.721
11.28	19.01	-0.721
11.28	18.94	-0.720
11.29	18.88	-0.720
11.30	18.81	-0.720
11.30	18.74	-0.720
11.31	18.68	-0.720
11.32	18.61	-0.720
11.32	18.55	-0.720
11.33	18.48	-0.720
11.34	18.41	-0.720
11.34	18.35	-0.720
11.35	18.28	-0.720
11.36	18.21	-0.720
11.36	18.15	-0.720
11.37	18.08	-0.720
11.38	18.01	-0.720
11.38	17.95	-0.720
11.39	17.88	-0.720
11.40	17.81	-0.720
11.40	17.75	-0.720
11.41	17.68	-0.719
11.42	17.61	-0.719
11.42	17.55	-0.719
11.43	17.48	-0.719
11.44	17.41	-0.719
11.44	17.35	-0.719
11.45	17.28	-0.719
11.46	17.21	-0.719
11.46	17.15	-0.719
11.47	17.08	-0.719
11.48	17.01	-0.719
11.48	16.95	-0.719
11.49	16.88	-0.719
11.50	16.82	-0.719
11.50	16.75	-0.719
11.51	16.68	-0.719
11.52	16.62	-0.719
11.52	16.55	-0.719
11.53	16.48	-0.719
11.54	16.42	-0.719
11.54	16.35	-0.719
11.55	16.28	-0.719
11.56	16.22	-0.719
11.56	16.15	-0.719
11.57	16.08	-0.719
11.58	16.02	-0.719
11.58	15.95	-0.719
11.59	15.88	-0.718
11.60	15.82	-0.718
11.60	15.75	-0.718
11.61	15.68	-0.718
11.62	15.62	-0.718
11.62	15.55	-0.718
11.63	15.48	-0.718
11.64	15.42	-0.718
11.64	15.35	-0.718
11.65	15.28	-0.718
11.66	15.22	-0.718
11.66	15.15	-0.718
11.67	15.09	-0.718
11.68	15.02	-0.718
11.68	14.95	-0.718
11.69	14.88	-0.718
11.70	14.82	-0.718
11.70	14.75	-0.718
11.71	14.69	-0.718
11.72	14.62	-0.718
11.72	14.55	-0.718
11.73	14.49	-0.718
11.74	14.42	-0.718
11.74	14.35	-0.718
11.75	14.29	-0.718
11.76	14.22	-0.718
11.76	14.15	-0.718
11.77	14.09	-0.718
11.78	14.02	-0.718
11.78	13.95	-0.718
11.79	13.89	-0.718
11.80	13.82	-0.718
11.80	13.76	-0.718
11.81	13.69	-0.718
11.82	13.62	-0.718
11.82	13.55	-0.717
11.83	13.49	-0.717
11.84	13.42	-0.717
11.84	13.36	-0.717
11.85	13.29	-0.717
11.86	13.22	-0.717
11.86	13.16	-0.717
11.87	13.09	-0.717
11.88	13.02	-0.717
11.88	12.96	-0.717
11.89	12.89	-0.717
11.90	12.82	-0.717
11.90	12.76	-0.717
11.91	12.69	-0.717
11.92	12.62	-0.717
11.92	12.56	-0.717
11.93	12.49	-0.717
11.94	12.42	-0.717
11.94	12.36	-0.717
11.95	12.29	-0.717
11.96	12.22	-0.717
11.96	12.16	-0.717
11.97	12.09	-0.717
11.98	12.02	-0.717
11.98	11.96	-0.717
11.99	11.89	-0.717
12.00	11.82	-0.717
12.00	11.76	-0.717
12.01	11.69	-0.717
12.02	11.62	-0.717
12.02	11.56	-0.717
12.03	11.49	-0.717
12.04	11.42	-0.717
12.04	11.36	-0.717
12.05	11.29	-0.717
12.06	11.23	-0.717
12.06	11.16	-0.717
12.07	11.09	-0.717
12.08	11.03	-0.717
12.08	10.96	-0.717
12.09	10.89	-0.717
12.10	10.83	-0.717
12.10	10.76	-0.717
12.11	10.69	-0.717
12.12	10.63	-0.717
12.12	10.56	-0.717
12.13	10.49	-0.717
12.14	10.43	-0.717
12.14	10.36	-0.717
12.15	10.29	-0.717
12.16	10.23	-0.717
12.16	10.16	-0.717
12.17	10.09	-0.717
12.18	10.03	-0.717
12.18	9.96	-0.717
12.19	9.89	-0.717
12.20	9.83	-0.717
12.20	9.76	-0.717
12.21	9.70	-0.717
12.22	9.63	-0.717
12.22	9.56	-0.717
12.23	9.50	-0.717
12.24	9.43	-0.717
12.24	9.36	-0.717
12.25	9.30	-0.717
12.26	9.23	-0.717
12.26	9.16	-0.717
12.27	9.10	-0.717
12.28	9.03	-0.717
12.28	8.96	-0.717
12.29	8.90	-0.717
12.30	8.83	-0.717
12.30	8.77	-0.717
12.31	8.70	-0.717
12.32	8.63	-0.717
12.32	8.57	-0.717
12.33	8.50	-0.717
12.34	8.43	-0.717
12.34	8.37	-0.717
12.35	8.30	-0.717
12.36	8.23	-0.717
12.36	8.17	-0.717
12.37	8.10	-0.717
12.38	8.03	-0.717
12.38	7.97	-0.717
12.39	7.90	-0.717
12.40	7.83	-0.717
12.40	7.77	-0.717
12.41	7.70	-0.717
12.42	7.63	-0.717
12.42	7.57	-0.717
12.43	7.50	-0.717
12.44	7.43	-0.717
12.44	7.37	-0.717
12.45	7.30	-0.717
12.46	7.24	-0.717
12.46	7.17	-0.717
12.47	7.10	-0.717
12.48	7.04	-0.717
12.48	6.97	-0.717
12.49	6.90	-0.717
12.50	6.84	-0.717
12.50	6.77	-0.717
12.51	6.70	-0.717
12.52	6.64	-0.717
12.52	6.57	-0.717
12.53	6.50	-0.717
12.54	6.44	-0.717
12.54	6.37	-0.717
12.55	6.31	-0.717
12.56	6.24	-0.717
12.56	6.17	-0.717
12.57	6.10	-0.717
12.58	6.04	-0.717
12.58	5.97	-0.717
12.59	5.90	-0.717
12.60	5.84	-0.717
12.60	5.77	-0.717
12.61	5.71	-0.717
12.62	5.64	-0.717
12.62	5.57	-0.717
12.63	5.51	-0.717
12.64	5.44	-0.717
12.64	5.37	-0.717
12.65	5.31	-0.717
12.66	5.24	-0.717
12.66	5.17	-0.717
12.67	5.11	-0.717
12.68	5.04	-0.717
12.68	4.97	-0.717
12.69	4.91	-0.717
12.70	4.84	-0.717
12.70	4.77	-0.717
12.71	4.71	-0.717
12.72	4.64	-0.717
12.72	4.57	-0.717
12.73	4.51	-0.717
12.74	4.44	-0.717
12.74	4.37	-0.717
12.75	4.31	-0.717
12.76	4.24	-0.717
12.76	4.17	-0.717
12.77	4.11	-0.717
12.78	4.04	-0.717
12.78	3.98	-0.717
12.79	3.91	-0.717
12.80	3.84	-0.717
12.80	3.78	-0.717
12.81	3.71	-0.717
12.82	3.64	-0.717
12.82	3.57	-0.717
12.83	3.51	-0.717
12.84	3.44	-0.717
12.84	3.38	-0.717
12.85	3.31	-0.717
12.86	3.24	-0.717
12.86	3.18	-0.717
12.87	3.11	-0.717
12.88	3.04	-0.718
12.88	2.98	-0.718
12.89	2.91	-0.718
12.90	2.84	-0.718
12.90	2.78	-0.718
12.91	2.71	-0.718
12.92	2.64	-0.718
12.92	2.58	-0.718
12.93	2.51	-0.718
12.94	2.44	-0.718
12.94	2.38	-0.718
12.95	2.31	-0.718
12.96	2.24	-0.718
12.96	2.18	-0.718
12.97	2.11	-0.718
12.98	2.04	-0.718
12.98	1.98	-0.718
12.99	1.91	-0.718
13.00	1.84	-0.718
13.00	1.77	-0.718
13.01	1.71	-0.718
13.02	1.64	-0.718
13.02	1.58	-0.718
13.03	1.51	-0.719
13.04	1.44	-0.719
13.04	1.38	-0.719
13.05	1.31	-0.719
13.06	1.24	-0.719
13.06	1.18	-0.719
13.07	1.11	-0.719
13.08	1.04	-0.719
13.08	0.98	-0.719
13.09	0.91	-0.719
13.10	0.84	-0.719
13.10	0.78	-0.719
13.11	0.71	-0.719
13.12	0.64	-0.719
13.12	0.58	-0.719
13.13	0.51	-0.719
13.14	0.44	-0.719
13.14	0.38	-0.719
13.15	0.31	-0.719
13.16	0.24	-0.719
13.16	0.18	-0.720
13.17	0.11	-0.720
13.18	0.04	-0.720
13.18	-0.02	-0.720
13.19	-0.09	-0.720
13.20	-0.16	-0.720
13.20	-0.22	-0.720
13.21	-0.29	-0.720
13.22	-0.36	-0.720
13.22	-0.42	-0.720
13.23	-0.49	-0.720
13.24	-0.56	-0.720
13.24	-0.62	-0.720
13.25	-0.69	-0.721
13.26	-0.76	-0.721
13.26	-0.82	-0.721
13.27	-0.89	-0.721
13.28	-0.96	-0.721
13.28	-1.02	-0.721
13.29	-1.09	-0.721
13.30	-1.16	-0.721
13.30	-1.22	-0.721
13.31	-1.29	-0.721
13.32	-1.36	-0.721
13.32	-1.42	-0.721
13.33	-1.49	-0.721
13.34	-1.56	-0.721
13.34	-1.62	-0.721
13.35	-1.69	-0.721
13.36	-1.76	-0.721
13.36	-1.82	-0.721
13.37	-1.89	-0.722
13.38	-1.96	-0.722
13.38	-2.02	-0.722
13.39	-2.09	-0.722
13.40	-2.16	-0.722
13.40	-2.22	-0.722
13.41	-2.29	-0.722
13.42	-2.36	-0.722
13.42	-2.42	-0.722
13.43	-2.49	-0.722
13.44	-2.56	-0.722
13.44	-2.62	-0.722
13.45	-2.69	-0.722
13.46	-2.76	-0.722
13.46	-2.82	-0.722
13.47	-2.89	-0.723
13.48	-2.96	-0.723
13.48	-3.02	-0.723
13.49	-3.09	-0.723
13.50	-3.16	-0.723
13.50	-3.22	-0.723
13.51	-3.29	-0.723
13.52	-3.36	-0.723
13.52	-3.42	-0.723
13.53	-3.49	-0.723
13.54	-3.56	-0.723
13.54	-3.62	-0.724
13.55	-3.69	-0.724
13.56	-3.76	-0.724
13.56	-3.82	-0.724
13.57	-3.89	-0.724
13.58	-3.96	-0.724
13.58	-4.02	-0.724
13.59	-4.09	-0.724
13.60	-4.16	-0.724
13.60	-4.22	-0.724
13.61	-4.29	-0.724
13.62	-4.36	-0.724
13.62	-4.42	-0.724
13.63	-4.49	-0.724
13.64	-4.56	-0.724
13.64	-4.62	-0.725
13.65	-4.69	-0.725
13.66	-4.76	-0.725
13.66	-4.83	-0.725
13.67	-4.89	-0.725
13.68	-4.96	-0.725
13.68	-5.02	-0.725
13.69	-5.09	-0.725
13.70	-5.16	-0.725
13.70	-5.22	-0.725
13.71	-5.29	-0.725
13.72	-5.36	-0.726
13.72	-5.42	-0.726
13.73	-5.49	-0.726
13.74	-5.56	-0.726
13.74	-5.62	-0.726
13.75	-5.69	-0.726
13.76	-5.76	-0.726
13.76	-5.82	-0.726
13.77	-5.89	-0.726
13.78	-5.96	-0.726
13.78	-6.03	-0.726
13.79	-6.09	-0.727
13.80	-6.16	-0.727
13.80	-6.23	-0.727
13.81	-6.29	-0.727
13.82	-6.36	-0.727
13.82	-6.43	-0.727
13.83	-6.49	-0.727
13.84	-6.56	-0.727
13.84	-6.63	-0.727
13.85	-6.69	-0.727
13.86	-6.76	-0.727
13.86	-6.83	-0.727
13.87	-6.89	-0.728
13.88	-6.96	-0.728
13.88	-7.03	-0.728
13.89	-7.09	-0.728
13.90	-7.16	-0.728
13.90	-7.23	-0.728
13.91	-7.29	-0.728
13.92	-7.36	-0.728
13.92	-7.43	-0.728
13.93	-7.49	-0.728
13.94	-7.56	-0.729
13.94	-7.63	-0.729
13.95	-7.69	-0.729
13.96	-7.76	-0.729
13.96	-7.83	-0.729
13.97	-7.89	-0.729
13.98	-7.96	-0.729
13.98	-8.03	-0.729
13.99	-8.09	-0.729
14.00	-8.16	-0.730
14.00	-8.23	-0.730
14.01	-8.29	-0.730
14.02	-8.36	-0.730
14.02	-8.43	-0.730
14.03	-8.49	-0.730
14.04	-8.56	-0.730
14.04	-8.63	-0.730
14.05	-8.69	-0.730
14.06	-8.76	-0.731
14.06	-8.83	-0.731
14.07	-8.89	-0.731
14.08	-8.96	-0.731
14.08	-9.03	-0.731
14.09	-9.09	-0.731
14.10	-9.16	-0.731
14.10	-9.23	-0.731
14.11	-9.29	-0.732
14.12	-9.36	-0.732
14.12	-9.43	-0.732
14.13	-9.49	-0.732
14.14	-9.56	-0.732
14.14	-9.63	-0.732
14.15	-9.69	-0.732
14.16	-9.76	-0.733
14.16	-9.82	-0.733
14.17	-9.89	-0.733
[...]
18.65	-35.08	0.300
18.66	-35.02	0.300
18.66	-34.95	0.301
18.67	-34.89	0.301
18.68	-34.82	0.302
18.68	-34.76	0.302
18.69	-34.69	0.303
18.69	-34.63	0.303
18.70	-34.56	0.303
18.71	-34.49	0.303
18.72	-34.43	0.304
18.72	-34.36	0.305
18.73	-34.30	0.305
18.73	-34.23	0.305
18.74	-34.17	0.305
18.75	-34.10	0.306
18.76	-34.04	0.306
18.76	-33.97	0.306
18.77	-33.91	0.306
18.78	-33.84	0.307
18.78	-33.77	0.307
18.79	-33.71	0.307
18.79	-33.64	0.307
18.80	-33.58	0.307
18.81	-33.51	0.307
18.82	-33.44	0.308
18.82	-33.38	0.308
18.83	-33.31	0.308
18.83	-33.25	0.308
18.84	-33.18	0.308
18.85	-33.12	0.309
18.86	-33.05	0.309
18.86	-32.98	0.309
18.87	-32.92	0.309
18.88	-32.85	0.309
18.88	-32.79	0.310
18.89	-32.72	0.310
18.89	-32.65	0.310
18.90	-32.59	0.310
18.91	-32.52	0.310
18.92	-32.46	0.310
18.92	-32.39	0.311
18.93	-32.32	0.311
18.93	-32.26	0.311
18.94	-32.19	0.311
18.95	-32.13	0.311
18.96	-32.06	0.312
18.96	-32.00	0.312
18.97	-31.93	0.312
18.98	-31.86	0.312
18.98	-31.80	0.312
18.99	-31.73	0.312
18.99	-31.66	0.313
19.00	-31.60	0.313
19.01	-31.53	0.313
19.02	-31.47	0.313
19.02	-31.40	0.313
19.03	-31.33	0.314
19.03	-31.27	0.314
19.04	-31.20	0.314
19.05	-31.14	0.314
19.06	-31.07	0.314
19.06	-31.00	0.314
19.07	-30.94	0.314
19.08	-30.87	0.315
19.08	-30.80	0.315
19.09	-30.74	0.315
19.09	-30.67	0.315
19.10	-30.61	0.315
19.11	-30.54	0.315
19.12	-30.47	0.315
19.12	-30.41	0.316
19.13	-30.34	0.316
19.13	-30.27	0.316
19.14	-30.21	0.316
19.15	-30.14	0.316
19.16	-30.08	0.316
19.16	-30.01	0.316
19.17	-29.94	0.316
19.18	-29.88	0.317
19.18	-29.81	0.317
19.19	-29.74	0.317
19.19	-29.68	0.317
19.20	-29.61	0.317
19.21	-29.54	0.317
19.22	-29.48	0.317
19.22	-29.41	0.317
19.23	-29.35	0.318
19.23	-29.28	0.318
19.24	-29.21	0.318
19.25	-29.15	0.318
19.26	-29.08	0.318
19.26	-29.01	0.318
19.27	-28.95	0.318
19.28	-28.88	0.318
19.28	-28.81	0.319
19.29	-28.75	0.319
19.29	-28.68	0.319
19.30	-28.62	0.319
19.31	-28.55	0.319
19.32	-28.48	0.319
19.32	-28.41	0.319
19.33	-28.35	0.319
19.33	-28.28	0.319
19.34	-28.22	0.320
19.35	-28.15	0.320
19.36	-28.08	0.320
19.36	-28.02	0.320
19.37	-27.95	0.320
19.38	-27.88	0.320
19.38	-27.82	0.320
19.39	-27.75	0.320
19.39	-27.69	0.320
19.40	-27.62	0.321
19.41	-27.55	0.321
19.42	-27.49	0.321
19.42	-27.42	0.321
19.43	-27.35	0.321
19.43	-27.29	0.321
19.44	-27.22	0.321
19.45	-27.15	0.321
19.46	-27.09	0.321
19.46	-27.02	0.321
19.47	-26.95	0.321
19.48	-26.89	0.322
19.48	-26.82	0.322
19.49	-26.75	0.322
19.49	-26.69	0.322
19.50	-26.62	0.322
19.51	-26.55	0.322
19.52	-26.49	0.322
19.52	-26.42	0.322
19.53	-26.36	0.322
19.53	-26.29	0.322
19.54	-26.22	0.322
19.55	-26.15	0.323
19.56	-26.09	0.323
19.56	-26.02	0.323
19.57	-25.95	0.323
19.58	-25.89	0.323
19.58	-25.82	0.323
19.59	-25.76	0.323
19.59	-25.69	0.323
19.60	-25.62	0.323
19.61	-25.56	0.323
19.62	-25.49	0.323
19.62	-25.42	0.323
19.63	-25.36	0.323
19.63	-25.29	0.324
19.64	-25.22	0.324
19.65	-25.16	0.324
19.66	-25.09	0.324
19.66	-25.02	0.324
19.67	-24.96	0.324
19.68	-24.89	0.324
19.68	-24.82	0.324
19.69	-24.76	0.324
19.69	-24.69	0.324
19.70	-24.62	0.324
19.71	-24.56	0.324
19.72	-24.49	0.325
19.72	-24.42	0.325
19.73	-24.36	0.325
19.73	-24.29	0.325
19.74	-24.22	0.325
19.75	-24.16	0.325
19.76	-24.09	0.325
19.76	-24.02	0.325
19.77	-23.96	0.325
19.78	-23.89	0.325
19.78	-23.82	0.325
19.79	-23.76	0.325
19.79	-23.69	0.325
19.80	-23.62	0.325
19.81	-23.56	0.325
19.82	-23.49	0.326
19.82	-23.42	0.326
19.83	-23.36	0.326
19.83	-23.29	0.326
19.84	-23.22	0.326
19.85	-23.16	0.326
19.86	-23.09	0.326
19.86	-23.02	0.326
19.87	-22.96	0.326
19.88	-22.89	0.326
19.88	-22.83	0.326
19.89	-22.76	0.326
19.89	-22.69	0.326
19.90	-22.62	0.326
19.91	-22.56	0.326
19.92	-22.49	0.326
19.92	-22.42	0.327
19.93	-22.36	0.327
19.93	-22.29	0.327
19.94	-22.22	0.327
19.95	-22.16	0.327
19.96	-22.09	0.327
19.96	-22.02	0.327
19.97	-21.96	0.327
19.98	-21.89	0.327
19.98	-21.83	0.327
19.99	-21.76	0.327
19.99	-21.69	0.327
20.00	-21.62	0.327
20.01	-21.56	0.327
20.02	-21.49	0.327
20.02	-21.42	0.327
20.03	-21.36	0.328
20.03	-21.29	0.328
20.04	-21.23	0.328
20.05	-21.16	0.328
20.06	-21.09	0.328
20.06	-21.02	0.328
20.07	-20.96	0.328
20.08	-20.89	0.328
20.08	-20.82	0.328
20.09	-20.76	0.328
20.09	-20.69	0.328
20.10	-20.62	0.328
20.11	-20.56	0.328
20.12	-20.49	0.328
20.12	-20.43	0.328
20.13	-20.36	0.328
20.13	-20.29	0.329
20.14	-20.23	0.329
20.15	-20.16	0.329
20.16	-20.09	0.329
20.16	-20.03	0.329
20.17	-19.96	0.329
20.18	-19.89	0.329
20.18	-19.82	0.329
20.19	-19.76	0.329
20.19	-19.69	0.329
20.20	-19.62	0.329
20.21	-19.56	0.329
20.22	-19.49	0.329
20.22	-19.42	0.329
20.23	-19.36	0.329
20.23	-19.29	0.329
20.24	-19.22	0.329
20.25	-19.16	0.329
20.26	-19.09	0.329
20.26	-19.02	0.329
20.27	-18.96	0.330
20.28	-18.89	0.330
20.28	-18.82	0.330
20.29	-18.76	0.330
20.29	-18.69	0.330
20.30	-18.62	0.330
20.31	-18.56	0.330
20.32	-18.49	0.330
20.32	-18.42	0.330
20.33	-18.36	0.330
20.33	-18.29	0.330
20.34	-18.22	0.330
20.35	-18.16	0.330
20.36	-18.09	0.330
20.36	-18.02	0.330
20.37	-17.96	0.330
20.38	-17.89	0.330
20.38	-17.82	0.330
20.39	-17.76	0.330
20.39	-17.69	0.331
20.40	-17.62	0.331
20.41	-17.56	0.331
20.42	-17.49	0.331
20.42	-17.42	0.331
20.43	-17.36	0.331
20.43	-17.29	0.331
20.44	-17.22	0.331
20.45	-17.16	0.331
20.46	-17.09	0.331
20.46	-17.02	0.331
20.47	-16.96	0.331
20.48	-16.89	0.331
20.48	-16.82	0.331
20.49	-16.76	0.331
20.49	-16.69	0.331
20.50	-16.62	0.332
20.51	-16.56	0.332
20.52	-16.49	0.332
20.52	-16.42	0.332
20.53	-16.36	0.332
20.53	-16.29	0.332
20.54	-16.22	0.332
20.55	-16.16	0.332
20.56	-16.09	0.332
20.56	-16.02	0.332
20.57	-15.95	0.332
20.58	-15.89	0.332
20.58	-15.82	0.332
20.59	-15.76	0.332
20.59	-15.69	0.332
20.60	-15.62	0.332
20.61	-15.56	0.332
20.62	-15.49	0.333
20.62	-15.42	0.333
20.63	-15.36	0.333
20.63	-15.29	0.333
20.64	-15.22	0.333
20.65	-15.16	0.333
20.66	-15.09	0.333
20.66	-15.02	0.333
20.67	-14.96	0.333
20.68	-14.89	0.333
20.68	-14.82	0.333
20.69	-14.76	0.333
20.69	-14.69	0.333
20.70	-14.62	0.333
20.71	-14.55	0.333
20.72	-14.49	0.334
20.72	-14.42	0.334
20.73	-14.35	0.334
20.73	-14.29	0.334
20.74	-14.22	0.334
20.75	-14.15	0.334
20.76	-14.09	0.334
20.76	-14.02	0.334
20.77	-13.95	0.334
20.78	-13.89	0.334
20.78	-13.82	0.334
20.79	-13.75	0.334
20.79	-13.69	0.334
20.80	-13.62	0.334
20.81	-13.55	0.334
20.82	-13.49	0.334
20.82	-13.42	0.335
20.83	-13.35	0.335
20.83	-13.29	0.335
20.84	-13.22	0.335
20.85	-13.15	0.335
20.86	-13.09	0.335
20.86	-13.02	0.335
20.87	-12.95	0.335
20.88	-12.89	0.335
20.88	-12.82	0.335
20.89	-12.75	0.335
20.89	-12.69	0.335
20.90	-12.62	0.335
20.91	-12.55	0.335
20.92	-12.49	0.335
20.92	-12.42	0.335
20.93	-12.36	0.335
20.93	-12.29	0.335
20.94	-12.22	0.335
20.95	-12.15	0.336
20.96	-12.09	0.336
20.96	-12.02	0.336
20.97	-11.95	0.336
20.98	-11.89	0.336
20.98	-11.82	0.336
20.99	-11.75	0.336
20.99	-11.69	0.336
21.00	-11.62	0.336
21.01	-11.55	0.336
21.02	-11.49	0.336
21.02	-11.42	0.336
21.03	-11.35	0.336
21.03	-11.29	0.336
21.04	-11.22	0.336
21.05	-11.15	0.336
21.06	-11.09	0.337
21.06	-11.02	0.337
21.07	-10.95	0.337
21.08	-10.89	0.337
21.08	-10.82	0.337
21.09	-10.75	0.337
21.09	-10.69	0.337
21.10	-10.62	0.337
21.11	-10.55	0.337
21.12	-10.49	0.337
21.12	-10.42	0.337
21.13	-10.35	0.337
21.13	-10.29	0.337
21.14	-10.22	0.337
21.15	-10.15	0.337
21.16	-10.09	0.338
21.16	-10.02	0.338
21.17	-9.95	0.338
21.18	-9.89	0.338
21.18	-9.82	0.338
21.19	-9.75	0.338
21.19	-9.69	0.338
21.20	-9.62	0.338
21.21	-9.55	0.338
21.22	-9.49	0.338
21.22	-9.42	0.338
21.23	-9.35	0.338
21.23	-9.29	0.338
21.24	-9.22	0.338
21.25	-9.15	0.338
21.26	-9.08	0.338
21.26	-9.02	0.339
21.27	-8.95	0.339
21.28	-8.89	0.339
21.28	-8.82	0.339
21.29	-8.75	0.339
21.29	-8.68	0.339
21.30	-8.62	0.339
21.31	-8.55	0.339
21.32	-8.48	0.339
21.32	-8.42	0.339
21.33	-8.35	0.339
21.33	-8.28	0.339
21.34	-8.22	0.339
21.35	-8.15	0.339
21.36	-8.08	0.340
21.36	-8.02	0.340
21.37	-7.95	0.340
21.38	-7.88	0.340
21.38	-7.82	0.340
21.39	-7.75	0.340
21.39	-7.68	0.340
21.40	-7.62	0.340
21.41	-7.55	0.340
21.42	-7.48	0.340
21.42	-7.42	0.340
21.43	-7.35	0.340
21.43	-7.28	0.340
21.44	-7.22	0.340
21.45	-7.15	0.340
21.46	-7.08	0.341
21.46	-7.02	0.341
21.47	-6.95	0.341
21.48	-6.88	0.341
21.48	-6.81	0.341
21.49	-6.75	0.341
21.49	-6.68	0.341
21.50	-6.62	0.341
21.51	-6.55	0.341
21.52	-6.48	0.341
21.52	-6.42	0.341
21.53	-6.35	0.341
21.53	-6.28	0.342
21.54	-6.22	0.342
21.55	-6.15	0.342
21.56	-6.08	0.342
21.56	-6.02	0.342
21.57	-5.95	0.342
21.58	-5.88	0.342
21.58	-5.82	0.342
21.59	-5.75	0.342
21.59	-5.68	0.342
21.60	-5.61	0.342
21.61	-5.55	0.342
21.62	-5.48	0.342
21.62	-5.41	0.343
21.63	-5.35	0.343
21.63	-5.28	0.343
21.64	-5.21	0.343
21.65	-5.15	0.343
21.66	-5.08	0.343
21.66	-5.01	0.343
21.67	-4.95	0.343
21.68	-4.88	0.343
21.68	-4.82	0.343
21.69	-4.75	0.343
21.69	-4.68	0.344
21.70	-4.61	0.344
21.71	-4.55	0.344
21.72	-4.48	0.344
21.72	-4.41	0.344
21.73	-4.35	0.344
21.73	-4.28	0.344
21.74	-4.21	0.344
21.75	-4.15	0.344
21.76	-4.08	0.344
21.76	-4.01	0.344
21.77	-3.95	0.344
21.78	-3.88	0.345
21.78	-3.81	0.345
21.79	-3.75	0.345
21.79	-3.68	0.345
21.80	-3.61	0.345
21.81	-3.55	0.345
21.82	-3.48	0.345
21.82	-3.41	0.345
21.83	-3.35	0.345
21.83	-3.28	0.345
21.84	-3.21	0.346
21.85	-3.15	0.346
21.86	-3.08	0.346
21.86	-3.01	0.346
21.87	-2.95	0.346
21.88	-2.88	0.346
21.88	-2.81	0.346
21.89	-2.75	0.346
21.89	-2.68	0.346
21.90	-2.61	0.347
21.91	-2.55	0.347
21.92	-2.48	0.347
21.92	-2.41	0.347
21.93	-2.35	0.347
21.93	-2.28	0.347
21.94	-2.21	0.347
21.95	-2.15	0.347
21.96	-2.08	0.347
21.96	-2.01	0.348
21.97	-1.95	0.348
21.98	-1.88	0.348
21.98	-1.81	0.349
21.99	-1.75	0.349
21.99	-1.68	0.349
22.00	-1.61	0.349
22.01	-1.55	0.349
22.02	-1.48	0.349
22.02	-1.41	0.350
22.03	-1.35	0.350
22.03	-1.28	0.351
22.04	-1.21	0.351
22.05	-1.15	0.351
22.06	-1.08	0.351
22.06	-1.01	0.351
22.07	-0.95	0.351
22.08	-0.88	0.351
22.08	-0.81	0.352
22.09	-0.75	0.352
22.09	-0.68	0.352
22.10	-0.61	0.352
22.11	-0.55	0.352
22.12	-0.48	0.353
22.12	-0.41	0.353
22.13	-0.35	0.353
22.13	-0.28	0.353
22.14	-0.21	0.354
22.15	-0.15	0.355
22.16	-0.08	0.356
22.16	-0.01	0.357
22.17	0.05	0.358
22.18	0.12	0.358
22.18	0.19	0.359
22.19	0.25	0.360
22.19	0.32	0.362
22.20	0.39	0.364
22.21	0.45	0.366
22.22	0.52	0.369
22.22	0.59	0.371
22.23	0.65	0.372
22.23	0.72	0.374
22.24	0.79	0.376
22.25	0.85	0.379
22.26	0.92	0.384
22.26	0.98	0.388
22.27	1.05	0.391
22.28	1.12	0.395
22.28	1.18	0.400
22.29	1.25	0.406
22.29	1.31	0.414
22.30	1.38	0.421
22.31	1.44	0.429
22.32	1.51	0.439
22.32	1.58	0.451
22.33	1.64	0.466
22.33	1.71	0.485
22.34	1.77	0.507
22.35	1.83	0.536
22.36	1.90	0.570
22.36	1.96	0.614
22.37	2.02	0.673
22.38	2.08	0.747
22.38	2.14	0.838
22.39	2.19	0.952
22.39	2.24	1.086
22.40	2.29	1.235
22.41	2.34	1.396
22.42	2.38	1.557
22.42	2.42	1.719
22.43	2.46	1.885
22.43	2.50	2.058
22.44	2.53	2.236
22.45	2.56	2.406
22.46	2.60	2.553
22.46	2.63	2.691
22.47	2.66	2.818
22.48	2.69	2.928
22.48	2.72	3.034
22.49	2.75	3.124
22.49	2.78	3.214
22.50	2.82	3.303
22.51	2.85	3.396
22.52	2.89	3.484
22.52	2.92	3.567
22.53	2.96	3.654
22.53	3.00	3.740
22.54	3.03	3.821
22.55	3.07	3.899
22.56	3.11	3.974
22.56	3.15	4.050
22.57	3.19	4.123
22.58	3.23	4.194
22.58	3.27	4.265
22.59	3.31	4.333
22.59	3.36	4.399
22.60	3.40	4.464
22.61	3.44	4.529
22.62	3.49	4.590
22.62	3.53	4.646
22.63	3.58	4.706
22.63	3.62	4.766
22.64	3.67	4.821
22.65	3.71	4.874
22.66	3.76	4.930
22.66	3.81	4.981
22.67	3.86	5.032
22.68	3.91	5.084
22.68	3.95	5.133
22.69	4.00	5.180
22.69	4.05	5.226
22.70	4.10	5.272
22.71	4.15	5.317
22.72	4.20	5.363
22.72	4.25	5.407
22.73	4.31	5.453
22.73	4.36	5.499
22.74	4.41	5.548
22.75	4.46	5.599
22.76	4.51	5.650
22.76	4.56	5.704
22.77	4.62	5.765
22.78	4.67	5.829
22.78	4.72	5.898
22.79	4.77	5.968
22.79	4.82	6.041
22.80	4.87	6.114
22.81	4.92	6.185
22.82	4.96	6.256
22.82	5.01	6.321
22.83	5.06	6.385
22.83	5.11	6.448
22.84	5.16	6.501
22.85	5.21	6.546
22.86	5.26	6.587
22.86	5.31	6.627
22.87	5.36	6.667
22.88	5.41	6.697
22.88	5.46	6.719
22.89	5.52	6.774
22.89	5.57	6.871
22.90	5.62	6.968
22.91	5.67	7.043
22.92	5.71	7.114
22.92	5.76	7.232
22.93	5.81	7.504
22.93	5.84	8.018
22.94	5.86	8.621
22.95	5.86	9.053
22.96	5.86	9.291
22.96	5.87	9.396
22.97	5.88	9.236
22.98	5.92	8.781
22.98	5.97	8.226
22.99	6.05	7.724
22.99	6.13	7.344
23.00	6.22	7.088
23.01	6.32	6.926
23.02	6.41	6.825
23.02	6.51	6.762
23.03	6.60	6.721
23.03	6.69	6.689
23.04	6.77	6.664
23.05	6.86	6.641
23.06	6.95	6.617
23.06	7.03	6.592
23.07	7.11	6.568
23.08	7.20	6.542
23.08	7.28	6.514
23.09	7.36	6.483
23.09	7.44	6.453
23.10	7.52	6.421
23.11	7.60	6.385
23.12	7.68	6.347
23.12	7.76	6.308
23.13	7.84	6.267
23.13	7.91	6.228
23.14	7.99	6.188
23.15	8.07	6.143
23.16	8.15	6.100
23.16	8.23	6.057
23.17	8.31	6.012
23.18	8.39	5.967
23.18	8.47	5.922
23.19	8.55	5.871
23.19	8.63	5.821
23.20	8.71	5.770
23.21	8.79	5.715
23.22	8.87	5.662
23.22	8.95	5.607
23.23	9.03	5.549
23.23	9.11	5.493
23.24	9.19	5.434
23.25	9.28	5.372
23.26	9.36	5.307
23.26	9.44	5.242
23.27	9.52	5.175
23.28	9.61	5.106
23.28	9.69	5.036
23.29	9.78	4.962
23.29	9.86	4.884
23.30	9.95	4.803
23.31	10.03	4.720
23.32	10.12	4.634
23.32	10.21	4.545
23.33	10.29	4.456
23.33	10.38	4.366
23.34	10.47	4.271
23.35	10.56	4.172
23.36	10.65	4.072
23.36	10.74	3.968
23.37	10.83	3.860
23.38	10.93	3.747
23.38	11.02	3.628
23.39	11.11	3.498
23.39	11.21	3.357
23.40	11.31	3.205
23.41	11.41	3.046
23.42	11.51	2.888
23.42	11.61	2.734
23.43	11.71	2.592
23.43	11.81	2.461
23.44	11.92	2.342
23.45	12.02	2.236
23.46	12.12	2.141
23.46	12.22	2.052
23.47	12.32	1.971
23.48	12.42	1.899
23.48	12.51	1.831
23.49	12.61	1.768
23.49	12.70	1.709
23.50	12.80	1.654
23.51	12.89	1.601
23.52	12.98	1.554
23.52	13.07	1.509
23.53	13.16	1.465
23.53	13.24	1.426
23.54	13.33	1.386
23.55	13.42	1.350
23.56	13.50	1.317
23.56	13.58	1.282
23.57	13.67	1.252
23.58	13.75	1.228
23.58	13.83	1.200
23.59	13.91	1.165
23.59	13.99	1.136
23.60	14.07	1.117
23.61	14.15	1.102
23.62	14.23	1.082
23.62	14.31	1.058
23.63	14.38	1.037
23.63	14.46	1.016
23.64	14.54	0.999
23.65	14.61	0.984
23.66	14.69	0.969
23.66	14.76	0.955
23.67	14.84	0.940
23.68	14.91	0.927
23.68	14.98	0.913
23.69	15.06	0.900
23.69	15.13	0.890
23.70	15.20	0.878
23.71	15.28	0.866
23.72	15.35	0.858
23.72	15.42	0.850
23.73	15.49	0.838
23.73	15.56	0.829
23.74	15.63	0.824
23.75	15.71	0.815
23.76	15.78	0.806
23.76	15.85	0.801
23.77	15.92	0.796
23.78	15.99	0.787
23.78	16.06	0.781
23.79	16.13	0.775
23.79	16.20	0.771
23.80	16.27	0.767
23.81	16.33	0.760
23.82	16.40	0.755
23.82	16.47	0.751
23.83	16.54	0.747
23.83	16.61	0.743
23.84	16.68	0.740
23.85	16.75	0.736
23.86	16.81	0.731
23.86	16.89	0.730
23.87	16.95	0.726
23.88	17.02	0.722
23.88	17.09	0.720
23.89	17.16	0.719
23.89	17.22	0.715
23.90	17.29	0.712
23.91	17.36	0.711
23.92	17.43	0.710
23.92	17.50	0.707
23.93	17.56	0.704
23.93	17.63	0.703
23.94	17.70	0.702
23.95	17.77	0.700
23.96	17.84	0.698
23.96	17.90	0.697
23.97	17.97	0.696
23.98	18.04	0.695
23.98	18.11	0.694
23.99	18.17	0.692
23.99	18.24	0.691
24.00	18.31	0.691
24.01	18.38	0.690
24.02	18.44	0.689
24.02	18.51	0.688
24.03	18.58	0.687
24.03	18.65	0.686
24.04	18.71	0.686
24.05	18.78	0.685
24.06	18.85	0.684
24.06	18.91	0.683
24.07	18.98	0.682
24.08	19.05	0.681
24.08	19.11	0.681
24.09	19.18	0.681
24.09	19.25	0.679
24.10	19.32	0.679
24.11	19.38	0.679
24.12	19.45	0.679
24.12	19.52	0.678
24.13	19.58	0.678
24.13	19.65	0.678
24.14	19.72	0.677
24.15	19.78	0.677
24.16	19.85	0.676
24.16	19.92	0.676
24.17	19.99	0.676
24.18	20.05	0.676
24.18	20.12	0.676
24.19	20.19	0.676
24.19	20.25	0.676
24.20	20.32	0.675
24.21	20.39	0.675
24.22	20.45	0.675
24.22	20.52	0.675
24.23	20.59	0.675
24.23	20.65	0.674
24.24	20.72	0.674
24.25	20.79	0.674
24.26	20.85	0.674
24.26	20.92	0.674
24.27	20.99	0.674
24.28	21.05	0.674
24.28	21.12	0.674
24.29	21.19	0.673
24.29	21.26	0.673
24.30	21.32	0.673
24.31	21.39	0.673
24.32	21.46	0.673
24.32	21.52	0.673
24.33	21.59	0.673
24.33	21.66	0.673
24.34	21.72	0.672
24.35	21.79	0.672
24.36	21.86	0.672
24.36	21.92	0.672
24.37	21.99	0.672
24.38	22.06	0.672
24.38	22.12	0.672
24.39	22.19	0.672
24.39	22.26	0.671
24.40	22.32	0.671
24.41	22.39	0.671
24.42	22.46	0.671
24.42	22.53	0.671
24.43	22.59	0.671
24.43	22.66	0.671
24.44	22.72	0.671
24.45	22.79	0.670
24.46	22.86	0.670
24.46	22.93	0.670
24.47	22.99	0.670
24.48	23.06	0.670
24.48	23.13	0.670
24.49	23.19	0.670
24.49	23.26	0.670
24.50	23.33	0.670
24.51	23.39	0.670
24.52	23.46	0.669
24.52	23.53	0.669
24.53	23.59	0.669
24.53	23.66	0.669
24.54	23.73	0.669
24.55	23.79	0.669
24.56	23.86	0.669
24.56	23.93	0.669
24.57	23.99	0.669
24.58	24.06	0.669
24.58	24.13	0.669
24.59	24.19	0.669
24.59	24.26	0.669
24.60	24.33	0.669
24.61	24.39	0.669
24.62	24.46	0.668
24.62	24.53	0.668
24.63	24.59	0.668
24.63	24.66	0.668
24.64	24.73	0.668
24.65	24.80	0.668
24.66	24.86	0.668
24.66	24.93	0.668
24.67	24.99	0.668
24.68	25.06	0.668
24.68	25.13	0.668
24.69	25.19	0.668
24.69	25.26	0.668
24.70	25.33	0.668
24.71	25.40	0.667
24.72	25.46	0.667
24.72	25.53	0.667
24.73	25.60	0.667
24.73	25.66	0.667
24.74	25.73	0.667
24.75	25.80	0.667
24.76	25.86	0.667
24.76	25.93	0.667
24.77	26.00	0.667
24.78	26.06	0.667
24.78	26.13	0.667
24.79	26.20	0.667
24.79	26.26	0.667
24.80	26.33	0.667
24.81	26.40	0.667
24.82	26.46	0.667
24.82	26.53	0.667
24.83	26.60	0.667
24.83	26.67	0.667
24.84	26.73	0.667
24.85	26.80	0.667
24.86	26.86	0.667
24.86	26.93	0.667
24.87	27.00	0.667
24.88	27.06	0.667
24.88	27.13	0.667
24.89	27.20	0.667
24.89	27.26	0.667
24.90	27.33	0.667
24.91	27.40	0.667
24.92	27.47	0.667
24.92	27.53	0.667
24.93	27.60	0.666
24.93	27.67	0.666
24.94	27.73	0.666
24.95	27.80	0.666
24.96	27.87	0.666
24.96	27.93	0.666
24.97	28.00	0.666
24.98	28.07	0.666
24.98	28.13	0.666
24.99	28.20	0.666
24.99	28.27	0.666
25.00	28.33	0.666
25.01	28.40	0.666
25.02	28.47	0.666
25.02	28.53	0.666
25.03	28.60	0.666
25.03	28.67	0.666
25.04	28.73	0.666
25.05	28.80	0.666
25.06	28.87	0.666
25.06	28.93	0.666
25.07	29.00	0.666
25.08	29.07	0.666
25.08	29.13	0.666
25.09	29.20	0.666
25.09	29.27	0.666
25.10	29.34	0.666
25.11	29.40	0.666
25.12	29.47	0.666
25.12	29.53	0.666
25.13	29.60	0.666
25.13	29.67	0.666
25.14	29.74	0.666
25.15	29.80	0.666
25.16	29.87	0.666
25.16	29.94	0.666
25.17	30.00	0.666
25.18	30.07	0.666
25.18	30.14	0.666
25.19	30.20	0.666
25.19	30.27	0.666
25.20	30.34	0.666
25.21	30.40	0.666
25.22	30.47	0.666
25.22	30.54	0.666
25.23	30.60	0.666
25.23	30.67	0.666
25.24	30.74	0.666
25.25	30.80	0.666
25.26	30.87	0.666
25.26	30.94	0.666
25.27	31.00	0.666
25.28	31.07	0.666
25.28	31.14	0.666
25.29	31.20	0.666
25.29	31.27	0.666
25.30	31.34	0.666
25.31	31.40	0.666
25.32	31.47	0.666
25.32	31.54	0.666
25.33	31.60	0.666
25.33	31.67	0.666
25.34	31.74	0.666
25.35	31.80	0.666
25.36	31.87	0.666
25.36	31.94	0.666
25.37	32.00	0.666
25.38	32.07	0.666
25.38	32.14	0.666
25.39	32.20	0.666
25.39	32.27	0.666
25.40	32.34	0.666
25.41	32.40	0.666
25.42	32.47	0.666
25.42	32.54	0.666
25.43	32.61	0.666
25.43	32.67	0.666
25.44	32.74	0.666
25.45	32.81	0.666
25.46	32.87	0.666
25.46	32.94	0.666
25.47	33.01	0.666
25.48	33.07	0.666
25.48	33.14	0.666
25.49	33.21	0.666
25.49	33.27	0.666
25.50	33.34	0.666
25.51	33.41	0.666
25.52	33.47	0.666
25.52	33.54	0.666
25.53	33.61	0.666
25.53	33.67	0.666
25.54	33.74	0.666
25.55	33.81	0.666
25.56	33.87	0.666
25.56	33.94	0.666
25.57	34.01	0.666
25.58	34.07	0.666
25.58	34.14	0.666
25.59	34.21	0.666
25.59	34.28	0.666
25.60	34.34	0.666
25.61	34.41	0.666
25.62	34.47	0.665
25.62	34.54	0.665
25.63	34.61	0.666
25.63	34.67	0.666
25.64	34.74	0.666
25.65	34.81	0.665
25.66	34.87	0.665
25.66	34.94	0.665
25.67	35.01	0.665
25.68	35.08	0.665
25.68	35.14	0.665
25.69	35.21	0.665
25.69	35.28	0.665
25.70	35.34	0.665
25.71	35.41	0.665
25.72	35.48	0.665
25.72	35.54	0.665
25.73	35.61	0.665
25.73	35.68	0.665
25.74	35.74	0.665
25.75	35.81	0.665
25.76	35.88	0.665
25.76	35.94	0.665
25.77	36.01	0.665
25.78	36.08	0.665
25.78	36.14	0.665
25.79	36.21	0.665
25.79	36.28	0.665
25.80	36.34	0.665
25.81	36.41	0.665
25.82	36.48	0.665
25.82	36.54	0.665
25.83	36.61	0.665
25.83	36.68	0.665
25.84	36.74	0.665
25.85	36.81	0.665
25.86	36.88	0.665
25.86	36.94	0.665
25.87	37.01	0.665
25.88	37.08	0.665
25.88	37.14	0.665
25.89	37.21	0.665
25.89	37.28	0.665
25.90	37.34	0.665
25.91	37.41	0.665
25.92	37.48	0.665
25.92	37.54	0.665
25.93	37.61	0.665
25.93	37.68	0.665
25.94	37.74
25.95	37.81
25.96	37.88
25.96	37.95
25.97	38.01
25.98	38.08
25.98	38.15
25.99
25.99