File: Data/2024_09_17_Naphthalene_DSC.txt
Filename	2024_09_17_Naphthalene_DSC
Instrument name	DSC2A-00468 (192.168.1.100)
Operator	CHM343
rundate	9/17/2024
Sample name	2024_09_17_Naphthalene_DSC
proceduresegments	Equilibrate 30.00 °C; Ramp 10.00 °C/min to 110.00 °C; Isothermal 1.0 min; Ramp 10.00 °C/min to 30.00 °C; Isothermal 1.0 min; Ramp 10.00 °C/min to 110.00 °C
[File Parameters]
Run date	9/17/2024 10:37:52 PM
Trios version	5.1.1.46572
Original File Name
Current File Name	C:\ProgramData\TA Instruments\TRIOS\Data\2024_09_17_Naphthalene_DSC.tri
[Procedure]
Procedure Name	CHM343_Fall2024_Naphthalene
Sample Name	2024_09_17_Naphthalene_DSC
Sample Mass	1.01 mg
Reference Sample Mass	0 mg
Pan Mass	53.87 mg
Pan Number	22
Reference Pan Mass	54 mg
Reference Pan Number	19
Pan Type	Aluminum
Comments	Naphthalene - Al Hermetic Sealed Pan, with ref Al pan.  ASU Online CHM343, Remote DSC experimental lab. Fall 2024.  Group Zoom Data Collection, Sept 17, 2024 from 9-11 pm.  TA Instruments DSC2500.
Project Name	Lab 4 - Fall 2024
Operator	CHM343
Test	Custom
Unload Max Temperature	30
Unload Min Temperature	30
Load Max Temperature	30
Load Min Temperature	30
Stop on Gas Flow Error	Yes
[Signal List]
Signal #1	Time (min)
Signal #2	Temperature (°C)
Signal #3	Heat Flow (mW)
Signal #4	Delta T (µV)
Signal #5	Delta Tzero (µV)
Signal #6	Tzero Temperature (°C)
Signal #7	Cell Purge (mL/min)
Signal #8	Heater Temp (°C)
Signal #9	Power Delivered (W)
Signal #10	Reference Junction Temperature (°C)
Signal #11	Flange Temperature (°C)
Signal #12	Heat Flow Phase (rad)
Signal #13	Total Heat Capacity (J/°C)
Signal #14	Heat Capacity (J/°C)
[Configuration]
Company Name	ASU
Instrument Name	DSC2A-00468
Instrument Type	DSC2500
Serial Number	DSC2A-00468
IP	192.168.1.100
Location of Instrument	MRRC
DisplayType	Unknown
Sample Interval 	0.1 s/pt
Selected Heat Flow	T4P
Exotherm Direction	Down
Cell Serial	DRC2-00792
Lid Type	Standard
Cooler	RCS 90
Leave Cooler on at End of Sequence	On
Gas 2	Nitrogen
Gas Selected	Channel 1
Flow Rate	50 mL/min
Secondary Purge	On
Licensed Heat Flow	Heat Flow T4P
Modulation Licensed	Yes
[Versions]
Common IDD Version	1
Cortex Version	VER 2.10.2.31
Driver	5.0.0.6
GDM Version	1.0.3.3
TouchscreenVersion	1.0.0.16145
FEP Version	1.2.1.21
FEP Bootloader	2.0.0.5
AutoSampler Version	2.1.1.26
Auto Sampler Bootloader	2.0.0.5
FCM Version	1.1.0.3
FCM Bootloader	2.0.0.5
[Experiment Logs]
Experiment Log Entry # 1	Equilibrate Segment 30 (C) Started
Experiment Log Entry # 3	Air Cool is off.
Experiment Log Entry # 5	Ramp Segment 10 C/min to 110 Started
Experiment Log Entry # 7	Isothermal Segment 1 min started
Experiment Log Entry # 9	Ramp Segment 10 C/min to 30 Started
Experiment Log Entry # 11	Isothermal Segment 1 min started
Experiment Log Entry # 13	Ramp Segment 10 C/min to 110 Started
[Method Log]
Method Log Entry # 1	Equilibrate 30 °C
Method Log Entry # 2	(Ramp 80928) Ramp 10 °C/minute to 110 °C
Method Log Entry # 3	Isothermal 1 minutes
Method Log Entry # 4	(Ramp 80930) Ramp 10 °C/minute to 30 °C
Method Log Entry # 5	Isothermal 1 minutes
Method Log Entry # 6	(Ramp 80932) Ramp 10 °C/minute to 110 °C
Cell Serial	DRC2-00792
[T1 Calibration]
Slope	-0.008529666
Offset	9.636258
Initial Temperature	98.23
GUID	f8bfdadc-4977-4fdf-ba6d-0ba9134940c3
[TZero Calibration]
Date Applied	11/29/2022 4:06:13 PM
Description	From -89.059 °C to 396.009 °C at 20.000°C/min
Gas Type	Nitrogen
Pan Type	None
Source Files 1	C:\Users\yargerlab\Desktop\DSC Data\General\TZero_calibration_11_29_22_2nd(2).tri
Source Files 2	C:\Users\yargerlab\Desktop\DSC Data\General\TZero_calibration_11_29_22_2nd(3).tri
Delta T Offset	13.05235
Delta T Slope	-0.007271007
Delta T0 Offset	-13.69128
Delta T0 Slope	0.06063341
[Temperature Calibration]
Date Applied	11/29/2022 7:12:28 PM
Description	From 106.590 °C to 186.590 °C at 10.000°C/min
Gas Type	Nitrogen
Pan Type	Tzero Aluminum Hermetic
Source Files 1	C:\Users\yargerlab\Desktop\DSC Data\General\Indium(6).tri
Measured 1	157.391
Known 1	156.598
[Cell Constant Calibration]
Date Applied	11/29/2022 7:12:29 PM
Description	From 106.590 °C to 186.590 °C at 10.000°C/min
Gas Type	Nitrogen
Pan Type	Tzero Aluminum Hermetic
Source Files 1	C:\Users\yargerlab\Desktop\DSC Data\General\Indium(6).tri
T4P KCell	1.006051
Onset Slope	63.26126 mW/°C
[Direct Cp Calibration]
Date Applied	11/30/2022 11:04:51 AM
Description	From -79.983 °C to 298.409 °C at 10.000°C/min
Gas Type	Nitrogen
Pan Type	Tzero Aluminum Hermetic
Source Files 1	C:\Users\yargerlab\Desktop\DSC Data\General\Sapphire_Heat_Capacity_11_30_22.tri
[Rev Cp Calibration]
Date Applied	11/30/2022 1:58:51 PM
Description	From -79.996 °C to 292.812 °C at 3.000°C/min
Gas Type	Nitrogen
Pan Type	Tzero Aluminum Hermetic
Source Files 1	C:\Users\yargerlab\Desktop\DSC Data\General\Sapphire_MDSC_Calibration_11_30_22.tri
[step]
Ramp 10.00 °C/min to 110.00 °C
Time	Temperature	Heat Flow (Normalized)
min	°C	W/g
0.00	30.07	-0.119
0.01	30.07	-0.118
0.01	30.07	-0.118
0.02	30.07	-0.117
0.03	30.08	-0.117
0.03	30.08	-0.116
0.04	30.08	-0.116
0.05	30.08	-0.116
0.05	30.09	-0.116
0.06	30.10	-0.116
0.07	30.11	-0.120
0.07	30.12	-0.135
0.08	30.13	-0.160
0.09	30.15	-0.184
0.09	30.17	-0.204
0.10	30.20	-0.224
0.11	30.23	-0.232
0.11	30.26	-0.237
0.12	30.29	-0.239
0.13	30.32	-0.237
0.13	30.36	-0.230
0.14	30.40	-0.226
0.15	30.45	-0.216
0.15	30.49	-0.187
0.16	30.54	-0.140
0.17	30.59	-0.101
0.17	30.64	-0.068
0.18	30.69	-0.036
0.19	30.74	-0.012
0.19	30.79	0.012
0.20	30.84	0.034
0.21	30.90	0.054
0.21	30.95	0.081
0.22	31.01	0.111
0.23	31.06	0.123
0.23	31.12	0.139
0.24	31.18	0.153
0.25	31.23	0.160
0.25	31.29	0.178
0.26	31.35	0.195
0.27	31.41	0.202
0.27	31.47	0.212
0.28	31.53	0.224
0.29	31.59	0.232
0.29	31.65	0.240
0.30	31.71	0.248
0.31	31.77	0.260
0.31	31.84	0.277
0.32	31.90	0.283
0.33	31.96	0.285
0.33	32.02	0.296
0.34	32.08	0.303
0.35	32.15	0.308
0.35	32.21	0.316
0.36	32.27	0.326
0.37	32.34	0.330
0.37	32.40	0.336
0.38	32.47	0.341
0.39	32.53	0.343
0.39	32.59	0.346
0.40	32.66	0.350
0.41	32.72	0.355
0.41	32.79	0.359
0.42	32.85	0.362
0.43	32.92	0.368
0.43	32.98	0.371
0.44	33.05	0.373
0.45	33.11	0.374
0.45	33.18	0.375
0.46	33.24	0.378
0.47	33.30	0.381
0.47	33.37	0.381
0.48	33.43	0.384
0.49	33.50	0.387
0.49	33.57	0.391
0.50	33.63	0.393
0.51	33.70	0.394
0.51	33.76	0.396
0.52	33.83	0.397
0.53	33.89	0.398
0.53	33.96	0.399
0.54	34.02	0.402
0.55	34.09	0.403
0.55	34.16	0.404
0.56	34.22	0.405
0.57	34.29	0.405
0.57	34.35	0.406
0.58	34.42	0.408
0.59	34.48	0.409
0.59	34.55	0.410
0.60	34.61	0.410
0.61	34.68	0.411
0.61	34.75	0.412
0.62	34.81	0.412
0.63	34.88	0.413
0.63	34.94	0.414
0.64	35.01	0.414
0.65	35.07	0.415
0.65	35.14	0.416
0.66	35.21	0.417
0.67	35.27	0.417
0.67	35.34	0.418
0.68	35.40	0.419
0.69	35.47	0.419
0.69	35.54	0.420
0.70	35.60	0.420
0.71	35.67	0.422
0.71	35.73	0.422
0.72	35.80	0.423
0.73	35.87	0.424
0.73	35.93	0.424
0.74	36.00	0.425
0.75	36.06	0.425
0.75	36.13	0.426
0.76	36.20	0.426
0.77	36.26	0.427
0.77	36.33	0.428
0.78	36.39	0.428
0.79	36.46	0.429
0.79	36.53	0.429
0.80	36.59	0.430
0.81	36.66	0.430
0.81	36.72	0.431
0.82	36.79	0.431
0.83	36.86	0.432
0.83	36.92	0.432
0.84	36.99	0.432
0.85	37.05	0.433
0.85	37.12	0.434
0.86	37.19	0.434
0.87	37.25	0.435
0.87	37.32	0.435
0.88	37.39	0.436
0.89	37.45	0.436
0.89	37.52	0.437
0.90	37.58	0.437
0.91	37.65	0.437
0.91	37.72	0.438
0.92	37.78	0.438
0.93	37.85	0.439
0.93	37.92	0.439
0.94	37.98	0.439
0.95	38.05	0.440
0.95	38.11	0.440
0.96	38.18	0.441
0.97	38.25	0.441
0.97	38.32	0.441
0.98	38.38	0.442
0.99	38.45	0.442
0.99	38.51	0.442
1.00	38.58	0.443
1.01	38.65	0.443
1.01	38.71	0.444
1.02	38.78	0.444
1.03	38.85	0.444
1.03	38.91	0.445
1.04	38.98	0.445
1.05	39.04	0.445
1.05	39.11	0.446
1.06	39.18	0.446
1.07	39.24	0.446
1.07	39.31	0.447
1.08	39.38	0.447
1.09	39.44	0.447
1.09	39.51	0.448
1.10	39.58	0.448
1.11	39.64	0.448
1.11	39.71	0.448
1.12	39.78	0.449
1.13	39.84	0.449
1.13	39.91	0.449
1.14	39.98	0.450
1.15	40.04	0.450
1.15	40.11	0.450
1.16	40.17	0.450
1.17	40.24	0.451
1.17	40.31	0.451
1.18	40.37	0.451
1.19	40.44	0.451
1.19	40.51	0.452
1.20	40.57	0.452
1.21	40.64	0.452
1.21	40.71	0.453
1.22	40.77	0.453
1.23	40.84	0.453
1.23	40.91	0.453
1.24	40.97	0.453
1.25	41.04	0.454
1.25	41.11	0.454
1.26	41.17	0.454
1.27	41.24	0.454
1.27	41.30	0.454
1.28	41.37	0.455
1.29	41.44	0.455
1.29	41.50	0.455
1.30	41.57	0.455
1.31	41.64	0.456
1.31	41.70	0.456
1.32	41.77	0.456
1.33	41.84	0.456
1.33	41.90	0.456
1.34	41.97	0.456
1.35	42.04	0.456
1.35	42.10	0.457
1.36	42.17	0.457
1.37	42.24	0.457
1.37	42.30	0.457
1.38	42.37	0.457
1.39	42.44	0.457
1.39	42.50	0.457
1.40	42.57	0.458
1.41	42.64	0.458
1.41	42.70	0.458
1.42	42.77	0.458
1.43	42.84	0.458
1.43	42.90	0.458
1.44	42.97	0.458
1.45	43.04	0.458
1.45	43.10	0.458
1.46	43.17	0.459
1.47	43.24	0.459
1.47	43.30	0.459
1.48	43.37	0.459
1.49	43.44	0.459
1.49	43.50	0.459
1.50	43.57	0.459
1.51	43.64	0.460
1.51	43.70	0.460
1.52	43.77	0.460
1.53	43.83	0.460
1.53	43.90	0.460
1.54	43.97	0.460
1.55	44.03	0.460
1.55	44.10	0.460
1.56	44.17	0.460
1.57	44.23	0.461
1.57	44.30	0.461
1.58	44.37	0.461
1.59	44.43	0.461
1.59	44.50	0.461
1.60	44.57	0.461
1.61	44.63	0.461
1.61	44.70	0.461
1.62	44.77	0.461
1.63	44.84	0.461
1.63	44.90	0.461
1.64	44.97	0.461
1.65	45.03	0.461
1.65	45.10	0.462
1.66	45.17	0.462
1.67	45.23	0.462
1.67	45.30	0.462
1.68	45.37	0.462
1.69	45.43	0.462
1.69	45.50	0.462
1.70	45.57	0.462
1.71	45.63	0.462
1.71	45.70	0.462
1.72	45.77	0.462
1.73	45.83	0.462
1.73	45.90	0.462
1.74	45.97	0.462
1.75	46.04	0.463
1.75	46.10	0.463
1.76	46.17	0.463
1.77	46.23	0.463
1.77	46.30	0.463
1.78	46.37	0.463
1.79	46.43	0.464
1.79	46.50	0.464
1.80	46.57	0.464
1.81	46.63	0.464
1.81	46.70	0.464
1.82	46.77	0.464
1.83	46.83	0.464
1.83	46.90	0.464
1.84	46.97	0.464
1.85	47.03	0.464
1.85	47.10	0.464
1.86	47.17	0.464
1.87	47.23	0.464
1.87	47.30	0.464
1.88	47.37	0.464
1.89	47.43	0.464
1.89	47.50	0.464
1.90	47.57	0.464
1.91	47.63	0.464
1.91	47.70	0.464
1.92	47.77	0.465
1.93	47.83	0.465
1.93	47.90	0.465
1.94	47.97	0.465
1.95	48.03	0.465
1.95	48.10	0.465
1.96	48.17	0.465
1.97	48.23	0.465
1.97	48.30	0.465
1.98	48.37	0.465
1.99	48.43	0.465
1.99	48.50	0.465
2.00	48.57	0.465
2.01	48.63	0.465
2.01	48.70	0.465
2.02	48.77	0.465
2.03	48.83	0.465
2.03	48.90	0.465
2.04	48.97	0.465
2.05	49.03	0.466
2.05	49.10	0.466
2.06	49.17	0.466
2.07	49.24	0.466
2.07	49.30	0.466
2.08	49.37	0.466
2.09	49.43	0.466
2.09	49.50	0.466
2.10	49.57	0.466
2.11	49.63	0.467
2.11	49.70	0.467
2.12	49.77	0.467
2.13	49.83	0.467
2.13	49.90	0.467
2.14	49.97	0.467
2.15	50.03	0.467
2.15	50.10	0.467
2.16	50.17	0.467
2.17	50.23	0.467
2.17	50.30	0.467
2.18	50.37	0.467
2.19	50.44	0.467
2.19	50.50	0.468
2.20	50.57	0.468
2.21	50.63	0.467
2.21	50.70	0.467
2.22	50.77	0.467
2.23	50.83	0.467
2.23	50.90	0.468
2.24	50.97	0.468
2.25	51.04	0.468
2.25	51.10	0.468
2.26	51.17	0.468
2.27	51.24	0.468
2.27	51.30	0.468
2.28	51.37	0.468
2.29	51.43	0.468
2.29	51.50	0.468
2.30	51.57	0.468
2.31	51.64	0.468
2.31	51.70	0.468
2.32	51.77	0.468
2.33	51.83	0.468
2.33	51.90	0.468
2.34	51.97	0.468
2.35	52.04	0.468
2.35	52.10	0.468
2.36	52.17	0.468
2.37	52.24	0.468
2.37	52.30	0.468
2.38	52.37	0.468
2.39	52.43	0.469
2.39	52.50	0.469
2.40	52.57	0.469
2.41	52.64	0.469
2.41	52.70	0.469
2.42	52.77	0.469
2.43	52.83	0.469
2.43	52.90	0.469
2.44	52.97	0.469
2.45	53.04	0.469
2.45	53.10	0.469
2.46	53.17	0.469
2.47	53.24	0.469
2.47	53.30	0.469
2.48	53.37	0.469
2.49	53.43	0.469
2.49	53.50	0.469
2.50	53.57	0.469
2.51	53.63	0.469
2.51	53.70	0.469
2.52	53.77	0.470
2.53	53.84	0.470
2.53	53.90	0.469
2.54	53.97	0.470
2.55	54.04	0.470
2.55	54.10	0.470
2.56	54.17	0.470
2.57	54.23	0.470
2.57	54.30	0.470
2.58	54.37	0.470
2.59	54.44	0.470
2.59	54.50	0.470
2.60	54.57	0.470
2.61	54.64	0.470
2.61	54.70	0.470
2.62	54.77	0.471
2.63	54.84	0.471
2.63	54.90	0.471
2.64	54.97	0.471
2.65	55.04	0.471
2.65	55.10	0.471
2.66	55.17	0.471
2.67	55.24	0.471
2.67	55.30	0.471
2.68	55.37	0.471
2.69	55.44	0.471
2.69	55.50	0.471
2.70	55.57	0.472
2.71	55.64	0.472
2.71	55.70	0.472
2.72	55.77	0.472
2.73	55.84	0.472
2.73	55.90	0.472
2.74	55.97	0.472
2.75	56.04	0.472
2.75	56.10	0.472
2.76	56.17	0.472
2.77	56.24	0.472
2.77	56.30	0.472
2.78	56.37	0.472
2.79	56.44	0.473
2.79	56.50	0.473
2.80	56.57	0.473
2.81	56.64	0.473
2.81	56.71	0.473
2.82	56.77	0.473
2.83	56.84	0.473
2.83	56.90	0.473
2.84	56.97	0.473
2.85	57.04	0.473
2.85	57.10	0.473
2.86	57.17	0.474
2.87	57.24	0.474
2.87	57.31	0.474
2.88	57.37	0.474
2.89	57.44	0.474
2.89	57.51	0.474
2.90	57.57	0.474
2.91	57.64	0.474
2.91	57.71	0.474
2.92	57.77	0.474
2.93	57.84	0.475
2.93	57.91	0.475
2.94	57.97	0.474
2.95	58.04	0.474
2.95	58.11	0.475
2.96	58.17	0.475
2.97	58.24	0.475
2.97	58.31	0.475
2.98	58.37	0.475
2.99	58.44	0.475
2.99	58.51	0.475
3.00	58.57	0.475
3.01	58.64	0.475
3.01	58.71	0.475
3.02	58.77	0.475
3.03	58.84	0.475
3.03	58.91	0.476
3.04	58.97	0.476
3.05	59.04	0.476
3.05	59.11	0.476
3.06	59.17	0.476
3.07	59.24	0.476
3.07	59.31	0.476
3.08	59.37	0.476
3.09	59.44	0.476
3.09	59.51	0.476
3.10	59.57	0.476
3.11	59.64	0.476
3.11	59.71	0.477
3.12	59.77	0.477
3.13	59.84	0.477
3.13	59.91	0.477
3.14	59.97	0.477
3.15	60.04	0.477
3.15	60.11	0.477
3.16	60.18	0.477
3.17	60.24	0.477
3.17	60.31	0.477
3.18	60.38	0.477
3.19	60.44	0.477
3.19	60.51	0.478
3.20	60.58	0.478
3.21	60.64	0.478
3.21	60.71	0.478
3.22	60.78	0.478
3.23	60.84	0.479
3.23	60.91	0.479
3.24	60.98	0.479
3.25	61.04	0.479
3.25	61.11	0.479
3.26	61.18	0.479
3.27	61.24	0.479
3.27	61.31	0.480
3.28	61.38	0.480
3.29	61.44	0.480
3.29	61.51	0.480
3.30	61.58	0.480
3.31	61.64	0.480
3.31	61.71	0.480
3.32	61.78	0.480
3.33	61.84	0.480
3.33	61.91	0.481
3.34	61.98	0.481
3.35	62.04	0.481
3.35	62.11	0.481
3.36	62.18	0.481
3.37	62.24	0.481
3.37	62.31	0.481
3.38	62.38	0.482
3.39	62.44	0.482
3.39	62.51	0.482
3.40	62.58	0.482
3.41	62.64	0.482
3.41	62.71	0.482
3.42	62.78	0.482
3.43	62.84	0.482
3.43	62.91	0.482
3.44	62.98	0.482
3.45	63.04	0.482
3.45	63.11	0.482
3.46	63.18	0.482
3.47	63.24	0.482
3.47	63.31	0.483
3.48	63.38	0.483
3.49	63.44	0.483
3.49	63.51	0.483
3.50	63.58	0.483
3.51	63.64	0.483
3.51	63.71	0.483
3.52	63.78	0.484
3.53	63.84	0.484
3.53	63.91	0.484
3.54	63.98	0.484
3.55	64.04	0.484
3.55	64.11	0.484
3.56	64.18	0.484
3.57	64.24	0.484
3.57	64.31	0.484
3.58	64.38	0.484
3.59	64.44	0.484
3.59	64.51	0.485
3.60	64.58	0.486
3.61	64.64	0.486
3.61	64.71	0.486
3.62	64.78	0.486
3.63	64.84	0.486
3.63	64.91	0.486
3.64	64.98	0.486
3.65	65.04	0.487
3.65	65.11	0.487
3.66	65.18	0.487
3.67	65.24	0.487
3.67	65.31	0.487
3.68	65.38	0.487
3.69	65.44	0.487
3.69	65.51	0.487
3.70	65.58	0.487
3.71	65.65	0.488
3.71	65.71	0.488
3.72	65.78	0.488
3.73	65.85	0.488
3.73	65.91	0.488
3.74	65.98	0.488
3.75	66.05	0.488
3.75	66.11	0.489
3.76	66.18	0.489
3.77	66.24	0.489
3.77	66.31	0.489
3.78	66.38	0.489
3.79	66.45	0.489
3.79	66.51	0.489
3.80	66.58	0.490
3.81	66.65	0.490
3.81	66.71	0.490
3.82	66.78	0.490
3.83	66.85	0.490
3.83	66.91	0.490
3.84	66.98	0.491
3.85	67.05	0.491
3.85	67.11	0.491
3.86	67.18	0.491
3.87	67.25	0.491
3.87	67.31	0.491
3.88	67.38	0.491
3.89	67.45	0.492
3.89	67.51	0.492
3.90	67.58	0.492
3.91	67.65	0.492
3.91	67.71	0.492
3.92	67.78	0.492
3.93	67.85	0.493
3.93	67.91	0.493
3.94	67.98	0.493
3.95	68.05	0.493
3.95	68.11	0.493
3.96	68.18	0.494
3.97	68.25	0.494
3.97	68.31	0.494
3.98	68.38	0.494
3.99	68.45	0.494
3.99	68.51	0.494
4.00	68.58	0.495
4.01	68.65	0.495
4.01	68.71	0.495
4.02	68.78	0.495
4.03	68.85	0.495
4.03	68.91	0.496
4.04	68.98	0.496
4.05	69.05	0.496
4.05	69.11	0.496
4.06	69.18	0.496
4.07	69.25	0.496
4.07	69.31	0.496
4.08	69.38	0.497
4.09	69.45	0.497
4.09	69.51	0.497
4.10	69.58	0.497
4.11	69.65	0.497
4.11	69.71	0.497
4.12	69.78	0.498
4.13	69.85	0.498
4.13	69.91	0.498
4.14	69.98	0.498
4.15	70.05	0.498
4.15	70.11	0.498
4.16	70.18	0.498
4.17	70.25	0.499
4.17	70.31	0.499
4.18	70.38	0.499
4.19	70.45	0.499
4.19	70.51	0.499
4.20	70.58	0.500
4.21	70.65	0.500
4.21	70.71	0.500
4.22	70.78	0.500
4.23	70.85	0.500
4.23	70.91	0.500
4.24	70.98	0.501
4.25	71.05	0.501
4.25	71.11	0.501
4.26	71.18	0.501
4.27	71.25	0.502
4.27	71.32	0.502
4.28	71.38	0.502
4.29	71.45	0.502
4.29	71.52	0.502
4.30	71.58	0.502
4.31	71.65	0.503
4.31	71.71	0.503
4.32	71.78	0.503
4.33	71.85	0.503
4.33	71.92	0.503
4.34	71.98	0.504
4.35	72.05	0.504
4.35	72.12	0.504
4.36	72.18	0.504
4.37	72.25	0.504
4.37	72.32	0.505
4.38	72.38	0.505
4.39	72.45	0.505
4.39	72.52	0.505
4.40	72.58	0.506
4.41	72.65	0.506
4.41	72.72	0.506
4.42	72.78	0.506
4.43	72.85	0.507
4.43	72.92	0.507
4.44	72.98	0.507
4.45	73.05	0.507
4.45	73.12	0.508
4.46	73.18	0.508
4.47	73.25	0.508
4.47	73.32	0.508
4.48	73.38	0.508
4.49	73.45	0.509
4.49	73.52	0.509
4.50	73.58	0.509
4.51	73.65	0.510
4.51	73.72	0.510
4.52	73.78	0.510
4.53	73.85	0.510
4.53	73.92	0.511
4.54	73.98	0.511
4.55	74.05	0.511
4.55	74.12	0.511
4.56	74.18	0.512
4.57	74.25	0.512
4.57	74.32	0.512
4.58	74.38	0.512
4.59	74.45	0.512
4.59	74.52	0.513
4.60	74.58	0.513
4.61	74.65	0.513
4.61	74.72	0.513
4.62	74.78	0.513
4.63	74.85	0.514
4.63	74.92	0.514
4.64	74.98	0.514
4.65	75.05	0.514
4.65	75.12	0.515
4.66	75.19	0.515
4.67	75.25	0.515
4.67	75.32	0.516
4.68	75.39	0.516
4.69	75.45	0.516
4.69	75.52	0.517
4.70	75.59	0.517
4.71	75.65	0.517
4.71	75.72	0.517
4.72	75.79	0.517
4.73	75.85	0.518
4.73	75.92	0.518
4.74	75.99	0.518
4.75	76.05	0.519
4.75	76.12	0.519
4.76	76.19	0.519
4.77	76.25	0.519
4.77	76.32	0.520
4.78	76.39	0.520
4.79	76.45	0.520
4.79	76.52	0.521
4.80	76.58	0.521
4.81	76.65	0.521
4.81	76.72	0.522
4.82	76.79	0.522
4.83	76.85	0.522
4.83	76.92	0.522
4.84	76.98	0.522
4.85	77.05	0.523
4.85	77.12	0.523
4.86	77.19	0.523
4.87	77.25	0.524
4.87	77.32	0.524
4.88	77.39	0.524
4.89	77.45	0.524
4.89	77.52	0.525
4.90	77.59	0.525
4.91	77.65	0.525
4.91	77.72	0.525
4.92	77.79	0.526
4.93	77.85	0.526
4.93	77.92	0.526
4.94	77.99	0.527
4.95	78.05	0.527
4.95	78.12	0.527
4.96	78.19	0.528
4.97	78.25	0.528
4.97	78.32	0.528
4.98	78.39	0.529
4.99	78.45	0.529
4.99	78.52	0.530
5.00	78.59	0.530
5.01	78.65	0.530
5.01	78.72	0.531
5.02	78.79	0.531
5.03	78.85	0.532
5.03	78.92	0.534
5.04	78.99	0.534
5.05	79.05	0.535
5.05	79.12	0.537
5.06	79.19	0.539
5.07	79.25	0.544
5.07	79.32	0.571
5.08	79.39	0.618
5.09	79.45	0.710
5.09	79.52	0.892
5.10	79.58	1.296
5.11	79.64	2.096
5.11	79.69	3.331
5.12	79.73	4.628
5.13	79.77	5.558
5.13	79.80	6.173
5.14	79.84	6.696
5.15	79.87	7.273
5.15	79.91	7.761
5.16	79.94	7.993
5.17	79.98	8.209
5.17	80.02	8.584
5.18	80.06	8.986
5.19	80.10	9.005
5.19	80.14	9.009
5.20	80.19	9.382
5.21	80.23	9.580
5.21	80.28	9.179
5.22	80.34	8.584
5.23	80.40	8.619
5.23	80.45	8.992
5.24	80.51	9.033
5.25	80.57	8.835
5.25	80.63	8.694
5.26	80.69	8.588
5.27	80.76	8.439
5.27	80.82	8.269
5.28	80.89	8.047
5.29	80.96	7.704
5.29	81.03	7.142
5.30	81.11	6.496
5.31	81.19	5.863
5.31	81.27	5.121
5.32	81.36	4.223
5.33	81.45	3.405
5.33	81.55	2.847
5.34	81.64	2.541
5.35	81.74	2.373
5.35	81.83	2.177
5.36	81.91	2.042
5.37	82.00	1.940
5.37	82.09	1.833
5.38	82.17	1.729
5.39	82.26	1.637
5.39	82.34	1.562
5.40	82.42	1.482
5.41	82.50	1.404
5.41	82.58	1.344
5.42	82.65	1.286
5.43	82.73	1.230
5.43	82.80	1.175
5.44	82.88	1.134
5.45	82.96	1.090
5.45	83.03	1.047
5.46	83.10	1.010
5.47	83.18	0.973
5.47	83.25	0.939
5.48	83.32	0.908
5.49	83.39	0.883
5.49	83.47	0.856
5.50	83.54	0.838
5.51	83.61	0.812
5.51	83.68	0.790
5.52	83.75	0.774
5.53	83.82	0.756
5.53	83.89	0.742
5.54	83.96	0.724
5.55	84.02	0.712
5.55	84.09	0.697
5.56	84.16	0.687
5.57	84.23	0.674
5.57	84.30	0.665
5.58	84.37	0.657
5.59	84.44	0.646
5.59	84.51	0.644
5.60	84.57	0.640
5.61	84.64	0.630
5.61	84.71	0.625
5.62	84.78	0.619
5.63	84.85	0.610
5.63	84.91	0.607
5.64	84.98	0.605
5.65	85.05	0.603
5.65	85.12	0.601
5.66	85.18	0.597
5.67	85.25	0.592
5.67	85.32	0.590
5.68	85.38	0.589
5.69	85.45	0.586
5.69	85.52	0.585
5.70	85.59	0.584
5.71	85.65	0.583
5.71	85.72	0.582
5.72	85.79	0.581
5.73	85.85	0.580
5.73	85.92	0.578
5.74	85.99	0.578
5.75	86.06	0.577
5.75	86.12	0.575
5.76	86.19	0.575
5.77	86.26	0.574
5.77	86.32	0.573
5.78	86.39	0.573
5.79	86.46	0.572
5.79	86.52	0.572
5.80	86.59	0.571
5.81	86.66	0.570
5.81	86.72	0.570
5.82	86.79	0.569
5.83	86.86	0.569
5.83	86.92	0.568
5.84	86.99	0.568
5.85	87.06	0.568
5.85	87.12	0.567
5.86	87.19	0.567
5.87	87.26	0.566
5.87	87.33	0.566
5.88	87.39	0.566
5.89	87.46	0.565
5.89	87.52	0.565
5.90	87.59	0.564
5.91	87.66	0.564
5.91	87.73	0.564
5.92	87.79	0.563
5.93	87.86	0.563
5.93	87.93	0.563
5.94	87.99	0.563
5.95	88.06	0.562
5.95	88.13	0.562
5.96	88.19	0.562
5.97	88.26	0.562
5.97	88.33	0.562
5.98	88.39	0.561
5.99	88.46	0.561
5.99	88.53	0.561
6.00	88.59	0.561
6.01	88.66	0.561
6.01	88.73	0.561
6.02	88.79	0.560
6.03	88.86	0.560
6.03	88.93	0.560
6.04	88.99	0.560
6.05	89.06	0.560
6.05	89.13	0.560
6.06	89.19	0.560
6.07	89.26	0.560
6.07	89.33	0.560
6.08	89.39	0.560
6.09	89.46	0.560
6.09	89.53	0.560
6.10	89.59	0.560
6.11	89.66	0.560
6.11	89.73	0.560
6.12	89.79	0.560
6.13	89.86	0.560
6.13	89.93	0.560
6.14	89.99	0.560
6.15	90.06	0.560
6.15	90.13	0.560
6.16	90.19	0.560
6.17	90.26	0.560
6.17	90.33	0.560
6.18	90.39	0.560
6.19	90.46	0.561
6.19	90.53	0.561
6.20	90.59	0.561
6.21	90.66	0.561
6.21	90.73	0.561
6.22	90.79	0.561
6.23	90.86	0.561
6.23	90.93	0.561
6.24	90.99	0.561
6.25	91.06	0.561
6.25	91.13	0.561
6.26	91.19	0.561
6.27	91.26	0.562
6.27	91.33	0.562
6.28	91.39	0.562
6.29	91.46	0.562
6.29	91.53	0.562
6.30	91.59	0.562
6.31	91.66	0.563
6.31	91.73	0.563
6.32	91.79	0.563
6.33	91.86	0.563
6.33	91.93	0.563
6.34	91.99	0.563
6.35	92.06	0.564
6.35	92.13	0.564
6.36	92.19	0.564
6.37	92.26	0.564
6.37	92.33	0.564
6.38	92.39	0.564
6.39	92.46	0.565
6.39	92.53	0.565
6.40	92.59	0.565
6.41	92.66	0.566
6.41	92.73	0.566
6.42	92.80	0.566
6.43	92.86	0.566
6.43	92.93	0.566
6.44	93.00	0.566
6.45	93.06	0.567
6.45	93.13	0.567
6.46	93.19	0.567
6.47	93.26	0.568
6.47	93.33	0.568
6.48	93.40	0.568
6.49	93.46	0.568
6.49	93.53	0.568
6.50	93.60	0.569
6.51	93.66	0.569
6.51	93.73	0.569
6.52	93.80	0.569
6.53	93.86	0.570
6.53	93.93	0.570
6.54	94.00	0.570
6.55	94.06	0.570
6.55	94.13	0.571
6.56	94.19	0.571
6.57	94.26	0.571
6.57	94.33	0.571
6.58	94.39	0.572
6.59	94.46	0.572
6.59	94.53	0.572
6.60	94.59	0.573
6.61	94.66	0.573
6.61	94.73	0.573
6.62	94.79	0.573
6.63	94.86	0.573
6.63	94.93	0.574
6.64	95.00	0.574
6.65	95.06	0.574
6.65	95.13	0.574
6.66	95.20	0.575
6.67	95.26	0.575
6.67	95.33	0.575
6.68	95.40	0.575
6.69	95.46	0.575
6.69	95.53	0.576
6.70	95.60	0.576
6.71	95.66	0.576
6.71	95.73	0.577
6.72	95.80	0.577
6.73	95.86	0.577
6.73	95.93	0.577
6.74	96.00	0.578
6.75	96.06	0.578
6.75	96.13	0.578
6.76	96.20	0.579
6.77	96.26	0.579
6.77	96.33	0.579
6.78	96.40	0.579
6.79	96.46	0.580
6.79	96.53	0.580
6.80	96.60	0.580
6.81	96.66	0.581
6.81	96.73	0.581
6.82	96.80	0.581
6.83	96.86	0.582
6.83	96.93	0.582
6.84	97.00	0.582
6.85	97.06	0.582
6.85	97.13	0.583
6.86	97.20	0.583
6.87	97.26	0.583
6.87	97.33	0.584
6.88	97.40	0.584
6.89	97.46	0.584
6.89	97.53	0.585
6.90	97.60	0.585
6.91	97.66	0.585
6.91	97.73	0.586
6.92	97.80	0.586
6.93	97.86	0.586
6.93	97.93	0.586
6.94	98.00	0.587
6.95	98.06	0.587
6.95	98.13	0.587
6.96	98.20	0.587
6.97	98.26	0.588
6.97	98.33	0.588
6.98	98.40	0.588
6.99	98.46	0.588
6.99	98.53	0.589
7.00	98.60	0.589
7.01	98.66	0.589
7.01	98.73	0.590
7.02	98.80	0.590
7.03	98.86	0.590
7.03	98.93	0.590
7.04	99.00	0.591
7.05	99.07	0.591
7.05	99.13	0.591
7.06	99.20	0.592
7.07	99.27	0.592
7.07	99.33	0.592
7.08	99.40	0.593
7.09	99.47	0.593
7.09	99.53	0.594
7.10	99.60	0.594
7.11	99.66	0.594
7.11	99.73	0.594
7.12	99.80	0.595
7.13	99.87	0.595
7.13	99.93	0.595
7.14	100.00	0.596
7.15	100.06	0.596
7.15	100.13	0.596
7.16	100.20	0.596
7.17	100.27	0.597
7.17	100.33	0.597
7.18	100.40	0.597
7.19	100.47	0.598
7.19	100.53	0.598
7.20	100.60	0.598
7.21	100.67	0.599
7.21	100.73	0.599
7.22	100.80	0.599
7.23	100.87	0.600
7.23	100.93	0.600
7.24	101.00	0.600
7.25	101.07	0.600
7.25	101.13	0.601
7.26	101.20	0.602
7.27	101.27	0.602
7.27	101.33	0.602
7.28	101.40	0.602
7.29	101.47	0.603
7.29	101.53	0.603
7.30	101.60	0.603
7.31	101.67	0.604
7.31	101.73	0.604
7.32	101.80	0.605
7.33	101.87	0.605
7.33	101.93	0.605
7.34	102.00	0.606
7.35	102.07	0.606
7.35	102.13	0.606
7.36	102.20	0.607
7.37	102.27	0.607
7.37	102.33	0.607
7.38	102.40	0.608
7.39	102.47	0.608
7.39	102.53	0.609
7.40	102.60	0.609
7.41	102.67	0.609
7.41	102.73	0.610
7.42	102.80	0.610
7.43	102.87	0.610
7.43	102.93	0.611
7.44	103.00	0.611
7.45	103.07	0.612
7.45	103.13	0.612
7.46	103.20	0.612
7.47	103.27	0.613
7.47	103.33	0.613
7.48	103.40	0.613
7.49	103.47	0.614
7.49	103.53	0.614
7.50	103.60	0.614
7.51	103.67	0.615
7.51	103.73	0.615
7.52	103.80	0.616
7.53	103.87	0.616
7.53	103.93	0.616
7.54	104.00	0.616
7.55	104.07	0.617
7.55	104.13	0.617
7.56	104.20	0.617
7.57	104.27	0.618
7.57	104.33	0.618
7.58	104.40	0.619
7.59	104.47	0.619
7.59	104.53	0.619
7.60	104.60	0.620
7.61	104.67	0.620
7.61	104.73	0.620
7.62	104.80	0.621
7.63	104.87	0.621
7.63	104.93	0.622
7.64	105.00	0.622
7.65	105.07	0.622
7.65	105.13	0.623
7.66	105.20	0.623
7.67	105.27	0.624
7.67	105.33	0.624
7.68	105.40	0.624
7.69	105.47	0.625
7.69	105.53	0.625
7.70	105.60	0.625
7.71	105.67	0.626
7.71	105.73	0.626
7.72	105.80	0.626
7.73	105.87	0.627
7.73	105.93	0.628
7.74	106.00	0.628
7.75	106.07	0.629
7.75	106.13	0.629
7.76	106.20	0.630
7.77	106.27	0.630
7.77	106.33	0.631
7.78	106.40	0.631
7.79	106.47	0.631
7.79	106.53	0.632
7.80	106.60	0.632
7.81	106.67	0.632
7.81	106.73	0.633
7.82	106.80	0.633
7.83	106.87	0.634
7.83	106.93	0.634
7.84	107.00	0.635
7.85	107.07	0.635
7.85	107.13	0.635
7.86	107.20	0.636
7.87	107.27	0.636
7.87	107.33	0.636
7.88	107.40	0.637
7.89	107.47	0.637
7.89	107.53	0.638
7.90	107.60	0.638
7.91	107.67	0.639
7.91	107.73	0.639
7.92	107.80	0.640
7.93	107.87	0.640
7.93	107.93	0.641
7.94	108.00	0.641
7.95	108.07	0.642
7.95	108.13	0.642
7.96	108.20	0.642
7.97	108.27	0.643
7.97	108.33	0.643
7.98	108.40	0.644
7.99	108.47	0.644
7.99	108.53	0.645
8.00	108.60	0.645
8.00	108.62	0.645

[step]
Ramp 10.00 °C/min to 30.00 °C
Time	Temperature	Heat Flow (Normalized)
min	°C	W/g
9.00	110.08	0.029
9.01	110.08	0.029
9.02	110.08	0.029
9.02	110.08	0.028
9.03	110.08	0.028
9.04	110.08	0.027
9.04	110.07	0.027
9.05	110.07	0.027
9.06	110.06	0.028
9.06	110.06	0.039
9.07	110.05	0.068
9.08	110.03	0.094
9.08	110.02	0.120
9.09	110.00	0.143
9.10	109.98	0.154
9.10	109.95	0.158
9.11	109.92	0.160
9.12	109.89	0.159
9.12	109.86	0.154
9.13	109.82	0.147
9.14	109.78	0.126
9.14	109.74	0.081
9.15	109.69	0.033
9.16	109.65	-0.014
9.16	109.60	-0.056
9.17	109.55	-0.093
9.18	109.50	-0.126
9.18	109.45	-0.157
9.19	109.40	-0.185
9.20	109.35	-0.219
9.20	109.29	-0.247
9.21	109.24	-0.260
9.22	109.18	-0.275
9.22	109.13	-0.309
9.23	109.07	-0.326
9.24	109.01	-0.340
9.24	108.95	-0.357
9.25	108.90	-0.370
9.26	108.84	-0.384
9.26	108.78	-0.395
9.27	108.72	-0.406
9.28	108.66	-0.416
9.28	108.60	-0.428
9.29	108.54	-0.438
9.30	108.48	-0.449
9.30	108.41	-0.460
9.31	108.35	-0.468
9.32	108.29	-0.479
9.32	108.23	-0.487
9.33	108.16	-0.496
9.34	108.10	-0.503
9.34	108.04	-0.511
9.35	107.98	-0.515
9.36	107.91	-0.520
9.36	107.85	-0.524
9.37	107.78	-0.529
9.38	107.72	-0.536
9.38	107.66	-0.540
9.39	107.59	-0.548
9.40	107.53	-0.551
9.40	107.46	-0.553
9.41	107.40	-0.554
9.42	107.34	-0.557
9.42	107.27	-0.565
9.43	107.21	-0.567
9.44	107.14	-0.570
9.44	107.08	-0.571
9.45	107.01	-0.574
9.46	106.95	-0.578
9.46	106.88	-0.582
9.47	106.82	-0.584
9.48	106.75	-0.585
9.48	106.69	-0.587
9.49	106.62	-0.590
9.50	106.56	-0.591
9.50	106.49	-0.592
9.51	106.43	-0.593
9.52	106.36	-0.594
9.52	106.30	-0.595
9.53	106.23	-0.596
9.54	106.17	-0.597
9.54	106.10	-0.598
9.55	106.03	-0.599
9.56	105.97	-0.602
9.56	105.90	-0.604
9.57	105.84	-0.605
9.58	105.77	-0.605
9.58	105.71	-0.607
9.59	105.64	-0.608
9.60	105.58	-0.609
9.60	105.51	-0.609
9.61	105.45	-0.610
9.62	105.38	-0.613
9.62	105.31	-0.613
9.63	105.25	-0.614
9.64	105.18	-0.615
9.64	105.12	-0.615
9.65	105.05	-0.616
9.66	104.98	-0.617
9.66	104.92	-0.617
9.67	104.85	-0.618
9.68	104.79	-0.619
9.68	104.72	-0.620
9.69	104.66	-0.620
9.70	104.59	-0.621
9.70	104.52	-0.622
9.71	104.46	-0.623
9.72	104.39	-0.624
9.72	104.33	-0.625
9.73	104.26	-0.626
9.74	104.20	-0.626
9.74	104.13	-0.627
9.75	104.06	-0.628
9.76	104.00	-0.628
9.76	103.93	-0.629
9.77	103.87	-0.630
9.78	103.80	-0.630
9.78	103.73	-0.631
9.79	103.67	-0.632
9.80	103.60	-0.632
9.80	103.54	-0.633
9.81	103.47	-0.634
9.82	103.40	-0.635
9.82	103.34	-0.636
9.83	103.27	-0.636
9.84	103.21	-0.637
9.84	103.14	-0.638
9.85	103.07	-0.638
9.86	103.01	-0.639
9.86	102.94	-0.639
9.87	102.88	-0.640
9.88	102.81	-0.641
9.88	102.74	-0.641
9.89	102.68	-0.642
9.90	102.61	-0.643
9.90	102.54	-0.643
9.91	102.48	-0.644
9.92	102.41	-0.644
9.92	102.34	-0.645
9.93	102.28	-0.646
9.94	102.21	-0.646
9.94	102.15	-0.647
9.95	102.08	-0.647
9.96	102.02	-0.648
9.96	101.95	-0.648
9.97	101.88	-0.649
9.98	101.82	-0.649
9.98	101.75	-0.650
9.99	101.68	-0.651
10.00	101.62	-0.651
10.00	101.55	-0.652
10.01	101.48	-0.652
10.02	101.42	-0.653
10.02	101.35	-0.653
10.03	101.29	-0.654
10.04	101.22	-0.655
10.04	101.15	-0.655
10.05	101.09	-0.656
10.06	101.02	-0.656
10.06	100.95	-0.657
10.07	100.89	-0.657
10.08	100.82	-0.657
10.08	100.76	-0.658
10.09	100.69	-0.658
10.10	100.62	-0.659
10.10	100.56	-0.660
10.11	100.49	-0.660
10.12	100.42	-0.661
10.12	100.36	-0.661
10.13	100.29	-0.662
10.14	100.22	-0.662
10.14	100.16	-0.662
10.15	100.09	-0.663
10.16	100.03	-0.663
10.16	99.96	-0.663
10.17	99.89	-0.664
10.18	99.83	-0.664
10.18	99.76	-0.665
10.19	99.69	-0.665
10.20	99.63	-0.665
10.20	99.56	-0.666
10.21	99.49	-0.666
10.22	99.43	-0.666
10.22	99.36	-0.667
10.23	99.30	-0.667
10.24	99.23	-0.667
10.24	99.16	-0.668
10.25	99.10	-0.668
10.26	99.03	-0.669
10.26	98.96	-0.669
10.27	98.90	-0.669
10.28	98.83	-0.670
10.28	98.76	-0.670
10.29	98.70	-0.670
10.30	98.63	-0.671
10.30	98.56	-0.671
10.31	98.50	-0.671
10.32	98.43	-0.672
10.32	98.36	-0.672
10.33	98.30	-0.672
10.34	98.23	-0.672
10.34	98.17	-0.673
10.35	98.10	-0.673
10.36	98.03	-0.673
10.36	97.97	-0.673
10.37	97.90	-0.673
10.38	97.83	-0.674
10.38	97.77	-0.674
10.39	97.70	-0.674
10.40	97.63	-0.674
10.40	97.57	-0.675
10.41	97.50	-0.675
10.42	97.44	-0.675
10.42	97.37	-0.675
10.43	97.30	-0.676
10.44	97.24	-0.676
10.44	97.17	-0.676
10.45	97.10	-0.676
10.46	97.04	-0.676
10.46	96.97	-0.677
10.47	96.90	-0.677
10.48	96.84	-0.677
10.48	96.77	-0.678
10.49	96.70	-0.678
10.50	96.64	-0.678
10.50	96.57	-0.678
10.51	96.50	-0.678
10.52	96.44	-0.679
10.52	96.37	-0.679
10.53	96.30	-0.679
10.54	96.24	-0.679
10.54	96.17	-0.679
10.55	96.10	-0.680
10.56	96.04	-0.680
10.56	95.97	-0.680
10.57	95.90	-0.680
10.58	95.84	-0.681
10.58	95.77	-0.681
10.59	95.71	-0.681
10.60	95.64	-0.681
10.60	95.57	-0.681
10.61	95.51	-0.681
10.62	95.44	-0.681
10.62	95.37	-0.682
10.63	95.31	-0.682
10.64	95.24	-0.682
10.64	95.17	-0.682
10.65	95.11	-0.682
10.66	95.04	-0.683
10.66	94.97	-0.683
10.67	94.91	-0.683
10.68	94.84	-0.683
10.68	94.77	-0.683
10.69	94.71	-0.683
10.70	94.64	-0.683
10.70	94.57	-0.684
10.71	94.51	-0.684
10.72	94.44	-0.684
10.72	94.37	-0.684
10.73	94.31	-0.684
10.74	94.24	-0.684
10.74	94.17	-0.685
10.75	94.11	-0.685
10.76	94.04	-0.685
10.76	93.98	-0.685
10.77	93.91	-0.685
10.78	93.84	-0.685
10.78	93.78	-0.686
10.79	93.71	-0.686
10.80	93.64	-0.686
10.80	93.58	-0.686
10.81	93.51	-0.686
10.82	93.44	-0.686
10.82	93.38	-0.686
10.83	93.31	-0.686
10.84	93.24	-0.687
10.84	93.18	-0.687
10.85	93.11	-0.687
10.86	93.04	-0.687
10.86	92.98	-0.687
10.87	92.91	-0.687
10.88	92.84	-0.687
10.88	92.78	-0.687
10.89	92.71	-0.687
10.90	92.64	-0.687
10.90	92.58	-0.687
10.91	92.51	-0.688
10.92	92.44	-0.688
10.92	92.38	-0.688
10.93	92.31	-0.688
10.94	92.24	-0.688
10.94	92.18	-0.688
10.95	92.11	-0.688
10.96	92.05	-0.688
10.96	91.98	-0.688
10.97	91.91	-0.688
10.98	91.85	-0.688
10.98	91.78	-0.688
10.99	91.71	-0.688
11.00	91.65	-0.689
11.00	91.58	-0.689
11.01	91.51	-0.689
11.02	91.45	-0.689
11.02	91.38	-0.689
11.03	91.31	-0.689
11.04	91.25	-0.689
11.04	91.18	-0.689
11.05	91.11	-0.689
11.06	91.05	-0.689
11.06	90.98	-0.689
11.07	90.91	-0.689
11.08	90.85	-0.689
11.08	90.78	-0.689
11.09	90.71	-0.689
11.10	90.65	-0.690
11.10	90.58	-0.690
11.11	90.51	-0.690
11.12	90.45	-0.690
11.12	90.38	-0.690
11.13	90.31	-0.690
11.14	90.25	-0.690
11.14	90.18	-0.690
11.15	90.12	-0.690
11.16	90.05	-0.690
11.16	89.98	-0.690
11.17	89.92	-0.690
11.18	89.85	-0.690
11.18	89.78	-0.690
11.19	89.72	-0.690
11.20	89.65	-0.690
11.20	89.58	-0.691
11.21	89.52	-0.691
11.22	89.45	-0.691
11.22	89.38	-0.691
11.23	89.32	-0.691
11.24	89.25	-0.691
11.24	89.18	-0.691
11.25	89.11	-0.690
11.26	89.05	-0.690
11.26	88.98	-0.690
11.27	88.92	-0.690
11.28	88.85	-0.691
11.28	88.78	-0.691
11.29	88.72	-0.691
11.30	88.65	-0.691
11.30	88.58	-0.691
11.31	88.52	-0.691
11.32	88.45	-0.691
11.32	88.38	-0.691
11.33	88.32	-0.691
11.34	88.25	-0.691
11.34	88.18	-0.691
11.35	88.12	-0.691
11.36	88.05	-0.691
11.36	87.98	-0.691
11.37	87.92	-0.691
11.38	87.85	-0.691
11.38	87.79	-0.691
11.39	87.72	-0.691
11.40	87.65	-0.691
11.40	87.59	-0.691
11.41	87.52	-0.691
11.42	87.45	-0.691
11.42	87.39	-0.691
11.43	87.32	-0.691
11.44	87.25	-0.692
11.44	87.19	-0.692
11.45	87.12	-0.692
11.46	87.05	-0.692
11.46	86.99	-0.692
11.47	86.92	-0.693
11.48	86.85	-0.693
11.48	86.79	-0.692
11.49	86.72	-0.693
11.50	86.65	-0.692
11.50	86.59	-0.692
11.51	86.52	-0.692
11.52	86.45	-0.693
11.52	86.39	-0.692
11.53	86.32	-0.692
11.54	86.25	-0.692
11.54	86.19	-0.692
11.55	86.12	-0.693
11.56	86.06	-0.693
11.56	85.99	-0.693
11.57	85.92	-0.693
11.58	85.85	-0.693
11.58	85.79	-0.693
11.59	85.72	-0.693
11.60	85.65	-0.693
11.60	85.59	-0.693
11.61	85.52	-0.693
11.62	85.45	-0.693
11.62	85.39	-0.693
11.63	85.32	-0.693
11.64	85.26	-0.693
11.64	85.19	-0.693
11.65	85.12	-0.693
11.66	85.05	-0.693
11.66	84.99	-0.693
11.67	84.92	-0.693
11.68	84.85	-0.693
11.68	84.79	-0.694
11.69	84.72	-0.694
11.70	84.66	-0.694
11.70	84.59	-0.694
11.71	84.52	-0.694
11.72	84.46	-0.694
11.72	84.39	-0.694
11.73	84.32	-0.694
11.74	84.26	-0.694
11.74	84.19	-0.695
11.75	84.12	-0.695
11.76	84.06	-0.695
11.76	83.99	-0.695
11.77	83.92	-0.695
11.78	83.86	-0.695
11.78	83.79	-0.695
11.79	83.72	-0.695
11.80	83.66	-0.695
11.80	83.59	-0.695
11.81	83.52	-0.695
11.82	83.46	-0.696
11.82	83.39	-0.696
11.83	83.32	-0.696
11.84	83.26	-0.696
11.84	83.19	-0.696
11.85	83.13	-0.696
11.86	83.06	-0.696
11.86	82.99	-0.696
11.87	82.92	-0.696
11.88	82.86	-0.696
11.88	82.79	-0.696
11.89	82.73	-0.696
11.90	82.66	-0.697
11.90	82.59	-0.697
11.91	82.52	-0.697
11.92	82.46	-0.697
11.92	82.39	-0.697
11.93	82.32	-0.697
11.94	82.26	-0.697
11.94	82.19	-0.697
11.95	82.12	-0.697
11.96	82.06	-0.697
11.96	81.99	-0.698
11.97	81.92	-0.698
11.98	81.86	-0.698
11.98	81.79	-0.698
11.99	81.72	-0.698
12.00	81.66	-0.699
12.00	81.59	-0.699
12.01	81.53	-0.699
12.02	81.46	-0.699
12.02	81.39	-0.699
12.03	81.33	-0.699
12.04	81.26	-0.699
12.04	81.19	-0.699
12.05	81.12	-0.699
12.06	81.06	-0.700
12.06	80.99	-0.700
12.07	80.93	-0.700
12.08	80.86	-0.700
12.08	80.79	-0.700
12.09	80.73	-0.701
12.10	80.66	-0.701
12.10	80.59	-0.701
12.11	80.53	-0.701
12.12	80.46	-0.701
12.12	80.39	-0.701
12.13	80.33	-0.701
12.14	80.26	-0.701
12.14	80.19	-0.701
12.15	80.13	-0.701
12.16	80.06	-0.701
12.16	79.99	-0.701
12.17	79.93	-0.702
12.18	79.86	-0.702
12.18	79.79	-0.702
12.19	79.73	-0.702
12.20	79.66	-0.702
12.20	79.60	-0.702
12.21	79.53	-0.702
12.22	79.46	-0.702
12.22	79.39	-0.702
12.23	79.33	-0.702
12.24	79.26	-0.703
12.24	79.20	-0.703
12.25	79.13	-0.703
12.26	79.06	-0.703
12.26	79.00	-0.703
12.27	78.93	-0.703
12.28	78.86	-0.703
12.28	78.80	-0.703
12.29	78.73	-0.703
12.30	78.66	-0.703
12.30	78.59	-0.703
12.31	78.53	-0.703
12.32	78.46	-0.703
12.32	78.40	-0.703
12.33	78.33	-0.703
12.34	78.26	-0.704
12.34	78.20	-0.704
12.35	78.13	-0.704
12.36	78.06	-0.704
12.36	78.00	-0.704
12.37	77.93	-0.704
12.38	77.86	-0.704
12.38	77.80	-0.704
12.39	77.73	-0.704
12.40	77.66	-0.704
12.40	77.60	-0.705
12.41	77.53	-0.705
12.42	77.46	-0.705
12.42	77.40	-0.705
12.43	77.33	-0.705
12.44	77.26	-0.705
12.44	77.20	-0.705
12.45	77.13	-0.705
12.46	77.06	-0.705
12.46	77.00	-0.705
12.47	76.93	-0.705
12.48	76.86	-0.705
12.48	76.80	-0.705
12.49	76.73	-0.705
12.50	76.66	-0.705
12.50	76.60	-0.705
12.51	76.53	-0.705
12.52	76.46	-0.705
12.52	76.40	-0.705
12.53	76.33	-0.706
12.54	76.26	-0.706
12.54	76.20	-0.705
12.55	76.13	-0.706
12.56	76.06	-0.706
12.56	76.00	-0.705
12.57	75.93	-0.706
12.58	75.87	-0.706
12.58	75.80	-0.706
12.59	75.73	-0.706
12.60	75.67	-0.706
12.60	75.60	-0.706
12.61	75.53	-0.706
12.62	75.47	-0.706
12.62	75.40	-0.706
12.63	75.33	-0.706
12.64	75.27	-0.706
12.64	75.20	-0.706
12.65	75.13	-0.706
12.66	75.07	-0.706
12.66	75.00	-0.706
12.67	74.93	-0.706
12.68	74.86	-0.706
12.68	74.80	-0.706
12.69	74.73	-0.706
12.70	74.67	-0.706
12.70	74.60	-0.706
12.71	74.53	-0.706
12.72	74.47	-0.706
12.72	74.40	-0.706
12.73	74.33	-0.707
12.74	74.27	-0.707
12.74	74.20	-0.707
12.75	74.13	-0.707
12.76	74.07	-0.707
12.76	74.00	-0.707
12.77	73.93	-0.707
12.78	73.87	-0.707
12.78	73.80	-0.707
12.79	73.73	-0.707
12.80	73.67	-0.707
12.80	73.60	-0.707
12.81	73.53	-0.707
12.82	73.47	-0.708
12.82	73.40	-0.708
12.83	73.33	-0.708
12.84	73.27	-0.708
12.84	73.20	-0.708
12.85	73.13	-0.708
12.86	73.07	-0.708
12.86	73.00	-0.708
12.87	72.93	-0.708
12.88	72.87	-0.708
12.88	72.80	-0.708
12.89	72.73	-0.708
12.90	72.67	-0.708
12.90	72.60	-0.708
12.91	72.53	-0.708
12.92	72.47	-0.708
12.92	72.40	-0.708
12.93	72.33	-0.708
12.94	72.27	-0.708
12.94	72.20	-0.708
12.95	72.13	-0.708
12.96	72.07	-0.708
12.96	72.00	-0.708
12.97	71.93	-0.708
12.98	71.87	-0.708
12.98	71.80	-0.708
12.99	71.73	-0.708
13.00	71.67	-0.708
13.00	71.60	-0.708
13.01	71.53	-0.708
13.02	71.47	-0.708
13.02	71.40	-0.709
13.03	71.34	-0.709
13.04	71.27	-0.708
13.04	71.20	-0.708
13.05	71.14	-0.709
13.06	71.07	-0.709
13.06	71.00	-0.709
13.07	70.94	-0.709
13.08	70.87	-0.709
13.08	70.80	-0.709
13.09	70.74	-0.708
13.10	70.67	-0.708
13.10	70.60	-0.708
13.11	70.54	-0.708
13.12	70.47	-0.708
13.12	70.40	-0.709
13.13	70.34	-0.709
13.14	70.27	-0.709
13.14	70.20	-0.709
13.15	70.14	-0.708
13.16	70.07	-0.708
13.16	70.00	-0.708
13.17	69.94	-0.709
13.18	69.87	-0.709
13.18	69.80	-0.709
13.19	69.74	-0.709
13.20	69.67	-0.709
13.20	69.60	-0.709
13.21	69.54	-0.709
13.22	69.47	-0.709
13.22	69.41	-0.709
13.23	69.34	-0.709
13.24	69.27	-0.709
13.24	69.20	-0.709
13.25	69.14	-0.709
13.26	69.07	-0.709
13.26	69.00	-0.709
13.27	68.94	-0.709
13.28	68.87	-0.709
13.28	68.81	-0.709
13.29	68.74	-0.709
13.30	68.67	-0.709
13.30	68.61	-0.709
13.31	68.54	-0.709
13.32	68.47	-0.709
13.32	68.41	-0.709
13.33	68.34	-0.709
13.34	68.27	-0.709
13.34	68.21	-0.709
13.35	68.14	-0.709
13.36	68.07	-0.709
13.36	68.01	-0.710
13.37	67.94	-0.709
13.38	67.87	-0.709
13.38	67.81	-0.709
13.39	67.74	-0.709
13.40	67.67	-0.709
13.40	67.61	-0.709
13.41	67.54	-0.709
13.42	67.47	-0.709
13.42	67.41	-0.709
13.43	67.34	-0.709
13.44	67.27	-0.709
13.44	67.21	-0.709
13.45	67.14	-0.709
13.46	67.08	-0.709
13.46	67.01	-0.709
13.47	66.94	-0.709
13.48	66.87	-0.709
13.48	66.81	-0.709
13.49	66.74	-1.421
13.50	66.69	-11.218
13.50	66.79	-52.318
13.51	67.31	-69.741
13.52	67.43	-33.073
13.52	67.34	-13.163
13.53	67.22	-8.057
13.54	67.10	-5.520
13.54	66.98	-4.210
13.55	66.86	-3.506
13.56	66.74	-3.086
13.56	66.63	-2.779
13.57	66.51	-2.562
13.58	66.41	-2.413
13.58	66.30	-2.278
13.59	66.20	-2.156
13.60	66.10	-2.049
13.60	66.00	-1.949
13.61	65.90	-1.857
13.62	65.81	-1.771
13.62	65.72	-1.693
13.63	65.63	-1.623
13.64	65.54	-1.550
13.64	65.45	-1.483
13.65	65.37	-1.433
13.66	65.29	-1.377
13.66	65.20	-1.324
13.67	65.12	-1.283
13.68	65.04	-1.238
13.68	64.96	-1.197
13.69	64.89	-1.160
13.70	64.81	-1.128
13.70	64.73	-1.095
13.71	64.66	-1.059
13.72	64.58	-1.040
13.72	64.51	-1.019
13.73	64.43	-0.985
13.74	64.36	-0.966
13.74	64.29	-0.957
13.75	64.22	-0.926
13.76	64.14	-0.901
13.76	64.07	-0.892
13.77	64.00	-0.887
13.78	63.93	-0.869
13.78	63.86	-0.857
13.79	63.79	-0.847
13.80	63.72	-0.827
13.80	63.65	-0.823
13.81	63.58	-0.820
13.82	63.51	-0.809
13.82	63.44	-0.791
13.83	63.37	-0.789
13.84	63.30	-0.791
13.84	63.23	-0.780
13.85	63.17	-0.775
13.86	63.10	-0.773
13.86	63.03	-0.767
13.87	62.96	-0.763
13.88	62.89	-0.758
13.88	62.83	-0.755
13.89	62.76	-0.754
13.90	62.69	-0.748
13.90	62.62	-0.743
13.91	62.56	-0.740
13.92	62.49	-0.739
13.92	62.42	-0.738
13.93	62.35	-0.736
13.94	62.29	-0.735
13.94	62.22	-0.733
13.95	62.15	-0.732
13.96	62.08	-0.732
13.96	62.02	-0.731
13.97	61.95	-0.730
13.98	61.88	-0.728
13.98	61.82	-0.726
13.99	61.75	-0.723
14.00	61.68	-0.722
14.00	61.62	-0.722
14.01	61.55	-0.720
14.02	61.48	-0.719
14.02	61.42	-0.719
14.03	61.35	-0.718
14.04	61.28	-0.717
14.04	61.22	-0.717
14.05	61.15	-0.716
14.06	61.08	-0.716
14.06	61.01	-0.715
14.07	60.95	-0.715
[...]
18.63	34.92	0.377
18.64	34.99	0.378
18.64	35.05	0.379
18.65	35.12	0.380
18.66	35.18	0.381
18.66	35.25	0.382
18.67	35.31	0.383
18.68	35.38	0.383
18.68	35.45	0.384
18.69	35.51	0.385
18.70	35.58	0.386
18.70	35.64	0.386
18.71	35.71	0.387
18.72	35.78	0.388
18.72	35.84	0.389
18.73	35.91	0.389
18.74	35.97	0.390
18.74	36.04	0.390
18.75	36.10	0.391
18.76	36.17	0.394
18.76	36.24	0.395
18.77	36.30	0.395
18.78	36.37	0.396
18.78	36.43	0.396
18.79	36.50	0.397
18.80	36.57	0.397
18.80	36.63	0.398
18.81	36.70	0.399
18.82	36.76	0.400
18.82	36.83	0.400
18.83	36.90	0.401
18.84	36.96	0.401
18.84	37.03	0.402
18.85	37.10	0.402
18.86	37.16	0.403
18.86	37.23	0.404
18.87	37.29	0.404
18.88	37.36	0.405
18.88	37.43	0.406
18.89	37.49	0.406
18.90	37.56	0.407
18.90	37.62	0.407
18.91	37.69	0.408
18.92	37.76	0.409
18.92	37.82	0.409
18.93	37.89	0.410
18.94	37.96	0.410
18.94	38.02	0.411
18.95	38.09	0.411
18.96	38.16	0.412
18.96	38.22	0.412
18.97	38.29	0.413
18.98	38.35	0.413
18.98	38.42	0.414
18.99	38.49	0.414
19.00	38.55	0.415
19.00	38.62	0.416
19.01	38.69	0.416
19.02	38.75	0.417
19.02	38.82	0.417
19.03	38.88	0.417
19.04	38.95	0.418
19.04	39.02	0.418
19.05	39.08	0.419
19.06	39.15	0.419
19.06	39.22	0.420
19.07	39.28	0.420
19.08	39.35	0.421
19.08	39.42	0.421
19.09	39.48	0.422
19.10	39.55	0.422
19.10	39.61	0.422
19.11	39.68	0.423
19.12	39.75	0.423
19.12	39.81	0.423
19.13	39.88	0.424
19.14	39.95	0.424
19.14	40.01	0.425
19.15	40.08	0.425
19.16	40.15	0.425
19.16	40.21	0.426
19.17	40.28	0.426
19.18	40.35	0.426
19.18	40.41	0.427
19.19	40.48	0.427
19.20	40.55	0.427
19.20	40.61	0.428
19.21	40.68	0.428
19.22	40.74	0.428
19.22	40.81	0.429
19.23	40.88	0.429
19.24	40.94	0.429
19.24	41.01	0.429
19.25	41.08	0.430
19.26	41.14	0.430
19.26	41.21	0.430
19.27	41.28	0.430
19.28	41.34	0.431
19.28	41.41	0.431
19.29	41.48	0.431
19.30	41.54	0.431
19.30	41.61	0.432
19.31	41.67	0.432
19.32	41.74	0.432
19.32	41.81	0.432
19.33	41.87	0.433
19.34	41.94	0.433
19.34	42.01	0.433
19.35	42.07	0.434
19.36	42.14	0.434
19.36	42.21	0.434
19.37	42.27	0.434
19.38	42.34	0.434
19.38	42.41	0.434
19.39	42.47	0.435
19.40	42.54	0.435
19.40	42.61	0.435
19.41	42.67	0.436
19.42	42.74	0.436
19.42	42.81	0.436
19.43	42.87	0.436
19.44	42.94	0.436
19.44	43.01	0.436
19.45	43.07	0.437
19.46	43.14	0.437
19.46	43.21	0.437
19.47	43.27	0.437
19.48	43.34	0.437
19.48	43.41	0.437
19.49	43.47	0.438
19.50	43.54	0.438
19.50	43.61	0.438
19.51	43.67	0.438
19.52	43.74	0.439
19.52	43.81	0.439
19.53	43.87	0.439
19.54	43.94	0.439
19.54	44.00	0.439
19.55	44.07	0.439
19.56	44.14	0.439
19.56	44.20	0.439
19.57	44.27	0.440
19.58	44.34	0.440
19.58	44.40	0.440
19.59	44.47	0.440
19.60	44.54	0.440
19.60	44.60	0.440
19.61	44.67	0.440
19.62	44.74	0.441
19.62	44.80	0.441
19.63	44.87	0.441
19.64	44.94	0.441
19.64	45.00	0.441
19.65	45.07	0.441
19.66	45.14	0.441
19.66	45.20	0.441
19.67	45.27	0.442
19.68	45.34	0.442
19.68	45.40	0.442
19.69	45.47	0.442
19.70	45.54	0.442
19.70	45.60	0.442
19.71	45.67	0.442
19.72	45.74	0.442
19.72	45.80	0.443
19.73	45.87	0.442
19.74	45.94	0.442
19.74	46.00	0.443
19.75	46.07	0.443
19.76	46.14	0.443
19.76	46.20	0.443
19.77	46.27	0.443
19.78	46.34	0.443
19.78	46.40	0.443
19.79	46.47	0.443
19.80	46.54	0.443
19.80	46.60	0.443
19.81	46.67	0.443
19.82	46.74	0.443
19.82	46.81	0.443
19.83	46.87	0.443
19.84	46.94	0.444
19.84	47.00	0.444
19.85	47.07	0.444
19.86	47.14	0.444
19.86	47.20	0.444
19.87	47.27	0.444
19.88	47.34	0.444
19.88	47.40	0.444
19.89	47.47	0.444
19.90	47.54	0.444
19.90	47.60	0.444
19.91	47.67	0.444
19.92	47.74	0.444
19.92	47.80	0.444
19.93	47.87	0.445
19.94	47.94	0.445
19.94	48.00	0.445
19.95	48.07	0.445
19.96	48.14	0.445
19.96	48.20	0.445
19.97	48.27	0.446
19.98	48.34	0.446
19.98	48.40	0.446
19.99	48.47	0.446
20.00	48.54	0.446
20.00	48.60	0.446
20.01	48.67	0.446
20.02	48.74	0.446
20.02	48.81	0.446
20.03	48.87	0.446
20.04	48.94	0.446
20.04	49.00	0.446
20.05	49.07	0.446
20.06	49.14	0.446
20.06	49.20	0.446
20.07	49.27	0.447
20.08	49.34	0.447
20.08	49.40	0.447
20.09	49.47	0.447
20.10	49.54	0.447
20.10	49.61	0.447
20.11	49.67	0.447
20.12	49.74	0.447
20.12	49.80	0.448
20.13	49.87	0.448
20.14	49.94	0.448
20.14	50.01	0.448
20.15	50.07	0.448
20.16	50.14	0.448
20.16	50.21	0.448
20.17	50.27	0.448
20.18	50.34	0.448
20.18	50.41	0.448
20.19	50.47	0.448
20.20	50.54	0.448
20.20	50.61	0.449
20.21	50.67	0.448
20.22	50.74	0.449
20.22	50.81	0.449
20.23	50.87	0.449
20.24	50.94	0.449
20.24	51.01	0.449
20.25	51.07	0.449
20.26	51.14	0.449
20.26	51.20	0.449
20.27	51.27	0.449
20.28	51.34	0.449
20.28	51.41	0.449
20.29	51.47	0.449
20.30	51.54	0.449
20.30	51.61	0.449
20.31	51.67	0.449
20.32	51.74	0.449
20.32	51.81	0.449
20.33	51.87	0.449
20.34	51.94	0.450
20.34	52.01	0.450
20.35	52.07	0.450
20.36	52.14	0.450
20.36	52.20	0.450
20.37	52.27	0.450
20.38	52.34	0.450
20.38	52.41	0.450
20.39	52.47	0.450
20.40	52.54	0.450
20.40	52.61	0.450
20.41	52.67	0.451
20.42	52.74	0.451
20.42	52.81	0.451
20.43	52.87	0.451
20.44	52.94	0.451
20.44	53.01	0.451
20.45	53.07	0.451
20.46	53.14	0.451
20.46	53.21	0.451
20.47	53.27	0.451
20.48	53.34	0.451
20.48	53.41	0.451
20.49	53.47	0.451
20.50	53.54	0.452
20.50	53.61	0.451
20.51	53.67	0.451
20.52	53.74	0.451
20.52	53.81	0.451
20.53	53.87	0.451
20.54	53.94	0.452
20.54	54.01	0.452
20.55	54.07	0.452
20.56	54.14	0.452
20.56	54.21	0.452
20.57	54.27	0.452
20.58	54.34	0.452
20.58	54.41	0.452
20.59	54.47	0.452
20.60	54.54	0.452
20.60	54.61	0.453
20.61	54.67	0.452
20.62	54.74	0.453
20.62	54.81	0.453
20.63	54.88	0.453
20.64	54.94	0.453
20.64	55.01	0.453
20.65	55.07	0.453
20.66	55.14	0.453
20.66	55.21	0.453
20.67	55.27	0.453
20.68	55.34	0.453
20.68	55.41	0.454
20.69	55.48	0.454
20.70	55.54	0.454
20.70	55.61	0.454
20.71	55.68	0.454
20.72	55.74	0.454
20.72	55.81	0.454
20.73	55.87	0.454
20.74	55.94	0.454
20.74	56.01	0.454
20.75	56.08	0.454
20.76	56.14	0.454
20.76	56.21	0.454
20.77	56.27	0.454
20.78	56.34	0.455
20.78	56.41	0.455
20.79	56.48	0.455
20.80	56.54	0.455
20.80	56.61	0.455
20.81	56.68	0.455
20.82	56.74	0.455
20.82	56.81	0.455
20.83	56.88	0.455
20.84	56.94	0.455
20.84	57.01	0.455
20.85	57.08	0.455
20.86	57.14	0.455
20.86	57.21	0.455
20.87	57.28	0.455
20.88	57.34	0.456
20.88	57.41	0.456
20.89	57.48	0.456
20.90	57.54	0.456
20.90	57.61	0.456
20.91	57.68	0.456
20.92	57.74	0.456
20.92	57.81	0.456
20.93	57.88	0.456
20.94	57.94	0.456
20.94	58.01	0.456
20.95	58.08	0.456
20.96	58.14	0.456
20.96	58.21	0.457
20.97	58.28	0.457
20.98	58.34	0.457
20.98	58.41	0.457
20.99	58.48	0.457
21.00	58.54	0.457
21.00	58.61	0.457
21.01	58.68	0.457
21.02	58.74	0.457
21.02	58.81	0.457
21.03	58.88	0.457
21.04	58.94	0.458
21.04	59.01	0.458
21.05	59.08	0.458
21.06	59.14	0.458
21.06	59.21	0.458
21.07	59.28	0.458
21.08	59.35	0.458
21.08	59.41	0.458
21.09	59.48	0.458
21.10	59.54	0.458
21.10	59.61	0.459
21.11	59.68	0.459
21.12	59.74	0.459
21.12	59.81	0.459
21.13	59.88	0.459
21.14	59.94	0.459
21.14	60.01	0.459
21.15	60.08	0.459
21.16	60.14	0.459
21.16	60.21	0.459
21.17	60.28	0.459
21.18	60.34	0.460
21.18	60.41	0.460
21.19	60.48	0.460
21.20	60.55	0.460
21.20	60.61	0.460
21.21	60.68	0.460
21.22	60.75	0.460
21.22	60.81	0.461
21.23	60.88	0.461
21.24	60.95	0.461
21.24	61.01	0.461
21.25	61.08	0.461
21.26	61.15	0.461
21.26	61.21	0.461
21.27	61.28	0.461
21.28	61.34	0.461
21.28	61.41	0.462
21.29	61.48	0.462
21.30	61.55	0.462
21.30	61.61	0.462
21.31	61.68	0.462
21.32	61.75	0.462
21.32	61.81	0.462
21.33	61.88	0.462
21.34	61.95	0.462
21.34	62.01	0.462
21.35	62.08	0.462
21.36	62.15	0.462
21.36	62.21	0.463
21.37	62.28	0.463
21.38	62.35	0.463
21.38	62.41	0.463
21.39	62.48	0.463
21.40	62.55	0.463
21.40	62.61	0.463
21.41	62.68	0.463
21.42	62.75	0.463
21.42	62.81	0.464
21.43	62.88	0.464
21.44	62.95	0.464
21.44	63.01	0.465
21.45	63.08	0.465
21.46	63.15	0.465
21.46	63.21	0.465
21.47	63.28	0.465
21.48	63.35	0.466
21.48	63.41	0.466
21.49	63.48	0.466
21.50	63.55	0.466
21.50	63.61	0.466
21.51	63.68	0.466
21.52	63.75	0.466
21.52	63.81	0.466
21.53	63.88	0.467
21.54	63.95	0.467
21.54	64.01	0.467
21.55	64.08	0.467
21.56	64.15	0.467
21.56	64.21	0.467
21.57	64.28	0.467
21.58	64.35	0.468
21.58	64.42	0.468
21.59	64.48	0.468
21.60	64.55	0.468
21.60	64.61	0.468
21.61	64.68	0.468
21.62	64.75	0.468
21.62	64.81	0.469
21.63	64.88	0.469
21.64	64.95	0.469
21.64	65.02	0.469
21.65	65.08	0.469
21.66	65.15	0.469
21.66	65.22	0.469
21.67	65.28	0.469
21.68	65.35	0.469
21.68	65.42	0.469
21.69	65.48	0.470
21.70	65.55	0.470
21.70	65.62	0.470
21.71	65.68	0.470
21.72	65.75	0.470
21.72	65.82	0.470
21.73	65.88	0.470
21.74	65.95	0.470
21.74	66.02	0.471
21.75	66.08	0.471
21.76	66.15	0.471
21.76	66.22	0.471
21.77	66.28	0.471
21.78	66.35	0.471
21.78	66.42	0.472
21.79	66.48	0.472
21.80	66.55	0.472
21.80	66.62	0.472
21.81	66.68	0.472
21.82	66.75	0.472
21.82	66.82	0.472
21.83	66.88	0.473
21.84	66.95	0.473
21.84	67.02	0.473
21.85	67.08	0.473
21.86	67.15	0.473
21.86	67.22	0.473
21.87	67.28	0.473
21.88	67.35	0.474
21.88	67.42	0.474
21.89	67.48	0.474
21.90	67.55	0.474
21.90	67.62	0.474
21.91	67.68	0.474
21.92	67.75	0.474
21.92	67.82	0.474
21.93	67.88	0.475
21.94	67.95	0.475
21.94	68.02	0.475
21.95	68.08	0.475
21.96	68.15	0.475
21.96	68.22	0.475
21.97	68.28	0.475
21.98	68.35	0.476
21.98	68.42	0.476
21.99	68.48	0.476
22.00	68.55	0.476
22.00	68.62	0.476
22.01	68.68	0.476
22.02	68.75	0.476
22.02	68.82	0.477
22.03	68.88	0.477
22.04	68.95	0.477
22.04	69.02	0.477
22.05	69.08	0.477
22.06	69.15	0.478
22.06	69.22	0.478
22.07	69.28	0.478
22.08	69.35	0.478
22.08	69.42	0.478
22.09	69.48	0.479
22.10	69.55	0.479
22.10	69.62	0.479
22.11	69.68	0.479
22.12	69.75	0.479
22.12	69.82	0.479
22.13	69.88	0.479
22.14	69.95	0.479
22.14	70.02	0.480
22.15	70.08	0.480
22.16	70.15	0.480
22.16	70.22	0.480
22.17	70.28	0.480
22.18	70.35	0.481
22.18	70.42	0.481
22.19	70.48	0.481
22.20	70.55	0.481
22.20	70.62	0.482
22.21	70.69	0.482
22.22	70.75	0.482
22.22	70.82	0.482
22.23	70.89	0.482
22.24	70.95	0.482
22.24	71.02	0.483
22.25	71.08	0.483
22.26	71.15	0.483
22.26	71.22	0.483
22.27	71.29	0.483
22.28	71.35	0.483
22.28	71.42	0.484
22.29	71.49	0.484
22.30	71.55	0.485
22.30	71.62	0.485
22.31	71.69	0.485
22.32	71.75	0.486
22.32	71.82	0.486
22.33	71.89	0.486
22.34	71.95	0.486
22.34	72.02	0.486
22.35	72.09	0.486
22.36	72.15	0.486
22.36	72.22	0.487
22.37	72.29	0.487
22.38	72.35	0.487
22.38	72.42	0.487
22.39	72.49	0.487
22.40	72.55	0.488
22.40	72.62	0.488
22.41	72.69	0.488
22.42	72.75	0.488
22.42	72.82	0.488
22.43	72.89	0.488
22.44	72.95	0.489
22.44	73.02	0.489
22.45	73.09	0.489
22.46	73.15	0.489
22.46	73.22	0.490
22.47	73.29	0.490
22.48	73.35	0.490
22.48	73.42	0.491
22.49	73.49	0.491
22.50	73.55	0.491
22.50	73.62	0.491
22.51	73.69	0.491
22.52	73.75	0.492
22.52	73.82	0.492
22.53	73.89	0.492
22.54	73.95	0.492
22.54	74.02	0.492
22.55	74.09	0.492
22.56	74.15	0.493
22.56	74.22	0.493
22.57	74.29	0.493
22.58	74.35	0.493
22.58	74.42	0.494
22.59	74.49	0.494
22.60	74.55	0.494
22.60	74.62	0.494
22.61	74.69	0.495
22.62	74.75	0.495
22.62	74.82	0.495
22.63	74.89	0.495
22.64	74.95	0.495
22.64	75.02	0.496
22.65	75.09	0.496
22.66	75.15	0.496
22.66	75.22	0.496
22.67	75.29	0.496
22.68	75.35	0.497
22.68	75.42	0.497
22.69	75.49	0.497
22.70	75.56	0.497
22.70	75.62	0.498
22.71	75.69	0.498
22.72	75.76	0.498
22.72	75.82	0.498
22.73	75.89	0.499
22.74	75.96	0.499
22.74	76.02	0.499
22.75	76.09	0.499
22.76	76.16	0.500
22.76	76.22	0.500
22.77	76.29	0.500
22.78	76.36	0.500
22.78	76.42	0.501
22.79	76.49	0.501
22.80	76.56	0.501
22.80	76.62	0.502
22.81	76.69	0.502
22.82	76.76	0.502
22.82	76.82	0.502
22.83	76.89	0.502
22.84	76.96	0.503
22.84	77.02	0.503
22.85	77.09	0.504
22.86	77.16	0.504
22.86	77.22	0.504
22.87	77.29	0.504
22.88	77.36	0.504
22.88	77.42	0.505
22.89	77.49	0.505
22.90	77.56	0.505
22.90	77.62	0.506
22.91	77.69	0.506
22.92	77.76	0.506
22.92	77.82	0.506
22.93	77.89	0.507
22.94	77.96	0.507
22.94	78.02	0.507
22.95	78.09	0.508
22.96	78.16	0.508
22.96	78.22	0.508
22.97	78.29	0.509
22.98	78.36	0.509
22.98	78.42	0.509
22.99	78.49	0.509
23.00	78.56	0.510
23.00	78.62	0.510
23.01	78.69	0.511
23.02	78.76	0.511
23.02	78.82	0.512
23.03	78.89	0.512
23.04	78.96	0.513
23.04	79.02	0.513
23.05	79.09	0.514
23.06	79.16	0.515
23.06	79.22	0.523
23.07	79.29	0.541
23.08	79.36	0.576
23.08	79.42	0.654
23.09	79.49	0.802
23.10	79.55	1.140
23.10	79.61	1.821
23.11	79.66	2.939
23.12	79.71	4.215
23.12	79.75	5.225
23.13	79.78	5.878
23.14	79.82	6.336
23.14	79.86	6.725
23.15	79.89	7.121
23.16	79.93	7.507
23.16	79.97	7.830
23.17	80.01	8.006
23.18	80.05	8.073
23.18	80.10	8.106
23.19	80.15	8.011
23.20	80.20	7.947
23.20	80.25	8.030
23.21	80.30	8.101
23.22	80.36	8.019
23.22	80.42	7.872
23.23	80.47	7.848
23.24	80.53	8.031
23.24	80.59	8.111
23.25	80.65	7.999
23.26	80.71	7.772
23.26	80.78	7.391
23.27	80.85	6.925
23.28	80.92	6.451
23.28	81.00	6.076
23.29	81.07	5.648
23.30	81.15	4.907
23.30	81.24	4.032
23.31	81.33	3.299
23.32	81.42	2.794
23.32	81.51	2.437
23.33	81.60	2.178
23.34	81.69	2.023
23.34	81.77	1.897
23.35	81.86	1.783
23.36	81.94	1.687
23.36	82.03	1.602
23.37	82.11	1.514
23.38	82.19	1.432
23.38	82.27	1.375
23.39	82.35	1.309
23.40	82.43	1.249
23.40	82.50	1.195
23.41	82.58	1.138
23.42	82.65	1.095
23.42	82.73	1.059
23.43	82.80	1.012
23.44	82.88	0.976
23.44	82.95	0.943
23.45	83.02	0.907
23.46	83.09	0.877
23.46	83.17	0.848
23.47	83.24	0.825
23.48	83.31	0.802
23.48	83.38	0.782
23.49	83.45	0.765
23.50	83.52	0.749
23.50	83.59	0.729
23.51	83.66	0.711
23.52	83.73	0.699
23.52	83.80	0.686
23.53	83.87	0.668
23.54	83.94	0.661
23.54	84.00	0.656
23.55	84.07	0.642
23.56	84.14	0.630
23.56	84.21	0.623
23.57	84.28	0.614
23.58	84.34	0.612
23.58	84.41	0.607
23.59	84.48	0.600
23.60	84.55	0.595
23.60	84.62	0.587
23.61	84.68	0.584
23.62	84.75	0.584
23.62	84.82	0.580
23.63	84.89	0.573
23.64	84.95	0.570
23.64	85.02	0.566
23.65	85.09	0.563
23.66	85.15	0.563
23.66	85.22	0.562
23.67	85.29	0.558
23.68	85.36	0.557
23.68	85.42	0.556
23.69	85.49	0.555
23.70	85.56	0.554
23.70	85.63	0.553
23.71	85.69	0.552
23.72	85.76	0.551
23.72	85.83	0.550
23.73	85.89	0.549
23.74	85.96	0.549
23.74	86.03	0.548
23.75	86.09	0.548
23.76	86.16	0.547
23.76	86.23	0.546
23.77	86.29	0.546
23.78	86.36	0.545
23.78	86.43	0.545
23.79	86.49	0.544
23.80	86.56	0.543
23.80	86.63	0.543
23.81	86.70	0.542
23.82	86.76	0.542
23.82	86.83	0.542
23.83	86.90	0.541
23.84	86.96	0.541
23.84	87.03	0.541
23.85	87.09	0.541
23.86	87.16	0.540
23.86	87.23	0.540
23.87	87.30	0.540
23.88	87.36	0.540
23.88	87.43	0.539
23.89	87.50	0.539
23.90	87.56	0.539
23.90	87.63	0.539
23.91	87.70	0.538
23.92	87.76	0.538
23.92	87.83	0.538
23.93	87.90	0.538
23.94	87.96	0.538
23.94	88.03	0.537
23.95	88.10	0.537
23.96	88.16	0.537
23.96	88.23	0.537
23.97	88.30	0.537
23.98	88.36	0.537
23.98	88.43	0.537
23.99	88.49	0.536
24.00	88.56	0.536
24.00	88.63	0.536
24.01	88.70	0.536
24.02	88.76	0.536
24.02	88.83	0.536
24.03	88.90	0.536
24.04	88.96	0.536
24.04	89.03	0.536
24.05	89.10	0.536
24.06	89.16	0.536
24.06	89.23	0.536
24.07	89.30	0.536
24.08	89.36	0.536
24.08	89.43	0.536
24.09	89.50	0.536
24.10	89.56	0.536
24.10	89.63	0.536
24.11	89.70	0.536
24.12	89.76	0.536
24.12	89.83	0.536
24.13	89.90	0.536
24.14	89.96	0.536
24.14	90.03	0.537
24.15	90.10	0.537
24.16	90.16	0.537
24.16	90.23	0.537
24.17	90.30	0.537
24.18	90.36	0.537
24.18	90.43	0.537
24.19	90.50	0.537
24.20	90.56	0.537
24.20	90.63	0.537
24.21	90.70	0.538
24.22	90.76	0.538
24.22	90.83	0.538
24.23	90.90	0.538
24.24	90.96	0.538
24.24	91.03	0.538
24.25	91.10	0.539
24.26	91.16	0.539
24.26	91.23	0.539
24.27	91.30	0.539
24.28	91.36	0.539
24.28	91.43	0.539
24.29	91.50	0.539
24.30	91.56	0.540
24.30	91.63	0.540
24.31	91.70	0.540
24.32	91.76	0.540
24.32	91.83	0.541
24.33	91.90	0.541
24.34	91.96	0.541
24.34	92.03	0.541
24.35	92.10	0.541
24.36	92.16	0.542
24.36	92.23	0.542
24.37	92.30	0.542
24.38	92.36	0.542
24.38	92.43	0.542
24.39	92.50	0.542
24.40	92.56	0.543
24.40	92.63	0.543
24.41	92.70	0.543
24.42	92.77	0.543
24.42	92.83	0.544
24.43	92.90	0.544
24.44	92.97	0.544
24.44	93.03	0.544
24.45	93.10	0.544
24.46	93.16	0.545
24.46	93.23	0.545
24.47	93.30	0.545
24.48	93.37	0.545
24.48	93.43	0.546
24.49	93.50	0.546
24.50	93.57	0.546
24.50	93.63	0.547
24.51	93.70	0.547
24.52	93.77	0.547
24.52	93.83	0.548
24.53	93.90	0.548
24.54	93.97	0.548
24.54	94.03	0.548
24.55	94.10	0.548
24.56	94.17	0.549
24.56	94.23	0.549
24.57	94.30	0.549
24.58	94.37	0.550
24.58	94.43	0.550
24.59	94.50	0.550
24.60	94.57	0.550
24.60	94.63	0.550
24.61	94.70	0.551
24.62	94.76	0.551
24.62	94.83	0.551
24.63	94.90	0.551
24.64	94.97	0.552
24.64	95.03	0.552
24.65	95.10	0.552
24.66	95.17	0.552
24.66	95.23	0.553
24.67	95.30	0.553
24.68	95.37	0.553
24.68	95.43	0.553
24.69	95.50	0.554
24.70	95.57	0.554
24.70	95.63	0.554
24.71	95.70	0.555
24.72	95.77	0.555
24.72	95.83	0.555
24.73	95.90	0.556
24.74	95.97	0.556
24.74	96.03	0.556
24.75	96.10	0.556
24.76	96.17	0.557
24.76	96.23	0.557
24.77	96.30	0.557
24.78	96.37	0.558
24.78	96.43	0.558
24.79	96.50	0.558
24.80	96.57	0.558
24.80	96.63	0.559
24.81	96.70	0.559
24.82	96.77	0.559
24.82	96.83	0.560
24.83	96.90	0.560
24.84	96.97	0.560
24.84	97.03	0.561
24.85	97.10	0.561
24.86	97.17	0.561
24.86	97.23	0.561
24.87	97.30	0.562
24.88	97.37	0.562
24.88	97.43	0.562
24.89	97.50	0.562
24.90	97.57	0.563
24.90	97.63	0.563
24.91	97.70	0.563
24.92	97.77	0.563
24.92	97.83	0.564
24.93	97.90	0.564
24.94	97.97	0.564
24.94	98.03	0.565
24.95	98.10	0.565
24.96	98.17	0.565
24.96	98.23	0.566
24.97	98.30	0.566
24.98	98.37	0.566
24.98	98.44	0.566
24.99	98.50	0.567
25.00	98.57	0.567
25.00	98.64	0.567
25.01	98.70	0.567
25.02	98.77	0.568
25.02	98.83	0.568
25.03	98.90	0.568
25.04	98.97	0.569
25.04	99.04	0.569
25.05	99.10	0.569
25.06	99.17	0.570
25.06	99.23	0.570
25.07	99.30	0.570
25.08	99.37	0.570
25.08	99.43	0.571
25.09	99.50	0.571
25.10	99.57	0.571
25.10	99.64	0.572
25.11	99.70	0.572
25.12	99.77	0.572
25.12	99.83	0.572
25.13	99.90	0.573
25.14	99.97	0.573
25.14	100.04	0.573
25.15	100.10	0.574
25.16	100.17	0.574
25.16	100.23	0.574
25.17	100.30	0.574
25.18	100.37	0.575
25.18	100.44	0.575
25.19	100.50	0.575
25.20	100.57	0.576
25.20	100.64	0.576
25.21	100.70	0.576
25.22	100.77	0.577
25.22	100.84	0.577
25.23	100.90	0.577
25.24	100.97	0.578
25.24	101.04	0.578
25.25	101.10	0.578
25.26	101.17	0.579
25.26	101.24	0.579
25.27	101.30	0.579
25.28	101.37	0.580
25.28	101.44	0.580
25.29	101.50	0.580
25.30	101.57	0.581
25.30	101.64	0.581
25.31	101.70	0.581
25.32	101.77	0.582
25.32	101.84	0.582
25.33	101.90	0.583
25.34	101.97	0.583
25.34	102.04	0.584
25.35	102.10	0.584
25.36	102.17	0.584
25.36	102.24	0.584
25.37	102.30	0.585
25.38	102.37	0.585
25.38	102.44	0.585
25.39	102.50	0.585
25.40	102.57	0.586
25.40	102.64	0.586
25.41	102.70	0.587
25.42	102.77	0.587
25.42	102.84	0.587
25.43	102.90	0.587
25.44	102.97	0.588
25.44	103.04	0.588
25.45	103.10	0.588
25.46	103.17	0.589
25.46	103.24	0.589
25.47	103.30	0.589
25.48	103.37	0.590
25.48	103.44	0.590
25.49	103.50	0.590
25.50	103.57	0.590
25.50	103.64	0.591
25.51	103.70	0.591
25.52	103.77	0.591
25.52	103.84	0.592
25.53	103.90	0.592
25.54	103.97	0.593
25.54	104.04	0.593
25.55	104.10	0.593
25.56	104.17	0.594
25.56	104.24	0.594
25.57	104.30	0.594
25.58	104.37	0.595
25.58	104.44	0.595
25.59	104.50	0.595
25.60	104.57	0.596
25.60	104.64	0.596
25.61	104.70	0.596
25.62	104.77	0.597
25.62	104.84	0.597
25.63	104.90	0.597
25.64	104.97	0.598
25.64	105.04	0.598
25.65	105.10	0.598
25.66	105.17	0.598
25.66	105.24	0.599
25.67	105.30	0.599
25.68	105.37	0.599
25.68	105.44	0.600
25.69	105.50	0.600
25.70	105.57	0.601
25.70	105.64	0.601
25.71	105.70	0.601
25.72	105.77	0.602
25.72	105.84	0.602
25.73	105.91	0.602
25.74	105.97	0.603
25.74	106.04	0.603
25.75	106.11	0.604
25.76	106.17	0.604
25.76	106.24	0.605
25.77	106.30	0.605
25.78	106.37	0.605
25.78	106.44	0.606
25.79	106.50	0.606
25.80	106.57	0.606
25.80	106.64	0.607
25.81	106.70	0.607
25.82	106.77	0.607
25.82	106.84	0.608
25.83	106.90	0.608
25.84	106.97	0.609
25.84	107.04	0.609
25.85	107.10	0.609
25.86	107.17	0.610
25.86	107.24	0.610
25.87	107.30	0.610
25.88	107.37	0.611
25.88	107.44	0.611
25.89	107.50	0.612
25.90	107.57	0.612
25.90	107.64	0.612
25.91	107.70	0.613
25.92	107.77	0.613
25.92	107.84	0.614
25.93	107.90	0.614
25.94	107.97	0.615
25.94	108.04	0.615
25.95	108.10
25.96	108.17
25.96	108.24
25.97	108.30
25.98	108.37
25.98	108.44
25.99	108.50
26.00
26.00