File: Data/2024_09_19_Empty_CHM343_DSC.txt
Filename	2024_09_19_Empty_CHM343_DSC
Instrument name	DSC2A-00468 (192.168.1.100)
Operator	CHM343
rundate	9/19/2024
Sample name	2024_09_19_Empty_CHM343_DSC
proceduresegments	Equilibrate 30.00 °C; Ramp 10.00 °C/min to 220.00 °C; Isothermal 1.0 min; Ramp 10.00 °C/min to 30.00 °C
[File Parameters]
Run date	9/19/2024 7:22:15 PM
Trios version	5.1.1.46572
Original File Name	C:\ProgramData\TA Instruments\TRIOS\Data\2024_09_19_Empty_CHM343_DSC.tri
Current File Name	D:\DSC2500\CHM343\2024_09_19_Empty_CHM343_DSC.tri
[Procedure]
Procedure Name	CHM343_Fall2024_Empty
Sample Name	2024_09_19_Empty_CHM343_DSC
Sample Mass	0 mg
Reference Sample Mass	0 mg
Pan Mass	54.56 mg
Pan Number	24
Reference Pan Mass	54 mg
Reference Pan Number	19
Pan Type	Aluminum
Comments	Empty- Al Hermetic Sealed Pan, with ref Al pan.  ASU Online CHM343, Remote DSC experimental lab. Fall 2024.  Group Zoom Data Collection, Sept 19, 2024 from 5-7 pm.  TA Instruments DSC2500.
Project Name	Lab 4 - Fall 2024
Operator	CHM343
Test	Custom
Unload Max Temperature	30
Unload Min Temperature	30
Load Max Temperature	30
Load Min Temperature	30
Stop on Gas Flow Error	Yes
[Signal List]
Signal #1	Time (min)
Signal #2	Temperature (°C)
Signal #3	Heat Flow (mW)
Signal #4	Delta T (µV)
Signal #5	Delta Tzero (µV)
Signal #6	Tzero Temperature (°C)
Signal #7	Cell Purge (mL/min)
Signal #8	Heater Temp (°C)
Signal #9	Power Delivered (W)
Signal #10	Reference Junction Temperature (°C)
Signal #11	Flange Temperature (°C)
Signal #12	Heat Flow Phase (rad)
Signal #13	Total Heat Capacity (J/°C)
Signal #14	Heat Capacity (J/°C)
[Configuration]
Company Name	ASU
Instrument Name	DSC2A-00468
Instrument Type	DSC2500
Serial Number	DSC2A-00468
IP	192.168.1.100
Location of Instrument	MRRC
DisplayType	Unknown
Sample Interval 	0.1 s/pt
Selected Heat Flow	T4P
Exotherm Direction	Down
Cell Serial	DRC2-00792
Lid Type	Standard
Cooler	RCS 90
Leave Cooler on at End of Sequence	On
Gas 2	Nitrogen
Gas Selected	Channel 1
Flow Rate	50 mL/min
Secondary Purge	On
Licensed Heat Flow	Heat Flow T4P
Modulation Licensed	Yes
[Versions]
Common IDD Version	1
Cortex Version	VER 2.10.2.31
Driver	5.0.0.6
GDM Version	1.0.3.3
TouchscreenVersion	1.0.0.16145
FEP Version	1.2.1.21
FEP Bootloader	2.0.0.5
AutoSampler Version	2.1.1.26
Auto Sampler Bootloader	2.0.0.5
FCM Version	1.1.0.3
FCM Bootloader	2.0.0.5
[Experiment Logs]
Experiment Log Entry # 1	Equilibrate Segment 30 (C) Started
Experiment Log Entry # 3	Air Cool is off.
Experiment Log Entry # 5	Ramp Segment 10 C/min to 220 Started
Experiment Log Entry # 7	Auto sampler has detected that FEP has gone offline
Experiment Log Entry # 9	Isothermal Segment 1 min started
Experiment Log Entry # 11	Ramp Segment 10 C/min to 30 Started
Experiment Log Entry # 13	Auto sampler has detected that FEP has gone offline
[Method Log]
Method Log Entry # 1	Equilibrate 30 °C
Method Log Entry # 2	(Ramp 19911) Ramp 10 °C/minute to 220 °C
Method Log Entry # 3	Isothermal 1 minutes
Method Log Entry # 4	(Ramp 19913) Ramp 10 °C/minute to 30 °C
Cell Serial	DRC2-00792
[T1 Calibration]
Slope	-0.008529666
Offset	9.636258
Initial Temperature	98.23
GUID	f8bfdadc-4977-4fdf-ba6d-0ba9134940c3
[TZero Calibration]
Date Applied	11/29/2022 4:06:13 PM
Description	From -89.059 °C to 396.009 °C at 20.000°C/min
Gas Type	Nitrogen
Pan Type	None
Source Files 1	C:\Users\yargerlab\Desktop\DSC Data\General\TZero_calibration_11_29_22_2nd(2).tri
Source Files 2	C:\Users\yargerlab\Desktop\DSC Data\General\TZero_calibration_11_29_22_2nd(3).tri
Delta T Offset	13.05235
Delta T Slope	-0.007271007
Delta T0 Offset	-13.69128
Delta T0 Slope	0.06063341
[Temperature Calibration]
Date Applied	11/29/2022 7:12:28 PM
Description	From 106.590 °C to 186.590 °C at 10.000°C/min
Gas Type	Nitrogen
Pan Type	Tzero Aluminum Hermetic
Source Files 1	C:\Users\yargerlab\Desktop\DSC Data\General\Indium(6).tri
Measured 1	157.391
Known 1	156.598
[Cell Constant Calibration]
Date Applied	11/29/2022 7:12:29 PM
Description	From 106.590 °C to 186.590 °C at 10.000°C/min
Gas Type	Nitrogen
Pan Type	Tzero Aluminum Hermetic
Source Files 1	C:\Users\yargerlab\Desktop\DSC Data\General\Indium(6).tri
T4P KCell	1.006051
Onset Slope	63.26126 mW/°C
[Direct Cp Calibration]
Date Applied	11/30/2022 11:04:51 AM
Description	From -79.983 °C to 298.409 °C at 10.000°C/min
Gas Type	Nitrogen
Pan Type	Tzero Aluminum Hermetic
Source Files 1	C:\Users\yargerlab\Desktop\DSC Data\General\Sapphire_Heat_Capacity_11_30_22.tri
[Rev Cp Calibration]
Date Applied	11/30/2022 1:58:51 PM
Description	From -79.996 °C to 292.812 °C at 3.000°C/min
Gas Type	Nitrogen
Pan Type	Tzero Aluminum Hermetic
Source Files 1	C:\Users\yargerlab\Desktop\DSC Data\General\Sapphire_MDSC_Calibration_11_30_22.tri
[step]
Ramp 10.00 °C/min to 220.00 °C
Time	Temperature	Heat Flow
min	°C	mW
0.00	30.08	-0.116
0.01	30.08	-0.116
0.03	30.08	-0.115
0.04	30.09	-0.115
0.05	30.10	-0.119
0.07	30.12	-0.176
0.08	30.15	-0.267
0.09	30.19	-0.352
0.11	30.24	-0.416
0.12	30.31	-0.463
0.13	30.38	-0.474
0.15	30.47	-0.464
0.16	30.56	-0.432
0.17	30.66	-0.386
0.19	30.77	-0.321
0.20	30.87	-0.261
0.21	30.98	-0.227
0.23	31.09	-0.188
0.24	31.21	-0.163
0.25	31.32	-0.130
0.27	31.44	-0.115
0.28	31.56	-0.097
0.29	31.68	-0.079
0.31	31.81	-0.063
0.32	31.93	-0.052
0.33	32.06	-0.033
0.35	32.18	-0.022
0.36	32.31	-0.008
0.37	32.44	0.000
0.39	32.56	0.008
0.40	32.69	0.019
0.41	32.82	0.023
0.43	32.95	0.028
0.44	33.08	0.034
0.45	33.21	0.037
0.47	33.34	0.039
0.48	33.47	0.043
0.49	33.60	0.045
0.51	33.73	0.047
0.52	33.87	0.049
0.53	33.99	0.050
0.55	34.13	0.053
0.56	34.26	0.053
0.57	34.39	0.055
0.59	34.52	0.056
0.60	34.65	0.057
0.61	34.78	0.058
0.63	34.92	0.059
0.64	35.05	0.060
0.65	35.18	0.061
0.67	35.31	0.062
0.68	35.44	0.063
0.69	35.58	0.064
0.71	35.71	0.065
0.72	35.84	0.065
0.73	35.97	0.067
0.75	36.10	0.067
0.76	36.24	0.068
0.77	36.37	0.069
0.79	36.50	0.070
0.80	36.63	0.070
0.81	36.77	0.071
0.83	36.90	0.071
0.84	37.03	0.072
0.85	37.16	0.073
0.87	37.30	0.073
0.88	37.43	0.073
0.89	37.56	0.073
0.91	37.69	0.074
0.92	37.82	0.074
0.93	37.96	0.074
0.95	38.09	0.075
0.96	38.22	0.075
0.97	38.36	0.075
0.99	38.49	0.075
1.00	38.62	0.076
1.01	38.75	0.076
1.03	38.89	0.076
1.04	39.02	0.076
1.05	39.15	0.076
1.07	39.29	0.076
1.08	39.42	0.077
1.09	39.55	0.076
1.11	39.68	0.077
1.12	39.82	0.076
1.13	39.95	0.077
1.15	40.08	0.077
1.16	40.21	0.077
1.17	40.35	0.077
1.19	40.48	0.077
1.20	40.61	0.077
1.21	40.75	0.077
1.23	40.88	0.077
1.24	41.01	0.077
1.25	41.15	0.077
1.27	41.28	0.077
1.28	41.41	0.077
1.29	41.55	0.076
1.31	41.68	0.076
1.32	41.81	0.076
1.33	41.95	0.077
1.35	42.08	0.076
1.36	42.21	0.076
1.37	42.34	0.076
1.39	42.48	0.076
1.40	42.61	0.076
1.41	42.74	0.076
1.43	42.88	0.075
1.44	43.01	0.075
1.45	43.14	0.075
1.47	43.28	0.075
1.48	43.41	0.075
1.49	43.54	0.075
1.51	43.68	0.075
1.52	43.81	0.075
1.53	43.94	0.075
1.55	44.08	0.074
1.56	44.21	0.074
1.57	44.34	0.074
1.59	44.48	0.074
1.60	44.61	0.074
1.61	44.74	0.074
1.63	44.88	0.074
1.64	45.01	0.074
1.65	45.14	0.074
1.67	45.28	0.073
1.68	45.41	0.073
1.69	45.54	0.073
1.71	45.68	0.073
1.72	45.81	0.073
1.73	45.94	0.073
1.75	46.08	0.072
1.76	46.21	0.073
1.77	46.34	0.072
1.79	46.48	0.072
1.80	46.61	0.072
1.81	46.74	0.072
1.83	46.88	0.072
1.84	47.01	0.072
1.85	47.14	0.071
1.87	47.28	0.071
1.88	47.41	0.071
1.89	47.54	0.071
1.91	47.68	0.071
1.92	47.81	0.071
1.93	47.94	0.071
1.95	48.08	0.071
1.96	48.21	0.071
1.97	48.34	0.071
1.99	48.48	0.071
2.00	48.61	0.070
2.01	48.74	0.070
2.03	48.88	0.070
2.04	49.01	0.070
2.05	49.14	0.069
2.07	49.28	0.070
2.08	49.41	0.069
2.09	49.54	0.069
2.11	49.68	0.069
2.12	49.81	0.069
2.13	49.94	0.069
2.15	50.08	0.068
2.16	50.21	0.068
2.17	50.34	0.068
2.19	50.48	0.068
2.20	50.61	0.067
2.21	50.74	0.067
2.23	50.88	0.067
2.24	51.01	0.067
2.25	51.15	0.066
2.27	51.28	0.066
2.28	51.41	0.066
2.29	51.54	0.066
2.31	51.68	0.066
2.32	51.81	0.066
2.33	51.94	0.066
2.35	52.08	0.066
2.36	52.21	0.066
2.37	52.34	0.065
2.39	52.48	0.065
2.40	52.61	0.065
2.41	52.75	0.065
2.43	52.88	0.065
2.44	53.01	0.065
2.45	53.14	0.064
2.47	53.28	0.064
2.48	53.41	0.064
2.49	53.54	0.064
2.51	53.68	0.064
2.52	53.81	0.064
2.53	53.95	0.063
2.55	54.08	0.063
2.56	54.21	0.063
2.57	54.35	0.063
2.59	54.48	0.063
2.60	54.61	0.062
2.61	54.75	0.062
2.63	54.88	0.062
2.64	55.01	0.062
2.65	55.15	0.062
2.67	55.28	0.062
2.68	55.41	0.062
2.69	55.55	0.062
2.71	55.68	0.062
2.72	55.81	0.061
2.73	55.95	0.062
2.75	56.08	0.061
2.76	56.22	0.061
2.77	56.35	0.061
2.79	56.48	0.061
2.80	56.62	0.061
2.81	56.75	0.061
2.83	56.88	0.061
2.84	57.02	0.061
2.85	57.15	0.060
2.87	57.28	0.061
2.88	57.42	0.060
2.89	57.55	0.060
2.91	57.68	0.061
2.92	57.82	0.060
2.93	57.95	0.060
2.95	58.08	0.060
2.96	58.22	0.060
2.97	58.35	0.060
2.99	58.48	0.059
3.00	58.62	0.060
3.01	58.75	0.059
3.03	58.88	0.059
3.04	59.02	0.059
3.05	59.15	0.059
3.07	59.28	0.059
3.08	59.42	0.059
3.09	59.55	0.059
3.11	59.68	0.059
3.12	59.82	0.058
3.13	59.95	0.058
3.15	60.09	0.058
3.16	60.22	0.058
3.17	60.35	0.058
3.19	60.48	0.058
3.20	60.62	0.058
3.21	60.75	0.057
3.23	60.89	0.057
3.24	61.02	0.057
3.25	61.15	0.057
3.27	61.29	0.057
3.28	61.42	0.057
3.29	61.55	0.057
3.31	61.68	0.057
3.32	61.82	0.057
3.33	61.95	0.057
3.35	62.09	0.057
3.36	62.22	0.057
3.37	62.35	0.057
3.39	62.49	0.056
3.40	62.62	0.056
3.41	62.75	0.056
3.43	62.89	0.056
3.44	63.02	0.056
3.45	63.15	0.056
3.47	63.29	0.056
3.48	63.42	0.055
3.49	63.55	0.056
3.51	63.69	0.055
3.52	63.82	0.055
3.53	63.95	0.055
3.55	64.09	0.055
3.56	64.22	0.055
3.57	64.35	0.055
3.59	64.49	0.055
3.60	64.62	0.055
3.61	64.75	0.055
3.63	64.89	0.055
3.64	65.02	0.055
3.65	65.15	0.055
3.67	65.29	0.055
3.68	65.42	0.055
3.69	65.56	0.055
3.71	65.69	0.054
3.72	65.82	0.054
3.73	65.96	0.054
3.75	66.09	0.054
3.76	66.22	0.054
3.77	66.36	0.054
3.79	66.49	0.054
3.80	66.62	0.054
3.81	66.76	0.054
3.83	66.89	0.054
3.84	67.02	0.054
3.85	67.16	0.053
3.87	67.29	0.053
3.88	67.42	0.053
3.89	67.56	0.053
3.91	67.69	0.053
3.92	67.82	0.053
3.93	67.96	0.053
3.95	68.09	0.053
3.96	68.23	0.053
3.97	68.36	0.053
3.99	68.49	0.052
4.00	68.62	0.052
4.01	68.76	0.052
4.03	68.89	0.052
4.04	69.02	0.052
4.05	69.16	0.052
4.07	69.29	0.052
4.08	69.43	0.052
4.09	69.56	0.052
4.11	69.69	0.052
4.12	69.83	0.051
4.13	69.96	0.051
4.15	70.09	0.051
4.16	70.23	0.051
4.17	70.36	0.051
4.19	70.49	0.051
4.20	70.63	0.051
4.21	70.76	0.051
4.23	70.89	0.051
4.24	71.03	0.050
4.25	71.16	0.050
4.27	71.29	0.050
4.28	71.43	0.050
4.29	71.56	0.050
4.31	71.70	0.050
4.32	71.83	0.050
4.33	71.96	0.049
4.35	72.09	0.049
4.36	72.23	0.050
4.37	72.36	0.049
4.39	72.49	0.049
4.40	72.63	0.049
4.41	72.76	0.049
4.43	72.90	0.049
4.44	73.03	0.049
4.45	73.16	0.049
4.47	73.30	0.049
4.48	73.43	0.049
4.49	73.56	0.048
4.51	73.70	0.048
4.52	73.83	0.048
4.53	73.96	0.048
4.55	74.10	0.048
4.56	74.23	0.048
4.57	74.36	0.048
4.59	74.50	0.048
4.60	74.63	0.048
4.61	74.76	0.048
4.63	74.90	0.048
4.64	75.03	0.048
4.65	75.16	0.047
4.67	75.30	0.047
4.68	75.43	0.047
4.69	75.56	0.047
4.71	75.70	0.047
4.72	75.83	0.047
4.73	75.96	0.047
4.75	76.10	0.047
4.76	76.23	0.047
4.77	76.37	0.047
4.79	76.50	0.047
4.80	76.63	0.047
4.81	76.77	0.047
4.83	76.90	0.047
4.84	77.03	0.047
4.85	77.17	0.047
4.87	77.30	0.047
4.88	77.43	0.047
4.89	77.57	0.047
4.91	77.70	0.047
4.92	77.83	0.046
4.93	77.97	0.046
4.95	78.10	0.046
4.96	78.23	0.046
4.97	78.37	0.046
4.99	78.50	0.046
5.00	78.63	0.046
5.01	78.77	0.046
5.03	78.90	0.046
5.04	79.03	0.046
5.05	79.17	0.046
5.07	79.30	0.046
5.08	79.43	0.045
5.09	79.57	0.045
5.11	79.70	0.045
5.12	79.84	0.045
5.13	79.97	0.045
5.15	80.10	0.045
5.16	80.24	0.045
5.17	80.37	0.045
5.19	80.50	0.045
5.20	80.63	0.045
5.21	80.77	0.045
5.23	80.90	0.045
5.24	81.04	0.045
5.25	81.17	0.044
5.27	81.30	0.044
5.28	81.44	0.044
5.29	81.57	0.044
5.31	81.70	0.044
5.32	81.84	0.044
5.33	81.97	0.043
5.35	82.10	0.043
5.36	82.24	0.043
5.37	82.37	0.043
5.39	82.50	0.043
5.40	82.64	0.043
5.41	82.77	0.043
5.43	82.90	0.043
5.44	83.04	0.043
5.45	83.17	0.042
5.47	83.30	0.042
5.48	83.44	0.042
5.49	83.57	0.042
5.51	83.70	0.042
5.52	83.84	0.042
5.53	83.97	0.041
5.55	84.10	0.041
5.56	84.24	0.041
5.57	84.37	0.041
5.59	84.50	0.041
5.60	84.64	0.041
5.61	84.77	0.041
5.63	84.91	0.041
5.64	85.04	0.040
5.65	85.17	0.040
5.67	85.31	0.040
5.68	85.44	0.040
5.69	85.57	0.040
5.71	85.71	0.040
5.72	85.84	0.040
5.73	85.97	0.039
5.75	86.11	0.039
5.76	86.24	0.039
5.77	86.37	0.038
5.79	86.51	0.038
5.80	86.64	0.038
5.81	86.77	0.038
5.83	86.91	0.038
5.84	87.04	0.038
5.85	87.17	0.038
5.87	87.31	0.038
5.88	87.44	0.038
5.89	87.57	0.038
5.91	87.71	0.037
5.92	87.84	0.037
5.93	87.97	0.037
5.95	88.11	0.037
5.96	88.24	0.037
5.97	88.37	0.037
5.99	88.51	0.037
6.00	88.64	0.037
6.01	88.77	0.037
6.03	88.91	0.037
6.04	89.04	0.037
6.05	89.17	0.037
6.07	89.31	0.037
6.08	89.44	0.037
6.09	89.57	0.036
6.11	89.71	0.036
6.12	89.84	0.036
6.13	89.98	0.036
6.15	90.11	0.036
6.16	90.24	0.036
6.17	90.38	0.036
6.19	90.51	0.036
6.20	90.64	0.036
6.21	90.78	0.037
6.23	90.91	0.036
6.24	91.04	0.037
6.25	91.18	0.036
6.27	91.31	0.036
6.28	91.44	0.037
6.29	91.57	0.037
6.31	91.71	0.037
6.32	91.84	0.036
6.33	91.98	0.036
6.35	92.11	0.036
6.36	92.24	0.036
6.37	92.38	0.036
6.39	92.51	0.036
6.40	92.64	0.036
6.41	92.78	0.036
6.43	92.91	0.036
6.44	93.04	0.036
6.45	93.18	0.036
6.47	93.31	0.036
6.48	93.44	0.036
6.49	93.58	0.036
6.51	93.71	0.036
6.52	93.85	0.037
6.53	93.98	0.037
6.55	94.11	0.037
6.56	94.25	0.037
6.57	94.38	0.037
6.59	94.51	0.037
6.60	94.65	0.037
6.61	94.78	0.037
6.63	94.91	0.036
6.64	95.05	0.036
6.65	95.18	0.037
6.67	95.31	0.037
6.68	95.45	0.037
6.69	95.58	0.037
6.71	95.71	0.037
6.72	95.85	0.037
6.73	95.98	0.037
6.75	96.11	0.037
6.76	96.25	0.037
6.77	96.38	0.037
6.79	96.51	0.037
6.80	96.65	0.037
6.81	96.78	0.037
6.83	96.91	0.037
6.84	97.05	0.037
6.85	97.18	0.037
6.87	97.31	0.037
6.88	97.45	0.037
6.89	97.58	0.037
6.91	97.71	0.037
6.92	97.85	0.037
6.93	97.98	0.037
6.95	98.11	0.037
6.96	98.25	0.037
6.97	98.38	0.037
6.99	98.51	0.037
7.00	98.65	0.037
7.01	98.78	0.037
7.03	98.91	0.037
7.04	99.05	0.037
7.05	99.18	0.037
7.07	99.32	0.036
7.08	99.45	0.037
7.09	99.58	0.036
7.11	99.72	0.036
7.12	99.85	0.036
7.13	99.98	0.036
7.15	100.11	0.036
7.16	100.25	0.036
7.17	100.38	0.037
7.19	100.52	0.036
7.20	100.65	0.036
7.21	100.78	0.036
7.23	100.92	0.036
7.24	101.05	0.036
7.25	101.18	0.036
7.27	101.32	0.036
7.28	101.45	0.036
7.29	101.58	0.036
7.31	101.72	0.035
7.32	101.85	0.036
7.33	101.98	0.035
7.35	102.12	0.035
7.36	102.25	0.035
7.37	102.38	0.035
7.39	102.52	0.035
7.40	102.65	0.035
7.41	102.78	0.035
7.43	102.92	0.035
7.44	103.05	0.035
7.45	103.18	0.035
7.47	103.32	0.035
7.48	103.45	0.035
7.49	103.58	0.035
7.51	103.72	0.035
7.52	103.85	0.035
7.53	103.99	0.035
7.55	104.12	0.035
7.56	104.25	0.035
7.57	104.39	0.035
7.59	104.52	0.035
7.60	104.65	0.035
7.61	104.79	0.035
7.63	104.92	0.035
7.64	105.05	0.035
7.65	105.19	0.035
7.67	105.32	0.035
7.68	105.45	0.035
7.69	105.59	0.035
7.71	105.72	0.035
7.72	105.85	0.035
7.73	105.99	0.035
7.75	106.12	0.035
7.76	106.25	0.034
7.77	106.39	0.034
7.79	106.52	0.034
7.80	106.65	0.034
7.81	106.79	0.034
7.83	106.92	0.034
7.84	107.05	0.034
7.85	107.19	0.034
7.87	107.32	0.034
7.88	107.45	0.034
7.89	107.59	0.034
7.91	107.72	0.034
7.92	107.85	0.034
7.93	107.99	0.034
7.95	108.12	0.034
7.96	108.25	0.034
7.97	108.39	0.034
7.99	108.52	0.034
8.00	108.66	0.034
8.01	108.79	0.034
8.03	108.92	0.034
8.04	109.06	0.034
8.05	109.19	0.034
8.07	109.32	0.034
8.08	109.45	0.034
8.09	109.59	0.034
8.11	109.72	0.034
8.12	109.86	0.034
8.13	109.99	0.034
8.15	110.12	0.034
8.16	110.25	0.033
8.17	110.39	0.033
8.19	110.52	0.033
8.20	110.66	0.034
8.21	110.79	0.034
8.23	110.92	0.033
8.24	111.06	0.033
8.25	111.19	0.033
8.27	111.32	0.033
8.28	111.46	0.033
8.29	111.59	0.033
8.31	111.72	0.033
8.32	111.86	0.033
8.33	111.99	0.033
8.35	112.12	0.033
8.36	112.26	0.033
8.37	112.39	0.033
8.39	112.52	0.033
8.40	112.66	0.033
8.41	112.79	0.033
8.43	112.92	0.033
8.44	113.06	0.033
8.45	113.19	0.033
8.47	113.32	0.033
8.48	113.46	0.033
8.49	113.59	0.033
8.51	113.72	0.033
8.52	113.86	0.033
8.53	113.99	0.033
8.55	114.13	0.033
8.56	114.26	0.033
8.57	114.39	0.033
8.59	114.52	0.033
8.60	114.66	0.032
8.61	114.79	0.032
8.63	114.93	0.032
8.64	115.06	0.032
8.65	115.19	0.032
8.67	115.33	0.032
8.68	115.46	0.033
8.69	115.59	0.032
8.71	115.73	0.032
8.72	115.86	0.032
8.73	115.99	0.032
8.75	116.12	0.032
8.76	116.26	0.032
8.77	116.39	0.032
8.79	116.53	0.032
8.80	116.66	0.032
8.81	116.79	0.031
8.83	116.93	0.032
8.84	117.06	0.031
8.85	117.19	0.031
8.87	117.33	0.031
8.88	117.46	0.031
8.89	117.59	0.031
8.91	117.73	0.031
8.92	117.86	0.031
8.93	117.99	0.031
8.95	118.13	0.031
8.96	118.26	0.031
8.97	118.39	0.030
8.99	118.53	0.030
9.00	118.66	0.031
9.01	118.79	0.031
9.03	118.93	0.030
9.04	119.06	0.031
9.05	119.19	0.031
9.07	119.33	0.030
9.08	119.46	0.030
9.09	119.59	0.030
9.11	119.73	0.030
9.12	119.86	0.030
9.13	119.99	0.030
9.15	120.13	0.030
9.16	120.26	0.030
9.17	120.39	0.030
9.19	120.53	0.030
9.20	120.66	0.030
9.21	120.80	0.030
9.23	120.93	0.029
9.24	121.06	0.029
9.25	121.20	0.029
9.27	121.33	0.029
9.28	121.46	0.029
9.29	121.60	0.029
9.31	121.73	0.029
9.32	121.86	0.029
9.33	122.00	0.029
9.35	122.13	0.029
9.36	122.26	0.029
9.37	122.40	0.029
9.39	122.53	0.029
9.40	122.66	0.029
9.41	122.80	0.029
9.43	122.93	0.029
9.44	123.06	0.029
9.45	123.20	0.029
9.47	123.33	0.029
9.48	123.46	0.029
9.49	123.60	0.029
9.51	123.73	0.029
9.52	123.86	0.029
9.53	124.00	0.029
9.55	124.13	0.029
9.56	124.26	0.029
9.57	124.40	0.028
9.59	124.53	0.029
9.60	124.67	0.028
9.61	124.80	0.028
9.63	124.93	0.028
9.64	125.06	0.029
9.65	125.20	0.029
9.67	125.33	0.028
9.68	125.46	0.028
9.69	125.60	0.028
9.71	125.73	0.028
9.72	125.87	0.028
9.73	126.00	0.028
9.75	126.13	0.028
9.76	126.26	0.028
9.77	126.40	0.028
9.79	126.53	0.028
9.80	126.67	0.028
9.81	126.80	0.028
9.83	126.93	0.028
9.84	127.07	0.028
9.85	127.20	0.028
9.87	127.33	0.028
9.88	127.47	0.028
9.89	127.60	0.027
9.91	127.73	0.027
9.92	127.87	0.027
9.93	128.00	0.027
9.95	128.13	0.027
9.96	128.27	0.027
9.97	128.40	0.027
9.99	128.53	0.027
10.00	128.67	0.027
10.01	128.80	0.027
10.03	128.93	0.027
10.04	129.07	0.027
10.05	129.20	0.026
10.07	129.33	0.027
10.08	129.47	0.026
10.09	129.60	0.026
10.11	129.73	0.026
10.12	129.87	0.026
10.13	130.00	0.026
10.15	130.14	0.026
10.16	130.27	0.026
10.17	130.40	0.026
10.19	130.53	0.026
10.20	130.67	0.026
10.21	130.80	0.026
10.23	130.93	0.026
10.24	131.07	0.026
10.25	131.20	0.026
10.27	131.33	0.026
10.28	131.47	0.026
10.29	131.60	0.025
10.31	131.74	0.026
10.32	131.87	0.025
10.33	132.00	0.025
10.35	132.14	0.025
10.36	132.27	0.025
10.37	132.40	0.025
10.39	132.54	0.025
10.40	132.67	0.025
10.41	132.80	0.025
10.43	132.94	0.025
10.44	133.07	0.025
10.45	133.20	0.025
10.47	133.34	0.025
10.48	133.47	0.025
10.49	133.60	0.025
10.51	133.74	0.025
10.52	133.87	0.025
10.53	134.00	0.025
10.55	134.14	0.025
10.56	134.27	0.025
10.57	134.40	0.025
10.59	134.54	0.025
10.60	134.67	0.025
10.61	134.80	0.024
10.63	134.94	0.025
10.64	135.07	0.024
10.65	135.20	0.024
10.67	135.34	0.024
10.68	135.47	0.024
10.69	135.60	0.024
10.71	135.74	0.025
10.72	135.87	0.025
10.73	136.01	0.025
10.75	136.14	0.025
10.76	136.27	0.025
10.77	136.40	0.025
10.79	136.54	0.025
10.80	136.67	0.025
10.81	136.80	0.025
10.83	136.94	0.024
10.84	137.07	0.025
10.85	137.20	0.024
10.87	137.34	0.024
10.88	137.47	0.024
10.89	137.60	0.024
10.91	137.74	0.024
10.92	137.87	0.024
10.93	138.00	0.024
10.95	138.14	0.024
10.96	138.27	0.024
10.97	138.40	0.024
10.99	138.54	0.024
11.00	138.67	0.024
11.01	138.81	0.024
11.03	138.94	0.024
11.04	139.07	0.024
11.05	139.21	0.024
11.07	139.34	0.024
11.08	139.47	0.024
11.09	139.61	0.024
11.11	139.74	0.024
11.12	139.87	0.024
11.13	140.01	0.024
11.15	140.14	0.024
11.16	140.27	0.024
11.17	140.41	0.024
11.19	140.54	0.024
11.20	140.67	0.024
11.21	140.81	0.024
11.23	140.94	0.024
11.24	141.07	0.024
11.25	141.21	0.024
11.27	141.34	0.024
11.28	141.47	0.024
11.29	141.61	0.024
11.31	141.74	0.024
11.32	141.87	0.023
11.33	142.01	0.023
11.35	142.14	0.024
11.36	142.27	0.023
11.37	142.41	0.023
11.39	142.54	0.024
11.40	142.67	0.024
11.41	142.81	0.024
11.43	142.94	0.023
11.44	143.07	0.023
11.45	143.21	0.024
11.47	143.34	0.024
11.48	143.47	0.024
11.49	143.61	0.023
11.51	143.74	0.023
11.52	143.87	0.023
11.53	144.01	0.023
11.55	144.14	0.024
11.56	144.28	0.023
11.57	144.41	0.023
11.59	144.54	0.023
11.60	144.68	0.023
11.61	144.81	0.023
11.63	144.94	0.023
11.64	145.08	0.023
11.65	145.21	0.023
11.67	145.34	0.023
11.68	145.48	0.023
11.69	145.61	0.023
11.71	145.74	0.023
11.72	145.88	0.023
11.73	146.01	0.023
11.75	146.14	0.023
11.76	146.28	0.023
11.77	146.41	0.023
11.79	146.54	0.023
11.80	146.68	0.023
11.81	146.81	0.023
11.83	146.94	0.023
11.84	147.08	0.023
11.85	147.21	0.023
11.87	147.34	0.023
11.88	147.48	0.023
11.89	147.61	0.023
11.91	147.74	0.022
11.92	147.88	0.022
11.93	148.01	0.022
11.95	148.14	0.022
11.96	148.28	0.022
11.97	148.41	0.022
11.99	148.55	0.022
12.00	148.68	0.022
12.01	148.81	0.022
12.03	148.94	0.022
12.04	149.08	0.023
12.05	149.21	0.023
12.07	149.34	0.023
12.08	149.48	0.023
12.09	149.61	0.023
12.11	149.74	0.023
12.12	149.88	0.023
12.13	150.01	0.023
12.15	150.14	0.023
12.16	150.28	0.023
12.17	150.41	0.023
12.19	150.54	0.023
12.20	150.68	0.023
12.21	150.81	0.023
12.23	150.94	0.023
12.24	151.08	0.023
12.25	151.21	0.023
12.27	151.35	0.023
12.28	151.48	0.023
12.29	151.61	0.023
12.31	151.75	0.023
12.32	151.88	0.023
12.33	152.01	0.024
12.35	152.15	0.023
12.36	152.28	0.023
12.37	152.41	0.024
12.39	152.55	0.024
12.40	152.68	0.024
12.41	152.81	0.024
12.43	152.95	0.024
12.44	153.08	0.024
12.45	153.21	0.024
12.47	153.35	0.024
12.48	153.48	0.024
12.49	153.61	0.024
12.51	153.75	0.025
12.52	153.88	0.025
12.53	154.01	0.025
12.55	154.15	0.025
12.56	154.28	0.025
12.57	154.41	0.025
12.59	154.55	0.025
12.60	154.68	0.025
12.61	154.81	0.025
12.63	154.95	0.024
12.64	155.08	0.025
12.65	155.21	0.024
12.67	155.35	0.024
12.68	155.48	0.024
12.69	155.61	0.025
12.71	155.75	0.024
12.72	155.88	0.024
12.73	156.01	0.025
12.75	156.15	0.025
12.76	156.28	0.025
12.77	156.41	0.025
12.79	156.55	0.025
12.80	156.68	0.025
12.81	156.81	0.025
12.83	156.95	0.025
12.84	157.08	0.026
12.85	157.22	0.026
12.87	157.35	0.026
12.88	157.48	0.026
12.89	157.61	0.026
12.91	157.75	0.026
12.92	157.88	0.026
12.93	158.02	0.026
12.95	158.15	0.026
12.96	158.28	0.026
12.97	158.41	0.026
12.99	158.55	0.026
13.00	158.68	0.026
13.01	158.82	0.026
13.03	158.95	0.026
13.04	159.08	0.026
13.05	159.22	0.027
13.07	159.35	0.027
13.08	159.48	0.027
13.09	159.61	0.027
13.11	159.75	0.027
13.12	159.88	0.028
13.13	160.01	0.028
13.15	160.15	0.028
13.16	160.28	0.028
13.17	160.41	0.028
13.19	160.55	0.028
13.20	160.68	0.028
13.21	160.82	0.028
13.23	160.95	0.028
13.24	161.08	0.028
13.25	161.22	0.028
13.27	161.35	0.028
13.28	161.48	0.028
13.29	161.62	0.028
13.31	161.75	0.029
13.32	161.88	0.029
13.33	162.02	0.029
13.35	162.15	0.029
13.36	162.28	0.029
13.37	162.42	0.030
13.39	162.55	0.030
13.40	162.68	0.030
13.41	162.82	0.030
13.43	162.95	0.029
13.44	163.08	0.029
13.45	163.22	0.029
13.47	163.35	0.030
13.48	163.48	0.029
13.49	163.62	0.030
13.51	163.75	0.030
13.52	163.88	0.030
13.53	164.02	0.030
13.55	164.15	0.030
13.56	164.28	0.030
13.57	164.42	0.030
13.59	164.55	0.031
13.60	164.68	0.031
13.61	164.82	0.031
13.63	164.95	0.031
13.64	165.08	0.031
13.65	165.22	0.031
13.67	165.35	0.031
13.68	165.48	0.031
13.69	165.62	0.031
13.71	165.75	0.031
13.72	165.88	0.031
13.73	166.02	0.031
13.75	166.15	0.031
13.76	166.28	0.031
13.77	166.42	0.031
13.79	166.55	0.031
13.80	166.69	0.032
13.81	166.82	0.032
13.83	166.95	0.032
13.84	167.09	0.032
13.85	167.22	0.032
13.87	167.35	0.033
13.88	167.48	0.033
13.89	167.62	0.033
13.91	167.75	0.033
13.92	167.88	0.033
13.93	168.02	0.033
13.95	168.15	0.033
13.96	168.28	0.034
13.97	168.42	0.034
13.99	168.55	0.034
14.00	168.69	0.034
14.01	168.82	0.034
14.03	168.95	0.034
14.04	169.08	0.034
14.05	169.22	0.034
14.07	169.35	0.034
14.08	169.49	0.034
14.09	169.62	0.034
14.11	169.75	0.035
14.12	169.89	0.035
14.13	170.02	0.035
14.15	170.15	0.035
14.16	170.29	0.036
14.17	170.42	0.036
14.19	170.55	0.036
14.20	170.69	0.036
14.21	170.82	0.036
14.23	170.95	0.036
14.24	171.09	0.036
14.25	171.22	0.037
14.27	171.35	0.037
14.28	171.49	0.037
14.29	171.62	0.037
14.31	171.75	0.037
14.32	171.89	0.038
14.33	172.02	0.038
14.35	172.15	0.038
14.36	172.29	0.038
14.37	172.42	0.038
14.39	172.55	0.038
14.40	172.69	0.038
14.41	172.82	0.038
14.43	172.95	0.038
14.44	173.09	0.039
14.45	173.22	0.039
14.47	173.35	0.039
14.48	173.49	0.039
14.49	173.62	0.039
14.51	173.75	0.040
14.52	173.89	0.040
14.53	174.02	0.040
14.55	174.15	0.040
14.56	174.29	0.041
14.57	174.42	0.041
14.59	174.55	0.041
14.60	174.69	0.042
14.61	174.82	0.042
14.63	174.96	0.042
14.64	175.09	0.043
14.65	175.22	0.043
14.67	175.35	0.043
14.68	175.49	0.043
14.69	175.62	0.044
14.71	175.75	0.044
14.72	175.89	0.045
14.73	176.02	0.045
14.75	176.15	0.045
14.76	176.29	0.045
14.77	176.42	0.046
14.79	176.55	0.046
14.80	176.69	0.046
14.81	176.82	0.047
14.83	176.96	0.047
14.84	177.09	0.047
14.85	177.22	0.048
14.87	177.35	0.048
14.88	177.49	0.049
14.89	177.62	0.049
14.91	177.75	0.050
14.92	177.89	0.050
14.93	178.02	0.050
14.95	178.16	0.050
14.96	178.29	0.050
14.97	178.42	0.050
14.99	178.55	0.050
15.00	178.69	0.051
15.01	178.82	0.051
15.03	178.95	0.051
15.04	179.09	0.051
15.05	179.22	0.052
15.07	179.36	0.052
15.08	179.49	0.053
15.09	179.62	0.053
15.11	179.76	0.053
15.12	179.89	0.054
15.13	180.02	0.054
15.15	180.16	0.054
15.16	180.29	0.054
15.17	180.42	0.055
15.19	180.56	0.055
15.20	180.69	0.055
15.21	180.82	0.055
15.23	180.96	0.056
15.24	181.09	0.056
15.25	181.22	0.056
15.27	181.36	0.056
15.28	181.49	0.057
15.29	181.62	0.057
15.31	181.76	0.057
15.32	181.89	0.057
15.33	182.02	0.057
15.35	182.16	0.058
15.36	182.29	0.058
15.37	182.42	0.059
15.39	182.56	0.060
15.40	182.69	0.060
15.41	182.82	0.060
15.43	182.96	0.061
15.44	183.09	0.061
15.45	183.22	0.062
15.47	183.36	0.062
15.48	183.49	0.062
15.49	183.62	0.063
15.51	183.76	0.064
15.52	183.89	0.064
15.53	184.02	0.064
15.55	184.16	0.065
15.56	184.29	0.065
15.57	184.42	0.066
15.59	184.56	0.066
15.60	184.69	0.067
15.61	184.82	0.067
15.63	184.96	0.068
15.64	185.09	0.068
15.65	185.22	0.069
15.67	185.36	0.069
15.68	185.49	0.069
15.69	185.62	0.070
15.71	185.76	0.070
15.72	185.89	0.070
15.73	186.02	0.071
15.75	186.16	0.071
15.76	186.29	0.072
15.77	186.42	0.072
15.79	186.56	0.072
15.80	186.69	0.073
15.81	186.82	0.073
15.83	186.96	0.073
15.84	187.09	0.074
15.85	187.22	0.074
15.87	187.36	0.075
15.88	187.49	0.075
15.89	187.62	0.076
15.91	187.76	0.076
15.92	187.89	0.076
15.93	188.02	0.077
15.95	188.16	0.077
15.96	188.29	0.078
15.97	188.42	0.078
15.99	188.56	0.078
16.00	188.69	0.078
16.01	188.82	0.079
16.03	188.96	0.079
16.04	189.09	0.079
16.05	189.22	0.080
16.07	189.36	0.080
16.08	189.49	0.080
16.09	189.62	0.081
16.11	189.76	0.081
16.12	189.89	0.081
16.13	190.02	0.081
16.15	190.16	0.082
16.16	190.29	0.082
16.17	190.42	0.082
16.19	190.56	0.082
16.20	190.69	0.083
16.21	190.82	0.083
16.23	190.96	0.083
16.24	191.09	0.083
16.25	191.23	0.084
16.27	191.36	0.084
16.28	191.49	0.084
16.29	191.63	0.084
16.31	191.76	0.085
16.32	191.89	0.085
16.33	192.02	0.085
16.35	192.16	0.085
16.36	192.29	0.086
16.37	192.43	0.086
16.39	192.56	0.086
16.40	192.69	0.086
16.41	192.83	0.086
16.43	192.96	0.086
16.44	193.09	0.086
16.45	193.23	0.087
16.47	193.36	0.087
16.48	193.49	0.087
16.49	193.63	0.087
16.51	193.76	0.087
16.52	193.89	0.087
16.53	194.03	0.087
16.55	194.16	0.087
16.56	194.29	0.088
16.57	194.43	0.088
16.59	194.56	0.088
16.60	194.69	0.088
16.61	194.83	0.088
16.63	194.96	0.089
16.64	195.09	0.089
16.65	195.23	0.089
16.67	195.36	0.089
16.68	195.49	0.089
16.69	195.63	0.089
16.71	195.76	0.089
16.72	195.89	0.089
16.73	196.03	0.090
16.75	196.16	0.090
16.76	196.29	0.090
16.77	196.43	0.090
16.79	196.56	0.090
16.80	196.69	0.090
16.81	196.83	0.090
16.83	196.96	0.091
16.84	197.09	0.091
16.85	197.23	0.091
16.87	197.36	0.091
16.88	197.49	0.091
16.89	197.63	0.092
16.91	197.76	0.091
16.92	197.89	0.092
16.93	198.03	0.092
16.95	198.16	0.092
16.96	198.29	0.092
16.97	198.43	0.092
16.99	198.56	0.092
17.00	198.69	0.092
17.01	198.83	0.092
17.03	198.96	0.092
17.04	199.09	0.093
17.05	199.23	0.093
17.07	199.36	0.093
17.08	199.49	0.093
17.09	199.63	0.094
17.11	199.76	0.094
17.12	199.89	0.094
17.13	200.03	0.094
17.15	200.16	0.095
17.16	200.29	0.095
17.17	200.43	0.095
17.19	200.56	0.095
17.20	200.69	0.095
17.21	200.83	0.096
17.23	200.96	0.096
17.24	201.09	0.096
17.25	201.23	0.096
17.27	201.36	0.096
17.28	201.49	0.097
17.29	201.63	0.097
17.31	201.76	0.097
17.32	201.89	0.097
17.33	202.03	0.097
17.35	202.16	0.097
17.36	202.29	0.098
17.37	202.43	0.098
17.39	202.56	0.098
17.40	202.69	0.098
17.41	202.83	0.098
17.43	202.96	0.098
17.44	203.10	0.098
17.45	203.23	0.099
17.47	203.36	0.099
17.48	203.50	0.099
17.49	203.63	0.099
17.51	203.76	0.100
17.52	203.90	0.100
17.53	204.03	0.100
17.55	204.16	0.100
17.56	204.29	0.100
17.57	204.43	0.100
17.59	204.56	0.100
17.60	204.69	0.100
17.61	204.83	0.100
17.63	204.96	0.100
17.64	205.09	0.100
17.65	205.23	0.100
17.67	205.36	0.101
17.68	205.49	0.101
17.69	205.63	0.101
17.71	205.76	0.101
17.72	205.90	0.101
17.73	206.03	0.101
17.75	206.16	0.102
17.76	206.30	0.102
17.77	206.43	0.102
17.79	206.56	0.102
17.80	206.70	0.102
17.81	206.83	0.102
17.83	206.96	0.102
17.84	207.09	0.102
17.85	207.23	0.102
17.87	207.36	0.102
17.88	207.50	0.102
17.89	207.63	0.102
17.91	207.76	0.102
17.92	207.90	0.103
17.93	208.03	0.103
17.95	208.16	0.103
17.96	208.30	0.103
17.97	208.43	0.103
17.99	208.56	0.103
18.00	208.70	0.103
18.01	208.83	0.104
18.03	208.96	0.104
18.04	209.10	0.104
18.05	209.23	0.104
18.07	209.36	0.104
18.08	209.50	0.104
18.09	209.63	0.104
18.11	209.76	0.104
18.12	209.90	0.104
18.13	210.03	0.104
18.15	210.16	0.105
18.16	210.30	0.105
18.17	210.43	0.105
18.19	210.56	0.105
18.20	210.70	0.105
18.21	210.83	0.105
18.23	210.96	0.105
18.24	211.10	0.105
18.25	211.23	0.106
18.27	211.36	0.106
18.28	211.50	0.106
18.29	211.63	0.106
18.31	211.76	0.106
18.32	211.90	0.106
18.33	212.03	0.106
18.35	212.16	0.106
18.36	212.30	0.107
18.37	212.43	0.107
18.39	212.56	0.107
18.40	212.70	0.107
18.41	212.83	0.107
18.43	212.96	0.108
18.44	213.10	0.108
18.45	213.23	0.108
18.47	213.36	0.108
18.48	213.50	0.108
18.49	213.63	0.108
18.51	213.76	0.108
18.52	213.90	0.109
18.53	214.03	0.109
18.55	214.16	0.109
18.56	214.30	0.109
18.57	214.43	0.109
18.59	214.56	0.109
18.60	214.70	0.109
18.61	214.83	0.109
18.63	214.96	0.109
18.64	215.10	0.110
18.65	215.23	0.110
18.67	215.36	0.110
18.68	215.50	0.110
18.69	215.63	0.111
18.71	215.76	0.111
18.72	215.90	0.111
18.73	216.03	0.111
18.75	216.16	0.111
18.76	216.30	0.112
18.77	216.43	0.112
18.79	216.56	0.112
18.80	216.70	0.112
18.81	216.83	0.113
18.83	216.96	0.113
18.84	217.10	0.113
18.85	217.23	0.113
18.87	217.36	0.113
18.88	217.50	0.113
18.89	217.63	0.114
18.91	217.77	0.114
18.92	217.90	0.114
18.93	218.03	0.114
18.95	218.16	0.114
18.96	218.30	0.114
18.97	218.43	0.115
18.99	218.57	0.115
19.00	218.70	0.115

[step]
Ramp 10.00 °C/min to 30.00 °C
Time	Temperature	Heat Flow (Normalized)
min	°C	W/g
20.00	220.07
20.02	220.07
20.03	220.07
20.04	220.06
20.06	220.05
20.07	220.04
20.08	220.02
20.09	219.98
20.11	219.93
20.12	219.88
20.13	219.81
20.15	219.72
20.16	219.63
20.18	219.53
20.19	219.43
20.20	219.32
20.22	219.21
20.23	219.09
20.24	218.97
20.26	218.85
20.27	218.73
20.28	218.60
20.29	218.48
20.31	218.35
20.32	218.22
20.33	218.10
20.35	217.97
20.36	217.84
20.38	217.71
20.39	217.58
20.40	217.45
20.42	217.32
20.43	217.19
20.44	217.06
20.46	216.93
20.47	216.80
20.48	216.67
20.49	216.54
20.51	216.41
20.52	216.28
20.53	216.15
20.55	216.01
20.56	215.88
20.58	215.75
20.59	215.62
20.60	215.49
20.62	215.36
20.63	215.22
20.64	215.09
20.66	214.96
20.67	214.83
20.68	214.70
20.69	214.56
20.71	214.43
20.72	214.30
20.73	214.17
20.75	214.04
20.76	213.90
20.78	213.77
20.79	213.64
20.80	213.51
20.82	213.38
20.83	213.24
20.84	213.11
20.86	212.98
20.87	212.85
20.88	212.71
20.89	212.58
20.91	212.45
20.92	212.32
20.93	212.19
20.95	212.05
20.96	211.92
20.98	211.79
20.99	211.66
21.00	211.52
21.02	211.39
21.03	211.26
21.04	211.13
21.06	210.99
21.07	210.86
21.08	210.73
21.09	210.60
21.11	210.46
21.12	210.33
21.13	210.20
21.15	210.07
21.16	209.93
21.18	209.80
21.19	209.67
21.20	209.53
21.22	209.40
21.23	209.27
21.24	209.14
21.26	209.00
21.27	208.87
21.28	208.74
21.29	208.60
21.31	208.47
21.32	208.34
21.33	208.21
21.35	208.07
21.36	207.94
21.38	207.81
21.39	207.67
21.40	207.54
21.42	207.41
21.43	207.28
21.44	207.14
21.46	207.01
21.47	206.88
21.48	206.74
21.49	206.61
21.51	206.48
21.52	206.34
21.53	206.21
21.55	206.08
21.56	205.95
21.58	205.81
21.59	205.68
21.60	205.55
21.62	205.41
21.63	205.28
21.64	205.15
21.66	205.01
21.67	204.88
21.68	204.75
21.69	204.62
21.71	204.48
21.72	204.35
21.73	204.22
21.75	204.08
21.76	203.95
21.78	203.82
21.79	203.68
21.80	203.55
21.82	203.42
21.83	203.29
21.84	203.15
21.86	203.02
21.87	202.89
21.88	202.75
21.89	202.62
21.91	202.49
21.92	202.35
21.93	202.22
21.95	202.09
21.96	201.95
21.98	201.82
21.99	201.69
22.00	201.55
22.02	201.42
22.03	201.29
22.04	201.16
22.06	201.02
22.07	200.89
22.08	200.76
22.09	200.62
22.11	200.49
22.12	200.36
22.13	200.22
22.15	200.09
22.16	199.96
22.18	199.82
22.19	199.69
22.20	199.56
22.22	199.42
22.23	199.29
22.24	199.16
22.26	199.02
22.27	198.89
22.28	198.76
22.29	198.63
22.31	198.49
22.32	198.36
22.33	198.23
22.35	198.09
22.36	197.96
22.38	197.83
22.39	197.69
22.40	197.56
22.42	197.43
22.43	197.29
22.44	197.16
22.46	197.03
22.47	196.89
22.48	196.76
22.49	196.63
22.51	196.50
22.52	196.36
22.53	196.23
22.55	196.10
22.56	195.96
22.58	195.83
22.59	195.70
22.60	195.56
22.62	195.43
22.63	195.30
22.64	195.16
22.66	195.03
22.67	194.90
22.68	194.76
22.69	194.63
22.71	194.50
22.72	194.37
22.73	194.23
22.75	194.10
22.76	193.96
22.78	193.83
22.79	193.70
22.80	193.57
22.82	193.43
22.83	193.30
22.84	193.17
22.86	193.03
22.87	192.90
22.88	192.77
22.89	192.63
22.91	192.50
22.92	192.37
22.93	192.23
22.95	192.10
22.96	191.97
22.98	191.83
22.99	191.70
23.00	191.57
23.02	191.44
23.03	191.30
23.04	191.17
23.06	191.03
23.07	190.90
23.08	190.77
23.09	190.64
23.11	190.50
23.12	190.37
23.13	190.24
23.15	190.10
23.16	189.97
23.18	189.84
23.19	189.70
23.20	189.57
23.22	189.44
23.23	189.30
23.24	189.17
23.26	189.04
23.27	188.91
23.28	188.77
23.29	188.64
23.31	188.51
23.32	188.37
23.33	188.24
23.35	188.11
23.36	187.97
23.38	187.84
23.39	187.71
23.40	187.57
23.42	187.44
23.43	187.31
23.44	187.17
23.46	187.04
23.47	186.91
23.48	186.77
23.49	186.64
23.51	186.51
23.52	186.37
23.53	186.24
23.55	186.11
23.56	185.97
23.58	185.84
23.59	185.71
23.60	185.58
23.62	185.44
23.63	185.31
23.64	185.18
23.66	185.04
23.67	184.91
23.68	184.78
23.69	184.64
23.71	184.51
23.72	184.38
23.73	184.24
23.75	184.11
23.76	183.98
23.78	183.84
23.79	183.71
23.80	183.58
23.82	183.44
23.83	183.31
23.84	183.18
23.86	183.04
23.87	182.91
23.88	182.78
23.89	182.64
23.91	182.51
23.92	182.38
23.93	182.25
23.95	182.11
23.96	181.98
23.98	181.85
23.99	181.71
24.00	181.58
24.02	181.45
24.03	181.31
24.04	181.18
24.06	181.05
24.07	180.91
24.08	180.78
24.09	180.65
24.11	180.51
24.12	180.38
24.13	180.25
24.15	180.11
24.16	179.98
24.18	179.85
24.19	179.71
24.20	179.58
24.22	179.45
24.23	179.31
24.24	179.18
24.26	179.05
24.27	178.91
24.28	178.78
24.29	178.65
24.31	178.52
24.32	178.38
24.33	178.25
24.35	178.12
24.36	177.98
24.38	177.85
24.39	177.72
24.40	177.58
24.42	177.45
24.43	177.32
24.44	177.19
24.46	177.05
24.47	176.92
24.48	176.78
24.49	176.65
24.51	176.52
24.52	176.38
24.53	176.25
24.55	176.12
24.56	175.99
24.58	175.85
24.59	175.72
24.60	175.59
24.62	175.45
24.63	175.32
24.64	175.19
24.66	175.05
24.67	174.92
24.68	174.79
24.69	174.65
24.71	174.52
24.72	174.39
24.73	174.25
24.75	174.12
24.76	173.99
24.78	173.85
24.79	173.72
24.80	173.59
24.82	173.45
24.83	173.32
24.84	173.19
24.86	173.05
24.87	172.92
24.88	172.79
24.89	172.66
24.91	172.52
24.92	172.39
24.93	172.25
24.95	172.12
24.96	171.99
24.98	171.86
24.99	171.72
25.00	171.59
25.02	171.46
25.03	171.32
25.04	171.19
25.06	171.06
25.07	170.92
25.08	170.79
25.09	170.66
25.11	170.52
25.12	170.39
25.13	170.26
25.15	170.12
25.16	169.99
25.18	169.86
25.19	169.72
25.20	169.59
25.22	169.46
25.23	169.32
25.24	169.19
25.26	169.06
25.27	168.93
25.28	168.79
25.29	168.66
25.31	168.53
25.32	168.39
25.33	168.26
25.35	168.13
25.36	167.99
25.38	167.86
25.39	167.73
25.40	167.59
25.42	167.46
25.43	167.33
25.44	167.19
25.46	167.06
25.47	166.93
25.48	166.79
25.49	166.66
25.51	166.53
25.52	166.40
25.53	166.26
25.55	166.13
25.56	166.00
25.58	165.86
25.59	165.73
25.60	165.60
25.62	165.46
25.63	165.33
25.64	165.20
25.66	165.06
25.67	164.93
25.68	164.80
25.69	164.66
25.71	164.53
25.72	164.40
25.73	164.26
25.75	164.13
25.76	164.00
25.78	163.87
25.79	163.73
25.80	163.60
25.82	163.47
25.83	163.33
25.84	163.20
25.86	163.07
25.87	162.93
25.88	162.80
25.89	162.67
25.91	162.53
25.92	162.40
25.93	162.27
25.95	162.13
25.96	162.00
25.98	161.87
25.99	161.73
26.00	161.60
26.02	161.47
26.03	161.33
26.04	161.20
26.06	161.07
26.07	160.93
26.08	160.80
26.09	160.67
26.11	160.53
26.12	160.40
26.13	160.27
26.15	160.13
26.16	160.00
26.18	159.87
26.19	159.73
26.20	159.60
26.22	159.47
26.23	159.34
26.24	159.20
26.26	159.07
26.27	158.93
26.28	158.80
26.29	158.67
26.31	158.54
26.32	158.40
26.33	158.27
26.35	158.14
26.36	158.00
26.38	157.87
26.39	157.74
26.40	157.60
26.42	157.47
26.43	157.34
26.44	157.20
26.46	157.07
26.47	156.94
26.48	156.80
26.49	156.67
26.51	156.54
26.52	156.40
26.53	156.27
26.55	156.14
26.56	156.00
26.58	155.87
26.59	155.74
26.60	155.60
26.62	155.47
26.63	155.34
26.64	155.21
26.66	155.07
26.67	154.94
26.68	154.81
26.69	154.67
26.71	154.54
26.72	154.41
26.73	154.27
26.75	154.14
26.76	154.01
26.78	153.87
26.79	153.74
26.80	153.61
26.82	153.47
26.83	153.34
26.84	153.21
26.86	153.07
26.87	152.94
26.88	152.81
26.89	152.67
26.91	152.54
26.92	152.41
26.93	152.28
26.95	152.14
26.96	152.01
26.98	151.88
26.99	151.74
27.00	151.61
27.02	151.48
27.03	151.34
27.04	151.21
27.06	151.08
27.07	150.94
27.08	150.81
27.09	150.68
27.11	150.54
27.12	150.41
27.13	150.28
27.15	150.14
27.16	150.01
27.18	149.88
27.19	149.75
27.20	149.61
27.22	149.48
27.23	149.35
27.24	149.21
27.26	149.08
27.27	148.94
27.28	148.81
27.29	148.68
27.31	148.55
27.32	148.41
27.33	148.28
27.35	148.15
27.36	148.01
27.38	147.88
27.39	147.75
27.40	147.61
27.42	147.48
27.43	147.35
27.44	147.21
27.46	147.08
27.47	146.95
27.48	146.81
27.49	146.68
27.51	146.55
27.52	146.41
27.53	146.28
27.55	146.15
27.56	146.02
27.58	145.88
27.59	145.75
27.60	145.61
27.62	145.48
27.63	145.35
27.64	145.21
27.66	145.08
27.67	144.95
27.68	144.81
27.69	144.68
27.71	144.55
27.72	144.41
27.73	144.28
27.75	144.15
27.76	144.02
27.78	143.88
27.79	143.75
27.80	143.62
27.82	143.48
27.83	143.35
27.84	143.22
27.86	143.08
27.87	142.95
27.88	142.82
27.89	142.68
27.91	142.55
27.92	142.42
27.93	142.28
27.95	142.15
27.96	142.02
27.98	141.89
27.99	141.75
28.00	141.62
28.02	141.49
28.03	141.35
28.04	141.22
28.06	141.09
28.07	140.95
28.08	140.82
28.09	140.69
28.11	140.55
28.12	140.42
28.13	140.29
28.15	140.15
28.16	140.02
28.18	139.89
28.19	139.75
28.20	139.62
28.22	139.49
28.23	139.36
28.24	139.22
28.26	139.09
28.27	138.96
28.28	138.82
28.29	138.69
28.31	138.56
28.32	138.42
28.33	138.29
28.35	138.16
28.36	138.02
28.38	137.89
28.39	137.76
28.40	137.62
28.42	137.49
28.43	137.36
28.44	137.22
28.46	137.09
28.47	136.96
28.48	136.82
28.49	136.69
28.51	136.56
28.52	136.42
28.53	136.29
28.55	136.16
28.56	136.02
28.58	135.89
28.59	135.76
28.60	135.62
28.62	135.49
28.63	135.36
28.64	135.22
28.66	135.09
28.67	134.96
28.68	134.83
28.69	134.69
28.71	134.56
28.72	134.43
28.73	134.29
28.75	134.16
28.76	134.03
28.78	133.89
28.79	133.76
28.80	133.63
28.82	133.49
28.83	133.36
28.84	133.23
28.86	133.09
28.87	132.96
28.88	132.83
28.89	132.69
28.91	132.56
28.92	132.43
28.93	132.29
28.95	132.16
28.96	132.03
28.98	131.89
28.99	131.76
29.00	131.63
29.02	131.49
29.03	131.36
29.04	131.23
29.06	131.09
29.07	130.96
29.08	130.83
29.09	130.70
29.11	130.56
29.12	130.43
29.13	130.30
29.15	130.16
29.16	130.03
29.18	129.90
29.19	129.76
29.20	129.63
29.22	129.50
29.23	129.36
29.24	129.23
29.26	129.10
29.27	128.96
29.28	128.83
29.29	128.70
29.31	128.56
29.32	128.43
29.33	128.30
29.35	128.16
29.36	128.03
29.38	127.90
29.39	127.76
29.40	127.63
29.42	127.50
29.43	127.37
29.44	127.23
29.46	127.10
29.47	126.97
29.48	126.83
29.49	126.70
29.51	126.57
29.52	126.43
29.53	126.30
29.55	126.17
29.56	126.03
29.58	125.90
29.59	125.77
29.60	125.63
29.62	125.50
29.63	125.37
29.64	125.23
29.66	125.10
29.67	124.97
29.68	124.83
29.69	124.70
29.71	124.57
29.72	124.43
29.73	124.30
29.75	124.17
29.76	124.03
29.78	123.90
29.79	123.77
29.80	123.64
29.82	123.50
29.83	123.37
29.84	123.24
29.86	123.10
29.87	122.97
29.88	122.84
29.89	122.70
29.91	122.57
29.92	122.44
29.93	122.30
29.95	122.17
29.96	122.04
29.98	121.90
29.99	121.77
30.00	121.64
30.02	121.50
30.03	121.37
30.04	121.24
30.06	121.10
30.07	120.97
30.08	120.84
30.09	120.71
30.11	120.57
30.12	120.44
30.13	120.31
30.15	120.17
30.16	120.04
30.18	119.91
30.19	119.77
30.20	119.64
30.22	119.51
30.23	119.37
30.24	119.24
30.26	119.11
30.27	118.97
30.28	118.84
30.29	118.71
30.31	118.57
30.32	118.44
30.33	118.31
30.35	118.17
30.36	118.04
30.38	117.91
30.39	117.77
30.40	117.64
30.42	117.51
30.43	117.37
30.44	117.24
30.46	117.11
30.47	116.97
30.48	116.84
30.49	116.71
30.51	116.58
30.52	116.44
30.53	116.31
30.55	116.18
30.56	116.04
30.58	115.91
30.59	115.78
30.60	115.64
30.62	115.51
30.63	115.38
30.64	115.24
30.66	115.11
30.67	114.98
30.68	114.84
30.69	114.71
30.71	114.58
30.72	114.44
30.73	114.31
30.75	114.18
30.76	114.04
30.78	113.91
30.79	113.78
30.80	113.65
30.82	113.51
30.83	113.38
30.84	113.24
30.86	113.11
30.87	112.98
30.88	112.85
30.89	112.71
30.91	112.58
30.92	112.45
30.93	112.31
30.95	112.18
30.96	112.05
30.98	111.91
30.99	111.78
31.00	111.65
31.02	111.51
31.03	111.38
31.04	111.25
31.06	111.11
31.07	110.98
31.08	110.85
31.09	110.71
31.11	110.58
31.12	110.45
31.13	110.31
31.15	110.18
31.16	110.05
31.18	109.92
31.19	109.78
31.20	109.65
31.22	109.51
31.23	109.38
31.24	109.25
31.26	109.11
31.27	108.98
31.28	108.85
31.29	108.72
31.31	108.58
31.32	108.45
31.33	108.32
31.35	108.18
31.36	108.05
31.38	107.92
31.39	107.78
31.40	107.65
31.42	107.52
31.43	107.38
31.44	107.25
31.46	107.12
31.47	106.98
31.48	106.85
31.49	106.72
31.51	106.58
31.52	106.45
31.53	106.32
31.55	106.18
31.56	106.05
31.58	105.92
31.59	105.79
31.60	105.65
31.62	105.52
31.63	105.39
31.64	105.25
31.66	105.12
31.67	104.99
31.68	104.85
31.69	104.72
31.71	104.59
31.72	104.45
31.73	104.32
31.75	104.19
31.76	104.05
31.78	103.92
31.79	103.79
31.80	103.65
31.82	103.52
31.83	103.39
31.84	103.26
31.86	103.12
31.87	102.99
31.88	102.85
31.89	102.72
31.91	102.59
31.92	102.45
31.93	102.32
31.95	102.19
31.96	102.05
31.98	101.92
31.99	101.79
32.00	101.65
32.02	101.52
32.03	101.39
32.04	101.26
32.06	101.12
32.07	100.99
32.08	100.86
32.09	100.72
32.11	100.59
32.12	100.46
32.13	100.32
32.15	100.19
32.16	100.06
32.18	99.92
32.19	99.79
32.20	99.66
32.22	99.52
32.23	99.39
32.24	99.26
32.26	99.12
32.27	98.99
32.28	98.86
32.29	98.72
32.31	98.59
32.32	98.46
32.33	98.33
32.35	98.19
32.36	98.06
32.38	97.93
32.39	97.79
32.40	97.66
32.42	97.53
32.43	97.39
32.44	97.26
32.46	97.13
32.47	96.99
32.48	96.86
32.49	96.73
32.51	96.59
32.52	96.46
32.53	96.33
32.55	96.19
32.56	96.06
32.58	95.93
32.59	95.79
32.60	95.66
32.62	95.53
32.63	95.39
32.64	95.26
32.66	95.13
32.67	94.99
32.68	94.86
32.69	94.73
32.71	94.59
32.72	94.46
32.73	94.33
32.75	94.19
32.76	94.06
32.78	93.93
32.79	93.80
32.80	93.66
32.82	93.53
32.83	93.40
32.84	93.26
32.86	93.13
32.87	93.00
32.88	92.86
32.89	92.73
32.91	92.60
32.92	92.46
32.93	92.33
32.95	92.20
32.96	92.06
32.98	91.93
32.99	91.80
33.00	91.66
33.02	91.53
33.03	91.40
33.04	91.26
33.06	91.13
33.07	91.00
33.08	90.86
33.09	90.73
33.11	90.60
33.12	90.46
33.13	90.33
33.15	90.20
33.16	90.07
33.18	89.93
33.19	89.80
33.20	89.67
33.22	89.53
33.23	89.40
33.24	89.27
33.26	89.13
33.27	89.00
33.28	88.87
33.29	88.73
33.31	88.60
33.32	88.47
33.33	88.33
33.35	88.20
33.36	88.07
33.38	87.93
33.39	87.80
33.40	87.67
33.42	87.54
33.43	87.40
33.44	87.27
33.46	87.14
33.47	87.00
33.48	86.87
33.49	86.74
33.51	86.60
33.52	86.47
33.53	86.34
33.55	86.20
33.56	86.07
33.58	85.94
33.59	85.80
33.60	85.67
33.62	85.54
33.63	85.40
33.64	85.27
33.66	85.14
33.67	85.00
33.68	84.87
33.69	84.74
33.71	84.60
33.72	84.47
33.73	84.34
33.75	84.20
33.76	84.07
33.78	83.94
33.79	83.81
33.80	83.67
33.82	83.54
33.83	83.40
33.84	83.27
33.86	83.14
33.87	83.01
33.88	82.87
33.89	82.74
33.91	82.61
33.92	82.47
33.93	82.34
33.95	82.21
33.96	82.07
33.98	81.94
33.99	81.81
34.00	81.67
34.02	81.54
34.03	81.41
34.04	81.27
34.06	81.14
34.07	81.01
34.08	80.87
34.09	80.74
34.11	80.61
34.12	80.47
34.14	80.34
34.15	80.21
34.16	80.07
34.18	79.94
34.19	79.81
34.20	79.68
34.21	79.54
34.23	79.41
34.24	79.28
34.26	79.14
34.27	79.01
34.28	78.88
34.29	78.74
34.31	78.61
34.32	78.48
34.34	78.34
34.35	78.21
34.36	78.08
34.38	77.94
34.39	77.81
34.40	77.68
34.41	77.54
34.43	77.41
34.44	77.28
34.46	77.14
34.47	77.01
34.48	76.88
34.49	76.74
34.51	76.61
34.52	76.48
34.54	76.34
34.55	76.21
34.56	76.08
34.58	75.95
34.59	75.81
34.60	75.68
34.61	75.55
34.63	75.41
34.64	75.28
34.66	75.15
34.67	75.01
34.68	74.88
34.69	74.75
34.71	74.61
34.72	74.48
34.74	74.35
34.75	74.21
34.76	74.08
34.78	73.95
34.79	73.81
34.80	73.68
34.81	73.55
34.83	73.41
34.84	73.28
34.86	73.15
34.87	73.01
34.88	72.88
34.89	72.75
34.91	72.61
34.92	72.48
34.94	72.35
34.95	72.21
34.96	72.08
34.98	71.95
34.99	71.81
35.00	71.68
35.01	71.55
35.03	71.42
35.04	71.28
35.06	71.15
35.07	71.02
35.08	70.88
35.09	70.75
35.11	70.62
35.12	70.48
35.14	70.35
35.15	70.22
35.16	70.08
35.18	69.95
35.19	69.82
35.20	69.68
35.21	69.55
35.23	69.42
35.24	69.28
35.26	69.15
35.27	69.02
35.28	68.88
35.29	68.75
35.31	68.62
35.32	68.48
35.34	68.35
35.35	68.22
35.36	68.08
35.38	67.95
35.39	67.82
35.40	67.69
35.41	67.55
35.43	67.42
35.44	67.29
35.46	67.15
35.47	67.02
35.48	66.89
35.49	66.75
35.51	66.62
35.52	66.49
35.54	66.35
35.55	66.22
35.56	66.09
35.58	65.95
35.59	65.82
35.60	65.69
35.61	65.55
35.63	65.42
35.64	65.29
35.66	65.15
35.67	65.02
35.68	64.89
35.69	64.76
35.71	64.62
35.72	64.49
35.74	64.36
35.75	64.22
35.76	64.09
35.78	63.96
35.79	63.82
35.80	63.69
35.81	63.56
35.83	63.42
35.84	63.29
35.86	63.16
35.87	63.02
35.88	62.89
35.89	62.76
35.91	62.62
35.92	62.49
35.94	62.36
35.95	62.22
35.96	62.09
35.98	61.96
35.99	61.82
36.00	61.69
36.01	61.56
36.03	61.42
36.04	61.29
36.06	61.16
36.07	61.02
36.08	60.89
36.09	60.76
36.11	60.62
36.12	60.49
36.14	60.36
36.15	60.23
36.16	60.09
36.18	59.96
36.19	59.83
36.20	59.69
36.21	59.56
36.23	59.43
36.24	59.29
36.26	59.16
36.27	59.03
36.28	58.89
36.29	58.76
36.31	58.63
36.32	58.49
36.34	58.36
36.35	58.23
36.36	58.09
36.38	57.96
36.39	57.83
36.40	57.69
36.41	57.56
36.43	57.43
36.44	57.30
36.46	57.16
36.47	57.03
36.48	56.90
36.49	56.76
36.51	56.63
36.52	56.50
36.54	56.36
36.55	56.23
36.56	56.10
36.58	55.96
36.59	55.83
36.60	55.70
36.61	55.56
36.63	55.43
36.64	55.30
36.66	55.16
36.67	55.03
36.68	54.90
36.69	54.76
36.71	54.63
36.72	54.50
36.74	54.36
36.75	54.23
36.76	54.10
36.78	53.96
36.79	53.83
36.80	53.70
36.81	53.56
36.83	53.43
36.84	53.30
36.86	53.16
36.87	53.03
36.88	52.90
36.89	52.77
36.91	52.63
36.92	52.50
36.94	52.37
36.95	52.23
36.96	52.10
36.98	51.97
36.99	51.83
37.00	51.70
37.01	51.57
37.03	51.43
37.04	51.30
37.06	51.17
37.07	51.03
37.08	50.90
37.09	50.77
37.11	50.63
37.12	50.50
37.14	50.37
37.15	50.23
37.16	50.10
37.18	49.97
37.19	49.83
37.20	49.70
37.21	49.57
37.23	49.43
37.24	49.30
37.26	49.17
37.27	49.03
37.28	48.90
37.29	48.77
37.31	48.63
37.32	48.50
37.34	48.37
37.35	48.24
37.36	48.10
37.38	47.97
37.39	47.84
37.40	47.70
37.41	47.57
37.43	47.44
37.44	47.30
37.46	47.17
37.47	47.04
37.48	46.90
37.49	46.77
37.51	46.64
37.52	46.50
37.54	46.37
37.55	46.24
37.56	46.10
37.58	45.97
37.59	45.84
37.60	45.70
37.61	45.57
37.63	45.44
37.64	45.30
37.66	45.17
37.67	45.04
37.68	44.91
37.69	44.77
37.71	44.64
37.72	44.51
37.74	44.37
37.75	44.24
37.76	44.11
37.78	43.97
37.79	43.84
37.80	43.71
37.81	43.57
37.83	43.44
37.84	43.31
37.86	43.17
37.87	43.04
37.88	42.91
37.89	42.78
37.91	42.64
37.92	42.51
37.94	42.38
37.95	42.24
37.96	42.11
37.98	41.98
37.99	41.84
38.00	41.71
38.01	41.58
38.03	41.44
38.04	41.31
38.06	41.18
38.07	41.04
38.08	40.91
38.09	40.78
38.11	40.64
38.12	40.51
38.14	40.38
38.15	40.24
38.16	40.11
38.18	39.98
38.19	39.84
38.20	39.71
38.21	39.58
38.23	39.44
38.24	39.31
38.26	39.18
38.27	39.04
38.28	38.91
38.29	38.78
38.31	38.64
38.32	38.51
38.34	38.38
38.35	38.24
38.36	38.11
38.38	37.98
38.39	37.84
38.40	37.71
38.41	37.58
38.43	37.45
38.44	37.31
38.46	37.18
38.47	37.05
38.48	36.91
38.49	36.78
38.51	36.65
38.52	36.51
38.54	36.38
38.55	36.25
38.56	36.11
38.58	35.98
38.59	35.85
38.60	35.71
38.61	35.58
38.63	35.45
38.64	35.31
38.66	35.18
38.67	35.05
38.68	34.92
38.69	34.78
38.71	34.65
38.72	34.51
38.74	34.38
38.75	34.25
38.76	34.11
38.78	33.98
38.79	33.85
38.80	33.71
38.81	33.58
38.83	33.45
38.84	33.32
38.86	33.18
38.87	33.05
38.88	32.92
38.89	32.78
38.91	32.65
38.92	32.52
38.94	32.38
38.95	32.25
38.96	32.12
38.98	31.98
38.99	31.85
39.00