File: Data/2024_09_19_Azulene_CHM343_DSC.txt
Filename	2024_09_19_Azulene_CHM343_DSC
Instrument name	DSC2A-00468 (192.168.1.100)
Operator	CHM343
rundate	9/19/2024
Sample name	2024_09_19_Azulene_CHM343_DSC
proceduresegments	Equilibrate 30.00 °C; Ramp 10.00 °C/min to 160.00 °C; Isothermal 1.0 min; Ramp 10.00 °C/min to 30.00 °C
[File Parameters]
Run date	9/19/2024 5:43:00 PM
Trios version	5.1.1.46572
Original File Name	C:\ProgramData\TA Instruments\TRIOS\Data\2024_09_19_Azulene_CHM343_DSC.tri
Current File Name	D:\DSC2500\CHM343\2024_09_19_Azulene_CHM343_DSC.tri
[Procedure]
Procedure Name	CHM343_Fall2024_Azulene
Sample Name	2024_09_19_Azulene_CHM343_DSC
Sample Mass	0.12 mg
Reference Sample Mass	0 mg
Pan Mass	53.61 mg
Pan Number	21
Reference Pan Mass	54 mg
Reference Pan Number	19
Pan Type	Aluminum
Comments	Azulene - Al Hermetic Sealed Pan, with ref Al pan.  ASU Online CHM343, Remote DSC experimental lab. Fall 2024.  Group Zoom Data Collection, Sept 19, 2024 from 5-7 pm.  TA Instruments DSC2500.
Project Name	Lab 4 - Fall 2024
Operator	CHM343
Test	Custom
Unload Max Temperature	30
Unload Min Temperature	30
Load Max Temperature	30
Load Min Temperature	30
Stop on Gas Flow Error	Yes
[Signal List]
Signal #1	Time (min)
Signal #2	Temperature (°C)
Signal #3	Heat Flow (mW)
Signal #4	Delta T (µV)
Signal #5	Delta Tzero (µV)
Signal #6	Tzero Temperature (°C)
Signal #7	Cell Purge (mL/min)
Signal #8	Heater Temp (°C)
Signal #9	Power Delivered (W)
Signal #10	Reference Junction Temperature (°C)
Signal #11	Flange Temperature (°C)
Signal #12	Heat Flow Phase (rad)
Signal #13	Total Heat Capacity (J/°C)
Signal #14	Heat Capacity (J/°C)
[Configuration]
Company Name	ASU
Instrument Name	DSC2A-00468
Instrument Type	DSC2500
Serial Number	DSC2A-00468
IP	192.168.1.100
Location of Instrument	MRRC
DisplayType	Unknown
Sample Interval 	0.1 s/pt
Selected Heat Flow	T4P
Exotherm Direction	Down
Cell Serial	DRC2-00792
Lid Type	Standard
Cooler	RCS 90
Leave Cooler on at End of Sequence	On
Gas 2	Nitrogen
Gas Selected	Channel 1
Flow Rate	50 mL/min
Secondary Purge	On
Licensed Heat Flow	Heat Flow T4P
Modulation Licensed	Yes
[Versions]
Common IDD Version	1
Cortex Version	VER 2.10.2.31
Driver	5.0.0.6
GDM Version	1.0.3.3
TouchscreenVersion	1.0.0.16145
FEP Version	1.2.1.21
FEP Bootloader	2.0.0.5
AutoSampler Version	2.1.1.26
Auto Sampler Bootloader	2.0.0.5
FCM Version	1.1.0.3
FCM Bootloader	2.0.0.5
[Experiment Logs]
Experiment Log Entry # 1	Equilibrate Segment 30 (C) Started
Experiment Log Entry # 3	Air Cool is off.
Experiment Log Entry # 5	Ramp Segment 10 C/min to 160 Started
Experiment Log Entry # 7	Isothermal Segment 1 min started
Experiment Log Entry # 9	Ramp Segment 10 C/min to 30 Started
[Method Log]
Method Log Entry # 1	Equilibrate 30 °C
Method Log Entry # 2	(Ramp 4778) Ramp 10 °C/minute to 160 °C
Method Log Entry # 3	Isothermal 1 minutes
Method Log Entry # 4	(Ramp 4780) Ramp 10 °C/minute to 30 °C
Cell Serial	DRC2-00792
[T1 Calibration]
Slope	-0.008529666
Offset	9.636258
Initial Temperature	98.23
GUID	f8bfdadc-4977-4fdf-ba6d-0ba9134940c3
[TZero Calibration]
Date Applied	11/29/2022 4:06:13 PM
Description	From -89.059 °C to 396.009 °C at 20.000°C/min
Gas Type	Nitrogen
Pan Type	None
Source Files 1	C:\Users\yargerlab\Desktop\DSC Data\General\TZero_calibration_11_29_22_2nd(2).tri
Source Files 2	C:\Users\yargerlab\Desktop\DSC Data\General\TZero_calibration_11_29_22_2nd(3).tri
Delta T Offset	13.05235
Delta T Slope	-0.007271007
Delta T0 Offset	-13.69128
Delta T0 Slope	0.06063341
[Temperature Calibration]
Date Applied	11/29/2022 7:12:28 PM
Description	From 106.590 °C to 186.590 °C at 10.000°C/min
Gas Type	Nitrogen
Pan Type	Tzero Aluminum Hermetic
Source Files 1	C:\Users\yargerlab\Desktop\DSC Data\General\Indium(6).tri
Measured 1	157.391
Known 1	156.598
[Cell Constant Calibration]
Date Applied	11/29/2022 7:12:29 PM
Description	From 106.590 °C to 186.590 °C at 10.000°C/min
Gas Type	Nitrogen
Pan Type	Tzero Aluminum Hermetic
Source Files 1	C:\Users\yargerlab\Desktop\DSC Data\General\Indium(6).tri
T4P KCell	1.006051
Onset Slope	63.26126 mW/°C
[Direct Cp Calibration]
Date Applied	11/30/2022 11:04:51 AM
Description	From -79.983 °C to 298.409 °C at 10.000°C/min
Gas Type	Nitrogen
Pan Type	Tzero Aluminum Hermetic
Source Files 1	C:\Users\yargerlab\Desktop\DSC Data\General\Sapphire_Heat_Capacity_11_30_22.tri
[Rev Cp Calibration]
Date Applied	11/30/2022 1:58:51 PM
Description	From -79.996 °C to 292.812 °C at 3.000°C/min
Gas Type	Nitrogen
Pan Type	Tzero Aluminum Hermetic
Source Files 1	C:\Users\yargerlab\Desktop\DSC Data\General\Sapphire_MDSC_Calibration_11_30_22.tri
[step]
Ramp 10.00 °C/min to 160.00 °C
Time	Temperature	Heat Flow (Normalized)
min	°C	W/g
0.00	30.06	-0.855
0.01	30.06	-0.854
0.02	30.06	-0.853
0.03	30.06	-0.852
0.04	30.07	-0.852
0.05	30.07	-0.857
0.06	30.09	-0.917
0.07	30.10	-1.184
0.08	30.13	-1.551
0.09	30.16	-1.886
0.10	30.20	-2.099
0.11	30.24	-2.254
0.12	30.29	-2.309
0.13	30.35	-2.317
0.14	30.41	-2.229
0.15	30.48	-2.166
0.16	30.55	-1.982
0.17	30.62	-1.526
0.18	30.70	-1.206
0.19	30.78	-0.842
0.20	30.86	-0.638
0.21	30.94	-0.392
0.22	31.03	-0.250
0.23	31.11	-0.030
0.24	31.20	0.096
0.25	31.29	0.192
0.26	31.38	0.324
0.27	31.47	0.413
0.28	31.56	0.535
0.29	31.65	0.571
0.30	31.74	0.685
0.31	31.84	0.782
0.32	31.93	0.827
0.33	32.02	0.916
0.34	32.12	1.029
0.35	32.21	1.047
0.36	32.31	1.089
0.37	32.41	1.113
0.38	32.50	1.172
0.39	32.60	1.238
0.40	32.70	1.251
0.41	32.79	1.281
0.42	32.89	1.319
0.43	32.99	1.336
0.44	33.09	1.359
0.45	33.18	1.378
0.46	33.28	1.392
0.47	33.38	1.400
0.48	33.48	1.424
0.49	33.57	1.434
0.50	33.67	1.441
0.51	33.77	1.452
0.52	33.87	1.463
0.53	33.97	1.471
0.54	34.07	1.477
0.55	34.17	1.490
0.56	34.26	1.501
0.57	34.36	1.507
0.58	34.46	1.514
0.59	34.56	1.521
0.60	34.66	1.528
0.61	34.76	1.535
0.62	34.86	1.541
0.63	34.96	1.550
0.64	35.06	1.555
0.65	35.15	1.563
0.66	35.25	1.569
0.67	35.35	1.575
0.68	35.45	1.583
0.69	35.55	1.589
0.70	35.65	1.597
0.71	35.75	1.601
0.72	35.85	1.607
0.73	35.95	1.612
0.74	36.05	1.620
0.75	36.15	1.626
0.76	36.24	1.628
0.77	36.34	1.634
0.78	36.44	1.639
0.79	36.54	1.643
0.80	36.64	1.649
0.81	36.74	1.655
0.82	36.84	1.659
0.83	36.94	1.663
0.84	37.04	1.667
0.85	37.14	1.670
0.86	37.24	1.674
0.87	37.34	1.677
0.88	37.44	1.682
0.89	37.54	1.685
0.90	37.64	1.687
0.91	37.74	1.691
0.92	37.83	1.694
0.93	37.94	1.697
0.94	38.03	1.696
0.95	38.13	1.700
0.96	38.23	1.702
0.97	38.33	1.705
0.98	38.43	1.707
0.99	38.53	1.711
1.00	38.63	1.713
1.01	38.73	1.714
1.02	38.83	1.715
1.03	38.93	1.717
1.04	39.03	1.718
1.05	39.13	1.720
1.06	39.23	1.722
1.07	39.33	1.725
1.08	39.43	1.726
1.09	39.53	1.727
1.10	39.63	1.727
1.11	39.73	1.730
1.12	39.83	1.731
1.13	39.93	1.731
1.14	40.03	1.733
1.15	40.13	1.736
1.16	40.23	1.736
1.17	40.33	1.737
1.18	40.43	1.738
1.19	40.53	1.738
1.20	40.63	1.738
1.21	40.73	1.738
1.22	40.83	1.740
1.23	40.93	1.741
1.24	41.02	1.741
1.25	41.12	1.742
1.26	41.22	1.742
1.27	41.32	1.741
1.28	41.42	1.742
1.29	41.52	1.743
1.30	41.62	1.742
1.31	41.72	1.744
1.32	41.82	1.744
1.33	41.92	1.744
1.34	42.02	1.743
1.35	42.12	1.744
1.36	42.22	1.744
1.37	42.32	1.744
1.38	42.42	1.743
1.39	42.52	1.743
1.40	42.62	1.743
1.41	42.72	1.744
1.42	42.82	1.743
1.43	42.92	1.742
1.44	43.02	1.744
1.45	43.12	1.743
1.46	43.22	1.743
1.47	43.32	1.743
1.48	43.42	1.743
1.49	43.52	1.745
1.50	43.62	1.744
1.51	43.72	1.743
1.52	43.82	1.744
1.53	43.92	1.745
1.54	44.02	1.742
1.55	44.12	1.743
1.56	44.22	1.742
1.57	44.32	1.741
1.58	44.42	1.740
1.59	44.52	1.740
1.60	44.62	1.739
1.61	44.72	1.738
1.62	44.82	1.738
1.63	44.92	1.737
1.64	45.02	1.737
1.65	45.12	1.738
1.66	45.22	1.738
1.67	45.32	1.740
1.68	45.42	1.739
1.69	45.52	1.738
1.70	45.62	1.738
1.71	45.72	1.737
1.72	45.82	1.736
1.73	45.92	1.738
1.74	46.02	1.734
1.75	46.12	1.735
1.76	46.22	1.735
1.77	46.32	1.735
1.78	46.42	1.734
1.79	46.52	1.733
1.80	46.62	1.733
1.81	46.72	1.731
1.82	46.82	1.733
1.83	46.92	1.732
1.84	47.02	1.731
1.85	47.12	1.729
1.86	47.22	1.729
1.87	47.32	1.728
1.88	47.42	1.724
1.89	47.52	1.723
1.90	47.62	1.722
1.91	47.72	1.722
1.92	47.82	1.721
1.93	47.92	1.722
1.94	48.02	1.722
1.95	48.12	1.722
1.96	48.22	1.721
1.97	48.32	1.721
1.98	48.42	1.722
1.99	48.52	1.721
2.00	48.62	1.719
2.01	48.72	1.718
2.02	48.82	1.718
2.03	48.92	1.719
2.04	49.02	1.719
2.05	49.12	1.717
2.06	49.22	1.717
2.07	49.32	1.718
2.08	49.42	1.718
2.09	49.52	1.718
2.10	49.62	1.715
2.11	49.72	1.715
2.12	49.82	1.714
2.13	49.92	1.715
2.14	50.02	1.715
2.15	50.12	1.716
2.16	50.22	1.715
2.17	50.32	1.714
2.18	50.42	1.712
2.19	50.52	1.711
2.20	50.62	1.712
2.21	50.72	1.711
2.22	50.82	1.712
2.23	50.92	1.711
2.24	51.02	1.710
2.25	51.12	1.711
2.26	51.22	1.711
2.27	51.32	1.711
2.28	51.42	1.710
2.29	51.52	1.711
2.30	51.62	1.711
2.31	51.72	1.708
2.32	51.82	1.707
2.33	51.92	1.706
2.34	52.02	1.705
2.35	52.12	1.704
2.36	52.22	1.704
2.37	52.32	1.704
2.38	52.42	1.705
2.39	52.52	1.703
2.40	52.62	1.701
2.41	52.72	1.701
2.42	52.82	1.700
2.43	52.92	1.700
2.44	53.02	1.698
2.45	53.12	1.697
2.46	53.22	1.697
2.47	53.32	1.697
2.48	53.43	1.697
2.49	53.52	1.696
2.50	53.62	1.696
2.51	53.72	1.695
2.52	53.82	1.694
2.53	53.92	1.695
2.54	54.02	1.695
2.55	54.13	1.694
2.56	54.23	1.694
2.57	54.32	1.693
2.58	54.43	1.692
2.59	54.53	1.693
2.60	54.63	1.691
2.61	54.73	1.692
2.62	54.83	1.691
2.63	54.93	1.690
2.64	55.03	1.689
2.65	55.12	1.688
2.66	55.23	1.689
2.67	55.33	1.688
2.68	55.43	1.687
2.69	55.53	1.685
2.70	55.63	1.686
2.71	55.73	1.685
2.72	55.83	1.685
2.73	55.93	1.685
2.74	56.03	1.685
2.75	56.13	1.684
2.76	56.23	1.683
2.77	56.33	1.683
2.78	56.43	1.683
2.79	56.53	1.684
2.80	56.63	1.685
2.81	56.73	1.684
2.82	56.83	1.685
2.83	56.93	1.685
2.84	57.03	1.683
2.85	57.13	1.683
2.86	57.23	1.682
2.87	57.33	1.682
2.88	57.43	1.683
2.89	57.53	1.683
2.90	57.63	1.681
2.91	57.73	1.682
2.92	57.83	1.682
2.93	57.93	1.681
2.94	58.03	1.682
2.95	58.13	1.681
2.96	58.23	1.680
2.97	58.33	1.680
2.98	58.43	1.679
2.99	58.53	1.679
3.00	58.63	1.680
3.01	58.73	1.679
3.02	58.83	1.678
3.03	58.93	1.676
3.04	59.03	1.675
3.05	59.13	1.676
3.06	59.23	1.676
3.07	59.33	1.675
3.08	59.43	1.674
3.09	59.53	1.674
3.10	59.63	1.672
3.11	59.73	1.673
3.12	59.83	1.673
3.13	59.93	1.671
3.14	60.03	1.673
3.15	60.13	1.671
3.16	60.23	1.671
3.17	60.33	1.672
3.18	60.43	1.672
3.19	60.53	1.672
3.20	60.63	1.672
3.21	60.73	1.671
3.22	60.83	1.670
3.23	60.93	1.669
3.24	61.03	1.669
3.25	61.13	1.669
3.26	61.23	1.669
3.27	61.33	1.669
3.28	61.43	1.668
3.29	61.53	1.668
3.30	61.63	1.668
3.31	61.73	1.667
3.32	61.83	1.667
3.33	61.93	1.667
3.34	62.03	1.668
3.35	62.13	1.666
3.36	62.23	1.665
3.37	62.33	1.666
3.38	62.43	1.666
3.39	62.53	1.667
3.40	62.63	1.664
3.41	62.73	1.664
3.42	62.83	1.666
3.43	62.93	1.667
3.44	63.03	1.665
3.45	63.13	1.666
3.46	63.23	1.665
3.47	63.33	1.665
3.48	63.43	1.665
3.49	63.53	1.664
3.50	63.63	1.664
3.51	63.73	1.664
3.52	63.83	1.665
3.53	63.93	1.665
3.54	64.03	1.664
3.55	64.13	1.666
3.56	64.23	1.666
3.57	64.33	1.665
3.58	64.43	1.666
3.59	64.53	1.666
3.60	64.63	1.666
3.61	64.73	1.666
3.62	64.83	1.665
3.63	64.93	1.666
3.64	65.03	1.665
3.65	65.13	1.666
3.66	65.23	1.666
3.67	65.33	1.666
3.68	65.43	1.666
3.69	65.53	1.666
3.70	65.63	1.664
3.71	65.73	1.666
3.72	65.83	1.667
3.73	65.93	1.665
3.74	66.03	1.664
3.75	66.13	1.663
3.76	66.23	1.664
3.77	66.33	1.663
3.78	66.43	1.664
3.79	66.53	1.664
3.80	66.63	1.663
3.81	66.73	1.664
3.82	66.83	1.663
3.83	66.94	1.663
3.84	67.03	1.662
3.85	67.14	1.663
3.86	67.24	1.663
3.87	67.34	1.662
3.88	67.44	1.663
3.89	67.54	1.664
3.90	67.64	1.664
3.91	67.74	1.665
3.92	67.84	1.665
3.93	67.94	1.663
3.94	68.04	1.663
3.95	68.14	1.664
3.96	68.24	1.665
3.97	68.34	1.665
3.98	68.44	1.665
3.99	68.54	1.666
4.00	68.64	1.665
4.01	68.74	1.665
4.02	68.84	1.665
4.03	68.94	1.665
4.04	69.04	1.665
4.05	69.14	1.665
4.06	69.24	1.664
4.07	69.34	1.666
4.08	69.44	1.665
4.09	69.54	1.666
4.10	69.64	1.667
4.11	69.74	1.668
4.12	69.84	1.668
4.13	69.94	1.668
4.14	70.04	1.668
4.15	70.14	1.667
4.16	70.24	1.668
4.17	70.34	1.669
4.18	70.44	1.669
4.19	70.54	1.668
4.20	70.64	1.668
4.21	70.74	1.666
4.22	70.84	1.668
4.23	70.94	1.666
4.24	71.04	1.667
4.25	71.14	1.667
4.26	71.24	1.668
4.27	71.34	1.667
4.28	71.44	1.666
4.29	71.54	1.667
4.30	71.64	1.667
4.31	71.74	1.667
4.32	71.84	1.667
4.33	71.94	1.667
4.34	72.04	1.667
4.35	72.14	1.668
4.36	72.24	1.669
4.37	72.34	1.669
4.38	72.44	1.668
4.39	72.54	1.669
4.40	72.64	1.668
4.41	72.74	1.669
4.42	72.84	1.670
4.43	72.94	1.669
4.44	73.04	1.668
4.45	73.14	1.667
4.46	73.24	1.669
4.47	73.34	1.669
4.48	73.44	1.669
4.49	73.54	1.668
4.50	73.64	1.668
4.51	73.74	1.669
4.52	73.84	1.667
4.53	73.94	1.667
4.54	74.04	1.667
4.55	74.14	1.666
4.56	74.24	1.666
4.57	74.34	1.666
4.58	74.44	1.666
4.59	74.54	1.666
4.60	74.64	1.665
4.61	74.74	1.664
4.62	74.84	1.665
4.63	74.94	1.665
4.64	75.04	1.665
4.65	75.14	1.665
4.66	75.24	1.666
4.67	75.34	1.666
4.68	75.44	1.667
4.69	75.54	1.667
4.70	75.64	1.666
4.71	75.74	1.667
4.72	75.84	1.667
4.73	75.94	1.667
4.74	76.04	1.668
4.75	76.14	1.669
4.76	76.24	1.668
4.77	76.34	1.667
4.78	76.44	1.669
4.79	76.54	1.669
4.80	76.64	1.669
4.81	76.74	1.669
4.82	76.84	1.669
4.83	76.94	1.669
4.84	77.04	1.669
4.85	77.14	1.670
4.86	77.24	1.671
4.87	77.34	1.671
4.88	77.44	1.671
4.89	77.54	1.671
4.90	77.64	1.671
4.91	77.74	1.671
4.92	77.84	1.672
4.93	77.94	1.671
4.94	78.04	1.673
4.95	78.14	1.672
4.96	78.24	1.671
4.97	78.34	1.671
4.98	78.44	1.671
4.99	78.54	1.671
5.00	78.64	1.672
5.01	78.74	1.674
5.02	78.84	1.673
5.03	78.94	1.673
5.04	79.04	1.674
5.05	79.14	1.673
5.06	79.24	1.673
5.07	79.34	1.672
5.08	79.44	1.672
5.09	79.54	1.672
5.10	79.64	1.672
5.11	79.75	1.671
5.12	79.84	1.672
5.13	79.94	1.672
5.14	80.04	1.673
5.15	80.15	1.674
5.16	80.25	1.673
5.17	80.35	1.673
5.18	80.45	1.671
5.19	80.55	1.671
5.20	80.65	1.671
5.21	80.75	1.671
5.22	80.85	1.672
5.23	80.95	1.672
5.24	81.05	1.670
5.25	81.15	1.670
5.26	81.25	1.670
5.27	81.34	1.669
5.28	81.45	1.669
5.29	81.55	1.668
5.30	81.65	1.668
5.31	81.75	1.666
5.32	81.84	1.666
5.33	81.95	1.664
5.34	82.04	1.664
5.35	82.15	1.663
5.36	82.25	1.664
5.37	82.35	1.662
5.38	82.45	1.663
5.39	82.55	1.661
5.40	82.65	1.663
5.41	82.75	1.664
5.42	82.85	1.660
5.43	82.95	1.660
5.44	83.05	1.660
5.45	83.15	1.662
5.46	83.25	1.659
5.47	83.35	1.656
5.48	83.45	1.657
5.49	83.55	1.658
5.50	83.65	1.657
5.51	83.75	1.656
5.52	83.85	1.655
5.53	83.95	1.655
5.54	84.05	1.656
5.55	84.15	1.655
5.56	84.25	1.654
5.57	84.35	1.654
5.58	84.45	1.654
5.59	84.55	1.654
5.60	84.65	1.655
5.61	84.75	1.653
5.62	84.85	1.654
5.63	84.95	1.653
5.64	85.05	1.654
5.65	85.15	1.653
5.66	85.25	1.654
5.67	85.35	1.654
5.68	85.45	1.654
5.69	85.55	1.654
5.70	85.65	1.653
5.71	85.75	1.653
5.72	85.85	1.653
5.73	85.95	1.653
5.74	86.05	1.652
5.75	86.15	1.653
5.76	86.25	1.654
5.77	86.35	1.653
5.78	86.45	1.653
5.79	86.55	1.653
5.80	86.65	1.653
5.81	86.75	1.653
5.82	86.85	1.654
5.83	86.95	1.654
5.84	87.05	1.654
5.85	87.15	1.654
5.86	87.25	1.655
5.87	87.35	1.656
5.88	87.45	1.656
5.89	87.55	1.655
5.90	87.65	1.656
5.91	87.75	1.656
5.92	87.85	1.654
5.93	87.95	1.654
5.94	88.05	1.655
5.95	88.15	1.656
5.96	88.25	1.655
5.97	88.35	1.656
5.98	88.45	1.658
5.99	88.55	1.658
6.00	88.65	1.658
6.01	88.75	1.659
6.02	88.85	1.660
6.03	88.95	1.661
6.04	89.05	1.661
6.05	89.15	1.662
6.06	89.25	1.662
6.07	89.35	1.661
6.08	89.45	1.662
6.09	89.55	1.662
6.10	89.65	1.663
6.11	89.75	1.663
6.12	89.85	1.662
6.13	89.95	1.664
6.14	90.05	1.664
6.15	90.15	1.666
6.16	90.25	1.666
6.17	90.35	1.666
6.18	90.45	1.668
6.19	90.55	1.669
6.20	90.65	1.670
6.21	90.75	1.671
6.22	90.85	1.672
6.23	90.95	1.674
6.24	91.05	1.675
6.25	91.15	1.675
6.26	91.25	1.676
6.27	91.35	1.677
6.28	91.45	1.677
6.29	91.55	1.677
6.30	91.65	1.678
6.31	91.75	1.679
6.32	91.85	1.680
6.33	91.95	1.681
6.34	92.05	1.681
6.35	92.15	1.684
6.36	92.25	1.684
6.37	92.35	1.685
6.38	92.45	1.686
6.39	92.55	1.686
6.40	92.65	1.686
6.41	92.75	1.688
6.42	92.85	1.689
6.43	92.95	1.691
6.44	93.05	1.692
6.45	93.15	1.694
6.46	93.25	1.695
6.47	93.35	1.696
6.48	93.45	1.695
6.49	93.55	1.699
6.50	93.65	1.699
6.51	93.75	1.701
6.52	93.85	1.703
6.53	93.95	1.704
6.54	94.05	1.704
6.55	94.15	1.705
6.56	94.25	1.706
6.57	94.35	1.707
6.58	94.45	1.708
6.59	94.55	1.709
6.60	94.66	1.710
6.61	94.75	1.711
6.62	94.85	1.713
6.63	94.95	1.713
6.64	95.05	1.716
6.65	95.15	1.717
6.66	95.26	1.719
6.67	95.36	1.721
6.68	95.46	1.725
6.69	95.56	1.727
6.70	95.66	1.730
6.71	95.76	1.730
6.72	95.86	1.732
6.73	95.96	1.736
6.74	96.06	1.738
6.75	96.16	1.742
6.76	96.26	1.744
6.77	96.36	1.747
6.78	96.46	1.750
6.79	96.56	1.753
6.80	96.66	1.757
6.81	96.76	1.760
6.82	96.86	1.764
6.83	96.96	1.772
6.84	97.06	1.777
6.85	97.16	1.782
6.86	97.26	1.787
6.87	97.36	1.796
6.88	97.46	1.806
6.89	97.56	1.818
6.90	97.66	1.834
6.91	97.75	1.852
6.92	97.86	1.871
6.93	97.95	1.953
6.94	98.05	2.070
6.95	98.15	2.141
6.96	98.25	2.387
6.97	98.35	2.708
6.98	98.45	3.041
6.99	98.55	3.469
7.00	98.65	4.101
7.01	98.75	5.145
7.02	98.84	6.746
7.03	98.94	9.407
7.04	99.03	13.452
7.05	99.11	18.757
7.06	99.20	23.623
7.07	99.27	25.953
7.08	99.36	25.275
7.09	99.45	23.296
7.10	99.54	19.983
7.11	99.64	15.361
7.12	99.75	10.052
7.13	99.86	7.110
7.14	99.97	6.048
7.15	100.08	5.427
7.16	100.19	4.990
7.17	100.30	4.550
7.18	100.41	4.208
7.19	100.51	3.913
7.20	100.62	3.735
7.21	100.72	3.446
7.22	100.83	3.298
7.23	100.93	3.067
7.24	101.03	2.933
7.25	101.14	2.830
7.26	101.24	2.639
7.27	101.34	2.584
7.28	101.44	2.495
7.29	101.55	2.406
7.30	101.65	2.343
7.31	101.75	2.309
7.32	101.85	2.229
7.33	101.95	2.166
7.34	102.05	2.117
7.35	102.15	2.090
7.36	102.25	2.069
7.37	102.35	2.037
7.38	102.45	2.018
7.39	102.56	2.001
7.40	102.66	1.983
7.41	102.76	1.976
7.42	102.86	1.961
7.43	102.96	1.949
7.44	103.06	1.937
7.45	103.16	1.924
7.46	103.26	1.909
7.47	103.36	1.899
7.48	103.46	1.895
7.49	103.56	1.887
7.50	103.66	1.880
7.51	103.76	1.873
7.52	103.86	1.868
7.53	103.96	1.863
7.54	104.06	1.858
7.55	104.16	1.853
7.56	104.26	1.849
7.57	104.36	1.845
7.58	104.46	1.842
7.59	104.56	1.837
7.60	104.66	1.834
7.61	104.76	1.830
7.62	104.86	1.827
7.63	104.96	1.822
7.64	105.06	1.821
7.65	105.16	1.818
7.66	105.26	1.814
7.67	105.36	1.810
7.68	105.46	1.809
7.69	105.56	1.805
7.70	105.66	1.802
7.71	105.76	1.801
7.72	105.86	1.800
7.73	105.96	1.796
7.74	106.06	1.794
7.75	106.16	1.792
7.76	106.26	1.790
7.77	106.36	1.788
7.78	106.46	1.785
7.79	106.56	1.786
7.80	106.66	1.784
7.81	106.76	1.781
7.82	106.86	1.780
7.83	106.96	1.780
7.84	107.06	1.780
7.85	107.16	1.777
7.86	107.26	1.774
7.87	107.36	1.773
7.88	107.46	1.772
7.89	107.56	1.771
7.90	107.66	1.772
7.91	107.76	1.771
7.92	107.86	1.768
7.93	107.97	1.767
7.94	108.06	1.766
7.95	108.16	1.764
7.96	108.26	1.764
7.97	108.36	1.766
7.98	108.46	1.764
7.99	108.56	1.763
8.00	108.67	1.764
8.01	108.77	1.765
8.02	108.86	1.765
8.03	108.97	1.764
8.04	109.07	1.763
8.05	109.17	1.764
8.06	109.26	1.764
8.07	109.37	1.763
8.08	109.47	1.762
8.09	109.57	1.764
8.10	109.66	1.763
8.11	109.77	1.764
8.12	109.86	1.764
8.13	109.96	1.765
8.14	110.06	1.764
8.15	110.17	1.764
8.16	110.26	1.764
8.17	110.37	1.763
8.18	110.46	1.764
8.19	110.57	1.763
8.20	110.67	1.762
8.21	110.77	1.763
8.22	110.86	1.762
8.23	110.96	1.762
8.24	111.06	1.761
8.25	111.16	1.764
8.26	111.26	1.762
8.27	111.37	1.763
8.28	111.47	1.762
8.29	111.56	1.761
8.30	111.66	1.761
8.31	111.77	1.760
8.32	111.87	1.762
8.33	111.97	1.763
8.34	112.07	1.762
8.35	112.17	1.763
8.36	112.27	1.764
8.37	112.37	1.764
8.38	112.47	1.764
8.39	112.57	1.764
8.40	112.67	1.765
8.41	112.77	1.765
8.42	112.87	1.764
8.43	112.97	1.763
8.44	113.07	1.763
8.45	113.17	1.765
8.46	113.27	1.766
8.47	113.37	1.764
8.48	113.47	1.772
8.49	113.57	1.772
8.50	113.67	1.773
8.51	113.77	1.773
8.52	113.87	1.772
8.53	113.97	1.774
8.54	114.07	1.774
8.55	114.17	1.774
8.56	114.27	1.776
8.57	114.37	1.775
8.58	114.47	1.774
8.59	114.57	1.776
8.60	114.67	1.776
8.61	114.77	1.776
8.62	114.87	1.775
8.63	114.97	1.774
8.64	115.07	1.775
8.65	115.17	1.776
8.66	115.27	1.777
8.67	115.37	1.777
8.68	115.47	1.778
8.69	115.57	1.778
8.70	115.67	1.778
8.71	115.77	1.779
8.72	115.87	1.779
8.73	115.97	1.779
8.74	116.07	1.778
8.75	116.17	1.779
8.76	116.27	1.779
8.77	116.37	1.778
8.78	116.47	1.780
8.79	116.57	1.780
8.80	116.67	1.781
8.81	116.77	1.783
8.82	116.87	1.782
8.83	116.97	1.783
8.84	117.07	1.783
8.85	117.17	1.784
8.86	117.27	1.784
8.87	117.37	1.785
8.88	117.47	1.786
8.89	117.57	1.786
8.90	117.67	1.787
8.91	117.77	1.787
8.92	117.87	1.786
8.93	117.97	1.789
8.94	118.07	1.789
8.95	118.17	1.788
8.96	118.27	1.788
8.97	118.37	1.789
8.98	118.47	1.788
8.99	118.57	1.789
9.00	118.67	1.789
9.01	118.77	1.789
9.02	118.87	1.790
9.03	118.97	1.791
9.04	119.07	1.792
9.05	119.17	1.791
9.06	119.27	1.792
9.07	119.37	1.792
9.08	119.47	1.793
9.09	119.57	1.793
9.10	119.67	1.793
9.11	119.77	1.795
9.12	119.87	1.796
9.13	119.97	1.797
9.14	120.07	1.796
9.15	120.17	1.796
9.16	120.27	1.796
9.17	120.37	1.797
9.18	120.47	1.797
9.19	120.57	1.797
9.20	120.67	1.799
9.21	120.77	1.798
9.22	120.87	1.797
9.23	120.97	1.799
9.24	121.07	1.799
9.25	121.17	1.800
9.26	121.27	1.801
9.27	121.37	1.801
9.28	121.47	1.803
9.29	121.57	1.804
9.30	121.67	1.804
9.31	121.77	1.804
9.32	121.87	1.806
9.33	121.97	1.806
9.34	122.07	1.806
9.35	122.17	1.807
9.36	122.27	1.808
9.37	122.37	1.807
9.38	122.47	1.807
9.39	122.57	1.806
9.40	122.67	1.808
9.41	122.77	1.809
9.42	122.87	1.810
9.43	122.97	1.810
9.44	123.07	1.812
9.45	123.17	1.812
9.46	123.27	1.813
9.47	123.37	1.814
9.48	123.47	1.814
9.49	123.57	1.814
9.50	123.67	1.814
9.51	123.77	1.815
9.52	123.87	1.815
9.53	123.97	1.815
9.54	124.07	1.815
9.55	124.17	1.814
9.56	124.27	1.813
9.57	124.37	1.813
9.58	124.47	1.815
9.59	124.57	1.816
9.60	124.67	1.816
9.61	124.77	1.817
9.62	124.87	1.817
9.63	124.97	1.817
9.64	125.07	1.818
9.65	125.17	1.818
9.66	125.27	1.818
9.67	125.37	1.820
9.68	125.47	1.821
9.69	125.57	1.822
9.70	125.67	1.823
9.71	125.77	1.823
9.72	125.87	1.822
9.73	125.97	1.823
9.74	126.07	1.823
9.75	126.17	1.824
9.76	126.27	1.826
9.77	126.37	1.827
9.78	126.47	1.826
9.79	126.57	1.827
9.80	126.67	1.828
9.81	126.77	1.828
9.82	126.87	1.829
9.83	126.97	1.829
9.84	127.07	1.829
9.85	127.17	1.830
9.86	127.27	1.830
9.87	127.37	1.830
9.88	127.47	1.833
9.89	127.57	1.832
9.90	127.67	1.831
9.91	127.77	1.831
9.92	127.87	1.832
9.93	127.98	1.832
9.94	128.07	1.832
9.95	128.17	1.832
9.96	128.27	1.832
9.97	128.38	1.832
9.98	128.48	1.834
9.99	128.57	1.834
10.00	128.68	1.833
10.01	128.77	1.835
10.02	128.88	1.835
10.03	128.98	1.835
10.04	129.07	1.836
10.05	129.18	1.837
10.06	129.28	1.837
10.07	129.38	1.836
10.08	129.48	1.837
10.09	129.58	1.839
10.10	129.68	1.839
10.11	129.78	1.840
10.12	129.88	1.839
10.13	129.98	1.839
10.14	130.08	1.841
10.15	130.18	1.841
10.16	130.28	1.843
10.17	130.38	1.843
10.18	130.48	1.844
10.19	130.58	1.844
10.20	130.68	1.844
10.21	130.78	1.845
10.22	130.88	1.846
10.23	130.98	1.846
10.24	131.08	1.847
10.25	131.18	1.847
10.26	131.28	1.846
10.27	131.38	1.848
10.28	131.48	1.849
10.29	131.58	1.848
10.30	131.68	1.849
10.31	131.78	1.849
10.32	131.88	1.849
10.33	131.98	1.850
10.34	132.08	1.850
10.35	132.18	1.849
10.36	132.28	1.851
10.37	132.38	1.852
10.38	132.48	1.852
10.39	132.58	1.852
10.40	132.68	1.853
10.41	132.78	1.853
10.42	132.88	1.854
10.43	132.98	1.854
10.44	133.08	1.853
10.45	133.18	1.853
10.46	133.28	1.853
10.47	133.38	1.854
10.48	133.48	1.855
10.49	133.58	1.855
10.50	133.68	1.855
10.51	133.78	1.857
10.52	133.88	1.858
10.53	133.98	1.858
10.54	134.08	1.857
10.55	134.18	1.859
10.56	134.28	1.860
10.57	134.38	1.860
10.58	134.48	1.861
10.59	134.58	1.861
10.60	134.68	1.861
10.61	134.78	1.862
10.62	134.88	1.862
10.63	134.98	1.862
10.64	135.08	1.863
10.65	135.18	1.862
10.66	135.28	1.863
10.67	135.38	1.863
10.68	135.48	1.864
10.69	135.58	1.866
10.70	135.68	1.868
10.71	135.78	1.868
10.72	135.88	1.868
10.73	135.98	1.872
10.74	136.08	1.873
10.75	136.18	1.872
10.76	136.28	1.872
10.77	136.38	1.873
10.78	136.48	1.873
10.79	136.58	1.874
10.80	136.68	1.874
10.81	136.78	1.876
10.82	136.88	1.876
10.83	136.98	1.875
10.84	137.08	1.875
10.85	137.18	1.876
10.86	137.28	1.877
10.87	137.38	1.878
10.88	137.48	1.878
10.89	137.58	1.879
10.90	137.68	1.879
10.91	137.78	1.878
10.92	137.88	1.881
10.93	137.98	1.882
10.94	138.08	1.883
10.95	138.18	1.883
10.96	138.28	1.882
10.97	138.38	1.882
10.98	138.48	1.883
10.99	138.58	1.884
11.00	138.68	1.885
11.01	138.78	1.886
11.02	138.88	1.887
11.03	138.98	1.887
11.04	139.08	1.889
11.05	139.18	1.890
11.06	139.28	1.891
11.07	139.38	1.893
11.08	139.48	1.893
11.09	139.58	1.893
11.10	139.68	1.895
11.11	139.78	1.896
11.12	139.88	1.896
11.13	139.98	1.898
11.14	140.08	1.898
11.15	140.18	1.900
11.16	140.28	1.900
11.17	140.38	1.898
11.18	140.48	1.899
11.19	140.58	1.900
11.20	140.68	1.899
11.21	140.78	1.900
11.22	140.88	1.901
11.23	140.98	1.902
11.24	141.08	1.901
11.25	141.18	1.901
11.26	141.28	1.902
11.27	141.38	1.901
11.28	141.48	1.902
11.29	141.58	1.903
11.30	141.68	1.904
11.31	141.78	1.904
11.32	141.88	1.904
11.33	141.98	1.905
11.34	142.08	1.907
11.35	142.18	1.908
11.36	142.28	1.908
11.37	142.38	1.910
11.38	142.48	1.912
11.39	142.58	1.912
11.40	142.68	1.912
11.41	142.78	1.913
11.42	142.88	1.912
11.43	142.98	1.914
11.44	143.08	1.914
11.45	143.18	1.914
11.46	143.28	1.916
11.47	143.38	1.917
11.48	143.48	1.920
11.49	143.58	1.920
11.50	143.68	1.920
11.51	143.78	1.921
11.52	143.88	1.922
11.53	143.98	1.923
11.54	144.08	1.922
11.55	144.18	1.921
11.56	144.28	1.923
11.57	144.38	1.923
11.58	144.48	1.924
11.59	144.58	1.924
11.60	144.68	1.926
11.61	144.78	1.927
11.62	144.88	1.928
11.63	144.98	1.929
11.64	145.08	1.929
11.65	145.18	1.931
11.66	145.28	1.932
11.67	145.38	1.933
11.68	145.49	1.931
11.69	145.58	1.933
11.70	145.68	1.934
11.71	145.79	1.934
11.72	145.88	1.934
11.73	145.98	1.935
11.74	146.08	1.937
11.75	146.18	1.938
11.76	146.28	1.937
11.77	146.39	1.938
11.78	146.48	1.939
11.79	146.58	1.941
11.80	146.68	1.940
11.81	146.78	1.940
11.82	146.89	1.941
11.83	146.98	1.943
11.84	147.08	1.944
11.85	147.18	1.945
11.86	147.28	1.945
11.87	147.39	1.946
11.88	147.49	1.946
11.89	147.59	1.947
11.90	147.68	1.947
11.91	147.79	1.947
11.92	147.89	1.948
11.93	147.98	1.950
11.94	148.09	1.950
11.95	148.19	1.950
11.96	148.28	1.952
11.97	148.39	1.953
11.98	148.49	1.953
11.99	148.59	1.953
12.00	148.69	1.953
12.01	148.79	1.956
12.02	148.89	1.955
12.03	148.99	1.956
12.04	149.09	1.957
12.05	149.19	1.958
12.06	149.29	1.959
12.07	149.38	1.961
12.08	149.49	1.961
12.09	149.59	1.961
12.10	149.69	1.961
12.11	149.79	1.963
12.12	149.89	1.965
12.13	149.99	1.964
12.14	150.09	1.964
12.15	150.19	1.966
12.16	150.29	1.967
12.17	150.39	1.966
12.18	150.49	1.968
12.19	150.59	1.969
12.20	150.69	1.969
12.21	150.79	1.969
12.22	150.89	1.970
12.23	150.98	1.970
12.24	151.09	1.970
12.25	151.19	1.970
12.26	151.29	1.971
12.27	151.39	1.972
12.28	151.49	1.972
12.29	151.59	1.974
12.30	151.69	1.975
12.31	151.79	1.976
12.32	151.89	1.976
12.33	151.99	1.976
12.34	152.09	1.977
12.35	152.19	1.978
12.36	152.29	1.980
12.37	152.39	1.981
12.38	152.49	1.982
12.39	152.59	1.982
12.40	152.69	1.983
12.41	152.79	1.985
12.42	152.89	1.987
12.43	152.99	1.987
12.44	153.09	1.989
12.45	153.19	1.990
12.46	153.29	1.993
12.47	153.39	1.992
12.48	153.49	1.990
12.49	153.59	1.991
12.50	153.69	1.992
12.51	153.79	1.993
12.52	153.89	1.993
12.53	153.99	1.995
12.54	154.09	1.995
12.55	154.19	1.994
12.56	154.29	1.994
12.57	154.39	1.996
12.58	154.49	1.996
12.59	154.59	1.997
12.60	154.69	1.998
12.61	154.79	1.999
12.62	154.89	1.998
12.63	154.99	1.996
12.64	155.09	1.996
12.65	155.19	1.996
12.66	155.29	1.998
12.67	155.39	2.000
12.68	155.49	2.001
12.69	155.59	2.000
12.70	155.69	2.002
12.71	155.79	2.002
12.72	155.89	2.005
12.73	155.99	2.009
12.74	156.09	2.008
12.75	156.19	2.008
12.76	156.29	2.008
12.77	156.39	2.008
12.78	156.49	2.009
12.79	156.59	2.010
12.80	156.69	2.010
12.81	156.79	2.011
12.82	156.89	2.012
12.83	156.99	2.012
12.84	157.09	2.013
12.85	157.19	2.012
12.86	157.29	2.013
12.87	157.39	2.014
12.88	157.49	2.015
12.89	157.59	2.016
12.90	157.69	2.017
12.91	157.79	2.018
12.92	157.89	2.018
12.93	157.99	2.019
12.94	158.09	2.020
12.95	158.19	2.020
12.96	158.29	2.019
12.97	158.39	2.020
12.98	158.49	2.020
12.99	158.59	2.020
13.00	158.69	2.019

[step]
Ramp 10.00 °C/min to 30.00 °C
Time	Temperature	Heat Flow (Normalized)	Heat Capacity (Normalized)
min	°C	W/g	J/(g.°C)
14.00	160.09	-1.567	0.000
14.01	160.09	-1.570	0.000
14.02	160.09	-1.572	0.000
14.03	160.08	-1.576	0.000
14.04	160.08	-1.576	0.000
14.05	160.08	-1.566	41.996
14.06	160.07	-1.482	33.725
14.07	160.05	-1.226	24.066
14.08	160.03	-0.855	14.681
14.09	160.00	-0.626	9.518
14.10	159.97	-0.426	5.787
14.11	159.93	-0.382	4.692
14.12	159.88	-0.369	4.126
14.13	159.82	-0.447	4.584
14.14	159.76	-0.510	4.831
14.15	159.69	-0.818	7.216
14.16	159.62	-1.413	11.685
14.17	159.55	-1.748	13.641
14.18	159.47	-2.128	15.771
14.19	159.39	-2.400	17.013
14.20	159.31	-2.758	18.815
14.21	159.23	-2.963	19.552
14.22	159.14	-3.198	20.524
14.23	159.06	-3.385	21.206
14.24	158.97	-3.602	22.108
14.25	158.88	-3.720	22.451
14.26	158.79	-3.864	22.977
14.27	158.70	-3.934	23.108
14.28	158.61	-4.072	23.659
14.29	158.51	-4.134	23.797
14.30	158.42	-4.197	23.975
14.31	158.33	-4.305	24.415
14.32	158.23	-4.369	24.628
14.33	158.14	-4.423	24.788
14.34	158.04	-4.520	25.211
14.35	157.95	-4.547	25.240
14.36	157.85	-4.576	25.306
14.37	157.75	-4.598	25.340
14.38	157.66	-4.638	25.488
14.39	157.56	-4.685	25.671
14.40	157.46	-4.699	25.682
14.41	157.37	-4.732	25.802
14.42	157.27	-4.756	25.886
14.43	157.17	-4.772	25.938
14.44	157.08	-4.787	25.967
14.45	156.98	-4.815	26.075
14.46	156.88	-4.833	26.139
14.47	156.78	-4.847	26.185
14.48	156.68	-4.856	26.213
14.49	156.59	-4.874	26.286
14.50	156.49	-4.878	26.276
14.51	156.39	-4.884	26.284
14.52	156.29	-4.894	26.312
14.53	156.20	-4.912	26.395
14.54	156.10	-4.919	26.411
14.55	156.00	-4.928	26.452
14.56	155.90	-4.935	26.467
14.57	155.80	-4.941	26.492
14.58	155.70	-4.947	26.508
14.59	155.60	-4.952	26.522
14.60	155.51	-4.960	26.555
14.61	155.41	-4.966	26.580
14.62	155.31	-4.971	26.594
14.63	155.21	-4.977	26.611
14.64	155.11	-4.982	26.635
14.65	155.01	-4.987	26.660
14.66	154.91	-4.997	26.703
14.67	154.81	-5.002	26.725
14.68	154.72	-5.008	26.740
14.69	154.62	-5.013	26.764
14.70	154.52	-5.021	26.801
14.71	154.42	-5.023	26.806
14.72	154.32	-5.030	26.837
14.73	154.22	-5.035	26.865
14.74	154.12	-5.038	26.876
14.75	154.02	-5.044	26.898
14.76	153.92	-5.049	26.925
14.77	153.83	-5.052	26.932
14.78	153.73	-5.055	26.942
14.79	153.63	-5.061	26.969
14.80	153.53	-5.064	26.979
14.81	153.43	-5.067	26.992
14.82	153.33	-5.070	27.006
14.83	153.23	-5.072	27.013
14.84	153.13	-5.076	27.026
14.85	153.03	-5.080	27.043
14.86	152.93	-5.081	27.051
14.87	152.83	-5.084	27.054
14.88	152.73	-5.087	27.072
14.89	152.63	-5.090	27.084
14.90	152.54	-5.090	27.075
14.91	152.44	-5.092	27.082
14.92	152.34	-5.095	27.096
14.93	152.24	-5.098	27.107
14.94	152.14	-5.099	27.111
14.95	152.04	-5.101	27.120
14.96	151.94	-5.102	27.111
14.97	151.84	-5.104	27.121
14.98	151.74	-5.106	27.133
14.99	151.64	-5.107	27.139
15.00	151.54	-5.108	27.150
15.01	151.44	-5.111	27.159
15.02	151.34	-5.113	27.167
15.03	151.24	-5.113	27.167
15.04	151.14	-5.114	27.167
15.05	151.04	-5.116	27.182
15.06	150.94	-5.116	27.178
15.07	150.85	-5.117	27.184
15.08	150.75	-5.117	27.178
15.09	150.65	-5.118	27.176
15.10	150.55	-5.119	27.185
15.11	150.45	-5.119	27.194
15.12	150.35	-5.120	27.196
15.13	150.25	-5.120	27.184
15.14	150.15	-5.119	27.174
15.15	150.05	-5.121	27.188
15.16	149.95	-5.120	27.195
15.17	149.85	-5.118	27.173
15.18	149.75	-5.120	27.184
15.19	149.65	-5.117	27.167
15.20	149.55	-5.117	27.163
15.21	149.45	-5.117	27.161
15.22	149.35	-5.116	27.148
15.23	149.25	-5.117	27.157
15.24	149.15	-5.116	27.155
15.25	149.05	-5.117	27.144
15.26	148.95	-5.117	27.137
15.27	148.85	-5.116	27.136
15.28	148.76	-5.116	27.137
15.29	148.66	-5.113	27.127
15.30	148.56	-5.114	27.127
15.31	148.46	-5.113	27.112
15.32	148.36	-5.111	27.103
15.33	148.26	-5.111	27.099
15.34	148.16	-5.110	27.096
15.35	148.06	-5.108	27.084
15.36	147.96	-5.106	27.065
15.37	147.86	-5.104	27.057
15.38	147.76	-5.105	27.059
15.39	147.66	-5.104	27.055
15.40	147.56	-5.102	27.043
15.41	147.46	-5.100	27.032
15.42	147.36	-5.100	27.040
15.43	147.26	-5.100	27.033
15.44	147.16	-5.099	27.020
15.45	147.06	-5.097	27.011
15.46	146.96	-5.096	27.006
15.47	146.86	-5.095	27.009
15.48	146.76	-5.095	27.008
15.49	146.66	-5.091	26.980
15.50	146.56	-5.089	26.969
15.51	146.46	-5.090	26.974
15.52	146.36	-5.087	26.961
15.53	146.26	-5.085	26.955
15.54	146.16	-5.084	26.950
15.55	146.06	-5.082	26.929
15.56	145.96	-5.081	26.931
15.57	145.86	-5.078	26.915
15.58	145.76	-5.077	26.906
15.59	145.66	-5.076	26.902
15.60	145.56	-5.076	26.890
15.61	145.46	-5.074	26.884
15.62	145.36	-5.073	26.878
15.63	145.26	-5.072	26.871
15.64	145.16	-5.070	26.869
15.65	145.06	-5.068	26.862
15.66	144.96	-5.067	26.858
15.67	144.86	-5.064	26.834
15.68	144.76	-5.062	26.816
15.69	144.66	-5.059	26.809
15.70	144.56	-5.053	26.777
15.71	144.46	-5.052	26.775
15.72	144.36	-5.052	26.772
15.73	144.26	-5.052	26.771
15.74	144.16	-5.050	26.763
15.75	144.07	-5.047	26.747
15.76	143.96	-5.045	26.738
15.77	143.86	-5.045	26.744
15.78	143.76	-5.043	26.737
15.79	143.67	-5.042	26.737
15.80	143.57	-5.040	26.724
15.81	143.47	-5.037	26.704
15.82	143.37	-5.036	26.701
15.83	143.27	-5.034	26.695
15.84	143.17	-5.034	26.688
15.85	143.07	-5.032	26.671
15.86	142.97	-5.029	26.663
15.87	142.87	-5.028	26.652
15.88	142.77	-5.026	26.651
15.89	142.67	-5.025	26.638
15.90	142.57	-5.025	26.642
15.91	142.47	-5.023	26.635
15.92	142.37	-5.022	26.629
15.93	142.27	-5.020	26.619
15.94	142.17	-5.018	26.605
15.95	142.07	-5.014	26.591
15.96	141.97	-5.014	26.592
15.97	141.87	-5.011	26.568
15.98	141.77	-5.011	26.563
15.99	141.67	-5.009	26.559
16.00	141.57	-5.006	26.546
16.01	141.47	-5.006	26.542
16.02	141.37	-5.002	26.521
16.03	141.27	-5.002	26.513
16.04	141.17	-5.000	26.504
16.05	141.07	-4.997	26.498
16.06	140.97	-4.995	26.483
16.07	140.87	-4.993	26.474
16.08	140.77	-4.991	26.463
16.09	140.67	-4.989	26.452
16.10	140.57	-4.987	26.440
16.11	140.47	-4.984	26.424
16.12	140.37	-4.983	26.422
16.13	140.27	-4.982	26.414
16.14	140.17	-4.979	26.399
16.15	140.07	-4.979	26.400
16.16	139.97	-4.977	26.390
16.17	139.87	-4.975	26.386
16.18	139.77	-4.975	26.386
16.19	139.67	-4.973	26.372
16.20	139.57	-4.971	26.349
16.21	139.47	-4.971	26.362
16.22	139.37	-4.971	26.363
16.23	139.27	-4.966	26.343
16.24	139.17	-4.963	26.331
16.25	139.07	-4.963	26.325
16.26	138.97	-4.960	26.314
16.27	138.87	-4.958	26.305
16.28	138.77	-4.955	26.292
16.29	138.67	-4.954	26.285
16.30	138.57	-4.953	26.272
16.31	138.47	-4.951	26.265
16.32	138.37	-4.947	26.237
16.33	138.27	-4.947	26.240
16.34	138.17	-4.946	26.237
16.35	138.07	-4.945	26.219
16.36	137.97	-4.942	26.211
16.37	137.87	-4.940	26.194
16.38	137.77	-4.939	26.193
16.39	137.67	-4.937	26.183
16.40	137.57	-4.936	26.188
16.41	137.48	-4.935	26.178
16.42	137.37	-4.933	26.168
16.43	137.27	-4.931	26.161
16.44	137.17	-4.930	26.149
16.45	137.07	-4.927	26.129
16.46	136.97	-4.927	26.130
16.47	136.88	-4.926	26.118
16.48	136.77	-4.926	26.114
16.49	136.68	-4.923	26.102
16.50	136.58	-4.920	26.090
16.51	136.47	-4.918	26.081
16.52	136.38	-4.918	26.086
16.53	136.28	-4.915	26.072
16.54	136.18	-4.915	26.068
16.55	136.08	-4.913	26.066
16.56	135.98	-4.912	26.052
16.57	135.88	-4.905	26.028
16.58	135.78	-4.904	26.008
16.59	135.68	-4.902	25.999
16.60	135.58	-4.901	25.997
16.61	135.48	-4.900	25.988
16.62	135.38	-4.897	25.966
16.63	135.28	-4.895	25.955
16.64	135.18	-4.893	25.948
16.65	135.08	-4.890	25.938
16.66	134.98	-4.889	25.932
16.67	134.88	-4.889	25.928
16.68	134.78	-4.888	25.929
16.69	134.68	-4.885	25.917
16.70	134.58	-4.884	25.909
16.71	134.48	-4.882	25.894
16.72	134.38	-4.881	25.881
16.73	134.28	-4.880	25.881
16.74	134.18	-4.879	25.879
16.75	134.08	-4.878	25.872
16.76	133.98	-4.874	25.859
16.77	133.88	-4.873	25.847
16.78	133.78	-4.873	25.858
16.79	133.68	-4.872	25.855
16.80	133.58	-4.870	25.839
16.81	133.48	-4.868	25.827
16.82	133.38	-4.867	25.828
16.83	133.28	-4.867	25.832
16.84	133.18	-4.865	25.812
16.85	133.08	-4.863	25.804
16.86	132.98	-4.863	25.807
16.87	132.88	-4.862	25.805
16.88	132.78	-4.858	25.788
16.89	132.68	-4.858	25.781
16.90	132.58	-4.859	25.791
16.91	132.48	-4.858	25.785
16.92	132.38	-4.852	25.768
16.93	132.28	-4.848	25.739
16.94	132.18	-4.849	25.737
16.95	132.08	-4.847	25.735
16.96	131.98	-4.848	25.736
16.97	131.88	-4.847	25.727
16.98	131.78	-4.846	25.720
16.99	131.68	-4.844	25.707
17.00	131.58	-4.842	25.705
17.01	131.48	-4.840	25.695
17.02	131.38	-4.840	25.696
17.03	131.28	-4.837	25.673
17.04	131.18	-4.836	25.673
17.05	131.08	-4.835	25.666
17.06	130.98	-4.835	25.666
17.07	130.88	-4.832	25.656
17.08	130.78	-4.830	25.640
17.09	130.68	-4.831	25.648
17.10	130.58	-4.826	25.627
17.11	130.48	-4.825	25.623
17.12	130.38	-4.825	25.612
17.13	130.28	-4.823	25.612
17.14	130.18	-4.822	25.610
17.15	130.08	-4.820	25.590
17.16	129.98	-4.819	25.584
17.17	129.88	-4.819	25.592
17.18	129.78	-4.818	25.591
17.19	129.68	-4.816	25.571
17.20	129.58	-4.813	25.558
17.21	129.48	-4.813	25.562
17.22	129.38	-4.813	25.568
17.23	129.28	-4.810	25.547
17.24	129.18	-4.809	25.545
17.25	129.08	-4.807	25.535
17.26	128.98	-4.806	25.525
17.27	128.88	-4.805	25.517
17.28	128.78	-4.805	25.519
17.29	128.68	-4.805	25.510
17.30	128.58	-4.804	25.504
17.31	128.48	-4.803	25.502
17.32	128.38	-4.801	25.497
17.33	128.28	-4.798	25.482
17.34	128.18	-4.799	25.480
17.35	128.08	-4.797	25.480
17.36	127.98	-4.797	25.484
17.37	127.88	-4.797	25.475
17.38	127.78	-4.795	25.466
17.39	127.68	-4.793	25.466
17.40	127.58	-4.789	25.452
17.41	127.48	-4.789	25.448
17.42	127.38	-4.789	25.445
17.43	127.29	-4.790	25.456
17.44	127.18	-4.789	25.447
17.45	127.08	-4.787	25.430
17.46	126.98	-4.788	25.442
17.47	126.88	-4.788	25.449
17.48	126.78	-4.782	25.405
17.49	126.68	-4.778	25.386
17.50	126.59	-4.779	25.391
17.51	126.49	-4.776	25.386
17.52	126.38	-4.776	25.385
17.53	126.29	-4.773	25.363
17.54	126.19	-4.770	25.350
17.55	126.09	-4.768	25.337
17.56	125.99	-4.769	25.338
17.57	125.89	-4.769	25.338
17.58	125.79	-4.767	25.333
17.59	125.69	-4.766	25.325
17.60	125.59	-4.767	25.321
17.61	125.49	-4.766	25.321
17.62	125.39	-4.766	25.323
17.63	125.29	-4.765	25.317
17.64	125.19	-4.765	25.314
17.65	125.09	-4.764	25.310
17.66	124.99	-4.763	25.307
17.67	124.89	-4.761	25.289
17.68	124.79	-4.763	25.316
17.69	124.69	-4.762	25.315
17.70	124.59	-4.758	25.293
17.71	124.49	-4.758	25.290
17.72	124.39	-4.757	25.280
17.73	124.29	-4.755	25.280
17.74	124.19	-4.755	25.277
17.75	124.09	-4.753	25.259
17.76	123.99	-4.750	25.250
17.77	123.89	-4.750	25.250
17.78	123.79	-4.749	25.239
17.79	123.69	-4.750	25.244
17.80	123.59	-4.748	25.233
17.81	123.49	-4.746	25.227
17.82	123.39	-4.746	25.229
17.83	123.29	-4.746	25.224
17.84	123.19	-4.743	25.208
17.85	123.09	-4.742	25.204
17.86	122.99	-4.739	25.193
17.87	122.89	-4.739	25.201
17.88	122.79	-4.739	25.192
17.89	122.69	-4.739	25.190
17.90	122.59	-4.736	25.178
17.91	122.49	-4.735	25.173
17.92	122.39	-4.735	25.177
17.93	122.29	-4.734	25.168
17.94	122.19	-4.728	25.137
17.95	122.09	-4.729	25.146
17.96	121.99	-4.729	25.147
17.97	121.89	-4.729	25.143
17.98	121.79	-4.726	25.127
17.99	121.69	-4.727	25.136
18.00	121.59	-4.723	25.109
18.01	121.49	-4.721	25.097
18.02	121.39	-4.722	25.098
18.03	121.29	-4.721	25.094
18.04	121.19	-4.720	25.098
18.05	121.09	-4.719	25.083
18.06	120.99	-4.719	25.080
18.07	120.89	-4.717	25.064
18.08	120.79	-4.717	25.071
18.09	120.69	-4.716	25.063
18.10	120.59	-4.715	25.058
18.11	120.49	-4.714	25.050
18.12	120.39	-4.714	25.048
18.13	120.29	-4.713	25.052
18.14	120.19	-4.711	25.035
18.15	120.09	-4.710	25.027
18.16	119.99	-4.710	25.033
18.17	119.89	-4.710	25.030
18.18	119.79	-4.708	25.033
18.19	119.69	-4.708	25.034
18.20	119.59	-4.708	25.044
18.21	119.49	-4.706	25.029
18.22	119.39	-4.705	25.031
18.23	119.29	-4.704	25.028
18.24	119.19	-4.705	25.019
18.25	119.09	-4.703	25.012
18.26	118.99	-4.703	25.012
18.27	118.89	-4.701	25.009
18.28	118.79	-4.702	25.010
18.29	118.69	-4.703	25.019
18.30	118.59	-4.702	25.014
18.31	118.49	-4.699	25.004
18.32	118.39	-4.699	25.001
18.33	118.29	-4.694	24.964
18.34	118.19	-4.693	24.968
18.35	118.09	-4.693	24.972
18.36	117.99	-4.690	24.953
18.37	117.89	-4.689	24.948
18.38	117.79	-4.688	24.937
18.39	117.69	-4.688	24.939
18.40	117.59	-4.687	24.928
18.41	117.49	-4.686	24.931
18.42	117.39	-4.687	24.933
18.43	117.29	-4.686	24.923
18.44	117.19	-4.685	24.925
18.45	117.09	-4.684	24.922
18.46	116.99	-4.682	24.914
18.47	116.89	-4.682	24.916
18.48	116.79	-4.680	24.898
18.49	116.69	-4.678	24.878
18.50	116.59	-4.679	24.891
18.51	116.49	-4.678	24.886
[...]
19.31	108.50	-4.608	24.543
19.32	108.40	-4.600	24.503
19.33	108.30	-4.603	24.514
19.34	108.20	-4.601	24.509
19.35	108.10	-4.600	24.507
19.36	108.00	-4.600	24.502
19.37	107.90	-4.603	24.516
19.38	107.80	-4.599	24.496
19.39	107.70	-4.599	24.502
19.40	107.60	-4.601	24.515
19.41	107.50	-4.596	24.481
19.42	107.40	-4.597	24.494
19.43	107.30	-4.596	24.488
19.44	107.20	-4.595	24.482
19.45	107.10	-4.593	24.471
19.46	107.00	-4.592	24.468
19.47	106.90	-4.586	24.439
19.48	106.80	-4.589	24.457
19.49	106.70	-4.589	24.460
19.50	106.60	-4.588	24.454
19.51	106.50	-4.586	24.441
19.52	106.40	-4.588	24.449
19.53	106.30	-4.586	24.440
19.54	106.20	-4.587	24.441
19.55	106.10	-4.586	24.438
19.56	106.00	-4.584	24.428
19.57	105.90	-4.584	24.431
19.58	105.80	-4.583	24.433
19.59	105.70	-4.583	24.429
19.60	105.60	-4.582	24.419
19.61	105.50	-4.583	24.431
19.62	105.40	-4.581	24.421
19.63	105.30	-4.580	24.420
19.64	105.21	-4.579	24.412
19.65	105.11	-4.578	24.401
19.66	105.01	-4.579	24.407
19.67	104.90	-4.575	24.381
19.68	104.81	-4.574	24.387
19.69	104.71	-4.573	24.382
19.70	104.61	-4.573	24.376
19.71	104.51	-4.573	24.377
19.72	104.41	-4.574	24.383
19.73	104.31	-4.572	24.375
19.74	104.21	-4.571	24.363
19.75	104.11	-4.567	24.343
19.76	104.01	-4.571	24.367
19.77	103.91	-4.571	24.371
19.78	103.81	-4.571	24.365
19.79	103.71	-4.570	24.364
19.80	103.61	-4.568	24.360
19.81	103.51	-4.567	24.346
19.82	103.41	-4.566	24.341
19.83	103.31	-4.564	24.324
19.84	103.21	-4.565	24.327
19.85	103.11	-4.562	24.321
19.86	103.01	-4.559	24.304
19.87	102.91	-4.560	24.316
19.88	102.81	-4.561	24.307
19.89	102.71	-4.559	24.303
19.90	102.61	-4.558	24.296
19.91	102.51	-4.557	24.293
19.92	102.41	-4.556	24.288
19.93	102.31	-4.556	24.294
19.94	102.21	-4.557	24.300
19.95	102.11	-4.557	24.298
19.96	102.01	-4.557	24.297
19.97	101.91	-4.557	24.296
19.98	101.81	-4.555	24.291
19.99	101.71	-4.554	24.283
20.00	101.61	-4.555	24.282
20.01	101.51	-4.554	24.283
20.02	101.41	-4.553	24.276
20.03	101.31	-4.551	24.270
20.04	101.21	-4.550	24.270
20.05	101.11	-4.550	24.264
20.06	101.01	-4.549	24.263
20.07	100.91	-4.549	24.261
20.08	100.81	-4.550	24.270
20.09	100.71	-4.548	24.263
20.10	100.61	-4.550	24.269
20.11	100.51	-4.548	24.259
20.12	100.41	-4.547	24.255
20.13	100.31	-4.547	24.251
20.14	100.21	-4.548	24.257
20.15	100.11	-4.549	24.270
20.16	100.01	-4.544	24.242
20.17	99.91	-4.542	24.234
20.18	99.81	-4.542	24.227
20.19	99.71	-4.541	24.228
20.20	99.61	-4.541	24.223
20.21	99.51	-4.541	24.228
20.22	99.41	-4.538	24.215
20.23	99.31	-4.538	24.217
20.24	99.21	-4.539	24.219
20.25	99.11	-4.540	24.221
20.26	99.01	-4.539	24.218
20.27	98.91	-4.539	24.214
20.28	98.81	-4.537	24.203
20.29	98.71	-4.537	24.205
20.30	98.61	-4.536	24.203
20.31	98.51	-4.536	24.201
20.32	98.41	-4.535	24.199
20.33	98.31	-4.534	24.186
20.34	98.21	-4.534	24.188
20.35	98.11	-4.533	24.182
20.36	98.01	-4.532	24.183
20.37	97.91	-4.531	24.180
20.38	97.81	-4.532	24.183
20.39	97.71	-4.532	24.184
20.40	97.61	-4.531	24.184
20.41	97.51	-4.531	24.179
20.42	97.41	-4.530	24.177
20.43	97.31	-4.528	24.170
20.44	97.21	-4.527	24.160
20.45	97.11	-4.527	24.162
20.46	97.01	-4.527	24.163
20.47	96.91	-4.526	24.155
20.48	96.81	-4.524	24.153
20.49	96.71	-4.523	24.146
20.50	96.61	-4.523	24.140
20.51	96.51	-4.523	24.144
20.52	96.41	-4.521	24.133
20.53	96.31	-4.520	24.133
20.54	96.21	-4.519	24.128
20.55	96.11	-4.519	24.125
20.56	96.01	-4.518	24.118
20.57	95.91	-4.519	24.124
20.58	95.81	-4.519	24.124
20.59	95.71	-4.517	24.117
20.60	95.61	-4.517	24.116
20.61	95.51	-4.517	24.116
20.62	95.41	-4.518	24.118
20.63	95.31	-4.518	24.117
20.64	95.22	-4.515	24.106
20.65	95.11	-4.516	24.113
20.66	95.01	-4.514	24.103
20.67	94.92	-4.512	24.095
20.68	94.81	-4.512	24.097
20.69	94.71	-4.511	24.084
20.70	94.62	-4.510	24.086
20.71	94.51	-4.510	24.087
20.72	94.41	-4.510	24.086
20.73	94.32	-4.510	24.093
20.74	94.21	-4.508	24.078
20.75	94.12	-4.507	24.073
20.76	94.02	-4.507	24.080
20.77	93.92	-4.506	24.073
20.78	93.82	-4.505	24.069
20.79	93.72	-4.503	24.056
20.80	93.62	-4.503	24.052
20.81	93.52	-4.503	24.049
20.82	93.42	-4.500	24.037
20.83	93.32	-4.496	24.014
20.84	93.22	-4.496	24.015
20.85	93.12	-4.495	24.009
20.86	93.02	-4.492	23.997
20.87	92.92	-4.491	23.986
20.88	92.82	-4.493	24.001
20.89	92.72	-4.491	23.987
20.90	92.62	-4.489	23.977
20.91	92.52	-4.489	23.973
20.92	92.42	-4.489	23.974
20.93	92.32	-4.488	23.965
20.94	92.22	-4.488	23.965
20.95	92.12	-4.486	23.956
20.96	92.02	-4.488	23.960
20.97	91.92	-4.486	23.950
20.98	91.82	-4.486	23.949
20.99	91.72	-4.484	23.940
21.00	91.62	-4.482	23.936
21.01	91.52	-4.483	23.939
21.02	91.42	-4.484	23.945
21.03	91.32	-4.482	23.941
21.04	91.22	-4.481	23.932
21.05	91.12	-4.479	23.926
21.06	91.02	-4.477	23.915
21.07	90.92	-4.477	23.922
21.08	90.82	-4.478	23.922
21.09	90.72	-4.477	23.922
21.10	90.62	-4.476	23.916
21.11	90.52	-4.474	23.907
21.12	90.42	-4.474	23.912
21.13	90.32	-4.471	23.896
21.14	90.22	-4.470	23.892
21.15	90.12	-4.472	23.901
21.16	90.02	-4.471	23.897
21.17	89.92	-4.470	23.899
21.18	89.82	-4.467	23.878
21.19	89.72	-4.467	23.880
21.20	89.62	-4.467	23.872
21.21	89.52	-4.465	23.871
21.22	89.42	-4.463	23.860
21.23	89.32	-4.463	23.856
21.24	89.22	-4.463	23.857
21.25	89.12	-4.460	23.844
21.26	89.02	-4.458	23.829
21.27	88.92	-4.458	23.827
21.28	88.82	-4.458	23.828
21.29	88.72	-4.458	23.827
21.30	88.62	-4.457	23.819
21.31	88.52	-4.455	23.813
21.32	88.42	-4.455	23.812
21.33	88.32	-4.455	23.802
21.34	88.22	-4.453	23.792
21.35	88.12	-4.451	23.792
21.36	88.02	-4.450	23.779
21.37	87.92	-4.449	23.777
21.38	87.82	-4.448	23.776
21.39	87.72	-4.442	23.742
21.40	87.62	-4.443	23.742
21.41	87.52	-4.441	23.737
21.42	87.42	-4.441	23.740
21.43	87.32	-4.440	23.735
21.44	87.22	-4.440	23.732
21.45	87.12	-4.438	23.721
21.46	87.02	-4.436	23.712
21.47	86.92	-4.438	23.720
21.48	86.82	-4.441	23.731
21.49	86.72	-4.439	23.720
21.50	86.62	-4.437	23.712
21.51	86.52	-4.437	23.705
21.52	86.42	-4.436	23.701
21.53	86.32	-4.436	23.710
21.54	86.22	-4.434	23.694
21.55	86.12	-4.435	23.698
21.56	86.02	-4.435	23.707
21.57	85.92	-4.432	23.693
21.58	85.82	-4.430	23.677
21.59	85.72	-4.430	23.710
21.60	85.62	-4.429	23.851
21.61	85.52	-4.430	23.931
21.62	85.42	-4.426	23.907
21.63	85.32	-4.428	23.898
21.64	85.22	-4.427	23.879
21.65	85.12	-4.425	23.848
21.66	85.02	-4.425	23.831
21.67	84.92	-4.425	23.818
21.68	84.82	-4.425	23.801
21.69	84.72	-8.887	47.791
21.70	84.64	-18.174	97.697
21.71	84.55	-9.324	50.108
21.72	84.45	-6.664	35.796
21.73	84.35	-5.909	31.721
21.74	84.24	-5.569	29.888
21.75	84.14	-5.349	28.710
21.76	84.04	-5.402	28.986
21.77	83.94	-5.258	28.195
21.78	83.84	-5.234	28.060
21.79	83.74	-5.234	28.038
21.80	83.64	-5.105	27.194
21.81	83.54	-5.138	27.249
21.82	83.44	-5.150	27.296
21.83	83.33	-5.141	27.257
21.84	83.23	-5.081	26.963
21.85	83.13	-5.104	27.105
21.86	83.03	-5.081	26.994
21.87	82.93	-5.056	26.871
21.88	82.83	-5.051	26.861
21.89	82.73	-5.044	26.830
21.90	82.63	-5.038	26.801
21.91	82.53	-5.022	26.731
21.92	82.43	-4.994	26.596
21.93	82.33	-4.988	26.574
21.94	82.23	-4.977	26.524
21.95	82.13	-4.970	26.484
21.96	82.03	-4.956	26.411
21.97	81.93	-4.951	26.397
21.98	81.83	-4.945	26.551
21.99	81.73	-4.937	27.571
22.00	81.63	-4.934	28.064
22.01	81.53	-4.928	27.917
22.02	81.43	-4.922	27.766
22.03	81.33	-4.918	27.608
22.04	81.23	-4.913	27.434
22.05	81.13	-4.903	27.250
22.06	81.03	-4.895	27.088
22.07	80.93	-4.893	26.976
22.08	80.84	-25.154	138.207
22.09	80.83	-90.195	494.026
22.10	80.76	-25.220	137.783
22.11	80.65	-14.581	79.450
22.12	80.54	-11.770	63.977
22.13	80.43	-9.161	49.701
22.14	80.32	-7.933	42.958
22.15	80.21	-7.282	39.363
22.16	80.10	-7.128	38.474
22.17	80.00	-7.251	39.089
22.18	79.89	-6.373	34.176
22.19	79.78	-6.076	31.473
22.20	79.68	-5.894	29.799
22.21	79.57	-5.722	28.995
22.22	79.47	-5.568	28.320
22.23	79.36	-5.442	27.783
22.24	79.26	-5.354	27.447
22.25	79.16	-5.222	26.881
22.26	79.05	-5.053	26.113
22.27	78.95	-5.052	26.191
22.28	78.85	-4.995	25.970
22.29	78.75	-4.928	25.695
22.30	78.65	-4.868	25.437
22.31	78.54	-4.859	25.452
22.32	78.44	-4.817	25.288
22.33	78.34	-4.781	25.142
22.34	78.24	-4.776	25.160
22.35	78.14	-4.748	25.045
22.36	78.04	-4.667	24.643
22.37	77.94	-4.673	24.704
22.38	77.84	-4.653	24.625
22.39	77.74	-4.648	24.621
22.40	77.64	-4.643	24.622
22.41	77.54	-4.639	24.615
22.42	77.43	-4.626	24.562
22.43	77.33	-4.614	24.515
22.44	77.23	-4.608	24.497
22.45	77.13	-4.603	24.480
22.46	77.03	-4.597	24.467
22.47	76.93	-4.592	24.450
22.48	76.83	-4.586	24.426
22.49	76.73	-4.580	24.405
22.50	76.63	-4.573	24.378
22.51	76.53	-4.569	24.358
22.52	76.43	-4.567	24.353
22.53	76.33	-4.551	24.270
22.54	76.23	-4.546	24.244
22.55	76.13	-4.541	24.229
22.56	76.03	-4.538	24.218
22.57	75.93	-4.532	24.183
22.58	75.83	-4.527	24.164
22.59	75.73	-4.524	24.150
22.60	75.63	-4.520	24.131
22.61	75.53	-4.515	24.105
22.62	75.43	-4.510	24.074
22.63	75.33	-4.507	24.065
22.64	75.23	-4.504	24.051
22.65	75.13	-4.500	24.033
22.66	75.03	-4.497	24.007
22.67	74.93	-4.494	23.991
22.68	74.83	-4.490	23.967
22.69	74.73	-4.486	23.944
22.70	74.63	-4.484	23.939
22.71	74.53	-4.481	23.921
22.72	74.43	-4.478	23.907
22.73	74.33	-4.475	23.896
22.74	74.23	-4.474	23.887
22.75	74.14	-4.470	23.861
22.76	74.03	-4.468	23.857
22.77	73.93	-4.465	23.847
22.78	73.83	-4.462	23.826
22.79	73.73	-4.458	23.804
22.80	73.64	-4.455	23.784
22.81	73.53	-4.454	23.773
22.82	73.43	-4.453	23.778
22.83	73.33	-4.449	23.754
22.84	73.23	-4.447	23.747
22.85	73.14	-4.445	23.731
22.86	73.04	-4.443	23.720
22.87	72.94	-4.440	23.706
22.88	72.84	-4.439	23.701
22.89	72.74	-4.438	23.696
22.90	72.64	-4.435	23.678
22.91	72.54	-4.432	23.665
22.92	72.44	-4.432	23.653
22.93	72.34	-4.430	23.646
22.94	72.24	-4.430	23.645
22.95	72.14	-4.428	23.639
22.96	72.04	-4.425	23.628
22.97	71.94	-4.425	23.622
22.98	71.84	-4.424	23.618
22.99	71.74	-4.420	23.606
23.00	71.64	-4.418	23.597
23.01	71.54	-4.415	23.581
23.02	71.44	-4.416	23.583
23.03	71.34	-4.415	23.578
23.04	71.24	-4.412	23.561
23.05	71.14	-4.410	23.550
23.06	71.04	-4.409	23.550
23.07	70.94	-4.406	23.535
23.08	70.84	-4.404	23.528
23.09	70.74	-4.410	23.559
23.10	70.64	-4.408	23.543
23.11	70.54	-4.408	23.547
23.12	70.44	-4.405	23.541
23.13	70.34	-4.399	23.507
23.14	70.24	-4.399	23.493
23.15	70.14	-4.398	23.490
23.16	70.04	-4.397	23.489
23.17	69.94	-4.397	23.490
23.18	69.84	-4.395	23.478
23.19	69.74	-4.395	23.472
23.20	69.64	-4.393	23.464
23.21	69.54	-4.393	23.465
23.22	69.44	-4.393	23.465
23.23	69.34	-4.393	23.460
23.24	69.24	-4.392	23.456
23.25	69.14	-4.390	23.445
23.26	69.04	-4.389	23.445
23.27	68.94	-4.388	23.437
23.28	68.84	-4.385	23.421
23.29	68.74	-4.385	23.420
23.30	68.64	-4.385	23.421
23.31	68.54	-4.383	23.410
23.32	68.44	-4.384	23.414
23.33	68.34	-4.384	23.406
23.34	68.24	-4.384	23.421
23.35	68.14	-4.381	23.406
23.36	68.04	-4.381	23.404
23.37	67.94	-4.381	23.396
23.38	67.84	-4.380	23.397
23.39	67.74	-4.379	23.394
23.40	67.64	-4.377	23.383
23.41	67.54	-4.375	23.370
23.42	67.44	-4.376	23.386
23.43	67.34	-4.376	23.380
23.44	67.24	-4.375	23.371
23.45	67.14	-4.373	23.365
23.46	67.04	-4.373	23.361
23.47	66.94	-4.373	23.360
23.48	66.84	-4.372	23.355
23.49	66.74	-4.370	23.345
23.50	66.64	-4.371	23.357
23.51	66.54	-4.371	23.352
23.52	66.44	-4.371	23.347
23.53	66.34	-4.370	23.351
23.54	66.24	-4.370	23.344
23.55	66.14	-4.366	23.329
23.56	66.04	-4.364	23.313
23.57	65.94	-4.365	23.321
23.58	65.84	-4.366	23.321
23.59	65.74	-4.367	23.337
23.60	65.64	-4.362	23.307
23.61	65.54	-4.361	23.306
23.62	65.44	-4.361	23.299
23.63	65.34	-4.360	23.291
23.64	65.24	-4.362	23.310
23.65	65.14	-4.362	23.307
23.66	65.04	-4.363	23.312
23.67	64.94	-4.362	23.316
23.68	64.84	-4.360	23.301
23.69	64.74	-4.361	23.297
23.70	64.64	-4.362	23.303
23.71	64.54	-4.363	23.316
23.72	64.44	-4.359	23.291
23.73	64.34	-4.357	23.275
23.74	64.24	-4.356	23.276
23.75	64.14	-4.355	23.265
23.76	64.04	-4.354	23.258
23.77	63.94	-4.355	23.263
23.78	63.84	-4.355	23.267
23.79	63.74	-4.348	23.225
23.80	63.64	-4.348	23.218
23.81	63.54	-4.348	23.218
23.82	63.44	-4.347	23.218
23.83	63.34	-4.347	23.222
23.84	63.24	-4.346	23.209
23.85	63.14	-4.342	23.188
23.86	63.04	-4.343	23.201
23.87	62.94	-4.345	23.204
23.88	62.84	-4.344	23.204
23.89	62.74	-4.343	23.204
23.90	62.64	-4.343	23.206
23.91	62.54	-4.344	23.212
23.92	62.44	-4.344	23.212
23.93	62.34	-4.342	23.207
23.94	62.24	-4.341	23.197
23.95	62.14	-4.342	23.205
23.96	62.04	-4.340	23.198
23.97	61.94	-4.338	23.185
23.98	61.84	-4.338	23.183
23.99	61.75	-4.333	23.160
24.00	61.65	-4.333	23.159
24.01	61.55	-4.333	23.159
24.02	61.45	-4.335	23.163
24.03	61.35	-4.333	23.152
24.04	61.25	-4.333	23.159
24.05	61.15	-4.333	23.161
24.06	61.05	-4.334	23.166
24.07	60.95	-4.333	23.163
24.08	60.85	-4.331	23.148
24.09	60.75	-4.331	23.149
24.10	60.65	-4.330	23.143
24.11	60.55	-4.327	23.132
24.12	60.45	-4.328	23.136
24.13	60.35	-4.327	23.129
24.14	60.25	-4.326	23.121
24.15	60.15	-4.325	23.115
24.16	60.05	-4.326	23.116
24.17	59.95	-4.326	23.120
24.18	59.85	-4.325	23.119
24.19	59.75	-4.324	23.109
24.20	59.65	-4.325	23.119
24.21	59.55	-4.324	23.109
24.22	59.45	-4.325	23.114
24.23	59.35	-4.323	23.108
24.24	59.25	-4.321	23.095
24.25	59.15	-4.321	23.089
24.26	59.05	-4.320	23.084
24.27	58.95	-4.317	23.066
24.28	58.85	-4.316	23.066
24.29	58.75	-4.315	23.058
24.30	58.65	-4.316	23.060
24.31	58.55	-4.315	23.054
24.32	58.45	-4.315	23.056
24.33	58.35	-4.314	23.048
24.34	58.25	-4.316	23.065
24.35	58.15	-4.316	23.062
24.36	58.05	-4.315	23.061
24.37	57.95	-4.315	23.057
24.38	57.85	-4.314	23.056
24.39	57.75	-4.313	23.059
24.40	57.65	-4.314	23.062
24.41	57.55	-4.313	23.054
24.42	57.45	-4.314	23.054
24.43	57.35	-4.315	23.060
24.44	57.25	-4.310	23.035
24.45	57.15	-4.312	23.043
24.46	57.05	-4.311	23.045
24.47	56.95	-4.310	23.036
24.48	56.85	-4.309	23.020
24.49	56.75	-4.309	23.018
24.50	56.65	-4.309	23.023
24.51	56.55	-4.308	23.015
24.52	56.45	-4.307	23.002
24.53	56.35	-4.305	22.998
24.54	56.25	-4.307	22.994
24.55	56.15	-4.305	22.991
24.56	56.05	-4.305	22.994
24.57	55.95	-4.304	22.988
24.58	55.85	-4.304	22.982
24.59	55.75	-4.302	22.974
24.60	55.65	-4.302	22.965
24.61	55.55	-4.301	22.961
24.62	55.45	-4.300	22.960
24.63	55.35	-4.300	22.953
24.64	55.25	-4.299	22.950
24.65	55.15	-4.299	22.953
24.66	55.05	-4.299	22.947
24.67	54.95	-4.297	22.940
24.68	54.85	-4.296	22.934
24.69	54.75	-4.296	22.936
24.70	54.65	-4.294	22.922
24.71	54.55	-4.294	22.921
24.72	54.45	-4.298	22.947
24.73	54.35	-4.296	22.932
24.74	54.25	-4.295	22.934
24.75	54.15	-4.295	22.928
24.76	54.05	-4.293	22.914
24.77	53.95	-4.292	22.908
24.78	53.85	-4.291	22.909
24.79	53.75	-4.288	22.882
24.80	53.65	-4.291	22.903
24.81	53.55	-4.286	22.886
24.82	53.45	-4.287	22.880
24.83	53.35	-4.287	22.879
24.84	53.25	-4.282	22.853
24.85	53.15	-4.280	22.838
24.86	53.05	-4.280	22.831
24.87	52.95	-4.282	22.842
24.88	52.85	-4.282	22.845
24.89	52.75	-4.281	22.836
24.90	52.65	-4.278	22.821
24.91	52.55	-4.278	22.824
24.92	52.45	-4.279	22.824
24.93	52.35	-4.276	22.808
24.94	52.25	-4.276	22.805
24.95	52.15	-4.275	22.805
24.96	52.05	-4.275	22.802
24.97	51.95	-4.274	22.797
24.98	51.85	-4.274	22.796
24.99	51.75	-4.275	22.798
25.00	51.65	-4.276	22.800
25.01	51.55	-4.276	22.787
25.02	51.45	-4.275	22.787
25.03	51.35	-4.274	22.791
25.04	51.25	-4.275	22.806
25.05	51.15	-4.275	22.801
25.06	51.05	-4.275	22.813
25.07	50.95	-4.272	22.800
25.08	50.86	-4.273	22.800
25.09	50.75	-4.272	22.791
25.10	50.65	-4.271	22.793
25.11	50.55	-4.269	22.777
25.12	50.45	-4.268	22.769
25.13	50.35	-4.267	22.764
25.14	50.25	-4.266	22.755
25.15	50.16	-4.264	22.738
25.16	50.06	-4.266	22.749
25.17	49.96	-4.266	22.748
25.18	49.86	-4.261	22.717
25.19	49.76	-4.261	22.723
25.20	49.66	-4.259	22.716
25.21	49.56	-4.258	22.716
25.22	49.46	-4.256	22.704
25.23	49.36	-4.256	22.703
25.24	49.26	-4.257	22.704
25.25	49.16	-4.255	22.695
25.26	49.06	-4.254	22.679
25.27	48.96	-4.254	22.676
25.28	48.86	-4.254	22.686
25.29	48.76	-4.253	22.680
25.30	48.66	-4.253	22.675
25.31	48.56	-4.253	22.675
25.32	48.46	-4.252	22.676
25.33	48.36	-4.254	22.689
25.34	48.26	-4.254	22.690
25.35	48.16	-4.252	22.685
25.36	48.06	-4.251	22.666
25.37	47.96	-4.249	22.667
25.38	47.86	-4.248	22.662
25.39	47.76	-4.246	22.648
25.40	47.66	-4.246	22.650
25.41	47.56	-4.247	22.655
25.42	47.46	-4.245	22.654
25.43	47.36	-4.243	22.637
25.44	47.26	-4.243	22.626
25.45	47.16	-4.243	22.622
25.46	47.06	-4.244	22.637
25.47	46.96	-4.243	22.634
25.48	46.86	-4.242	22.624
25.49	46.76	-4.242	22.632
25.50	46.66	-4.243	22.634
25.51	46.56	-4.240	22.621
25.52	46.46	-4.241	22.632
25.53	46.36	-4.241	22.629
25.54	46.26	-4.239	22.616
25.55	46.16	-4.238	22.610
25.56	46.06	-4.236	22.613
25.57	45.96	-4.238	22.622
25.58	45.86	-4.239	22.623
25.59	45.76	-4.238	22.621
25.60	45.66	-4.238	22.622
25.61	45.56	-4.237	22.613
25.62	45.46	-4.237	22.604
25.63	45.36	-4.234	22.592
25.64	45.26	-4.236	22.603
25.65	45.16	-4.237	22.617
25.66	45.06	-4.236	22.607
25.67	44.96	-4.235	22.598
25.68	44.86	-4.233	22.598
25.69	44.76	-4.233	22.595
25.70	44.66	-4.232	22.590
25.71	44.56	-4.229	22.575
25.72	44.46	-4.228	22.573
25.73	44.36	-4.229	22.576
25.74	44.26	-4.229	22.579
25.75	44.16	-4.228	22.570
25.76	44.06	-4.227	22.565
25.77	43.96	-4.225	22.556
25.78	43.86	-4.225	22.554
25.79	43.76	-4.226	22.563
25.80	43.66	-4.225	22.559
25.81	43.56	-4.227	22.574
25.82	43.46	-4.222	22.548
25.83	43.36	-4.222	22.549
25.84	43.26	-4.221	22.546
25.85	43.16	-4.220	22.544
25.86	43.06	-4.221	22.554
25.87	42.96	-4.221	22.546
25.88	42.86	-4.217	22.524
25.89	42.76	-4.216	22.519
25.90	42.66	-4.220	22.533
25.91	42.56	-4.219	22.533
25.92	42.46	-4.219	22.528
25.93	42.36	-4.219	22.527
25.94	42.26	-4.218	22.534
25.95	42.16	-4.214	22.516
25.96	42.06	-4.213	22.502
25.97	41.96	-4.213	22.510
25.98	41.86	-4.210	22.495
25.99	41.76	-4.210	22.495
26.00	41.66	-4.209	22.494
26.01	41.56	-4.210	22.498
26.02	41.46	-4.209	22.498
26.03	41.36	-4.209	22.494
26.04	41.26	-4.209	22.497
26.05	41.16	-4.209	22.495
26.06	41.06	-4.207	22.481
26.07	40.96	-4.206	22.484
26.08	40.86	-4.206	22.485
26.09	40.76	-4.204	22.477
26.10	40.66	-4.204	22.482
26.11	40.56	-4.203	22.484
26.12	40.46	-4.202	22.474
26.13	40.36	-4.202	22.473
26.14	40.26	-4.200	22.466
26.15	40.17	-4.198	22.457
26.16	40.07	-4.197	22.453
26.17	39.97	-4.199	22.459
26.18	39.86	-4.195	22.443
26.19	39.76	-4.195	22.444
26.20	39.67	-4.194	22.440
26.21	39.57	-4.195	22.441
26.22	39.47	-4.191	22.419
26.23	39.37	-4.189	22.410
26.24	39.27	-4.191	22.423
26.25	39.17	-4.190	22.411
26.26	39.07	-4.188	22.410
26.27	38.97	-4.188	22.411
26.28	38.87	-4.189	22.417
26.29	38.77	-4.188	22.413
26.30	38.67	-4.187	22.405
26.31	38.57	-4.187	22.405
26.32	38.47	-4.186	22.398
26.33	38.37	-4.185	22.401
26.34	38.27	-4.186	22.407
26.35	38.17	-4.186	22.394
26.36	38.07	-4.184	22.394
26.37	37.97	-4.183	22.391
26.38	37.87	-4.183	22.387
26.39	37.77	-4.182	22.381
26.40	37.67	-4.184	22.391
26.41	37.57	-4.181	22.384
26.42	37.47	-4.181	22.388
26.43	37.37	-4.181	22.385
26.44	37.27	-4.180	22.382
26.45	37.17	-4.181	22.395
26.46	37.07	-4.180	22.387
26.47	36.97	-4.179	22.381
26.48	36.87	-4.172	22.341
26.49	36.77	-4.173	22.340
26.50	36.67	-4.172	22.340
26.51	36.57	-4.172	22.332
26.52	36.47	-4.173	22.338
26.53	36.37	-4.171	22.332
26.54	36.27	-4.169	22.319
26.55	36.17	-4.170	22.328
26.56	36.07	-4.171	22.329
26.57	35.97	-4.171	22.332
26.58	35.87	-4.170	22.336
26.59	35.77	-4.170	22.330
26.60	35.67	-4.168	22.322
26.61	35.57	-4.168	22.317
26.62	35.47	-4.168	22.312
26.63	35.37	-4.167	22.318
26.64	35.27	-4.168	22.319
26.65	35.17	-4.166	22.303
26.66	35.07	-4.165	22.305
26.67	34.97	-4.163	22.292
26.68	34.87	-4.164	22.301
26.69	34.77	-4.165	22.308
26.70	34.67	-4.164	22.299
26.71	34.57	-4.161	22.290
26.72	34.47	-4.164	22.306
26.73	34.37	-4.166	22.309
26.74	34.27	-4.165	22.313
26.75	34.17	-4.164	22.309
26.76	34.07	-4.165	22.306
26.77	33.97	-4.165	22.312
26.78	33.87	-4.164	22.304
26.79	33.77	-4.164	22.301
26.80	33.67	-4.163	22.295
26.81	33.57	-4.159	22.281
26.82	33.47	-4.158	22.276
26.83	33.37	-4.156	22.256
26.84	33.27	-4.155	22.256
26.85	33.17	-4.156	22.264
26.86	33.07	-4.155	22.260
26.87	32.97	-4.156	22.265
26.88	32.87	-4.154	22.254
26.89	32.77	-4.155
26.90	32.67	-4.156
26.91	32.57	-4.153
26.92	32.47	-4.150
26.93	32.37	-4.148
26.94	32.27	-4.147
26.95	32.17
26.96	32.07
26.97	31.97
26.98	31.87
26.99	31.77
27.00