File: Data/2024_09_19_Sucrose_CHM343_DSC.txt
Filename	2024_09_19_Sucrose_CHM343_DSC
Instrument name	DSC2A-00468 (192.168.1.100)
Operator	CHM343
rundate	9/19/2024
Sample name	2024_09_19_Sucrose_CHM343_DSC
proceduresegments	Equilibrate 30.00 °C; Ramp 10.00 °C/min to 220.00 °C; Isothermal 1.0 min; Ramp 10.00 °C/min to 30.00 °C
[File Parameters]
Run date	9/19/2024 6:41:09 PM
Trios version	5.1.1.46572
Original File Name	C:\ProgramData\TA Instruments\TRIOS\Data\2024_09_19_Sucrose_CHM343_DSC.tri
Current File Name	D:\DSC2500\CHM343\2024_09_19_Sucrose_CHM343_DSC.tri
[Procedure]
Procedure Name	CHM343_Fall2024_Sucrose
Sample Name	2024_09_19_Sucrose_CHM343_DSC
Sample Mass	3.13 mg
Reference Sample Mass	0 mg
Pan Mass	53.68 mg
Pan Number	23
Reference Pan Mass	54 mg
Reference Pan Number	19
Pan Type	Aluminum
Comments	Sucrose - Al Hermetic Sealed Pan, with ref Al pan.  ASU Online CHM343, Remote DSC experimental lab. Fall 2024.  Group Zoom Data Collection, Sept 19, 2024 from 5-7 pm.  TA Instruments DSC2500.
Project Name	Lab 4 - Fall 2024
Operator	CHM343
Test	Custom
Unload Max Temperature	30
Unload Min Temperature	30
Load Max Temperature	30
Load Min Temperature	30
Stop on Gas Flow Error	Yes
[Signal List]
Signal #1	Time (min)
Signal #2	Temperature (°C)
Signal #3	Heat Flow (mW)
Signal #4	Delta T (µV)
Signal #5	Delta Tzero (µV)
Signal #6	Tzero Temperature (°C)
Signal #7	Cell Purge (mL/min)
Signal #8	Heater Temp (°C)
Signal #9	Power Delivered (W)
Signal #10	Reference Junction Temperature (°C)
Signal #11	Flange Temperature (°C)
Signal #12	Heat Flow Phase (rad)
Signal #13	Total Heat Capacity (J/°C)
Signal #14	Heat Capacity (J/°C)
[Configuration]
Company Name	ASU
Instrument Name	DSC2A-00468
Instrument Type	DSC2500
Serial Number	DSC2A-00468
IP	192.168.1.100
Location of Instrument	MRRC
DisplayType	Unknown
Sample Interval 	0.1 s/pt
Selected Heat Flow	T4P
Exotherm Direction	Down
Cell Serial	DRC2-00792
Lid Type	Standard
Cooler	RCS 90
Leave Cooler on at End of Sequence	On
Gas 2	Nitrogen
Gas Selected	Channel 1
Flow Rate	50 mL/min
Secondary Purge	On
Licensed Heat Flow	Heat Flow T4P
Modulation Licensed	Yes
[Versions]
Common IDD Version	1
Cortex Version	VER 2.10.2.31
Driver	5.0.0.6
GDM Version	1.0.3.3
TouchscreenVersion	1.0.0.16145
FEP Version	1.2.1.21
FEP Bootloader	2.0.0.5
AutoSampler Version	2.1.1.26
Auto Sampler Bootloader	2.0.0.5
FCM Version	1.1.0.3
FCM Bootloader	2.0.0.5
[Experiment Logs]
Experiment Log Entry # 1	Equilibrate Segment 30 (C) Started
Experiment Log Entry # 3	Air Cool is off.
Experiment Log Entry # 5	Ramp Segment 10 C/min to 220 Started
Experiment Log Entry # 7	Isothermal Segment 1 min started
Experiment Log Entry # 9	Ramp Segment 10 C/min to 30 Started
[Method Log]
Method Log Entry # 1	Equilibrate 30 °C
Method Log Entry # 2	(Ramp 14364) Ramp 10 °C/minute to 220 °C
Method Log Entry # 3	Isothermal 1 minutes
Method Log Entry # 4	(Ramp 14366) Ramp 10 °C/minute to 30 °C
Cell Serial	DRC2-00792
[T1 Calibration]
Slope	-0.008529666
Offset	9.636258
Initial Temperature	98.23
GUID	f8bfdadc-4977-4fdf-ba6d-0ba9134940c3
[TZero Calibration]
Date Applied	11/29/2022 4:06:13 PM
Description	From -89.059 °C to 396.009 °C at 20.000°C/min
Gas Type	Nitrogen
Pan Type	None
Source Files 1	C:\Users\yargerlab\Desktop\DSC Data\General\TZero_calibration_11_29_22_2nd(2).tri
Source Files 2	C:\Users\yargerlab\Desktop\DSC Data\General\TZero_calibration_11_29_22_2nd(3).tri
Delta T Offset	13.05235
Delta T Slope	-0.007271007
Delta T0 Offset	-13.69128
Delta T0 Slope	0.06063341
[Temperature Calibration]
Date Applied	11/29/2022 7:12:28 PM
Description	From 106.590 °C to 186.590 °C at 10.000°C/min
Gas Type	Nitrogen
Pan Type	Tzero Aluminum Hermetic
Source Files 1	C:\Users\yargerlab\Desktop\DSC Data\General\Indium(6).tri
Measured 1	157.391
Known 1	156.598
[Cell Constant Calibration]
Date Applied	11/29/2022 7:12:29 PM
Description	From 106.590 °C to 186.590 °C at 10.000°C/min
Gas Type	Nitrogen
Pan Type	Tzero Aluminum Hermetic
Source Files 1	C:\Users\yargerlab\Desktop\DSC Data\General\Indium(6).tri
T4P KCell	1.006051
Onset Slope	63.26126 mW/°C
[Direct Cp Calibration]
Date Applied	11/30/2022 11:04:51 AM
Description	From -79.983 °C to 298.409 °C at 10.000°C/min
Gas Type	Nitrogen
Pan Type	Tzero Aluminum Hermetic
Source Files 1	C:\Users\yargerlab\Desktop\DSC Data\General\Sapphire_Heat_Capacity_11_30_22.tri
[Rev Cp Calibration]
Date Applied	11/30/2022 1:58:51 PM
Description	From -79.996 °C to 292.812 °C at 3.000°C/min
Gas Type	Nitrogen
Pan Type	Tzero Aluminum Hermetic
Source Files 1	C:\Users\yargerlab\Desktop\DSC Data\General\Sapphire_MDSC_Calibration_11_30_22.tri
[step]
Ramp 10.00 °C/min to 220.00 °C
Time	Temperature	Heat Flow (Normalized)	Heat Capacity (Normalized)
min	°C	W/g	J/(g.°C)
0.00	30.05	0.004	0.000
0.01	30.05	0.002	0.000
0.03	30.05	0.001	0.000
0.04	30.06	-0.004	-0.093
0.05	30.08	-0.036	-0.744
0.07	30.10	-0.086	-1.510
0.08	30.13	-0.159	-2.380
0.09	30.19	-0.243	-3.180
0.11	30.25	-0.319	-3.708
0.12	30.33	-0.381	-3.963
0.13	30.41	-0.414	-3.905
0.15	30.51	-0.420	-3.638
0.16	30.61	-0.402	-3.227
0.17	30.71	-0.371	-2.795
0.19	30.81	-0.332	-2.372
0.20	30.92	-0.293	-2.011
0.21	31.03	-0.259	-1.721
0.23	31.14	-0.225	-1.456
0.24	31.25	-0.197	-1.251
0.25	31.36	-0.173	-1.083
0.27	31.48	-0.154	-0.951
0.28	31.60	-0.133	-0.811
0.29	31.72	-0.117	-0.705
0.31	31.84	-0.096	-0.573
0.32	31.96	-0.077	-0.455
0.33	32.08	-0.062	-0.364
0.35	32.21	-0.046	-0.264
0.36	32.33	-0.031	-0.181
0.37	32.46	-0.019	-0.107
0.39	32.58	-0.005	-0.029
0.40	32.71	0.004	0.025
0.41	32.83	0.017	0.094
0.43	32.96	0.023	0.131
0.44	33.09	0.034	0.190
0.45	33.22	0.039	0.220
0.47	33.35	0.047	0.264
0.48	33.48	0.053	0.293
0.49	33.61	0.060	0.330
0.51	33.74	0.064	0.352
0.52	33.87	0.071	0.393
0.53	34.00	0.074	0.405
0.55	34.13	0.079	0.435
0.56	34.26	0.082	0.448
0.57	34.39	0.086	0.473
0.59	34.52	0.089	0.483
0.60	34.65	0.094	0.514
0.61	34.78	0.096	0.524
0.63	34.91	0.098	0.535
0.64	35.04	0.100	0.544
0.65	35.17	0.101	0.551
0.67	35.31	0.104	0.566
0.68	35.44	0.106	0.574
0.69	35.57	0.108	0.587
0.71	35.70	0.109	0.593
0.72	35.83	0.111	0.600
0.73	35.96	0.113	0.611
0.75	36.09	0.114	0.617
0.76	36.23	0.115	0.619
0.77	36.36	0.115	0.623
0.79	36.49	0.116	0.628
0.80	36.62	0.117	0.633
0.81	36.76	0.118	0.638
0.83	36.89	0.119	0.643
0.84	37.02	0.121	0.651
0.85	37.15	0.121	0.653
0.87	37.28	0.122	0.658
0.88	37.42	0.123	0.662
0.89	37.55	0.124	0.666
0.91	37.68	0.124	0.670
0.92	37.81	0.125	0.675
0.93	37.95	0.126	0.677
0.95	38.08	0.127	0.684
0.96	38.21	0.128	0.686
0.97	38.34	0.128	0.689
0.99	38.48	0.129	0.691
1.00	38.61	0.129	0.694
1.01	38.74	0.130	0.696
1.03	38.88	0.130	0.698
1.04	39.01	0.131	0.701
1.05	39.14	0.131	0.704
1.07	39.27	0.132	0.707
1.08	39.41	0.132	0.709
1.09	39.54	0.133	0.713
1.11	39.67	0.133	0.716
1.12	39.80	0.134	0.718
1.13	39.94	0.134	0.720
1.15	40.07	0.135	0.723
1.16	40.20	0.135	0.725
1.17	40.34	0.136	0.728
1.19	40.47	0.136	0.731
1.20	40.60	0.137	0.733
1.21	40.73	0.137	0.736
1.23	40.87	0.138	0.739
1.24	41.00	0.138	0.741
1.25	41.13	0.139	0.743
1.27	41.27	0.139	0.746
1.28	41.40	0.140	0.748
1.29	41.53	0.140	0.751
1.31	41.66	0.141	0.753
1.32	41.80	0.141	0.756
1.33	41.93	0.142	0.759
1.35	42.07	0.142	0.760
1.36	42.20	0.143	0.763
1.37	42.33	0.144	0.768
1.39	42.46	0.144	0.770
1.40	42.60	0.144	0.772
1.41	42.73	0.145	0.774
1.43	42.86	0.145	0.776
1.44	43.00	0.146	0.779
1.45	43.13	0.146	0.782
1.47	43.26	0.147	0.784
1.48	43.39	0.147	0.786
1.49	43.53	0.148	0.788
1.51	43.66	0.148	0.790
1.52	43.80	0.148	0.792
1.53	43.93	0.149	0.794
1.55	44.06	0.149	0.796
1.56	44.19	0.150	0.799
1.57	44.33	0.150	0.801
1.59	44.46	0.150	0.802
1.60	44.59	0.151	0.804
1.61	44.73	0.151	0.807
1.63	44.86	0.152	0.809
1.64	44.99	0.152	0.810
1.65	45.13	0.152	0.813
1.67	45.26	0.153	0.816
1.68	45.39	0.153	0.818
1.69	45.53	0.154	0.820
1.71	45.66	0.154	0.823
1.72	45.79	0.155	0.825
1.73	45.93	0.155	0.827
1.75	46.06	0.155	0.830
1.76	46.19	0.156	0.831
1.77	46.33	0.156	0.834
1.79	46.46	0.157	0.836
1.80	46.59	0.157	0.838
1.81	46.72	0.158	0.841
1.83	46.86	0.158	0.842
1.84	46.99	0.158	0.845
1.85	47.12	0.159	0.847
1.87	47.26	0.159	0.849
1.88	47.39	0.160	0.851
1.89	47.53	0.160	0.853
1.91	47.66	0.160	0.855
1.92	47.79	0.161	0.857
1.93	47.93	0.161	0.860
1.95	48.06	0.162	0.866
1.96	48.19	0.163	0.868
1.97	48.32	0.163	0.871
1.99	48.46	0.164	0.874
2.00	48.59	0.164	0.877
2.01	48.73	0.165	0.879
2.03	48.86	0.165	0.881
2.04	48.99	0.166	0.884
2.05	49.12	0.166	0.887
2.07	49.26	0.167	0.889
2.08	49.39	0.167	0.891
2.09	49.52	0.168	0.894
2.11	49.66	0.168	0.896
2.12	49.79	0.169	0.899
2.13	49.92	0.169	0.901
2.15	50.06	0.169	0.903
2.16	50.19	0.170	0.906
2.17	50.32	0.170	0.909
2.19	50.46	0.171	0.911
2.20	50.59	0.172	0.914
2.21	50.72	0.172	0.916
2.23	50.86	0.172	0.919
2.24	50.99	0.173	0.920
2.25	51.12	0.173	0.923
2.27	51.26	0.174	0.926
2.28	51.39	0.174	0.928
2.29	51.52	0.175	0.930
2.31	51.66	0.175	0.932
2.32	51.79	0.175	0.935
2.33	51.92	0.176	0.937
2.35	52.06	0.176	0.939
2.36	52.19	0.176	0.941
2.37	52.32	0.177	0.942
2.39	52.46	0.177	0.945
2.40	52.59	0.178	0.947
2.41	52.72	0.178	0.948
2.43	52.86	0.178	0.951
2.44	52.99	0.179	0.953
2.45	53.12	0.179	0.954
2.47	53.26	0.179	0.956
2.48	53.39	0.180	0.958
2.49	53.52	0.180	0.960
2.51	53.66	0.180	0.961
2.52	53.79	0.181	0.963
2.53	53.92	0.181	0.964
2.55	54.06	0.181	0.965
2.56	54.19	0.181	0.967
2.57	54.32	0.182	0.968
2.59	54.46	0.182	0.970
2.60	54.59	0.182	0.971
2.61	54.73	0.182	0.972
2.63	54.86	0.183	0.974
2.64	54.99	0.183	0.974
2.65	55.13	0.183	0.976
2.67	55.26	0.183	0.977
2.68	55.39	0.183	0.978
2.69	55.53	0.184	0.979
2.71	55.66	0.184	0.980
2.72	55.79	0.184	0.981
2.73	55.92	0.184	0.982
2.75	56.06	0.184	0.983
2.76	56.19	0.184	0.984
2.77	56.33	0.185	0.985
2.79	56.46	0.185	0.986
2.80	56.59	0.185	0.986
2.81	56.73	0.185	0.987
2.83	56.86	0.185	0.988
2.84	56.99	0.185	0.989
2.85	57.13	0.186	0.990
2.87	57.26	0.186	0.991
2.88	57.39	0.186	0.992
2.89	57.53	0.186	0.992
2.91	57.66	0.186	0.992
2.92	57.79	0.186	0.993
2.93	57.93	0.186	0.994
2.95	58.06	0.186	0.994
2.96	58.19	0.186	0.995
2.97	58.33	0.187	0.995
2.99	58.46	0.187	0.995
3.00	58.59	0.187	0.996
3.01	58.73	0.187	0.997
3.03	58.86	0.187	0.997
3.04	58.99	0.187	0.998
3.05	59.13	0.187	0.999
3.07	59.26	0.187	0.999
3.08	59.40	0.187	1.000
3.09	59.53	0.188	1.001
3.11	59.66	0.188	1.001
3.12	59.79	0.188	1.001
3.13	59.93	0.188	1.002
3.15	60.06	0.188	1.003
3.16	60.20	0.188	1.004
3.17	60.33	0.188	1.005
3.19	60.46	0.189	1.006
3.20	60.60	0.189	1.007
3.21	60.73	0.189	1.008
3.23	60.86	0.189	1.009
3.24	61.00	0.189	1.010
3.25	61.13	0.189	1.010
3.27	61.26	0.189	1.011
3.28	61.40	0.189	1.011
3.29	61.53	0.190	1.012
3.31	61.66	0.190	1.013
3.32	61.80	0.190	1.014
3.33	61.93	0.190	1.015
3.35	62.06	0.190	1.015
3.36	62.20	0.190	1.016
3.37	62.33	0.191	1.018
3.39	62.46	0.191	1.018
3.40	62.60	0.191	1.019
3.41	62.73	0.191	1.020
3.43	62.86	0.191	1.021
3.44	63.00	0.192	1.022
3.45	63.13	0.192	1.023
3.47	63.26	0.192	1.025
3.48	63.40	0.192	1.026
3.49	63.53	0.192	1.026
3.51	63.66	0.192	1.027
3.52	63.80	0.193	1.028
3.53	63.93	0.193	1.029
3.55	64.06	0.193	1.030
3.56	64.20	0.193	1.031
3.57	64.33	0.194	1.032
3.59	64.46	0.194	1.034
3.60	64.60	0.194	1.036
3.61	64.73	0.194	1.037
3.63	64.86	0.195	1.039
3.64	65.00	0.195	1.040
3.65	65.13	0.195	1.041
3.67	65.26	0.195	1.043
3.68	65.40	0.196	1.045
3.69	65.53	0.196	1.047
3.71	65.66	0.197	1.049
3.72	65.80	0.197	1.050
3.73	65.93	0.197	1.051
3.75	66.06	0.197	1.053
3.76	66.20	0.197	1.054
3.77	66.33	0.198	1.055
3.79	66.47	0.198	1.056
3.80	66.60	0.198	1.058
3.81	66.73	0.198	1.059
3.83	66.87	0.199	1.060
3.84	67.00	0.199	1.062
3.85	67.13	0.199	1.064
3.87	67.27	0.200	1.065
3.88	67.40	0.200	1.067
3.89	67.53	0.200	1.070
3.91	67.67	0.201	1.071
3.92	67.80	0.201	1.074
3.93	67.93	0.202	1.076
3.95	68.07	0.202	1.077
3.96	68.20	0.202	1.079
3.97	68.33	0.202	1.080
3.99	68.47	0.203	1.082
4.00	68.60	0.203	1.084
4.01	68.73	0.203	1.086
4.03	68.87	0.204	1.087
4.04	69.00	0.204	1.088
4.05	69.13	0.204	1.089
4.07	69.27	0.205	1.091
4.08	69.40	0.205	1.093
4.09	69.53	0.205	1.094
4.11	69.67	0.205	1.095
4.12	69.80	0.206	1.096
4.13	69.93	0.206	1.098
4.15	70.07	0.206	1.099
4.16	70.20	0.207	1.101
4.17	70.33	0.207	1.103
4.19	70.47	0.207	1.104
4.20	70.60	0.208	1.107
4.21	70.73	0.208	1.109
4.23	70.87	0.208	1.111
4.24	71.00	0.209	1.113
4.25	71.13	0.209	1.115
4.27	71.27	0.209	1.117
4.28	71.40	0.210	1.119
4.29	71.53	0.210	1.121
4.31	71.67	0.210	1.123
4.32	71.80	0.211	1.124
4.33	71.93	0.211	1.126
4.35	72.07	0.212	1.129
4.36	72.20	0.212	1.131
4.37	72.33	0.212	1.132
4.39	72.47	0.213	1.135
4.40	72.60	0.213	1.136
4.41	72.73	0.213	1.138
4.43	72.87	0.214	1.140
4.44	73.00	0.214	1.142
4.45	73.13	0.214	1.144
4.47	73.27	0.215	1.145
4.48	73.40	0.215	1.147
4.49	73.53	0.215	1.148
4.51	73.67	0.216	1.150
4.52	73.80	0.216	1.152
4.53	73.94	0.216	1.154
4.55	74.07	0.217	1.156
4.56	74.20	0.217	1.158
4.57	74.33	0.218	1.160
4.59	74.47	0.218	1.162
4.60	74.60	0.218	1.164
4.61	74.74	0.219	1.166
4.63	74.87	0.219	1.169
4.64	75.00	0.219	1.170
4.65	75.13	0.220	1.172
4.67	75.27	0.220	1.174
4.68	75.40	0.221	1.176
4.69	75.53	0.221	1.178
4.71	75.67	0.221	1.180
4.72	75.80	0.222	1.182
4.73	75.93	0.222	1.184
4.75	76.07	0.222	1.185
4.76	76.20	0.223	1.187
4.77	76.33	0.223	1.190
4.79	76.47	0.223	1.191
4.80	76.60	0.224	1.193
4.81	76.74	0.224	1.195
4.83	76.87	0.224	1.196
4.84	77.00	0.225	1.198
4.85	77.14	0.225	1.200
4.87	77.27	0.226	1.203
4.88	77.40	0.226	1.205
4.89	77.54	0.227	1.211
4.91	77.67	0.227	1.213
4.92	77.80	0.228	1.215
4.93	77.93	0.228	1.217
4.95	78.07	0.228	1.218
4.96	78.20	0.229	1.220
4.97	78.34	0.229	1.221
4.99	78.47	0.229	1.222
5.00	78.60	0.230	1.224
5.01	78.74	0.230	1.226
5.03	78.87	0.230	1.228
5.04	79.00	0.230	1.230
5.05	79.14	0.231	1.232
5.07	79.27	0.231	1.234
5.08	79.40	0.232	1.236
5.09	79.54	0.232	1.238
5.11	79.67	0.232	1.239
5.12	79.80	0.233	1.241
5.13	79.94	0.233	1.243
5.15	80.07	0.233	1.245
5.16	80.20	0.234	1.247
5.17	80.34	0.234	1.248
5.19	80.47	0.234	1.250
5.20	80.60	0.234	1.251
5.21	80.74	0.235	1.254
5.23	80.87	0.235	1.255
5.24	81.00	0.235	1.257
5.25	81.14	0.236	1.258
5.27	81.27	0.236	1.259
5.28	81.40	0.236	1.261
5.29	81.54	0.237	1.262
5.31	81.67	0.237	1.265
5.32	81.80	0.238	1.267
5.33	81.94	0.238	1.268
5.35	82.07	0.238	1.270
5.36	82.20	0.238	1.272
5.37	82.34	0.239	1.274
5.39	82.47	0.239	1.275
5.40	82.60	0.239	1.278
5.41	82.74	0.240	1.279
5.43	82.87	0.240	1.282
5.44	83.00	0.241	1.283
5.45	83.14	0.241	1.285
5.47	83.27	0.241	1.286
5.48	83.40	0.241	1.289
5.49	83.54	0.242	1.290
5.51	83.67	0.242	1.292
5.52	83.80	0.242	1.293
5.53	83.94	0.243	1.295
5.55	84.07	0.243	1.297
5.56	84.20	0.243	1.298
5.57	84.34	0.244	1.301
5.59	84.47	0.244	1.303
5.60	84.60	0.244	1.304
5.61	84.74	0.245	1.307
5.63	84.87	0.245	1.309
5.64	85.00	0.246	1.311
5.65	85.14	0.246	1.312
5.67	85.27	0.246	1.314
5.68	85.40	0.246	1.315
5.69	85.54	0.247	1.316
5.71	85.67	0.247	1.317
5.72	85.80	0.247	1.318
5.73	85.94	0.247	1.320
5.75	86.07	0.247	1.320
5.76	86.20	0.248	1.322
5.77	86.34	0.248	1.323
5.79	86.47	0.248	1.325
5.80	86.60	0.249	1.326
5.81	86.74	0.249	1.329
5.83	86.87	0.249	1.330
5.84	87.00	0.250	1.332
5.85	87.14	0.250	1.334
5.87	87.27	0.250	1.336
5.88	87.41	0.251	1.338
5.89	87.54	0.251	1.340
5.91	87.67	0.251	1.341
5.92	87.81	0.252	1.344
5.93	87.94	0.252	1.345
5.95	88.07	0.252	1.347
5.96	88.20	0.253	1.351
5.97	88.34	0.253	1.352
5.99	88.47	0.254	1.353
6.00	88.60	0.254	1.355
6.01	88.74	0.254	1.356
6.03	88.87	0.254	1.357
6.04	89.01	0.254	1.358
6.05	89.14	0.255	1.358
6.07	89.27	0.255	1.360
6.08	89.41	0.255	1.361
6.09	89.54	0.255	1.362
6.11	89.67	0.256	1.364
6.12	89.81	0.256	1.365
6.13	89.94	0.256	1.367
6.15	90.07	0.256	1.369
6.16	90.21	0.257	1.370
6.17	90.34	0.257	1.372
6.19	90.47	0.257	1.373
6.20	90.60	0.258	1.375
6.21	90.74	0.258	1.377
6.23	90.87	0.258	1.378
6.24	91.01	0.258	1.379
6.25	91.14	0.259	1.381
6.27	91.27	0.259	1.381
6.28	91.41	0.259	1.382
6.29	91.54	0.259	1.384
6.31	91.67	0.260	1.385
6.32	91.81	0.260	1.388
6.33	91.94	0.260	1.388
6.35	92.07	0.261	1.390
6.36	92.21	0.261	1.391
6.37	92.34	0.261	1.392
6.39	92.47	0.261	1.394
6.40	92.61	0.261	1.395
6.41	92.74	0.262	1.396
6.43	92.87	0.262	1.398
6.44	93.01	0.262	1.399
6.45	93.14	0.263	1.400
6.47	93.27	0.263	1.403
6.48	93.41	0.263	1.404
6.49	93.54	0.263	1.406
6.51	93.67	0.264	1.407
6.52	93.81	0.264	1.408
6.53	93.94	0.264	1.409
6.55	94.07	0.264	1.410
6.56	94.21	0.265	1.411
6.57	94.34	0.265	1.411
6.59	94.47	0.265	1.412
6.60	94.61	0.265	1.412
6.61	94.74	0.265	1.413
6.63	94.88	0.265	1.415
6.64	95.01	0.266	1.416
6.65	95.14	0.266	1.417
6.67	95.28	0.266	1.417
6.68	95.41	0.266	1.419
6.69	95.54	0.266	1.420
6.71	95.68	0.266	1.420
6.72	95.81	0.267	1.422
6.73	95.94	0.267	1.423
6.75	96.08	0.267	1.425
6.76	96.21	0.268	1.426
6.77	96.34	0.268	1.428
6.79	96.48	0.268	1.428
6.80	96.61	0.268	1.430
6.81	96.74	0.268	1.431
6.83	96.88	0.269	1.432
6.84	97.01	0.269	1.432
6.85	97.14	0.269	1.433
6.87	97.28	0.269	1.434
6.88	97.41	0.269	1.435
6.89	97.54	0.269	1.436
6.91	97.68	0.270	1.437
6.92	97.81	0.270	1.438
6.93	97.94	0.270	1.439
6.95	98.08	0.270	1.439
6.96	98.21	0.270	1.440
6.97	98.34	0.270	1.440
6.99	98.48	0.271	1.441
7.00	98.61	0.271	1.442
7.01	98.74	0.271	1.443
7.03	98.88	0.271	1.443
7.04	99.01	0.271	1.444
7.05	99.14	0.271	1.445
7.07	99.28	0.271	1.445
7.08	99.41	0.271	1.445
7.09	99.54	0.271	1.445
7.11	99.68	0.271	1.445
7.12	99.81	0.272	1.446
7.13	99.95	0.272	1.447
7.15	100.08	0.272	1.448
7.16	100.21	0.272	1.449
7.17	100.35	0.273	1.451
7.19	100.48	0.273	1.452
7.20	100.61	0.273	1.453
7.21	100.75	0.273	1.454
7.23	100.88	0.273	1.455
7.24	101.01	0.273	1.456
7.25	101.14	0.273	1.457
7.27	101.28	0.274	1.457
7.28	101.41	0.274	1.458
7.29	101.55	0.274	1.458
7.31	101.68	0.274	1.459
7.32	101.81	0.274	1.459
7.33	101.95	0.274	1.460
7.35	102.08	0.274	1.460
7.36	102.21	0.274	1.461
7.37	102.35	0.275	1.462
7.39	102.48	0.275	1.462
7.40	102.61	0.275	1.463
7.41	102.75	0.275	1.462
7.43	102.88	0.275	1.464
7.44	103.01	0.275	1.464
7.45	103.15	0.275	1.465
7.47	103.28	0.275	1.465
7.48	103.41	0.275	1.466
7.49	103.55	0.276	1.467
7.51	103.68	0.276	1.467
7.52	103.81	0.276	1.468
7.53	103.95	0.276	1.469
7.55	104.08	0.276	1.470
7.56	104.21	0.276	1.471
7.57	104.35	0.276	1.471
7.59	104.48	0.277	1.472
7.60	104.61	0.277	1.473
7.61	104.75	0.277	1.474
7.63	104.88	0.277	1.474
7.64	105.01	0.277	1.474
7.65	105.15	0.277	1.475
7.67	105.28	0.277	1.475
7.68	105.41	0.277	1.476
7.69	105.55	0.277	1.476
7.71	105.68	0.278	1.477
7.72	105.81	0.278	1.477
7.73	105.95	0.278	1.478
7.75	106.08	0.278	1.478
7.76	106.21	0.278	1.478
7.77	106.35	0.278	1.479
7.79	106.48	0.278	1.479
7.80	106.62	0.278	1.479
7.81	106.75	0.278	1.481
7.83	106.88	0.279	1.482
7.84	107.02	0.279	1.483
7.85	107.15	0.279	1.484
7.87	107.28	0.279	1.485
7.88	107.42	0.279	1.485
7.89	107.55	0.279	1.486
7.91	107.68	0.279	1.486
7.92	107.81	0.279	1.487
7.93	107.95	0.279	1.486
7.95	108.08	0.279	1.487
7.96	108.22	0.279	1.486
7.97	108.35	0.280	1.486
7.99	108.48	0.280	1.487
8.00	108.62	0.280	1.488
8.01	108.75	0.280	1.490
8.03	108.88	0.280	1.491
8.04	109.02	0.280	1.492
8.05	109.15	0.281	1.493
8.07	109.28	0.281	1.495
8.08	109.42	0.281	1.496
8.09	109.55	0.281	1.497
8.11	109.68	0.281	1.497
8.12	109.82	0.281	1.498
8.13	109.95	0.282	1.498
8.15	110.08	0.282	1.498
8.16	110.22	0.282	1.499
8.17	110.35	0.282	1.499
8.19	110.48	0.282	1.499
8.20	110.62	0.282	1.500
8.21	110.75	0.282	1.500
8.23	110.88	0.282	1.500
8.24	111.02	0.282	1.500
8.25	111.15	0.282	1.500
8.27	111.28	0.282	1.501
8.28	111.42	0.282	1.500
8.29	111.55	0.282	1.501
8.31	111.68	0.283	1.502
8.32	111.82	0.283	1.502
8.33	111.95	0.283	1.502
8.35	112.08	0.283	1.503
8.36	112.22	0.283	1.503
8.37	112.35	0.283	1.505
8.39	112.48	0.283	1.505
8.40	112.62	0.283	1.506
8.41	112.75	0.283	1.506
8.43	112.88	0.284	1.508
8.44	113.02	0.284	1.508
8.45	113.15	0.284	1.509
8.47	113.28	0.284	1.510
8.48	113.42	0.284	1.511
8.49	113.55	0.284	1.512
8.51	113.68	0.285	1.513
8.52	113.82	0.285	1.514
8.53	113.95	0.285	1.515
8.55	114.08	0.285	1.516
8.56	114.22	0.285	1.516
8.57	114.35	0.285	1.516
8.59	114.49	0.285	1.517
8.60	114.62	0.285	1.517
8.61	114.75	0.286	1.518
8.63	114.88	0.286	1.518
8.64	115.02	0.286	1.519
8.65	115.15	0.286	1.519
8.67	115.29	0.286	1.519
8.68	115.42	0.286	1.520
8.69	115.55	0.286	1.520
8.71	115.69	0.286	1.521
8.72	115.82	0.286	1.522
8.73	115.95	0.286	1.521
8.75	116.09	0.286	1.522
8.76	116.22	0.287	1.522
8.77	116.35	0.287	1.523
8.79	116.49	0.287	1.524
8.80	116.62	0.287	1.525
8.81	116.75	0.287	1.525
8.83	116.89	0.287	1.526
8.84	117.02	0.287	1.527
8.85	117.15	0.287	1.528
8.87	117.29	0.288	1.528
8.88	117.42	0.288	1.529
8.89	117.55	0.288	1.529
8.91	117.69	0.288	1.529
8.92	117.82	0.288	1.529
8.93	117.95	0.288	1.529
8.95	118.09	0.288	1.530
8.96	118.22	0.288	1.530
8.97	118.35	0.288	1.529
8.99	118.49	0.288	1.530
9.00	118.62	0.288	1.530
9.01	118.75	0.288	1.531
9.03	118.89	0.288	1.531
9.04	119.02	0.289	1.532
9.05	119.15	0.289	1.532
9.07	119.29	0.289	1.534
9.08	119.42	0.289	1.534
9.09	119.55	0.289	1.534
9.11	119.69	0.289	1.535
9.12	119.82	0.289	1.536
9.13	119.95	0.289	1.537
9.15	120.09	0.289	1.537
9.16	120.22	0.290	1.537
9.17	120.35	0.290	1.538
9.19	120.49	0.290	1.537
9.20	120.62	0.290	1.539
9.21	120.76	0.290	1.539
9.23	120.89	0.290	1.540
9.24	121.02	0.290	1.541
9.25	121.16	0.290	1.541
9.27	121.29	0.290	1.541
9.28	121.42	0.290	1.541
9.29	121.56	0.291	1.542
9.31	121.69	0.291	1.543
9.32	121.82	0.291	1.543
9.33	121.96	0.291	1.544
9.35	122.09	0.291	1.545
9.36	122.22	0.291	1.546
9.37	122.36	0.291	1.546
9.39	122.49	0.291	1.547
9.40	122.62	0.292	1.548
9.41	122.76	0.292	1.549
9.43	122.89	0.292	1.549
9.44	123.02	0.292	1.549
9.45	123.16	0.292	1.550
9.47	123.29	0.292	1.550
9.48	123.42	0.292	1.551
9.49	123.56	0.292	1.551
9.51	123.69	0.292	1.552
9.52	123.82	0.292	1.552
9.53	123.96	0.292	1.551
9.55	124.09	0.292	1.552
9.56	124.22	0.292	1.552
9.57	124.36	0.292	1.552
9.59	124.49	0.292	1.552
9.60	124.62	0.292	1.551
9.61	124.76	0.293	1.552
9.63	124.89	0.293	1.553
9.64	125.02	0.293	1.553
9.65	125.16	0.293	1.553
9.67	125.29	0.293	1.554
9.68	125.42	0.293	1.554
9.69	125.56	0.293	1.555
9.71	125.69	0.293	1.555
9.72	125.82	0.293	1.555
9.73	125.96	0.293	1.556
9.75	126.09	0.293	1.556
9.76	126.23	0.293	1.556
9.77	126.36	0.293	1.556
9.79	126.49	0.294	1.557
9.80	126.63	0.294	1.557
9.81	126.76	0.294	1.557
9.83	126.89	0.294	1.558
9.84	127.03	0.294	1.558
9.85	127.16	0.294	1.559
9.87	127.29	0.294	1.560
9.88	127.43	0.294	1.560
9.89	127.56	0.294	1.561
9.91	127.69	0.294	1.561
9.92	127.83	0.294	1.561
9.93	127.96	0.294	1.561
9.95	128.09	0.294	1.562
9.96	128.23	0.295	1.562
9.97	128.36	0.295	1.563
9.99	128.49	0.295	1.563
10.00	128.63	0.295	1.564
10.01	128.76	0.295	1.564
10.03	128.89	0.295	1.564
10.04	129.03	0.295	1.565
10.05	129.16	0.295	1.565
10.07	129.29	0.295	1.564
10.08	129.43	0.295	1.565
10.09	129.56	0.295	1.565
10.11	129.69	0.295	1.565
10.12	129.83	0.295	1.565
10.13	129.96	0.295	1.566
10.15	130.09	0.295	1.567
10.16	130.23	0.296	1.567
10.17	130.36	0.296	1.568
10.19	130.49	0.296	1.570
10.20	130.63	0.296	1.570
10.21	130.76	0.296	1.571
10.23	130.89	0.296	1.571
10.24	131.03	0.296	1.571
10.25	131.16	0.296	1.571
10.27	131.29	0.297	1.572
10.28	131.43	0.297	1.571
10.29	131.56	0.297	1.572
10.31	131.69	0.297	1.572
10.32	131.83	0.297	1.573
10.33	131.96	0.297	1.573
10.35	132.10	0.297	1.574
10.36	132.23	0.297	1.575
10.37	132.36	0.297	1.575
10.39	132.49	0.297	1.575
10.40	132.63	0.297	1.576
10.41	132.76	0.297	1.576
10.43	132.89	0.297	1.576
10.44	133.03	0.297	1.576
10.45	133.16	0.297	1.576
10.47	133.30	0.298	1.576
10.48	133.43	0.298	1.577
10.49	133.56	0.298	1.577
10.51	133.69	0.298	1.576
10.52	133.83	0.298	1.578
10.53	133.96	0.298	1.578
10.55	134.10	0.298	1.578
10.56	134.23	0.298	1.578
10.57	134.36	0.298	1.579
10.59	134.50	0.298	1.580
10.60	134.63	0.298	1.580
10.61	134.76	0.298	1.580
10.63	134.90	0.298	1.581
10.64	135.03	0.299	1.582
10.65	135.16	0.299	1.583
10.67	135.30	0.299	1.584
10.68	135.43	0.299	1.585
10.69	135.56	0.299	1.586
10.71	135.70	0.299	1.587
10.72	135.83	0.300	1.588
10.73	135.96	0.300	1.589
10.75	136.10	0.300	1.590
10.76	136.23	0.300	1.590
10.77	136.36	0.300	1.590
10.79	136.50	0.300	1.590
10.80	136.63	0.300	1.589
10.81	136.76	0.300	1.589
10.83	136.90	0.300	1.589
10.84	137.03	0.300	1.589
10.85	137.16	0.300	1.588
10.87	137.30	0.300	1.589
10.88	137.43	0.300	1.589
10.89	137.56	0.300	1.589
10.91	137.70	0.300	1.588
10.92	137.83	0.300	1.589
10.93	137.96	0.300	1.590
10.95	138.10	0.301	1.590
10.96	138.23	0.301	1.591
10.97	138.36	0.301	1.591
10.99	138.50	0.301	1.592
11.00	138.63	0.301	1.593
11.01	138.77	0.301	1.594
11.03	138.90	0.301	1.594
11.04	139.03	0.301	1.595
11.05	139.17	0.301	1.597
11.07	139.30	0.302	1.597
11.08	139.43	0.302	1.597
11.09	139.57	0.302	1.598
11.11	139.70	0.302	1.599
11.12	139.83	0.302	1.600
11.13	139.97	0.302	1.601
11.15	140.10	0.303	1.601
11.16	140.23	0.303	1.602
11.17	140.36	0.303	1.603
11.19	140.50	0.303	1.603
11.20	140.63	0.303	1.603
11.21	140.77	0.303	1.602
11.23	140.90	0.303	1.602
11.24	141.03	0.303	1.602
11.25	141.17	0.303	1.602
11.27	141.30	0.303	1.603
11.28	141.43	0.303	1.604
11.29	141.57	0.303	1.604
11.31	141.70	0.303	1.605
11.32	141.83	0.303	1.606
11.33	141.97	0.304	1.606
11.35	142.10	0.304	1.607
11.36	142.23	0.304	1.608
11.37	142.37	0.304	1.609
11.39	142.50	0.304	1.610
11.40	142.63	0.304	1.611
11.41	142.77	0.305	1.612
11.43	142.90	0.305	1.612
11.44	143.03	0.305	1.612
11.45	143.17	0.305	1.612
11.47	143.30	0.305	1.613
11.48	143.43	0.305	1.612
11.49	143.57	0.305	1.613
11.51	143.70	0.305	1.614
11.52	143.83	0.305	1.614
11.53	143.97	0.305	1.615
11.55	144.10	0.305	1.616
11.56	144.23	0.306	1.617
11.57	144.37	0.306	1.617
11.59	144.50	0.306	1.617
11.60	144.63	0.306	1.618
11.61	144.77	0.306	1.618
11.63	144.90	0.306	1.619
11.64	145.03	0.306	1.619
11.65	145.17	0.306	1.618
11.67	145.30	0.306	1.618
11.68	145.43	0.306	1.619
11.69	145.57	0.306	1.619
11.71	145.70	0.306	1.618
11.72	145.83	0.306	1.619
11.73	145.97	0.306	1.619
11.75	146.10	0.307	1.620
11.76	146.23	0.307	1.620
11.77	146.37	0.307	1.622
11.79	146.50	0.307	1.623
11.80	146.64	0.307	1.623
11.81	146.77	0.307	1.624
11.83	146.90	0.307	1.624
11.84	147.04	0.308	1.625
11.85	147.17	0.308	1.627
11.87	147.30	0.308	1.627
11.88	147.44	0.308	1.627
11.89	147.57	0.308	1.628
11.91	147.70	0.308	1.628
11.92	147.84	0.308	1.628
11.93	147.97	0.308	1.628
11.95	148.10	0.308	1.628
11.96	148.24	0.308	1.629
11.97	148.37	0.308	1.629
11.99	148.50	0.308	1.629
12.00	148.64	0.308	1.630
12.01	148.77	0.309	1.629
12.03	148.90	0.309	1.630
12.04	149.04	0.309	1.631
12.05	149.17	0.309	1.631
12.07	149.30	0.309	1.633
12.08	149.44	0.309	1.633
12.09	149.57	0.309	1.634
12.11	149.70	0.309	1.635
12.12	149.84	0.309	1.635
12.13	149.97	0.310	1.636
12.15	150.10	0.310	1.636
12.16	150.24	0.310	1.637
12.17	150.37	0.310	1.636
12.19	150.50	0.310	1.636
12.20	150.64	0.310	1.636
12.21	150.77	0.310	1.637
12.23	150.90	0.310	1.636
12.24	151.04	0.310	1.636
12.25	151.17	0.310	1.636
12.27	151.30	0.310	1.635
12.28	151.44	0.310	1.636
12.29	151.57	0.310	1.635
12.31	151.70	0.310	1.636
12.32	151.84	0.310	1.636
12.33	151.97	0.310	1.636
12.35	152.10	0.310	1.636
12.36	152.24	0.310	1.637
12.37	152.37	0.310	1.638
12.39	152.50	0.310	1.638
12.40	152.64	0.310	1.639
12.41	152.77	0.311	1.640
12.43	152.90	0.311	1.640
12.44	153.04	0.311	1.641
12.45	153.17	0.311	1.642
12.47	153.31	0.311	1.643
12.48	153.44	0.311	1.643
12.49	153.57	0.311	1.643
12.51	153.70	0.311	1.643
12.52	153.84	0.311	1.643
12.53	153.97	0.311	1.644
12.55	154.10	0.311	1.644
12.56	154.24	0.311	1.644
12.57	154.37	0.312	1.645
12.59	154.50	0.311	1.644
12.60	154.64	0.312	1.644
12.61	154.77	0.312	1.644
12.63	154.91	0.312	1.644
12.64	155.04	0.311	1.643
12.65	155.17	0.311	1.643
12.67	155.30	0.311	1.643
12.68	155.44	0.312	1.643
12.69	155.57	0.311	1.642
12.71	155.71	0.311	1.642
12.72	155.84	0.312	1.642
12.73	155.97	0.312	1.643
12.75	156.11	0.312	1.643
12.76	156.24	0.312	1.643
12.77	156.37	0.312	1.644
12.79	156.51	0.312	1.644
12.80	156.64	0.312	1.644
12.81	156.77	0.312	1.645
12.83	156.91	0.312	1.644
12.84	157.04	0.312	1.644
12.85	157.17	0.312	1.645
12.87	157.31	0.312	1.645
12.88	157.44	0.312	1.646
12.89	157.57	0.312	1.646
12.91	157.71	0.312	1.647
12.92	157.84	0.312	1.647
12.93	157.97	0.312	1.647
12.95	158.11	0.312	1.647
12.96	158.24	0.312	1.645
12.97	158.37	0.312	1.645
12.99	158.51	0.312	1.644
13.00	158.64	0.312	1.645
13.01	158.77	0.312	1.645
13.03	158.91	0.312	1.644
13.04	159.04	0.312	1.645
13.05	159.17	0.312	1.645
13.07	159.31	0.312	1.646
13.08	159.44	0.312	1.646
13.09	159.57	0.312	1.646
13.11	159.71	0.313	1.647
13.12	159.84	0.313	1.648
13.13	159.97	0.313	1.648
13.15	160.11	0.313	1.648
13.16	160.24	0.313	1.648
13.17	160.38	0.313	1.648
13.19	160.51	0.313	1.647
13.20	160.64	0.313	1.647
13.21	160.78	0.313	1.647
13.23	160.91	0.313	1.647
13.24	161.04	0.313	1.647
13.25	161.18	0.313	1.648
13.27	161.31	0.313	1.648
13.28	161.44	0.313	1.649
13.29	161.58	0.313	1.649
13.31	161.71	0.313	1.650
13.32	161.84	0.313	1.650
13.33	161.98	0.313	1.650
13.35	162.11	0.313	1.651
13.36	162.24	0.313	1.651
13.37	162.38	0.313	1.651
13.39	162.51	0.314	1.651
13.40	162.64	0.314	1.652
13.41	162.78	0.314	1.651
13.43	162.91	0.313	1.651
13.44	163.04	0.313	1.650
13.45	163.18	0.313	1.651
13.47	163.31	0.313	1.650
13.48	163.44	0.313	1.650
13.49	163.58	0.313	1.650
13.51	163.71	0.313	1.650
13.52	163.84	0.314	1.651
13.53	163.98	0.314	1.651
13.55	164.11	0.314	1.652
13.56	164.24	0.314	1.652
13.57	164.38	0.314	1.653
13.59	164.51	0.314	1.653
13.60	164.64	0.314	1.653
13.61	164.78	0.314	1.653
13.63	164.91	0.314	1.653
13.64	165.04	0.314	1.653
13.65	165.18	0.314	1.652
13.67	165.31	0.314	1.651
13.68	165.44	0.314	1.651
13.69	165.58	0.314	1.651
13.71	165.71	0.314	1.651
13.72	165.84	0.314	1.651
13.73	165.98	0.314	1.651
13.75	166.11	0.314	1.651
13.76	166.24	0.314	1.652
13.77	166.38	0.314	1.652
13.79	166.51	0.314	1.654
13.80	166.64	0.315	1.654
13.81	166.78	0.315	1.654
13.83	166.91	0.315	1.656
13.84	167.05	0.315	1.656
13.85	167.18	0.315	1.657
13.87	167.31	0.315	1.658
13.88	167.44	0.315	1.658
13.89	167.58	0.315	1.658
13.91	167.71	0.315	1.658
13.92	167.85	0.315	1.658
13.93	167.98	0.315	1.658
13.95	168.11	0.315	1.658
13.96	168.25	0.315	1.658
13.97	168.38	0.316	1.659
13.99	168.51	0.316	1.659
14.00	168.64	0.316	1.658
14.01	168.78	0.316	1.659
14.03	168.91	0.315	1.658
14.04	169.05	0.315	1.658
14.05	169.18	0.315	1.657
14.07	169.31	0.315	1.657
14.08	169.45	0.315	1.657
14.09	169.58	0.315	1.657
14.11	169.71	0.315	1.657
14.12	169.85	0.315	1.657
14.13	169.98	0.316	1.658
14.15	170.11	0.316	1.658
14.16	170.25	0.316	1.659
14.17	170.38	0.316	1.659
14.19	170.51	0.316	1.660
14.20	170.65	0.316	1.660
14.21	170.78	0.316	1.660
14.23	170.91	0.316	1.661
14.24	171.05	0.316	1.661
14.25	171.18	0.316	1.660
14.27	171.31	0.316	1.661
14.28	171.45	0.316	1.660
14.29	171.58	0.316	1.661
14.31	171.71	0.316	1.661
14.32	171.85	0.316	1.662
14.33	171.98	0.317	1.662
14.35	172.11	0.317	1.663
14.36	172.25	0.317	1.663
14.37	172.38	0.317	1.663
14.39	172.51	0.317	1.663
14.40	172.65	0.317	1.663
14.41	172.78	0.317	1.663
14.43	172.91	0.317	1.662
14.44	173.05	0.317	1.662
14.45	173.18	0.317	1.662
14.47	173.31	0.317	1.662
14.48	173.45	0.317	1.662
14.49	173.58	0.317	1.662
14.51	173.71	0.317	1.663
14.52	173.85	0.317	1.663
14.53	173.98	0.317	1.663
14.55	174.11	0.317	1.664
14.56	174.25	0.317	1.664
14.57	174.38	0.317	1.664
14.59	174.51	0.317	1.664
14.60	174.65	0.317	1.665
14.61	174.78	0.317	1.664
14.63	174.91	0.317	1.664
14.64	175.05	0.317	1.664
14.65	175.18	0.317	1.664
14.67	175.32	0.317	1.665
14.68	175.45	0.317	1.665
14.69	175.58	0.318	1.665
14.71	175.72	0.318	1.666
14.72	175.85	0.318	1.666
14.73	175.98	0.318	1.667
14.75	176.12	0.318	1.667
14.76	176.25	0.318	1.667
14.77	176.38	0.318	1.668
14.79	176.52	0.318	1.668
14.80	176.65	0.318	1.668
14.81	176.78	0.318	1.668
14.83	176.92	0.318	1.668
14.84	177.05	0.318	1.668
14.85	177.18	0.318	1.669
14.87	177.32	0.318	1.669
14.88	177.45	0.318	1.669
14.89	177.58	0.318	1.669
14.91	177.72	0.318	1.669
14.92	177.85	0.318	1.670
14.93	177.98	0.318	1.669
14.95	178.12	0.318	1.669
14.96	178.25	0.318	1.669
14.97	178.38	0.318	1.669
14.99	178.52	0.318	1.669
15.00	178.65	0.318	1.668
15.01	178.78	0.318	1.668
15.03	178.92	0.318	1.668
15.04	179.05	0.318	1.669
15.05	179.18	0.318	1.668
15.07	179.32	0.318	1.669
15.08	179.45	0.319	1.669
15.09	179.58	0.319	1.669
15.11	179.72	0.319	1.670
15.12	179.85	0.319	1.670
15.13	179.98	0.319	1.670
15.15	180.12	0.319	1.670
15.16	180.25	0.319	1.670
15.17	180.38	0.319	1.669
15.19	180.52	0.319	1.668
15.20	180.65	0.319	1.669
15.21	180.78	0.319	1.669
15.23	180.92	0.319	1.669
15.24	181.05	0.319	1.669
15.25	181.18	0.319	1.670
15.27	181.32	0.319	1.670
15.28	181.45	0.319	1.671
15.29	181.58	0.319	1.671
15.31	181.72	0.319	1.672
15.32	181.85	0.319	1.672
15.33	181.98	0.319	1.672
15.35	182.12	0.319	1.672
15.36	182.25	0.319	1.673
15.37	182.39	0.319	1.673
15.39	182.52	0.319	1.673
15.40	182.65	0.320	1.674
15.41	182.78	0.320	1.674
15.43	182.92	0.320	1.673
15.44	183.05	0.320	1.673
15.45	183.18	0.320	1.673
15.47	183.32	0.320	1.673
15.48	183.45	0.320	1.673
15.49	183.58	0.320	1.672
15.51	183.72	0.320	1.672
15.52	183.85	0.319	1.671
15.53	183.99	0.319	1.671
15.55	184.12	0.319	1.670
15.56	184.25	0.319	1.669
15.57	184.39	0.319	1.670
15.59	184.52	0.320	1.672
15.60	184.65	0.320	1.673
15.61	184.79	0.320	1.674
15.63	184.92	0.320	1.676
15.64	185.05	0.320	1.677
15.65	185.19	0.320	1.677
15.67	185.32	0.320	1.677
15.68	185.45	0.321	1.678
15.69	185.58	0.321	1.678
15.71	185.72	0.321	1.678
15.72	185.85	0.321	1.677
15.73	185.99	0.321	1.677
15.75	186.12	0.320	1.676
15.76	186.25	0.320	1.676
15.77	186.39	0.320	1.675
15.79	186.52	0.320	1.675
15.80	186.65	0.320	1.675
15.81	186.79	0.320	1.676
15.83	186.92	0.320	1.675
15.84	187.05	0.321	1.676
15.85	187.19	0.321	1.676
15.87	187.32	0.321	1.677
15.88	187.45	0.321	1.677
15.89	187.59	0.321	1.677
15.91	187.72	0.321	1.677
15.92	187.85	0.321	1.676
15.93	187.99	0.321	1.675
15.95	188.12	0.321	1.676
15.96	188.25	0.321	1.676
15.97	188.39	0.321	1.675
15.99	188.52	0.321	1.674
16.00	188.65	0.321	1.674
16.01	188.79	0.321	1.675
16.03	188.92	0.321	1.676
16.04	189.06	0.321	1.677
16.05	189.19	0.321	1.678
16.07	189.32	0.321	1.679
16.08	189.45	0.321	1.680
16.09	189.59	0.321	1.680
16.11	189.72	0.321	1.681
16.12	189.85	0.321	1.681
16.13	189.99	0.322	1.682
16.15	190.12	0.322	1.681
16.16	190.25	0.322	1.681
16.17	190.39	0.322	1.681
16.19	190.52	0.322	1.681
16.20	190.65	0.322	1.681
16.21	190.79	0.322	1.680
16.23	190.92	0.322	1.680
16.24	191.05	0.322	1.680
16.25	191.19	0.321	1.679
16.27	191.32	0.321	1.679
16.28	191.45	0.321	1.678
16.29	191.59	0.321	1.678
16.31	191.72	0.321	1.678
16.32	191.85	0.321	1.678
16.33	191.99	0.321	1.678
16.35	192.12	0.321	1.677
16.36	192.25	0.321	1.678
16.37	192.39	0.321	1.678
16.39	192.52	0.321	1.677
16.40	192.65	0.322	1.679
16.41	192.79	0.322	1.678
16.43	192.92	0.322	1.678
16.44	193.05	0.322	1.678
16.45	193.19	0.322	1.678
16.47	193.32	0.322	1.678
16.48	193.45	0.322	1.677
16.49	193.59	0.322	1.678
16.51	193.72	0.322	1.677
16.52	193.86	0.322	1.677
16.53	193.99	0.322	1.678
16.55	194.12	0.322	1.679
16.56	194.26	0.322	1.679
16.57	194.39	0.322	1.679
16.59	194.52	0.322	1.680
16.60	194.65	0.322	1.680
16.61	194.79	0.322	1.680
16.63	194.92	0.322	1.681
16.64	195.06	0.322	1.681
16.65	195.19	0.322	1.681
16.67	195.32	0.322	1.682
16.68	195.46	0.322	1.682
16.69	195.59	0.322	1.681
16.71	195.72	0.323	1.682
16.72	195.85	0.323	1.683
16.73	195.99	0.323	1.682
16.75	196.12	0.322	1.682
16.76	196.25	0.322	1.681
16.77	196.39	0.322	1.681
16.79	196.52	0.322	1.680
16.80	196.66	0.323	1.681
16.81	196.79	0.323	1.681
16.83	196.92	0.323	1.681
16.84	197.06	0.323	1.682
16.85	197.19	0.323	1.683
16.87	197.32	0.323	1.683
16.88	197.46	0.323	1.684
16.89	197.59	0.323	1.685
16.91	197.72	0.323	1.684
16.92	197.86	0.323	1.684
16.93	197.99	0.323	1.684
16.95	198.12	0.323	1.684
16.96	198.26	0.323	1.684
16.97	198.39	0.323	1.684
16.99	198.52	0.323	1.684
17.00	198.66	0.323	1.682
17.01	198.79	0.323	1.682
17.03	198.92	0.323	1.682
17.04	199.06	0.323	1.682
17.05	199.19	0.323	1.683
17.07	199.32	0.323	1.683
17.08	199.46	0.323	1.683
17.09	199.59	0.323	1.683
17.11	199.72	0.323	1.684
17.12	199.86	0.324	1.685
17.13	199.99	0.324	1.685
17.15	200.12	0.324	1.686
17.16	200.26	0.324	1.686
17.17	200.39	0.324	1.687
17.19	200.53	0.324	1.687
17.20	200.66	0.324	1.688
17.21	200.79	0.324	1.687
17.23	200.92	0.324	1.688
17.24	201.06	0.324	1.689
17.25	201.19	0.324	1.689
17.27	201.32	0.324	1.689
17.28	201.46	0.325	1.689
17.29	201.59	0.325	1.690
17.31	201.72	0.325	1.689
17.32	201.86	0.325	1.689
17.33	201.99	0.325	1.690
17.35	202.13	0.325	1.689
17.36	202.26	0.325	1.688
17.37	202.39	0.324	1.688
17.39	202.53	0.324	1.687
17.40	202.66	0.325	1.688
17.41	202.79	0.325	1.688
17.43	202.92	0.325	1.688
17.44	203.06	0.325	1.688
17.45	203.19	0.325	1.689
17.47	203.33	0.325	1.689
17.48	203.46	0.325	1.690
17.49	203.59	0.325	1.692
17.51	203.73	0.325	1.692
17.52	203.86	0.325	1.693
17.53	203.99	0.326	1.694
17.55	204.13	0.326	1.695
17.56	204.26	0.326	1.695
17.57	204.39	0.326	1.695
17.59	204.53	0.326	1.695
17.60	204.66	0.326	1.696
17.61	204.79	0.326	1.696
17.63	204.93	0.326	1.695
17.64	205.06	0.326	1.695
17.65	205.19	0.326	1.695
17.67	205.32	0.326	1.695
17.68	205.46	0.326	1.695
17.69	205.59	0.326	1.695
17.71	205.72	0.326	1.695
17.72	205.86	0.326	1.696
17.73	205.99	0.326	1.696
17.75	206.12	0.326	1.696
17.76	206.26	0.327	1.697
17.77	206.39	0.327	1.697
17.79	206.52	0.327	1.697
17.80	206.66	0.327	1.697
17.81	206.79	0.327	1.698
17.83	206.92	0.327	1.698
17.84	207.06	0.327	1.698
17.85	207.19	0.327	1.698
17.87	207.33	0.327	1.698
17.88	207.46	0.327	1.698
17.89	207.59	0.327	1.698
17.91	207.73	0.327	1.699
17.92	207.86	0.327	1.700
17.93	207.99	0.328	1.700
17.95	208.13	0.328	1.701
17.96	208.26	0.328	1.701
17.97	208.39	0.328	1.702
17.99	208.53	0.328	1.702
18.00	208.66	0.328	1.703
18.01	208.79	0.328	1.703
18.03	208.93	0.328	1.703
18.04	209.06	0.328	1.704
18.05	209.19	0.328	1.703
18.07	209.33	0.328	1.704
18.08	209.46	0.329	1.704
18.09	209.59	0.329	1.704
18.11	209.73	0.329	1.704
18.12	209.86	0.329	1.705
18.13	209.99	0.329	1.705
18.15	210.13	0.329	1.706
18.16	210.26	0.329	1.706
18.17	210.39	0.329	1.707
18.19	210.53	0.329	1.708
18.20	210.66	0.329	1.709
18.21	210.79	0.329	1.709
18.23	210.93	0.330	1.710
18.24	211.06	0.330	1.710
18.25	211.19	0.330	1.711
18.27	211.33	0.330	1.711
18.28	211.46	0.330	1.712
18.29	211.59	0.330	1.711
18.31	211.73	0.330	1.711
18.32	211.86	0.330	1.711
18.33	211.99	0.330	1.710
18.35	212.13	0.330	1.710
18.36	212.26	0.330	1.710
18.37	212.39	0.330	1.710
18.39	212.53	0.330	1.710
18.40	212.66	0.330	1.710
18.41	212.79	0.330	1.710
18.43	212.93	0.330	1.710
18.44	213.06	0.330	1.711
18.45	213.19	0.330	1.711
18.47	213.33	0.330	1.711
18.48	213.46	0.330	1.710
18.49	213.59	0.330	1.710
18.51	213.73	0.330	1.710
18.52	213.86	0.330	1.709
18.53	213.99	0.330	1.709
18.55	214.13	0.330	1.709
18.56	214.26	0.330	1.708
18.57	214.39	0.330	1.707
18.59	214.53	0.330	1.707
18.60	214.66	0.330	1.706
18.61	214.80	0.330	1.707
18.63	214.93	0.330	1.707
18.64	215.06	0.330	1.707
18.65	215.20	0.330	1.707
18.67	215.33	0.330	1.707
18.68	215.46	0.330	1.707
18.69	215.60	0.330	1.708
18.71	215.73	0.330	1.708
18.72	215.86	0.330	1.708
18.73	216.00	0.330	1.708
18.75	216.13	0.330	1.708
18.76	216.26	0.330	1.708
18.77	216.40	0.330	1.708
18.79	216.53	0.330	1.708
18.80	216.66	0.330	1.708
18.81	216.79	0.330	1.707
18.83	216.93	0.330	1.706
18.84	217.06	0.330	1.706
18.85	217.19	0.330	1.705
18.87	217.33	0.330	1.704
18.88	217.46	0.329	1.704
18.89	217.60	0.329	1.703
18.91	217.73	0.329	1.701
18.92	217.86	0.329	1.701
18.93	218.00	0.329	1.703
18.95	218.13	0.329	1.709
18.96	218.26	0.329	1.720
18.97	218.40	0.329	1.740
18.99	218.53	0.329	1.771
19.00	218.66	0.329	1.815

[step]
Ramp 10.00 °C/min to 30.00 °C
Time	Temperature	Heat Flow (Normalized)
min	°C	W/g
20.00	220.05	0.028
20.02	220.05	0.027
20.03	220.05	0.027
20.04	220.05	0.027
20.06	220.04	0.059
20.07	220.02	0.109
20.08	219.99	0.177
20.09	219.95	0.246
20.11	219.90	0.308
20.12	219.83	0.354
20.13	219.75	0.376
20.15	219.66	0.374
20.16	219.57	0.350
20.18	219.47	0.310
20.19	219.37	0.264
20.20	219.26	0.209
20.22	219.15	0.157
20.23	219.03	0.108
20.24	218.92	0.065
20.26	218.80	0.026
20.27	218.68	-0.006
20.28	218.56	-0.034
20.29	218.44	-0.059
20.31	218.32	-0.081
20.32	218.20	-0.100
20.33	218.07	-0.115
20.35	217.95	-0.130
20.36	217.82	-0.145
20.38	217.69	-0.159
20.39	217.57	-0.166
20.40	217.44	-0.178
20.42	217.31	-0.186
20.43	217.18	-0.193
20.44	217.06	-0.202
20.46	216.93	-0.208
20.47	216.80	-0.214
20.48	216.67	-0.219
20.49	216.54	-0.223
20.51	216.41	-0.228
20.52	216.28	-0.231
20.53	216.15	-0.234
20.55	216.02	-0.238
[...]
25.32	168.41	-0.284
25.33	168.27	-0.284
25.35	168.14	-0.284
25.36	168.01	-0.284
25.38	167.88	-0.284
25.39	167.74	-0.284
25.40	167.61	-0.284
25.42	167.48	-0.284
25.43	167.34	-0.284
25.44	167.21	-0.284
25.46	167.08	-0.284
25.47	166.94	-0.284
25.48	166.81	-0.284
25.49	166.68	-0.284
25.51	166.54	-0.284
25.52	166.41	-0.284
25.53	166.28	-0.284
25.55	166.14	-0.284
25.56	166.01	-0.284
25.58	165.88	-0.284
25.59	165.74	-0.284
25.60	165.61	-0.284
25.62	165.48	-0.284
25.63	165.35	-0.284
25.64	165.21	-0.284
25.66	165.08	-0.284
25.67	164.94	-0.284
25.68	164.81	-0.284
25.69	164.68	-0.284
25.71	164.55	-0.284
25.72	164.41	-0.284
25.73	164.28	-0.284
25.75	164.15	-0.284
25.76	164.01	-0.284
25.78	163.88	-0.284
25.79	163.75	-0.285
25.80	163.61	-0.284
25.82	163.48	-0.285
25.83	163.35	-0.284
25.84	163.21	-0.284
25.86	163.08	-0.284
25.87	162.95	-0.284
25.88	162.81	-0.284
25.89	162.68	-0.284
25.91	162.55	-0.284
25.92	162.41	-0.285
25.93	162.28	-0.285
25.95	162.15	-0.285
25.96	162.01	-0.285
25.98	161.88	-0.286
25.99	161.75	-0.286
26.00	161.61	-0.286
26.02	161.48	-0.286
26.03	161.35	-0.285
26.04	161.22	-0.285
26.06	161.08	-0.285
26.07	160.95	-0.285
26.08	160.82	-0.285
26.09	160.68	-0.285
26.11	160.55	-0.285
26.12	160.42	-0.285
26.13	160.28	-0.285
26.15	160.15	-0.285
26.16	160.02	-0.285
26.18	159.88	-0.285
26.19	159.75	-0.285
26.20	159.62	-0.285
26.22	159.48	-0.286
26.23	159.35	-0.286
26.24	159.22	-0.286
26.26	159.08	-0.286
26.27	158.95	-0.286
26.28	158.82	-0.286
26.29	158.68	-0.286
26.31	158.55	-0.286
26.32	158.42	-0.286
26.33	158.28	-0.286
26.35	158.15	-0.286
26.36	158.02	-0.286
26.38	157.89	-0.286
26.39	157.75	-0.286
26.40	157.62	-0.286
26.42	157.49	-0.286
26.43	157.35	-0.286
26.44	157.22	-0.286
26.46	157.09	-0.286
26.47	156.95	-0.286
26.48	156.82	-0.286
26.49	156.69	-0.286
26.51	156.55	-0.286
26.52	156.42	-0.286
26.53	156.29	-0.286
26.55	156.15	-0.286
26.56	156.02	-0.287
26.58	155.89	-0.287
26.59	155.76	-0.287
26.60	155.62	-0.287
26.62	155.49	-0.287
26.63	155.35	-0.287
26.64	155.22	-0.287
26.66	155.09	-0.287
26.67	154.95	-0.287
26.68	154.82	-0.287
26.69	154.69	-0.287
26.71	154.56	-0.287
26.72	154.42	-0.287
26.73	154.29	-0.287
26.75	154.16	-0.287
26.76	154.02	-0.287
26.78	153.89	-0.287
26.79	153.76	-0.287
26.80	153.62	-0.287
26.82	153.49	-0.287
26.83	153.36	-0.287
26.84	153.22	-0.287
26.86	153.09	-0.287
26.87	152.96	-0.287
26.88	152.82	-0.288
26.89	152.69	-0.288
26.91	152.56	-0.288
26.92	152.43	-0.288
26.93	152.29	-0.288
26.95	152.16	-0.288
26.96	152.03	-0.288
26.98	151.89	-0.288
26.99	151.76	-0.288
27.00	151.63	-0.288
27.02	151.49	-0.288
27.03	151.36	-0.288
27.04	151.23	-0.288
27.06	151.09	-0.288
27.07	150.96	-0.288
27.08	150.83	-0.288
27.09	150.69	-0.288
27.11	150.56	-0.288
27.12	150.43	-0.288
27.13	150.29	-0.288
27.15	150.16	-0.288
27.16	150.03	-0.289
27.18	149.89	-0.289
27.19	149.76	-0.289
27.20	149.63	-0.289
27.22	149.50	-0.289
27.23	149.36	-0.289
27.24	149.23	-0.289
27.26	149.10	-0.289
27.27	148.96	-0.289
27.28	148.83	-0.288
27.29	148.70	-0.288
27.31	148.56	-0.289
27.32	148.43	-0.289
27.33	148.30	-0.289
27.35	148.16	-0.289
27.36	148.03	-0.289
27.38	147.90	-0.289
27.39	147.76	-0.289
27.40	147.63	-0.289
27.42	147.50	-0.289
27.43	147.36	-0.289
27.44	147.23	-0.289
27.46	147.10	-0.289
27.47	146.96	-0.289
27.48	146.83	-0.289
27.49	146.70	-0.289
27.51	146.56	-0.290
27.52	146.43	-0.290
27.53	146.30	-0.290
27.55	146.16	-0.290
27.56	146.03	-0.290
27.58	145.90	-0.290
27.59	145.76	-0.290
27.60	145.63	-0.290
27.62	145.50	-0.290
27.63	145.37	-0.290
27.64	145.23	-0.290
27.66	145.10	-0.290
27.67	144.97	-0.290
27.68	144.83	-0.290
27.69	144.70	-0.290
27.71	144.57	-0.290
27.72	144.43	-0.290
27.73	144.30	-0.290
27.75	144.17	-0.290
27.76	144.03	-0.290
27.78	143.90	-0.290
27.79	143.77	-0.290
27.80	143.63	-0.290
27.82	143.50	-0.290
27.83	143.37	-0.290
27.84	143.23	-0.290
27.86	143.10	-0.290
27.87	142.97	-0.290
27.88	142.83	-0.290
27.89	142.70	-0.290
27.91	142.57	-0.290
27.92	142.43	-0.291
27.93	142.30	-0.291
27.95	142.17	-0.291
27.96	142.04	-0.291
27.98	141.90	-0.291
27.99	141.77	-0.291
28.00	141.63	-0.291
28.02	141.50	-0.291
28.03	141.37	-0.291
28.04	141.24	-0.291
28.06	141.10	-0.291
28.07	140.97	-0.291
28.08	140.84	-0.291
28.09	140.70	-0.291
28.11	140.57	-0.291
28.12	140.44	-0.291
28.13	140.30	-0.291
28.15	140.17	-0.291
28.16	140.04	-0.291
28.18	139.90	-0.291
28.19	139.77	-0.291
28.20	139.64	-0.291
28.22	139.50	-0.291
28.23	139.37	-0.291
28.24	139.24	-0.291
28.26	139.11	-0.291
28.27	138.97	-0.291
28.28	138.84	-0.291
28.29	138.70	-0.291
28.31	138.57	-0.291
28.32	138.44	-0.291
28.33	138.31	-0.291
28.35	138.17	-0.292
28.36	138.04	-0.291
28.38	137.91	-0.291
28.39	137.77	-0.292
28.40	137.64	-0.291
28.42	137.51	-0.292
28.43	137.37	-0.291
28.44	137.24	-0.291
28.46	137.11	-0.291
28.47	136.97	-0.291
28.48	136.84	-0.291
28.49	136.71	-0.291
28.51	136.58	-0.291
28.52	136.44	-0.291
28.53	136.31	-0.291
28.55	136.17	-0.291
28.56	136.04	-0.291
28.58	135.91	-0.292
28.59	135.77	-0.292
28.60	135.64	-0.292
28.62	135.51	-0.292
28.63	135.38	-0.292
28.64	135.24	-0.292
28.66	135.11	-0.292
28.67	134.98	-0.292
28.68	134.84	-0.292
28.69	134.71	-0.292
28.71	134.58	-0.292
28.72	134.44	-0.292
28.73	134.31	-0.292
28.75	134.18	-0.292
28.76	134.04	-0.292
28.78	133.91	-0.292
28.79	133.78	-0.292
28.80	133.64	-0.292
28.82	133.51	-0.292
28.83	133.38	-0.292
28.84	133.24	-0.292
28.86	133.11	-0.292
28.87	132.98	-0.292
28.88	132.84	-0.292
28.89	132.71	-0.293
28.91	132.58	-0.293
28.92	132.44	-0.293
28.93	132.31	-0.293
28.95	132.18	-0.293
28.96	132.04	-0.293
28.98	131.91	-0.293
28.99	131.78	-0.293
29.00	131.65	-0.293
29.02	131.51	-0.293
29.03	131.38	-0.293
29.04	131.25	-0.293
29.06	131.11	-0.293
29.07	130.98	-0.293
29.08	130.85	-0.293
29.09	130.71	-0.293
29.11	130.58	-0.293
29.12	130.45	-0.293
29.13	130.31	-0.293
29.15	130.18	-0.293
29.16	130.05	-0.293
29.18	129.91	-0.293
29.19	129.78	-0.293
29.20	129.65	-0.293
29.22	129.52	-0.293
29.23	129.38	-0.293
29.24	129.25	-0.293
29.26	129.11	-0.293
29.27	128.98	-0.293
29.28	128.85	-0.293
29.29	128.71	-0.293
29.31	128.58	-0.293
29.32	128.45	-0.293
29.33	128.32	-0.293
29.35	128.18	-0.293
29.36	128.05	-0.293
29.38	127.92	-0.293
29.39	127.78	-0.293
29.40	127.65	-0.293
29.42	127.52	-0.293
29.43	127.38	-0.293
29.44	127.25	-0.293
29.46	127.12	-0.293
29.47	126.98	-0.293
29.48	126.85	-0.293
29.49	126.72	-0.294
29.51	126.58	-0.294
29.52	126.45	-0.294
29.53	126.32	-0.294
29.55	126.19	-0.294
29.56	126.05	-0.294
29.58	125.92	-0.294
29.59	125.79	-0.294
29.60	125.65	-0.294
29.62	125.52	-0.294
29.63	125.39	-0.294
29.64	125.25	-0.294
29.66	125.12	-0.294
29.67	124.99	-0.294
29.68	124.85	-0.294
29.69	124.72	-0.294
29.71	124.59	-0.294
29.72	124.45	-0.294
29.73	124.32	-0.294
29.75	124.19	-0.294
29.76	124.05	-0.294
29.78	123.92	-0.294
29.79	123.79	-0.294
29.80	123.65	-0.294
29.82	123.52	-0.294
29.83	123.39	-0.294
29.84	123.25	-0.294
29.86	123.12	-0.294
29.87	122.99	-0.294
29.88	122.85	-0.294
29.89	122.72	-0.294
29.91	122.59	-0.294
29.92	122.45	-0.294
29.93	122.32	-0.294
29.95	122.19	-0.294
29.96	122.05	-0.294
29.98	121.92	-0.294
29.99	121.79	-0.294
30.00	121.65	-0.294
30.02	121.52	-0.294
30.03	121.39	-0.294
30.04	121.26	-0.294
30.06	121.12	-0.294
30.07	120.99	-0.294
30.08	120.86	-0.294
30.09	120.72	-0.294
30.11	120.59	-0.294
30.12	120.46	-0.294
30.13	120.32	-0.294
30.15	120.19	-0.294
30.16	120.06	-0.294
30.18	119.92	-0.295
30.19	119.79	-0.295
30.20	119.66	-0.295
30.22	119.52	-0.294
30.23	119.39	-0.295
30.24	119.26	-0.295
30.26	119.12	-0.295
30.27	118.99	-0.294
30.28	118.86	-0.294
30.29	118.72	-0.294
30.31	118.59	-0.294
30.32	118.46	-0.294
30.33	118.33	-0.295
30.35	118.19	-0.295
30.36	118.06	-0.295
30.38	117.93	-0.294
30.39	117.79	-0.294
30.40	117.66	-0.294
30.42	117.53	-0.294
30.43	117.39	-0.294
30.44	117.26	-0.294
30.46	117.13	-0.295
30.47	116.99	-0.294
30.48	116.86	-0.294
30.49	116.73	-0.295
30.51	116.59	-0.294
30.52	116.46	-0.295
30.53	116.33	-0.295
30.55	116.19	-0.295
30.56	116.06	-0.295
30.58	115.93	-0.295
30.59	115.79	-0.294
30.60	115.66	-0.294
30.62	115.53	-0.294
30.63	115.40	-0.294
30.64	115.26	-0.295
30.66	115.13	-0.295
30.67	114.99	-0.295
30.68	114.86	-0.295
30.69	114.73	-0.295
30.71	114.60	-0.295
30.72	114.46	-0.295
30.73	114.33	-0.295
30.75	114.20	-0.295
30.76	114.06	-0.295
30.78	113.93	-0.295
30.79	113.80	-0.294
30.80	113.66	-0.295
30.82	113.53	-0.294
30.83	113.40	-0.294
30.84	113.26	-0.294
30.86	113.13	-0.294
30.87	113.00	-0.294
30.88	112.86	-0.294
30.89	112.73	-0.294
30.91	112.60	-0.294
30.92	112.46	-0.294
30.93	112.33	-0.294
30.95	112.20	-0.294
30.96	112.06	-0.294
30.98	111.93	-0.294
30.99	111.80	-0.294
31.00	111.66	-0.294
31.02	111.53	-0.294
31.03	111.40	-0.294
31.04	111.27	-0.294
31.06	111.13	-0.294
31.07	111.00	-0.294
31.08	110.87	-0.294
31.09	110.73	-0.294
31.11	110.60	-0.294
31.12	110.47	-0.293
31.13	110.33	-0.293
31.15	110.20	-0.293
31.16	110.07	-0.293
31.18	109.93	-0.293
31.19	109.80	-0.293
31.20	109.67	-0.293
31.22	109.53	-0.293
31.23	109.40	-0.293
31.24	109.27	-0.293
31.26	109.13	-0.293
31.27	109.00	-0.293
31.28	108.87	-0.293
31.29	108.73	-0.293
31.31	108.60	-0.293
31.32	108.47	-0.292
31.33	108.34	-0.292
31.35	108.20	-0.292
31.36	108.07	-0.292
31.38	107.94	-0.292
31.39	107.80	-0.292
31.40	107.67	-0.292
31.42	107.54	-0.292
31.43	107.40	-0.292
31.44	107.27	-0.291
31.46	107.14	-0.291
31.47	107.00	-0.291
31.48	106.87	-0.291
31.49	106.74	-0.291
31.51	106.60	-0.291
31.52	106.47	-0.291
31.53	106.34	-0.291
31.55	106.20	-0.291
31.56	106.07	-0.291
31.58	105.94	-0.291
31.59	105.80	-0.290
31.60	105.67	-0.290
31.62	105.54	-0.290
31.63	105.40	-0.290
31.64	105.27	-0.290
31.66	105.14	-0.290
31.67	105.00	-0.290
31.68	104.87	-0.290
31.69	104.74	-0.289
31.71	104.60	-0.289
31.72	104.47	-0.289
31.73	104.34	-0.289
31.75	104.20	-0.289
31.76	104.07	-0.289
31.78	103.94	-0.289
31.79	103.80	-0.288
31.80	103.67	-0.288
31.82	103.54	-0.288
31.83	103.40	-0.288
31.84	103.27	-0.288
31.86	103.14	-0.288
31.87	103.00	-0.288
31.88	102.87	-0.288
31.89	102.74	-0.287
31.91	102.61	-0.287
31.92	102.47	-0.287
31.93	102.34	-0.287
31.95	102.21	-0.287
31.96	102.07	-0.287
31.98	101.94	-0.286
31.99	101.81	-0.286
32.00	101.67	-0.286
32.02	101.54	-0.286
32.03	101.41	-0.285
32.04	101.27	-0.285
32.06	101.14	-0.285
32.07	101.01	-0.285
32.08	100.87	-0.284
32.09	100.74	-0.284
32.11	100.61	-0.284
32.12	100.47	-0.284
32.13	100.34	-0.284
32.15	100.21	-0.283
32.16	100.07	-0.283
32.18	99.94	-0.282
32.19	99.81	-0.282
32.20	99.67	-0.282
32.22	99.54	-0.282
32.23	99.41	-0.282
32.24	99.27	-0.282
32.26	99.14	-0.281
32.27	99.01	-0.281
32.28	98.87	-0.281
32.29	98.74	-0.281
32.31	98.61	-0.281
32.32	98.48	-0.281
32.33	98.34	-0.280
32.35	98.21	-0.280
32.36	98.07	-0.280
32.38	97.94	-0.279
32.39	97.81	-0.279
32.40	97.68	-0.279
32.42	97.54	-0.278
32.43	97.41	-0.278
32.44	97.27	-0.278
32.46	97.14	-0.278
32.47	97.01	-0.277
32.48	96.87	-0.277
32.49	96.74	-0.277
32.51	96.61	-0.277
32.52	96.48	-0.276
32.53	96.34	-0.276
32.55	96.21	-0.276
32.56	96.08	-0.275
32.58	95.94	-0.275
32.59	95.81	-0.275
32.60	95.68	-0.275
32.62	95.54	-0.274
32.63	95.41	-0.274
32.64	95.28	-0.274
32.66	95.14	-0.274
32.67	95.01	-0.273
32.68	94.88	-0.273
32.69	94.74	-0.273
32.71	94.61	-0.272
32.72	94.48	-0.272
32.73	94.34	-0.272
32.75	94.21	-0.271
32.76	94.08	-0.271
32.78	93.94	-0.271
32.79	93.81	-0.271
32.80	93.68	-0.270
32.82	93.54	-0.270
32.83	93.41	-0.270
32.84	93.28	-0.270
32.86	93.14	-0.269
32.87	93.01	-0.269
32.88	92.88	-0.269
32.89	92.74	-0.268
32.91	92.61	-0.268
32.92	92.48	-0.268
32.93	92.34	-0.267
32.95	92.21	-0.267
32.96	92.08	-0.267
32.98	91.94	-0.266
32.99	91.81	-0.266
33.00	91.68	-0.266
33.02	91.54	-0.265
33.03	91.41	-0.265
33.04	91.28	-0.265
33.06	91.15	-0.264
33.07	91.01	-0.264
33.08	90.88	-0.264
33.09	90.74	-0.263
33.11	90.61	-0.263
33.12	90.48	-0.263
33.13	90.35	-0.263
33.15	90.21	-0.262
33.16	90.08	-0.262
33.18	89.95	-0.262
33.19	89.81	-0.261
33.20	89.68	-0.261
33.22	89.54	-0.261
33.23	89.41	-0.261
33.24	89.28	-0.260
33.26	89.15	-0.260
33.27	89.01	-0.260
33.28	88.88	-0.260
33.29	88.75	-0.259
33.31	88.61	-0.259
33.32	88.48	-0.259
33.33	88.35	-0.258
33.35	88.21	-0.258
33.36	88.08	-0.258
33.38	87.95	-0.257
33.39	87.81	-0.257
33.40	87.68	-0.257
33.42	87.55	-0.257
33.43	87.41	-0.256
33.44	87.28	-0.256
33.46	87.15	-0.256
33.47	87.01	-0.256
33.48	86.88	-0.255
33.49	86.75	-0.255
33.51	86.61	-0.255
33.52	86.48	-0.254
33.53	86.35	-0.254
33.55	86.21	-0.254
33.56	86.08	-0.254
33.58	85.95	-0.253
33.59	85.81	-0.253
33.60	85.68	-0.253
33.62	85.55	-0.253
33.63	85.42	-0.252
33.64	85.28	-0.252
33.66	85.15	-0.252
33.67	85.01	-0.252
33.68	84.88	-0.252
33.69	84.75	-0.252
33.71	84.62	-0.251
33.72	84.48	-0.251
33.73	84.35	-0.251
33.75	84.22	-0.251
33.76	84.08	-0.251
33.78	83.95	-0.250
33.79	83.82	-0.250
33.80	83.68	-0.250
33.82	83.55	-0.250
33.83	83.42	-0.250
33.84	83.28	-0.250
33.86	83.15	-0.249
33.87	83.02	-0.249
33.88	82.88	-0.249
33.89	82.75	-0.249
33.91	82.62	-0.248
33.92	82.48	-0.248
33.93	82.35	-0.248
33.95	82.22	-0.248
33.96	82.08	-0.248
33.98	81.95	-0.248
33.99	81.82	-0.248
34.00	81.68	-0.248
34.02	81.55	-0.248
34.03	81.42	-0.248
34.04	81.28	-0.248
34.06	81.15	-0.247
34.07	81.02	-0.247
34.08	80.89	-0.247
34.09	80.75	-0.247
34.11	80.62	-0.247
34.12	80.48	-0.247
34.14	80.35	-0.247
34.15	80.22	-0.247
34.16	80.09	-0.246
34.18	79.95	-0.246
34.19	79.82	-0.246
34.20	79.69	-0.246
34.21	79.55	-0.246
34.23	79.42	-0.246
34.24	79.29	-0.246
34.26	79.15	-0.245
34.27	79.02	-0.245
34.28	78.89	-0.245
34.29	78.75	-0.245
34.31	78.62	-0.245
34.32	78.49	-0.245
34.34	78.35	-0.245
34.35	78.22	-0.245
34.36	78.09	-0.244
34.38	77.95	-0.244
34.39	77.82	-0.244
34.40	77.69	-0.244
34.41	77.55	-0.244
34.43	77.42	-0.244
34.44	77.29	-0.244
34.46	77.15	-0.244
34.47	77.02	-0.243
34.48	76.89	-0.243
34.49	76.75	-0.243
34.51	76.62	-0.243
34.52	76.49	-0.243
34.54	76.35	-0.243
34.55	76.22	-0.243
34.56	76.09	-0.242
34.58	75.96	-0.242
34.59	75.82	-0.242
34.60	75.69	-0.242
34.61	75.56	-0.242
34.63	75.42	-0.242
34.64	75.29	-0.242
34.66	75.16	-0.242
34.67	75.02	-0.242
34.68	74.89	-0.241
34.69	74.76	-0.241
34.71	74.62	-0.241
34.72	74.49	-0.241
34.74	74.36	-0.241
34.75	74.22	-0.241
34.76	74.09	-0.241
34.78	73.96	-0.240
34.79	73.82	-0.240
34.80	73.69	-0.240
34.81	73.56	-0.240
34.83	73.42	-0.240
34.84	73.29	-0.239
34.86	73.16	-0.240
34.87	73.02	-0.239
34.88	72.89	-0.239
34.89	72.76	-0.239
34.91	72.62	-0.239
34.92	72.49	-0.239
34.94	72.36	-0.239
34.95	72.22	-0.239
34.96	72.09	-0.239
34.98	71.96	-0.239
34.99	71.82	-0.239
35.00	71.69	-0.239
35.01	71.56	-0.238
35.03	71.42	-0.238
35.04	71.29	-0.238
35.06	71.16	-0.238
35.07	71.03	-0.238
35.08	70.89	-0.238
35.09	70.76	-0.238
35.11	70.63	-0.238
35.12	70.49	-0.238
35.14	70.36	-0.237
35.15	70.23	-0.237
35.16	70.09	-0.237
35.18	69.96	-0.237
35.19	69.83	-0.237
35.20	69.69	-0.237
35.21	69.56	-0.237
35.23	69.43	-0.237
35.24	69.29	-0.237
35.26	69.16	-0.237
35.27	69.03	-0.237
35.28	68.89	-0.236
35.29	68.76	-0.236
35.31	68.63	-0.236
35.32	68.49	-0.236
35.34	68.36	-0.236
35.35	68.23	-0.235
35.36	68.09	-0.235
35.38	67.96	-0.235
35.39	67.83	-0.235
35.40	67.69	-0.235
35.41	67.56	-0.235
35.43	67.43	-0.235
35.44	67.29	-0.235
35.46	67.16	-0.235
35.47	67.03	-0.235
35.48	66.89	-0.235
35.49	66.76	-0.235
35.51	66.63	-0.235
35.52	66.50	-0.235
35.54	66.36	-0.235
35.55	66.23	-0.235
35.56	66.10	-0.234
35.58	65.96	-0.234
35.59	65.83	-0.234
35.60	65.70	-0.234
35.61	65.56	-0.234
35.63	65.43	-0.234
35.64	65.30	-0.234
35.66	65.16	-0.234
35.67	65.03	-0.234
35.68	64.90	-0.234
35.69	64.76	-0.234
35.71	64.63	-0.234
35.72	64.50	-0.234
35.74	64.37	-0.233
35.75	64.23	-0.233
35.76	64.10	-0.233
35.78	63.96	-0.233
35.79	63.83	-0.233
35.80	63.70	-0.233
35.81	63.57	-0.233
35.83	63.43	-0.233
35.84	63.30	-0.233
35.86	63.17	-0.233
35.87	63.03	-0.233
35.88	62.90	-0.232
35.89	62.77	-0.232
35.91	62.63	-0.232
35.92	62.50	-0.232
35.94	62.37	-0.232
35.95	62.23	-0.232
35.96	62.10	-0.232
35.98	61.97	-0.232
35.99	61.83	-0.232
36.00	61.70	-0.232
36.01	61.57	-0.232
36.03	61.43	-0.232
36.04	61.30	-0.232
36.06	61.17	-0.232
36.07	61.03	-0.231
36.08	60.90	-0.231
36.09	60.77	-0.231
36.11	60.63	-0.231
36.12	60.50	-0.231
36.14	60.37	-0.231
36.15	60.24	-0.231
36.16	60.10	-0.231
36.18	59.97	-0.231
36.19	59.83	-0.231
36.20	59.70	-0.231
36.21	59.57	-0.231
36.23	59.44	-0.230
36.24	59.30	-0.230
36.26	59.17	-0.230
36.27	59.04	-0.230
36.28	58.90	-0.230
36.29	58.77	-0.230
36.31	58.64	-0.230
36.32	58.50	-0.230
36.34	58.37	-0.230
36.35	58.23	-0.230
36.36	58.10	-0.230
36.38	57.97	-0.230
36.39	57.84	-0.230
36.40	57.70	-0.229
36.41	57.57	-0.229
36.43	57.44	-0.229
36.44	57.30	-0.229
36.46	57.17	-0.229
36.47	57.04	-0.229
36.48	56.90	-0.229
36.49	56.77	-0.229
36.51	56.64	-0.229
36.52	56.50	-0.229
36.54	56.37	-0.229
36.55	56.24	-0.229
36.56	56.10	-0.229
36.58	55.97	-0.229
36.59	55.84	-0.229
36.60	55.70	-0.229
36.61	55.57	-0.229
36.63	55.44	-0.228
36.64	55.31	-0.228
36.66	55.17	-0.228
36.67	55.04	-0.228
36.68	54.91	-0.228
36.69	54.77	-0.228
36.71	54.64	-0.228
36.72	54.51	-0.228
36.74	54.37	-0.228
36.75	54.24	-0.228
36.76	54.11	-0.228
36.78	53.97	-0.228
36.79	53.84	-0.228
36.80	53.71	-0.227
36.81	53.57	-0.227
36.83	53.44	-0.227
36.84	53.31	-0.227
36.86	53.17	-0.227
36.87	53.04	-0.227
36.88	52.91	-0.227
36.89	52.77	-0.227
36.91	52.64	-0.227
36.92	52.51	-0.227
36.94	52.37	-0.227
36.95	52.24	-0.227
36.96	52.11	-0.227
36.98	51.97	-0.227
36.99	51.84	-0.227
37.00	51.71	-0.227
37.01	51.57	-0.227
37.03	51.44	-0.227
37.04	51.31	-0.226
37.06	51.17	-0.226
37.07	51.04	-0.226
37.08	50.91	-0.226
37.09	50.78	-0.226
37.11	50.64	-0.226
37.12	50.51	-0.226
37.14	50.37	-0.226
37.15	50.24	-0.226
37.16	50.11	-0.226
37.18	49.98	-0.226
37.19	49.84	-0.226
37.20	49.71	-0.226
37.21	49.58	-0.226
37.23	49.44	-0.225
37.24	49.31	-0.225
37.26	49.18	-0.225
37.27	49.04	-0.225
37.28	48.91	-0.225
37.29	48.78	-0.225
37.31	48.64	-0.225
37.32	48.51	-0.225
37.34	48.38	-0.225
37.35	48.24	-0.225
37.36	48.11	-0.225
37.38	47.98	-0.225
37.39	47.85	-0.225
37.40	47.71	-0.225
37.41	47.58	-0.224
37.43	47.45	-0.224
37.44	47.31	-0.224
37.46	47.18	-0.224
37.47	47.05	-0.224
37.48	46.91	-0.224
37.49	46.78	-0.224
37.51	46.65	-0.224
37.52	46.51	-0.224
37.54	46.38	-0.224
37.55	46.25	-0.224
37.56	46.11	-0.224
37.58	45.98	-0.224
37.59	45.85	-0.224
37.60	45.71	-0.224
37.61	45.58	-0.224
37.63	45.45	-0.223
37.64	45.31	-0.223
37.66	45.18	-0.223
37.67	45.05	-0.223
37.68	44.91	-0.223
37.69	44.78	-0.223
37.71	44.65	-0.223
37.72	44.51	-0.223
37.74	44.38	-0.223
37.75	44.25	-0.223
37.76	44.12	-0.223
37.78	43.98	-0.223
37.79	43.85	-0.223
37.80	43.71	-0.223
37.81	43.58	-0.222
37.83	43.45	-0.222
37.84	43.31	-0.222
37.86	43.18	-0.222
37.87	43.05	-0.222
37.88	42.91	-0.222
37.89	42.78	-0.222
37.91	42.65	-0.222
37.92	42.51	-0.222
37.94	42.38	-0.222
37.95	42.25	-0.222
37.96	42.11	-0.222
37.98	41.98	-0.222
37.99	41.85	-0.222
38.00	41.72	-0.222
38.01	41.58	-0.222
38.03	41.45	-0.221
38.04	41.32	-0.221
38.06	41.18	-0.221
38.07	41.05	-0.221
38.08	40.92	-0.221
38.09	40.78	-0.221
38.11	40.65	-0.221
38.12	40.52	-0.221
38.14	40.38	-0.220
38.15	40.25	-0.220
38.16	40.12	-0.220
38.18	39.98	-0.220
38.19	39.85	-0.220
38.20	39.72	-0.220
38.21	39.58	-0.220
38.23	39.45	-0.220
38.24	39.32	-0.220
38.26	39.19	-0.220
38.27	39.05	-0.220
38.28	38.92	-0.220
38.29	38.79	-0.220
38.31	38.65	-0.220
38.32	38.52	-0.219
38.34	38.39	-0.219
38.35	38.25	-0.219
38.36	38.12	-0.219
38.38	37.99	-0.219
38.39	37.85	-0.219
38.40	37.72	-0.219
38.41	37.59	-0.219
38.43	37.45	-0.219
38.44	37.32	-0.219
38.46	37.19	-0.219
38.47	37.05	-0.218
38.48	36.92	-0.218
38.49	36.79	-0.218
38.51	36.65	-0.218
38.52	36.52	-0.218
38.54	36.39	-0.218
38.55	36.25	-0.218
38.56	36.12	-0.218
38.58	35.99	-0.218
38.59	35.85	-0.218
38.60	35.72	-0.218
38.61	35.59	-0.218
38.63	35.46	-0.218
38.64	35.32	-0.218
38.66	35.19	-0.217
38.67	35.06	-0.217
38.68	34.92	-0.217
38.69	34.79	-0.217
38.71	34.66	-0.217
38.72	34.52	-0.217
38.74	34.39	-0.217
38.75	34.26	-0.217
38.76	34.12	-0.217
38.78	33.99	-0.217
38.79	33.86	-0.217
38.80	33.72	-0.217
38.81	33.59	-0.217
38.83	33.46	-0.216
38.84	33.32	-0.216
38.86	33.19	-0.216
38.87	33.06	-0.216
38.88	32.92	-0.216
38.89	32.79	-0.216
38.91	32.66	-0.216
38.92	32.52	-0.216
38.94	32.39	-0.216
38.95	32.26
38.96	32.12
38.98	31.99
38.99	31.86
39.00