File: Data/2024_09_17_Azulene_DSC.txt
Filename	2024_09_17_Azulene_DSC
Instrument name	DSC2A-00468 (192.168.1.100)
Operator	CHM343
rundate	9/17/2024
Sample name	2024_09_17_Azulene_DSC
proceduresegments	Equilibrate 30.00 °C; Ramp 10.00 °C/min to 120.00 °C; Isothermal 1.0 min; Ramp 10.00 °C/min to 30.00 °C; Isothermal 1.0 min; Ramp 10.00 °C/min to 120.00 °C
[File Parameters]
Run date	9/17/2024 11:08:24 PM
Trios version	5.1.1.46572
Original File Name
Current File Name	C:\ProgramData\TA Instruments\TRIOS\Data\2024_09_17_Azulene_DSC.tri
[Procedure]
Procedure Name	CHM343_Fall2024_Azulene
Sample Name	2024_09_17_Azulene_DSC
Sample Mass	0.12 mg
Reference Sample Mass	0 mg
Pan Mass	53.61 mg
Pan Number	21
Reference Pan Mass	54 mg
Reference Pan Number	19
Pan Type	Aluminum
Comments	Azulene - Al Hermetic Sealed Pan, with ref Al pan.  ASU Online CHM343, Remote DSC experimental lab. Fall 2024.  Group Zoom Data Collection, Sept 17, 2024 from 9-11 pm.  TA Instruments DSC2500.
Project Name	Lab 4 - Fall 2024
Operator	CHM343
Test	Custom
Unload Max Temperature	30
Unload Min Temperature	30
Load Max Temperature	30
Load Min Temperature	30
Stop on Gas Flow Error	Yes
[Signal List]
Signal #1	Time (min)
Signal #2	Temperature (°C)
Signal #3	Heat Flow (mW)
Signal #4	Delta T (µV)
Signal #5	Delta Tzero (µV)
Signal #6	Tzero Temperature (°C)
Signal #7	Cell Purge (mL/min)
Signal #8	Heater Temp (°C)
Signal #9	Power Delivered (W)
Signal #10	Reference Junction Temperature (°C)
Signal #11	Flange Temperature (°C)
Signal #12	Heat Flow Phase (rad)
Signal #13	Total Heat Capacity (J/°C)
Signal #14	Heat Capacity (J/°C)
[Configuration]
Company Name	ASU
Instrument Name	DSC2A-00468
Instrument Type	DSC2500
Serial Number	DSC2A-00468
IP	192.168.1.100
Location of Instrument	MRRC
DisplayType	Unknown
Sample Interval 	0.1 s/pt
Selected Heat Flow	T4P
Exotherm Direction	Down
Cell Serial	DRC2-00792
Lid Type	Standard
Cooler	RCS 90
Leave Cooler on at End of Sequence	On
Gas 2	Nitrogen
Gas Selected	Channel 1
Flow Rate	50 mL/min
Secondary Purge	On
Licensed Heat Flow	Heat Flow T4P
Modulation Licensed	Yes
[Versions]
Common IDD Version	1
Cortex Version	VER 2.10.2.31
Driver	5.0.0.6
GDM Version	1.0.3.3
TouchscreenVersion	1.0.0.16145
FEP Version	1.2.1.21
FEP Bootloader	2.0.0.5
AutoSampler Version	2.1.1.26
Auto Sampler Bootloader	2.0.0.5
FCM Version	1.1.0.3
FCM Bootloader	2.0.0.5
[Experiment Logs]
Experiment Log Entry # 1	Equilibrate Segment 30 (C) Started
Experiment Log Entry # 3	Air Cool is off.
Experiment Log Entry # 5	Ramp Segment 10 C/min to 120 Started
Experiment Log Entry # 7	Isothermal Segment 1 min started
Experiment Log Entry # 9	Ramp Segment 10 C/min to 30 Started
Experiment Log Entry # 11	Isothermal Segment 1 min started
Experiment Log Entry # 13	Ramp Segment 10 C/min to 120 Started
[Method Log]
Method Log Entry # 1	Equilibrate 30 °C
Method Log Entry # 2	(Ramp 85459) Ramp 10 °C/minute to 120 °C
Method Log Entry # 3	Isothermal 1 minutes
Method Log Entry # 4	(Ramp 85461) Ramp 10 °C/minute to 30 °C
Method Log Entry # 5	Isothermal 1 minutes
Method Log Entry # 6	(Ramp 85463) Ramp 10 °C/minute to 120 °C
Cell Serial	DRC2-00792
[T1 Calibration]
Slope	-0.008529666
Offset	9.636258
Initial Temperature	98.23
GUID	f8bfdadc-4977-4fdf-ba6d-0ba9134940c3
[TZero Calibration]
Date Applied	11/29/2022 4:06:13 PM
Description	From -89.059 °C to 396.009 °C at 20.000°C/min
Gas Type	Nitrogen
Pan Type	None
Source Files 1	C:\Users\yargerlab\Desktop\DSC Data\General\TZero_calibration_11_29_22_2nd(2).tri
Source Files 2	C:\Users\yargerlab\Desktop\DSC Data\General\TZero_calibration_11_29_22_2nd(3).tri
Delta T Offset	13.05235
Delta T Slope	-0.007271007
Delta T0 Offset	-13.69128
Delta T0 Slope	0.06063341
[Temperature Calibration]
Date Applied	11/29/2022 7:12:28 PM
Description	From 106.590 °C to 186.590 °C at 10.000°C/min
Gas Type	Nitrogen
Pan Type	Tzero Aluminum Hermetic
Source Files 1	C:\Users\yargerlab\Desktop\DSC Data\General\Indium(6).tri
Measured 1	157.391
Known 1	156.598
[Cell Constant Calibration]
Date Applied	11/29/2022 7:12:29 PM
Description	From 106.590 °C to 186.590 °C at 10.000°C/min
Gas Type	Nitrogen
Pan Type	Tzero Aluminum Hermetic
Source Files 1	C:\Users\yargerlab\Desktop\DSC Data\General\Indium(6).tri
T4P KCell	1.006051
Onset Slope	63.26126 mW/°C
[Direct Cp Calibration]
Date Applied	11/30/2022 11:04:51 AM
Description	From -79.983 °C to 298.409 °C at 10.000°C/min
Gas Type	Nitrogen
Pan Type	Tzero Aluminum Hermetic
Source Files 1	C:\Users\yargerlab\Desktop\DSC Data\General\Sapphire_Heat_Capacity_11_30_22.tri
[Rev Cp Calibration]
Date Applied	11/30/2022 1:58:51 PM
Description	From -79.996 °C to 292.812 °C at 3.000°C/min
Gas Type	Nitrogen
Pan Type	Tzero Aluminum Hermetic
Source Files 1	C:\Users\yargerlab\Desktop\DSC Data\General\Sapphire_MDSC_Calibration_11_30_22.tri
[step]
Ramp 10.00 °C/min to 120.00 °C
Time	Temperature	Heat Flow (Normalized)
min	°C	W/g
0.00	30.06	-1.147
0.01	30.06	-1.145
0.01	30.06	-1.141
0.02	30.06	-1.138
0.03	30.06	-1.134
0.03	30.07	-1.131
0.04	30.07	-1.128
0.05	30.07	-1.126
0.05	30.08	-1.125
0.06	30.09	-1.148
0.07	30.10	-1.263
0.07	30.11	-1.499
0.08	30.12	-1.754
0.09	30.14	-2.047
0.09	30.16	-2.263
0.10	30.19	-2.427
0.11	30.22	-2.569
0.11	30.25	-2.686
0.12	30.28	-2.727
0.13	30.32	-2.714
0.13	30.36	-2.708
0.14	30.40	-2.687
0.15	30.45	-2.584
0.15	30.49	-2.526
0.16	30.54	-2.413
0.17	30.59	-2.126
0.17	30.64	-1.818
0.18	30.69	-1.524
0.19	30.74	-1.279
0.19	30.79	-1.102
0.20	30.85	-0.921
0.21	30.90	-0.696
0.21	30.96	-0.545
0.22	31.01	-0.423
0.23	31.07	-0.304
0.23	31.13	-0.195
0.24	31.18	-0.087
0.25	31.24	-0.036
0.25	31.30	0.064
0.26	31.36	0.159
0.27	31.42	0.257
0.27	31.48	0.309
0.28	31.54	0.396
0.29	31.60	0.464
0.29	31.66	0.515
0.30	31.72	0.612
0.31	31.79	0.653
0.31	31.85	0.677
0.32	31.91	0.743
0.33	31.97	0.814
0.33	32.04	0.851
0.34	32.10	0.923
0.35	32.16	0.950
0.35	32.23	0.985
0.36	32.29	1.051
0.37	32.35	1.097
0.37	32.42	1.126
0.38	32.48	1.158
0.39	32.55	1.227
0.39	32.61	1.253
0.40	32.67	1.258
0.41	32.74	1.284
0.41	32.80	1.300
0.42	32.87	1.310
0.43	32.93	1.348
0.43	33.00	1.361
0.44	33.06	1.364
0.45	33.13	1.375
0.45	33.19	1.409
0.46	33.26	1.425
0.47	33.32	1.433
0.47	33.39	1.445
0.48	33.45	1.462
0.49	33.52	1.473
0.49	33.58	1.482
0.50	33.65	1.487
0.51	33.71	1.498
0.51	33.78	1.504
0.52	33.85	1.508
0.53	33.91	1.512
0.53	33.98	1.515
0.54	34.04	1.519
0.55	34.11	1.524
0.55	34.17	1.530
0.56	34.24	1.535
0.57	34.31	1.540
0.57	34.37	1.549
0.58	34.44	1.555
0.59	34.50	1.560
0.59	34.57	1.565
0.60	34.63	1.568
0.61	34.70	1.573
0.61	34.77	1.579
0.62	34.83	1.584
0.63	34.90	1.588
0.63	34.96	1.593
0.64	35.03	1.609
0.65	35.10	1.616
0.65	35.16	1.621
0.66	35.23	1.625
0.67	35.29	1.628
0.67	35.36	1.632
0.68	35.42	1.636
0.69	35.49	1.640
0.69	35.56	1.645
0.70	35.62	1.649
0.71	35.69	1.654
0.71	35.76	1.659
0.72	35.82	1.663
0.73	35.89	1.666
0.73	35.95	1.670
0.74	36.02	1.674
0.75	36.09	1.678
0.75	36.15	1.681
0.76	36.22	1.685
0.77	36.28	1.689
0.77	36.35	1.692
0.78	36.42	1.695
0.79	36.48	1.698
0.79	36.55	1.701
0.80	36.62	1.705
0.81	36.68	1.709
0.81	36.75	1.711
0.82	36.82	1.714
0.83	36.88	1.717
0.83	36.95	1.721
0.84	37.01	1.724
0.85	37.08	1.728
0.85	37.14	1.735
0.86	37.21	1.739
0.87	37.28	1.740
0.87	37.34	1.742
0.88	37.41	1.743
0.89	37.48	1.745
0.89	37.54	1.747
0.90	37.61	1.750
0.91	37.68	1.752
0.91	37.74	1.754
0.92	37.81	1.756
0.93	37.87	1.759
0.93	37.94	1.762
0.94	38.01	1.765
0.95	38.07	1.767
0.95	38.14	1.770
0.96	38.21	1.772
0.97	38.27	1.773
0.97	38.34	1.773
0.98	38.40	1.775
0.99	38.47	1.777
0.99	38.54	1.779
1.00	38.60	1.782
1.01	38.67	1.785
1.01	38.74	1.786
1.02	38.80	1.787
1.03	38.87	1.790
1.03	38.94	1.792
1.04	39.00	1.794
1.05	39.07	1.796
1.05	39.14	1.798
1.06	39.20	1.800
1.07	39.27	1.801
1.07	39.34	1.801
1.08	39.40	1.802
1.09	39.47	1.803
1.09	39.53	1.804
1.10	39.60	1.805
1.11	39.67	1.806
1.11	39.73	1.807
1.12	39.80	1.808
1.13	39.87	1.809
1.13	39.93	1.811
1.14	40.00	1.812
1.15	40.07	1.813
1.15	40.13	1.814
1.16	40.20	1.815
1.17	40.27	1.816
1.17	40.33	1.816
1.18	40.40	1.817
1.19	40.47	1.817
1.19	40.53	1.818
1.20	40.60	1.820
1.21	40.67	1.820
1.21	40.73	1.820
1.22	40.80	1.820
1.23	40.86	1.821
1.23	40.93	1.821
1.24	41.00	1.820
1.25	41.06	1.820
1.25	41.13	1.821
1.26	41.20	1.822
1.27	41.26	1.824
1.27	41.33	1.825
1.28	41.40	1.823
1.29	41.46	1.822
1.29	41.53	1.822
1.30	41.60	1.824
1.31	41.66	1.826
1.31	41.73	1.825
1.32	41.80	1.824
1.33	41.86	1.824
1.33	41.93	1.825
1.34	42.00	1.825
1.35	42.06	1.826
1.35	42.13	1.825
1.36	42.20	1.824
1.37	42.26	1.824
1.37	42.33	1.825
1.38	42.40	1.825
1.39	42.46	1.825
1.39	42.53	1.826
1.40	42.60	1.825
1.41	42.66	1.824
1.41	42.73	1.824
1.42	42.79	1.825
1.43	42.86	1.825
1.43	42.93	1.825
1.44	42.99	1.825
1.45	43.06	1.825
1.45	43.13	1.824
1.46	43.19	1.824
1.47	43.26	1.825
1.47	43.33	1.826
1.48	43.39	1.826
1.49	43.46	1.824
1.49	43.53	1.825
1.50	43.59	1.826
1.51	43.66	1.826
1.51	43.73	1.826
1.52	43.79	1.826
1.53	43.86	1.827
1.53	43.93	1.826
1.54	43.99	1.826
1.55	44.06	1.827
1.55	44.13	1.827
1.56	44.19	1.827
1.57	44.26	1.826
1.57	44.33	1.826
1.58	44.39	1.826
1.59	44.46	1.825
1.59	44.53	1.824
1.60	44.59	1.825
1.61	44.66	1.824
1.61	44.73	1.823
1.62	44.79	1.825
1.63	44.86	1.825
1.63	44.93	1.823
1.64	44.99	1.823
1.65	45.06	1.823
1.65	45.13	1.823
1.66	45.19	1.823
1.67	45.26	1.823
1.67	45.33	1.822
1.68	45.39	1.821
1.69	45.46	1.821
1.69	45.53	1.821
1.70	45.59	1.820
1.71	45.66	1.820
1.71	45.73	1.821
1.72	45.79	1.822
1.73	45.86	1.822
1.73	45.93	1.820
1.74	45.99	1.818
1.75	46.06	1.817
1.75	46.13	1.816
1.76	46.19	1.815
1.77	46.26	1.817
1.77	46.33	1.816
1.78	46.39	1.816
1.79	46.46	1.817
1.79	46.53	1.817
1.80	46.59	1.817
1.81	46.66	1.816
1.81	46.73	1.816
1.82	46.79	1.815
1.83	46.86	1.815
1.83	46.93	1.815
1.84	46.99	1.815
1.85	47.06	1.815
1.85	47.13	1.814
1.86	47.19	1.814
1.87	47.26	1.812
1.87	47.33	1.813
1.88	47.39	1.814
1.89	47.46	1.814
1.89	47.53	1.814
1.90	47.59	1.814
1.91	47.66	1.813
1.91	47.73	1.813
1.92	47.79	1.812
1.93	47.86	1.811
1.93	47.93	1.811
1.94	47.99	1.811
1.95	48.06	1.812
1.95	48.13	1.812
1.96	48.19	1.812
1.97	48.26	1.812
1.97	48.33	1.812
1.98	48.39	1.813
1.99	48.46	1.813
1.99	48.53	1.811
2.00	48.59	1.810
2.01	48.66	1.810
2.01	48.73	1.810
2.02	48.79	1.810
2.03	48.86	1.810
2.03	48.93	1.810
2.04	48.99	1.809
2.05	49.06	1.809
2.05	49.13	1.808
2.06	49.19	1.808
2.07	49.26	1.808
2.07	49.33	1.808
2.08	49.39	1.809
2.09	49.46	1.810
2.09	49.53	1.811
2.10	49.59	1.810
2.11	49.66	1.810
2.11	49.73	1.809
2.12	49.79	1.809
2.13	49.86	1.810
2.13	49.93	1.810
2.14	49.99	1.811
2.15	50.06	1.810
2.15	50.13	1.810
2.16	50.19	1.809
2.17	50.26	1.808
2.17	50.33	1.808
2.18	50.39	1.806
2.19	50.46	1.807
2.19	50.53	1.807
2.20	50.59	1.807
2.21	50.66	1.807
2.21	50.73	1.806
2.22	50.80	1.807
2.23	50.86	1.808
2.23	50.93	1.806
2.24	50.99	1.805
2.25	51.06	1.805
2.25	51.13	1.805
2.26	51.19	1.806
2.27	51.26	1.805
2.27	51.33	1.805
2.28	51.39	1.806
2.29	51.46	1.806
2.29	51.53	1.806
2.30	51.59	1.806
2.31	51.66	1.807
2.31	51.73	1.807
2.32	51.79	1.807
2.33	51.86	1.807
2.33	51.93	1.807
2.34	51.99	1.807
2.35	52.06	1.806
2.35	52.13	1.806
2.36	52.19	1.806
2.37	52.26	1.806
2.37	52.33	1.806
2.38	52.40	1.807
2.39	52.46	1.806
2.39	52.53	1.805
2.40	52.60	1.804
2.41	52.66	1.804
2.41	52.73	1.812
2.42	52.80	1.812
2.43	52.86	1.812
2.43	52.93	1.812
2.44	53.00	1.811
2.45	53.06	1.812
2.45	53.13	1.812
2.46	53.20	1.811
2.47	53.26	1.813
2.47	53.33	1.812
2.48	53.40	1.811
2.49	53.46	1.811
2.49	53.53	1.812
2.50	53.60	1.812
2.51	53.66	1.813
2.51	53.73	1.813
2.52	53.80	1.813
2.53	53.86	1.812
2.53	53.93	1.810
2.54	54.00	1.810
2.55	54.06	1.810
2.55	54.13	1.810
2.56	54.20	1.810
2.57	54.26	1.809
2.57	54.33	1.810
2.58	54.40	1.811
2.59	54.46	1.811
2.59	54.53	1.811
2.60	54.60	1.811
2.61	54.66	1.811
2.61	54.73	1.812
2.62	54.80	1.812
2.63	54.86	1.811
2.63	54.93	1.812
2.64	55.00	1.813
2.65	55.06	1.817
2.65	55.13	1.829
2.66	55.20	1.834
2.67	55.26	1.835
2.67	55.33	1.837
2.68	55.40	1.838
2.69	55.46	1.839
2.69	55.53	1.838
2.70	55.60	1.837
2.71	55.66	1.837
2.71	55.73	1.840
2.72	55.80	1.841
2.73	55.87	1.841
2.73	55.93	1.843
2.74	56.00	1.842
2.75	56.06	1.842
2.75	56.13	1.842
2.76	56.20	1.843
2.77	56.26	1.843
2.77	56.33	1.843
2.78	56.40	1.845
2.79	56.47	1.845
2.79	56.53	1.845
2.80	56.60	1.845
2.81	56.67	1.846
2.81	56.73	1.846
2.82	56.80	1.847
2.83	56.87	1.848
2.83	56.93	1.850
2.84	57.00	1.850
2.85	57.07	1.850
2.85	57.13	1.851
2.86	57.20	1.853
2.87	57.27	1.854
2.87	57.33	1.854
2.88	57.40	1.854
2.89	57.47	1.854
2.89	57.53	1.856
2.90	57.60	1.857
2.91	57.67	1.858
2.91	57.73	1.857
2.92	57.80	1.858
2.93	57.87	1.858
2.93	57.93	1.860
2.94	58.00	1.860
2.95	58.07	1.860
2.95	58.13	1.860
2.96	58.20	1.860
2.97	58.27	1.861
2.97	58.33	1.863
2.98	58.40	1.864
2.99	58.47	1.864
2.99	58.53	1.863
3.00	58.60	1.864
3.01	58.67	1.864
3.01	58.73	1.864
3.02	58.80	1.865
3.03	58.87	1.865
3.03	58.93	1.865
3.04	59.00	1.865
3.05	59.07	1.865
3.05	59.13	1.866
3.06	59.20	1.866
3.07	59.27	1.865
3.07	59.33	1.866
3.08	59.40	1.865
3.09	59.47	1.865
3.09	59.53	1.866
3.10	59.60	1.865
3.11	59.67	1.866
3.11	59.73	1.867
3.12	59.80	1.868
3.13	59.87	1.868
3.13	59.93	1.869
3.14	60.00	1.869
3.15	60.07	1.870
3.15	60.13	1.870
3.16	60.20	1.872
3.17	60.27	1.873
3.17	60.33	1.872
3.18	60.40	1.872
3.19	60.47	1.872
3.19	60.53	1.872
3.20	60.60	1.874
3.21	60.67	1.875
3.21	60.73	1.875
3.22	60.80	1.875
3.23	60.87	1.875
3.23	60.93	1.875
3.24	61.00	1.876
3.25	61.07	1.878
3.25	61.13	1.878
3.26	61.20	1.877
3.27	61.27	1.877
3.27	61.33	1.878
3.28	61.40	1.878
3.29	61.47	1.878
3.29	61.54	1.879
3.30	61.60	1.880
3.31	61.67	1.880
3.31	61.74	1.881
3.32	61.80	1.880
3.33	61.87	1.880
3.33	61.94	1.881
3.34	62.00	1.883
3.35	62.07	1.883
3.35	62.14	1.883
3.36	62.20	1.883
3.37	62.27	1.887
3.37	62.34	1.888
3.38	62.40	1.887
3.39	62.47	1.889
3.39	62.54	1.891
3.40	62.60	1.892
3.41	62.67	1.892
3.41	62.74	1.893
3.42	62.80	1.893
3.43	62.87	1.893
3.43	62.93	1.894
3.44	63.00	1.896
3.45	63.07	1.897
3.45	63.13	1.898
3.46	63.20	1.898
3.47	63.27	1.897
3.47	63.34	1.897
3.48	63.40	1.898
3.49	63.47	1.899
3.49	63.54	1.900
3.50	63.60	1.901
3.51	63.67	1.901
3.51	63.74	1.901
3.52	63.80	1.902
3.53	63.87	1.903
3.53	63.94	1.905
3.54	64.00	1.906
3.55	64.07	1.906
3.55	64.14	1.906
3.56	64.20	1.908
3.57	64.27	1.909
3.57	64.34	1.909
3.58	64.40	1.909
3.59	64.47	1.909
3.59	64.54	1.910
3.60	64.60	1.912
3.61	64.67	1.913
3.61	64.74	1.913
3.62	64.80	1.913
3.63	64.87	1.913
3.63	64.94	1.915
3.64	65.00	1.916
3.65	65.07	1.915
3.65	65.14	1.915
3.66	65.20	1.916
3.67	65.27	1.918
3.67	65.34	1.918
3.68	65.40	1.917
3.69	65.47	1.917
3.69	65.54	1.917
3.70	65.60	1.918
3.71	65.67	1.920
3.71	65.74	1.920
3.72	65.80	1.919
3.73	65.87	1.920
3.73	65.94	1.920
3.74	66.00	1.920
3.75	66.07	1.921
3.75	66.14	1.921
3.76	66.21	1.920
3.77	66.27	1.921
3.77	66.34	1.922
3.78	66.40	1.923
3.79	66.47	1.923
3.79	66.54	1.919
3.80	66.61	1.918
3.81	66.67	1.918
3.81	66.74	1.920
3.82	66.81	1.922
3.83	66.87	1.923
3.83	66.94	1.922
3.84	67.01	1.922
3.85	67.07	1.924
3.85	67.14	1.924
3.86	67.21	1.924
3.87	67.27	1.925
3.87	67.34	1.926
3.88	67.41	1.927
3.89	67.47	1.927
3.89	67.54	1.928
3.90	67.61	1.928
3.91	67.67	1.928
3.91	67.74	1.929
3.92	67.81	1.931
3.93	67.87	1.932
3.93	67.94	1.931
3.94	68.01	1.932
3.95	68.07	1.933
3.95	68.14	1.933
3.96	68.21	1.933
3.97	68.27	1.933
3.97	68.34	1.934
3.98	68.41	1.935
3.99	68.47	1.934
3.99	68.54	1.934
4.00	68.61	1.935
4.01	68.67	1.935
4.01	68.74	1.935
4.02	68.81	1.935
4.03	68.87	1.937
4.03	68.94	1.938
4.04	69.01	1.938
4.05	69.07	1.939
4.05	69.14	1.939
4.06	69.21	1.939
4.07	69.27	1.940
4.07	69.34	1.941
4.08	69.41	1.940
4.09	69.47	1.939
4.09	69.54	1.939
4.10	69.61	1.939
4.11	69.67	1.939
4.11	69.74	1.940
4.12	69.81	1.940
4.13	69.87	1.941
4.13	69.94	1.942
4.14	70.01	1.943
4.15	70.07	1.943
4.15	70.14	1.942
4.16	70.21	1.941
4.17	70.27	1.941
4.17	70.34	1.942
4.18	70.41	1.942
4.19	70.48	1.942
4.19	70.54	1.943
4.20	70.61	1.943
4.21	70.68	1.942
4.21	70.74	1.943
4.22	70.81	1.942
4.23	70.88	1.942
4.23	70.94	1.942
4.24	71.01	1.943
4.25	71.08	1.943
4.25	71.14	1.944
4.26	71.21	1.944
4.27	71.28	1.944
4.27	71.34	1.945
4.28	71.41	1.946
4.29	71.48	1.946
4.29	71.54	1.946
4.30	71.61	1.946
4.31	71.68	1.945
4.31	71.74	1.946
4.32	71.81	1.947
4.33	71.88	1.948
4.33	71.94	1.948
4.34	72.01	1.949
4.35	72.08	1.949
4.35	72.14	1.949
4.36	72.21	1.948
4.37	72.28	1.947
4.37	72.34	1.948
4.38	72.41	1.949
4.39	72.48	1.949
4.39	72.54	1.950
4.40	72.61	1.949
4.41	72.68	1.948
4.41	72.74	1.948
4.42	72.81	1.949
4.43	72.88	1.948
4.43	72.94	1.948
4.44	73.01	1.948
4.45	73.08	1.949
4.45	73.14	1.949
4.46	73.21	1.949
4.47	73.28	1.949
4.47	73.34	1.950
4.48	73.41	1.950
4.49	73.48	1.950
4.49	73.54	1.950
4.50	73.61	1.951
4.51	73.68	1.950
4.51	73.75	1.950
4.52	73.81	1.950
4.53	73.88	1.950
4.53	73.94	1.951
4.54	74.01	1.951
4.55	74.08	1.952
4.55	74.14	1.952
4.56	74.21	1.952
4.57	74.28	1.952
4.57	74.35	1.952
4.58	74.41	1.952
4.59	74.48	1.953
4.59	74.55	1.954
4.60	74.61	1.954
4.61	74.68	1.954
4.61	74.75	1.954
4.62	74.81	1.954
4.63	74.88	1.954
4.63	74.95	1.954
4.64	75.01	1.954
4.65	75.08	1.954
4.65	75.15	1.955
4.66	75.21	1.956
4.67	75.28	1.956
4.67	75.35	1.955
4.68	75.41	1.955
4.69	75.48	1.956
4.69	75.55	1.956
4.70	75.61	1.956
4.71	75.68	1.956
4.71	75.75	1.957
4.72	75.81	1.956
4.73	75.88	1.956
4.73	75.95	1.957
4.74	76.01	1.957
4.75	76.08	1.959
4.75	76.15	1.959
4.76	76.21	1.959
4.77	76.28	1.959
4.77	76.35	1.958
4.78	76.41	1.958
4.79	76.48	1.960
4.79	76.55	1.960
4.80	76.61	1.959
4.81	76.68	1.960
4.81	76.75	1.960
4.82	76.81	1.961
4.83	76.88	1.963
4.83	76.95	1.963
4.84	77.01	1.962
4.85	77.08	1.958
4.85	77.15	1.958
4.86	77.21	1.960
4.87	77.28	1.960
4.87	77.35	1.960
4.88	77.41	1.960
4.89	77.48	1.960
4.89	77.55	1.961
4.90	77.61	1.960
4.91	77.68	1.961
4.91	77.75	1.962
4.92	77.82	1.961
4.93	77.88	1.962
4.93	77.95	1.963
4.94	78.01	1.964
4.95	78.08	1.964
4.95	78.15	1.964
4.96	78.21	1.964
4.97	78.28	1.965
4.97	78.35	1.965
4.98	78.42	1.965
4.99	78.48	1.964
4.99	78.55	1.963
5.00	78.62	1.964
5.01	78.68	1.965
5.01	78.75	1.966
5.02	78.81	1.967
5.03	78.88	1.967
5.03	78.95	1.967
5.04	79.02	1.968
5.05	79.08	1.969
5.05	79.15	1.970
5.06	79.22	1.971
5.07	79.28	1.972
5.07	79.35	1.971
5.08	79.42	1.968
5.09	79.48	1.968
5.09	79.55	1.968
5.10	79.62	1.969
5.11	79.68	1.969
5.11	79.75	1.969
5.12	79.82	1.969
5.13	79.88	1.969
5.13	79.95	1.970
5.14	80.02	1.970
5.15	80.08	1.970
5.15	80.15	1.970
5.16	80.22	1.971
5.17	80.28	1.971
5.17	80.35	1.970
5.18	80.42	1.970
5.19	80.48	1.971
5.19	80.55	1.971
5.20	80.62	1.971
5.21	80.68	1.972
5.21	80.75	1.972
5.22	80.82	1.972
5.23	80.88	1.972
5.23	80.95	1.973
5.24	81.02	1.973
5.25	81.08	1.972
5.25	81.15	1.972
5.26	81.22	1.972
5.27	81.28	1.971
5.27	81.35	1.972
5.28	81.42	1.973
5.29	81.48	1.973
5.29	81.55	1.973
5.30	81.62	1.973
5.31	81.68	1.974
5.31	81.75	1.975
5.32	81.82	1.974
5.33	81.88	1.972
5.33	81.95	1.972
5.34	82.02	1.973
5.35	82.08	1.972
5.35	82.15	1.972
5.36	82.22	1.973
5.37	82.28	1.974
5.37	82.35	1.974
5.38	82.42	1.972
5.39	82.49	1.972
5.39	82.55	1.972
5.40	82.62	1.974
5.41	82.68	1.974
5.41	82.75	1.973
5.42	82.82	1.974
5.43	82.88	1.975
5.43	82.95	1.975
5.44	83.02	1.974
5.45	83.08	1.974
5.45	83.15	1.973
5.46	83.22	1.974
5.47	83.28	1.975
5.47	83.35	1.976
5.48	83.42	1.976
5.49	83.49	1.976
5.49	83.55	1.978
5.50	83.62	1.977
5.51	83.69	1.977
5.51	83.75	1.977
5.52	83.82	1.977
5.53	83.89	1.977
5.53	83.95	1.977
5.54	84.02	1.977
5.55	84.09	1.976
5.55	84.15	1.976
5.56	84.22	1.976
5.57	84.29	1.977
5.57	84.35	1.977
5.58	84.42	1.978
5.59	84.49	1.977
5.59	84.55	1.977
5.60	84.62	1.976
5.61	84.69	1.976
5.61	84.75	1.976
5.62	84.82	1.976
5.63	84.89	1.975
5.63	84.95	1.976
5.64	85.02	1.977
5.65	85.09	1.977
5.65	85.15	1.978
5.66	85.22	1.978
5.67	85.29	1.978
5.67	85.35	1.977
5.68	85.42	1.976
5.69	85.49	1.976
5.69	85.55	1.975
5.70	85.62	1.976
5.71	85.69	1.977
5.71	85.75	1.979
5.72	85.82	1.979
5.73	85.89	1.976
5.73	85.95	1.976
5.74	86.02	1.976
5.75	86.09	1.976
5.75	86.15	1.976
5.76	86.22	1.975
5.77	86.29	1.974
5.77	86.35	1.974
5.78	86.42	1.974
5.79	86.49	1.974
5.79	86.55	1.975
5.80	86.62	1.976
5.81	86.69	1.975
5.81	86.75	1.975
5.82	86.82	1.976
5.83	86.89	1.975
5.83	86.95	1.974
5.84	87.02	1.975
5.85	87.09	1.976
5.85	87.15	1.975
5.86	87.22	1.975
5.87	87.29	1.976
5.87	87.35	1.976
5.88	87.42	1.976
5.89	87.49	1.976
5.89	87.56	1.977
5.90	87.62	1.977
5.91	87.69	1.976
5.91	87.76	1.978
5.92	87.82	1.978
5.93	87.89	1.978
5.93	87.96	1.977
5.94	88.02	1.978
5.95	88.09	1.981
5.95	88.16	1.981
5.96	88.22	1.980
5.97	88.29	1.980
5.97	88.36	1.981
5.98	88.42	1.982
5.99	88.49	1.982
5.99	88.56	1.982
6.00	88.62	1.981
6.01	88.69	1.982
6.01	88.76	1.983
6.02	88.82	1.984
6.03	88.89	1.986
6.03	88.96	1.986
6.04	89.02	1.986
6.05	89.09	1.987
6.05	89.16	1.987
6.06	89.22	1.986
6.07	89.29	1.987
6.07	89.36	1.988
6.08	89.42	1.989
6.09	89.49	1.989
6.09	89.56	1.988
6.10	89.62	1.988
6.11	89.69	1.989
6.11	89.76	1.990
6.12	89.82	1.991
6.13	89.89	1.991
6.13	89.96	1.991
6.14	90.02	1.992
6.15	90.09	1.994
6.15	90.16	1.994
6.16	90.22	1.994
6.17	90.29	1.994
6.17	90.36	1.995
6.18	90.42	1.995
6.19	90.49	1.996
6.19	90.56	1.996
6.20	90.62	1.997
6.21	90.69	1.997
6.21	90.76	1.997
6.22	90.82	1.998
6.23	90.89	1.999
6.23	90.96	2.000
6.24	91.02	2.000
6.25	91.09	2.001
6.25	91.16	2.002
6.26	91.22	2.003
6.27	91.29	2.005
6.27	91.36	2.004
6.28	91.42	2.005
6.29	91.49	2.006
6.29	91.56	2.007
6.30	91.62	2.007
6.31	91.69	2.008
6.31	91.76	2.010
6.32	91.83	2.010
6.33	91.89	2.011
6.33	91.96	2.011
6.34	92.02	2.011
6.35	92.09	2.011
6.35	92.16	2.013
6.36	92.23	2.015
6.37	92.29	2.017
6.37	92.36	2.018
6.38	92.42	2.018
6.39	92.49	2.018
6.39	92.56	2.018
6.40	92.63	2.019
6.41	92.69	2.021
6.41	92.76	2.022
6.42	92.83	2.023
6.43	92.89	2.025
6.43	92.96	2.025
6.44	93.03	2.024
6.45	93.09	2.026
6.45	93.16	2.027
6.46	93.23	2.028
6.47	93.29	2.028
6.47	93.36	2.029
6.48	93.43	2.029
6.49	93.49	2.032
6.49	93.56	2.034
6.50	93.63	2.034
6.51	93.69	2.034
6.51	93.76	2.036
6.52	93.83	2.037
6.53	93.89	2.036
6.53	93.96	2.037
6.54	94.03	2.038
6.55	94.09	2.039
6.55	94.16	2.040
6.56	94.23	2.041
6.57	94.29	2.042
6.57	94.36	2.043
6.58	94.43	2.044
6.59	94.49	2.046
6.59	94.56	2.045
6.60	94.63	2.046
6.61	94.69	2.048
6.61	94.76	2.050
6.62	94.83	2.050
6.63	94.89	2.052
6.63	94.96	2.052
6.64	95.03	2.053
6.65	95.09	2.053
6.65	95.16	2.054
6.66	95.23	2.055
6.67	95.29	2.057
6.67	95.36	2.059
6.68	95.43	2.060
6.69	95.49	2.061
6.69	95.56	2.062
6.70	95.63	2.063
6.71	95.69	2.065
6.71	95.76	2.066
6.72	95.83	2.067
6.73	95.89	2.070
6.73	95.96	2.075
6.74	96.03	2.077
6.75	96.09	2.078
6.75	96.16	2.080
6.76	96.23	2.082
6.77	96.29	2.085
6.77	96.36	2.088
6.78	96.43	2.089
6.79	96.49	2.089
6.79	96.56	2.092
6.80	96.63	2.094
6.81	96.69	2.096
6.81	96.76	2.099
6.82	96.83	2.102
6.83	96.89	2.107
6.83	96.96	2.111
6.84	97.03	2.113
6.85	97.09	2.115
6.85	97.16	2.120
6.86	97.23	2.125
6.87	97.29	2.131
6.87	97.36	2.155
6.88	97.43	2.166
6.89	97.49	2.169
6.89	97.56	2.175
6.90	97.63	2.182
6.91	97.69	2.191
6.91	97.76	2.208
6.92	97.83	2.219
6.93	97.89	2.249
6.93	97.96	2.291
6.94	98.03	2.375
6.95	98.09	2.479
6.95	98.16	2.537
6.96	98.23	2.674
6.97	98.29	2.895
6.97	98.36	3.017
6.98	98.42	3.217
6.99	98.49	3.535
6.99	98.56	3.894
7.00	98.62	4.317
7.01	98.69	4.812
7.01	98.75	5.573
7.02	98.82	6.647
7.03	98.88	8.111
7.03	98.94	10.111
7.04	99.00	12.830
7.05	99.06	16.397
7.05	99.12	20.327
7.06	99.17	23.741
7.07	99.22	25.994
7.07	99.28	26.692
7.08	99.33	25.883
7.09	99.39	24.449
7.09	99.45	22.774
7.10	99.51	20.759
7.11	99.58	18.402
7.11	99.65	15.391
7.12	99.72	11.833
7.13	99.79	8.833
7.13	99.87	7.304
7.14	99.94	6.542
7.15	100.01	6.048
7.15	100.09	5.696
7.16	100.16	5.382
7.17	100.23	5.109
7.17	100.30	4.856
7.18	100.38	4.658
7.19	100.45	4.418
7.19	100.52	4.226
7.20	100.59	4.111
7.21	100.66	3.942
7.21	100.73	3.760
7.22	100.80	3.626
7.23	100.87	3.540
7.23	100.94	3.409
7.24	101.00	3.323
7.25	101.07	3.214
7.25	101.14	3.106
7.26	101.21	3.040
7.27	101.28	3.004
7.27	101.35	2.958
7.28	101.42	2.851
7.29	101.48	2.764
7.29	101.55	2.745
7.30	101.62	2.687
7.31	101.69	2.641
7.31	101.75	2.616
7.32	101.82	2.581
7.33	101.89	2.553
7.33	101.96	2.535
7.34	102.02	2.508
7.35	102.09	2.488
7.35	102.16	2.458
7.36	102.23	2.427
7.37	102.29	2.409
7.37	102.36	2.393
7.38	102.43	2.377
7.39	102.49	2.362
7.39	102.56	2.353
7.40	102.63	2.350
7.41	102.69	2.345
7.41	102.76	2.337
7.42	102.83	2.321
7.43	102.90	2.311
7.43	102.96	2.306
7.44	103.03	2.300
7.45	103.10	2.294
7.45	103.16	2.290
7.46	103.23	2.283
7.47	103.30	2.279
7.47	103.36	2.275
7.48	103.43	2.269
7.49	103.50	2.266
7.49	103.56	2.260
7.50	103.63	2.254
7.51	103.70	2.250
7.51	103.76	2.247
7.52	103.83	2.245
7.53	103.90	2.240
7.53	103.96	2.236
7.54	104.03	2.234
7.55	104.10	2.231
7.55	104.17	2.228
7.56	104.23	2.225
7.57	104.30	2.223
7.57	104.37	2.220
7.58	104.43	2.217
7.59	104.50	2.213
7.59	104.56	2.208
7.60	104.63	2.205
7.61	104.70	2.204
7.61	104.77	2.202
7.62	104.83	2.199
7.63	104.90	2.197
7.63	104.97	2.194
7.64	105.03	2.190
7.65	105.10	2.188
7.65	105.17	2.186
7.66	105.23	2.184
7.67	105.30	2.182
7.67	105.37	2.180
7.68	105.43	2.178
7.69	105.50	2.176
7.69	105.57	2.173
7.70	105.63	2.172
7.71	105.70	2.171
7.71	105.77	2.170
7.72	105.83	2.168
7.73	105.90	2.165
7.73	105.97	2.163
7.74	106.03	2.161
7.75	106.10	2.159
7.75	106.17	2.157
7.76	106.23	2.157
7.77	106.30	2.157
7.77	106.37	2.155
7.78	106.43	2.154
7.79	106.50	2.151
7.79	106.57	2.150
7.80	106.63	2.150
7.81	106.70	2.149
7.81	106.77	2.148
7.82	106.83	2.149
7.83	106.90	2.148
7.83	106.97	2.147
7.84	107.03	2.146
7.85	107.10	2.143
7.85	107.17	2.143
7.86	107.23	2.143
7.87	107.30	2.142
7.87	107.37	2.142
7.88	107.43	2.142
7.89	107.50	2.141
7.89	107.57	2.140
7.90	107.63	2.140
7.91	107.70	2.140
7.91	107.77	2.139
7.92	107.84	2.139
7.93	107.90	2.140
7.93	107.97	2.140
7.94	108.04	2.139
7.95	108.10	2.138
7.95	108.17	2.138
7.96	108.24	2.138
7.97	108.30	2.138
7.97	108.37	2.138
7.98	108.43	2.138
7.99	108.50	2.138
7.99	108.57	2.137
8.00	108.64	2.137
8.01	108.70	2.136
8.01	108.77	2.134
8.02	108.84	2.134
8.03	108.90	2.133
8.03	108.97	2.132
8.04	109.04	2.131
8.05	109.10	2.131
8.05	109.17	2.130
8.06	109.24	2.131
8.07	109.30	2.131
8.07	109.37	2.131
8.08	109.44	2.131
8.09	109.50	2.132
8.09	109.57	2.132
8.10	109.64	2.132
8.11	109.70	2.133
8.11	109.77	2.133
8.12	109.84	2.131
8.13	109.90	2.131
8.13	109.97	2.132
8.14	110.04	2.131
8.15	110.10	2.130
8.15	110.17	2.131
8.16	110.24	2.130
8.17	110.30	2.130
8.17	110.37	2.131
8.18	110.44	2.131
8.19	110.50	2.132
8.19	110.57	2.131
8.20	110.64	2.131
8.21	110.70	2.132
8.21	110.77	2.132
8.22	110.84	2.132
8.23	110.90	2.132
8.23	110.97	2.132
8.24	111.04	2.132
8.25	111.10	2.132
8.25	111.17	2.133
8.26	111.24	2.133
8.27	111.30	2.134
8.27	111.37	2.135
8.28	111.44	2.135
8.29	111.50	2.133
8.29	111.57	2.133
8.30	111.64	2.133
8.31	111.70	2.134
8.31	111.77	2.135
8.32	111.84	2.135
8.33	111.90	2.134
8.33	111.97	2.132
8.34	112.04	2.132
8.35	112.10	2.133
8.35	112.17	2.133
8.36	112.24	2.133
8.37	112.30	2.136
8.37	112.37	2.137
8.38	112.44	2.138
8.39	112.50	2.138
8.39	112.57	2.136
8.40	112.64	2.137
8.41	112.70	2.138
8.41	112.77	2.140
8.42	112.84	2.141
8.43	112.91	2.141
8.43	112.97	2.142
8.44	113.04	2.143
8.45	113.11	2.143
8.45	113.17	2.143
8.46	113.24	2.142
8.47	113.31	2.142
8.47	113.37	2.144
8.48	113.44	2.144
8.49	113.50	2.143
8.49	113.57	2.143
8.50	113.64	2.144
8.51	113.70	2.145
8.51	113.77	2.146
8.52	113.84	2.146
8.53	113.90	2.146
8.53	113.97	2.147
8.54	114.04	2.147
8.55	114.11	2.148
8.55	114.17	2.148
8.56	114.24	2.148
8.57	114.31	2.149
8.57	114.37	2.149
8.58	114.44	2.148
8.59	114.51	2.148
8.59	114.57	2.148
8.60	114.64	2.150
8.61	114.71	2.150
8.61	114.77	2.149
8.62	114.84	2.149
8.63	114.91	2.149
8.63	114.97	2.150
8.64	115.04	2.151
8.65	115.11	2.153
8.65	115.17	2.153
8.66	115.24	2.152
8.67	115.30	2.152
8.67	115.37	2.153
8.68	115.44	2.154
8.69	115.50	2.156
8.69	115.57	2.156
8.70	115.64	2.157
8.71	115.70	2.158
8.71	115.77	2.158
8.72	115.84	2.157
8.73	115.91	2.157
8.73	115.97	2.158
8.74	116.04	2.160
8.75	116.11	2.159
8.75	116.17	2.160
8.76	116.24	2.159
8.77	116.31	2.159
8.77	116.37	2.159
8.78	116.44	2.160
8.79	116.51	2.161
8.79	116.57	2.162
8.80	116.64	2.162
8.81	116.71	2.162
8.81	116.77	2.163
8.82	116.84	2.164
8.83	116.91	2.164
8.83	116.97	2.164
8.84	117.04	2.165
8.85	117.11	2.166
8.85	117.17	2.168
8.86	117.24	2.167
8.87	117.31	2.167
8.87	117.37	2.168
8.88	117.44	2.169
8.89	117.51	2.169
8.89	117.57	2.169
8.90	117.64	2.170
8.91	117.71	2.171
8.91	117.77	2.173
8.92	117.84	2.173
8.93	117.91	2.173
8.93	117.97	2.173
8.94	118.04	2.174
8.95	118.11	2.175
8.95	118.17	2.175
8.96	118.24	2.176
8.97	118.31	2.176
8.97	118.37	2.177
8.98	118.44	2.177
8.99	118.51	2.178
8.99	118.57	2.179
9.00	118.64	2.180
9.00	118.66	2.180

[step]
Ramp 10.00 °C/min to 30.00 °C
Time	Temperature	Heat Flow (Normalized)
min	°C	W/g
10.00	120.09	-1.426
10.01	120.09	-1.428
10.02	120.09	-1.430
10.02	120.09	-1.432
10.03	120.09	-1.434
10.04	120.09	-1.436
10.04	120.08	-1.437
10.05	120.08	-1.434
10.06	120.08	-1.401
10.06	120.07	-1.287
10.07	120.06	-1.080
10.08	120.04	-0.857
10.08	120.03	-0.635
10.09	120.01	-0.484
10.10	119.99	-0.358
10.10	119.96	-0.276
10.11	119.93	-0.205
10.12	119.90	-0.218
10.12	119.87	-0.279
10.13	119.83	-0.351
10.14	119.79	-0.383
10.14	119.75	-0.492
10.15	119.71	-0.847
10.16	119.66	-1.196
10.16	119.61	-1.483
10.17	119.56	-1.814
10.18	119.51	-2.035
10.18	119.46	-2.198
10.19	119.41	-2.404
10.20	119.35	-2.613
10.20	119.30	-2.763
10.21	119.25	-2.909
10.22	119.19	-3.123
10.22	119.13	-3.267
10.23	119.08	-3.383
10.24	119.02	-3.477
10.24	118.96	-3.601
10.25	118.90	-3.608
10.26	118.84	-3.650
10.26	118.78	-3.723
10.27	118.72	-3.823
10.28	118.66	-3.941
10.28	118.60	-4.024
10.29	118.54	-4.075
10.30	118.48	-4.089
10.30	118.41	-4.154
10.31	118.35	-4.236
10.32	118.29	-4.268
10.32	118.23	-4.324
10.33	118.16	-4.395
10.34	118.10	-4.463
10.34	118.04	-4.495
10.35	117.98	-4.496
10.36	117.91	-4.524
10.36	117.85	-4.561
10.37	117.78	-4.579
10.38	117.72	-4.605
10.38	117.65	-4.632
10.39	117.59	-4.655
10.40	117.53	-4.662
10.40	117.46	-4.686
10.41	117.40	-4.728
10.42	117.33	-4.746
10.42	117.27	-4.761
10.43	117.20	-4.780
10.44	117.14	-4.788
10.44	117.07	-4.794
10.45	117.01	-4.809
10.46	116.94	-4.814
10.46	116.88	-4.824
10.47	116.81	-4.829
10.48	116.75	-4.835
10.48	116.68	-4.847
10.49	116.62	-4.854
10.50	116.55	-4.859
10.50	116.49	-4.864
10.51	116.42	-4.871
10.52	116.36	-4.890
10.52	116.29	-4.899
10.53	116.23	-4.903
10.54	116.16	-4.907
10.54	116.10	-4.912
10.55	116.03	-4.915
10.56	115.96	-4.919
10.56	115.90	-4.925
10.57	115.83	-4.930
10.58	115.77	-4.935
10.58	115.70	-4.939
10.59	115.64	-4.942
10.60	115.57	-4.947
10.60	115.51	-4.951
10.61	115.44	-4.955
10.62	115.37	-4.959
10.62	115.31	-4.963
10.63	115.24	-4.976
10.64	115.18	-4.988
10.64	115.11	-4.991
10.65	115.05	-4.994
10.66	114.98	-4.998
10.66	114.91	-5.002
10.67	114.85	-5.006
10.68	114.78	-5.011
10.68	114.72	-5.015
10.69	114.65	-5.017
10.70	114.58	-5.019
10.70	114.52	-5.024
10.71	114.45	-5.027
10.72	114.39	-5.030
10.72	114.32	-5.034
10.73	114.25	-5.037
10.74	114.19	-5.041
10.74	114.12	-5.044
10.75	114.06	-5.047
10.76	113.99	-5.052
10.76	113.93	-5.055
10.77	113.86	-5.056
10.78	113.79	-5.059
10.78	113.73	-5.061
10.79	113.66	-5.064
10.80	113.59	-5.070
10.80	113.53	-5.072
10.81	113.46	-5.073
10.82	113.40	-5.075
10.82	113.33	-5.080
10.83	113.26	-5.087
10.84	113.20	-5.090
10.84	113.13	-5.092
10.85	113.07	-5.094
10.86	113.00	-5.097
10.86	112.93	-5.098
10.87	112.87	-5.099
10.88	112.80	-5.101
10.88	112.73	-5.105
10.89	112.67	-5.108
10.90	112.60	-5.109
10.90	112.54	-5.110
10.91	112.47	-5.111
10.92	112.40	-5.112
10.92	112.34	-5.115
10.93	112.27	-5.118
10.94	112.20	-5.119
10.94	112.14	-5.121
10.95	112.07	-5.123
10.96	112.01	-5.124
10.96	111.94	-5.125
10.97	111.87	-5.125
10.98	111.81	-5.126
10.98	111.74	-5.128
10.99	111.67	-5.130
11.00	111.61	-5.131
11.00	111.54	-5.131
11.01	111.48	-5.133
11.02	111.41	-5.135
11.02	111.34	-5.137
11.03	111.28	-5.138
11.04	111.21	-5.138
11.04	111.14	-5.138
11.05	111.08	-5.140
11.06	111.01	-5.140
11.06	110.95	-5.140
11.07	110.88	-5.140
11.08	110.81	-5.141
11.08	110.75	-5.141
11.09	110.68	-5.142
11.10	110.61	-5.146
11.10	110.55	-5.147
11.11	110.48	-5.146
11.12	110.41	-5.147
11.12	110.35	-5.147
11.13	110.28	-5.147
11.14	110.21	-5.148
11.14	110.15	-5.150
11.15	110.08	-5.151
11.16	110.01	-5.152
11.16	109.95	-5.155
11.17	109.88	-5.156
11.18	109.82	-5.155
11.18	109.75	-5.154
11.19	109.68	-5.153
11.20	109.62	-5.154
11.20	109.55	-5.155
11.21	109.48	-5.156
11.22	109.42	-5.156
11.22	109.35	-5.156
11.23	109.29	-5.156
11.24	109.22	-5.156
11.24	109.15	-5.157
11.25	109.09	-5.157
11.26	109.02	-5.156
11.26	108.95	-5.156
11.27	108.89	-5.156
11.28	108.82	-5.156
11.28	108.75	-5.155
11.29	108.69	-5.155
11.30	108.62	-5.154
11.30	108.55	-5.153
11.31	108.49	-5.153
11.32	108.42	-5.153
11.32	108.36	-5.152
11.33	108.29	-5.152
11.34	108.22	-5.153
11.34	108.16	-5.154
11.35	108.09	-5.153
11.36	108.02	-5.153
11.36	107.96	-5.151
11.37	107.89	-5.150
11.38	107.82	-5.150
11.38	107.76	-5.151
11.39	107.69	-5.150
11.40	107.62	-5.148
11.40	107.56	-5.147
11.41	107.49	-5.147
11.42	107.42	-5.147
11.42	107.36	-5.147
11.43	107.29	-5.147
11.44	107.22	-5.146
11.44	107.16	-5.146
11.45	107.09	-5.147
11.46	107.03	-5.147
11.46	106.96	-5.146
11.47	106.89	-5.145
11.48	106.82	-5.144
11.48	106.76	-5.144
11.49	106.69	-5.144
11.50	106.63	-5.144
11.50	106.56	-5.142
11.51	106.49	-5.140
11.52	106.43	-5.139
11.52	106.36	-5.139
11.53	106.29	-5.138
11.54	106.23	-5.139
11.54	106.16	-5.138
11.55	106.09	-5.138
11.56	106.03	-5.135
11.56	105.96	-5.133
11.57	105.89	-5.133
11.58	105.83	-5.132
11.58	105.76	-5.131
11.59	105.69	-5.132
11.60	105.63	-5.132
11.60	105.56	-5.130
11.61	105.49	-5.128
11.62	105.43	-5.127
11.62	105.36	-5.127
11.63	105.29	-5.127
11.64	105.23	-5.128
11.64	105.16	-5.127
11.65	105.10	-5.125
11.66	105.03	-5.124
11.66	104.96	-5.124
11.67	104.90	-5.125
11.68	104.83	-5.124
11.68	104.76	-5.122
11.69	104.70	-5.120
11.70	104.63	-5.120
11.70	104.56	-5.120
11.71	104.50	-5.119
11.72	104.43	-5.118
11.72	104.36	-5.118
11.73	104.30	-5.117
11.74	104.23	-5.116
11.74	104.16	-5.115
11.75	104.10	-5.113
11.76	104.03	-5.113
11.76	103.96	-5.112
11.77	103.90	-5.111
11.78	103.83	-5.110
11.78	103.76	-5.109
11.79	103.70	-5.109
11.80	103.63	-5.108
11.80	103.57	-5.106
11.81	103.50	-5.105
11.82	103.43	-5.105
11.82	103.37	-5.104
11.83	103.30	-5.104
11.84	103.23	-5.102
11.84	103.17	-5.101
11.85	103.10	-5.101
11.86	103.03	-5.102
11.86	102.97	-5.100
11.87	102.90	-5.095
11.88	102.83	-5.093
11.88	102.77	-5.092
11.89	102.70	-5.091
11.90	102.63	-5.091
11.90	102.57	-5.090
11.91	102.50	-5.089
11.92	102.43	-5.087
11.92	102.37	-5.086
11.93	102.30	-5.085
11.94	102.23	-5.084
11.94	102.17	-5.083
11.95	102.10	-5.083
11.96	102.03	-5.083
11.96	101.97	-5.082
11.97	101.90	-5.082
11.98	101.83	-5.082
11.98	101.77	-5.080
11.99	101.70	-5.079
12.00	101.63	-5.079
12.00	101.57	-5.078
12.01	101.50	-5.077
12.02	101.43	-5.075
12.02	101.37	-5.074
12.03	101.30	-5.074
12.04	101.24	-5.075
12.04	101.17	-5.075
12.05	101.10	-5.066
12.06	101.04	-5.063
12.06	100.97	-5.063
12.07	100.90	-5.064
12.08	100.84	-5.064
12.08	100.77	-5.062
12.09	100.70	-5.061
12.10	100.64	-5.061
12.10	100.57	-5.061
12.11	100.50	-5.061
12.12	100.44	-5.060
12.12	100.37	-5.060
12.13	100.30	-5.058
12.14	100.24	-5.057
12.14	100.17	-5.058
12.15	100.10	-5.058
12.16	100.04	-5.055
12.16	99.97	-5.054
12.17	99.90	-5.055
12.18	99.84	-5.054
12.18	99.77	-5.054
12.19	99.70	-5.052
12.20	99.64	-5.050
12.20	99.57	-5.049
12.21	99.50	-5.049
12.22	99.44	-5.049
12.22	99.37	-5.049
12.23	99.30	-5.049
12.24	99.24	-5.049
12.24	99.17	-5.049
12.25	99.10	-5.049
12.26	99.04	-5.047
12.26	98.97	-5.047
12.27	98.90	-5.046
12.28	98.84	-5.046
12.28	98.77	-5.044
12.29	98.70	-5.043
12.30	98.64	-5.043
12.30	98.57	-5.042
12.31	98.50	-5.040
12.32	98.44	-5.039
12.32	98.37	-5.038
12.33	98.30	-5.037
12.34	98.24	-5.036
12.34	98.17	-5.035
12.35	98.11	-5.035
12.36	98.04	-5.036
12.36	97.97	-5.035
12.37	97.91	-5.032
12.38	97.84	-5.030
12.38	97.77	-5.029
12.39	97.71	-5.030
12.40	97.64	-5.028
12.40	97.57	-5.027
12.41	97.51	-5.027
12.42	97.44	-5.025
12.42	97.37	-5.024
12.43	97.31	-5.022
12.44	97.24	-5.022
12.44	97.17	-5.021
12.45	97.11	-5.020
12.46	97.04	-5.020
12.46	96.97	-5.020
12.47	96.91	-5.020
12.48	96.84	-5.020
12.48	96.77	-5.019
12.49	96.71	-5.018
12.50	96.64	-5.016
12.50	96.57	-5.014
12.51	96.51	-5.013
12.52	96.44	-5.011
12.52	96.37	-5.009
12.53	96.31	-5.009
12.54	96.24	-5.009
12.54	96.17	-5.008
12.55	96.11	-5.007
12.56	96.04	-5.006
12.56	95.98	-5.005
12.57	95.91	-5.005
12.58	95.84	-5.003
12.58	95.77	-5.002
12.59	95.71	-5.002
12.60	95.64	-5.001
12.60	95.58	-5.000
12.61	95.51	-4.998
12.62	95.44	-4.998
12.62	95.38	-4.998
12.63	95.31	-4.995
12.64	95.24	-4.994
12.64	95.18	-4.994
12.65	95.11	-4.994
12.66	95.04	-4.991
12.66	94.98	-4.991
12.67	94.91	-4.990
12.68	94.84	-4.990
12.68	94.78	-4.990
12.69	94.71	-4.989
12.70	94.64	-4.988
12.70	94.58	-4.986
12.71	94.51	-4.984
12.72	94.44	-4.983
12.72	94.38	-4.983
12.73	94.31	-4.983
12.74	94.24	-4.981
12.74	94.18	-4.980
12.75	94.11	-4.979
12.76	94.04	-4.978
12.76	93.98	-4.978
12.77	93.91	-4.979
12.78	93.84	-4.978
12.78	93.78	-4.974
12.79	93.71	-4.973
12.80	93.64	-4.973
12.80	93.58	-4.972
12.81	93.51	-4.973
12.82	93.44	-4.973
12.82	93.38	-4.972
12.83	93.31	-4.972
12.84	93.24	-4.971
12.84	93.18	-4.970
12.85	93.11	-4.969
12.86	93.04	-4.968
12.86	92.98	-4.967
12.87	92.91	-4.966
12.88	92.84	-4.966
12.88	92.78	-4.965
12.89	92.71	-4.963
12.90	92.64	-4.962
12.90	92.58	-4.962
12.91	92.51	-4.961
12.92	92.44	-4.959
12.92	92.38	-4.958
12.93	92.31	-4.958
12.94	92.24	-4.957
12.94	92.18	-4.955
12.95	92.11	-4.955
12.96	92.04	-4.955
12.96	91.98	-4.954
12.97	91.91	-4.951
12.98	91.84	-4.950
12.98	91.78	-4.950
12.99	91.71	-4.949
13.00	91.64	-4.949
13.00	91.58	-4.949
13.01	91.51	-4.947
13.02	91.44	-4.945
13.02	91.38	-4.945
13.03	91.31	-4.945
13.04	91.25	-4.944
13.04	91.18	-4.941
13.05	91.11	-4.940
13.06	91.05	-4.939
13.06	90.98	-4.937
13.07	90.91	-4.936
13.08	90.85	-4.936
13.08	90.78	-4.935
13.09	90.71	-4.932
13.10	90.65	-4.932
13.10	90.58	-4.932
13.11	90.51	-4.931
13.12	90.45	-4.930
13.12	90.38	-4.929
13.13	90.31	-4.928
13.14	90.25	-4.927
13.14	90.18	-4.927
13.15	90.11	-4.929
13.16	90.05	-4.927
13.16	89.98	-4.922
13.17	89.91	-4.921
13.18	89.85	-4.920
13.18	89.78	-4.918
13.19	89.71	-4.917
13.20	89.65	-4.917
13.20	89.58	-4.916
13.21	89.51	-4.914
13.22	89.45	-4.913
13.22	89.38	-4.913
13.23	89.31	-4.911
13.24	89.25	-4.908
13.24	89.18	-4.906
13.25	89.11	-4.907
13.26	89.05	-4.907
13.26	88.98	-4.905
13.27	88.91	-4.905
13.28	88.85	-4.905
13.28	88.78	-4.905
13.29	88.71	-4.905
13.30	88.65	-4.903
13.30	88.58	-4.901
13.31	88.51	-4.900
13.32	88.45	-4.897
13.32	88.38	-4.897
13.33	88.31	-4.898
13.34	88.25	-4.896
13.34	88.18	-4.895
13.35	88.12	-4.894
13.36	88.05	-4.892
13.36	87.98	-4.890
13.37	87.91	-4.889
13.38	87.85	-4.890
13.38	87.78	-4.890
13.39	87.72	-4.884
13.40	87.65	-4.881
13.40	87.58	-4.882
13.41	87.52	-4.882
13.42	87.45	-4.881
13.42	87.38	-4.881
13.43	87.32	-4.880
13.44	87.25	-4.878
13.44	87.18	-4.878
13.45	87.12	-4.878
13.46	87.05	-4.877
13.46	86.98	-4.875
13.47	86.92	-4.874
13.48	86.85	-4.873
13.48	86.78	-4.872
13.49	86.72	-4.872
13.50	86.65	-4.871
13.50	86.58	-4.870
13.51	86.52	-4.868
13.52	86.45	-4.866
13.52	86.38	-4.867
13.53	86.32	-4.868
13.54	86.25	-4.885
13.54	86.18	-4.929
13.55	86.12	-4.931
13.56	86.05	-4.931
13.56	85.98	-4.931
13.57	85.92	-4.931
13.58	85.85	-4.929
13.58	85.78	-4.928
13.59	85.72	-4.927
13.60	85.65	-4.926
13.60	85.59	-4.926
13.61	85.52	-4.925
13.62	85.45	-4.924
13.62	85.39	-4.923
13.63	85.32	-4.921
13.64	85.25	-4.921
13.64	85.18	-4.921
13.65	85.12	-4.920
13.66	85.05	-4.919
13.66	84.98	-4.919
13.67	84.92	-4.919
13.68	84.85	-4.917
13.68	84.78	-4.917
13.69	84.72	-4.919
13.70	84.65	-4.919
13.70	84.59	-4.918
13.71	84.52	-4.916
13.72	84.45	-4.915
13.72	84.39	-4.915
13.73	84.32	-4.914
13.74	84.25	-4.914
13.74	84.19	-4.912
13.75	84.12	-4.911
13.76	84.05	-4.911
13.76	83.99	-4.910
13.77	83.92	-4.910
13.78	83.85	-4.910
13.78	83.79	-4.910
13.79	83.72	-4.910
13.80	83.65	-4.910
13.80	83.59	-4.909
13.81	83.52	-4.909
13.82	83.45	-4.910
13.82	83.39	-4.942
13.83	83.32	-17.223
13.84	83.28	-78.778
13.84	83.32	-103.777
13.85	83.27	-41.470
13.86	83.20	-18.954
13.86	83.13	-14.432
13.87	83.05	-13.007
13.88	82.98	-12.621
13.88	82.90	-10.355
13.89	82.83	-8.922
13.90	82.76	-8.366
13.90	82.68	-8.099
13.91	82.61	-8.072
13.92	82.54	-8.159
13.92	82.46	-7.933
13.93	82.39	-7.344
13.94	82.32	-7.077
13.94	82.25	-6.861
13.95	82.18	-6.751
13.96	82.11	-6.763
13.96	82.04	-6.931
13.97	81.97	-6.790
13.98	81.90	-6.461
13.98	81.83	-6.280
13.99	81.76	-6.157
14.00	81.69	-6.115
14.00	81.62	-6.023
[...]
21.69	45.48	2.263
21.70	45.55	2.263
21.70	45.62	2.263
21.71	45.68	2.263
21.72	45.75	2.260
21.72	45.82	2.257
21.73	45.88	2.259
21.74	45.95	2.260
21.74	46.02	2.259
21.75	46.09	2.259
21.76	46.15	2.258
21.76	46.22	2.258
21.77	46.29	2.259
21.78	46.35	2.259
21.78	46.42	2.259
21.79	46.49	2.260
21.80	46.55	2.259
21.80	46.62	2.262
21.81	46.69	2.262
21.82	46.75	2.261
21.82	46.82	2.259
21.83	46.89	2.258
21.84	46.95	2.259
21.84	47.02	2.259
21.85	47.08	2.259
21.86	47.15	2.259
21.86	47.22	2.258
21.87	47.29	2.258
21.88	47.35	2.257
21.88	47.42	2.256
21.89	47.49	2.256
21.90	47.55	2.254
21.90	47.62	2.255
21.91	47.68	2.255
21.92	47.75	2.255
21.92	47.82	2.255
21.93	47.89	2.256
21.94	47.95	2.256
21.94	48.02	2.256
21.95	48.09	2.257
21.96	48.15	2.257
21.96	48.22	2.257
21.97	48.28	2.258
21.98	48.35	2.258
21.98	48.42	2.258
21.99	48.48	2.258
22.00	48.55	2.254
22.00	48.62	2.252
22.01	48.68	2.252
22.02	48.75	2.251
22.02	48.82	2.250
22.03	48.89	2.250
22.04	48.95	2.250
22.04	49.02	2.250
22.05	49.09	2.249
22.06	49.15	2.249
22.06	49.22	2.249
22.07	49.29	2.249
22.08	49.35	2.249
22.08	49.42	2.249
22.09	49.49	2.249
22.10	49.55	2.249
22.10	49.62	2.248
22.11	49.69	2.247
22.12	49.75	2.247
22.12	49.82	2.248
22.13	49.89	2.248
22.14	49.95	2.248
22.14	50.02	2.247
22.15	50.09	2.247
22.16	50.15	2.247
22.16	50.22	2.246
22.17	50.29	2.246
22.18	50.35	2.245
22.18	50.42	2.244
22.19	50.49	2.243
22.20	50.55	2.243
22.20	50.62	2.242
22.21	50.69	2.243
22.22	50.75	2.243
22.22	50.82	2.242
22.23	50.89	2.241
22.24	50.95	2.239
22.24	51.02	2.239
22.25	51.09	2.239
22.26	51.15	2.239
22.26	51.22	2.238
22.27	51.29	2.237
22.28	51.35	2.237
22.28	51.42	2.237
22.29	51.49	2.237
22.30	51.55	2.236
22.30	51.62	2.235
22.31	51.69	2.235
22.32	51.75	2.236
22.32	51.82	2.234
22.33	51.89	2.234
22.34	51.95	2.234
22.34	52.02	2.234
22.35	52.09	2.233
22.36	52.15	2.233
22.36	52.22	2.233
22.37	52.29	2.232
22.38	52.35	2.231
22.38	52.42	2.232
22.39	52.49	2.231
22.40	52.55	2.230
22.40	52.62	2.231
22.41	52.69	2.231
22.42	52.75	2.231
22.42	52.82	2.227
22.43	52.89	2.224
22.44	52.95	2.226
22.44	53.02	2.226
22.45	53.09	2.225
22.46	53.15	2.224
22.46	53.22	2.224
22.47	53.29	2.224
22.48	53.35	2.226
22.48	53.42	2.228
22.49	53.49	2.226
22.50	53.55	2.226
22.50	53.62	2.226
22.51	53.69	2.227
22.52	53.76	2.226
22.52	53.82	2.225
22.53	53.89	2.226
22.54	53.96	2.226
22.54	54.02	2.224
22.55	54.09	2.222
22.56	54.16	2.222
22.56	54.22	2.223
22.57	54.29	2.223
22.58	54.35	2.223
22.58	54.42	2.223
22.59	54.49	2.223
22.60	54.56	2.222
22.60	54.62	2.222
22.61	54.69	2.223
22.62	54.76	2.223
22.62	54.82	2.223
22.63	54.89	2.223
22.64	54.96	2.222
22.64	55.02	2.222
22.65	55.09	2.221
22.66	55.16	2.220
22.66	55.22	2.219
22.67	55.29	2.218
22.68	55.36	2.218
22.68	55.42	2.217
22.69	55.49	2.216
22.70	55.56	2.216
22.70	55.62	2.215
22.71	55.69	2.215
22.72	55.76	2.213
22.72	55.82	2.213
22.73	55.89	2.214
22.74	55.96	2.213
22.74	56.02	2.213
22.75	56.09	2.212
22.76	56.16	2.211
22.76	56.22	2.211
22.77	56.29	2.212
22.78	56.36	2.213
22.78	56.42	2.211
22.79	56.49	2.209
22.80	56.56	2.209
22.80	56.62	2.209
22.81	56.69	2.209
22.82	56.76	2.208
22.82	56.82	2.207
22.83	56.89	2.206
22.84	56.96	2.206
22.84	57.02	2.207
22.85	57.09	2.207
22.86	57.16	2.206
22.86	57.22	2.205
22.87	57.29	2.205
22.88	57.36	2.206
22.88	57.43	2.204
22.89	57.49	2.203
22.90	57.56	2.204
22.90	57.62	2.205
22.91	57.69	2.203
22.92	57.76	2.202
22.92	57.82	2.201
22.93	57.89	2.201
22.94	57.96	2.201
22.94	58.02	2.201
22.95	58.09	2.200
22.96	58.16	2.199
22.96	58.22	2.198
22.97	58.29	2.199
22.98	58.36	2.199
22.98	58.42	2.198
22.99	58.49	2.198
23.00	58.56	2.198
23.00	58.63	2.198
23.01	58.69	2.198
23.02	58.76	2.197
23.02	58.83	2.196
23.03	58.89	2.196
23.04	58.96	2.195
23.04	59.03	2.194
23.05	59.09	2.195
23.06	59.16	2.196
23.06	59.23	2.197
23.07	59.29	2.196
23.08	59.36	2.194
23.08	59.42	2.194
23.09	59.49	2.194
23.10	59.56	2.194
23.10	59.63	2.193
23.11	59.69	2.192
23.12	59.76	2.192
23.12	59.83	2.192
23.13	59.89	2.192
23.14	59.96	2.192
23.14	60.03	2.192
23.15	60.09	2.192
23.16	60.16	2.192
23.16	60.23	2.192
23.17	60.29	2.192
23.18	60.36	2.192
23.18	60.43	2.193
23.19	60.49	2.193
23.20	60.56	2.192
23.20	60.63	2.191
23.21	60.69	2.192
23.22	60.76	2.192
23.22	60.83	2.191
23.23	60.89	2.191
23.24	60.96	2.192
23.24	61.03	2.191
23.25	61.09	2.190
23.26	61.16	2.191
23.26	61.23	2.191
23.27	61.29	2.191
23.28	61.36	2.191
23.28	61.43	2.192
23.29	61.49	2.193
23.30	61.56	2.194
23.30	61.63	2.194
23.31	61.69	2.193
23.32	61.76	2.193
23.32	61.83	2.192
23.33	61.89	2.191
23.34	61.96	2.190
23.34	62.03	2.191
23.35	62.09	2.192
23.36	62.16	2.191
23.36	62.23	2.190
23.37	62.29	2.189
23.38	62.36	2.188
23.38	62.43	2.188
23.39	62.50	2.189
23.40	62.56	2.192
23.40	62.63	2.193
23.41	62.70	2.192
23.42	62.76	2.192
23.42	62.83	2.192
23.43	62.90	2.192
23.44	62.96	2.192
23.44	63.03	2.191
23.45	63.10	2.191
23.46	63.16	2.192
23.46	63.23	2.192
23.47	63.30	2.192
23.48	63.36	2.191
23.48	63.43	2.192
23.49	63.50	2.192
23.50	63.56	2.193
23.50	63.63	2.192
23.51	63.70	2.191
23.52	63.76	2.191
23.52	63.83	2.191
23.53	63.90	2.191
23.54	63.96	2.190
23.54	64.03	2.190
23.55	64.10	2.190
23.56	64.16	2.190
23.56	64.23	2.189
23.57	64.30	2.189
23.58	64.36	2.188
23.58	64.43	2.189
23.59	64.50	2.190
23.60	64.56	2.190
23.60	64.63	2.190
23.61	64.70	2.190
23.62	64.76	2.189
23.62	64.83	2.188
23.63	64.90	2.186
23.64	64.96	2.185
23.64	65.03	2.185
23.65	65.10	2.186
23.66	65.16	2.186
23.66	65.23	2.186
23.67	65.30	2.185
23.68	65.36	2.185
23.68	65.43	2.185
23.69	65.50	2.184
23.70	65.56	2.184
23.70	65.63	2.185
23.71	65.70	2.185
23.72	65.76	2.185
23.72	65.83	2.183
23.73	65.90	2.183
23.74	65.96	2.183
23.74	66.03	2.184
23.75	66.10	2.184
23.76	66.16	2.184
23.76	66.23	2.184
23.77	66.30	2.184
23.78	66.37	2.183
23.78	66.43	2.182
23.79	66.50	2.183
23.80	66.57	2.183
23.80	66.63	2.182
23.81	66.70	2.181
23.82	66.76	2.182
23.82	66.83	2.181
23.83	66.90	2.181
23.84	66.96	2.181
23.84	67.03	2.181
23.85	67.10	2.180
23.86	67.17	2.179
23.86	67.23	2.179
23.87	67.30	2.179
23.88	67.37	2.179
23.88	67.43	2.178
23.89	67.50	2.176
23.90	67.57	2.177
23.90	67.63	2.177
23.91	67.70	2.177
23.92	67.76	2.176
23.92	67.83	2.176
23.93	67.90	2.176
23.94	67.97	2.176
23.94	68.03	2.176
23.95	68.10	2.176
23.96	68.17	2.177
23.96	68.23	2.178
23.97	68.30	2.178
23.98	68.37	2.178
23.98	68.43	2.178
23.99	68.50	2.177
24.00	68.57	2.177
24.00	68.63	2.178
24.01	68.70	2.178
24.02	68.77	2.177
24.02	68.83	2.176
24.03	68.90	2.174
24.04	68.97	2.173
24.04	69.03	2.174
24.05	69.10	2.175
24.06	69.17	2.174
24.06	69.23	2.172
24.07	69.30	2.171
24.08	69.37	2.174
24.08	69.43	2.175
24.09	69.50	2.175
24.10	69.57	2.175
24.10	69.63	2.174
24.11	69.70	2.173
24.12	69.77	2.174
24.12	69.83	2.175
24.13	69.90	2.175
24.14	69.97	2.174
24.14	70.03	2.173
24.15	70.10	2.172
24.16	70.17	2.173
24.16	70.23	2.174
24.17	70.30	2.173
24.18	70.37	2.174
24.18	70.43	2.175
24.19	70.50	2.175
24.20	70.57	2.175
24.20	70.64	2.174
24.21	70.70	2.174
24.22	70.77	2.174
24.22	70.83	2.173
24.23	70.90	2.173
24.24	70.97	2.173
24.24	71.04	2.172
24.25	71.10	2.171
24.26	71.17	2.171
24.26	71.23	2.172
24.27	71.30	2.172
24.28	71.37	2.173
24.28	71.44	2.172
24.29	71.50	2.171
24.30	71.57	2.171
24.30	71.64	2.171
24.31	71.70	2.172
24.32	71.77	2.173
24.32	71.84	2.173
24.33	71.90	2.173
24.34	71.97	2.173
24.34	72.04	2.173
24.35	72.10	2.173
24.36	72.17	2.173
24.36	72.24	2.172
24.37	72.30	2.173
24.38	72.37	2.173
24.38	72.44	2.173
24.39	72.50	2.174
24.40	72.57	2.175
24.40	72.64	2.175
24.41	72.70	2.174
24.42	72.77	2.172
24.42	72.84	2.172
24.43	72.90	2.173
24.44	72.97	2.173
24.44	73.04	2.174
24.45	73.10	2.174
24.46	73.17	2.173
24.46	73.24	2.171
24.47	73.30	2.170
24.48	73.37	2.170
24.48	73.44	2.171
24.49	73.50	2.171
24.50	73.57	2.171
24.50	73.64	2.170
24.51	73.70	2.170
24.52	73.77	2.171
24.52	73.84	2.171
24.53	73.90	2.171
24.54	73.97	2.170
24.54	74.04	2.171
24.55	74.10	2.172
24.56	74.17	2.171
24.56	74.24	2.171
24.57	74.31	2.170
24.58	74.37	2.169
24.58	74.44	2.168
24.59	74.50	2.169
24.60	74.57	2.170
24.60	74.64	2.170
24.61	74.70	2.170
24.62	74.77	2.169
24.62	74.84	2.169
24.63	74.90	2.169
24.64	74.97	2.169
24.64	75.04	2.168
24.65	75.11	2.167
24.66	75.17	2.166
24.66	75.24	2.166
24.67	75.31	2.167
24.68	75.37	2.168
24.68	75.44	2.167
24.69	75.51	2.167
24.70	75.57	2.167
24.70	75.64	2.169
24.71	75.71	2.171
24.72	75.77	2.170
24.72	75.84	2.168
24.73	75.91	2.168
24.74	75.97	2.170
24.74	76.04	2.171
24.75	76.11	2.171
24.76	76.17	2.171
24.76	76.24	2.170
24.77	76.31	2.170
24.78	76.37	2.171
24.78	76.44	2.172
24.79	76.51	2.172
24.80	76.57	2.171
24.80	76.64	2.171
24.81	76.71	2.170
24.82	76.77	2.168
24.82	76.84	2.172
24.83	76.91	2.174
24.84	76.97	2.175
24.84	77.04	2.176
24.85	77.11	2.175
24.86	77.17	2.174
24.86	77.24	2.174
24.87	77.31	2.174
24.88	77.37	2.173
24.88	77.44	2.174
24.89	77.51	2.175
24.90	77.57	2.175
24.90	77.64	2.173
24.91	77.71	2.171
24.92	77.78	2.172
24.92	77.84	2.173
24.93	77.91	2.173
24.94	77.97	2.173
24.94	78.04	2.173
24.95	78.11	2.173
24.96	78.18	2.174
24.96	78.24	2.174
24.97	78.31	2.175
24.98	78.37	2.177
24.98	78.44	2.178
24.99	78.51	2.178
25.00	78.57	2.177
25.00	78.64	2.177
25.01	78.71	2.178
25.02	78.77	2.178
25.02	78.84	2.177
25.03	78.91	2.176
25.04	78.97	2.175
25.04	79.04	2.175
25.05	79.11	2.176
25.06	79.17	2.176
25.06	79.24	2.175
25.07	79.31	2.175
25.08	79.38	2.175
25.08	79.44	2.175
25.09	79.51	2.175
25.10	79.57	2.174
25.10	79.64	2.174
25.11	79.71	2.175
25.12	79.77	2.175
25.12	79.84	2.175
25.13	79.91	2.174
25.14	79.97	2.173
25.14	80.04	2.174
25.15	80.11	2.175
25.16	80.18	2.176
25.16	80.24	2.176
25.17	80.31	2.175
25.18	80.38	2.174
25.18	80.44	2.175
25.19	80.51	2.174
25.20	80.58	2.175
25.20	80.64	2.175
25.21	80.71	2.175
25.22	80.78	2.173
25.22	80.84	2.173
25.23	80.91	2.173
25.24	80.98	2.174
25.24	81.04	2.174
25.25	81.11	2.174
25.26	81.18	2.175
25.26	81.24	2.175
25.27	81.31	2.175
25.28	81.38	2.175
25.28	81.44	2.175
25.29	81.51	2.174
25.30	81.58	2.174
25.30	81.64	2.173
25.31	81.71	2.171
25.32	81.78	2.172
25.32	81.84	2.172
25.33	81.91	2.172
25.34	81.98	2.172
25.34	82.04	2.173
25.35	82.11	2.172
25.36	82.18	2.171
25.36	82.24	2.171
25.37	82.31	2.171
25.38	82.38	2.170
25.38	82.44	2.169
25.39	82.51	2.169
25.40	82.58	2.168
25.40	82.64	2.167
25.41	82.71	2.167
25.42	82.78	2.167
25.42	82.84	2.167
25.43	82.91	2.167
25.44	82.98	2.167
25.44	83.04	2.166
25.45	83.11	2.165
25.46	83.18	2.164
25.46	83.25	2.164
25.47	83.31	2.165
25.48	83.38	2.165
25.48	83.45	2.164
25.49	83.51	2.164
25.50	83.58	2.164
25.50	83.64	2.164
25.51	83.71	2.163
25.52	83.78	2.163
25.52	83.85	2.164
25.53	83.91	2.165
25.54	83.98	2.164
25.54	84.05	2.163
25.55	84.11	2.162
25.56	84.18	2.161
25.56	84.24	2.161
25.57	84.31	2.161
25.58	84.38	2.161
25.58	84.45	2.161
25.59	84.51	2.161
25.60	84.58	2.160
25.60	84.65	2.159
25.61	84.71	2.159
25.62	84.78	2.159
25.62	84.85	2.160
25.63	84.91	2.160
25.64	84.98	2.159
25.64	85.05	2.159
25.65	85.11	2.160
25.66	85.18	2.160
25.66	85.25	2.158
25.67	85.31	2.157
25.68	85.38	2.157
25.68	85.45	2.157
25.69	85.51	2.157
25.70	85.58	2.158
25.70	85.65	2.157
25.71	85.71	2.156
25.72	85.78	2.156
25.72	85.85	2.155
25.73	85.91	2.156
25.74	85.98	2.155
25.74	86.05	2.155
25.75	86.11	2.157
25.76	86.18	2.156
25.76	86.25	2.154
25.77	86.31	2.154
25.78	86.38	2.154
25.78	86.45	2.155
25.79	86.51	2.155
25.80	86.58	2.153
25.80	86.65	2.152
25.81	86.71	2.152
25.82	86.78	2.152
25.82	86.85	2.152
25.83	86.91	2.153
25.84	86.98	2.153
25.84	87.05	2.152
25.85	87.11	2.153
25.86	87.18	2.154
25.86	87.25	2.154
25.87	87.31	2.154
25.88	87.38	2.154
25.88	87.45	2.154
25.89	87.51	2.155
25.90	87.58	2.156
25.90	87.65	2.156
25.91	87.72	2.156
25.92	87.78	2.157
25.92	87.85	2.157
25.93	87.92	2.156
25.94	87.98	2.156
25.94	88.05	2.156
25.95	88.11	2.157
25.96	88.18	2.156
25.96	88.25	2.155
25.97	88.32	2.156
25.98	88.38	2.156
25.98	88.45	2.156
25.99	88.51	2.157
26.00	88.58	2.157
26.00	88.65	2.157
26.01	88.72	2.157
26.02	88.78	2.157
26.02	88.85	2.157
26.03	88.92	2.158
26.04	88.98	2.157
26.04	89.05	2.156
26.05	89.12	2.158
26.06	89.18	2.159
26.06	89.25	2.160
26.07	89.32	2.161
26.08	89.38	2.161
26.08	89.45	2.161
26.09	89.52	2.162
26.10	89.58	2.161
26.10	89.65	2.162
26.11	89.72	2.163
26.12	89.78	2.162
26.12	89.85	2.162
26.13	89.92	2.163
26.14	89.98	2.163
26.14	90.05	2.163
26.15	90.12	2.163
26.16	90.18	2.163
26.16	90.25	2.162
26.17	90.32	2.162
26.18	90.38	2.162
26.18	90.45	2.163
26.19	90.52	2.164
26.20	90.58	2.163
26.20	90.65	2.163
26.21	90.72	2.164
26.22	90.78	2.165
26.22	90.85	2.166
26.23	90.92	2.166
26.24	90.98	2.165
26.24	91.05	2.165
26.25	91.12	2.165
26.26	91.18	2.167
26.26	91.25	2.168
26.27	91.32	2.168
26.28	91.38	2.168
26.28	91.45	2.169
26.29	91.52	2.170
26.30	91.58	2.171
26.30	91.65	2.172
26.31	91.72	2.173
26.32	91.78	2.173
26.32	91.85	2.174
26.33	91.92	2.175
26.34	91.98	2.177
26.34	92.05	2.177
26.35	92.12	2.178
26.36	92.18	2.178
26.36	92.25	2.179
26.37	92.32	2.180
26.38	92.38	2.179
26.38	92.45	2.180
26.39	92.52	2.182
26.40	92.58	2.182
26.40	92.65	2.183
26.41	92.72	2.183
26.42	92.78	2.184
26.42	92.85	2.185
26.43	92.92	2.186
26.44	92.99	2.186
26.44	93.05	2.185
26.45	93.12	2.186
26.46	93.19	2.187
26.46	93.25	2.187
26.47	93.32	2.187
26.48	93.39	2.189
26.48	93.45	2.189
26.49	93.52	2.189
26.50	93.59	2.192
26.50	93.65	2.194
26.51	93.72	2.194
26.52	93.79	2.193
26.52	93.85	2.194
26.53	93.92	2.196
26.54	93.99	2.197
26.54	94.05	2.198
26.55	94.12	2.200
26.56	94.19	2.201
26.56	94.25	2.202
26.57	94.32	2.201
26.58	94.39	2.203
26.58	94.45	2.203
26.59	94.52	2.203
26.60	94.59	2.205
26.60	94.65	2.205
26.61	94.72	2.206
26.62	94.79	2.209
26.62	94.85	2.208
26.63	94.92	2.210
26.64	94.99	2.211
26.64	95.05	2.211
26.65	95.12	2.212
26.66	95.19	2.213
26.66	95.25	2.215
26.67	95.32	2.216
26.68	95.39	2.217
26.68	95.45	2.217
26.69	95.52	2.217
26.70	95.59	2.218
26.70	95.65	2.220
26.71	95.72	2.221
26.72	95.79	2.222
26.72	95.85	2.224
26.73	95.92	2.226
26.74	95.99	2.227
26.74	96.05	2.229
26.75	96.12	2.231
26.76	96.19	2.232
26.76	96.25	2.233
26.77	96.32	2.234
26.78	96.39	2.238
26.78	96.45	2.241
26.79	96.52	2.242
26.80	96.59	2.244
26.80	96.65	2.245
26.81	96.72	2.247
26.82	96.79	2.255
26.82	96.85	2.258
26.83	96.92	2.261
26.84	96.99	2.263
26.84	97.05	2.266
26.85	97.12	2.271
26.86	97.19	2.276
26.86	97.25	2.281
26.87	97.32	2.286
26.88	97.39	2.295
26.88	97.45	2.309
26.89	97.52	2.314
26.90	97.59	2.318
26.90	97.65	2.328
26.91	97.72	2.367
26.92	97.79	2.411
26.92	97.85	2.436
26.93	97.92	2.463
26.94	97.99	2.530
26.94	98.05	2.567
26.95	98.12	2.659
26.96	98.19	2.807
26.96	98.25	2.931
26.97	98.32	3.136
26.98	98.38	3.359
26.98	98.45	3.563
26.99	98.52	3.929
27.00	98.58	4.329
27.00	98.65	4.792
27.01	98.71	5.456
27.02	98.78	6.448
27.02	98.84	7.734
27.03	98.90	9.465
27.04	98.96	11.893
27.04	99.02	15.089
27.05	99.08	18.873
27.06	99.13	22.639
27.06	99.19	25.585
27.07	99.24	27.002
27.08	99.29	26.697
27.08	99.35	25.504
27.09	99.41	23.935
27.10	99.47	21.952
27.10	99.54	19.522
27.11	99.60	16.464
27.12	99.68	12.843
27.12	99.75	9.522
27.13	99.82	7.690
27.14	99.90	6.836
27.14	99.97	6.264
27.15	100.04	5.915
27.16	100.12	5.586
27.16	100.19	5.296
27.17	100.26	5.039
27.18	100.33	4.810
27.18	100.41	4.658
27.19	100.48	4.447
27.20	100.55	4.249
27.20	100.62	4.105
27.21	100.69	3.952
27.22	100.76	3.814
27.22	100.83	3.723
27.23	100.89	3.596
27.24	100.96	3.424
27.24	101.03	3.381
27.25	101.10	3.335
27.26	101.17	3.164
27.26	101.24	3.133
27.27	101.31	3.065
27.28	101.37	2.978
27.28	101.44	2.924
27.29	101.51	2.883
27.30	101.58	2.834
27.30	101.65	2.762
27.31	101.71	2.714
27.32	101.78	2.701
27.32	101.85	2.684
27.33	101.92	2.624
27.34	101.98	2.593
27.34	102.05	2.596
27.35	102.12	2.574
27.36	102.18	2.546
27.36	102.25	2.530
27.37	102.32	2.504
27.38	102.39	2.496
27.38	102.45	2.489
27.39	102.52	2.477
27.40	102.59	2.463
27.40	102.65	2.457
27.41	102.72	2.443
27.42	102.79	2.436
27.42	102.86	2.431
27.43	102.92	2.424
27.44	102.99	2.412
27.44	103.06	2.408
27.45	103.12	2.402
27.46	103.19	2.388
27.46	103.26	2.380
27.47	103.32	2.373
27.48	103.39	2.370
27.48	103.46	2.367
27.49	103.52	2.364
27.50	103.59	2.361
27.50	103.66	2.357
27.51	103.73	2.353
27.52	103.79	2.350
27.52	103.86	2.346
27.53	103.93	2.341
27.54	103.99	2.337
27.54	104.06	2.335
27.55	104.13	2.332
27.56	104.19	2.330
27.56	104.26	2.327
27.57	104.33	2.324
27.58	104.39	2.322
27.58	104.46	2.319
27.59	104.53	2.317
27.60	104.59	2.314
27.60	104.66	2.311
27.61	104.73	2.309
27.62	104.79	2.306
27.62	104.86	2.303
27.63	104.93	2.301
27.64	104.99	2.298
27.64	105.06	2.295
27.65	105.13	2.294
27.66	105.19	2.292
27.66	105.26	2.289
27.67	105.33	2.286
27.68	105.39	2.284
27.68	105.46	2.282
27.69	105.53	2.279
27.70	105.59	2.277
27.70	105.66	2.275
27.71	105.73	2.272
27.72	105.79	2.271
27.72	105.86	2.270
27.73	105.93	2.269
27.74	105.99	2.268
27.74	106.06	2.266
27.75	106.13	2.264
27.76	106.19	2.261
27.76	106.26	2.261
27.77	106.33	2.261
27.78	106.39	2.258
27.78	106.46	2.256
27.79	106.53	2.255
27.80	106.59	2.254
27.80	106.66	2.253
27.81	106.73	2.252
27.82	106.79	2.251
27.82	106.86	2.250
27.83	106.93	2.249
27.84	106.99	2.248
27.84	107.06	2.247
27.85	107.13	2.246
27.86	107.19	2.244
27.86	107.26	2.244
27.87	107.33	2.244
27.88	107.39	2.242
27.88	107.46	2.242
27.89	107.53	2.243
27.90	107.59	2.242
27.90	107.66	2.241
27.91	107.73	2.239
27.92	107.80	2.239
27.92	107.86	2.239
27.93	107.93	2.238
27.94	108.00	2.238
27.94	108.06	2.238
27.95	108.13	2.236
27.96	108.20	2.235
27.96	108.26	2.235
27.97	108.33	2.236
27.98	108.40	2.237
27.98	108.46	2.236
27.99	108.53	2.235
28.00	108.59	2.235
28.00	108.66	2.234
28.01	108.73	2.234
28.02	108.80	2.234
28.02	108.86	2.234
28.03	108.93	2.234
28.04	109.00	2.233
28.04	109.06	2.234
28.05	109.13	2.234
28.06	109.20	2.232
28.06	109.26	2.232
28.07	109.33	2.232
28.08	109.40	2.230
28.08	109.46	2.230
28.09	109.53	2.230
28.10	109.60	2.230
28.10	109.66	2.230
28.11	109.73	2.231
28.12	109.80	2.233
28.12	109.86	2.232
28.13	109.93	2.232
28.14	110.00	2.233
28.14	110.06	2.233
28.15	110.13	2.233
28.16	110.20	2.234
28.16	110.26	2.235
28.17	110.33	2.232
28.18	110.40	2.229
28.18	110.46	2.233
28.19	110.53	2.234
28.20	110.60	2.233
28.20	110.66	2.232
28.21	110.73	2.232
28.22	110.80	2.233
28.22	110.86	2.232
28.23	110.93	2.232
28.24	111.00	2.231
28.24	111.06	2.231
28.25	111.13	2.230
28.26	111.20	2.231
28.26	111.26	2.231
28.27	111.33	2.231
28.28	111.40	2.231
28.28	111.46	2.231
28.29	111.53	2.230
28.30	111.60	2.230
28.30	111.66	2.231
28.31	111.73	2.231
28.32	111.80	2.231
28.32	111.87	2.231
28.33	111.93	2.230
28.34	112.00	2.230
28.34	112.06	2.230
28.35	112.13	2.230
28.36	112.20	2.230
28.36	112.26	2.230
28.37	112.33	2.228
28.38	112.40	2.229
28.38	112.47	2.230
28.39	112.53	2.231
28.40	112.60	2.230
28.40	112.66	2.231
28.41	112.73	2.232
28.42	112.80	2.231
28.42	112.87	2.231
28.43	112.93	2.231
28.44	113.00	2.231
28.44	113.07	2.231
28.45	113.13	2.231
28.46	113.20	2.231
28.46	113.26	2.232
28.47	113.33	2.233
28.48	113.40	2.233
28.48	113.47	2.233
28.49	113.53	2.233
28.50	113.60	2.233
28.50	113.67	2.233
28.51	113.73	2.234
28.52	113.80	2.235
28.52	113.87	2.234
28.53	113.93	2.234
28.54	114.00	2.235
28.54	114.07	2.235
28.55	114.13	2.236
28.56	114.20	2.237
28.56	114.27	2.238
28.57	114.33	2.238
28.58	114.40	2.239
28.58	114.47	2.238
28.59	114.53	2.236
28.60	114.60	2.237
28.60	114.67	2.238
28.61	114.73	2.238
28.62	114.80	2.238
28.62	114.87	2.238
28.63	114.93	2.238
28.64	115.00	2.238
28.64	115.07	2.237
28.65	115.13	2.237
28.66	115.20	2.239
28.66	115.27	2.238
28.67	115.33	2.237
28.68	115.40	2.237
28.68	115.47	2.238
28.69	115.53	2.239
28.70	115.60	2.239
28.70	115.67	2.239
28.71	115.73	2.239
28.72	115.80	2.238
28.72	115.87	2.239
28.73	115.93	2.240
28.74	116.00	2.241
28.74	116.07	2.240
28.75	116.13	2.240
28.76	116.20	2.241
28.76	116.27	2.240
28.77	116.33	2.240
28.78	116.40	2.239
28.78	116.47	2.239
28.79	116.53	2.239
28.80	116.60	2.240
28.80	116.67	2.241
28.81	116.73	2.242
28.82	116.80	2.240
28.82	116.87	2.240
28.83	116.93	2.241
28.84	117.00	2.243
28.84	117.07	2.244
28.85	117.13	2.243
28.86	117.20	2.243
28.86	117.27	2.243
28.87	117.33	2.244
28.88	117.40	2.244
28.88	117.47	2.245
28.89	117.53	2.246
28.90	117.60	2.246
28.90	117.67	2.246
28.91	117.74	2.245
28.92	117.80	2.245
28.92	117.87	2.246
28.93	117.93	2.247
28.94	118.00	2.247
28.94	118.07	2.247
28.95	118.13
28.96	118.20
28.96	118.27
28.97	118.33
28.98	118.40
28.98	118.47
28.99	118.53
29.00
29.00