File: Data/2024_09_17_Empty_DSC.txt
Filename	2024_09_17_Empty_DSC
Instrument name	DSC2A-00468 (192.168.1.100)
Operator	CHM343
rundate	9/18/2024
Sample name	2024_09_17_Empty_DSC
proceduresegments	Equilibrate 30.00 °C; Ramp 10.00 °C/min to 210.00 °C; Isothermal 1.0 min; Ramp 10.00 °C/min to 30.00 °C; Isothermal 1.0 min; Ramp 10.00 °C/min to 210.00 °C
[File Parameters]
Run date	9/18/2024 1:46:12 AM
Trios version	5.1.1.46572
Original File Name	C:\ProgramData\TA Instruments\TRIOS\Data\2024_09_17_Empty_DSC.tri
Current File Name	D:\DSC2500\CHM343\2024_09_17_Empty_DSC.tri
[Procedure]
Procedure Name	CHM343_Fall2024_Indium
Sample Name	2024_09_17_Empty_DSC
Sample Mass	0 mg
Reference Sample Mass	0 mg
Pan Mass	54.56 mg
Pan Number	24
Reference Pan Mass	54 mg
Reference Pan Number	19
Pan Type	Aluminum
Comments	Empty Pans - Al Hermetic Sealed Pan, with ref Al pan.  ASU Online CHM343, Remote DSC experimental lab. Fall 2024.  Group Zoom Data Collection, Sept 17, 2024 from 9-11 pm.  TA Instruments DSC2500.
Project Name	Lab 4 - Fall 2024
Operator	CHM343
Test	Custom
Unload Max Temperature	30
Unload Min Temperature	30
Load Max Temperature	30
Load Min Temperature	30
Stop on Gas Flow Error	Yes
[Signal List]
Signal #1	Time (min)
Signal #2	Temperature (°C)
Signal #3	Heat Flow (mW)
Signal #4	Delta T (µV)
Signal #5	Delta Tzero (µV)
Signal #6	Tzero Temperature (°C)
Signal #7	Cell Purge (mL/min)
Signal #8	Heater Temp (°C)
Signal #9	Power Delivered (W)
Signal #10	Reference Junction Temperature (°C)
Signal #11	Flange Temperature (°C)
Signal #12	Heat Flow Phase (rad)
Signal #13	Total Heat Capacity (J/°C)
Signal #14	Heat Capacity (J/°C)
[Configuration]
Company Name	ASU
Instrument Name	DSC2A-00468
Instrument Type	DSC2500
Serial Number	DSC2A-00468
IP	192.168.1.100
Location of Instrument	MRRC
DisplayType	Unknown
Sample Interval 	0.1 s/pt
Selected Heat Flow	T4P
Exotherm Direction	Down
Cell Serial	DRC2-00792
Lid Type	Standard
Cooler	RCS 90
Leave Cooler on at End of Sequence	On
Gas 2	Nitrogen
Gas Selected	Channel 1
Flow Rate	50 mL/min
Secondary Purge	On
Licensed Heat Flow	Heat Flow T4P
Modulation Licensed	Yes
[Versions]
Common IDD Version	1
Cortex Version	VER 2.10.2.31
Driver	5.0.0.6
GDM Version	1.0.3.3
TouchscreenVersion	1.0.0.16145
FEP Version	1.2.1.21
FEP Bootloader	2.0.0.5
AutoSampler Version	2.1.1.26
Auto Sampler Bootloader	2.0.0.5
FCM Version	1.1.0.3
FCM Bootloader	2.0.0.5
[Experiment Logs]
Experiment Log Entry # 1	Equilibrate Segment 30 (C) Started
Experiment Log Entry # 3	Air Cool is off.
Experiment Log Entry # 5	Ramp Segment 10 C/min to 210 Started
Experiment Log Entry # 7	Isothermal Segment 1 min started
Experiment Log Entry # 9	Ramp Segment 10 C/min to 30 Started
Experiment Log Entry # 11	Isothermal Segment 1 min started
Experiment Log Entry # 13	Ramp Segment 10 C/min to 210 Started
[Method Log]
Method Log Entry # 1	Equilibrate 30 °C
Method Log Entry # 2	(Ramp 108282) Ramp 10 °C/minute to 210 °C
Method Log Entry # 3	Isothermal 1 minutes
Method Log Entry # 4	(Ramp 108284) Ramp 10 °C/minute to 30 °C
Method Log Entry # 5	Isothermal 1 minutes
Method Log Entry # 6	(Ramp 108286) Ramp 10 °C/minute to 210 °C
Cell Serial	DRC2-00792
[T1 Calibration]
Slope	-0.008529666
Offset	9.636258
Initial Temperature	98.23
GUID	f8bfdadc-4977-4fdf-ba6d-0ba9134940c3
[TZero Calibration]
Date Applied	11/29/2022 4:06:13 PM
Description	From -89.059 °C to 396.009 °C at 20.000°C/min
Gas Type	Nitrogen
Pan Type	None
Source Files 1	C:\Users\yargerlab\Desktop\DSC Data\General\TZero_calibration_11_29_22_2nd(2).tri
Source Files 2	C:\Users\yargerlab\Desktop\DSC Data\General\TZero_calibration_11_29_22_2nd(3).tri
Delta T Offset	13.05235
Delta T Slope	-0.007271007
Delta T0 Offset	-13.69128
Delta T0 Slope	0.06063341
[Temperature Calibration]
Date Applied	11/29/2022 7:12:28 PM
Description	From 106.590 °C to 186.590 °C at 10.000°C/min
Gas Type	Nitrogen
Pan Type	Tzero Aluminum Hermetic
Source Files 1	C:\Users\yargerlab\Desktop\DSC Data\General\Indium(6).tri
Measured 1	157.391
Known 1	156.598
[Cell Constant Calibration]
Date Applied	11/29/2022 7:12:29 PM
Description	From 106.590 °C to 186.590 °C at 10.000°C/min
Gas Type	Nitrogen
Pan Type	Tzero Aluminum Hermetic
Source Files 1	C:\Users\yargerlab\Desktop\DSC Data\General\Indium(6).tri
T4P KCell	1.006051
Onset Slope	63.26126 mW/°C
[Direct Cp Calibration]
Date Applied	11/30/2022 11:04:51 AM
Description	From -79.983 °C to 298.409 °C at 10.000°C/min
Gas Type	Nitrogen
Pan Type	Tzero Aluminum Hermetic
Source Files 1	C:\Users\yargerlab\Desktop\DSC Data\General\Sapphire_Heat_Capacity_11_30_22.tri
[Rev Cp Calibration]
Date Applied	11/30/2022 1:58:51 PM
Description	From -79.996 °C to 292.812 °C at 3.000°C/min
Gas Type	Nitrogen
Pan Type	Tzero Aluminum Hermetic
Source Files 1	C:\Users\yargerlab\Desktop\DSC Data\General\Sapphire_MDSC_Calibration_11_30_22.tri
[step]
Ramp 10.00 °C/min to 210.00 °C
Time	Temperature	Heat Flow
min	°C	mW
0.00	30.07	-0.123
0.01	30.07	-0.122
0.03	30.08	-0.121
0.04	30.08	-0.120
0.05	30.09	-0.123
0.07	30.11	-0.205
0.08	30.14	-0.316
0.09	30.18	-0.429
0.11	30.24	-0.534
0.12	30.31	-0.609
0.13	30.39	-0.643
0.15	30.47	-0.633
0.16	30.57	-0.601
0.17	30.67	-0.553
0.19	30.77	-0.480
0.20	30.88	-0.425
0.21	30.98	-0.373
0.23	31.10	-0.324
0.24	31.21	-0.295
0.25	31.33	-0.263
0.27	31.44	-0.236
0.28	31.56	-0.221
0.29	31.68	-0.199
0.31	31.81	-0.169
0.32	31.93	-0.155
0.33	32.06	-0.136
0.35	32.18	-0.115
0.36	32.31	-0.113
0.37	32.43	-0.093
0.39	32.56	-0.078
0.40	32.69	-0.072
0.41	32.82	-0.065
0.43	32.95	-0.055
0.44	33.08	-0.050
0.45	33.21	-0.047
0.47	33.34	-0.042
0.48	33.47	-0.039
0.49	33.60	-0.036
0.51	33.73	-0.032
0.52	33.86	-0.030
0.53	33.99	-0.027
0.55	34.12	-0.025
0.56	34.25	-0.023
0.57	34.38	-0.021
0.59	34.52	-0.020
0.60	34.65	-0.019
0.61	34.78	-0.018
0.63	34.91	-0.017
0.64	35.04	-0.015
0.65	35.17	-0.014
0.67	35.31	-0.013
0.68	35.44	-0.012
0.69	35.57	-0.011
0.71	35.70	-0.010
0.72	35.83	-0.009
0.73	35.97	-0.008
0.75	36.10	-0.007
0.76	36.23	-0.007
0.77	36.36	-0.006
0.79	36.49	-0.005
0.80	36.63	-0.004
0.81	36.76	-0.004
0.83	36.89	-0.003
0.84	37.02	-0.003
0.85	37.16	-0.002
0.87	37.29	-0.001
0.88	37.42	-0.001
0.89	37.55	-0.001
0.91	37.69	0.000
0.92	37.82	0.000
0.93	37.95	0.000
0.95	38.08	0.001
0.96	38.22	0.001
0.97	38.35	0.001
0.99	38.48	0.001
1.00	38.62	0.002
1.01	38.75	0.002
1.03	38.88	0.002
1.04	39.01	0.002
1.05	39.15	0.002
1.07	39.28	0.002
1.08	39.41	0.002
1.09	39.54	0.002
1.11	39.68	0.002
1.12	39.81	0.002
1.13	39.94	0.002
1.15	40.08	0.002
1.16	40.21	0.002
1.17	40.34	0.002
1.19	40.48	0.002
1.20	40.61	0.002
1.21	40.74	0.002
1.23	40.87	0.002
1.24	41.01	0.002
1.25	41.14	0.001
1.27	41.27	0.001
1.28	41.41	0.001
1.29	41.54	0.001
1.31	41.67	0.001
1.32	41.81	0.001
1.33	41.94	0.001
1.35	42.07	0.001
1.36	42.21	0.000
1.37	42.34	0.000
1.39	42.47	0.000
1.40	42.61	0.000
1.41	42.74	0.000
1.43	42.87	0.000
1.44	43.01	0.000
1.45	43.14	0.000
1.47	43.27	-0.001
1.48	43.40	-0.001
1.49	43.54	-0.001
1.51	43.67	-0.001
1.52	43.80	-0.001
1.53	43.94	-0.002
1.55	44.07	-0.002
1.56	44.20	-0.002
1.57	44.34	-0.003
1.59	44.47	-0.002
1.60	44.60	-0.003
1.61	44.74	-0.003
1.63	44.87	-0.003
1.64	45.00	-0.004
1.65	45.14	-0.004
1.67	45.27	-0.004
1.68	45.40	-0.004
1.69	45.54	-0.004
1.71	45.67	-0.005
1.72	45.80	-0.005
1.73	45.94	-0.005
1.75	46.07	-0.006
1.76	46.20	-0.006
1.77	46.34	-0.006
1.79	46.47	-0.006
1.80	46.60	-0.006
1.81	46.74	-0.007
1.83	46.87	-0.007
1.84	47.00	-0.007
1.85	47.14	-0.007
1.87	47.27	-0.007
1.88	47.40	-0.008
1.89	47.54	-0.008
1.91	47.67	-0.008
1.92	47.80	-0.008
1.93	47.94	-0.009
1.95	48.07	-0.009
1.96	48.20	-0.009
1.97	48.34	-0.009
1.99	48.47	-0.010
2.00	48.60	-0.010
2.01	48.74	-0.010
2.03	48.87	-0.011
2.04	49.00	-0.011
2.05	49.14	-0.011
2.07	49.27	-0.011
2.08	49.40	-0.011
2.09	49.54	-0.012
2.11	49.67	-0.012
2.12	49.81	-0.012
2.13	49.94	-0.012
2.15	50.07	-0.013
2.16	50.21	-0.013
2.17	50.34	-0.013
2.19	50.47	-0.014
2.20	50.61	-0.014
2.21	50.74	-0.014
2.23	50.87	-0.014
2.24	51.01	-0.014
2.25	51.14	-0.014
2.27	51.27	-0.015
2.28	51.41	-0.015
2.29	51.54	-0.015
2.31	51.67	-0.015
2.32	51.80	-0.016
2.33	51.94	-0.017
2.35	52.07	-0.017
2.36	52.21	-0.017
2.37	52.34	-0.017
2.39	52.47	-0.017
2.40	52.61	-0.017
2.41	52.74	-0.017
2.43	52.87	-0.018
2.44	53.01	-0.018
2.45	53.14	-0.018
2.47	53.27	-0.018
2.48	53.41	-0.018
2.49	53.54	-0.019
2.51	53.67	-0.019
2.52	53.81	-0.019
2.53	53.94	-0.019
2.55	54.07	-0.020
2.56	54.21	-0.020
2.57	54.34	-0.020
2.59	54.47	-0.020
2.60	54.61	-0.020
2.61	54.74	-0.020
2.63	54.87	-0.021
2.64	55.01	-0.021
2.65	55.14	-0.021
2.67	55.28	-0.021
2.68	55.41	-0.021
2.69	55.54	-0.022
2.71	55.68	-0.022
2.72	55.81	-0.022
2.73	55.94	-0.022
2.75	56.08	-0.023
2.76	56.21	-0.023
2.77	56.34	-0.023
2.79	56.48	-0.023
2.80	56.61	-0.023
2.81	56.74	-0.024
2.83	56.88	-0.024
2.84	57.01	-0.024
2.85	57.14	-0.024
2.87	57.28	-0.024
2.88	57.41	-0.025
2.89	57.54	-0.025
2.91	57.68	-0.025
2.92	57.81	-0.025
2.93	57.94	-0.025
2.95	58.08	-0.026
2.96	58.21	-0.026
2.97	58.34	-0.026
2.99	58.48	-0.027
3.00	58.61	-0.027
3.01	58.74	-0.027
3.03	58.88	-0.027
3.04	59.01	-0.027
3.05	59.14	-0.027
3.07	59.28	-0.028
3.08	59.41	-0.028
3.09	59.55	-0.028
3.11	59.68	-0.028
3.12	59.81	-0.028
3.13	59.95	-0.028
3.15	60.08	-0.029
3.16	60.21	-0.029
3.17	60.35	-0.029
3.19	60.48	-0.029
3.20	60.61	-0.029
3.21	60.75	-0.029
3.23	60.88	-0.030
3.24	61.01	-0.030
3.25	61.15	-0.030
3.27	61.28	-0.030
3.28	61.41	-0.030
3.29	61.55	-0.030
3.31	61.68	-0.030
3.32	61.81	-0.031
3.33	61.95	-0.031
3.35	62.08	-0.031
3.36	62.21	-0.031
3.37	62.35	-0.031
3.39	62.48	-0.031
3.40	62.61	-0.031
3.41	62.75	-0.032
3.43	62.88	-0.031
3.44	63.01	-0.032
3.45	63.15	-0.032
3.47	63.28	-0.032
3.48	63.41	-0.032
3.49	63.55	-0.033
3.51	63.68	-0.033
3.52	63.82	-0.033
3.53	63.95	-0.033
3.55	64.08	-0.033
3.56	64.22	-0.033
3.57	64.35	-0.033
3.59	64.48	-0.033
3.60	64.62	-0.033
3.61	64.75	-0.034
3.63	64.88	-0.034
3.64	65.02	-0.034
3.65	65.15	-0.034
3.67	65.28	-0.034
3.68	65.42	-0.034
3.69	65.55	-0.035
3.71	65.68	-0.035
3.72	65.82	-0.035
3.73	65.95	-0.035
3.75	66.08	-0.035
3.76	66.22	-0.035
3.77	66.35	-0.035
3.79	66.48	-0.035
3.80	66.62	-0.036
3.81	66.75	-0.036
3.83	66.88	-0.036
3.84	67.02	-0.036
3.85	67.15	-0.036
3.87	67.28	-0.036
3.88	67.42	-0.037
3.89	67.55	-0.037
3.91	67.69	-0.037
3.92	67.82	-0.038
3.93	67.95	-0.038
3.95	68.09	-0.038
3.96	68.22	-0.038
3.97	68.35	-0.038
3.99	68.49	-0.038
4.00	68.62	-0.038
4.01	68.75	-0.038
4.03	68.89	-0.038
4.04	69.02	-0.039
4.05	69.15	-0.039
4.07	69.29	-0.039
4.08	69.42	-0.039
4.09	69.55	-0.039
4.11	69.69	-0.039
4.12	69.82	-0.039
4.13	69.95	-0.040
4.15	70.09	-0.040
4.16	70.22	-0.040
4.17	70.35	-0.040
4.19	70.49	-0.040
4.20	70.62	-0.040
4.21	70.75	-0.040
4.23	70.89	-0.040
4.24	71.02	-0.040
4.25	71.16	-0.041
4.27	71.29	-0.041
4.28	71.42	-0.040
4.29	71.55	-0.041
4.31	71.69	-0.041
4.32	71.82	-0.041
4.33	71.96	-0.041
4.35	72.09	-0.041
4.36	72.22	-0.041
4.37	72.36	-0.042
4.39	72.49	-0.042
4.40	72.62	-0.042
4.41	72.76	-0.042
4.43	72.89	-0.042
4.44	73.02	-0.042
4.45	73.16	-0.043
4.47	73.29	-0.043
4.48	73.42	-0.043
4.49	73.56	-0.043
4.51	73.69	-0.043
4.52	73.82	-0.043
4.53	73.96	-0.044
4.55	74.09	-0.044
4.56	74.22	-0.044
4.57	74.36	-0.044
4.59	74.49	-0.044
4.60	74.62	-0.044
4.61	74.76	-0.044
4.63	74.89	-0.044
4.64	75.02	-0.044
4.65	75.16	-0.045
4.67	75.29	-0.045
4.68	75.43	-0.045
4.69	75.56	-0.045
4.71	75.69	-0.046
4.72	75.83	-0.046
4.73	75.96	-0.046
4.75	76.09	-0.046
4.76	76.23	-0.046
4.77	76.36	-0.046
4.79	76.49	-0.046
4.80	76.63	-0.046
4.81	76.76	-0.046
4.83	76.89	-0.047
4.84	77.03	-0.047
4.85	77.16	-0.047
4.87	77.29	-0.047
4.88	77.43	-0.047
4.89	77.56	-0.047
4.91	77.69	-0.047
4.92	77.83	-0.047
4.93	77.96	-0.048
4.95	78.09	-0.048
4.96	78.23	-0.048
4.97	78.36	-0.048
4.99	78.49	-0.048
5.00	78.63	-0.048
5.01	78.76	-0.048
5.03	78.90	-0.048
5.04	79.03	-0.048
5.05	79.16	-0.048
5.07	79.30	-0.048
5.08	79.43	-0.049
5.09	79.56	-0.049
5.11	79.70	-0.049
5.12	79.83	-0.049
5.13	79.96	-0.049
5.15	80.10	-0.049
5.16	80.23	-0.050
5.17	80.36	-0.050
5.19	80.50	-0.050
5.20	80.63	-0.050
5.21	80.76	-0.051
5.23	80.90	-0.051
5.24	81.03	-0.051
5.25	81.16	-0.051
5.27	81.30	-0.051
5.28	81.43	-0.051
5.29	81.56	-0.051
5.31	81.70	-0.051
5.32	81.83	-0.051
5.33	81.96	-0.052
5.35	82.10	-0.052
5.36	82.23	-0.052
5.37	82.36	-0.052
5.39	82.50	-0.052
5.40	82.63	-0.052
5.41	82.76	-0.053
5.43	82.90	-0.053
5.44	83.03	-0.053
5.45	83.17	-0.053
5.47	83.30	-0.053
5.48	83.43	-0.053
5.49	83.57	-0.054
5.51	83.70	-0.054
5.52	83.83	-0.054
5.53	83.97	-0.054
5.55	84.10	-0.055
5.56	84.23	-0.055
5.57	84.37	-0.055
5.59	84.50	-0.055
5.60	84.63	-0.055
5.61	84.77	-0.056
5.63	84.90	-0.056
5.64	85.03	-0.056
5.65	85.17	-0.056
5.67	85.30	-0.056
5.68	85.43	-0.057
5.69	85.57	-0.057
5.71	85.70	-0.057
5.72	85.83	-0.057
5.73	85.97	-0.057
5.75	86.10	-0.057
5.76	86.23	-0.057
5.77	86.37	-0.057
5.79	86.50	-0.058
5.80	86.63	-0.058
5.81	86.77	-0.058
5.83	86.90	-0.058
5.84	87.03	-0.059
5.85	87.17	-0.059
5.87	87.30	-0.059
5.88	87.43	-0.059
5.89	87.57	-0.059
5.91	87.70	-0.060
5.92	87.84	-0.060
5.93	87.97	-0.060
5.95	88.10	-0.060
5.96	88.24	-0.060
5.97	88.37	-0.060
5.99	88.50	-0.060
6.00	88.63	-0.060
6.01	88.77	-0.061
6.03	88.90	-0.061
6.04	89.04	-0.061
6.05	89.17	-0.061
6.07	89.30	-0.061
6.08	89.44	-0.061
6.09	89.57	-0.061
6.11	89.70	-0.061
6.12	89.84	-0.061
6.13	89.97	-0.061
6.15	90.10	-0.061
6.16	90.24	-0.061
6.17	90.37	-0.061
6.19	90.50	-0.061
6.20	90.64	-0.061
6.21	90.77	-0.061
6.23	90.90	-0.061
6.24	91.04	-0.062
6.25	91.17	-0.062
6.27	91.30	-0.062
6.28	91.44	-0.062
6.29	91.57	-0.062
6.31	91.70	-0.062
6.32	91.84	-0.061
6.33	91.97	-0.061
6.35	92.10	-0.061
6.36	92.24	-0.061
6.37	92.37	-0.061
6.39	92.50	-0.061
6.40	92.64	-0.061
6.41	92.77	-0.061
6.43	92.90	-0.061
6.44	93.04	-0.061
6.45	93.17	-0.062
6.47	93.30	-0.062
6.48	93.44	-0.062
6.49	93.57	-0.062
6.51	93.71	-0.062
6.52	93.84	-0.062
6.53	93.97	-0.062
6.55	94.11	-0.062
6.56	94.24	-0.062
6.57	94.37	-0.062
6.59	94.51	-0.062
6.60	94.64	-0.062
6.61	94.77	-0.062
6.63	94.91	-0.063
6.64	95.04	-0.063
6.65	95.17	-0.063
6.67	95.31	-0.063
6.68	95.44	-0.063
6.69	95.57	-0.063
6.71	95.71	-0.063
6.72	95.84	-0.063
6.73	95.97	-0.063
6.75	96.11	-0.063
6.76	96.24	-0.063
6.77	96.37	-0.063
6.79	96.51	-0.063
6.80	96.64	-0.063
6.81	96.78	-0.063
6.83	96.91	-0.064
6.84	97.04	-0.064
6.85	97.17	-0.064
6.87	97.31	-0.064
6.88	97.44	-0.064
6.89	97.58	-0.064
6.91	97.71	-0.064
6.92	97.84	-0.064
6.93	97.98	-0.064
6.95	98.11	-0.065
6.96	98.24	-0.065
6.97	98.38	-0.065
6.99	98.51	-0.065
7.00	98.64	-0.065
7.01	98.78	-0.065
7.03	98.91	-0.065
7.04	99.04	-0.066
7.05	99.18	-0.066
7.07	99.31	-0.066
7.08	99.44	-0.066
7.09	99.58	-0.066
7.11	99.71	-0.066
7.12	99.84	-0.066
7.13	99.98	-0.066
7.15	100.11	-0.067
7.16	100.24	-0.067
7.17	100.38	-0.067
7.19	100.51	-0.066
7.20	100.64	-0.067
7.21	100.78	-0.067
7.23	100.91	-0.067
7.24	101.05	-0.067
7.25	101.18	-0.067
7.27	101.31	-0.067
7.28	101.44	-0.067
7.29	101.58	-0.067
7.31	101.71	-0.067
7.32	101.84	-0.067
7.33	101.98	-0.067
7.35	102.11	-0.067
7.36	102.24	-0.067
7.37	102.38	-0.067
7.39	102.51	-0.067
7.40	102.64	-0.067
7.41	102.78	-0.067
7.43	102.91	-0.067
7.44	103.04	-0.067
7.45	103.18	-0.067
7.47	103.31	-0.067
7.48	103.44	-0.067
7.49	103.58	-0.067
7.51	103.71	-0.068
7.52	103.84	-0.068
7.53	103.98	-0.068
7.55	104.11	-0.068
7.56	104.24	-0.068
7.57	104.38	-0.068
7.59	104.51	-0.068
7.60	104.65	-0.068
7.61	104.78	-0.068
7.63	104.91	-0.068
7.64	105.05	-0.068
7.65	105.18	-0.069
7.67	105.31	-0.069
7.68	105.45	-0.069
7.69	105.58	-0.069
7.71	105.71	-0.069
7.72	105.85	-0.069
7.73	105.98	-0.069
7.75	106.11	-0.069
7.76	106.25	-0.069
7.77	106.38	-0.069
7.79	106.52	-0.069
7.80	106.65	-0.069
7.81	106.78	-0.069
7.83	106.91	-0.069
7.84	107.05	-0.069
7.85	107.18	-0.069
7.87	107.31	-0.070
7.88	107.45	-0.070
7.89	107.58	-0.070
7.91	107.72	-0.070
7.92	107.85	-0.070
7.93	107.98	-0.070
7.95	108.12	-0.070
7.96	108.25	-0.070
7.97	108.38	-0.070
7.99	108.52	-0.070
8.00	108.65	-0.070
8.01	108.78	-0.070
8.03	108.92	-0.071
8.04	109.05	-0.071
8.05	109.18	-0.071
8.07	109.32	-0.071
8.08	109.45	-0.071
8.09	109.58	-0.071
8.11	109.72	-0.071
8.12	109.85	-0.071
8.13	109.98	-0.071
8.15	110.12	-0.071
8.16	110.25	-0.071
8.17	110.38	-0.071
8.19	110.52	-0.071
8.20	110.65	-0.071
8.21	110.78	-0.071
8.23	110.92	-0.071
8.24	111.05	-0.071
8.25	111.18	-0.071
8.27	111.32	-0.071
8.28	111.45	-0.072
8.29	111.58	-0.072
8.31	111.72	-0.072
8.32	111.85	-0.072
8.33	111.98	-0.072
8.35	112.12	-0.072
8.36	112.25	-0.072
8.37	112.38	-0.072
8.39	112.52	-0.072
8.40	112.65	-0.073
8.41	112.79	-0.073
8.43	112.92	-0.073
8.44	113.05	-0.073
8.45	113.19	-0.073
8.47	113.32	-0.073
8.48	113.45	-0.073
8.49	113.58	-0.073
8.51	113.72	-0.073
8.52	113.85	-0.074
8.53	113.99	-0.073
8.55	114.12	-0.073
8.56	114.25	-0.074
8.57	114.39	-0.074
8.59	114.52	-0.073
8.60	114.65	-0.073
8.61	114.79	-0.073
8.63	114.92	-0.073
8.64	115.05	-0.074
8.65	115.19	-0.074
8.67	115.32	-0.074
8.68	115.45	-0.074
8.69	115.59	-0.074
8.71	115.72	-0.074
8.72	115.85	-0.074
8.73	115.99	-0.074
8.75	116.12	-0.074
8.76	116.25	-0.074
8.77	116.39	-0.075
8.79	116.52	-0.075
8.80	116.65	-0.075
8.81	116.79	-0.075
8.83	116.92	-0.075
8.84	117.05	-0.075
8.85	117.19	-0.075
8.87	117.32	-0.075
8.88	117.46	-0.075
8.89	117.59	-0.075
8.91	117.72	-0.075
8.92	117.85	-0.075
8.93	117.99	-0.075
8.95	118.12	-0.075
8.96	118.25	-0.076
8.97	118.39	-0.076
8.99	118.52	-0.076
9.00	118.66	-0.076
9.01	118.79	-0.076
9.03	118.92	-0.076
9.04	119.05	-0.076
9.05	119.19	-0.077
9.07	119.32	-0.077
9.08	119.46	-0.077
9.09	119.59	-0.077
9.11	119.72	-0.077
9.12	119.86	-0.077
9.13	119.99	-0.077
9.15	120.12	-0.076
9.16	120.26	-0.077
9.17	120.39	-0.077
9.19	120.52	-0.077
9.20	120.66	-0.077
9.21	120.79	-0.077
9.23	120.92	-0.077
9.24	121.06	-0.077
9.25	121.19	-0.078
9.27	121.32	-0.077
9.28	121.46	-0.078
9.29	121.59	-0.078
9.31	121.72	-0.078
9.32	121.86	-0.078
9.33	121.99	-0.078
9.35	122.13	-0.078
9.36	122.26	-0.078
9.37	122.39	-0.078
9.39	122.52	-0.078
9.40	122.66	-0.078
9.41	122.79	-0.078
9.43	122.93	-0.078
9.44	123.06	-0.078
9.45	123.19	-0.078
9.47	123.32	-0.078
9.48	123.46	-0.079
9.49	123.59	-0.079
9.51	123.73	-0.079
9.52	123.86	-0.079
9.53	123.99	-0.079
9.55	124.13	-0.079
9.56	124.26	-0.079
9.57	124.39	-0.079
9.59	124.53	-0.079
9.60	124.66	-0.080
9.61	124.79	-0.080
9.63	124.93	-0.080
9.64	125.06	-0.080
9.65	125.19	-0.080
9.67	125.33	-0.080
9.68	125.46	-0.081
9.69	125.59	-0.081
9.71	125.73	-0.081
9.72	125.86	-0.081
9.73	125.99	-0.081
9.75	126.13	-0.081
9.76	126.26	-0.080
9.77	126.39	-0.081
9.79	126.53	-0.081
9.80	126.66	-0.081
9.81	126.79	-0.081
9.83	126.93	-0.081
9.84	127.06	-0.081
9.85	127.19	-0.081
9.87	127.33	-0.081
9.88	127.46	-0.081
9.89	127.59	-0.081
9.91	127.73	-0.082
9.92	127.86	-0.082
9.93	127.99	-0.082
9.95	128.13	-0.082
9.96	128.26	-0.082
9.97	128.39	-0.082
9.99	128.53	-0.082
10.00	128.66	-0.082
10.01	128.79	-0.082
10.03	128.93	-0.082
10.04	129.06	-0.082
10.05	129.19	-0.082
10.07	129.33	-0.083
10.08	129.46	-0.083
10.09	129.59	-0.083
10.11	129.73	-0.083
10.12	129.86	-0.083
10.13	129.99	-0.084
10.15	130.13	-0.084
10.16	130.26	-0.084
10.17	130.40	-0.084
10.19	130.53	-0.084
10.20	130.66	-0.084
10.21	130.80	-0.084
10.23	130.93	-0.084
10.24	131.06	-0.084
10.25	131.20	-0.084
10.27	131.33	-0.084
10.28	131.46	-0.084
10.29	131.60	-0.084
10.31	131.73	-0.084
10.32	131.86	-0.084
10.33	132.00	-0.084
10.35	132.13	-0.084
10.36	132.26	-0.085
10.37	132.40	-0.085
10.39	132.53	-0.085
10.40	132.66	-0.085
10.41	132.80	-0.085
10.43	132.93	-0.086
10.44	133.06	-0.086
10.45	133.20	-0.085
10.47	133.33	-0.085
10.48	133.46	-0.085
10.49	133.60	-0.086
10.51	133.73	-0.086
10.52	133.86	-0.086
10.53	134.00	-0.086
10.55	134.13	-0.086
10.56	134.26	-0.086
10.57	134.40	-0.086
10.59	134.53	-0.087
10.60	134.66	-0.087
10.61	134.80	-0.086
10.63	134.93	-0.087
10.64	135.06	-0.087
10.65	135.20	-0.087
10.67	135.33	-0.087
10.68	135.46	-0.088
10.69	135.60	-0.088
10.71	135.73	-0.088
10.72	135.87	-0.088
10.73	136.00	-0.088
10.75	136.13	-0.088
10.76	136.27	-0.088
10.77	136.40	-0.088
10.79	136.53	-0.088
10.80	136.67	-0.088
10.81	136.80	-0.088
10.83	136.93	-0.089
10.84	137.07	-0.088
10.85	137.20	-0.089
10.87	137.33	-0.089
10.88	137.47	-0.089
10.89	137.60	-0.089
10.91	137.73	-0.089
10.92	137.87	-0.089
10.93	138.00	-0.089
10.95	138.13	-0.090
10.96	138.27	-0.090
10.97	138.40	-0.090
10.99	138.53	-0.090
11.00	138.67	-0.090
11.01	138.80	-0.091
11.03	138.93	-0.091
11.04	139.07	-0.091
11.05	139.20	-0.091
11.07	139.33	-0.091
11.08	139.47	-0.091
11.09	139.60	-0.091
11.11	139.73	-0.091
11.12	139.87	-0.091
11.13	140.00	-0.091
11.15	140.13	-0.091
11.16	140.27	-0.091
11.17	140.40	-0.091
11.19	140.53	-0.091
11.20	140.67	-0.091
11.21	140.80	-0.091
11.23	140.93	-0.091
11.24	141.07	-0.092
11.25	141.20	-0.092
11.27	141.33	-0.092
11.28	141.47	-0.092
11.29	141.60	-0.092
11.31	141.73	-0.092
11.32	141.87	-0.093
11.33	142.00	-0.093
11.35	142.13	-0.093
11.36	142.27	-0.093
11.37	142.40	-0.093
11.39	142.53	-0.093
11.40	142.67	-0.093
11.41	142.80	-0.093
11.43	142.93	-0.093
11.44	143.07	-0.093
11.45	143.20	-0.094
11.47	143.34	-0.093
11.48	143.47	-0.093
11.49	143.60	-0.093
11.51	143.74	-0.094
11.52	143.87	-0.094
11.53	144.00	-0.094
11.55	144.14	-0.094
11.56	144.27	-0.095
11.57	144.40	-0.094
11.59	144.54	-0.095
11.60	144.67	-0.095
11.61	144.80	-0.095
11.63	144.94	-0.095
11.64	145.07	-0.095
11.65	145.20	-0.095
11.67	145.34	-0.095
11.68	145.47	-0.095
11.69	145.60	-0.096
11.71	145.74	-0.096
11.72	145.87	-0.096
11.73	146.00	-0.096
11.75	146.14	-0.096
11.76	146.27	-0.096
11.77	146.40	-0.096
11.79	146.54	-0.096
11.80	146.67	-0.096
11.81	146.80	-0.096
11.83	146.94	-0.096
11.84	147.07	-0.097
11.85	147.20	-0.097
11.87	147.34	-0.097
11.88	147.47	-0.097
11.89	147.60	-0.097
11.91	147.74	-0.097
11.92	147.87	-0.097
11.93	148.00	-0.097
11.95	148.14	-0.097
11.96	148.27	-0.097
11.97	148.40	-0.097
11.99	148.54	-0.097
12.00	148.67	-0.097
12.01	148.81	-0.098
12.03	148.94	-0.097
12.04	149.07	-0.098
12.05	149.21	-0.098
12.07	149.34	-0.098
12.08	149.47	-0.098
12.09	149.61	-0.098
12.11	149.74	-0.098
12.12	149.87	-0.098
12.13	150.01	-0.098
12.15	150.14	-0.098
12.16	150.27	-0.098
12.17	150.41	-0.098
12.19	150.54	-0.098
12.20	150.67	-0.098
12.21	150.81	-0.098
12.23	150.94	-0.098
12.24	151.07	-0.098
12.25	151.20	-0.098
12.27	151.34	-0.098
12.28	151.47	-0.098
12.29	151.61	-0.098
12.31	151.74	-0.099
12.32	151.87	-0.098
12.33	152.01	-0.099
12.35	152.14	-0.099
12.36	152.27	-0.099
12.37	152.41	-0.099
12.39	152.54	-0.099
12.40	152.67	-0.099
12.41	152.81	-0.099
12.43	152.94	-0.099
12.44	153.07	-0.099
12.45	153.21	-0.099
12.47	153.34	-0.099
12.48	153.47	-0.099
12.49	153.61	-0.099
12.51	153.74	-0.099
12.52	153.87	-0.099
12.53	154.01	-0.099
12.55	154.14	-0.099
12.56	154.27	-0.099
12.57	154.41	-0.099
12.59	154.54	-0.099
12.60	154.67	-0.099
12.61	154.81	-0.099
12.63	154.94	-0.099
12.64	155.07	-0.100
12.65	155.21	-0.100
12.67	155.34	-0.100
12.68	155.47	-0.101
12.69	155.61	-0.101
12.71	155.74	-0.101
12.72	155.87	-0.101
12.73	156.01	-0.101
12.75	156.14	-0.101
12.76	156.28	-0.101
12.77	156.41	-0.101
12.79	156.54	-0.101
12.80	156.68	-0.101
12.81	156.81	-0.102
12.83	156.94	-0.102
12.84	157.08	-0.102
12.85	157.21	-0.102
12.87	157.34	-0.102
12.88	157.48	-0.102
12.89	157.61	-0.102
12.91	157.74	-0.103
12.92	157.88	-0.103
12.93	158.01	-0.103
12.95	158.14	-0.103
12.96	158.28	-0.103
12.97	158.41	-0.103
12.99	158.54	-0.103
13.00	158.68	-0.103
13.01	158.81	-0.103
13.03	158.94	-0.103
13.04	159.08	-0.103
13.05	159.21	-0.104
13.07	159.34	-0.104
13.08	159.48	-0.104
13.09	159.61	-0.104
13.11	159.74	-0.104
13.12	159.88	-0.104
13.13	160.01	-0.104
13.15	160.14	-0.104
13.16	160.28	-0.104
13.17	160.41	-0.104
13.19	160.54	-0.104
13.20	160.68	-0.104
13.21	160.81	-0.104
13.23	160.94	-0.104
13.24	161.08	-0.104
13.25	161.21	-0.104
13.27	161.35	-0.104
13.28	161.48	-0.105
13.29	161.61	-0.105
13.31	161.74	-0.105
13.32	161.88	-0.105
13.33	162.01	-0.105
13.35	162.14	-0.105
13.36	162.28	-0.105
13.37	162.41	-0.105
13.39	162.54	-0.105
13.40	162.68	-0.105
13.41	162.81	-0.105
13.43	162.94	-0.105
13.44	163.08	-0.105
13.45	163.21	-0.105
13.47	163.34	-0.106
13.48	163.48	-0.105
13.49	163.61	-0.106
13.51	163.75	-0.106
13.52	163.88	-0.106
13.53	164.01	-0.106
13.55	164.14	-0.106
13.56	164.28	-0.106
13.57	164.41	-0.106
13.59	164.55	-0.106
13.60	164.68	-0.106
13.61	164.81	-0.106
13.63	164.95	-0.106
13.64	165.08	-0.106
13.65	165.21	-0.106
13.67	165.35	-0.106
13.68	165.48	-0.106
13.69	165.61	-0.107
13.71	165.75	-0.107
13.72	165.88	-0.107
13.73	166.01	-0.108
13.75	166.15	-0.108
13.76	166.28	-0.108
13.77	166.41	-0.108
13.79	166.55	-0.108
13.80	166.68	-0.108
13.81	166.81	-0.108
13.83	166.95	-0.108
13.84	167.08	-0.107
13.85	167.21	-0.108
13.87	167.35	-0.108
13.88	167.48	-0.107
13.89	167.61	-0.108
13.91	167.75	-0.108
13.92	167.88	-0.108
13.93	168.01	-0.108
13.95	168.15	-0.108
13.96	168.28	-0.108
13.97	168.41	-0.108
13.99	168.55	-0.108
14.00	168.68	-0.108
14.01	168.81	-0.108
14.03	168.95	-0.108
14.04	169.08	-0.108
14.05	169.21	-0.109
14.07	169.35	-0.109
14.08	169.48	-0.109
14.09	169.61	-0.110
14.11	169.75	-0.110
14.12	169.88	-0.110
14.13	170.01	-0.110
14.15	170.15	-0.110
14.16	170.28	-0.110
14.17	170.42	-0.110
14.19	170.55	-0.110
14.20	170.68	-0.110
14.21	170.82	-0.110
14.23	170.95	-0.110
14.24	171.08	-0.110
14.25	171.22	-0.110
14.27	171.35	-0.110
14.28	171.48	-0.110
14.29	171.62	-0.110
14.31	171.75	-0.111
14.32	171.88	-0.111
14.33	172.02	-0.111
14.35	172.15	-0.111
14.36	172.28	-0.111
14.37	172.41	-0.111
14.39	172.55	-0.111
14.40	172.68	-0.111
14.41	172.82	-0.111
14.43	172.95	-0.112
14.44	173.08	-0.112
14.45	173.22	-0.112
14.47	173.35	-0.112
14.48	173.48	-0.113
14.49	173.62	-0.113
14.51	173.75	-0.113
14.52	173.88	-0.113
14.53	174.02	-0.113
14.55	174.15	-0.113
14.56	174.28	-0.113
14.57	174.42	-0.113
14.59	174.55	-0.113
14.60	174.68	-0.113
14.61	174.82	-0.113
14.63	174.95	-0.113
14.64	175.08	-0.113
14.65	175.22	-0.113
14.67	175.35	-0.113
14.68	175.48	-0.114
14.69	175.62	-0.114
14.71	175.75	-0.113
14.72	175.88	-0.114
14.73	176.02	-0.114
14.75	176.15	-0.114
14.76	176.28	-0.113
14.77	176.42	-0.113
14.79	176.55	-0.114
14.80	176.68	-0.114
14.81	176.82	-0.114
14.83	176.95	-0.114
14.84	177.08	-0.114
14.85	177.22	-0.115
14.87	177.35	-0.115
14.88	177.48	-0.115
14.89	177.62	-0.115
14.91	177.75	-0.115
14.92	177.89	-0.115
14.93	178.02	-0.115
14.95	178.15	-0.115
14.96	178.29	-0.115
14.97	178.42	-0.115
14.99	178.55	-0.115
15.00	178.68	-0.115
15.01	178.82	-0.115
15.03	178.95	-0.116
15.04	179.09	-0.116
15.05	179.22	-0.116
15.07	179.35	-0.116
15.08	179.49	-0.116
15.09	179.62	-0.116
15.11	179.75	-0.116
15.12	179.89	-0.116
15.13	180.02	-0.116
15.15	180.15	-0.117
15.16	180.29	-0.117
15.17	180.42	-0.117
15.19	180.55	-0.117
15.20	180.69	-0.117
15.21	180.82	-0.117
15.23	180.95	-0.117
15.24	181.09	-0.118
15.25	181.22	-0.118
15.27	181.35	-0.118
15.28	181.49	-0.118
15.29	181.62	-0.118
15.31	181.75	-0.118
15.32	181.89	-0.118
15.33	182.02	-0.118
15.35	182.15	-0.119
15.36	182.29	-0.118
15.37	182.42	-0.119
15.39	182.55	-0.119
15.40	182.69	-0.119
15.41	182.82	-0.119
15.43	182.95	-0.119
15.44	183.09	-0.119
15.45	183.22	-0.119
15.47	183.35	-0.119
15.48	183.49	-0.119
15.49	183.62	-0.119
15.51	183.75	-0.119
15.52	183.89	-0.119
15.53	184.02	-0.120
15.55	184.15	-0.120
15.56	184.29	-0.120
15.57	184.42	-0.120
15.59	184.55	-0.120
15.60	184.69	-0.120
15.61	184.82	-0.120
15.63	184.95	-0.120
15.64	185.09	-0.120
15.65	185.22	-0.120
15.67	185.36	-0.120
15.68	185.49	-0.120
15.69	185.62	-0.120
15.71	185.76	-0.120
15.72	185.89	-0.120
15.73	186.02	-0.121
15.75	186.16	-0.121
15.76	186.29	-0.121
15.77	186.42	-0.121
15.79	186.55	-0.121
15.80	186.69	-0.121
15.81	186.82	-0.122
15.83	186.96	-0.122
15.84	187.09	-0.122
15.85	187.22	-0.122
15.87	187.36	-0.122
15.88	187.49	-0.122
15.89	187.62	-0.122
15.91	187.75	-0.122
15.92	187.89	-0.122
15.93	188.02	-0.122
15.95	188.16	-0.122
15.96	188.29	-0.123
15.97	188.42	-0.123
15.99	188.56	-0.123
16.00	188.69	-0.123
16.01	188.82	-0.123
16.03	188.96	-0.124
16.04	189.09	-0.123
16.05	189.22	-0.123
16.07	189.36	-0.123
16.08	189.49	-0.123
16.09	189.62	-0.123
16.11	189.76	-0.123
16.12	189.89	-0.123
16.13	190.02	-0.124
16.15	190.16	-0.123
16.16	190.29	-0.124
16.17	190.42	-0.124
16.19	190.56	-0.124
16.20	190.69	-0.124
16.21	190.82	-0.124
16.23	190.96	-0.124
16.24	191.09	-0.124
16.25	191.22	-0.124
16.27	191.36	-0.124
16.28	191.49	-0.124
16.29	191.62	-0.125
16.31	191.76	-0.125
16.32	191.89	-0.125
16.33	192.02	-0.125
16.35	192.16	-0.125
16.36	192.29	-0.125
16.37	192.42	-0.125
16.39	192.56	-0.125
16.40	192.69	-0.125
16.41	192.82	-0.125
16.43	192.96	-0.125
16.44	193.09	-0.125
16.45	193.22	-0.126
16.47	193.36	-0.126
16.48	193.49	-0.126
16.49	193.62	-0.126
16.51	193.76	-0.126
16.52	193.89	-0.126
16.53	194.02	-0.126
16.55	194.16	-0.126
16.56	194.29	-0.126
16.57	194.42	-0.126
16.59	194.56	-0.126
16.60	194.69	-0.126
16.61	194.83	-0.126
16.63	194.96	-0.126
16.64	195.09	-0.126
16.65	195.23	-0.126
16.67	195.36	-0.126
16.68	195.49	-0.126
16.69	195.62	-0.126
16.71	195.76	-0.127
16.72	195.89	-0.127
16.73	196.03	-0.127
16.75	196.16	-0.127
16.76	196.29	-0.127
16.77	196.43	-0.127
16.79	196.56	-0.127
16.80	196.69	-0.127
16.81	196.83	-0.127
16.83	196.96	-0.127
16.84	197.09	-0.127
16.85	197.23	-0.127
16.87	197.36	-0.127
16.88	197.49	-0.127
16.89	197.63	-0.127
16.91	197.76	-0.127
16.92	197.89	-0.127
16.93	198.03	-0.127
16.95	198.16	-0.127
16.96	198.29	-0.128
16.97	198.43	-0.128
16.99	198.56	-0.128
17.00	198.69	-0.128
17.01	198.83	-0.128
17.03	198.96	-0.128
17.04	199.09	-0.128
17.05	199.23	-0.129
17.07	199.36	-0.129
17.08	199.49	-0.129
17.09	199.63	-0.129
17.11	199.76	-0.129
17.12	199.89	-0.129
17.13	200.03	-0.129
17.15	200.16	-0.129
17.16	200.29	-0.129
17.17	200.43	-0.129
17.19	200.56	-0.129
17.20	200.69	-0.129
17.21	200.83	-0.129
17.23	200.96	-0.129
17.24	201.09	-0.129
17.25	201.23	-0.129
17.27	201.36	-0.129
17.28	201.49	-0.129
17.29	201.63	-0.130
17.31	201.76	-0.130
17.32	201.89	-0.130
17.33	202.03	-0.130
17.35	202.16	-0.130
17.36	202.29	-0.130
17.37	202.43	-0.130
17.39	202.56	-0.130
17.40	202.69	-0.131
17.41	202.83	-0.132
17.43	202.96	-0.131
17.44	203.09	-0.132
17.45	203.23	-0.132
17.47	203.36	-0.132
17.48	203.50	-0.132
17.49	203.63	-0.132
17.51	203.76	-0.131
17.52	203.90	-0.131
17.53	204.03	-0.131
17.55	204.16	-0.131
17.56	204.30	-0.131
17.57	204.43	-0.131
17.59	204.56	-0.131
17.60	204.70	-0.131
17.61	204.83	-0.132
17.63	204.96	-0.132
17.64	205.09	-0.132
17.65	205.23	-0.132
17.67	205.36	-0.132
17.68	205.49	-0.132
17.69	205.63	-0.133
17.71	205.76	-0.133
17.72	205.89	-0.132
17.73	206.03	-0.133
17.75	206.16	-0.132
17.76	206.29	-0.133
17.77	206.43	-0.133
17.79	206.56	-0.133
17.80	206.70	-0.133
17.81	206.83	-0.133
17.83	206.96	-0.133
17.84	207.09	-0.134
17.85	207.23	-0.134
17.87	207.36	-0.134
17.88	207.50	-0.134
17.89	207.63	-0.134
17.91	207.76	-0.134
17.92	207.90	-0.134
17.93	208.03	-0.134
17.95	208.16	-0.134
17.96	208.30	-0.134
17.97	208.43	-0.134
17.99	208.56	-0.135
18.00	208.70	-0.135
18.00	208.71	-0.135

[step]
Ramp 10.00 °C/min to 30.00 °C
Time	Temperature	Heat Flow (Normalized)
min	°C	W/g
19.00	210.07
19.02	210.07
19.03	210.07
19.04	210.07
19.06	210.06
19.07	210.04
19.08	210.02
19.10	209.98
19.11	209.93
19.12	209.87
19.14	209.79
19.15	209.71
19.16	209.62
19.18	209.52
19.19	209.41
19.20	209.30
19.22	209.19
19.23	209.07
19.24	208.95
19.26	208.83
19.27	208.71
19.28	208.59
19.30	208.46
19.31	208.34
19.32	208.21
19.34	208.08
19.35	207.96
19.36	207.83
19.38	207.70
19.39	207.57
19.40	207.44
19.42	207.31
19.43	207.18
19.44	207.05
19.46	206.92
19.47	206.79
19.48	206.66
19.50	206.53
19.51	206.40
19.52	206.27
19.54	206.14
19.55	206.01
19.56	205.87
19.58	205.74
19.59	205.61
19.60	205.48
19.62	205.35
19.63	205.22
19.64	205.08
19.66	204.95
19.67	204.82
19.68	204.69
19.70	204.56
19.71	204.43
19.72	204.30
19.74	204.16
19.75	204.03
19.76	203.90
19.78	203.77
19.79	203.63
19.80	203.50
19.82	203.37
19.83	203.24
19.84	203.10
19.86	202.97
19.87	202.84
19.88	202.71
19.90	202.58
19.91	202.44
19.92	202.31
19.94	202.18
19.95	202.05
19.96	201.91
19.98	201.78
19.99	201.65
20.00	201.52
20.02	201.38
20.03	201.25
20.04	201.12
20.06	200.99
20.07	200.86
20.08	200.72
20.10	200.59
20.11	200.46
20.12	200.32
20.14	200.19
20.15	200.06
20.16	199.92
20.18	199.79
20.19	199.66
20.20	199.53
20.22	199.39
20.23	199.26
20.24	199.13
20.26	199.00
20.27	198.86
20.28	198.73
20.30	198.60
20.31	198.46
20.32	198.33
20.34	198.20
20.35	198.07
20.36	197.93
20.38	197.80
20.39	197.67
20.40	197.53
20.42	197.40
20.43	197.27
20.44	197.13
20.46	197.00
20.47	196.87
20.48	196.73
20.50	196.60
20.51	196.47
20.52	196.34
20.54	196.20
20.55	196.07
20.56	195.94
20.58	195.81
20.59	195.67
20.60	195.54
20.62	195.41
20.63	195.27
20.64	195.14
20.66	195.01
20.67	194.87
20.68	194.74
20.70	194.61
20.71	194.47
20.72	194.34
20.74	194.21
20.75	194.08
20.76	193.94
20.78	193.81
20.79	193.68
20.80	193.54
20.82	193.41
20.83	193.28
20.84	193.14
20.86	193.01
20.87	192.88
20.88	192.74
20.90	192.61
20.91	192.48
20.92	192.34
20.94	192.21
20.95	192.08
20.96	191.94
20.98	191.81
20.99	191.68
21.00	191.55
21.02	191.41
21.03	191.28
21.04	191.15
21.06	191.01
21.07	190.88
21.08	190.75
21.10	190.61
21.11	190.48
21.12	190.35
21.14	190.21
21.15	190.08
21.16	189.95
21.18	189.82
21.19	189.68
21.20	189.55
21.22	189.42
21.23	189.28
21.24	189.15
21.26	189.02
21.27	188.88
21.28	188.75
21.30	188.62
21.31	188.48
21.32	188.35
21.34	188.22
21.35	188.08
21.36	187.95
21.38	187.82
21.39	187.68
21.40	187.55
21.42	187.42
21.43	187.28
21.44	187.15
21.46	187.02
21.47	186.88
21.48	186.75
21.50	186.62
21.51	186.49
21.52	186.35
21.54	186.22
21.55	186.09
21.56	185.96
21.58	185.82
21.59	185.69
21.60	185.55
21.62	185.42
21.63	185.29
21.64	185.16
21.66	185.02
21.67	184.89
21.68	184.76
21.70	184.62
21.71	184.49
21.72	184.35
21.74	184.22
21.75	184.09
21.76	183.96
21.78	183.82
21.79	183.69
21.80	183.56
21.82	183.42
21.83	183.29
21.84	183.16
21.86	183.02
21.87	182.89
21.88	182.76
21.90	182.62
21.91	182.49
21.92	182.36
21.94	182.22
21.95	182.09
21.96	181.96
21.98	181.82
21.99	181.69
22.00	181.56
22.02	181.43
22.03	181.29
22.04	181.16
22.06	181.03
22.07	180.89
22.08	180.76
22.10	180.63
22.11	180.49
22.12	180.36
22.14	180.23
22.15	180.09
22.16	179.96
22.18	179.83
22.19	179.69
22.20	179.56
22.22	179.43
22.23	179.29
22.24	179.16
22.26	179.03
22.27	178.89
22.28	178.76
22.30	178.63
22.31	178.49
22.32	178.36
22.34	178.23
22.35	178.09
22.36	177.96
22.38	177.83
22.39	177.70
22.40	177.56
22.42	177.43
22.43	177.30
22.44	177.16
22.46	177.03
22.47	176.90
22.48	176.76
22.50	176.63
22.51	176.50
22.52	176.36
22.54	176.23
22.55	176.10
22.56	175.96
22.58	175.83
22.59	175.70
22.60	175.56
22.62	175.43
22.63	175.30
22.64	175.16
22.66	175.03
22.67	174.90
22.68	174.77
22.70	174.63
22.71	174.50
22.72	174.37
22.74	174.23
22.75	174.10
22.76	173.97
22.78	173.83
22.79	173.70
22.80	173.57
22.82	173.43
22.83	173.30
22.84	173.17
22.86	173.03
22.87	172.90
22.88	172.77
22.90	172.63
22.91	172.50
22.92	172.37
22.94	172.23
22.95	172.10
22.96	171.97
22.98	171.83
22.99	171.70
23.00	171.57
23.02	171.43
23.03	171.30
23.04	171.17
23.06	171.03
23.07	170.90
23.08	170.77
23.10	170.63
23.11	170.50
23.12	170.37
23.14	170.24
23.15	170.10
23.16	169.97
23.18	169.84
23.19	169.70
23.20	169.57
23.22	169.44
23.23	169.30
23.24	169.17
23.26	169.04
23.27	168.90
23.28	168.77
23.30	168.64
23.31	168.50
23.32	168.37
23.34	168.24
23.35	168.10
23.36	167.97
23.38	167.84
23.39	167.71
23.40	167.57
23.42	167.44
23.43	167.31
23.44	167.17
23.46	167.04
23.47	166.91
23.48	166.77
23.50	166.64
23.51	166.51
23.52	166.37
23.54	166.24
23.55	166.11
23.56	165.97
23.58	165.84
23.59	165.71
23.60	165.57
23.62	165.44
23.63	165.31
23.64	165.17
23.66	165.04
23.67	164.91
23.68	164.78
23.70	164.64
23.71	164.51
23.72	164.38
23.74	164.24
23.75	164.11
23.76	163.98
23.78	163.84
23.79	163.71
23.80	163.58
23.82	163.44
23.83	163.31
23.84	163.18
23.86	163.04
23.87	162.91
23.88	162.78
23.90	162.64
23.91	162.51
23.92	162.38
23.94	162.24
23.95	162.11
23.96	161.98
23.98	161.84
23.99	161.71
24.00	161.58
24.02	161.44
24.03	161.31
24.04	161.18
24.06	161.04
24.07	160.91
24.08	160.78
24.10	160.65
24.11	160.51
24.12	160.38
24.14	160.25
24.15	160.11
24.16	159.98
24.18	159.85
24.19	159.71
24.20	159.58
24.22	159.45
24.23	159.31
24.24	159.18
24.26	159.05
24.27	158.91
24.28	158.78
24.30	158.65
24.31	158.51
24.32	158.38
24.34	158.25
24.35	158.11
24.36	157.98
24.38	157.85
24.39	157.71
24.40	157.58
24.42	157.45
24.43	157.32
24.44	157.18
24.46	157.05
24.47	156.92
24.48	156.78
24.50	156.65
24.51	156.52
24.52	156.38
24.54	156.25
24.55	156.12
24.56	155.98
24.58	155.85
24.59	155.72
24.60	155.58
24.62	155.45
24.63	155.32
24.64	155.18
24.66	155.05
24.67	154.92
24.68	154.78
24.70	154.65
24.71	154.52
24.72	154.39
24.74	154.25
24.75	154.12
24.76	153.99
24.78	153.85
24.79	153.72
24.80	153.59
24.82	153.45
24.83	153.32
24.84	153.19
24.86	153.05
24.87	152.92
24.88	152.79
24.90	152.65
24.91	152.52
24.92	152.39
24.94	152.25
24.95	152.12
24.96	151.99
24.98	151.85
24.99	151.72
25.00	151.59
25.02	151.45
25.03	151.32
25.04	151.19
25.06	151.05
25.07	150.92
25.08	150.79
25.10	150.65
25.11	150.52
25.12	150.39
25.14	150.25
25.15	150.12
25.16	149.99
25.18	149.86
25.19	149.72
25.20	149.59
25.22	149.46
25.23	149.32
25.24	149.19
25.26	149.06
25.27	148.92
25.28	148.79
25.30	148.66
25.31	148.52
25.32	148.39
25.34	148.26
25.35	148.12
25.36	147.99
25.38	147.86
25.39	147.73
25.40	147.59
25.42	147.46
25.43	147.32
25.44	147.19
25.46	147.06
25.47	146.93
25.48	146.79
25.50	146.66
25.51	146.53
25.52	146.39
25.54	146.26
25.55	146.13
25.56	145.99
25.58	145.86
25.59	145.73
25.60	145.59
25.62	145.46
25.63	145.33
25.64	145.19
25.66	145.06
25.67	144.93
25.68	144.79
25.70	144.66
25.71	144.53
25.72	144.39
25.74	144.26
25.75	144.13
25.76	144.00
25.78	143.86
25.79	143.73
25.80	143.60
25.82	143.46
25.83	143.33
25.84	143.20
25.86	143.06
25.87	142.93
25.88	142.80
25.90	142.66
25.91	142.53
25.92	142.40
25.94	142.26
25.95	142.13
25.96	142.00
25.98	141.86
25.99	141.73
26.00	141.60
26.02	141.46
26.03	141.33
26.04	141.20
26.06	141.06
26.07	140.93
26.08	140.80
26.10	140.66
26.11	140.53
26.12	140.40
26.14	140.26
26.15	140.13
26.16	140.00
26.18	139.87
26.19	139.73
26.20	139.60
26.22	139.46
26.23	139.33
26.24	139.20
26.26	139.07
26.27	138.93
26.28	138.80
26.30	138.67
26.31	138.53
26.32	138.40
26.34	138.27
26.35	138.13
26.36	138.00
26.38	137.87
26.39	137.73
26.40	137.60
26.42	137.47
26.43	137.33
26.44	137.20
26.46	137.07
26.47	136.93
26.48	136.80
26.50	136.67
26.51	136.54
26.52	136.40
26.54	136.27
26.55	136.14
26.56	136.00
26.58	135.87
26.59	135.73
26.60	135.60
26.62	135.47
26.63	135.34
26.64	135.20
26.66	135.07
26.67	134.94
26.68	134.80
26.70	134.67
26.71	134.54
26.72	134.40
26.74	134.27
26.75	134.14
26.76	134.00
26.78	133.87
26.79	133.74
26.80	133.60
26.82	133.47
26.83	133.34
26.84	133.20
26.86	133.07
26.87	132.94
26.88	132.80
26.90	132.67
26.91	132.54
26.92	132.41
26.94	132.27
26.95	132.14
26.96	132.01
26.98	131.87
26.99	131.74
27.00	131.61
27.02	131.47
27.03	131.34
27.04	131.21
27.06	131.07
27.07	130.94
27.08	130.81
27.10	130.67
27.11	130.54
27.12	130.41
27.14	130.27
27.15	130.14
27.16	130.01
27.18	129.87
27.19	129.74
27.20	129.61
27.22	129.47
27.23	129.34
27.24	129.21
27.26	129.07
27.27	128.94
27.28	128.81
27.30	128.68
27.31	128.54
27.32	128.41
27.34	128.28
27.35	128.14
27.36	128.01
27.38	127.88
27.39	127.74
27.40	127.61
27.42	127.48
27.43	127.34
27.44	127.21
27.46	127.08
27.47	126.94
27.48	126.81
27.50	126.68
27.51	126.54
27.52	126.41
27.54	126.28
27.55	126.14
27.56	126.01
27.58	125.88
27.59	125.74
27.60	125.61
27.62	125.48
27.63	125.34
27.64	125.21
27.66	125.08
27.67	124.94
27.68	124.81
27.70	124.68
27.71	124.55
27.72	124.41
27.74	124.28
27.75	124.15
27.76	124.01
27.78	123.88
27.79	123.75
27.80	123.61
27.82	123.48
27.83	123.35
27.84	123.21
27.86	123.08
27.87	122.95
27.88	122.81
27.90	122.68
27.91	122.55
27.92	122.41
27.94	122.28
27.95	122.15
27.96	122.01
27.98	121.88
27.99	121.75
28.00	121.61
28.02	121.48
28.03	121.35
28.04	121.22
28.06	121.08
28.07	120.95
28.08	120.82
28.10	120.68
28.11	120.55
28.12	120.42
28.14	120.28
28.15	120.15
28.16	120.02
28.18	119.88
28.19	119.75
28.20	119.62
28.22	119.48
28.23	119.35
28.24	119.22
28.26	119.08
28.27	118.95
28.28	118.82
28.30	118.68
28.31	118.55
28.32	118.42
28.34	118.29
28.35	118.15
28.36	118.02
28.38	117.89
28.39	117.75
28.40	117.62
28.42	117.48
28.43	117.35
28.44	117.22
28.46	117.09
28.47	116.95
28.48	116.82
28.50	116.69
28.51	116.55
28.52	116.42
28.54	116.29
28.55	116.15
28.56	116.02
28.58	115.89
[...]
33.82	63.53
33.83	63.40
33.84	63.27
33.86	63.13
33.87	63.00
33.88	62.87
33.90	62.73
33.91	62.60
33.92	62.47
33.94	62.33
33.95	62.20
33.96	62.07
33.98	61.93
33.99	61.80
34.00	61.67
34.02	61.53
34.03	61.40
34.04	61.27
34.06	61.14
34.07	61.00
34.08	60.87
34.10	60.74
34.11	60.60
34.12	60.47
34.14	60.34
34.15	60.20
34.16	60.07
34.18	59.94
34.19	59.80
34.20	59.67
34.22	59.54
34.23	59.40
34.24	59.27
34.26	59.14
34.27	59.00
34.28	58.87
34.30	58.74
34.31	58.60
34.32	58.47
34.34	58.34
34.35	58.20
34.36	58.07
34.38	57.94
34.39	57.80
34.40	57.67
34.42	57.54
34.43	57.40
34.44	57.27
34.46	57.14
34.47	57.00
34.48	56.87
34.50	56.74
34.51	56.60
34.52	56.47
34.54	56.34
34.55	56.21
34.56	56.07
34.58	55.94
34.59	55.81
34.60	55.67
34.62	55.54
34.63	55.41
34.64	55.27
34.66	55.14
34.67	55.01
34.68	54.87
34.70	54.74
34.71	54.61
34.72	54.47
34.74	54.34
34.75	54.21
34.76	54.07
34.78	53.94
34.79	53.81
34.80	53.67
34.82	53.54
34.83	53.41
34.84	53.27
34.86	53.14
34.87	53.01
34.88	52.87
34.90	52.74
34.91	52.61
34.92	52.48
34.94	52.34
34.95	52.21
34.96	52.08
34.98	51.94
34.99	51.81
35.00	51.68
35.02	51.54
35.03	51.41
35.04	51.28
35.06	51.14
35.07	51.01
35.08	50.88
35.10	50.74
35.11	50.61
35.12	50.48
35.14	50.34
35.15	50.21
35.16	50.08
35.18	49.94
35.19	49.81
35.20	49.68
35.22	49.54
35.23	49.41
35.24	49.28
35.26	49.14
35.27	49.01
35.28	48.88
35.30	48.74
35.31	48.61
35.32	48.48
35.34	48.35
35.35	48.21
35.36	48.08
35.38	47.95
35.39	47.81
35.40	47.68
35.42	47.55
35.43	47.41
35.44	47.28
35.46	47.15
35.47	47.01
35.48	46.88
35.50	46.75
35.51	46.61
35.52	46.48
35.54	46.35
35.55	46.21
35.56	46.08
35.58	45.95
35.59	45.81
35.60	45.68
35.62	45.55
35.63	45.41
35.64	45.28
35.66	45.15
35.67	45.01
35.68	44.88
35.70	44.75
35.71	44.62
35.72	44.48
35.74	44.35
35.75	44.22
35.76	44.08
35.78	43.95
35.79	43.82
35.80	43.68
35.82	43.55
35.83	43.42
35.84	43.28
35.86	43.15
35.87	43.02
35.88	42.88
35.90	42.75
35.91	42.62
35.92	42.48
35.94	42.35
35.95	42.22
35.96	42.08
35.98	41.95
35.99	41.82
36.00	41.68
36.02	41.55
36.03	41.42
36.04	41.28
36.06	41.15
36.07	41.02
36.08	40.89
36.10	40.75
36.11	40.62
36.12	40.48
36.14	40.35
36.15	40.22
36.16	40.09
36.18	39.95
36.19	39.82
36.20	39.69
36.22	39.55
36.23	39.42
36.24	39.29
36.26	39.15
36.27	39.02
36.28	38.89
36.30	38.75
36.31	38.62
36.32	38.49
36.34	38.35
36.35	38.22
36.36	38.09
36.38	37.95
36.39	37.82
36.40	37.69
36.42	37.56
36.43	37.42
36.44	37.29
36.46	37.16
36.47	37.02
36.48	36.89
36.50	36.76
36.51	36.62
36.52	36.49
36.54	36.36
36.55	36.22
36.56	36.09
36.58	35.96
36.59	35.82
36.60	35.69
36.62	35.56
36.63	35.42
36.64	35.29
36.66	35.16
36.67	35.02
36.68	34.89
36.70	34.76
36.71	34.62
36.72	34.49
36.74	34.36
36.75	34.22
36.76	34.09
36.78	33.96
36.79	33.82
36.80	33.69
36.82	33.56
36.83	33.42
36.84	33.29
36.86	33.16
36.87	33.02
36.88	32.89
36.90	32.76
36.91	32.62
36.92	32.49
36.94	32.36
36.95	32.22
36.96	32.09
36.98	31.96
36.99	31.83
37.00	31.71

[step]
Ramp 10.00 °C/min to 210.00 °C
Time	Temperature	Heat Flow (Normalized)
min	°C	W/g
38.00	30.14
38.02	30.14
38.03	30.14
38.04	30.14
38.06	30.15
38.07	30.17
38.08	30.20
38.10	30.25
38.11	30.30
38.12	30.37
38.14	30.45
38.15	30.54
38.16	30.63
38.18	30.73
38.19	30.83
38.20	30.94
38.22	31.05
38.23	31.16
38.24	31.27
38.26	31.38
38.27	31.50
38.28	31.62
38.30	31.74
38.31	31.86
38.32	31.99
38.34	32.11
38.35	32.24
38.36	32.36
38.38	32.49
38.39	32.62
38.40	32.74
38.42	32.87
38.43	33.00
38.44	33.13
38.46	33.26
38.47	33.39
38.48	33.52
38.50	33.64
38.51	33.77
38.52	33.91
38.54	34.04
38.55	34.17
38.56	34.30
38.58	34.43
38.59	34.56
38.60	34.69
38.62	34.82
38.63	34.95
38.64	35.08
38.66	35.21
38.67	35.35
38.68	35.48
38.70	35.61
38.71	35.74
38.72	35.87
38.74	36.01
38.75	36.14
38.76	36.27
38.78	36.40
38.79	36.53
38.80	36.67
38.82	36.80
38.83	36.93
38.84	37.06
38.86	37.20
38.87	37.33
38.88	37.46
38.90	37.59
38.91	37.72
38.92	37.86
38.94	37.99
38.95	38.12
38.96	38.25
38.98	38.39
38.99	38.52
39.00	38.65
39.02	38.79
39.03	38.92
39.04	39.05
39.06	39.18
39.07	39.32
39.08	39.45
39.10	39.58
39.11	39.71
39.12	39.85
39.14	39.98
39.15	40.11
39.16	40.25
39.18	40.38
39.19	40.51
39.20	40.65
39.22	40.78
39.23	40.91
39.24	41.04
39.26	41.18
39.27	41.31
39.28	41.44
39.30	41.58
39.31	41.71
39.32	41.84
39.34	41.97
39.35	42.11
39.36	42.24
39.38	42.37
39.39	42.51
39.40	42.64
39.42	42.77
39.43	42.91
39.44	43.04
39.46	43.17
39.47	43.31
39.48	43.44
39.50	43.57
39.51	43.71
39.52	43.84
39.54	43.97
39.55	44.10
39.56	44.24
39.58	44.37
39.59	44.50
39.60	44.64
39.62	44.77
39.63	44.91
39.64	45.04
39.66	45.17
39.67	45.30
39.68	45.44
39.70	45.57
39.71	45.71
39.72	45.84
39.74	45.97
39.75	46.11
39.76	46.24
39.78	46.37
39.79	46.51
39.80	46.64
39.82	46.77
39.83	46.90
39.84	47.04
39.86	47.17
39.87	47.31
39.88	47.44
39.90	47.57
39.91	47.71
39.92	47.84
39.94	47.97
39.95	48.10
39.96	48.24
39.98	48.37
39.99	48.50
40.00	48.64
40.02	48.77
40.03	48.91
40.04	49.04
40.06	49.17
40.07	49.31
40.08	49.44
40.10	49.57
40.11	49.71
40.12	49.84
40.14	49.97
40.15	50.11
40.16	50.24
40.18	50.37
40.19	50.51
40.20	50.64
40.22	50.77
40.23	50.91
40.24	51.04
40.26	51.17
40.27	51.31
40.28	51.44
40.30	51.57
40.31	51.71
40.32	51.84
40.34	51.97
40.35	52.11
40.36	52.24
40.38	52.37
40.39	52.51
40.40	52.64
40.42	52.77
40.43	52.91
40.44	53.04
40.46	53.18
40.47	53.31
40.48	53.44
40.50	53.57
40.51	53.71
40.52	53.84
40.54	53.97
40.55	54.11
40.56	54.24
40.58	54.38
40.59	54.51
40.60	54.64
40.62	54.78
40.63	54.91
40.64	55.04
40.66	55.18
40.67	55.31
40.68	55.44
40.70	55.58
40.71	55.71
40.72	55.84
40.74	55.98
40.75	56.11
40.76	56.24
40.78	56.38
40.79	56.51
40.80	56.64
40.82	56.78
40.83	56.91
40.84	57.04
40.86	57.18
40.87	57.31
40.88	57.44
40.90	57.58
40.91	57.71
40.92	57.84
40.94	57.98
40.95	58.11
40.96	58.24
40.98	58.38
40.99	58.51
41.00	58.65
41.02	58.78
41.03	58.91
41.04	59.05
41.06	59.18
41.07	59.31
41.08	59.45
41.10	59.58
41.11	59.71
41.12	59.85
41.14	59.98
41.15	60.11
41.16	60.25
41.18	60.38
41.19	60.51
41.20	60.65
41.22	60.78
41.23	60.91
41.24	61.05
41.26	61.18
41.27	61.31
41.28	61.45
41.30	61.58
41.31	61.71
41.32	61.85
41.34	61.98
41.35	62.12
41.36	62.25
41.38	62.38
41.39	62.52
41.40	62.65
41.42	62.78
41.43	62.91
41.44	63.05
41.46	63.18
41.47	63.32
41.48	63.45
41.50	63.58
41.51	63.72
41.52	63.85
41.54	63.98
41.55	64.12
41.56	64.25
41.58	64.38
41.59	64.52
41.60	64.65
41.62	64.78
41.63	64.92
41.64	65.05
41.66	65.18
41.67	65.32
41.68	65.45
41.70	65.58
41.71	65.72
41.72	65.85
41.74	65.98
41.75	66.12
41.76	66.25
41.78	66.39
41.79	66.52
41.80	66.65
41.82	66.78
41.83	66.92
41.84	67.05
41.86	67.19
41.87	67.32
41.88	67.45
41.90	67.59
41.91	67.72
41.92	67.85
41.94	67.99
41.95	68.12
41.96	68.25
41.98	68.39
41.99	68.52
42.00	68.65
42.02	68.79
42.03	68.92
42.04	69.05
42.06	69.19
42.07	69.32
42.08	69.45
42.10	69.59
42.11	69.72
42.12	69.86
42.14	69.99
42.15	70.12
42.16	70.25
42.18	70.39
42.19	70.52
42.20	70.66
42.22	70.79
42.23	70.92
42.24	71.06
42.26	71.19
42.27	71.32
42.28	71.46
42.30	71.59
42.31	71.72
42.32	71.86
42.34	71.99
42.35	72.12
42.36	72.26
42.38	72.39
42.39	72.52
42.40	72.66
42.42	72.79
42.43	72.92
42.44	73.06
42.46	73.19
42.47	73.32
42.48	73.46
42.50	73.59
42.51	73.72
42.52	73.86
42.54	73.99
42.55	74.12
42.56	74.26
42.58	74.39
42.59	74.52
42.60	74.66
42.62	74.79
42.63	74.93
42.64	75.06
42.66	75.19
42.67	75.33
42.68	75.46
42.70	75.59
42.71	75.73
42.72	75.86
42.74	75.99
42.75	76.13
42.76	76.26
42.78	76.39
42.79	76.53
42.80	76.66
42.82	76.79
42.83	76.93
42.84	77.06
42.86	77.19
42.87	77.33
42.88	77.46
42.90	77.59
42.91	77.73
42.92	77.86
42.94	77.99
42.95	78.13
42.96	78.26
42.98	78.39
42.99	78.53
43.00	78.66
43.02	78.79
43.03	78.93
43.04	79.06
43.06	79.20
43.07	79.33
43.08	79.46
43.10	79.60
43.11	79.73
43.12	79.86
43.14	80.00
43.15	80.13
43.16	80.26
43.18	80.40
43.19	80.53
43.20	80.66
43.22	80.80
43.23	80.93
43.24	81.06
43.26	81.20
43.27	81.33
43.28	81.46
43.30	81.60
43.31	81.73
43.32	81.86
43.34	82.00
43.35	82.13
43.36	82.26
43.38	82.40
43.39	82.53
43.40	82.67
43.42	82.80
43.43	82.93
43.44	83.07
43.46	83.20
43.47	83.33
43.48	83.47
43.50	83.60
43.51	83.73
43.52	83.87
43.54	84.00
43.55	84.13
43.56	84.27
43.58	84.40
43.59	84.53
43.60	84.67
43.62	84.80
43.63	84.93
43.64	85.07
43.66	85.20
43.67	85.33
43.68	85.47
43.70	85.60
43.71	85.73
43.72	85.87
43.74	86.00
43.75	86.13
43.76	86.27
43.78	86.40
43.79	86.53
43.80	86.67
43.82	86.80
43.83	86.93
43.84	87.07
43.86	87.20
43.87	87.34
43.88	87.47
43.90	87.60
43.91	87.74
43.92	87.87
43.94	88.00
43.95	88.14
43.96	88.27
43.98	88.40
43.99	88.54
44.00	88.67
44.02	88.80
44.03	88.94
44.04	89.07
44.06	89.20
44.07	89.34
44.08	89.47
44.10	89.60
44.11	89.74
44.12	89.87
44.14	90.00
44.15	90.14
44.16	90.27
44.18	90.40
44.19	90.54
44.20	90.67
44.22	90.80
44.23	90.94
44.24	91.07
44.26	91.21
44.27	91.34
44.28	91.47
44.30	91.61
44.31	91.74
44.32	91.87
44.34	92.01
44.35	92.14
44.36	92.27
44.38	92.41
44.39	92.54
44.40	92.67
44.42	92.81
44.43	92.94
44.44	93.07
44.46	93.21
44.47	93.34
44.48	93.47
44.50	93.61
44.51	93.74
44.52	93.87
44.54	94.01
44.55	94.14
44.56	94.27
44.58	94.41
44.59	94.54
44.60	94.67
44.62	94.81
44.63	94.94
44.64	95.07
44.66	95.21
44.67	95.34
44.68	95.47
44.70	95.61
44.71	95.74
44.72	95.87
44.74	96.01
44.75	96.14
44.76	96.28
44.78	96.41
44.79	96.54
44.80	96.68
44.82	96.81
44.83	96.94
44.84	97.08
44.86	97.21
44.87	97.34
44.88	97.48
44.90	97.61
44.91	97.74
44.92	97.88
44.94	98.01
44.95	98.14
44.96	98.28
44.98	98.41
44.99	98.54
45.00	98.68
45.02	98.81
45.03	98.94
45.04	99.08
45.06	99.21
45.07	99.34
45.08	99.48
45.10	99.61
45.11	99.74
45.12	99.88
45.14	100.01
45.15	100.14
45.16	100.28
45.18	100.41
45.19	100.55
45.20	100.68
45.22	100.81
45.23	100.94
45.24	101.08
45.26	101.21
45.27	101.35
45.28	101.48
45.30	101.61
45.31	101.75
45.32	101.88
45.34	102.01
45.35	102.15
45.36	102.28
45.38	102.41
45.39	102.55
45.40	102.68
45.42	102.81
45.43	102.95
45.44	103.08
45.46	103.21
45.47	103.35
45.48	103.48
45.50	103.61
45.51	103.75
45.52	103.88
45.54	104.01
45.55	104.15
45.56	104.28
45.58	104.41
45.59	104.55
45.60	104.68
45.62	104.82
45.63	104.95
45.64	105.08
45.66	105.22
45.67	105.35
45.68	105.48
45.70	105.61
45.71	105.75
45.72	105.88
45.74	106.02
45.75	106.15
45.76	106.28
45.78	106.42
45.79	106.55
45.80	106.68
45.82	106.82
45.83	106.95
45.84	107.08
45.86	107.22
45.87	107.35
45.88	107.48
45.90	107.62
45.91	107.75
45.92	107.88
45.94	108.02
45.95	108.15
45.96	108.28
45.98	108.42
45.99	108.55
46.00	108.68
46.02	108.82
46.03	108.95
46.04	109.08
46.06	109.22
46.07	109.35
46.08	109.48
46.10	109.62
46.11	109.75
46.12	109.88
46.14	110.02
46.15	110.15
46.16	110.28
46.18	110.42
46.19	110.55
46.20	110.68
46.22	110.82
46.23	110.95
46.24	111.08
46.26	111.22
46.27	111.35
46.28	111.48
46.30	111.62
46.31	111.75
46.32	111.89
46.34	112.02
46.35	112.15
46.36	112.29
46.38	112.42
46.39	112.55
46.40	112.69
46.42	112.82
46.43	112.95
46.44	113.09
46.46	113.22
46.47	113.35
46.48	113.49
46.50	113.62
46.51	113.75
46.52	113.89
46.54	114.02
46.55	114.15
46.56	114.29
46.58	114.42
46.59	114.55
46.60	114.69
46.62	114.82
46.63	114.95
46.64	115.09
46.66	115.22
46.67	115.35
46.68	115.49
46.70	115.62
46.71	115.75
46.72	115.89
46.74	116.02
46.75	116.16
46.76	116.29
46.78	116.42
46.79	116.56
46.80	116.69
46.82	116.82
46.83	116.95
46.84	117.09
46.86	117.22
46.87	117.35
46.88	117.49
46.90	117.62
46.91	117.76
46.92	117.89
46.94	118.02
46.95	118.16
46.96	118.29
46.98	118.42
46.99	118.56
47.00	118.69
47.02	118.82
47.03	118.96
47.04	119.09
47.06	119.22
47.07	119.36
47.08	119.49
47.10	119.62
47.11	119.76
47.12	119.89
47.14	120.02
47.15	120.16
47.16	120.29
47.18	120.42
47.19	120.56
47.20	120.69
47.22	120.83
47.23	120.96
47.24	121.09
47.26	121.23
47.27	121.36
47.28	121.49
47.30	121.63
47.31	121.76
47.32	121.89
47.34	122.03
47.35	122.16
47.36	122.29
47.38	122.42
47.39	122.56
47.40	122.69
47.42	122.83
47.43	122.96
47.44	123.09
47.46	123.23
47.47	123.36
47.48	123.49
47.50	123.63
47.51	123.76
47.52	123.89
47.54	124.03
47.55	124.16
47.56	124.29
47.58	124.43
47.59	124.56
47.60	124.69
47.62	124.83
47.63	124.96
47.64	125.09
47.66	125.23
47.67	125.36
47.68	125.49
47.70	125.63
47.71	125.76
47.72	125.89
47.74	126.03
47.75	126.16
47.76	126.29
47.78	126.43
47.79	126.56
47.80	126.70
47.82	126.83
47.83	126.96
47.84	127.09
47.86	127.23
47.87	127.36
47.88	127.50
47.90	127.63
47.91	127.76
47.92	127.90
47.94	128.03
47.95	128.16
47.96	128.30
47.98	128.43
47.99	128.56
48.00	128.70
48.02	128.83
48.03	128.96
48.04	129.10
48.06	129.23
48.07	129.36
48.08	129.50
48.10	129.63
48.11	129.76
48.12	129.90
48.14	130.03
48.15	130.16
48.16	130.30
48.18	130.43
48.19	130.56
48.20	130.70
48.22	130.83
48.23	130.96
48.24	131.10
48.26	131.23
48.27	131.36
48.28	131.50
48.30	131.63
48.31	131.76
48.32	131.90
48.34	132.03
48.35	132.16
48.36	132.30
48.38	132.43
48.39	132.57
48.40	132.70
48.42	132.83
48.43	132.96
48.44	133.10
48.46	133.23
48.47	133.37
48.48	133.50
48.50	133.63
48.51	133.76
48.52	133.90
48.54	134.03
48.55	134.17
48.56	134.30
48.58	134.43
48.59	134.57
48.60	134.70
48.62	134.83
48.63	134.96
48.64	135.10
48.66	135.23
48.67	135.36
48.68	135.50
48.70	135.63
48.71	135.77
48.72	135.90
48.74	136.03
48.75	136.17
48.76	136.30
48.78	136.43
48.79	136.57
48.80	136.70
48.82	136.83
48.83	136.97
48.84	137.10
48.86	137.23
48.87	137.37
48.88	137.50
48.90	137.63
48.91	137.77
48.92	137.90
48.94	138.03
48.95	138.17
48.96	138.30
48.98	138.43
48.99	138.57
49.00	138.70
49.02	138.84
49.03	138.97
49.04	139.10
49.06	139.23
49.07	139.37
49.08	139.50
49.10	139.63
49.11	139.77
49.12	139.90
49.14	140.04
49.15	140.17
49.16	140.30
49.18	140.44
49.19	140.57
49.20	140.70
49.22	140.83
49.23	140.97
49.24	141.10
49.26	141.24
49.27	141.37
49.28	141.50
49.30	141.64
49.31	141.77
49.32	141.90
49.34	142.04
49.35	142.17
49.36	142.30
49.38	142.44
49.39	142.57
49.40	142.70
49.42	142.84
49.43	142.97
49.44	143.10
49.46	143.24
49.47	143.37
49.48	143.50
49.50	143.64
49.51	143.77
49.52	143.90
49.54	144.04
49.55	144.17
49.56	144.30
49.58	144.44
49.59	144.57
49.60	144.70
49.62	144.84
49.63	144.97
49.64	145.10
49.66	145.24
49.67	145.37
49.68	145.50
49.70	145.64
49.71	145.77
49.72	145.90
49.74	146.04
49.75	146.17
49.76	146.30
49.78	146.44
49.79	146.57
49.80	146.71
49.82	146.84
49.83	146.97
49.84	147.11
49.86	147.24
49.87	147.37
49.88	147.51
49.90	147.64
49.91	147.77
49.92	147.91
49.94	148.04
49.95	148.17
49.96	148.31
49.98	148.44
49.99	148.57
50.00	148.71
50.02	148.84
50.03	148.97
50.04	149.11
50.06	149.24
50.07	149.37
50.08	149.51
50.10	149.64
50.11	149.77
50.12	149.91
50.14	150.04
50.15	150.17
50.16	150.31
50.18	150.44
50.19	150.57
50.20	150.71
50.22	150.84
50.23	150.97
50.24	151.11
50.26	151.24
50.27	151.37
50.28	151.51
50.30	151.64
50.31	151.77
50.32	151.91
50.34	152.04
50.35	152.17
50.36	152.31
50.38	152.44
50.39	152.57
50.40	152.71
50.42	152.84
50.43	152.97
50.44	153.11
50.46	153.24
50.47	153.37
50.48	153.51
50.50	153.64
50.51	153.78
50.52	153.91
50.54	154.04
50.55	154.17
50.56	154.31
50.58	154.44
50.59	154.58
50.60	154.71
50.62	154.84
50.63	154.97
50.64	155.11
50.66	155.24
50.67	155.37
50.68	155.51
50.70	155.64
50.71	155.78
50.72	155.91
50.74	156.04
50.75	156.18
50.76	156.31
50.78	156.44
50.79	156.58
50.80	156.71
50.82	156.84
50.83	156.98
50.84	157.11
50.86	157.24
50.87	157.38
50.88	157.51
50.90	157.64
50.91	157.78
50.92	157.91
50.94	158.04
50.95	158.18
50.96	158.31
50.98	158.44
50.99	158.58
51.00	158.71
51.02	158.84
51.03	158.98
51.04	159.11
51.06	159.24
51.07	159.38
51.08	159.51
51.10	159.64
51.11	159.78
51.12	159.91
51.14	160.04
51.15	160.18
51.16	160.31
51.18	160.44
51.19	160.58
51.20	160.71
51.22	160.84
51.23	160.98
51.24	161.11
51.26	161.25
51.27	161.38
51.28	161.51
51.30	161.65
51.31	161.78
51.32	161.91
51.34	162.05
51.35	162.18
51.36	162.31
51.38	162.45
51.39	162.58
51.40	162.71
51.42	162.84
51.43	162.98
51.44	163.11
51.46	163.25
51.47	163.38
51.48	163.51
51.50	163.65
51.51	163.78
51.52	163.91
51.54	164.05
51.55	164.18
51.56	164.31
51.58	164.45
51.59	164.58
51.60	164.71
51.62	164.85
51.63	164.98
51.64	165.11
51.66	165.25
51.67	165.38
51.68	165.51
51.70	165.65
51.71	165.78
51.72	165.91
51.74	166.05
51.75	166.18
51.76	166.31
51.78	166.45
51.79	166.58
51.80	166.71
51.82	166.85
51.83	166.98
51.84	167.11
51.86	167.25
51.87	167.38
51.88	167.52
51.90	167.65
51.91	167.78
51.92	167.92
51.94	168.05
51.95	168.18
51.96	168.32
51.98	168.45
51.99	168.58
52.00	168.72
52.02	168.85
52.03	168.98
52.04	169.12
52.06	169.25
52.07	169.38
52.08	169.52
52.10	169.65
52.11	169.78
52.12	169.92
52.14	170.05
52.15	170.18
52.16	170.32
52.18	170.45
52.19	170.58
52.20	170.72
52.22	170.85
52.23	170.98
52.24	171.12
52.26	171.25
52.27	171.38
52.28	171.52
52.30	171.65
52.31	171.78
52.32	171.92
52.34	172.05
52.35	172.18
52.36	172.32
52.38	172.45
52.39	172.58
52.40	172.72
52.42	172.85
52.43	172.98
52.44	173.12
52.46	173.25
52.47	173.38
52.48	173.52
52.50	173.65
52.51	173.78
52.52	173.92
52.54	174.05
52.55	174.18
52.56	174.32
52.58	174.45
52.59	174.58
52.60	174.72
52.62	174.85
52.63	174.98
52.64	175.12
52.66	175.25
52.67	175.38
52.68	175.52
52.70	175.65
52.71	175.78
52.72	175.92
52.74	176.05
52.75	176.19
52.76	176.32
52.78	176.45
52.79	176.58
52.80	176.72
52.82	176.85
52.83	176.99
52.84	177.12
52.86	177.25
52.87	177.39
52.88	177.52
52.90	177.65
52.91	177.79
52.92	177.92
52.94	178.05
52.95	178.19
52.96	178.32
52.98	178.45
52.99	178.59
53.00	178.72
53.02	178.85
53.03	178.99
53.04	179.12
53.06	179.25
53.07	179.39
53.08	179.52
53.10	179.65
53.11	179.79
53.12	179.92
53.14	180.05
53.15	180.19
53.16	180.32
53.18	180.45
53.19	180.59
53.20	180.72
53.22	180.85
53.23	180.99
53.24	181.12
53.26	181.25
53.27	181.39
53.28	181.52
53.30	181.65
53.31	181.79
53.32	181.92
53.34	182.05
53.35	182.19
53.36	182.32
53.38	182.45
53.39	182.59
53.40	182.72
53.42	182.86
53.43	182.99
53.44	183.12
53.46	183.25
53.47	183.39
53.48	183.52
53.50	183.65
53.51	183.79
53.52	183.92
53.54	184.05
53.55	184.19
53.56	184.32
53.58	184.46
53.59	184.59
53.60	184.72
53.62	184.86
53.63	184.99
53.64	185.12
53.66	185.26
53.67	185.39
53.68	185.52
53.70	185.66
53.71	185.79
53.72	185.92
53.74	186.06
53.75	186.19
53.76	186.32
53.78	186.46
53.79	186.59
53.80	186.72
53.82	186.86
53.83	186.99
53.84	187.12
53.86	187.25
53.87	187.39
53.88	187.52
53.90	187.66
53.91	187.79
53.92	187.92
53.94	188.06
53.95	188.19
53.96	188.32
53.98	188.46
53.99	188.59
54.00	188.72
54.02	188.86
54.03	188.99
54.04	189.12
54.06	189.26
54.07	189.39
54.08	189.52
54.10	189.66
54.11	189.79
54.12	189.92
54.14	190.06
54.15	190.19
54.16	190.32
54.18	190.46
54.19	190.59
54.20	190.72
54.22	190.86
54.23	190.99
54.24	191.12
54.26	191.26
54.27	191.39
54.28	191.52
54.30	191.66
54.31	191.79
54.32	191.92
54.34	192.06
54.35	192.19
54.36	192.32
54.38	192.46
54.39	192.59
54.40	192.72
54.42	192.86
54.43	192.99
54.44	193.12
54.46	193.26
54.47	193.39
54.48	193.53
54.50	193.66
54.51	193.79
54.52	193.93
54.54	194.06
54.55	194.19
54.56	194.33
54.58	194.46
54.59	194.59
54.60	194.73
54.62	194.86
54.63	194.99
54.64	195.13
54.66	195.26
54.67	195.39
54.68	195.53
54.70	195.66
54.71	195.79
54.72	195.93
54.74	196.06
54.75	196.19
54.76	196.33
54.78	196.46
54.79	196.59
54.80	196.73
54.82	196.86
54.83	196.99
54.84	197.13
54.86	197.26
54.87	197.39
54.88	197.53
54.90	197.66
54.91	197.79
54.92	197.93
54.94	198.06
54.95	198.19
54.96	198.33
54.98	198.46
54.99	198.59
55.00	198.73
55.02	198.86
55.03	198.99
55.04	199.13
55.06	199.26
55.07	199.39
55.08	199.53
55.10	199.66
55.11	199.79
55.12	199.93
55.14	200.06
55.15	200.19
55.16	200.33
55.18	200.46
55.19	200.59
55.20	200.73
55.22	200.86
55.23	201.00
55.24	201.13
55.26	201.26
55.27	201.39
55.28	201.53
55.30	201.66
55.31	201.79
55.32	201.93
55.34	202.06
55.35	202.19
55.36	202.33
55.38	202.46
55.39	202.59
55.40	202.73
55.42	202.86
55.43	202.99
55.44	203.13
55.46	203.26
55.47	203.40
55.48	203.53
55.50	203.66
55.51	203.80
55.52	203.93
55.54	204.06
55.55	204.20
55.56	204.33
55.58	204.46
55.59	204.60
55.60	204.73
55.62	204.86
55.63	205.00
55.64	205.13
55.66	205.26
55.67	205.40
55.68	205.53
55.70	205.66
55.71	205.80
55.72	205.93
55.74	206.06
55.75	206.20
55.76	206.33
55.78	206.46
55.79	206.60
55.80	206.73
55.82	206.86
55.83	206.99
55.84	207.13
55.86	207.26
55.87	207.40
55.88	207.53
55.90	207.66
55.91	207.80
55.92	207.93
55.94	208.06
55.95	208.20
55.96	208.33
55.98	208.46
55.99	208.60
56.00