File: Data/2024_09_19_Water_CHM343_DSC.txt
Filename	2024_09_19_Water_CHM343_DSC
Instrument name	DSC2A-00468 (192.168.1.100)
Operator	CHM343
rundate	9/19/2024
Sample name	2024_09_19_Water_CHM343_DSC
proceduresegments	Equilibrate -50.00 °C; Ramp 10.00 °C/min to 50.00 °C; Isothermal 1.0 min; Ramp 10.00 °C/min to -50.00 °C
[File Parameters]
Run date	9/19/2024 8:44:29 PM
Trios version	5.1.1.46572
Original File Name	C:\ProgramData\TA Instruments\TRIOS\Data\2024_09_19_Water_CHM343_DSC.tri
Current File Name	D:\DSC2500\CHM343\2024_09_19_Water_CHM343_DSC.tri
[Procedure]
Procedure Name	CHM343_Fall2024_water
Sample Name	2024_09_19_Water_CHM343_DSC
Sample Mass	3.47 mg
Reference Sample Mass	0 mg
Pan Mass	54.2 mg
Pan Number	26
Reference Pan Mass	54 mg
Reference Pan Number	19
Pan Type	Aluminum
Comments	Water - H2O - Al Hermetic Sealed Pan, with ref Al pan.  ASU Online CHM343, Remote DSC experimental lab. Fall 2024.  Group Zoom Data Collection, Sept 19, 2024 from 5-7 pm.  TA Instruments DSC2500.
Project Name	Lab 4 - Fall 2024
Operator	CHM343
Test	Custom
Unload Max Temperature	30
Unload Min Temperature	30
Load Max Temperature	30
Load Min Temperature	30
Stop on Gas Flow Error	Yes
[Signal List]
Signal #1	Time (min)
Signal #2	Temperature (°C)
Signal #3	Heat Flow (mW)
Signal #4	Delta T (µV)
Signal #5	Delta Tzero (µV)
Signal #6	Tzero Temperature (°C)
Signal #7	Cell Purge (mL/min)
Signal #8	Heater Temp (°C)
Signal #9	Power Delivered (W)
Signal #10	Reference Junction Temperature (°C)
Signal #11	Flange Temperature (°C)
Signal #12	Heat Flow Phase (rad)
Signal #13	Total Heat Capacity (J/°C)
Signal #14	Heat Capacity (J/°C)
[Configuration]
Company Name	ASU
Instrument Name	DSC2A-00468
Instrument Type	DSC2500
Serial Number	DSC2A-00468
IP	192.168.1.100
Location of Instrument	MRRC
DisplayType	Unknown
Sample Interval 	0.1 s/pt
Selected Heat Flow	T4P
Exotherm Direction	Down
Cell Serial	DRC2-00792
Lid Type	Standard
Cooler	RCS 90
Leave Cooler on at End of Sequence	On
Gas 2	Nitrogen
Gas Selected	Channel 1
Flow Rate	50 mL/min
Secondary Purge	On
Licensed Heat Flow	Heat Flow T4P
Modulation Licensed	Yes
[Versions]
Common IDD Version	1
Cortex Version	VER 2.10.2.31
Driver	5.0.0.6
GDM Version	1.0.3.3
TouchscreenVersion	1.0.0.16145
FEP Version	1.2.1.21
FEP Bootloader	2.0.0.5
AutoSampler Version	2.1.1.26
Auto Sampler Bootloader	2.0.0.5
FCM Version	1.1.0.3
FCM Bootloader	2.0.0.5
[Experiment Logs]
Experiment Log Entry # 1	Equilibrate Segment -50 (C) Started
Experiment Log Entry # 3	Air Cool is off.
Experiment Log Entry # 5	Ramp Segment 10 C/min to 50 Started
Experiment Log Entry # 7	Isothermal Segment 1 min started
Experiment Log Entry # 9	Ramp Segment 10 C/min to -50 Started
[Method Log]
Method Log Entry # 1	Equilibrate -50 °C
Method Log Entry # 2	(Ramp 30957) Ramp 10 °C/minute to 50 °C
Method Log Entry # 3	Isothermal 1 minutes
Method Log Entry # 4	(Ramp 30959) Ramp 10 °C/minute to -50 °C
Cell Serial	DRC2-00792
[T1 Calibration]
Slope	-0.008529666
Offset	9.636258
Initial Temperature	98.23
GUID	f8bfdadc-4977-4fdf-ba6d-0ba9134940c3
[TZero Calibration]
Date Applied	11/29/2022 4:06:13 PM
Description	From -89.059 °C to 396.009 °C at 20.000°C/min
Gas Type	Nitrogen
Pan Type	None
Source Files 1	C:\Users\yargerlab\Desktop\DSC Data\General\TZero_calibration_11_29_22_2nd(2).tri
Source Files 2	C:\Users\yargerlab\Desktop\DSC Data\General\TZero_calibration_11_29_22_2nd(3).tri
Delta T Offset	13.05235
Delta T Slope	-0.007271007
Delta T0 Offset	-13.69128
Delta T0 Slope	0.06063341
[Temperature Calibration]
Date Applied	11/29/2022 7:12:28 PM
Description	From 106.590 °C to 186.590 °C at 10.000°C/min
Gas Type	Nitrogen
Pan Type	Tzero Aluminum Hermetic
Source Files 1	C:\Users\yargerlab\Desktop\DSC Data\General\Indium(6).tri
Measured 1	157.391
Known 1	156.598
[Cell Constant Calibration]
Date Applied	11/29/2022 7:12:29 PM
Description	From 106.590 °C to 186.590 °C at 10.000°C/min
Gas Type	Nitrogen
Pan Type	Tzero Aluminum Hermetic
Source Files 1	C:\Users\yargerlab\Desktop\DSC Data\General\Indium(6).tri
T4P KCell	1.006051
Onset Slope	63.26126 mW/°C
[Direct Cp Calibration]
Date Applied	11/30/2022 11:04:51 AM
Description	From -79.983 °C to 298.409 °C at 10.000°C/min
Gas Type	Nitrogen
Pan Type	Tzero Aluminum Hermetic
Source Files 1	C:\Users\yargerlab\Desktop\DSC Data\General\Sapphire_Heat_Capacity_11_30_22.tri
[Rev Cp Calibration]
Date Applied	11/30/2022 1:58:51 PM
Description	From -79.996 °C to 292.812 °C at 3.000°C/min
Gas Type	Nitrogen
Pan Type	Tzero Aluminum Hermetic
Source Files 1	C:\Users\yargerlab\Desktop\DSC Data\General\Sapphire_MDSC_Calibration_11_30_22.tri
[step]
Ramp 10.00 °C/min to 50.00 °C
Time	Temperature	Heat Flow (Normalized)	Heat Capacity (Normalized)
min	°C	W/g	J/(g.°C)
0.00	-49.71	-0.081	0.000
0.01	-49.71	-0.082	27.820
0.01	-49.71	-0.081	0.000
0.02	-49.72	-0.079	0.000
0.03	-49.72	-0.076	0.000
0.03	-49.72	-0.073	0.000
0.04	-49.73	-0.070	0.000
0.05	-49.73	-0.066	0.000
0.05	-49.72	-0.063	0.000
0.06	-49.72	-0.061	-2.231
0.07	-49.72	-0.058	-1.827
0.07	-49.71	-0.055	-1.515
0.08	-49.70	-0.053	-1.282
0.09	-49.69	-0.049	-1.064
0.09	-49.68	-0.044	-0.861
0.10	-49.66	-0.038	-0.670
0.11	-49.64	-0.032	-0.514
0.11	-49.62	-0.025	-0.371
0.12	-49.59	-0.017	-0.229
0.13	-49.56	-0.008	-0.104
0.13	-49.53	0.002	0.021
0.14	-49.50	0.014	0.158
0.15	-49.47	0.027	0.286
0.15	-49.43	0.037	0.373
0.16	-49.39	0.050	0.479
0.17	-49.35	0.064	0.587
0.17	-49.31	0.077	0.678
0.18	-49.26	0.090	0.765
0.19	-49.22	0.102	0.833
0.19	-49.17	0.116	0.917
0.20	-49.12	0.130	0.998
0.21	-49.07	0.140	1.047
0.21	-49.02	0.152	1.103
0.22	-48.97	0.164	1.166
0.23	-48.92	0.176	1.223
0.23	-48.87	0.187	1.274
0.24	-48.81	0.195	1.304
0.25	-48.76	0.205	1.350
0.25	-48.70	0.214	1.385
0.26	-48.65	0.222	1.424
0.27	-48.59	0.231	1.458
0.27	-48.53	0.237	1.479
0.28	-48.48	0.244	1.507
0.29	-48.42	0.249	1.527
0.29	-48.36	0.256	1.555
0.30	-48.30	0.263	1.581
0.31	-48.25	0.268	1.600
0.31	-48.19	0.271	1.608
0.32	-48.13	0.278	1.639
0.33	-48.07	0.283	1.655
0.33	-48.01	0.285	1.660
0.34	-47.95	0.291	1.686
0.35	-47.89	0.295	1.699
0.35	-47.83	0.297	1.706
0.36	-47.77	0.301	1.720
0.37	-47.70	0.305	1.738
0.37	-47.64	0.307	1.738
0.38	-47.58	0.310	1.750
0.39	-47.52	0.313	1.764
0.39	-47.46	0.315	1.770
0.40	-47.40	0.318	1.777
0.41	-47.33	0.319	1.781
0.41	-47.27	0.323	1.799
0.42	-47.21	0.326	1.806
0.43	-47.14	0.326	1.807
0.43	-47.08	0.328	1.811
0.44	-47.02	0.329	1.816
0.45	-46.96	0.332	1.826
0.45	-46.89	0.335	1.838
0.46	-46.83	0.336	1.842
0.47	-46.77	0.337	1.846
0.47	-46.70	0.338	1.849
0.48	-46.64	0.338	1.845
0.49	-46.57	0.340	1.849
0.49	-46.51	0.342	1.858
0.50	-46.45	0.342	1.857
0.51	-46.38	0.343	1.861
0.51	-46.32	0.344	1.867
0.52	-46.25	0.345	1.868
0.53	-46.19	0.346	1.871
0.53	-46.13	0.346	1.871
0.54	-46.06	0.347	1.871
0.55	-46.00	0.347	1.872
0.55	-45.93	0.348	1.874
0.56	-45.87	0.348	1.876
0.57	-45.80	0.349	1.878
0.57	-45.74	0.349	1.878
0.58	-45.67	0.350	1.879
0.59	-45.61	0.351	1.882
0.59	-45.54	0.351	1.882
0.60	-45.48	0.351	1.884
0.61	-45.41	0.352	1.885
0.61	-45.35	0.352	1.885
0.62	-45.29	0.352	1.885
0.63	-45.22	0.353	1.886
0.63	-45.16	0.353	1.887
0.64	-45.09	0.353	1.889
0.65	-45.02	0.354	1.890
0.65	-44.96	0.354	1.890
0.66	-44.90	0.354	1.890
0.67	-44.83	0.354	1.890
0.67	-44.77	0.355	1.892
0.68	-44.70	0.355	1.893
0.69	-44.63	0.355	1.895
0.69	-44.57	0.356	1.895
0.70	-44.50	0.356	1.895
0.71	-44.44	0.356	1.898
0.71	-44.37	0.357	1.898
0.72	-44.31	0.357	1.898
0.73	-44.24	0.357	1.898
0.73	-44.18	0.357	1.899
0.74	-44.11	0.357	1.900
0.75	-44.05	0.358	1.900
0.75	-43.98	0.358	1.901
0.76	-43.92	0.358	1.901
0.77	-43.85	0.358	1.901
0.77	-43.78	0.358	1.901
0.78	-43.72	0.358	1.902
0.79	-43.65	0.359	1.902
0.79	-43.59	0.359	1.903
0.80	-43.52	0.359	1.904
0.81	-43.46	0.359	1.904
0.81	-43.39	0.359	1.904
0.82	-43.32	0.360	1.905
0.83	-43.26	0.360	1.906
0.83	-43.20	0.360	1.907
0.84	-43.13	0.360	1.907
0.85	-43.06	0.360	1.907
0.85	-43.00	0.361	1.908
0.86	-42.93	0.361	1.908
0.87	-42.87	0.361	1.910
0.87	-42.80	0.361	1.910
0.88	-42.73	0.361	1.910
0.89	-42.67	0.362	1.911
0.89	-42.60	0.362	1.912
0.90	-42.54	0.362	1.913
0.91	-42.47	0.362	1.913
0.91	-42.40	0.362	1.913
0.92	-42.34	0.362	1.915
0.93	-42.27	0.363	1.916
0.93	-42.21	0.363	1.917
0.94	-42.14	0.363	1.918
0.95	-42.08	0.363	1.919
0.95	-42.01	0.363	1.919
0.96	-41.94	0.364	1.919
0.97	-41.88	0.364	1.920
0.97	-41.81	0.364	1.921
0.98	-41.75	0.364	1.922
0.99	-41.68	0.364	1.923
0.99	-41.61	0.364	1.923
1.00	-41.55	0.364	1.923
1.01	-41.48	0.365	1.924
1.01	-41.42	0.365	1.924
1.02	-41.35	0.365	1.925
1.03	-41.29	0.365	1.925
1.03	-41.22	0.365	1.926
1.04	-41.15	0.365	1.926
1.05	-41.09	0.365	1.927
1.05	-41.02	0.366	1.928
1.06	-40.95	0.366	1.929
1.07	-40.89	0.366	1.928
1.07	-40.82	0.366	1.929
1.08	-40.76	0.366	1.930
1.09	-40.69	0.366	1.930
1.09	-40.62	0.366	1.931
1.10	-40.56	0.366	1.931
1.11	-40.49	0.367	1.932
1.11	-40.43	0.367	1.933
1.12	-40.36	0.367	1.933
1.13	-40.29	0.367	1.934
1.13	-40.23	0.367	1.934
1.14	-40.16	0.367	1.934
1.15	-40.09	0.367	1.934
1.15	-40.03	0.367	1.935
1.16	-39.96	0.367	1.936
1.17	-39.90	0.368	1.937
1.17	-39.83	0.368	1.938
1.18	-39.76	0.368	1.938
1.19	-39.70	0.368	1.938
1.19	-39.63	0.368	1.939
1.20	-39.56	0.368	1.939
1.21	-39.50	0.368	1.939
1.21	-39.43	0.368	1.940
1.22	-39.37	0.369	1.941
1.23	-39.30	0.369	1.942
1.23	-39.23	0.369	1.942
1.24	-39.17	0.369	1.942
1.25	-39.10	0.369	1.942
1.25	-39.03	0.369	1.943
1.26	-38.97	0.369	1.943
1.27	-38.90	0.369	1.943
1.27	-38.83	0.369	1.943
1.28	-38.77	0.369	1.943
1.29	-38.70	0.369	1.944
1.29	-38.64	0.369	1.945
1.30	-38.57	0.370	1.945
1.31	-38.50	0.370	1.945
1.31	-38.44	0.370	1.945
1.32	-38.37	0.370	1.946
1.33	-38.30	0.370	1.947
1.33	-38.24	0.370	1.947
1.34	-38.17	0.370	1.947
1.35	-38.10	0.370	1.948
1.35	-38.04	0.370	1.949
1.36	-37.97	0.370	1.949
1.37	-37.91	0.370	1.949
1.37	-37.84	0.371	1.950
1.38	-37.77	0.371	1.950
1.39	-37.71	0.371	1.950
1.39	-37.64	0.371	1.951
1.40	-37.57	0.371	1.952
1.41	-37.51	0.371	1.953
1.41	-37.44	0.371	1.953
1.42	-37.37	0.371	1.954
1.43	-37.31	0.371	1.954
1.43	-37.24	0.371	1.954
1.44	-37.17	0.372	1.956
1.45	-37.11	0.372	1.956
1.45	-37.04	0.372	1.956
1.46	-36.97	0.372	1.957
1.47	-36.91	0.372	1.957
1.47	-36.84	0.372	1.958
1.48	-36.78	0.372	1.959
1.49	-36.71	0.372	1.959
1.49	-36.64	0.372	1.959
1.50	-36.58	0.372	1.959
1.51	-36.51	0.372	1.960
1.51	-36.44	0.372	1.960
1.52	-36.38	0.373	1.961
1.53	-36.31	0.373	1.961
1.53	-36.24	0.373	1.962
1.54	-36.18	0.373	1.962
1.55	-36.11	0.373	1.963
1.55	-36.04	0.373	1.963
1.56	-35.98	0.373	1.964
1.57	-35.91	0.373	1.964
1.57	-35.85	0.373	1.964
1.58	-35.78	0.373	1.965
1.59	-35.71	0.373	1.965
1.59	-35.65	0.373	1.966
1.60	-35.58	0.374	1.966
1.61	-35.51	0.374	1.965
1.61	-35.44	0.374	1.967
1.62	-35.38	0.374	1.968
1.63	-35.31	0.374	1.968
1.63	-35.25	0.374	1.969
1.64	-35.18	0.374	1.969
1.65	-35.11	0.374	1.970
1.65	-35.05	0.374	1.970
1.66	-34.98	0.374	1.970
1.67	-34.91	0.374	1.971
1.67	-34.85	0.374	1.971
1.68	-34.78	0.374	1.971
1.69	-34.71	0.374	1.971
1.69	-34.65	0.375	1.971
1.70	-34.58	0.375	1.972
1.71	-34.51	0.375	1.972
1.71	-34.45	0.375	1.972
1.72	-34.38	0.375	1.973
1.73	-34.31	0.375	1.973
1.73	-34.25	0.375	1.973
1.74	-34.18	0.375	1.974
1.75	-34.11	0.375	1.974
1.75	-34.05	0.375	1.974
1.76	-33.98	0.375	1.974
1.77	-33.91	0.375	1.974
1.77	-33.85	0.375	1.975
1.78	-33.78	0.375	1.976
1.79	-33.71	0.375	1.977
1.79	-33.65	0.376	1.977
1.80	-33.58	0.376	1.977
1.81	-33.51	0.376	1.978
1.81	-33.45	0.376	1.978
1.82	-33.38	0.376	1.978
1.83	-33.31	0.376	1.978
1.83	-33.25	0.376	1.979
1.84	-33.18	0.376	1.979
1.85	-33.12	0.376	1.979
1.85	-33.05	0.376	1.980
1.86	-32.98	0.376	1.980
1.87	-32.91	0.376	1.979
1.87	-32.85	0.376	1.980
1.88	-32.78	0.376	1.981
1.89	-32.72	0.376	1.982
1.89	-32.65	0.376	1.981
1.90	-32.58	0.376	1.981
1.91	-32.52	0.376	1.982
1.91	-32.45	0.376	1.983
1.92	-32.38	0.376	1.983
1.93	-32.32	0.377	1.984
1.93	-32.25	0.377	1.985
1.94	-32.18	0.377	1.984
1.95	-32.12	0.377	1.984
1.95	-32.05	0.377	1.985
1.96	-31.98	0.377	1.986
1.97	-31.91	0.377	1.986
1.97	-31.85	0.377	1.986
1.98	-31.78	0.377	1.986
1.99	-31.72	0.377	1.987
1.99	-31.65	0.377	1.987
2.00	-31.58	0.377	1.987
2.01	-31.51	0.377	1.987
2.01	-31.45	0.377	1.987
2.02	-31.38	0.377	1.988
2.03	-31.32	0.377	1.988
2.03	-31.25	0.377	1.988
2.04	-31.18	0.377	1.989
2.05	-31.11	0.377	1.989
2.05	-31.05	0.377	1.990
2.06	-30.98	0.377	1.990
2.07	-30.91	0.377	1.991
2.07	-30.85	0.378	1.992
2.08	-30.78	0.378	1.992
2.09	-30.71	0.378	1.991
2.09	-30.65	0.378	1.992
2.10	-30.58	0.378	1.993
2.11	-30.51	0.378	1.994
2.11	-30.45	0.378	1.994
2.12	-30.38	0.378	1.994
2.13	-30.32	0.378	1.994
2.13	-30.25	0.378	1.994
2.14	-30.18	0.378	1.994
2.15	-30.12	0.378	1.995
2.15	-30.05	0.378	1.996
2.16	-29.98	0.378	1.996
2.17	-29.91	0.378	1.995
2.17	-29.85	0.378	1.996
2.18	-29.78	0.378	1.997
2.19	-29.71	0.378	1.997
2.19	-29.65	0.378	1.997
2.20	-29.58	0.378	1.998
2.21	-29.52	0.378	1.998
2.21	-29.45	0.379	1.998
2.22	-29.38	0.379	1.998
2.23	-29.32	0.379	1.999
2.23	-29.25	0.379	1.999
2.24	-29.18	0.379	1.998
2.25	-29.12	0.379	1.999
2.25	-29.05	0.379	1.999
2.26	-28.98	0.379	2.000
2.27	-28.91	0.379	2.000
2.27	-28.85	0.379	2.000
2.28	-28.78	0.379	2.000
2.29	-28.72	0.379	2.001
2.29	-28.65	0.379	2.002
2.30	-28.58	0.379	2.001
2.31	-28.52	0.379	2.001
2.31	-28.45	0.379	2.002
2.32	-28.38	0.379	2.003
2.33	-28.32	0.379	2.003
2.33	-28.25	0.379	2.003
2.34	-28.18	0.379	2.004
2.35	-28.11	0.379	2.005
2.35	-28.05	0.380	2.005
2.36	-27.98	0.380	2.004
2.37	-27.91	0.380	2.005
2.37	-27.85	0.380	2.006
2.38	-27.78	0.380	2.006
2.39	-27.71	0.380	2.006
2.39	-27.65	0.380	2.006
2.40	-27.58	0.380	2.006
2.41	-27.51	0.380	2.006
2.41	-27.45	0.380	2.006
2.42	-27.38	0.380	2.007
2.43	-27.31	0.380	2.008
2.43	-27.25	0.380	2.009
2.44	-27.18	0.380	2.009
2.45	-27.12	0.380	2.010
2.45	-27.05	0.380	2.010
2.46	-26.98	0.380	2.010
2.47	-26.91	0.380	2.010
2.47	-26.85	0.380	2.011
2.48	-26.78	0.380	2.012
2.49	-26.71	0.381	2.012
2.49	-26.65	0.381	2.012
2.50	-26.58	0.381	2.013
2.51	-26.51	0.381	2.013
2.51	-26.45	0.381	2.013
2.52	-26.38	0.381	2.014
2.53	-26.31	0.381	2.014
2.53	-26.25	0.381	2.015
2.54	-26.18	0.381	2.014
2.55	-26.11	0.381	2.014
2.55	-26.05	0.381	2.014
2.56	-25.98	0.381	2.015
2.57	-25.91	0.381	2.016
2.57	-25.85	0.381	2.016
2.58	-25.78	0.381	2.016
2.59	-25.71	0.381	2.016
2.59	-25.65	0.381	2.017
2.60	-25.58	0.381	2.018
2.61	-25.51	0.381	2.018
2.61	-25.45	0.381	2.018
2.62	-25.38	0.381	2.018
2.63	-25.31	0.381	2.018
2.63	-25.25	0.382	2.019
2.64	-25.18	0.382	2.020
2.65	-25.11	0.382	2.020
2.65	-25.05	0.382	2.021
2.66	-24.98	0.382	2.020
2.67	-24.91	0.382	2.020
2.67	-24.85	0.382	2.021
2.68	-24.78	0.382	2.022
2.69	-24.71	0.382	2.022
2.69	-24.65	0.382	2.022
2.70	-24.58	0.382	2.022
2.71	-24.51	0.382	2.023
2.71	-24.45	0.382	2.023
2.72	-24.38	0.382	2.022
2.73	-24.31	0.382	2.023
2.73	-24.24	0.382	2.023
2.74	-24.18	0.382	2.024
2.75	-24.11	0.382	2.025
2.75	-24.05	0.382	2.025
2.76	-23.98	0.382	2.026
2.77	-23.91	0.383	2.026
2.77	-23.85	0.383	2.026
2.78	-23.78	0.383	2.026
2.79	-23.71	0.383	2.026
2.79	-23.65	0.383	2.026
2.80	-23.58	0.383	2.027
2.81	-23.51	0.383	2.028
2.81	-23.44	0.383	2.028
2.82	-23.38	0.383	2.028
2.83	-23.31	0.383	2.029
2.83	-23.24	0.383	2.030
2.84	-23.18	0.383	2.030
2.85	-23.11	0.383	2.030
2.85	-23.05	0.383	2.030
2.86	-22.98	0.383	2.031
2.87	-22.91	0.383	2.032
2.87	-22.84	0.383	2.032
2.88	-22.78	0.384	2.032
2.89	-22.71	0.384	2.031
2.89	-22.64	0.384	2.032
2.90	-22.58	0.384	2.033
2.91	-22.51	0.384	2.033
2.91	-22.44	0.384	2.034
2.92	-22.38	0.384	2.034
2.93	-22.31	0.384	2.035
2.93	-22.24	0.384	2.036
2.94	-22.18	0.384	2.036
2.95	-22.11	0.384	2.036
2.95	-22.04	0.384	2.037
2.96	-21.98	0.384	2.037
2.97	-21.91	0.384	2.038
2.97	-21.84	0.384	2.038
2.98	-21.78	0.384	2.038
2.99	-21.71	0.384	2.038
2.99	-21.64	0.384	2.039
3.00	-21.58	0.384	2.039
3.01	-21.51	0.384	2.039
3.01	-21.44	0.385	2.039
3.02	-21.38	0.385	2.040
3.03	-21.31	0.385	2.040
3.03	-21.24	0.385	2.041
3.04	-21.18	0.385	2.041
3.05	-21.11	0.385	2.042
3.05	-21.04	0.385	2.042
3.06	-20.98	0.385	2.042
3.07	-20.91	0.385	2.042
3.07	-20.84	0.385	2.042
3.08	-20.78	0.385	2.043
3.09	-20.71	0.385	2.043
3.09	-20.64	0.385	2.044
3.10	-20.58	0.385	2.045
3.11	-20.51	0.385	2.045
3.11	-20.44	0.385	2.045
3.12	-20.38	0.385	2.046
3.13	-20.31	0.385	2.046
3.13	-20.24	0.385	2.046
3.14	-20.18	0.386	2.047
3.15	-20.11	0.386	2.047
3.15	-20.04	0.386	2.047
3.16	-19.98	0.386	2.047
3.17	-19.91	0.386	2.047
3.17	-19.84	0.386	2.047
3.18	-19.78	0.386	2.048
3.19	-19.71	0.386	2.049
3.19	-19.64	0.386	2.050
3.20	-19.58	0.386	2.049
3.21	-19.51	0.386	2.049
3.21	-19.44	0.386	2.051
3.22	-19.38	0.386	2.051
3.23	-19.31	0.386	2.051
3.23	-19.24	0.386	2.052
3.24	-19.18	0.386	2.053
3.25	-19.11	0.387	2.053
3.25	-19.04	0.387	2.054
3.26	-18.98	0.387	2.054
3.27	-18.91	0.387	2.055
3.27	-18.84	0.387	2.055
3.28	-18.77	0.387	2.056
3.29	-18.71	0.387	2.056
3.29	-18.64	0.387	2.055
3.30	-18.57	0.387	2.056
3.31	-18.51	0.387	2.056
3.31	-18.44	0.387	2.057
3.32	-18.38	0.387	2.057
3.33	-18.31	0.387	2.057
3.33	-18.24	0.387	2.058
3.34	-18.18	0.387	2.058
3.35	-18.11	0.388	2.058
3.35	-18.04	0.388	2.059
3.36	-17.97	0.388	2.059
3.37	-17.91	0.388	2.059
3.37	-17.84	0.388	2.060
3.38	-17.78	0.388	2.061
3.39	-17.71	0.388	2.061
3.39	-17.64	0.388	2.061
3.40	-17.57	0.388	2.062
3.41	-17.51	0.388	2.063
3.41	-17.44	0.388	2.063
3.42	-17.37	0.388	2.063
3.43	-17.31	0.388	2.063
3.43	-17.24	0.388	2.063
3.44	-17.17	0.388	2.064
3.45	-17.11	0.389	2.065
3.45	-17.04	0.389	2.065
3.46	-16.97	0.389	2.065
3.47	-16.91	0.389	2.066
3.47	-16.84	0.389	2.066
3.48	-16.77	0.389	2.066
3.49	-16.71	0.389	2.066
3.49	-16.64	0.389	2.068
3.50	-16.57	0.389	2.068
3.51	-16.51	0.389	2.069
3.51	-16.44	0.389	2.069
3.52	-16.37	0.389	2.069
3.53	-16.31	0.389	2.070
3.53	-16.24	0.389	2.071
3.54	-16.17	0.389	2.072
3.55	-16.11	0.390	2.072
3.55	-16.04	0.390	2.072
3.56	-15.97	0.390	2.073
3.57	-15.91	0.390	2.074
3.57	-15.84	0.390	2.074
3.58	-15.77	0.390	2.073
3.59	-15.71	0.390	2.074
3.59	-15.64	0.390	2.074
3.60	-15.57	0.390	2.074
3.61	-15.51	0.390	2.075
3.61	-15.44	0.390	2.076
3.62	-15.37	0.390	2.077
3.63	-15.31	0.390	2.077
3.63	-15.24	0.390	2.078
3.64	-15.17	0.390	2.078
3.65	-15.11	0.390	2.078
3.65	-15.04	0.391	2.078
3.66	-14.97	0.391	2.079
3.67	-14.91	0.391	2.080
3.67	-14.84	0.391	2.080
3.68	-14.77	0.391	2.081
3.69	-14.70	0.391	2.081
3.69	-14.64	0.391	2.080
3.70	-14.57	0.391	2.080
3.71	-14.50	0.391	2.081
3.71	-14.44	0.391	2.083
3.72	-14.37	0.391	2.084
3.73	-14.31	0.391	2.084
3.73	-14.24	0.392	2.085
3.74	-14.17	0.392	2.086
3.75	-14.11	0.392	2.086
3.75	-14.04	0.392	2.086
3.76	-13.97	0.392	2.087
3.77	-13.90	0.392	2.087
3.77	-13.84	0.392	2.087
3.78	-13.77	0.392	2.088
3.79	-13.70	0.392	2.089
3.79	-13.64	0.392	2.088
3.80	-13.57	0.392	2.089
3.81	-13.50	0.392	2.090
3.81	-13.44	0.392	2.090
3.82	-13.37	0.393	2.091
3.83	-13.30	0.393	2.091
3.83	-13.24	0.393	2.092
3.84	-13.17	0.393	2.092
3.85	-13.10	0.393	2.093
3.85	-13.04	0.393	2.094
3.86	-12.97	0.393	2.094
3.87	-12.90	0.393	2.094
3.87	-12.84	0.393	2.096
3.88	-12.77	0.393	2.096
3.89	-12.70	0.393	2.096
3.89	-12.64	0.393	2.097
3.90	-12.57	0.393	2.097
3.91	-12.50	0.393	2.097
3.91	-12.44	0.393	2.097
3.92	-12.37	0.394	2.098
3.93	-12.30	0.394	2.098
3.93	-12.24	0.394	2.098
3.94	-12.17	0.394	2.098
3.95	-12.10	0.394	2.099
3.95	-12.04	0.394	2.100
3.96	-11.97	0.394	2.100
3.97	-11.90	0.394	2.100
3.97	-11.84	0.394	2.101
3.98	-11.77	0.394	2.101
3.99	-11.70	0.394	2.102
3.99	-11.64	0.394	2.103
4.00	-11.57	0.394	2.103
4.01	-11.50	0.395	2.104
4.01	-11.44	0.395	2.105
4.02	-11.37	0.395	2.105
4.03	-11.30	0.395	2.105
4.03	-11.24	0.395	2.105
4.04	-11.17	0.395	2.106
4.05	-11.10	0.395	2.106
4.05	-11.04	0.395	2.107
4.06	-10.97	0.395	2.108
4.07	-10.90	0.395	2.109
4.07	-10.84	0.395	2.108
4.08	-10.77	0.395	2.108
4.09	-10.70	0.395	2.109
4.09	-10.64	0.396	2.110
4.10	-10.57	0.396	2.111
4.11	-10.50	0.396	2.112
4.11	-10.44	0.396	2.112
4.12	-10.37	0.396	2.113
4.13	-10.30	0.396	2.113
4.13	-10.24	0.396	2.113
4.14	-10.17	0.396	2.114
4.15	-10.10	0.396	2.115
4.15	-10.04	0.396	2.115
4.16	-9.97	0.396	2.116
4.17	-9.90	0.396	2.116
4.17	-9.84	0.397	2.116
4.18	-9.77	0.397	2.116
4.19	-9.70	0.397	2.117
4.19	-9.64	0.397	2.118
4.20	-9.57	0.397	2.118
4.21	-9.50	0.397	2.119
4.21	-9.44	0.397	2.119
4.22	-9.37	0.397	2.120
4.23	-9.30	0.397	2.121
4.23	-9.24	0.397	2.121
4.24	-9.17	0.397	2.122
4.25	-9.10	0.397	2.122
4.25	-9.04	0.398	2.122
4.26	-8.97	0.398	2.122
4.27	-8.90	0.398	2.123
4.27	-8.83	0.398	2.124
4.28	-8.77	0.398	2.125
4.29	-8.70	0.398	2.125
4.29	-8.63	0.398	2.126
4.30	-8.57	0.398	2.126
4.31	-8.50	0.398	2.127
4.31	-8.44	0.399	2.128
4.32	-8.37	0.399	2.128
4.33	-8.30	0.399	2.128
4.33	-8.24	0.399	2.129
4.34	-8.17	0.399	2.130
4.35	-8.10	0.399	2.131
4.35	-8.03	0.399	2.131
4.36	-7.97	0.399	2.132
4.37	-7.90	0.399	2.133
4.37	-7.83	0.399	2.134
4.38	-7.77	0.400	2.135
4.39	-7.70	0.400	2.135
4.39	-7.63	0.400	2.135
4.40	-7.57	0.400	2.136
4.41	-7.50	0.400	2.136
4.41	-7.43	0.400	2.136
4.42	-7.37	0.400	2.138
4.43	-7.30	0.400	2.139
4.43	-7.23	0.401	2.140
4.44	-7.17	0.401	2.140
4.45	-7.10	0.401	2.141
4.45	-7.03	0.401	2.142
4.46	-6.97	0.401	2.143
4.47	-6.90	0.401	2.144
4.47	-6.83	0.401	2.144
4.48	-6.77	0.401	2.145
4.49	-6.70	0.401	2.146
4.49	-6.63	0.402	2.146
4.50	-6.57	0.402	2.148
4.51	-6.50	0.402	2.149
4.51	-6.43	0.402	2.150
4.52	-6.37	0.402	2.150
4.53	-6.30	0.402	2.152
4.53	-6.23	0.403	2.153
4.54	-6.17	0.403	2.154
4.55	-6.10	0.403	2.154
4.55	-6.03	0.403	2.155
4.56	-5.97	0.403	2.155
4.57	-5.90	0.403	2.157
4.57	-5.83	0.403	2.157
4.58	-5.77	0.404	2.158
4.59	-5.70	0.404	2.159
4.59	-5.63	0.404	2.160
4.60	-5.57	0.404	2.160
4.61	-5.50	0.404	2.163
4.61	-5.43	0.405	2.164
4.62	-5.37	0.405	2.164
4.63	-5.30	0.405	2.166
4.63	-5.23	0.405	2.168
4.64	-5.17	0.405	2.168
4.65	-5.10	0.406	2.170
4.65	-5.03	0.406	2.171
4.66	-4.97	0.406	2.172
4.67	-4.90	0.406	2.174
4.67	-4.83	0.407	2.175
4.68	-4.77	0.407	2.176
4.69	-4.70	0.407	2.179
4.69	-4.63	0.408	2.182
4.70	-4.57	0.408	2.184
4.71	-4.50	0.408	2.185
4.71	-4.43	0.409	2.187
4.72	-4.37	0.409	2.192
4.73	-4.30	0.410	2.196
4.73	-4.23	0.411	2.199
4.74	-4.17	0.411	2.202
4.75	-4.10	0.411	2.204
4.75	-4.03	0.412	2.207
4.76	-3.97	0.413	2.213
4.77	-3.90	0.414	2.218
4.77	-3.83	0.415	2.226
4.78	-3.77	0.417	2.240
4.79	-3.70	0.419	2.250
4.79	-3.63	0.420	2.257
4.80	-3.57	0.421	2.264
4.81	-3.50	0.423	2.276
4.81	-3.44	0.426	2.293
4.82	-3.37	0.430	2.312
4.83	-3.30	0.432	2.327
4.83	-3.24	0.434	2.341
4.84	-3.17	0.437	2.356
4.85	-3.10	0.439	2.372
4.85	-3.04	0.443	2.398
4.86	-2.97	0.447	2.420
4.87	-2.90	0.451	2.447
4.87	-2.84	0.457	2.490
4.88	-2.77	0.464	2.536
4.89	-2.71	0.469	2.573
4.89	-2.64	0.475	2.623
4.90	-2.57	0.485	2.699
4.91	-2.51	0.494	2.771
4.91	-2.44	0.499	2.831
4.92	-2.38	0.511	2.937
4.93	-2.31	0.528	3.079
4.93	-2.25	0.543	3.222
4.94	-2.18	0.562	3.401
4.95	-2.12	0.587	3.626
4.95	-2.05	0.617	3.898
4.96	-1.99	0.656	4.245
4.97	-1.93	0.705	4.686
4.97	-1.87	0.765	5.224
4.98	-1.81	0.839	5.888
4.99	-1.75	0.934	6.755
4.99	-1.69	1.054	7.850
5.00	-1.64	1.201	9.230
5.01	-1.59	1.377	10.929
5.01	-1.54	1.576	12.940
5.02	-1.50	1.793	15.245
5.03	-1.46	2.027	17.850
5.03	-1.43	2.272	20.740
5.04	-1.40	2.512	23.815
5.05	-1.37	2.747	27.047
5.05	-1.34	2.973	30.415
5.06	-1.31	3.187	33.865
5.07	-1.29	3.399	37.506
5.07	-1.27	3.602	41.251
5.08	-1.25	3.802	45.183
5.09	-1.22	3.999	49.254
5.09	-1.20	4.189	53.352
5.10	-1.18	4.377	57.510
5.11	-1.16	4.562	61.600
5.11	-1.14	4.742	65.410
5.12	-1.12	4.918	68.965
5.13	-1.10	5.090	72.210
5.13	-1.08	5.256	75.001
5.14	-1.05	5.418	77.347
5.15	-1.03	5.576	79.237
5.15	-1.01	5.728	80.728
5.16	-0.99	5.875	81.861
5.17	-0.96	6.013	82.685
5.17	-0.94	6.148	83.227
5.18	-0.91	6.281	83.462
5.19	-0.89	6.414	83.606
5.19	-0.86	6.548	83.705
5.20	-0.83	6.679	83.617
5.21	-0.80	6.801	83.285
5.21	-0.77	6.918	82.817
5.22	-0.74	7.034	82.326
5.23	-0.71	7.149	81.840
5.23	-0.68	7.263	81.338
5.24	-0.65	7.374	80.733
5.25	-0.62	7.482	80.105
5.25	-0.58	7.589	79.465
5.26	-0.55	7.692	78.810
5.27	-0.51	7.792	78.145
5.27	-0.48	7.890	77.498
5.28	-0.44	7.983	76.923
5.29	-0.40	8.073	76.633
5.29	-0.36	8.156	77.356
5.30	-0.32	8.231	79.719
5.31	-0.29	8.304	82.995
5.31	-0.24	8.378	86.336
5.32	-0.20	8.455	89.677
5.33	-0.16	8.534	92.546
5.33	-0.12	8.609	94.137
5.34	-0.08	8.675	94.450
5.35	-0.03	8.734	94.073
5.35	0.01	8.789	93.361
5.36	0.06	8.835	92.534
5.37	0.11	8.883	91.808
5.37	0.15	8.949	91.236
5.38	0.20	9.035	90.906
5.39	0.25	9.255	91.876
5.39	0.28	10.006	97.976
5.40	0.28	11.036	0.000
5.41	0.27	11.528	109.958
5.41	0.27	11.722	0.000
5.42	0.27	11.912	0.000
5.43	0.28	11.836	108.226
5.43	0.30	11.512	103.685
5.44	0.33	11.237	99.640
5.45	0.38	11.092	96.773
5.45	0.42	11.046	94.793
5.46	0.47	11.058	93.269
5.47	0.52	11.097	91.898
5.47	0.57	11.140	90.481
5.48	0.62	11.177	88.856
5.49	0.67	11.207	86.955
5.49	0.73	11.222	84.191
5.50	0.78	11.231	80.060
5.51	0.83	11.242	75.439
5.51	0.89	11.251	71.198
5.52	0.95	11.248	67.315
5.53	1.01	11.238	63.848
5.53	1.07	11.211	60.934
5.54	1.13	11.169	58.505
5.55	1.19	11.120	56.347
5.55	1.26	11.058	54.295
5.56	1.32	10.977	52.251
5.57	1.39	10.881	50.165
5.57	1.47	10.768	48.061
5.58	1.54	10.643	45.978
5.59	1.62	10.508	43.909
5.59	1.70	10.357	41.840
5.60	1.79	10.175	39.722
5.61	1.87	9.961	37.570
5.61	1.97	9.702	35.366
5.62	2.06	9.420	33.239
5.63	2.16	9.154	31.340
5.63	2.27	8.889	29.603
5.64	2.38	8.612	27.967
5.65	2.49	8.329	26.436
5.65	2.60	8.030	24.962
5.66	2.72	7.707	23.512
5.67	2.84	7.362	22.089
5.67	2.97	6.987	20.658
5.68	3.10	6.579	19.204
5.69	3.23	6.143	17.731
5.69	3.37	5.675	16.219
5.70	3.52	5.175	14.676
5.71	3.67	4.665	13.150
5.71	3.83	4.218	11.839
5.72	3.98	3.889	10.887
5.73	4.14	3.644	10.192
5.73	4.28	3.446	9.645
5.74	4.43	3.273	9.180
5.75	4.57	3.117	8.771
5.75	4.71	2.977	8.417
5.76	4.84	2.848	8.100
5.77	4.97	2.728	7.816
5.77	5.10	2.617	7.565
5.78	5.22	2.511	7.339
5.79	5.34	2.411	7.134
5.79	5.46	2.318	6.957
5.80	5.57	2.231	6.809
5.81	5.68	2.149	6.682
5.81	5.79	2.069	6.565
5.82	5.90	1.994	6.467
5.83	6.00	1.926	6.380
5.83	6.10	1.860	6.290
5.84	6.20	1.798	6.208
5.85	6.30	1.737	6.119
5.85	6.40	1.681	6.035
5.86	6.49	1.629	5.960
5.87	6.59	1.580	5.881
5.87	6.68	1.533	5.806
5.88	6.77	1.490	5.738
5.89	6.86	1.449	5.668
5.89	6.94	1.408	5.594
5.90	7.03	1.369	5.518
5.91	7.12	1.337	5.465
5.91	7.20	1.308	5.416
5.92	7.28	1.269	5.325
5.93	7.37	1.232	5.232
5.93	7.45	1.210	5.198
5.94	7.53	1.194	5.188
5.95	7.61	1.169	5.130
5.95	7.69	1.140	5.054
5.96	7.77	1.114	4.988
5.97	7.84	1.094	4.944
5.97	7.92	1.077	4.909
5.98	8.00	1.060	4.871
5.99	8.07	1.041	4.823
5.99	8.15	1.023	4.778
6.00	8.23	1.009	4.748
6.01	8.30	0.993	4.703
6.01	8.37	0.979	4.666
6.02	8.45	0.968	4.638
6.03	8.52	0.954	4.602
6.03	8.59	0.942	4.568
6.04	8.67	0.931	4.536
6.05	8.74	0.920	4.509
6.05	8.81	0.911	4.485
6.06	8.88	0.900	4.452
6.07	8.95	0.892	4.432
6.07	9.03	0.884	4.409
6.08	9.10	0.877	4.391
6.09	9.17	0.870	4.371
6.09	9.24	0.862	4.343
6.10	9.31	0.855	4.324
6.11	9.38	0.849	4.307
6.11	9.45	0.844	4.293
6.12	9.52	0.838	4.272
6.13	9.59	0.833	4.260
6.13	9.66	0.828	4.243
6.14	9.72	0.822	4.223
6.15	9.79	0.820	4.221
6.15	9.86	0.815	4.206
6.16	9.93	0.811	4.192
6.17	10.00	0.807	4.180
6.17	10.07	0.805	4.176
6.18	10.14	0.801	4.165
6.19	10.20	0.797	4.148
6.19	10.27	0.796	4.152
6.20	10.34	0.794	4.147
6.21	10.41	0.790	4.130
6.21	10.48	0.786	4.116
6.22	10.55	0.785	4.113
6.23	10.61	0.784	4.115
6.23	10.68	0.783	4.113
6.24	10.75	0.781	4.106
6.25	10.82	0.778	4.093
6.25	10.89	0.776	4.086
6.26	10.95	0.774	4.081
6.27	11.02	0.773	4.077
6.27	11.09	0.772	4.077
6.28	11.16	0.770	4.067
6.29	11.22	0.768	4.061
6.29	11.29	0.768	4.064
6.30	11.36	0.767	4.063
6.31	11.42	0.765	4.055
6.31	11.49	0.765	4.053
6.32	11.56	0.765	4.052
6.33	11.63	0.764	4.052
6.33	11.69	0.763	4.049
6.34	11.76	0.762	4.043
6.35	11.83	0.761	4.038
6.35	11.90	0.760	4.036
6.36	11.96	0.760	4.037
6.37	12.03	0.759	4.038
6.37	12.10	0.759	4.035
6.38	12.16	0.758	4.033
6.39	12.23	0.758	4.034
6.39	12.30	0.758	4.034
6.40	12.37	0.758	4.034
6.41	12.43	0.758	4.033
6.41	12.50	0.757	4.032
6.42	12.57	0.757	4.029
6.43	12.63	0.756	4.027
6.43	12.70	0.756	4.026
6.44	12.77	0.756	4.025
6.45	12.83	0.755	4.026
6.45	12.90	0.755	4.028
6.46	12.97	0.755	4.028
6.47	13.03	0.755	4.027
6.47	13.10	0.755	4.027
6.48	13.17	0.755	4.027
6.49	13.23	0.755	4.027
6.49	13.30	0.754	4.026
6.50	13.37	0.754	4.025
6.51	13.43	0.754	4.024
6.51	13.50	0.754	4.023
6.52	13.57	0.754	4.023
6.53	13.64	0.753	4.023
6.53	13.70	0.753	4.022
6.54	13.77	0.753	4.020
6.55	13.84	0.753	4.020
6.55	13.90	0.753	4.020
6.56	13.97	0.753	4.018
6.57	14.04	0.753	4.018
6.57	14.10	0.752	4.017
6.58	14.17	0.752	4.017
6.59	14.24	0.752	4.016
6.59	14.30	0.752	4.015
6.60	14.37	0.752	4.015
6.61	14.44	0.752	4.014
6.61	14.50	0.751	4.014
6.62	14.57	0.751	4.014
6.63	14.64	0.751	4.015
6.63	14.70	0.751	4.014
6.64	14.77	0.751	4.013
6.65	14.84	0.751	4.012
6.65	14.91	0.751	4.010
6.66	14.97	0.750	4.008
6.67	15.04	0.750	4.007
6.67	15.11	0.750	4.007
6.68	15.17	0.750	4.007
6.69	15.24	0.750	4.005
6.69	15.31	0.750	4.005
6.70	15.37	0.750	4.005
6.71	15.44	0.750	4.005
6.71	15.51	0.749	4.005
6.72	15.57	0.749	4.005
6.73	15.64	0.749	4.004
6.73	15.71	0.749	4.003
6.74	15.77	0.749	4.004
6.75	15.84	0.749	4.004
6.75	15.91	0.749	4.003
6.76	15.97	0.749	4.003
6.77	16.04	0.749	4.002
6.77	16.11	0.749	4.002
6.78	16.17	0.749	4.002
6.79	16.24	0.749	4.001
6.79	16.31	0.748	4.000
6.80	16.37	0.748	3.999
6.81	16.44	0.748	3.997
6.81	16.51	0.748	3.997
6.82	16.57	0.748	3.997
6.83	16.64	0.748	3.996
6.83	16.71	0.748	3.995
6.84	16.77	0.748	3.996
6.85	16.84	0.748	3.995
6.85	16.91	0.748	3.995
6.86	16.97	0.748	3.997
6.87	17.04	0.748	3.996
6.87	17.11	0.748	3.996
6.88	17.17	0.748	3.996
6.89	17.24	0.748	3.996
6.89	17.31	0.747	3.995
6.90	17.37	0.747	3.995
6.91	17.44	0.747	3.994
6.91	17.51	0.747	3.993
6.92	17.58	0.747	3.995
6.93	17.64	0.747	3.995
6.93	17.71	0.747	3.994
6.94	17.78	0.747	3.994
6.95	17.84	0.747	3.993
6.95	17.91	0.747	3.992
6.96	17.98	0.747	3.992
6.97	18.04	0.747	3.992
6.97	18.11	0.747	3.992
6.98	18.18	0.747	3.991
6.99	18.24	0.747	3.991
6.99	18.31	0.747	3.991
7.00	18.38	0.747	3.991
7.01	18.44	0.747	3.993
7.01	18.51	0.747	3.993
7.02	18.58	0.747	3.992
7.03	18.64	0.747	3.991
7.03	18.71	0.747	3.991
7.04	18.78	0.747	3.991
7.05	18.84	0.746	3.991
7.05	18.91	0.746	3.991
7.06	18.98	0.746	3.990
7.07	19.04	0.746	3.990
7.07	19.11	0.746	3.990
7.08	19.18	0.746	3.989
7.09	19.24	0.746	3.989
7.09	19.31	0.746	3.989
7.10	19.38	0.746	3.988
7.11	19.44	0.746	3.988
7.11	19.51	0.746	3.989
7.12	19.58	0.746	3.989
7.13	19.65	0.746	3.988
7.13	19.71	0.746	3.988
7.14	19.78	0.746	3.988
7.15	19.84	0.746	3.989
7.15	19.91	0.746	3.989
7.16	19.98	0.746	3.989
7.17	20.05	0.746	3.988
7.17	20.11	0.746	3.988
7.18	20.18	0.746	3.989
7.19	20.25	0.746	3.990
7.19	20.31	0.746	3.989
7.20	20.38	0.746	3.987
7.21	20.45	0.746	3.987
7.21	20.51	0.746	3.988
7.22	20.58	0.746	3.989
7.23	20.65	0.746	3.989
7.23	20.71	0.746	3.989
7.24	20.78	0.746	3.988
7.25	20.85	0.746	3.988
7.25	20.91	0.746	3.989
7.26	20.98	0.746	3.989
7.27	21.05	0.746	3.989
7.27	21.11	0.746	3.989
7.28	21.18	0.746	3.988
7.29	21.25	0.746	3.988
7.29	21.31	0.746	3.988
7.30	21.38	0.746	3.989
7.31	21.45	0.746	3.989
7.31	21.51	0.746	3.989
7.32	21.58	0.746	3.988
7.33	21.65	0.746	3.987
7.33	21.71	0.746	3.987
7.34	21.78	0.746	3.988
7.35	21.85	0.746	3.989
7.35	21.91	0.746	3.989
7.36	21.98	0.746	3.989
7.37	22.05	0.746	3.990
7.37	22.11	0.746	3.990
7.38	22.18	0.746	3.990
7.39	22.25	0.746	3.989
7.39	22.31	0.746	3.990
7.40	22.38	0.746	3.990
7.41	22.45	0.746	3.990
7.41	22.52	0.746	3.989
7.42	22.58	0.746	3.989
7.43	22.65	0.746	3.990
7.43	22.71	0.746	3.990
7.44	22.78	0.746	3.990
7.45	22.85	0.747	3.991
7.45	22.91	0.747	3.990
7.46	22.98	0.747	3.990
7.47	23.05	0.747	3.990
7.47	23.12	0.747	3.990
7.48	23.18	0.747	3.990
7.49	23.25	0.747	3.991
7.49	23.31	0.747	3.991
7.50	23.38	0.747	3.991
7.51	23.45	0.747	3.991
7.51	23.52	0.747	3.991
7.52	23.58	0.747	3.991
7.53	23.65	0.747	3.991
7.53	23.72	0.747	3.992
7.54	23.78	0.747	3.992
7.55	23.85	0.747	3.993
7.55	23.92	0.747	3.994
7.56	23.98	0.747	3.993
7.57	24.05	0.747	3.992
7.57	24.12	0.747	3.993
7.58	24.18	0.747	3.992
7.59	24.25	0.747	3.991
7.59	24.32	0.747	3.992
7.60	24.38	0.747	3.994
7.61	24.45	0.747	3.993
7.61	24.52	0.747	3.992
7.62	24.58	0.747	3.994
7.63	24.65	0.747	3.994
7.63	24.72	0.747	3.993
7.64	24.78	0.747	3.993
7.65	24.85	0.747	3.993
7.65	24.92	0.747	3.993
7.66	24.98	0.747	3.994
7.67	25.05	0.747	3.993
7.67	25.12	0.747	3.993
7.68	25.18	0.747	3.994
7.69	25.25	0.747	3.993
7.69	25.32	0.747	3.993
7.70	25.38	0.747	3.993
7.71	25.45	0.747	3.993
7.71	25.52	0.747	3.994
7.72	25.58	0.747	3.994
7.73	25.65	0.747	3.994
7.73	25.72	0.747	3.993
7.74	25.78	0.747	3.993
7.75	25.85	0.747	3.993
7.75	25.92	0.747	3.993
7.76	25.98	0.747	3.994
7.77	26.05	0.747	3.994
7.77	26.12	0.747	3.994
7.78	26.19	0.747	3.994
7.79	26.25	0.747	3.995
7.79	26.32	0.747	3.995
7.80	26.38	0.747	3.994
7.81	26.45	0.747	3.994
7.81	26.52	0.747	3.995
7.82	26.59	0.747	3.994
7.83	26.65	0.747	3.994
7.83	26.72	0.747	3.994
7.84	26.79	0.747	3.995
7.85	26.85	0.748	3.994
7.85	26.92	0.748	3.995
7.86	26.99	0.748	3.996
7.87	27.05	0.748	3.996
7.87	27.12	0.748	3.996
7.88	27.19	0.748	3.996
7.89	27.25	0.748	3.996
7.89	27.32	0.748	3.996
7.90	27.39	0.748	3.996
7.91	27.45	0.748	3.997
7.91	27.52	0.748	3.997
7.92	27.59	0.748	3.996
7.93	27.65	0.748	3.996
7.93	27.72	0.748	3.996
7.94	27.79	0.748	3.998
7.95	27.85	0.748	3.998
7.95	27.92	0.748	3.998
7.96	27.99	0.748	3.998
7.97	28.05	0.748	3.998
7.97	28.12	0.748	3.998
7.98	28.19	0.748	3.998
7.99	28.25	0.748	3.997
7.99	28.32	0.748	3.997
8.00	28.39	0.748	3.997
8.01	28.45	0.748	3.998
8.01	28.52	0.748	3.999
8.02	28.59	0.748	3.998
8.03	28.66	0.748	3.998
8.03	28.72	0.748	3.998
8.04	28.79	0.748	3.999
8.05	28.85	0.748	4.000
8.05	28.92	0.748	4.000
8.06	28.99	0.748	4.000
8.07	29.05	0.748	3.999
8.07	29.12	0.748	3.999
8.08	29.19	0.748	4.000
8.09	29.26	0.748	4.000
8.09	29.32	0.748	4.000
8.10	29.39	0.748	4.001
8.11	29.46	0.748	4.001
8.11	29.52	0.748	4.001
8.12	29.59	0.748	4.001
8.13	29.66	0.748	4.002
8.13	29.72	0.748	4.003
8.14	29.79	0.748	4.002
8.15	29.86	0.748	4.000
8.15	29.92	0.748	4.000
8.16	29.99	0.748	4.000
8.17	30.06	0.748	4.000
8.17	30.12	0.749	4.002
8.18	30.19	0.749	4.003
8.19	30.26	0.749	4.003
8.19	30.32	0.749	4.003
8.20	30.39	0.749	4.003
8.21	30.46	0.749	4.004
8.21	30.52	0.749	4.003
8.22	30.59	0.749	4.002
8.23	30.66	0.749	4.003
8.23	30.72	0.749	4.004
8.24	30.79	0.749	4.004
8.25	30.86	0.749	4.003
8.25	30.92	0.749	4.004
8.26	30.99	0.749	4.003
8.27	31.06	0.749	4.003
8.27	31.12	0.749	4.004
8.28	31.19	0.749	4.004
8.29	31.26	0.749	4.004
8.29	31.32	0.749	4.005
8.30	31.39	0.749	4.004
8.31	31.46	0.749	4.004
8.31	31.52	0.749	4.004
8.32	31.59	0.749	4.005
8.33	31.66	0.749	4.006
8.33	31.72	0.749	4.005
8.34	31.79	0.749	4.006
8.35	31.86	0.749	4.008
8.35	31.93	0.750	4.008
8.36	31.99	0.750	4.009
8.37	32.06	0.750	4.009
8.37	32.13	0.750	4.008
8.38	32.19	0.750	4.008
8.39	32.26	0.750	4.009
8.39	32.32	0.750	4.009
8.40	32.39	0.750	4.010
8.41	32.46	0.750	4.009
8.41	32.53	0.750	4.010
8.42	32.59	0.750	4.011
8.43	32.66	0.750	4.011
8.43	32.72	0.750	4.010
8.44	32.79	0.750	4.011
8.45	32.86	0.750	4.011
8.45	32.93	0.750	4.011
8.46	32.99	0.750	4.012
8.47	33.06	0.750	4.012
8.47	33.13	0.750	4.012
8.48	33.19	0.750	4.013
8.49	33.26	0.750	4.014
8.49	33.33	0.750	4.013
8.50	33.39	0.750	4.013
8.51	33.46	0.751	4.014
8.51	33.53	0.751	4.014
8.52	33.59	0.751	4.013
8.53	33.66	0.751	4.014
8.53	33.73	0.751	4.014
8.54	33.79	0.751	4.013
8.55	33.86	0.751	4.014
8.55	33.93	0.751	4.015
8.56	33.99	0.751	4.015
8.57	34.06	0.751	4.014
8.57	34.13	0.751	4.015
8.58	34.19	0.751	4.015
8.59	34.26	0.751	4.015
8.59	34.33	0.751	4.016
8.60	34.39	0.751	4.016
8.61	34.46	0.751	4.016
8.61	34.53	0.751	4.016
8.62	34.60	0.751	4.017
8.63	34.66	0.751	4.018
8.63	34.73	0.751	4.018
8.64	34.79	0.751	4.017
8.65	34.86	0.751	4.017
8.65	34.93	0.751	4.017
8.66	34.99	0.751	4.017
8.67	35.06	0.751	4.016
8.67	35.13	0.751	4.017
8.68	35.20	0.751	4.018
8.69	35.26	0.751	4.018
8.69	35.33	0.751	4.018
8.70	35.39	0.751	4.018
8.71	35.46	0.751	4.018
8.71	35.53	0.752	4.018
8.72	35.59	0.752	4.018
8.73	35.66	0.751	4.016
8.73	35.73	0.752	4.017
8.74	35.80	0.752	4.018
8.75	35.86	0.752	4.018
8.75	35.93	0.752	4.017
8.76	36.00	0.752	4.017
8.77	36.06	0.752	4.018
8.77	36.13	0.752	4.019
8.78	36.20	0.752	4.019
8.79	36.26	0.752	4.019
8.79	36.33	0.752	4.018
8.80	36.40	0.752	4.019
8.81	36.46	0.752	4.020
8.81	36.53	0.752	4.019
8.82	36.60	0.752	4.018
8.83	36.66	0.752	4.017
8.83	36.73	0.752	4.017
8.84	36.80	0.752	4.018
8.85	36.86	0.752	4.018
8.85	36.93	0.752	4.018
8.86	37.00	0.752	4.019
8.87	37.06	0.752	4.019
8.87	37.13	0.752	4.020
8.88	37.20	0.752	4.019
8.89	37.26	0.752	4.019
8.89	37.33	0.752	4.018
8.90	37.40	0.752	4.018
8.91	37.46	0.752	4.019
8.91	37.53	0.752	4.020
8.92	37.60	0.752	4.019
8.93	37.67	0.752	4.020
8.93	37.73	0.752	4.021
8.94	37.80	0.752	4.020
8.95	37.87	0.752	4.020
8.95	37.93	0.753	4.020
8.96	38.00	0.753	4.021
8.97	38.06	0.753	4.020
8.97	38.13	0.753	4.021
8.98	38.20	0.753	4.021
8.99	38.27	0.753	4.020
8.99	38.33	0.753	4.020
9.00	38.40	0.753	4.020
9.01	38.47	0.753	4.019
9.01	38.53	0.753	4.019
9.02	38.60	0.753	4.019
9.03	38.67	0.753	4.020
9.03	38.73	0.753	4.020
9.04	38.80	0.753	4.020
9.05	38.86	0.753	4.021
9.05	38.93	0.753	4.020
9.06	39.00	0.753	4.020
9.07	39.06	0.753	4.020
9.07	39.13	0.753	4.020
9.08	39.20	0.753	4.020
9.09	39.27	0.753	4.021
9.09	39.33	0.753	4.021
9.10	39.40	0.753	4.022
9.11	39.47	0.753	4.021
9.11	39.53	0.753	4.019
9.12	39.60	0.753	4.020
9.13	39.67	0.753	4.020
9.13	39.73	0.753	4.019
9.14	39.80	0.753	4.019
9.15	39.87	0.753	4.019
9.15	39.93	0.753	4.020
9.16	40.00	0.753	4.020
9.17	40.07	0.753	4.020
9.17	40.13	0.753	4.019
9.18	40.20	0.753	4.018
9.19	40.27	0.753	4.019
9.19	40.33	0.753	4.020
9.20	40.40	0.754	4.020
9.21	40.47	0.754	4.020
9.21	40.53	0.754	4.021
9.22	40.60	0.754	4.022
9.23	40.67	0.754	4.021
9.23	40.73	0.754	4.021
9.24	40.80	0.754	4.021
9.25	40.87	0.754	4.022
9.25	40.93	0.754	4.022
9.26	41.00	0.754	4.022
9.27	41.07	0.754	4.021
9.27	41.13	0.754	4.021
9.28	41.20	0.754	4.022
9.29	41.27	0.754	4.022
9.29	41.34	0.754	4.022
9.30	41.40	0.754	4.022
9.31	41.47	0.754	4.022
9.31	41.54	0.754	4.022
9.32	41.60	0.754	4.023
9.33	41.67	0.754	4.023
9.33	41.74	0.754	4.023
9.34	41.80	0.755	4.023
9.35	41.87	0.755	4.023
9.35	41.94	0.755	4.024
9.36	42.00	0.755	4.023
9.37	42.07	0.755	4.023
9.37	42.14	0.755	4.023
9.38	42.20	0.755	4.023
9.39	42.27	0.755	4.024
9.39	42.34	0.755	4.024
9.40	42.40	0.755	4.025
9.41	42.47	0.755	4.025
9.41	42.54	0.755	4.024
9.42	42.60	0.755	4.023
9.43	42.67	0.755	4.024
9.43	42.74	0.755	4.024
9.44	42.80	0.755	4.024
9.45	42.87	0.755	4.024
9.45	42.94	0.755	4.024
9.46	43.00	0.755	4.025
9.47	43.07	0.755	4.025
9.47	43.14	0.755	4.025
9.48	43.20	0.755	4.025
9.49	43.27	0.755	4.025
9.49	43.34	0.755	4.025
9.50	43.40	0.755	4.025
9.51	43.47	0.755	4.025
9.51	43.54	0.756	4.026
9.52	43.60	0.756	4.025
9.53	43.67	0.756	4.025
9.53	43.74	0.756	4.026
9.54	43.80	0.756	4.027
9.55	43.87	0.756	4.027
9.55	43.94	0.756	4.026
9.56	44.00	0.756	4.026
9.57	44.07	0.756	4.027
9.57	44.14	0.756	4.027
9.58	44.20	0.756	4.027
9.59	44.27	0.756	4.027
9.59	44.34	0.756	4.027
9.60	44.41	0.756	4.027
9.61	44.47	0.756	4.027
9.61	44.54	0.756	4.028
9.62	44.60	0.756	4.029
9.63	44.67	0.756	4.029
9.63	44.74	0.756	4.028
9.64	44.80	0.756	4.028
9.65	44.87	0.757	4.028
9.65	44.94	0.757	4.029
9.66	45.01	0.757	4.028
9.67	45.07	0.757	4.029
9.67	45.14	0.757	4.030
9.68	45.21	0.757	4.029
9.69	45.27	0.757	4.030
9.69	45.34	0.757	4.030
9.70	45.41	0.757	4.030
9.71	45.47	0.757	4.031
9.71	45.54	0.757	4.031
9.72	45.61	0.757	4.031
9.73	45.67	0.757	4.032
9.73	45.74	0.757	4.033
9.74	45.81	0.757	4.031
9.75	45.87	0.757	4.030
9.75	45.94	0.757	4.031
9.76	46.01	0.757	4.031
9.77	46.07	0.757	4.030
9.77	46.14	0.757	4.031
9.78	46.21	0.757	4.031
9.79	46.27	0.757	4.030
9.79	46.34	0.757	4.030
9.80	46.41	0.757	4.030
9.81	46.47	0.757	4.031
9.81	46.54	0.758	4.032
9.82	46.61	0.758	4.031
9.83	46.67	0.758	4.032
9.83	46.74	0.758	4.032
9.84	46.81	0.758	4.031
9.85	46.87	0.758	4.032
9.85	46.94	0.758	4.033
9.86	47.01	0.758	4.034
9.87	47.08	0.758	4.034
9.87	47.14	0.758	4.034
9.88	47.21	0.758	4.034
9.89	47.28	0.758	4.035
9.89	47.34	0.758	4.035
9.90	47.41	0.758	4.036
9.91	47.48	0.758	4.036
9.91	47.54	0.758	4.036
9.92	47.61	0.758	4.038
9.93	47.68	0.758	4.043
9.93	47.74	0.758	4.050
9.94	47.81	0.758	4.059
9.95	47.88	0.758	4.071
9.95	47.94	0.758	4.085
9.96	48.01	0.758	4.103
9.97	48.08	0.759	4.129
9.97	48.14	0.759	4.160
9.98	48.21	0.759	4.197
9.99	48.27	0.759	4.242
9.99	48.34	0.759	4.294

[step]
Ramp 10.00 °C/min to -50.00 °C
Time	Temperature	Heat Flow (Normalized)
min	°C	W/g
11.00	50.08	-0.027
11.00	50.08	-0.027
11.01	50.08	-0.027
11.02	50.08	-0.028
[...]
14.12	20.60	-0.822
14.12	20.53	-0.822
14.13	20.47	-0.822
14.13	20.40	-0.822
14.14	20.33	-0.822
14.15	20.27	-0.822
14.15	20.20	-0.822
14.16	20.13	-0.821
14.17	20.07	-0.821
14.18	20.00	-0.821
14.18	19.93	-0.821
14.19	19.87	-0.821
14.20	19.80	-0.821
14.20	19.73	-0.821
14.21	19.67	-0.821
14.22	19.60	-0.821
14.22	19.53	-0.821
14.23	19.47	-0.821
14.23	19.40	-0.821
14.24	19.33	-0.821
14.25	19.27	-0.820
14.25	19.20	-0.820
14.26	19.13	-0.820
14.27	19.07	-0.820
14.28	19.00	-0.820
14.28	18.93	-0.820
14.29	18.87	-0.820
14.30	18.80	-0.820
14.30	18.73	-0.820
14.31	18.67	-0.820
14.32	18.60	-0.820
14.32	18.54	-0.820
14.33	18.47	-0.820
14.33	18.40	-0.820
14.34	18.33	-0.819
14.35	18.27	-0.819
14.35	18.20	-0.819
14.36	18.14	-0.819
14.37	18.07	-0.819
14.38	18.00	-0.819
14.38	17.94	-0.819
14.39	17.87	-0.819
14.40	17.80	-0.819
14.40	17.74	-0.819
14.41	17.67	-0.819
14.42	17.60	-0.819
14.42	17.54	-0.819
14.43	17.47	-0.819
14.43	17.40	-0.819
14.44	17.34	-0.819
14.45	17.27	-0.819
14.45	17.20	-0.819
14.46	17.14	-0.819
14.47	17.07	-0.819
14.48	17.00	-0.818
14.48	16.94	-0.818
14.49	16.87	-0.818
14.50	16.80	-0.818
14.50	16.74	-0.818
14.51	16.67	-0.818
14.52	16.60	-0.818
14.52	16.54	-0.818
14.53	16.47	-0.818
14.53	16.40	-0.818
14.54	16.34	-0.818
14.55	16.27	-0.818
14.55	16.20	-0.818
14.56	16.14	-0.818
14.57	16.07	-0.818
14.58	16.01	-0.818
14.58	15.94	-0.818
14.59	15.87	-0.818
14.60	15.80	-0.818
14.60	15.74	-0.817
14.61	15.67	-0.817
14.62	15.61	-0.817
14.62	15.54	-0.817
14.63	15.47	-0.817
14.63	15.41	-0.817
14.64	15.34	-0.817
14.65	15.27	-0.817
14.65	15.21	-0.817
14.66	15.14	-0.817
14.67	15.07	-0.817
14.68	15.01	-0.817
14.68	14.94	-0.817
14.69	14.87	-0.817
14.70	14.81	-0.817
14.70	14.74	-0.817
14.71	14.68	-0.817
14.72	14.61	-0.817
14.72	14.54	-0.817
14.73	14.47	-0.817
14.73	14.41	-0.817
14.74	14.34	-0.817
14.75	14.27	-0.816
14.75	14.21	-0.816
14.76	14.14	-0.816
14.77	14.08	-0.816
14.78	14.01	-0.816
14.78	13.94	-0.816
14.79	13.88	-0.816
14.80	13.81	-0.816
14.80	13.74	-0.816
14.81	13.68	-0.816
14.82	13.61	-0.816
14.82	13.54	-0.816
14.83	13.48	-0.816
14.83	13.41	-0.816
14.84	13.34	-0.816
14.85	13.28	-0.816
14.85	13.21	-0.816
14.86	13.14	-0.816
14.87	13.08	-0.816
14.88	13.01	-0.816
14.88	12.94	-0.816
14.89	12.88	-0.816
14.90	12.81	-0.816
14.90	12.75	-0.815
14.91	12.68	-0.816
14.92	12.61	-0.816
14.92	12.54	-0.815
14.93	12.48	-0.815
14.93	12.41	-0.815
14.94	12.35	-0.815
14.95	12.28	-0.815
14.95	12.21	-0.815
14.96	12.14	-0.815
14.97	12.08	-0.815
14.98	12.01	-0.815
14.98	11.95	-0.815
14.99	11.88	-0.815
15.00	11.81	-0.815
15.00	11.75	-0.815
15.01	11.68	-0.815
15.02	11.61	-0.815
15.02	11.55	-0.815
15.03	11.48	-0.815
15.03	11.41	-0.815
15.04	11.35	-0.815
15.05	11.28	-0.815
15.05	11.21	-0.815
15.06	11.15	-0.815
15.07	11.08	-0.815
15.08	11.01	-0.815
15.08	10.95	-0.815
15.09	10.88	-0.815
15.10	10.81	-0.815
15.10	10.75	-0.815
15.11	10.68	-0.815
15.12	10.61	-0.815
15.12	10.55	-0.815
15.13	10.48	-0.815
15.13	10.42	-0.815
15.14	10.35	-0.815
15.15	10.28	-0.814
15.15	10.22	-0.814
15.16	10.15	-0.814
15.17	10.08	-0.814
15.18	10.02	-0.814
15.18	9.95	-0.814
15.19	9.88	-0.814
15.20	9.82	-0.814
15.20	9.75	-0.814
15.21	9.68	-0.814
15.22	9.62	-0.814
15.22	9.55	-0.814
15.23	9.48	-0.814
15.23	9.42	-0.814
15.24	9.35	-0.814
15.25	9.28	-0.814
15.25	9.22	-0.814
15.26	9.15	-0.814
15.27	9.08	-0.814
15.28	9.02	-0.814
15.28	8.95	-0.814
15.29	8.89	-0.814
15.30	8.82	-0.814
15.30	8.75	-0.814
15.31	8.69	-0.814
15.32	8.62	-0.814
15.32	8.55	-0.814
15.33	8.49	-0.814
15.33	8.42	-0.814
15.34	8.35	-0.814
15.35	8.29	-0.813
15.35	8.22	-0.813
15.36	8.15	-0.813
15.37	8.09	-0.813
15.38	8.02	-0.813
15.38	7.95	-0.813
15.39	7.89	-0.813
15.40	7.82	-0.813
15.40	7.75	-0.813
15.41	7.69	-0.813
15.42	7.62	-0.813
15.42	7.55	-0.813
15.43	7.49	-0.813
15.43	7.42	-0.813
15.44	7.36	-0.813
15.45	7.29	-0.813
15.45	7.22	-0.813
15.46	7.16	-0.813
15.47	7.09	-0.813
15.48	7.02	-0.813
15.48	6.96	-0.813
15.49	6.89	-0.813
15.50	6.82	-0.813
15.50	6.76	-0.813
15.51	6.69	-0.813
15.52	6.62	-0.813
15.52	6.56	-0.813
15.53	6.49	-0.813
15.53	6.43	-0.813
15.54	6.36	-0.813
15.55	6.29	-0.813
15.55	6.22	-0.813
15.56	6.16	-0.813
15.57	6.09	-0.813
15.58	6.02	-0.813
15.58	5.96	-0.813
15.59	5.89	-0.813
15.60	5.82	-0.813
15.60	5.76	-0.813
15.61	5.69	-0.813
15.62	5.63	-0.813
15.62	5.56	-0.813
15.63	5.49	-0.813
15.63	5.43	-0.813
15.64	5.36	-0.813
15.65	5.29	-0.813
15.65	5.23	-0.813
15.66	5.16	-0.813
15.67	5.09	-0.813
15.68	5.03	-0.813
15.68	4.96	-0.813
15.69	4.89	-0.813
15.70	4.83	-0.813
15.70	4.76	-0.813
15.71	4.69	-0.812
15.72	4.63	-0.812
15.72	4.56	-0.812
15.73	4.49	-0.812
15.73	4.43	-0.812
15.74	4.36	-0.812
15.75	4.29	-0.812
15.75	4.23	-0.812
15.76	4.16	-0.812
15.77	4.09	-0.812
15.78	4.03	-0.812
15.78	3.96	-0.812
15.79	3.89	-0.812
15.80	3.83	-0.812
15.80	3.76	-0.812
15.81	3.69	-0.812
15.82	3.63	-0.813
15.82	3.56	-0.812
15.83	3.49	-0.812
15.83	3.43	-0.812
15.84	3.36	-0.812
15.85	3.30	-0.812
15.85	3.23	-0.812
15.86	3.16	-0.812
15.87	3.09	-0.812
15.88	3.03	-0.813
15.88	2.96	-0.813
15.89	2.90	-0.813
15.90	2.83	-0.813
15.90	2.76	-0.813
15.91	2.70	-0.813
15.92	2.63	-0.813
15.92	2.56	-0.813
15.93	2.50	-0.813
15.93	2.43	-0.813
15.94	2.36	-0.813
15.95	2.29	-0.813
15.95	2.23	-0.813
15.96	2.16	-0.813
15.97	2.10	-0.813
15.98	2.03	-0.813
15.98	1.96	-0.813
15.99	1.90	-0.813
16.00	1.83	-0.813
16.00	1.76	-0.813
16.01	1.70	-0.813
16.02	1.63	-0.813
16.02	1.56	-0.813
16.03	1.50	-0.813
16.03	1.43	-0.813
16.04	1.36	-0.813
16.05	1.30	-0.813
16.05	1.23	-0.813
16.06	1.16	-0.813
16.07	1.10	-0.813
16.08	1.03	-0.813
16.08	0.96	-0.813
16.09	0.90	-0.813
16.10	0.83	-0.813
16.10	0.76	-0.813
16.11	0.70	-0.813
16.12	0.63	-0.813
16.12	0.56	-0.813
16.13	0.50	-0.813
16.13	0.43	-0.813
16.14	0.36	-0.813
16.15	0.30	-0.813
16.15	0.23	-0.813
16.16	0.16	-0.813
16.17	0.09	-0.813
16.18	0.03	-0.813
16.18	-0.04	-0.813
16.19	-0.11	-0.813
16.20	-0.17	-0.813
16.20	-0.24	-0.813
16.21	-0.31	-0.813
16.22	-0.37	-0.813
16.22	-0.44	-0.813
16.23	-0.51	-0.814
16.23	-0.57	-0.814
16.24	-0.64	-0.814
16.25	-0.70	-0.814
16.25	-0.77	-0.814
16.26	-0.84	-0.814
16.27	-0.91	-0.814
16.28	-0.97	-0.814
16.28	-1.04	-0.814
16.29	-1.10	-0.814
16.30	-1.17	-0.814
16.30	-1.24	-0.814
16.31	-1.31	-0.814
16.32	-1.37	-0.814
16.32	-1.44	-0.814
16.33	-1.50	-0.814
16.33	-1.57	-0.814
16.34	-1.64	-0.814
16.35	-1.71	-0.814
16.35	-1.77	-0.814
16.36	-1.84	-0.814
16.37	-1.90	-0.814
16.38	-1.97	-0.814
16.38	-2.04	-0.814
16.39	-2.11	-0.814
16.40	-2.17	-0.814
16.40	-2.24	-0.814
16.41	-2.31	-0.814
16.42	-2.37	-0.814
16.42	-2.44	-0.814
16.43	-2.51	-0.814
16.43	-2.57	-0.814
16.44	-2.64	-0.814
16.45	-2.71	-0.814
16.45	-2.77	-0.814
16.46	-2.84	-0.814
16.47	-2.91	-0.815
16.48	-2.97	-0.815
16.48	-3.04	-0.815
16.49	-3.11	-0.815
16.50	-3.17	-0.815
16.50	-3.24	-0.815
16.51	-3.31	-0.815
16.52	-3.37	-0.815
16.52	-3.44	-0.815
16.53	-3.51	-0.815
16.53	-3.57	-0.815
16.54	-3.64	-0.815
16.55	-3.71	-0.815
16.55	-3.77	-0.815
16.56	-3.84	-0.815
16.57	-3.91	-0.815
16.58	-3.97	-0.815
16.58	-4.04	-0.815
16.59	-4.11	-0.815
16.60	-4.17	-0.815
16.60	-4.24	-0.815
16.61	-4.31	-0.815
16.62	-4.37	-0.815
16.62	-4.44	-0.815
16.63	-4.51	-0.815
16.63	-4.57	-0.816
16.64	-4.64	-0.816
16.65	-4.71	-0.816
16.65	-4.77	-0.816
16.66	-4.84	-0.816
16.67	-4.91	-0.816
16.68	-4.97	-0.816
16.68	-5.04	-0.816
16.69	-5.11	-0.816
16.70	-5.17	-0.816
16.70	-5.24	-0.816
16.71	-5.31	-0.816
16.72	-5.37	-0.816
16.72	-5.44	-0.816
16.73	-5.51	-0.816
16.73	-5.57	-0.816
16.74	-5.64	-0.816
16.75	-5.71	-0.816
16.75	-5.77	-0.816
16.76	-5.84	-0.816
16.77	-5.91	-0.816
16.78	-5.97	-0.816
16.78	-6.04	-0.816
16.79	-6.11	-0.816
16.80	-6.17	-0.816
16.80	-6.24	-0.816
16.81	-6.31	-0.817
16.82	-6.37	-0.817
16.82	-6.44	-0.817
16.83	-6.51	-0.817
16.83	-6.57	-0.817
16.84	-6.64	-0.817
16.85	-6.71	-0.817
16.85	-6.77	-0.817
16.86	-6.84	-0.817
16.87	-6.91	-0.817
16.88	-6.98	-0.817
16.88	-7.04	-0.817
16.89	-7.11	-0.817
16.90	-7.17	-0.817
16.90	-7.24	-0.817
16.91	-7.31	-0.817
16.92	-7.38	-0.817
16.92	-7.44	-0.817
16.93	-7.51	-0.817
16.93	-7.58	-0.817
16.94	-7.64	-0.817
16.95	-7.71	-0.817
16.95	-7.78	-0.817
16.96	-7.84	-0.817
16.97	-7.91	-0.817
16.98	-7.98	-0.817
16.98	-8.04	-0.817
16.99	-8.11	-0.817
17.00	-8.18	-0.818
17.00	-8.24	-0.818
17.01	-8.31	-0.818
17.02	-8.37	-0.818
17.02	-8.44	-0.818
17.03	-8.51	-0.818
17.03	-8.58	-0.818
17.04	-8.64	-0.818
17.05	-8.71	-0.818
17.05	-8.78	-0.818
17.06	-8.84	-0.818
17.07	-8.91	-0.818
17.08	-8.98	-0.818
17.08	-9.04	-0.818
17.09	-9.11	-0.818
17.09	-9.17	-0.818
17.10	-9.24	-0.818
17.11	-9.31	-0.818
17.12	-9.38	-0.818
17.12	-9.44	-0.818
17.13	-9.51	-0.818
17.13	-9.58	-0.819
17.14	-9.64	-0.819
17.15	-9.71	-0.819
17.16	-9.78	-0.819
17.16	-9.84	-0.819
17.17	-9.91	-0.819
17.18	-9.98	-0.819
17.18	-10.04	-0.819
17.19	-10.11	-0.819
17.19	-10.18	-0.819
17.20	-10.24	-0.819
17.21	-10.31	-0.819
17.22	-10.38	-0.819
17.22	-10.44	-0.819
17.23	-10.51	-0.819
17.23	-10.58	-0.819
17.24	-10.64	-0.819
17.25	-10.71	-0.819
17.26	-10.78	-0.819
17.26	-10.84	-0.819
17.27	-10.91	-0.820
17.28	-10.98	-0.820
17.28	-11.04	-0.820
17.29	-11.11	-0.820
17.29	-11.18	-0.820
17.30	-11.24	-0.820
17.31	-11.31	-0.820
17.32	-11.38	-0.820
17.32	-11.44	-0.820
17.33	-11.51	-0.820
17.33	-11.58	-0.820
17.34	-11.64	-0.820
17.35	-11.71	-0.821
17.36	-11.78	-0.821
17.36	-11.84	-0.821
17.37	-11.91	-0.821
17.38	-11.98	-0.821
17.38	-12.04	-0.821
17.39	-12.11	-0.821
17.39	-12.18	-0.821
17.40	-12.24	-0.821
17.41	-12.31	-0.821
17.42	-12.38	-0.821
17.42	-12.44	-0.821
17.43	-12.51	-0.821
17.43	-12.58	-0.821
17.44	-12.64	-0.822
17.45	-12.71	-0.822
17.46	-12.78	-0.822
17.46	-12.84	-0.822
17.47	-12.91	-0.822
17.48	-12.98	-0.822
17.48	-13.04	-0.822
17.49	-13.11	-0.822
17.49	-13.18	-0.822
17.50	-13.24	-0.822
17.51	-13.31	-0.822
17.52	-13.38	-0.822
17.52	-13.44	-0.822
17.53	-13.51	-0.822
17.53	-13.58	-0.822
17.54	-13.64	-0.823
17.55	-13.71	-0.823
17.56	-13.78	-0.823
17.56	-13.84	-0.823
17.57	-13.91	-0.823
17.58	-13.98	-0.823
17.58	-14.04	-0.823
17.59	-14.11	-0.823
17.59	-14.18	-0.823
17.60	-14.24	-0.823
17.61	-14.31	-0.823
17.62	-14.38	-0.824
17.62	-14.44	-0.824
17.63	-14.51	-0.824
17.63	-14.58	-0.824
17.64	-14.64	-0.824
17.65	-14.71	-0.824
17.66	-14.78	-0.824
17.66	-14.84	-0.824
17.67	-14.91	-0.824
17.68	-14.98	-0.824
17.68	-15.04	-0.824
17.69	-15.11	-0.825
17.69	-15.18	-0.825
17.70	-15.24	-0.825
17.71	-15.31	-0.825
17.72	-15.38	-0.825
17.72	-15.44	-0.825
17.73	-15.51	-0.825
17.73	-15.57	-0.825
17.74	-15.64	-0.825
17.75	-15.71	-0.826
17.76	-15.78	-0.826
17.76	-15.84	-0.826
17.77	-15.91	-0.826
17.78	-15.98	-0.826
17.78	-16.04	-0.826
17.79	-16.11	-0.826
17.79	-16.18	-0.826
17.80	-16.24	-0.826
17.81	-16.31	-0.826
17.82	-16.38	-0.827
17.82	-16.44	-0.827
17.83	-16.51	-0.827
17.83	-16.58	-0.827
17.84	-16.64	-0.827
17.85	-16.71	-0.828
17.86	-16.78	-0.828
17.86	-16.84	-0.828
17.87	-16.91	-0.828
17.88	-16.98	-0.828
17.88	-17.04	-0.828
17.89	-17.11	-0.828
17.89	-17.18	-0.829
17.90	-17.24	-0.829
17.91	-17.31	-0.829
17.92	-17.38	-0.829
17.92	-17.44	-0.829
17.93	-17.51	-0.829
17.93	-17.58	-0.829
17.94	-17.64	-0.829
17.95	-17.71	-0.829
17.96	-17.77	-0.830
17.96	-17.84	-0.830
17.97	-17.91	-0.830
17.98	-17.97	-0.830
17.98	-18.04	-0.830
17.99	-18.11	-0.830
17.99	-18.17	-0.830
18.00	-18.24	-0.831
18.01	-18.31	-0.831
18.02	-18.37	-0.831
18.02	-18.44	-0.831
18.03	-18.51	-0.831
18.03	-18.57	-0.831
18.04	-18.64	-0.831
18.05	-18.71	-0.832
18.06	-18.77	-0.832
18.06	-18.84	-0.832
18.07	-18.91	-0.832
18.08	-18.97	-0.832
18.08	-19.04	-0.832
18.09	-19.11	-0.833
18.09	-19.17	-0.833
18.10	-19.24	-0.833
18.11	-19.31	-0.833
18.12	-19.37	-0.833
18.12	-19.44	-0.833
18.13	-19.51	-0.834
18.13	-19.57	-0.834
18.14	-19.64	-0.834
18.15	-19.71	-0.834
18.16	-19.77	-0.834
18.16	-19.84	-0.835
18.17	-19.91	-0.835
18.18	-19.97	-0.835
18.18	-20.04	-0.835
18.19	-20.11	-0.835
18.19	-20.17	-0.835
18.20	-20.24	-0.836
18.21	-20.31	-0.836
18.22	-20.37	-0.836
18.22	-20.44	-0.836
18.23	-20.51	-0.850
18.23	-20.57	-1.579
18.24	-20.58	-5.441
18.25	-20.43	-9.554
18.26	-20.31	-7.351
18.26	-20.35	-3.793
18.27	-20.42	-2.758
18.28	-20.50	-2.321
18.28	-20.58	-2.036
18.29	-20.66	-1.816
18.29	-20.75	-1.678
18.30	-20.84	-1.606
18.31	-20.92	-1.536
18.32	-21.01	-1.472
18.32	-21.09	-1.429
18.33	-21.18	-1.386
18.33	-21.26	-1.351
18.34	-21.34	-1.327
18.35	-21.42	-1.297
18.36	-21.50	-1.267
18.36	-21.58	-1.243
18.37	-21.66	-1.220
18.38	-21.74	-1.196
18.38	-21.82	-1.176
18.39	-21.90	-1.158
18.39	-21.98	-1.141
18.40	-22.06	-1.128
18.41	-22.13	-1.113
18.42	-22.21	-1.101
18.42	-22.28	-1.089
18.43	-22.36	-1.079
18.43	-22.43	-1.068
18.44	-22.50	-1.052
18.45	-22.58	-1.037
18.46	-22.65	-1.028
18.46	-22.73	-1.018
18.47	-22.80	-1.006
18.48	-22.87	-0.998
18.48	-22.94	-0.992
18.49	-23.02	-0.989
18.49	-23.09	-0.982
18.50	-23.16	-0.973
18.51	-23.23	-0.976
18.52	-23.30	-2.260
18.52	-23.29	-18.806
18.53	-22.19	-84.605
18.53	-18.46	-128.390
18.54	-16.38	-93.992
18.55	-15.63	-62.055
18.56	-15.41	-44.224
18.56	-15.50	-31.793
18.57	-15.80	-22.542
18.58	-16.25	-15.939
18.58	-16.75	-11.976
18.59	-17.25	-9.659
18.59	-17.74	-8.301
18.60	-18.21	-7.506
18.61	-18.65	-6.930
18.62	-19.08	-6.441
18.62	-19.48	-6.016
18.63	-19.86	-5.659
18.63	-20.22	-5.316
18.64	-20.56	-5.003
18.65	-20.89	-4.731
18.66	-21.20	-4.491
18.66	-21.49	-4.266
18.67	-21.77	-4.032
18.68	-22.04	-3.807
18.68	-22.29	-3.611
18.69	-22.54	-3.426
18.69	-22.77	-3.244
18.70	-22.99	-3.086
18.71	-23.20	-2.943
18.72	-23.40	-2.792
18.72	-23.59	-2.647
18.73	-23.78	-2.517
18.73	-23.96	-2.386
18.74	-24.13	-2.270
18.75	-24.30	-2.179
18.76	-24.46	-2.096
18.76	-24.61	-1.998
18.77	-24.76	-1.895
18.78	-24.90	-1.813
18.78	-25.04	-1.759
18.79	-25.17	-1.881
18.79	-25.29	-2.568
18.80	-25.37	-2.578
18.81	-25.49	-1.810
18.82	-25.61	-1.574
18.82	-25.73	-1.445
18.83	-25.85	-1.358
18.83	-25.96	-1.304
18.84	-26.07	-1.248
18.85	-26.18	-1.189
18.86	-26.28	-1.143
18.86	-26.39	-1.106
18.87	-26.49	-1.071
18.88	-26.58	-1.035
18.88	-26.68	-1.001
18.89	-26.77	-0.977
18.89	-26.87	-0.943
18.90	-26.96	-0.899
18.91	-27.05	-0.873
18.92	-27.14	-0.868
18.92	-27.22	-0.859
18.93	-27.31	-0.821
18.93	-27.39	-0.790
18.94	-27.48	-0.767
18.95	-27.56	-0.745
18.96	-27.64	-0.722
18.96	-27.72	-0.704
18.97	-27.80	-0.696
18.98	-27.88	-0.689
18.98	-27.96	-0.678
18.99	-28.04	-0.660
18.99	-28.11	-0.655
19.00	-28.19	-0.695
19.01	-28.26	-0.758
19.02	-28.33	-0.727
19.02	-28.41	-0.646
19.03	-28.48	-0.624
19.03	-28.56	-0.615
19.04	-28.63	-0.595
19.05	-28.70	-0.581
19.06	-28.78	-0.574
19.06	-28.85	-0.583
19.07	-28.92	-0.614
19.08	-28.99	-0.617
19.08	-29.06	-0.619
19.09	-29.13	-0.607
19.09	-29.20	-0.557
19.10	-29.27	-0.541
19.11	-29.34	-0.536
19.12	-29.41	-0.536
19.12	-29.48	-0.540
19.13	-29.55	-0.568
19.13	-29.62	-0.588
19.14	-29.69	-0.565
19.15	-29.76	-0.531
19.16	-29.83	-0.530
19.16	-29.90	-0.531
19.17	-29.97	-0.524
19.18	-30.03	-0.516
19.18	-30.10	-0.520
19.19	-30.17	-0.527
19.19	-30.24	-0.520
19.20	-30.31	-0.505
19.21	-30.38	-0.499
19.22	-30.44	-0.494
19.22	-30.51	-0.490
19.23	-30.58	-0.486
19.23	-30.65	-0.485
19.24	-30.72	-0.493
19.25	-30.79	-0.493
19.26	-30.85	-0.484
19.26	-30.92	-0.481
19.27	-30.99	-0.480
19.28	-31.06	-0.484
19.28	-31.12	-0.494
19.29	-31.19	-0.566
19.29	-31.25	-0.620
19.30	-31.32	-0.564
19.31	-31.39	-0.506
19.32	-31.45	-0.499
19.32	-31.52	-0.500
19.33	-31.59	-0.492
19.33	-31.66	-0.483
19.34	-31.72	-0.480
19.35	-31.79	-0.473
19.36	-31.86	-0.471
19.36	-31.93	-0.471
19.37	-31.99	-0.470
19.38	-32.06	-0.474
19.38	-32.13	-0.477
19.39	-32.20	-0.481
19.39	-32.26	-0.485
19.40	-32.33	-0.486
19.41	-32.40	-0.481
19.42	-32.46	-0.472
19.42	-32.53	-0.468
19.43	-32.60	-0.468
19.43	-32.67	-0.470
19.44	-32.73	-0.471
19.45	-32.80	-0.471
19.46	-32.87	-0.471
19.46	-32.93	-0.475
19.47	-33.00	-0.478
19.48	-33.07	-0.476
19.48	-33.13	-0.469
19.49	-33.20	-0.463
19.49	-33.27	-0.462
19.50	-33.34	-0.462
19.51	-33.40	-0.462
19.52	-33.47	-0.461
19.52	-33.54	-0.461
19.53	-33.60	-0.461
19.53	-33.67	-0.461
19.54	-33.74	-0.462
19.55	-33.80	-0.464
19.56	-33.87	-0.488
19.56	-33.93	-0.565
19.57	-34.00	-0.624
19.58	-34.06	-0.590
19.58	-34.13	-0.540
19.59	-34.19	-0.502
19.59	-34.26	-0.490
19.60	-34.33	-0.485
19.61	-34.40	-0.484
19.62	-34.46	-0.479
19.62	-34.53	-0.477
19.63	-34.60	-0.476
19.63	-34.66	-0.477
19.64	-34.73	-0.473
19.65	-34.80	-0.465
19.66	-34.87	-0.461
19.66	-34.93	-0.462
19.67	-35.00	-0.466
19.68	-35.07	-0.468
19.68	-35.13	-0.467
19.69	-35.20	-0.468
19.69	-35.27	-0.472
19.70	-35.33	-0.474
19.71	-35.40	-0.471
19.72	-35.47	-0.465
19.72	-35.54	-0.464
19.73	-35.60	-0.464
19.73	-35.67	-0.464
19.74	-35.74	-0.465
19.75	-35.80	-0.465
19.76	-35.87	-0.467
19.76	-35.94	-0.487
19.77	-36.00	-0.488
19.78	-36.07	-0.488
19.78	-36.13	-0.487
19.79	-36.20	-0.487
19.79	-36.27	-0.490
19.80	-36.33	-0.501
19.81	-36.40	-0.498
19.82	-36.47	-0.497
19.82	-36.53	-0.538
19.83	-36.60	-0.553
19.83	-36.66	-0.529
19.84	-36.73	-0.517
19.85	-36.80	-0.487
19.86	-36.86	-0.482
19.86	-36.93	-0.478
19.87	-37.00	-0.468
19.88	-37.06	-0.470
19.88	-37.13	-0.467
19.89	-37.20	-0.462
19.89	-37.27	-0.462
19.90	-37.33	-0.463
19.91	-37.40	-0.464
19.92	-37.47	-0.465
19.92	-37.53	-0.466
19.93	-37.60	-0.466
19.93	-37.67	-0.466
19.94	-37.74	-0.464
19.95	-37.80	-0.462
19.96	-37.87	-0.461
19.96	-37.94	-0.464
19.97	-38.00	-0.480
19.98	-38.07	-0.485
19.98	-38.14	-0.497
19.99	-38.20	-0.523
19.99	-38.27	-0.524
20.00	-38.33	-0.519
20.01	-38.40	-0.516
20.02	-38.46	-0.509
20.02	-38.53	-0.512
20.03	-38.60	-0.528
20.03	-38.66	-0.532
20.04	-38.73	-0.534
20.05	-38.80	-0.533
20.06	-38.86	-0.552
20.06	-38.92	-0.561
20.07	-38.99	-0.545
20.08	-39.06	-0.540
20.08	-39.12	-0.539
20.09	-39.19	-0.539
20.09	-39.26	-0.536
20.10	-39.32	-0.530
20.11	-39.39	-0.527
20.12	-39.45	-0.526
20.12	-39.52	-0.524
20.13	-39.59	-0.522
20.13	-39.66	-0.521
20.14	-39.72	-0.517
20.15	-39.79	-0.510
20.16	-39.86	-0.507
20.16	-39.92	-0.504
20.17	-39.99	-0.498
20.18	-40.06	-0.492
20.18	-40.12	-0.485
20.19	-40.19	-0.474
20.19	-40.26	-0.463
20.20	-40.33	-0.457
20.21	-40.40	-0.452
20.22	-40.46	-0.448
20.22	-40.53	-0.446
20.23	-40.60	-0.442
20.23	-40.67	-0.437
20.24	-40.73	-0.435
20.25	-40.80	-0.434
20.26	-40.87	-0.430
20.26	-40.94	-0.430
20.27	-41.00	-0.429
20.28	-41.07	-0.428
20.28	-41.14	-0.428
20.29	-41.21	-0.426
20.29	-41.27	-0.424
20.30	-41.34	-0.424
20.31	-41.41	-0.424
20.32	-41.48	-0.423
20.32	-41.54	-0.422
20.33	-41.61	-0.422
20.33	-41.68	-0.422
20.34	-41.74	-0.421
20.35	-41.81	-0.421
20.36	-41.88	-0.421
20.36	-41.94	-0.420
20.37	-42.01	-0.420
20.38	-42.08	-0.420
20.38	-42.15	-0.419
20.39	-42.21	-0.419
20.39	-42.28	-0.419
20.40	-42.35	-0.419
20.41	-42.42	-0.419
20.42	-42.48	-0.418
20.42	-42.55	-0.418
20.43	-42.62	-0.418
20.43	-42.68	-0.418
20.44	-42.75	-0.418
20.45	-42.82	-0.418
20.46	-42.88	-0.417
20.46	-42.95	-0.417
20.47	-43.02	-0.417
20.48	-43.08	-0.416
20.48	-43.15	-0.416
20.49	-43.22	-0.416
20.49	-43.28	-0.416
20.50	-43.35	-0.416
20.51	-43.42	-0.416
20.52	-43.48	-0.415
20.52	-43.55	-0.415
20.53	-43.62	-0.415
20.53	-43.68	-0.415
20.54	-43.75	-0.415
20.55	-43.82	-0.415
20.56	-43.88	-0.415
20.56	-43.95	-0.414
20.57	-44.02	-0.414
20.58	-44.09	-0.414
20.58	-44.15	-0.413
20.59	-44.22	-0.413
20.59	-44.29	-0.413
20.60	-44.35	-0.413
20.61	-44.42	-0.413
20.62	-44.49	-0.413
20.62	-44.55	-0.413
20.63	-44.62	-0.412
20.63	-44.69	-0.412
20.64	-44.75	-0.412
20.65	-44.82	-0.412
20.66	-44.89	-0.412
20.66	-44.95	-0.412
20.67	-45.02	-0.411
20.68	-45.09	-0.411
20.68	-45.15	-0.411
20.69	-45.22	-0.411
20.69	-45.28	-0.411
20.70	-45.35	-0.411
20.71	-45.42	-0.411
20.72	-45.49	-0.410
20.72	-45.55	-0.410
20.73	-45.62	-0.410
20.73	-45.68	-0.410
20.74	-45.75	-0.410
20.75	-45.82	-0.410
20.76	-45.89	-0.410
20.76	-45.95	-0.409
20.77	-46.02	-0.409
20.78	-46.09	-0.409
20.78	-46.15	-0.409
20.79	-46.22	-0.409
20.79	-46.29	-0.409
20.80	-46.35	-0.409
20.81	-46.42	-0.409
20.82	-46.49	-0.408
20.82	-46.55	-0.408
20.83	-46.62	-0.408
20.83	-46.69	-0.408
20.84	-46.75	-0.408
20.85	-46.82	-0.408
20.86	-46.89	-0.408
20.86	-46.95	-0.407
20.87	-47.02	-0.407
20.88	-47.09	-0.407
20.88	-47.15	-0.407
20.89	-47.22	-0.407
20.89	-47.29	-0.406
20.90	-47.35	-0.406
20.91	-47.42	-0.406
20.92	-47.49	-0.406
20.92	-47.55	-0.406
20.93	-47.62	-0.406
20.93	-47.69	-0.406
20.94	-47.75
20.95	-47.82
20.96	-47.89
20.96	-47.95
20.97	-48.02
20.98	-48.09
20.98	-48.15
20.99
20.99