File: Data/2024_09_19_D2O_CHM343_DSC.txt
Filename	2024_09_19_D2O_CHM343_DSC
Instrument name	DSC2A-00468 (192.168.1.100)
Operator	CHM343
rundate	9/19/2024
Sample name	2024_09_19_D2O_CHM343_DSC
proceduresegments	Equilibrate -50.00 °C; Ramp 10.00 °C/min to 50.00 °C; Isothermal 1.0 min; Ramp 10.00 °C/min to -50.00 °C
[File Parameters]
Run date	9/19/2024 9:12:51 PM
Trios version	5.1.1.46572
Original File Name
Current File Name	C:\ProgramData\TA Instruments\TRIOS\Data\2024_09_19_D2O_CHM343_DSC.tri
[Procedure]
Procedure Name	CHM343_Fall2024_water
Sample Name	2024_09_19_D2O_CHM343_DSC
Sample Mass	3.98 mg
Reference Sample Mass	0 mg
Pan Mass	54.39 mg
Pan Number	27
Reference Pan Mass	54 mg
Reference Pan Number	19
Pan Type	Aluminum
Comments	Water - D2O - Al Hermetic Sealed Pan, with ref Al pan.  ASU Online CHM343, Remote DSC experimental lab. Fall 2024.  Group Zoom Data Collection, Sept 19, 2024 from 5-7 pm.  TA Instruments DSC2500.
Project Name	Lab 4 - Fall 2024
Operator	CHM343
Test	Custom
Unload Max Temperature	30
Unload Min Temperature	30
Load Max Temperature	30
Load Min Temperature	30
Stop on Gas Flow Error	Yes
[Signal List]
Signal #1	Time (min)
Signal #2	Temperature (°C)
Signal #3	Heat Flow (mW)
Signal #4	Delta T (µV)
Signal #5	Delta Tzero (µV)
Signal #6	Tzero Temperature (°C)
Signal #7	Cell Purge (mL/min)
Signal #8	Heater Temp (°C)
Signal #9	Power Delivered (W)
Signal #10	Reference Junction Temperature (°C)
Signal #11	Flange Temperature (°C)
Signal #12	Heat Flow Phase (rad)
Signal #13	Total Heat Capacity (J/°C)
Signal #14	Heat Capacity (J/°C)
[Configuration]
Company Name	ASU
Instrument Name	DSC2A-00468
Instrument Type	DSC2500
Serial Number	DSC2A-00468
IP	192.168.1.100
Location of Instrument	MRRC
DisplayType	Unknown
Sample Interval 	0.1 s/pt
Selected Heat Flow	T4P
Exotherm Direction	Down
Cell Serial	DRC2-00792
Lid Type	Standard
Cooler	RCS 90
Leave Cooler on at End of Sequence	On
Gas 2	Nitrogen
Gas Selected	Channel 1
Flow Rate	50 mL/min
Secondary Purge	On
Licensed Heat Flow	Heat Flow T4P
Modulation Licensed	Yes
[Versions]
Common IDD Version	1
Cortex Version	VER 2.10.2.31
Driver	5.0.0.6
GDM Version	1.0.3.3
TouchscreenVersion	1.0.0.16145
FEP Version	1.2.1.21
FEP Bootloader	2.0.0.5
AutoSampler Version	2.1.1.26
Auto Sampler Bootloader	2.0.0.5
FCM Version	1.1.0.3
FCM Bootloader	2.0.0.5
[Experiment Logs]
Experiment Log Entry # 1	Air Cool is off.
Experiment Log Entry # 3	Equilibrate Segment -50 (C) Started
Experiment Log Entry # 5	Ramp Segment 10 C/min to 50 Started
Experiment Log Entry # 7	Isothermal Segment 1 min started
Experiment Log Entry # 9	Ramp Segment 10 C/min to -50 Started
[Method Log]
Method Log Entry # 1	Equilibrate -50 °C
Method Log Entry # 2	(Ramp 34764) Ramp 10 °C/minute to 50 °C
Method Log Entry # 3	Isothermal 1 minutes
Method Log Entry # 4	(Ramp 34766) Ramp 10 °C/minute to -50 °C
Cell Serial	DRC2-00792
[T1 Calibration]
Slope	-0.008529666
Offset	9.636258
Initial Temperature	98.23
GUID	f8bfdadc-4977-4fdf-ba6d-0ba9134940c3
[TZero Calibration]
Date Applied	11/29/2022 4:06:13 PM
Description	From -89.059 °C to 396.009 °C at 20.000°C/min
Gas Type	Nitrogen
Pan Type	None
Source Files 1	C:\Users\yargerlab\Desktop\DSC Data\General\TZero_calibration_11_29_22_2nd(2).tri
Source Files 2	C:\Users\yargerlab\Desktop\DSC Data\General\TZero_calibration_11_29_22_2nd(3).tri
Delta T Offset	13.05235
Delta T Slope	-0.007271007
Delta T0 Offset	-13.69128
Delta T0 Slope	0.06063341
[Temperature Calibration]
Date Applied	11/29/2022 7:12:28 PM
Description	From 106.590 °C to 186.590 °C at 10.000°C/min
Gas Type	Nitrogen
Pan Type	Tzero Aluminum Hermetic
Source Files 1	C:\Users\yargerlab\Desktop\DSC Data\General\Indium(6).tri
Measured 1	157.391
Known 1	156.598
[Cell Constant Calibration]
Date Applied	11/29/2022 7:12:29 PM
Description	From 106.590 °C to 186.590 °C at 10.000°C/min
Gas Type	Nitrogen
Pan Type	Tzero Aluminum Hermetic
Source Files 1	C:\Users\yargerlab\Desktop\DSC Data\General\Indium(6).tri
T4P KCell	1.006051
Onset Slope	63.26126 mW/°C
[Direct Cp Calibration]
Date Applied	11/30/2022 11:04:51 AM
Description	From -79.983 °C to 298.409 °C at 10.000°C/min
Gas Type	Nitrogen
Pan Type	Tzero Aluminum Hermetic
Source Files 1	C:\Users\yargerlab\Desktop\DSC Data\General\Sapphire_Heat_Capacity_11_30_22.tri
[Rev Cp Calibration]
Date Applied	11/30/2022 1:58:51 PM
Description	From -79.996 °C to 292.812 °C at 3.000°C/min
Gas Type	Nitrogen
Pan Type	Tzero Aluminum Hermetic
Source Files 1	C:\Users\yargerlab\Desktop\DSC Data\General\Sapphire_MDSC_Calibration_11_30_22.tri
[step]
Ramp 10.00 °C/min to 50.00 °C
Time	Temperature	Heat Flow (Normalized)
min	°C	W/g
0.00	-49.70	-0.115
0.01	-49.70	-0.118
0.01	-49.71	-0.114
0.02	-49.71	-0.109
0.03	-49.72	-0.105
0.03	-49.72	-0.102
0.04	-49.72	-0.101
0.05	-49.72	-0.101
0.05	-49.72	-0.101
0.06	-49.71	-0.103
0.07	-49.71	-0.106
0.07	-49.70	-0.111
0.08	-49.69	-0.122
0.09	-49.67	-0.137
0.09	-49.66	-0.146
0.10	-49.64	-0.157
0.11	-49.61	-0.169
0.11	-49.59	-0.179
0.12	-49.56	-0.185
0.13	-49.53	-0.192
0.13	-49.49	-0.196
0.14	-49.46	-0.198
0.15	-49.42	-0.198
0.15	-49.38	-0.197
0.16	-49.34	-0.190
0.17	-49.29	-0.187
0.17	-49.25	-0.180
0.18	-49.20	-0.167
0.19	-49.16	-0.152
0.19	-49.11	-0.138
0.20	-49.06	-0.124
0.21	-49.01	-0.112
0.21	-48.96	-0.097
0.22	-48.91	-0.082
0.23	-48.86	-0.068
0.23	-48.80	-0.053
0.24	-48.75	-0.041
0.25	-48.70	-0.027
0.25	-48.64	-0.012
0.26	-48.59	-0.001
0.27	-48.53	0.011
0.27	-48.48	0.022
0.28	-48.42	0.032
0.29	-48.36	0.043
0.29	-48.31	0.052
0.30	-48.25	0.061
0.31	-48.19	0.071
0.31	-48.14	0.079
0.32	-48.08	0.087
0.33	-48.02	0.093
0.33	-47.96	0.100
0.34	-47.90	0.109
0.35	-47.84	0.115
0.35	-47.78	0.122
0.36	-47.72	0.127
0.37	-47.66	0.132
0.37	-47.60	0.137
0.38	-47.54	0.143
0.39	-47.48	0.148
0.39	-47.42	0.153
0.40	-47.36	0.157
0.41	-47.30	0.161
0.41	-47.23	0.168
0.42	-47.17	0.170
0.43	-47.11	0.174
0.43	-47.05	0.180
0.44	-46.99	0.181
0.45	-46.92	0.183
0.45	-46.86	0.189
0.46	-46.80	0.192
0.47	-46.74	0.195
0.47	-46.67	0.199
0.48	-46.61	0.200
0.49	-46.55	0.203
0.49	-46.48	0.205
0.50	-46.42	0.207
0.51	-46.36	0.208
0.51	-46.29	0.211
0.52	-46.23	0.214
0.53	-46.16	0.216
0.53	-46.10	0.218
0.54	-46.04	0.219
0.55	-45.97	0.221
0.55	-45.91	0.222
0.56	-45.85	0.223
0.57	-45.78	0.225
0.57	-45.72	0.227
0.58	-45.65	0.229
0.59	-45.59	0.229
0.59	-45.52	0.230
0.60	-45.46	0.231
0.61	-45.40	0.233
0.61	-45.33	0.233
0.62	-45.27	0.234
0.63	-45.20	0.235
0.63	-45.14	0.236
0.64	-45.07	0.237
0.65	-45.01	0.238
0.65	-44.94	0.238
0.66	-44.88	0.239
0.67	-44.81	0.241
0.67	-44.75	0.242
0.68	-44.68	0.242
0.69	-44.62	0.242
0.69	-44.55	0.244
0.70	-44.49	0.244
0.71	-44.42	0.244
0.71	-44.36	0.245
0.72	-44.29	0.246
0.73	-44.23	0.246
0.73	-44.16	0.247
0.74	-44.10	0.247
0.75	-44.03	0.247
0.75	-43.97	0.248
0.76	-43.90	0.248
0.77	-43.84	0.248
0.77	-43.77	0.248
0.78	-43.71	0.249
0.79	-43.64	0.249
0.79	-43.58	0.249
0.80	-43.51	0.250
0.81	-43.44	0.250
0.81	-43.38	0.251
0.82	-43.31	0.251
0.83	-43.25	0.251
0.83	-43.18	0.251
0.84	-43.12	0.252
0.85	-43.05	0.252
0.85	-42.98	0.252
0.86	-42.92	0.252
0.87	-42.85	0.252
0.87	-42.79	0.252
0.88	-42.72	0.253
0.89	-42.66	0.253
0.89	-42.59	0.253
0.90	-42.52	0.254
0.91	-42.46	0.254
0.91	-42.39	0.254
0.92	-42.32	0.254
0.93	-42.26	0.254
0.93	-42.19	0.254
0.94	-42.13	0.255
0.95	-42.06	0.255
0.95	-42.00	0.255
0.96	-41.93	0.255
0.97	-41.86	0.255
0.97	-41.80	0.256
0.98	-41.73	0.256
0.99	-41.67	0.256
0.99	-41.60	0.256
1.00	-41.54	0.256
1.01	-41.47	0.256
1.01	-41.40	0.256
1.02	-41.34	0.257
1.03	-41.27	0.257
1.03	-41.20	0.257
1.04	-41.14	0.257
1.05	-41.07	0.257
1.05	-41.01	0.257
1.06	-40.94	0.258
1.07	-40.87	0.258
1.07	-40.81	0.258
1.08	-40.74	0.258
1.09	-40.68	0.258
1.09	-40.61	0.259
1.10	-40.54	0.259
1.11	-40.48	0.259
1.11	-40.41	0.259
1.12	-40.35	0.259
1.13	-40.28	0.259
1.13	-40.21	0.259
1.14	-40.15	0.260
1.15	-40.08	0.260
1.15	-40.02	0.260
1.16	-39.95	0.260
1.17	-39.88	0.260
1.17	-39.82	0.260
1.18	-39.75	0.260
1.19	-39.68	0.260
1.19	-39.62	0.261
1.20	-39.55	0.261
1.21	-39.48	0.261
1.21	-39.42	0.261
1.22	-39.35	0.261
1.23	-39.29	0.261
1.23	-39.22	0.261
1.24	-39.15	0.262
1.25	-39.09	0.262
1.25	-39.02	0.262
1.26	-38.95	0.262
1.27	-38.89	0.262
1.27	-38.82	0.262
1.28	-38.76	0.262
1.29	-38.69	0.262
1.29	-38.62	0.263
1.30	-38.56	0.263
1.31	-38.49	0.263
1.31	-38.42	0.263
1.32	-38.36	0.263
1.33	-38.29	0.263
1.33	-38.23	0.263
1.34	-38.16	0.263
1.35	-38.09	0.263
1.35	-38.02	0.263
1.36	-37.96	0.264
1.37	-37.89	0.264
1.37	-37.83	0.264
1.38	-37.76	0.264
1.39	-37.69	0.264
1.39	-37.63	0.264
1.40	-37.56	0.264
1.41	-37.49	0.264
1.41	-37.43	0.264
1.42	-37.36	0.265
1.43	-37.29	0.265
1.43	-37.23	0.265
1.44	-37.16	0.265
1.45	-37.09	0.265
1.45	-37.03	0.265
1.46	-36.96	0.265
1.47	-36.90	0.265
1.47	-36.83	0.265
1.48	-36.76	0.265
1.49	-36.70	0.265
1.49	-36.63	0.266
1.50	-36.56	0.266
1.51	-36.50	0.266
1.51	-36.43	0.266
1.52	-36.36	0.266
1.53	-36.30	0.266
1.53	-36.23	0.266
1.54	-36.16	0.266
1.55	-36.10	0.266
1.55	-36.03	0.266
1.56	-35.96	0.266
1.57	-35.90	0.266
1.57	-35.83	0.266
1.58	-35.76	0.267
1.59	-35.70	0.267
1.59	-35.63	0.267
1.60	-35.56	0.267
1.61	-35.50	0.267
1.61	-35.43	0.267
1.62	-35.37	0.267
1.63	-35.30	0.267
1.63	-35.23	0.267
1.64	-35.17	0.267
1.65	-35.10	0.267
1.65	-35.03	0.267
1.66	-34.97	0.267
1.67	-34.90	0.267
1.67	-34.83	0.268
1.68	-34.77	0.268
1.69	-34.70	0.268
1.69	-34.63	0.268
1.70	-34.57	0.268
1.71	-34.50	0.268
1.71	-34.43	0.268
1.72	-34.37	0.268
1.73	-34.30	0.268
1.73	-34.23	0.268
1.74	-34.17	0.268
1.75	-34.10	0.268
1.75	-34.03	0.268
1.76	-33.97	0.269
1.77	-33.90	0.269
1.77	-33.83	0.269
1.78	-33.77	0.269
1.79	-33.70	0.269
1.79	-33.64	0.269
1.80	-33.57	0.269
1.81	-33.50	0.269
1.81	-33.44	0.269
1.82	-33.37	0.269
1.83	-33.30	0.269
1.83	-33.24	0.269
1.84	-33.17	0.269
1.85	-33.10	0.269
1.85	-33.03	0.269
1.86	-32.97	0.269
1.87	-32.90	0.269
1.87	-32.83	0.270
1.88	-32.77	0.270
1.89	-32.70	0.270
1.89	-32.64	0.270
1.90	-32.57	0.270
1.91	-32.50	0.270
1.91	-32.43	0.270
1.92	-32.37	0.270
1.93	-32.30	0.270
1.93	-32.23	0.270
1.94	-32.17	0.270
1.95	-32.10	0.270
1.95	-32.04	0.270
1.96	-31.97	0.270
1.97	-31.90	0.270
1.97	-31.83	0.270
1.98	-31.77	0.271
1.99	-31.70	0.271
1.99	-31.63	0.271
2.00	-31.57	0.271
2.01	-31.50	0.271
2.01	-31.43	0.271
2.02	-31.37	0.271
2.03	-31.30	0.271
2.03	-31.24	0.271
2.04	-31.17	0.271
2.05	-31.10	0.271
2.05	-31.04	0.271
2.06	-30.97	0.271
2.07	-30.90	0.271
2.07	-30.84	0.271
2.08	-30.77	0.271
2.09	-30.70	0.272
2.09	-30.64	0.272
2.10	-30.57	0.272
2.11	-30.50	0.272
2.11	-30.44	0.272
2.12	-30.37	0.272
2.13	-30.30	0.272
2.13	-30.23	0.272
2.14	-30.17	0.272
2.15	-30.10	0.272
2.15	-30.04	0.272
2.16	-29.97	0.272
2.17	-29.90	0.272
2.17	-29.84	0.272
2.18	-29.77	0.272
2.19	-29.70	0.272
2.19	-29.64	0.272
2.20	-29.57	0.272
2.21	-29.50	0.272
2.21	-29.43	0.272
2.22	-29.37	0.272
2.23	-29.30	0.272
2.23	-29.23	0.272
2.24	-29.17	0.272
2.25	-29.10	0.273
2.25	-29.03	0.273
2.26	-28.97	0.273
2.27	-28.90	0.273
2.27	-28.83	0.273
2.28	-28.77	0.273
2.29	-28.70	0.273
2.29	-28.63	0.273
2.30	-28.57	0.273
2.31	-28.50	0.273
2.31	-28.43	0.273
2.32	-28.37	0.273
2.33	-28.30	0.273
2.33	-28.23	0.273
2.34	-28.17	0.273
2.35	-28.10	0.273
2.35	-28.04	0.273
2.36	-27.97	0.273
2.37	-27.90	0.274
2.37	-27.83	0.274
2.38	-27.77	0.274
2.39	-27.70	0.274
2.39	-27.63	0.274
2.40	-27.57	0.274
2.41	-27.50	0.274
2.41	-27.43	0.274
2.42	-27.37	0.274
2.43	-27.30	0.274
2.43	-27.23	0.274
2.44	-27.17	0.274
2.45	-27.10	0.274
2.45	-27.03	0.274
2.46	-26.97	0.274
2.47	-26.90	0.274
2.47	-26.83	0.274
2.48	-26.77	0.274
2.49	-26.70	0.274
2.49	-26.63	0.274
2.50	-26.57	0.274
2.51	-26.50	0.275
2.51	-26.43	0.275
2.52	-26.37	0.275
2.53	-26.30	0.275
2.53	-26.23	0.275
2.54	-26.17	0.275
2.55	-26.10	0.275
2.55	-26.03	0.275
2.56	-25.97	0.275
2.57	-25.90	0.275
2.57	-25.83	0.275
2.58	-25.77	0.275
2.59	-25.70	0.275
2.59	-25.63	0.275
2.60	-25.57	0.275
2.61	-25.50	0.275
2.61	-25.43	0.275
2.62	-25.37	0.275
2.63	-25.30	0.275
2.63	-25.23	0.275
2.64	-25.17	0.275
2.65	-25.10	0.275
2.65	-25.03	0.276
2.66	-24.97	0.276
2.67	-24.90	0.276
2.67	-24.83	0.276
2.68	-24.77	0.276
2.69	-24.70	0.276
2.69	-24.63	0.276
2.70	-24.57	0.276
2.71	-24.50	0.276
2.71	-24.43	0.276
2.72	-24.37	0.276
2.73	-24.30	0.276
2.73	-24.23	0.276
2.74	-24.17	0.276
2.75	-24.10	0.276
2.75	-24.03	0.276
2.76	-23.97	0.276
2.77	-23.90	0.277
2.77	-23.83	0.277
2.78	-23.77	0.277
2.79	-23.70	0.277
2.79	-23.63	0.277
2.80	-23.57	0.277
2.81	-23.50	0.277
2.81	-23.43	0.277
2.82	-23.37	0.277
2.83	-23.30	0.277
2.83	-23.23	0.277
2.84	-23.16	0.277
2.85	-23.10	0.277
2.85	-23.03	0.277
2.86	-22.96	0.277
2.87	-22.90	0.277
2.87	-22.83	0.277
2.88	-22.77	0.277
2.89	-22.70	0.277
2.89	-22.63	0.277
2.90	-22.56	0.277
2.91	-22.50	0.277
2.91	-22.43	0.278
2.92	-22.36	0.278
2.93	-22.30	0.278
2.93	-22.23	0.278
2.94	-22.16	0.278
2.95	-22.10	0.278
2.95	-22.03	0.278
2.96	-21.97	0.278
2.97	-21.90	0.278
2.97	-21.83	0.278
2.98	-21.76	0.278
2.99	-21.70	0.278
2.99	-21.63	0.278
3.00	-21.56	0.278
3.01	-21.50	0.278
3.01	-21.43	0.278
3.02	-21.36	0.278
3.03	-21.30	0.278
3.03	-21.23	0.279
3.04	-21.16	0.279
3.05	-21.10	0.279
3.05	-21.03	0.279
3.06	-20.96	0.279
3.07	-20.90	0.279
3.07	-20.83	0.279
3.08	-20.76	0.279
3.09	-20.70	0.279
3.09	-20.63	0.279
3.10	-20.56	0.279
3.11	-20.50	0.279
3.11	-20.43	0.279
3.12	-20.36	0.279
3.13	-20.30	0.279
3.13	-20.23	0.279
3.14	-20.16	0.279
3.15	-20.10	0.279
3.15	-20.03	0.279
3.16	-19.96	0.279
3.17	-19.90	0.279
3.17	-19.83	0.279
3.18	-19.76	0.279
3.19	-19.70	0.280
3.19	-19.63	0.280
3.20	-19.56	0.280
3.21	-19.50	0.280
3.21	-19.43	0.280
3.22	-19.36	0.280
3.23	-19.30	0.280
3.23	-19.23	0.280
3.24	-19.16	0.280
3.25	-19.10	0.280
3.25	-19.03	0.280
3.26	-18.96	0.280
3.27	-18.90	0.280
3.27	-18.83	0.280
3.28	-18.76	0.280
3.29	-18.70	0.280
3.29	-18.63	0.280
3.30	-18.56	0.280
3.31	-18.50	0.281
3.31	-18.43	0.281
3.32	-18.36	0.281
3.33	-18.30	0.281
3.33	-18.23	0.281
3.34	-18.16	0.281
3.35	-18.09	0.281
3.35	-18.03	0.281
3.36	-17.96	0.281
3.37	-17.89	0.281
3.37	-17.83	0.281
3.38	-17.76	0.281
3.39	-17.69	0.281
3.39	-17.63	0.281
3.40	-17.56	0.281
3.41	-17.49	0.281
3.41	-17.43	0.282
3.42	-17.36	0.282
3.43	-17.29	0.281
3.43	-17.23	0.282
3.44	-17.16	0.282
3.45	-17.10	0.282
3.45	-17.03	0.282
3.46	-16.96	0.282
3.47	-16.89	0.282
3.47	-16.83	0.282
3.48	-16.76	0.282
3.49	-16.69	0.282
3.49	-16.63	0.282
3.50	-16.56	0.282
3.51	-16.49	0.282
3.51	-16.43	0.282
3.52	-16.36	0.282
3.53	-16.29	0.282
3.53	-16.23	0.282
3.54	-16.16	0.282
3.55	-16.09	0.283
3.55	-16.03	0.283
3.56	-15.96	0.283
3.57	-15.89	0.283
3.57	-15.83	0.283
3.58	-15.76	0.283
3.59	-15.69	0.283
3.59	-15.63	0.283
3.60	-15.56	0.283
3.61	-15.49	0.283
3.61	-15.43	0.283
3.62	-15.36	0.283
3.63	-15.29	0.283
3.63	-15.23	0.283
3.64	-15.16	0.283
3.65	-15.09	0.283
3.65	-15.03	0.283
3.66	-14.96	0.284
3.67	-14.89	0.284
3.67	-14.83	0.284
3.68	-14.76	0.284
3.69	-14.69	0.284
3.69	-14.63	0.284
3.70	-14.56	0.284
3.71	-14.49	0.284
3.71	-14.43	0.284
3.72	-14.36	0.284
3.73	-14.29	0.284
3.73	-14.23	0.284
3.74	-14.16	0.284
3.75	-14.09	0.284
3.75	-14.03	0.284
3.76	-13.96	0.284
3.77	-13.89	0.284
3.77	-13.82	0.285
3.78	-13.76	0.285
3.79	-13.69	0.285
3.79	-13.62	0.285
3.80	-13.56	0.285
3.81	-13.49	0.285
3.81	-13.42	0.285
3.82	-13.36	0.285
3.83	-13.29	0.285
3.83	-13.22	0.285
3.84	-13.16	0.285
3.85	-13.09	0.285
3.85	-13.02	0.285
3.86	-12.96	0.285
3.87	-12.89	0.285
3.87	-12.82	0.286
3.88	-12.76	0.286
3.89	-12.69	0.286
3.89	-12.62	0.286
3.90	-12.56	0.286
3.91	-12.49	0.286
3.91	-12.42	0.286
3.92	-12.36	0.286
3.93	-12.29	0.286
3.93	-12.22	0.286
3.94	-12.16	0.286
3.95	-12.09	0.286
3.95	-12.02	0.286
3.96	-11.96	0.286
3.97	-11.89	0.286
3.97	-11.82	0.286
3.98	-11.76	0.286
3.99	-11.69	0.286
3.99	-11.62	0.286
4.00	-11.56	0.287
4.01	-11.49	0.287
4.01	-11.42	0.287
4.02	-11.36	0.287
4.03	-11.29	0.287
4.03	-11.22	0.287
4.04	-11.16	0.287
4.05	-11.09	0.287
4.05	-11.02	0.287
4.06	-10.96	0.287
4.07	-10.89	0.287
4.07	-10.82	0.287
4.08	-10.76	0.287
4.09	-10.69	0.287
4.09	-10.62	0.288
4.10	-10.56	0.288
4.11	-10.49	0.288
4.11	-10.42	0.288
4.12	-10.36	0.288
4.13	-10.29	0.288
4.13	-10.22	0.288
4.14	-10.16	0.288
4.15	-10.09	0.288
4.15	-10.02	0.288
4.16	-9.96	0.288
4.17	-9.89	0.288
4.17	-9.82	0.288
4.18	-9.76	0.289
4.19	-9.69	0.289
4.19	-9.62	0.289
4.20	-9.56	0.289
4.21	-9.49	0.289
4.21	-9.42	0.289
4.22	-9.36	0.289
4.23	-9.29	0.289
4.23	-9.22	0.289
4.24	-9.16	0.289
4.25	-9.09	0.289
4.25	-9.02	0.289
4.26	-8.96	0.289
4.27	-8.89	0.289
4.27	-8.82	0.289
4.28	-8.76	0.289
4.29	-8.69	0.290
4.29	-8.62	0.290
4.30	-8.55	0.290
4.31	-8.49	0.290
4.31	-8.42	0.290
4.32	-8.36	0.290
4.33	-8.29	0.290
4.33	-8.22	0.290
4.34	-8.15	0.290
4.35	-8.09	0.290
4.35	-8.02	0.290
4.36	-7.95	0.290
4.37	-7.89	0.290
4.37	-7.82	0.290
4.38	-7.75	0.290
4.39	-7.69	0.291
4.39	-7.62	0.291
4.40	-7.55	0.291
4.41	-7.49	0.291
4.41	-7.42	0.291
4.42	-7.35	0.291
4.43	-7.29	0.291
4.43	-7.22	0.291
4.44	-7.15	0.291
4.45	-7.09	0.291
4.45	-7.02	0.291
4.46	-6.95	0.291
4.47	-6.89	0.292
4.47	-6.82	0.292
4.48	-6.75	0.292
4.49	-6.69	0.292
4.49	-6.62	0.292
4.50	-6.55	0.292
4.51	-6.49	0.292
4.51	-6.42	0.292
4.52	-6.35	0.292
4.53	-6.29	0.292
4.53	-6.22	0.292
4.54	-6.15	0.292
4.55	-6.09	0.293
4.55	-6.02	0.293
4.56	-5.95	0.293
4.57	-5.89	0.293
4.57	-5.82	0.293
4.58	-5.75	0.293
4.59	-5.69	0.293
4.59	-5.62	0.293
4.60	-5.55	0.293
4.61	-5.49	0.293
4.61	-5.42	0.293
4.62	-5.35	0.293
4.63	-5.29	0.293
4.63	-5.22	0.293
4.64	-5.15	0.293
4.65	-5.08	0.293
4.65	-5.02	0.294
4.66	-4.95	0.294
4.67	-4.89	0.294
4.67	-4.82	0.294
4.68	-4.75	0.294
4.69	-4.68	0.294
4.69	-4.62	0.294
4.70	-4.55	0.294
4.71	-4.48	0.294
4.71	-4.42	0.294
4.72	-4.35	0.295
4.73	-4.28	0.295
4.73	-4.22	0.295
4.74	-4.15	0.295
4.75	-4.08	0.295
4.75	-4.02	0.295
4.76	-3.95	0.295
4.77	-3.88	0.295
4.77	-3.82	0.295
4.78	-3.75	0.295
4.79	-3.68	0.295
4.79	-3.62	0.295
4.80	-3.55	0.296
4.81	-3.48	0.296
4.81	-3.42	0.296
4.82	-3.35	0.296
4.83	-3.28	0.296
4.83	-3.22	0.296
4.84	-3.15	0.296
4.85	-3.08	0.296
4.85	-3.02	0.296
4.86	-2.95	0.296
4.87	-2.88	0.297
4.87	-2.82	0.297
4.88	-2.75	0.297
4.89	-2.68	0.297
4.89	-2.62	0.297
4.90	-2.55	0.297
4.91	-2.48	0.297
4.91	-2.42	0.297
4.92	-2.35	0.297
4.93	-2.28	0.297
4.93	-2.22	0.298
4.94	-2.15	0.298
4.95	-2.08	0.298
4.95	-2.02	0.298
4.96	-1.95	0.298
4.97	-1.88	0.298
4.97	-1.82	0.298
4.98	-1.75	0.299
4.99	-1.68	0.299
4.99	-1.62	0.299
5.00	-1.55	0.299
5.01	-1.48	0.299
5.01	-1.41	0.299
5.02	-1.35	0.300
5.03	-1.28	0.300
5.03	-1.22	0.300
5.04	-1.15	0.300
5.05	-1.08	0.301
5.05	-1.02	0.301
5.06	-0.95	0.301
5.07	-0.88	0.301
5.07	-0.82	0.301
5.08	-0.75	0.301
5.09	-0.68	0.302
5.09	-0.62	0.302
5.10	-0.55	0.302
5.11	-0.48	0.302
5.11	-0.42	0.303
5.12	-0.35	0.303
5.13	-0.28	0.304
5.13	-0.22	0.304
5.14	-0.15	0.304
5.15	-0.08	0.305
5.15	-0.02	0.306
5.16	0.05	0.307
5.17	0.12	0.308
5.17	0.18	0.308
5.18	0.25	0.310
5.19	0.32	0.311
5.19	0.38	0.312
5.20	0.45	0.313
5.21	0.52	0.316
5.21	0.58	0.318
5.22	0.65	0.321
5.23	0.72	0.324
5.23	0.78	0.325
5.24	0.85	0.328
5.25	0.91	0.332
5.25	0.98	0.333
5.26	1.05	0.336
5.27	1.11	0.340
5.27	1.18	0.344
5.28	1.25	0.351
5.29	1.31	0.358
5.29	1.38	0.365
5.30	1.44	0.371
5.31	1.51	0.378
5.31	1.58	0.387
5.32	1.64	0.399
5.33	1.70	0.413
5.33	1.77	0.429
5.34	1.83	0.447
5.35	1.90	0.471
5.35	1.96	0.499
5.36	2.02	0.536
5.37	2.08	0.583
5.37	2.15	0.640
5.38	2.21	0.714
5.39	2.26	0.800
5.39	2.32	0.903
5.40	2.37	1.028
5.41	2.42	1.165
5.41	2.47	1.313
5.42	2.51	1.469
5.43	2.55	1.629
5.43	2.59	1.788
5.44	2.63	1.949
5.45	2.67	2.106
5.45	2.70	2.258
5.46	2.73	2.409
5.47	2.77	2.550
5.47	2.80	2.697
5.48	2.83	2.838
5.49	2.86	2.971
5.49	2.89	3.111
5.50	2.92	3.241
5.51	2.95	3.371
5.51	2.98	3.502
5.52	3.01	3.628
5.53	3.04	3.752
5.53	3.07	3.876
5.54	3.10	3.992
5.55	3.13	4.104
5.55	3.16	4.210
5.56	3.19	4.308
5.57	3.22	4.401
5.57	3.26	4.481
5.58	3.29	4.546
5.59	3.33	4.597
5.59	3.37	4.636
5.60	3.41	4.671
5.61	3.45	4.708
5.61	3.49	4.750
5.62	3.53	4.796
5.63	3.58	4.842
5.63	3.63	4.892
5.64	3.67	4.937
5.65	3.72	4.979
5.65	3.77	5.020
5.66	3.82	5.059
5.67	3.87	5.096
5.67	3.92	5.134
5.68	3.97	5.172
5.69	4.02	5.211
5.69	4.07	5.254
5.70	4.12	5.295
5.71	4.18	5.337
5.71	4.23	5.379
5.72	4.28	5.420
5.73	4.33	5.458
5.73	4.39	5.495
5.74	4.44	5.532
5.75	4.50	5.567
5.75	4.55	5.602
5.76	4.60	5.634
5.77	4.66	5.666
5.77	4.71	5.698
5.78	4.77	5.726
5.79	4.83	5.754
5.79	4.88	5.784
5.80	4.94	5.813
5.81	4.99	5.839
5.81	5.05	5.862
5.82	5.11	5.887
5.83	5.17	5.910
5.83	5.22	5.932
5.84	5.28	5.955
5.85	5.34	5.977
5.85	5.40	5.997
5.86	5.46	6.015
5.87	5.52	6.032
5.87	5.58	6.050
5.88	5.64	6.067
5.89	5.70	6.081
5.89	5.76	6.097
5.90	5.82	6.112
5.91	5.88	6.126
5.91	5.94	6.140
5.92	6.00	6.150
5.93	6.06	6.160
5.93	6.12	6.172
5.94	6.19	6.182
5.95	6.25	6.190
5.95	6.31	6.196
5.96	6.37	6.207
5.97	6.44	6.214
5.97	6.50	6.220
5.98	6.56	6.227
5.99	6.63	6.235
5.99	6.69	6.246
6.00	6.75	6.268
6.01	6.82	6.306
6.01	6.88	6.368
6.02	6.94	6.455
6.03	6.99	6.569
6.03	7.05	6.738
6.04	7.09	7.028
6.05	7.13	7.487
6.05	7.15	7.912
6.06	7.18	7.959
6.07	7.21	7.680
6.07	7.26	7.359
6.08	7.32	7.103
6.09	7.39	6.912
6.09	7.47	6.774
6.10	7.54	6.669
6.11	7.62	6.588
6.11	7.69	6.523
6.12	7.77	6.462
6.13	7.85	6.410
6.13	7.93	6.362
6.14	8.01	6.312
6.15	8.09	6.263
6.15	8.17	6.213
6.16	8.24	6.162
6.17	8.32	6.111
6.17	8.41	6.058
6.18	8.49	6.004
6.19	8.57	5.949
6.19	8.65	5.893
6.20	8.73	5.836
6.21	8.81	5.776
6.21	8.89	5.716
6.22	8.97	5.656
6.23	9.05	5.593
6.23	9.14	5.528
6.24	9.22	5.462
6.25	9.30	5.393
6.25	9.39	5.322
6.26	9.47	5.250
6.27	9.56	5.176
6.27	9.64	5.103
6.28	9.73	5.024
6.29	9.81	4.944
6.29	9.90	4.862
6.30	9.99	4.779
6.31	10.07	4.696
6.31	10.16	4.609
6.32	10.25	4.518
6.33	10.34	4.429
6.33	10.43	4.334
6.34	10.52	4.236
6.35	10.61	4.135
6.35	10.70	4.031
6.36	10.79	3.924
6.37	10.89	3.812
6.37	10.98	3.697
6.38	11.07	3.578
6.39	11.17	3.448
6.39	11.26	3.311
6.40	11.36	3.165
6.41	11.46	3.012
6.41	11.56	2.858
6.42	11.66	2.712
6.43	11.76	2.575
6.43	11.87	2.448
6.44	11.97	2.336
6.45	12.07	2.236
6.45	12.17	2.142
6.46	12.27	2.058
6.47	12.37	1.980
6.47	12.47	1.908
6.48	12.56	1.843
6.49	12.66	1.778
6.49	12.75	1.722
6.50	12.85	1.668
6.51	12.94	1.616
6.51	13.03	1.567
6.52	13.12	1.522
6.53	13.21	1.478
6.53	13.29	1.438
6.54	13.38	1.398
6.55	13.47	1.361
6.55	13.55	1.326
6.56	13.63	1.291
6.57	13.72	1.260
6.57	13.80	1.233
6.58	13.88	1.205
6.59	13.96	1.171
6.59	14.04	1.136
6.60	14.12	1.115
6.61	14.20	1.102
6.61	14.28	1.081
6.62	14.36	1.054
6.63	14.43	1.029
6.63	14.51	1.009
6.64	14.59	0.990
6.65	14.66	0.974
6.65	14.74	0.958
6.66	14.81	0.940
6.67	14.89	0.924
6.67	14.96	0.911
6.68	15.03	0.896
6.69	15.11	0.882
6.69	15.18	0.869
6.70	15.25	0.855
6.71	15.33	0.845
6.71	15.40	0.835
6.72	15.47	0.823
6.73	15.54	0.812
6.73	15.62	0.803
6.74	15.69	0.795
6.75	15.76	0.786
6.75	15.83	0.778
6.76	15.90	0.769
6.77	15.97	0.761
6.77	16.04	0.754
6.78	16.11	0.748
6.79	16.18	0.743
6.79	16.25	0.736
6.80	16.32	0.730
6.81	16.39	0.723
6.81	16.46	0.717
6.82	16.53	0.713
6.83	16.60	0.710
6.83	16.67	0.704
6.84	16.74	0.699
6.85	16.81	0.695
6.85	16.88	0.692
6.86	16.94	0.688
6.87	17.01	0.683
6.87	17.08	0.679
6.88	17.15	0.676
6.89	17.22	0.673
6.89	17.29	0.669
6.90	17.35	0.666
6.91	17.42	0.664
6.91	17.49	0.662
6.92	17.56	0.660
6.93	17.63	0.658
6.93	17.69	0.655
6.94	17.76	0.652
6.95	17.83	0.650
6.95	17.90	0.649
6.96	17.97	0.647
6.97	18.03	0.645
6.97	18.10	0.644
6.98	18.17	0.643
6.99	18.24	0.641
6.99	18.30	0.640
7.00	18.37	0.639
7.01	18.44	0.638
7.01	18.51	0.637
7.02	18.57	0.636
7.03	18.64	0.635
7.03	18.71	0.633
7.04	18.78	0.632
7.05	18.84	0.632
7.05	18.91	0.631
7.06	18.98	0.629
7.07	19.04	0.627
7.07	19.11	0.627
7.08	19.18	0.627
7.09	19.24	0.626
7.09	19.31	0.625
7.10	19.38	0.625
7.11	19.45	0.624
7.11	19.51	0.624
7.12	19.58	0.624
7.13	19.65	0.624
7.13	19.71	0.623
7.14	19.78	0.622
7.15	19.85	0.622
7.15	19.92	0.622
7.16	19.98	0.621
7.17	20.05	0.621
7.17	20.12	0.620
7.18	20.18	0.620
7.19	20.25	0.620
7.19	20.32	0.620
7.20	20.38	0.619
7.21	20.45	0.619
7.21	20.52	0.619
7.22	20.59	0.618
7.23	20.65	0.618
7.23	20.72	0.618
7.24	20.79	0.618
7.25	20.85	0.618
7.25	20.92	0.617
7.26	20.99	0.617
7.27	21.05	0.617
7.27	21.12	0.617
7.28	21.19	0.617
7.29	21.25	0.616
7.29	21.32	0.616
7.30	21.39	0.616
7.31	21.45	0.616
7.31	21.52	0.616
7.32	21.59	0.616
7.33	21.65	0.615
7.33	21.72	0.615
7.34	21.79	0.615
7.35	21.86	0.615
7.35	21.92	0.615
7.36	21.99	0.615
7.37	22.06	0.615
7.37	22.12	0.614
7.38	22.19	0.614
7.39	22.26	0.614
7.39	22.32	0.614
7.40	22.39	0.614
7.41	22.46	0.614
7.41	22.52	0.614
7.42	22.59	0.614
7.43	22.66	0.613
7.43	22.72	0.613
7.44	22.79	0.613
7.45	22.86	0.613
7.45	22.92	0.613
7.46	22.99	0.613
7.47	23.06	0.613
7.47	23.13	0.612
7.48	23.19	0.612
7.49	23.26	0.612
7.49	23.33	0.612
7.50	23.39	0.612
7.51	23.46	0.612
7.51	23.52	0.612
7.52	23.59	0.612
7.53	23.66	0.612
7.53	23.72	0.612
7.54	23.79	0.611
7.55	23.86	0.611
7.55	23.92	0.611
7.56	23.99	0.611
7.57	24.06	0.611
7.57	24.13	0.611
7.58	24.19	0.611
7.59	24.26	0.611
7.59	24.32	0.611
7.60	24.39	0.611
7.61	24.46	0.611
7.61	24.53	0.610
7.62	24.59	0.610
7.63	24.66	0.610
7.63	24.73	0.610
7.64	24.79	0.610
7.65	24.86	0.610
7.65	24.93	0.610
7.66	24.99	0.610
7.67	25.06	0.610
7.67	25.13	0.610
7.68	25.19	0.610
7.69	25.26	0.610
7.69	25.33	0.610
7.70	25.39	0.610
7.71	25.46	0.610
7.71	25.53	0.609
7.72	25.59	0.609
7.73	25.66	0.609
7.73	25.73	0.609
7.74	25.80	0.609
7.75	25.86	0.609
7.75	25.93	0.609
7.76	26.00	0.609
7.77	26.06	0.609
7.77	26.13	0.609
7.78	26.19	0.609
7.79	26.26	0.609
7.79	26.33	0.609
7.80	26.39	0.609
7.81	26.46	0.609
7.81	26.53	0.609
7.82	26.60	0.609
7.83	26.66	0.609
7.83	26.73	0.609
7.84	26.80	0.608
7.85	26.86	0.608
7.85	26.93	0.608
7.86	27.00	0.608
7.87	27.06	0.608
7.87	27.13	0.608
7.88	27.20	0.608
7.89	27.26	0.608
7.89	27.33	0.608
7.90	27.40	0.608
7.91	27.46	0.608
7.91	27.53	0.608
7.92	27.60	0.608
7.93	27.66	0.608
7.93	27.73	0.608
7.94	27.80	0.608
7.95	27.86	0.608
7.95	27.93	0.608
7.96	28.00	0.608
7.97	28.06	0.608
7.97	28.13	0.608
7.98	28.20	0.608
7.99	28.26	0.608
7.99	28.33	0.608
8.00	28.40	0.608
8.01	28.46	0.608
8.01	28.53	0.608
8.02	28.60	0.608
8.03	28.66	0.608
8.03	28.73	0.608
8.04	28.80	0.608
8.05	28.86	0.608
8.05	28.93	0.608
8.06	29.00	0.608
8.07	29.07	0.608
8.07	29.13	0.608
8.08	29.20	0.607
8.09	29.27	0.607
8.09	29.33	0.607
8.10	29.40	0.607
8.11	29.47	0.607
8.11	29.53	0.607
8.12	29.60	0.607
8.13	29.67	0.607
8.13	29.73	0.607
8.14	29.80	0.607
8.15	29.87	0.607
8.15	29.93	0.607
8.16	30.00	0.607
8.17	30.07	0.607
8.17	30.13	0.607
8.18	30.20	0.607
8.19	30.27	0.607
8.19	30.33	0.607
8.20	30.40	0.607
8.21	30.47	0.607
8.21	30.53	0.607
8.22	30.60	0.607
8.23	30.67	0.607
8.23	30.73	0.607
8.24	30.80	0.607
8.25	30.87	0.607
8.25	30.93	0.607
8.26	31.00	0.607
8.27	31.07	0.607
8.27	31.14	0.607
8.28	31.20	0.607
8.29	31.27	0.607
8.29	31.34	0.607
8.30	31.40	0.607
8.31	31.47	0.608
8.31	31.54	0.608
8.32	31.60	0.608
8.33	31.67	0.608
8.33	31.74	0.608
8.34	31.80	0.608
8.35	31.87	0.608
8.35	31.94	0.608
8.36	32.00	0.608
8.37	32.07	0.608
8.37	32.14	0.608
8.38	32.20	0.608
8.39	32.27	0.608
8.39	32.34	0.608
8.40	32.40	0.608
8.41	32.47	0.608
8.41	32.54	0.608
8.42	32.60	0.608
8.43	32.67	0.608
8.43	32.74	0.608
8.44	32.80	0.608
8.45	32.87	0.608
8.45	32.94	0.608
8.46	33.00	0.608
8.47	33.07	0.608
8.47	33.14	0.608
8.48	33.20	0.608
8.49	33.27	0.608
8.49	33.34	0.608
8.50	33.40	0.608
8.51	33.47	0.608
8.51	33.54	0.608
8.52	33.60	0.608
8.53	33.67	0.608
8.53	33.74	0.608
8.54	33.81	0.608
8.55	33.87	0.608
8.55	33.94	0.608
8.56	34.01	0.608
8.57	34.07	0.608
8.57	34.14	0.608
8.58	34.20	0.608
8.59	34.27	0.608
8.59	34.34	0.608
8.60	34.41	0.608
8.61	34.47	0.608
8.61	34.54	0.608
8.62	34.61	0.608
8.63	34.67	0.608
8.63	34.74	0.608
8.64	34.81	0.608
8.65	34.87	0.608
8.65	34.94	0.608
8.66	35.01	0.608
8.67	35.07	0.608
8.67	35.14	0.608
8.68	35.21	0.608
8.69	35.27	0.608
8.69	35.34	0.608
8.70	35.41	0.608
8.71	35.47	0.608
8.71	35.54	0.608
8.72	35.61	0.608
8.73	35.67	0.608
8.73	35.74	0.608
8.74	35.81	0.608
8.75	35.87	0.608
8.75	35.94	0.608
8.76	36.01	0.608
8.77	36.07	0.608
8.77	36.14	0.608
8.78	36.21	0.608
8.79	36.28	0.608
8.79	36.34	0.608
8.80	36.41	0.608
8.81	36.47	0.608
8.81	36.54	0.608
8.82	36.61	0.608
8.83	36.67	0.608
8.83	36.74	0.608
8.84	36.81	0.608
8.85	36.87	0.608
8.85	36.94	0.608
8.86	37.01	0.609
8.87	37.07	0.609
8.87	37.14	0.609
8.88	37.21	0.609
8.89	37.27	0.609
8.89	37.34	0.609
8.90	37.41	0.609
8.91	37.48	0.609
8.91	37.54	0.609
8.92	37.61	0.609
8.93	37.68	0.609
8.93	37.74	0.609
8.94	37.81	0.609
8.95	37.88	0.609
8.95	37.94	0.609
8.96	38.01	0.609
8.97	38.08	0.609
8.97	38.14	0.609
8.98	38.21	0.609
8.99	38.28	0.609
8.99	38.34	0.609
9.00	38.41	0.609
9.01	38.48	0.609
9.01	38.54	0.609
9.02	38.61	0.609
9.03	38.68	0.609
9.03	38.74	0.609
9.04	38.81	0.609
9.05	38.88	0.609
9.05	38.94	0.609
9.06	39.01	0.609
9.07	39.08	0.609
9.07	39.14	0.609
9.08	39.21	0.609
9.09	39.28	0.609
9.09	39.35	0.609
9.10	39.41	0.609
9.11	39.48	0.609
9.11	39.54	0.609
9.12	39.61	0.609
9.13	39.68	0.609
9.13	39.74	0.609
9.14	39.81	0.609
9.15	39.88	0.609
9.15	39.94	0.609
9.16	40.01	0.609
9.17	40.08	0.609
9.17	40.15	0.609
9.18	40.21	0.609
9.19	40.28	0.609
9.19	40.35	0.609
9.20	40.41	0.609
9.21	40.48	0.609
9.21	40.55	0.609
9.22	40.61	0.609
9.23	40.68	0.609
9.23	40.75	0.609
9.24	40.81	0.609
9.25	40.88	0.609
9.25	40.95	0.609
9.26	41.01	0.609
9.27	41.08	0.609
9.27	41.15	0.609
9.28	41.21	0.609
9.29	41.28	0.609
9.29	41.35	0.609
9.30	41.41	0.610
9.31	41.48	0.610
9.31	41.55	0.610
9.32	41.61	0.610
9.33	41.68	0.610
9.33	41.75	0.610
9.34	41.81	0.610
9.35	41.88	0.610
9.35	41.95	0.610
9.36	42.02	0.610
9.37	42.08	0.610
9.37	42.15	0.610
9.38	42.22	0.610
9.39	42.28	0.610
9.39	42.35	0.610
9.40	42.41	0.610
9.41	42.48	0.610
9.41	42.55	0.610
9.42	42.61	0.610
9.43	42.68	0.610
9.43	42.75	0.610
9.44	42.82	0.610
9.45	42.88	0.610
9.45	42.95	0.610
9.46	43.02	0.610
9.47	43.08	0.610
9.47	43.15	0.610
9.48	43.22	0.610
9.49	43.28	0.610
9.49	43.35	0.610
9.50	43.42	0.610
9.51	43.48	0.610
9.51	43.55	0.610
9.52	43.62	0.610
9.53	43.68	0.610
9.53	43.75	0.610
9.54	43.82	0.610
9.55	43.88	0.610
9.55	43.95	0.610
9.56	44.02	0.610
9.57	44.08	0.610
9.57	44.15	0.610
9.58	44.22	0.610
9.59	44.28	0.610
9.59	44.35	0.611
9.60	44.42	0.611
9.61	44.48	0.611
9.61	44.55	0.611
9.62	44.62	0.611
9.63	44.68	0.611
9.63	44.75	0.611
9.64	44.82	0.611
9.65	44.88	0.611
9.65	44.95	0.611
9.66	45.02	0.611
9.67	45.08	0.611
9.67	45.15	0.611
9.68	45.22	0.611
9.69	45.28	0.611
9.69	45.35	0.611
9.70	45.42	0.611
9.71	45.48	0.611
9.71	45.55	0.611
9.72	45.62	0.611
9.73	45.69	0.611
9.73	45.75	0.611
9.74	45.82	0.611
9.75	45.89	0.611
9.75	45.95	0.611
9.76	46.02	0.611
9.77	46.08	0.611
9.77	46.15	0.611
9.78	46.22	0.611
9.79	46.29	0.611
9.79	46.35	0.611
9.80	46.42	0.611
9.81	46.49	0.612
9.81	46.55	0.612
9.82	46.62	0.612
9.83	46.69	0.612
9.83	46.75	0.612
9.84	46.82	0.612
9.85	46.89	0.612
9.85	46.95	0.612
9.86	47.02	0.612
9.87	47.09	0.612
9.87	47.15	0.612
9.88	47.22	0.612
9.89	47.29	0.612
9.89	47.35	0.612
9.90	47.42	0.612
9.91	47.49	0.612
9.91	47.55	0.612
9.92	47.62	0.612
9.93	47.69	0.612
9.93	47.75	0.612
9.94	47.82	0.612
9.95	47.89	0.612
9.95	47.95	0.612
9.96	48.02	0.612
9.97	48.09	0.612
9.97	48.15	0.612
9.98	48.22	0.612
9.99	48.29	0.612
9.99	48.35	0.612

[step]
Ramp 10.00 °C/min to -50.00 °C
Time	Temperature	Heat Flow (Normalized)
min	°C	W/g
11.00	50.07	-0.020
11.00	50.08	-0.021
11.01	50.08	-0.021
11.02	50.08	-0.022
11.02	50.07	-0.022
11.03	50.07	-0.022
11.03	50.07	-0.022
11.04	50.07	-0.020
11.05	50.06	-0.009
11.05	50.05	0.007
11.06	50.04	0.021
11.07	50.03	0.037
11.08	50.01	0.052
11.08	49.99	0.067
11.09	49.97	0.080
11.10	49.94	0.088
11.10	49.92	0.093
11.11	49.89	0.095
11.12	49.85	0.090
11.12	49.82	0.082
11.13	49.78	0.072
11.13	49.74	0.057
11.14	49.70	0.034
11.15	49.65	0.010
11.15	49.61	-0.015
11.16	49.56	-0.041
11.17	49.52	-0.068
11.18	49.47	-0.098
11.18	49.42	-0.125
11.19	49.37	-0.152
11.20	49.32	-0.178
11.20	49.27	-0.202
11.21	49.22	-0.226
11.22	49.17	-0.251
11.22	49.11	-0.272
11.23	49.06	-0.291
11.23	49.01	-0.309
11.24	48.95	-0.328
11.25	48.90	-0.343
11.25	48.84	-0.358
11.26	48.79	-0.372
11.27	48.73	-0.386
11.28	48.67	-0.402
11.28	48.62	-0.415
11.29	48.56	-0.425
11.30	48.50	-0.436
11.30	48.44	-0.448
11.31	48.38	-0.457
11.32	48.33	-0.466
11.32	48.27	-0.478
11.33	48.21	-0.486
11.33	48.15	-0.494
11.34	48.09	-0.504
11.35	48.03	-0.513
11.35	47.97	-0.520
11.36	47.90	-0.526
11.37	47.84	-0.532
11.38	47.78	-0.539
11.38	47.72	-0.547
11.39	47.66	-0.553
11.40	47.60	-0.559
11.40	47.54	-0.564
11.41	47.47	-0.568
11.42	47.41	-0.574
11.42	47.35	-0.580
11.43	47.29	-0.585
11.43	47.22	-0.590
11.44	47.16	-0.592
11.45	47.10	-0.595
11.45	47.03	-0.600
11.46	46.97	-0.603
11.47	46.91	-0.606
11.48	46.84	-0.611
11.48	46.78	-0.614
11.49	46.71	-0.615
11.50	46.65	-0.617
11.50	46.59	-0.621
11.51	46.52	-0.622
11.52	46.46	-0.627
11.52	46.40	-0.629
11.53	46.33	-0.629
11.53	46.27	-0.630
11.54	46.20	-0.633
11.55	46.14	-0.636
11.55	46.07	-0.637
11.56	46.01	-0.638
11.57	45.94	-0.640
11.58	45.88	-0.642
11.58	45.81	-0.643
11.59	45.75	-0.644
11.60	45.68	-0.646
11.60	45.62	-0.647
11.61	45.55	-0.648
11.62	45.49	-0.650
11.62	45.42	-0.652
11.63	45.36	-0.653
11.63	45.29	-0.654
11.64	45.23	-0.655
11.65	45.16	-0.656
11.65	45.10	-0.656
11.66	45.03	-0.656
11.67	44.97	-0.658
11.68	44.90	-0.658
11.68	44.83	-0.658
11.69	44.77	-0.659
11.70	44.70	-0.660
11.70	44.64	-0.660
11.71	44.57	-0.661
11.72	44.51	-0.662
11.72	44.44	-0.662
11.73	44.38	-0.662
11.73	44.31	-0.662
11.74	44.25	-0.663
11.75	44.18	-0.663
11.75	44.12	-0.664
11.76	44.05	-0.664
11.77	43.98	-0.664
11.78	43.92	-0.665
11.78	43.85	-0.665
11.79	43.79	-0.665
11.80	43.72	-0.666
11.80	43.65	-0.666
11.81	43.59	-0.666
11.82	43.52	-0.666
11.82	43.46	-0.666
11.83	43.39	-0.667
11.83	43.32	-0.667
11.84	43.26	-0.668
11.85	43.19	-0.668
11.85	43.13	-0.668
11.86	43.06	-0.668
11.87	43.00	-0.669
11.88	42.93	-0.669
11.88	42.86	-0.669
11.89	42.80	-0.669
11.90	42.73	-0.669
11.90	42.66	-0.670
11.91	42.60	-0.670
11.92	42.53	-0.670
11.92	42.47	-0.670
11.93	42.40	-0.670
11.93	42.33	-0.670
11.94	42.27	-0.671
11.95	42.20	-0.671
11.95	42.14	-0.671
11.96	42.07	-0.671
11.97	42.00	-0.671
11.98	41.94	-0.671
11.98	41.87	-0.672
11.99	41.80	-0.672
12.00	41.74	-0.672
12.00	41.67	-0.672
12.01	41.61	-0.672
12.02	41.54	-0.672
12.02	41.47	-0.672
12.03	41.41	-0.673
12.03	41.34	-0.673
12.04	41.28	-0.673
12.05	41.21	-0.673
12.05	41.14	-0.673
12.06	41.08	-0.673
12.07	41.01	-0.673
12.08	40.94	-0.674
12.08	40.88	-0.674
12.09	40.81	-0.674
12.10	40.75	-0.674
12.10	40.68	-0.674
12.11	40.61	-0.674
12.12	40.55	-0.674
12.12	40.48	-0.674
12.13	40.42	-0.674
12.13	40.35	-0.674
12.14	40.28	-0.675
12.15	40.22	-0.675
12.15	40.15	-0.675
12.16	40.08	-0.675
12.17	40.02	-0.675
12.18	39.95	-0.675
12.18	39.88	-0.675
12.19	39.82	-0.675
12.20	39.75	-0.675
12.20	39.69	-0.675
12.21	39.62	-0.675
12.22	39.55	-0.675
12.22	39.49	-0.675
12.23	39.42	-0.676
12.23	39.35	-0.676
12.24	39.29	-0.676
12.25	39.22	-0.676
12.25	39.15	-0.676
12.26	39.09	-0.676
12.27	39.02	-0.676
12.28	38.95	-0.676
12.28	38.89	-0.676
12.29	38.82	-0.676
12.30	38.76	-0.676
12.30	38.69	-0.676
12.31	38.62	-0.676
12.32	38.56	-0.676
12.32	38.49	-0.676
12.33	38.42	-0.676
12.33	38.36	-0.677
12.34	38.29	-0.677
12.35	38.22	-0.677
12.35	38.16	-0.677
12.36	38.09	-0.677
12.37	38.02	-0.677
12.38	37.96	-0.677
12.38	37.89	-0.677
12.39	37.83	-0.677
12.40	37.76	-0.677
12.40	37.69	-0.677
12.41	37.63	-0.677
12.42	37.56	-0.677
12.42	37.49	-0.677
12.43	37.43	-0.677
12.43	37.36	-0.677
12.44	37.30	-0.677
12.45	37.23	-0.678
12.45	37.16	-0.678
12.46	37.10	-0.678
12.47	37.03	-0.678
12.48	36.96	-0.678
12.48	36.90	-0.678
12.49	36.83	-0.678
12.50	36.76	-0.678
12.50	36.70	-0.678
12.51	36.63	-0.678
12.52	36.56	-0.678
12.52	36.50	-0.678
12.53	36.43	-0.678
12.53	36.36	-0.678
12.54	36.30	-0.678
12.55	36.23	-0.678
12.55	36.16	-0.678
12.56	36.10	-0.678
12.57	36.03	-0.678
12.58	35.96	-0.678
12.58	35.90	-0.678
12.59	35.83	-0.678
12.60	35.77	-0.678
12.60	35.70	-0.678
12.61	35.63	-0.678
12.62	35.57	-0.678
12.62	35.50	-0.678
12.63	35.43	-0.678
12.63	35.37	-0.678
12.64	35.30	-0.678
12.65	35.23	-0.678
12.65	35.17	-0.678
12.66	35.10	-0.678
12.67	35.03	-0.678
12.68	34.97	-0.678
12.68	34.90	-0.678
12.69	34.83	-0.678
12.70	34.77	-0.678
12.70	34.70	-0.678
12.71	34.63	-0.678
12.72	34.57	-0.677
12.72	34.50	-0.677
12.73	34.44	-0.677
12.73	34.37	-0.677
12.74	34.30	-0.677
12.75	34.23	-0.677
12.75	34.17	-0.677
12.76	34.10	-0.677
12.77	34.04	-0.677
12.78	33.97	-0.677
12.78	33.90	-0.677
12.79	33.83	-0.677
12.80	33.77	-0.677
12.80	33.70	-0.677
12.81	33.64	-0.677
12.82	33.57	-0.677
12.82	33.50	-0.677
12.83	33.44	-0.677
12.83	33.37	-0.677
12.84	33.30	-0.677
12.85	33.24	-0.677
12.85	33.17	-0.677
12.86	33.10	-0.677
12.87	33.04	-0.677
12.88	32.97	-0.677
12.88	32.90	-0.677
12.89	32.84	-0.677
12.90	32.77	-0.677
12.90	32.70	-0.677
12.91	32.64	-0.677
12.92	32.57	-0.677
12.92	32.50	-0.677
12.93	32.44	-0.677
12.93	32.37	-0.676
12.94	32.31	-0.676
12.95	32.24	-0.676
12.95	32.17	-0.676
12.96	32.10	-0.676
12.97	32.04	-0.676
12.98	31.97	-0.676
12.98	31.91	-0.676
12.99	31.84	-0.676
13.00	31.77	-0.676
13.00	31.71	-0.676
13.01	31.64	-0.676
13.02	31.57	-0.676
13.02	31.51	-0.676
13.03	31.44	-0.676
13.03	31.37	-0.676
13.04	31.31	-0.676
13.05	31.24	-0.676
13.05	31.17	-0.676
13.06	31.11	-0.676
13.07	31.04	-0.676
13.08	30.97	-0.676
13.08	30.91	-0.676
13.09	30.84	-0.676
13.10	30.77	-0.676
13.10	30.71	-0.676
13.11	30.64	-0.676
13.12	30.57	-0.675
13.12	30.51	-0.675
13.13	30.44	-0.675
13.13	30.38	-0.675
13.14	30.31	-0.675
13.15	30.24	-0.672
13.15	30.18	-0.670
13.16	30.11	-0.670
13.17	30.04	-0.670
13.18	29.98	-0.670
13.18	29.91	-0.670
13.19	29.84	-0.670
13.20	29.78	-0.670
13.20	29.71	-0.670
13.21	29.64	-0.670
13.22	29.58	-0.670
13.22	29.51	-0.670
13.23	29.44	-0.670
13.23	29.38	-0.670
13.24	29.31	-0.670
13.25	29.24	-0.670
13.25	29.18	-0.670
13.26	29.11	-0.670
13.27	29.04	-0.670
13.28	28.98	-0.670
13.28	28.91	-0.670
13.29	28.84	-0.670
13.30	28.78	-0.670
13.30	28.71	-0.670
13.31	28.64	-0.670
13.32	28.58	-0.670
13.32	28.51	-0.670
13.33	28.45	-0.670
13.33	28.38	-0.670
13.34	28.31	-0.670
13.35	28.24	-0.670
13.35	28.18	-0.670
13.36	28.11	-0.670
13.37	28.04	-0.670
13.38	27.98	-0.670
13.38	27.91	-0.670
13.39	27.85	-0.670
13.40	27.78	-0.670
13.40	27.71	-0.670
13.41	27.65	-0.670
13.42	27.58	-0.670
13.42	27.51	-0.670
13.43	27.45	-0.670
13.43	27.38	-0.670
13.44	27.31	-0.670
13.45	27.25	-0.670
13.45	27.18	-0.670
13.46	27.11	-0.670
13.47	27.05	-0.670
13.48	26.98	-0.670
13.48	26.91	-0.670
13.49	26.85	-0.670
13.50	26.78	-0.670
13.50	26.72	-0.670
13.51	26.65	-0.670
13.52	26.58	-0.670
13.52	26.51	-0.670
13.53	26.45	-0.670
13.53	26.38	-0.670
13.54	26.31	-0.670
13.55	26.25	-0.670
13.55	26.18	-0.670
13.56	26.11	-0.670
13.57	26.05	-0.670
13.58	25.98	-0.670
13.58	25.92	-0.670
13.59	25.85	-0.670
13.60	25.78	-0.670
13.60	25.71	-0.670
13.61	25.65	-0.670
13.62	25.58	-0.670
13.62	25.52	-0.670
13.63	25.45	-0.670
13.63	25.38	-0.670
13.64	25.32	-0.670
13.65	25.25	-0.670
13.65	25.18	-0.670
13.66	25.12	-0.670
13.67	25.05	-0.670
13.68	24.98	-0.669
13.68	24.92	-0.669
13.69	24.85	-0.669
13.70	24.78	-0.669
13.70	24.72	-0.669
13.71	24.65	-0.669
13.72	24.58	-0.669
13.72	24.52	-0.669
13.73	24.45	-0.669
13.73	24.39	-0.669
13.74	24.32	-0.669
13.75	24.25	-0.669
13.75	24.19	-0.669
13.76	24.12	-0.669
13.77	24.05	-0.669
13.78	23.99	-0.669
13.78	23.92	-0.669
13.79	23.85	-0.669
13.80	23.79	-0.669
13.80	23.72	-0.669
13.81	23.65	-0.669
13.82	23.59	-0.669
13.82	23.52	-0.669
13.83	23.45	-0.669
13.83	23.39	-0.669
13.84	23.32	-0.669
13.85	23.25	-0.669
13.85	23.19	-0.669
13.86	23.12	-0.669
13.87	23.05	-0.668
13.88	22.99	-0.668
13.88	22.92	-0.668
13.89	22.85	-0.668
13.90	22.79	-0.668
13.90	22.72	-0.668
13.91	22.65	-0.668
13.92	22.59	-0.668
13.92	22.52	-0.668
13.93	22.45	-0.668
13.93	22.39	-0.668
13.94	22.32	-0.668
13.95	22.25	-0.668
13.95	22.19	-0.668
13.96	22.12	-0.668
13.97	22.05	-0.668
13.98	21.99	-0.668
13.98	21.92	-0.667
13.99	21.85	-0.667
14.00	21.79	-0.667
14.00	21.72	-0.667
14.01	21.65	-0.667
14.02	21.59	-0.667
14.02	21.52	-0.667
14.03	21.45	-0.667
14.03	21.39	-0.667
14.04	21.32	-0.667
14.05	21.25	-0.667
14.05	21.19	-0.667
14.06	21.12	-0.667
14.07	21.05	-0.667
14.08	20.99	-0.667
14.08	20.92	-0.667
14.09	20.86	-0.667
14.10	20.79	-0.667
14.10	20.72	-0.666
14.11	20.66	-0.666
14.12	20.59	-0.666
14.12	20.52	-0.666
14.13	20.46	-0.666
14.13	20.39	-0.666
14.14	20.32	-0.666
14.15	20.26	-0.666
14.15	20.19	-0.666
14.16	20.12	-0.666
14.17	20.06	-0.666
14.18	19.99	-0.666
14.18	19.92	-0.666
14.19	19.86	-0.666
14.20	19.79	-0.665
14.20	19.72	-0.665
14.21	19.66	-0.665
14.22	19.59	-0.665
14.22	19.52	-0.665
14.23	19.46	-0.665
14.23	19.39	-0.665
14.24	19.32	-0.665
14.25	19.26	-0.665
14.25	19.19	-0.665
14.26	19.12	-0.665
14.27	19.06	-0.665
14.28	18.99	-0.665
14.28	18.92	-0.665
14.29	18.86	-0.665
14.30	18.79	-0.665
14.30	18.72	-0.665
14.31	18.66	-0.665
14.32	18.59	-0.664
14.32	18.52	-0.664
14.33	18.46	-0.664
14.33	18.39	-0.664
14.34	18.33	-0.664
14.35	18.26	-0.664
14.35	18.19	-0.664
14.36	18.13	-0.664
14.37	18.06	-0.664
14.38	17.99	-0.664
14.38	17.93	-0.664
14.39	17.86	-0.664
14.40	17.79	-0.664
14.40	17.73	-0.664
14.41	17.66	-0.664
14.42	17.59	-0.664
14.42	17.53	-0.664
14.43	17.46	-0.664
14.43	17.39	-0.664
14.44	17.33	-0.664
14.45	17.26	-0.663
14.45	17.19	-0.663
14.46	17.13	-0.663
14.47	17.06	-0.663
14.48	16.99	-0.663
14.48	16.93	-0.663
14.49	16.86	-0.663
14.50	16.79	-0.663
14.50	16.73	-0.663
14.51	16.66	-0.663
14.52	16.59	-0.663
14.52	16.53	-0.663
14.53	16.46	-0.663
14.53	16.40	-0.663
14.54	16.33	-0.663
14.55	16.26	-0.663
14.55	16.19	-0.663
14.56	16.13	-0.663
14.57	16.06	-0.663
14.58	16.00	-0.663
14.58	15.93	-0.663
14.59	15.86	-0.662
14.60	15.80	-0.662
14.60	15.73	-0.662
14.61	15.66	-0.662
14.62	15.60	-0.662
14.62	15.53	-0.662
14.63	15.46	-0.662
14.63	15.40	-0.662
14.64	15.33	-0.662
14.65	15.26	-0.662
14.65	15.20	-0.662
14.66	15.13	-0.662
14.67	15.06	-0.662
14.68	15.00	-0.662
14.68	14.93	-0.662
14.69	14.86	-0.662
14.70	14.80	-0.662
14.70	14.73	-0.662
14.71	14.66	-0.662
14.72	14.60	-0.662
14.72	14.53	-0.662
14.73	14.46	-0.662
14.73	14.40	-0.662
14.74	14.33	-0.662
14.75	14.26	-0.662
14.75	14.20	-0.662
14.76	14.13	-0.662
14.77	14.06	-0.662
14.78	14.00	-0.662
14.78	13.93	-0.662
14.79	13.87	-0.662
14.80	13.80	-0.662
14.80	13.73	-0.662
14.81	13.66	-0.662
14.82	13.60	-0.662
14.82	13.53	-0.662
14.83	13.47	-0.662
14.83	13.40	-0.662
14.84	13.33	-0.662
14.85	13.27	-0.662
14.85	13.20	-0.662
14.86	13.13	-0.662
14.87	13.07	-0.662
14.88	13.00	-0.662
14.88	12.93	-0.662
14.89	12.87	-0.662
14.90	12.80	-0.661
14.90	12.73	-0.661
14.91	12.67	-0.662
14.92	12.60	-0.662
14.92	12.53	-0.661
14.93	12.47	-0.661
14.93	12.40	-0.661
14.94	12.33	-0.661
14.95	12.27	-0.661
14.95	12.20	-0.661
14.96	12.13	-0.661
14.97	12.07	-0.661
14.98	12.00	-0.661
14.98	11.94	-0.661
14.99	11.87	-0.661
15.00	11.80	-0.661
15.00	11.73	-0.661
15.01	11.67	-0.661
15.02	11.60	-0.661
15.02	11.54	-0.661
15.03	11.47	-0.661
15.03	11.40	-0.661
15.04	11.34	-0.661
15.05	11.27	-0.661
15.05	11.20	-0.661
15.06	11.14	-0.661
15.07	11.07	-0.661
15.08	11.00	-0.661
15.08	10.94	-0.661
15.09	10.87	-0.661
15.10	10.80	-0.661
15.10	10.74	-0.661
15.11	10.67	-0.661
15.12	10.60	-0.661
15.12	10.54	-0.661
15.13	10.47	-0.661
15.13	10.40	-0.661
15.14	10.34	-0.661
15.15	10.27	-0.661
15.15	10.20	-0.661
15.16	10.14	-0.661
15.17	10.07	-0.661
15.18	10.00	-0.661
15.18	9.94	-0.661
15.19	9.87	-0.661
15.20	9.80	-0.661
15.20	9.74	-0.661
15.21	9.67	-0.661
15.22	9.61	-0.661
15.22	9.54	-0.661
15.23	9.47	-0.661
15.23	9.41	-0.661
15.24	9.34	-0.661
15.25	9.27	-0.661
15.25	9.21	-0.661
15.26	9.14	-0.661
15.27	9.07	-0.661
15.28	9.01	-0.661
15.28	8.94	-0.661
15.29	8.87	-0.660
15.30	8.81	-0.660
15.30	8.74	-0.660
15.31	8.67	-0.660
15.32	8.61	-0.660
15.32	8.54	-0.660
15.33	8.47	-0.660
15.33	8.41	-0.660
15.34	8.34	-0.660
15.35	8.28	-0.660
15.35	8.21	-0.660
15.36	8.14	-0.660
15.37	8.08	-0.660
15.38	8.01	-0.660
15.38	7.94	-0.660
15.39	7.88	-0.660
15.40	7.81	-0.660
15.40	7.74	-0.660
15.41	7.68	-0.660
15.42	7.61	-0.660
15.42	7.54	-0.660
15.43	7.48	-0.660
15.43	7.41	-0.660
15.44	7.34	-0.660
15.45	7.28	-0.660
15.45	7.21	-0.660
15.46	7.14	-0.660
15.47	7.08	-0.660
15.48	7.01	-0.660
15.48	6.94	-0.660
15.49	6.88	-0.660
15.50	6.81	-0.658
15.50	6.75	-0.657
15.51	6.68	-0.657
15.52	6.61	-0.657
15.52	6.54	-0.657
15.53	6.48	-0.657
15.53	6.41	-0.657
15.54	6.34	-0.657
15.55	6.28	-0.657
15.55	6.21	-0.657
15.56	6.15	-0.657
15.57	6.08	-0.657
15.58	6.01	-0.657
15.58	5.95	-0.657
15.59	5.88	-0.658
15.60	5.81	-0.657
15.60	5.75	-0.658
15.61	5.68	-0.658
15.62	5.61	-0.658
15.62	5.55	-0.658
15.63	5.48	-0.658
15.63	5.41	-0.658
15.64	5.35	-0.658
15.65	5.28	-0.658
15.65	5.21	-0.658
15.66	5.15	-0.658
15.67	5.08	-0.658
15.68	5.01	-0.658
15.68	4.95	-0.658
15.69	4.88	-0.658
15.70	4.82	-0.658
15.70	4.75	-0.658
15.71	4.68	-0.658
15.72	4.62	-0.658
15.72	4.55	-0.658
15.73	4.48	-0.658
15.73	4.41	-0.658
15.74	4.35	-0.659
15.75	4.28	-0.659
15.75	4.22	-0.659
15.76	4.15	-0.659
15.77	4.08	-0.659
15.78	4.02	-0.659
15.78	3.95	-0.659
15.79	3.88	-0.659
15.80	3.82	-0.659
15.80	3.75	-0.659
15.81	3.68	-0.659
15.82	3.62	-0.659
15.82	3.55	-0.659
15.83	3.48	-0.659
15.83	3.42	-0.659
15.84	3.35	-0.659
15.85	3.28	-0.659
15.85	3.22	-0.659
15.86	3.15	-0.659
15.87	3.08	-0.659
15.88	3.02	-0.659
15.88	2.95	-0.660
15.89	2.88	-0.660
15.90	2.82	-0.660
15.90	2.75	-0.660
15.91	2.68	-0.660
15.92	2.62	-0.660
15.92	2.55	-0.660
15.93	2.48	-0.660
15.93	2.42	-0.660
15.94	2.35	-0.660
15.95	2.28	-0.660
15.95	2.22	-0.660
15.96	2.15	-0.660
15.97	2.08	-0.660
15.98	2.02	-0.660
15.98	1.95	-0.660
15.99	1.88	-0.660
16.00	1.82	-0.660
16.00	1.75	-0.660
16.01	1.68	-0.660
16.02	1.62	-0.660
16.02	1.55	-0.660
16.03	1.48	-0.660
16.03	1.42	-0.660
16.04	1.35	-0.660
16.05	1.28	-0.660
16.05	1.22	-0.660
16.06	1.15	-0.660
16.07	1.08	-0.660
16.08	1.02	-0.660
16.08	0.95	-0.660
16.09	0.88	-0.660
16.10	0.82	-0.660
16.10	0.75	-0.660
16.11	0.68	-0.660
16.12	0.62	-0.660
16.12	0.55	-0.660
16.13	0.48	-0.660
16.13	0.42	-0.660
16.14	0.35	-0.660
16.15	0.28	-0.660
16.15	0.22	-0.660
16.16	0.15	-0.660
16.17	0.08	-0.660
16.18	0.02	-0.661
16.18	-0.05	-0.661
16.19	-0.12	-0.661
16.20	-0.18	-0.661
16.20	-0.25	-0.661
16.21	-0.32	-0.661
16.22	-0.38	-0.661
16.22	-0.45	-0.661
16.23	-0.52	-0.661
16.23	-0.58	-0.661
16.24	-0.65	-0.661
16.25	-0.72	-0.661
16.25	-0.78	-0.661
16.26	-0.85	-0.661
16.27	-0.92	-0.661
16.28	-0.98	-0.661
16.28	-1.05	-0.661
16.29	-1.12	-0.661
16.30	-1.18	-0.662
16.30	-1.25	-0.662
16.31	-1.32	-0.662
16.32	-1.38	-0.662
16.32	-1.45	-0.662
16.33	-1.52	-0.662
16.33	-1.58	-0.662
16.34	-1.65	-0.662
16.35	-1.72	-0.662
16.35	-1.78	-0.662
16.36	-1.85	-0.662
16.37	-1.92	-0.662
16.38	-1.98	-0.662
16.38	-2.05	-0.662
16.39	-2.12	-0.662
16.40	-2.18	-0.662
16.40	-2.25	-0.663
16.41	-2.32	-0.663
16.42	-2.38	-0.663
16.42	-2.45	-0.663
16.43	-2.52	-0.663
16.43	-2.58	-0.663
16.44	-2.65	-0.663
16.45	-2.72	-0.663
16.45	-2.78	-0.663
16.46	-2.85	-0.663
16.47	-2.92	-0.663
16.48	-2.98	-0.663
16.48	-3.05	-0.664
16.49	-3.12	-0.664
16.50	-3.18	-0.664
16.50	-3.25	-0.664
16.51	-3.32	-0.664
16.52	-3.38	-0.664
16.52	-3.45	-0.664
16.53	-3.52	-0.664
16.53	-3.58	-0.664
16.54	-3.65	-0.664
16.55	-3.72	-0.664
16.55	-3.78	-0.664
16.56	-3.85	-0.664
16.57	-3.92	-0.665
16.58	-3.98	-0.665
16.58	-4.05	-0.665
16.59	-4.12	-0.665
16.60	-4.18	-0.665
16.60	-4.25	-0.665
16.61	-4.32	-0.665
16.62	-4.38	-0.665
16.62	-4.45	-0.665
16.63	-4.52	-0.665
16.63	-4.58	-0.665
16.64	-4.65	-0.665
16.65	-4.72	-0.666
16.65	-4.78	-0.666
16.66	-4.85	-0.666
16.67	-4.92	-0.666
16.68	-4.98	-0.666
16.68	-5.05	-0.666
16.69	-5.12	-0.666
16.70	-5.18	-0.666
16.70	-5.25	-0.666
16.71	-5.32	-0.666
16.72	-5.39	-0.666
16.72	-5.45	-0.666
16.73	-5.52	-0.666
16.73	-5.58	-0.667
16.74	-5.65	-0.667
16.75	-5.72	-0.667
16.75	-5.78	-0.667
16.76	-5.85	-0.667
16.77	-5.92	-0.667
16.78	-5.98	-0.667
16.78	-6.05	-0.668
16.79	-6.12	-0.668
16.80	-6.18	-0.668
16.80	-6.25	-0.668
16.81	-6.32	-0.668
16.82	-6.38	-0.668
16.82	-6.45	-0.668
16.83	-6.52	-0.668
16.83	-6.58	-0.668
16.84	-6.65	-0.668
16.85	-6.72	-0.668
16.85	-6.79	-0.668
16.86	-6.85	-0.668
16.87	-6.92	-0.669
16.88	-6.98	-0.669
16.88	-7.05	-0.669
16.89	-7.12	-0.669
16.90	-7.18	-0.669
16.90	-7.25	-0.669
16.91	-7.32	-0.669
16.92	-7.38	-0.669
16.92	-7.45	-0.669
16.93	-7.52	-0.669
16.93	-7.58	-0.670
16.94	-7.65	-0.670
16.95	-7.72	-0.670
16.95	-7.78	-0.670
16.96	-7.85	-0.670
16.97	-7.92	-0.670
16.98	-7.98	-0.670
16.98	-8.05	-0.670
16.99	-8.12	-0.670
17.00	-8.18	-0.671
17.00	-8.25	-0.671
17.01	-8.32	-0.671
17.02	-8.39	-0.671
17.02	-8.45	-0.671
17.03	-8.52	-0.671
17.03	-8.59	-0.671
17.04	-8.65	-0.671
17.05	-8.72	-0.671
17.05	-8.78	-0.671
17.06	-8.85	-0.671
17.07	-8.92	-0.672
17.08	-8.98	-0.672
17.08	-9.05	-0.672
17.09	-9.12	-0.672
17.09	-9.18	-0.672
17.10	-9.25	-0.672
17.11	-9.32	-0.672
17.12	-9.38	-0.672
17.12	-9.45	-0.672
17.13	-9.52	-0.672
17.13	-9.59	-0.672
17.14	-9.65	-0.672
17.15	-9.72	-0.673
17.16	-9.78	-0.673
17.16	-9.85	-0.673
17.17	-9.92	-0.673
17.18	-9.98	-0.673
17.18	-10.05	-0.673
17.19	-10.12	-0.673
17.19	-10.18	-0.673
17.20	-10.25	-0.673
17.21	-10.32	-0.674
17.22	-10.39	-0.674
17.22	-10.45	-0.674
17.23	-10.52	-0.674
17.23	-10.58	-0.674
17.24	-10.65	-0.674
17.25	-10.72	-0.674
17.26	-10.78	-0.674
17.26	-10.85	-0.674
17.27	-10.92	-0.675
17.28	-10.98	-0.675
17.28	-11.05	-0.675
17.29	-11.12	-0.675
17.29	-11.18	-0.675
17.30	-11.25	-0.676
17.31	-11.32	-0.676
17.32	-11.38	-0.676
17.32	-11.45	-0.676
17.33	-11.52	-0.676
17.33	-11.58	-0.676
17.34	-11.65	-0.676
17.35	-11.72	-0.676
17.36	-11.78	-0.676
17.36	-11.85	-0.676
17.37	-11.92	-0.677
17.38	-11.98	-0.677
17.38	-12.05	-0.677
17.39	-12.12	-0.677
17.39	-12.18	-0.677
17.40	-12.25	-0.677
17.41	-12.32	-0.677
17.42	-12.38	-0.677
17.42	-12.45	-0.678
17.43	-12.52	-0.678
17.43	-12.58	-0.678
17.44	-12.65	-0.678
17.45	-12.72	-0.678
17.46	-12.78	-0.678
17.46	-12.85	-0.679
17.47	-12.92	-0.679
17.48	-12.98	-0.679
17.48	-13.05	-0.679
17.49	-13.12	-0.679
17.49	-13.18	-0.679
17.50	-13.25	-0.680
17.51	-13.32	-0.680
17.52	-13.38	-0.680
17.52	-13.45	-0.680
17.53	-13.52	-0.680
17.53	-13.58	-0.681
17.54	-13.65	-0.681
17.55	-13.72	-0.681
17.56	-13.78	-0.681
17.56	-13.85	-0.681
17.57	-13.92	-0.682
17.58	-13.98	-0.682
17.58	-14.05	-0.682
17.59	-14.12	-0.682
17.59	-14.18	-0.682
17.60	-14.25	-0.683
17.61	-14.32	-0.683
17.62	-14.38	-0.683
17.62	-14.45	-0.683
17.63	-14.52	-0.683
17.63	-14.58	-0.683
17.64	-14.65	-0.684
17.65	-14.72	-0.684
17.66	-14.78	-0.684
17.66	-14.85	-0.684
17.67	-14.92	-0.684
17.68	-14.98	-0.684
17.68	-15.05	-0.685
17.69	-15.12	-0.685
17.69	-15.18	-0.685
17.70	-15.25	-0.685
17.71	-15.32	-0.685
17.72	-15.38	-0.686
17.72	-15.45	-0.686
17.73	-15.51	-0.686
17.73	-15.58	-0.686
17.74	-15.65	-0.686
17.75	-15.71	-0.686
17.76	-15.78	-0.687
17.76	-15.85	-0.687
17.77	-15.92	-0.687
17.78	-15.98	-0.687
17.78	-16.05	-0.688
17.79	-16.11	-0.688
17.79	-16.18	-0.688
17.80	-16.25	-0.688
17.81	-16.31	-0.688
17.82	-16.38	-0.688
17.82	-16.45	-0.689
17.83	-16.52	-0.689
17.83	-16.58	-0.689
17.84	-16.65	-0.689
17.85	-16.71	-0.689
17.86	-16.78	-0.690
17.86	-16.85	-0.690
17.87	-16.91	-0.690
17.88	-16.98	-0.690
17.88	-17.05	-0.690
17.89	-17.11	-0.691
17.89	-17.18	-0.691
17.90	-17.25	-0.691
17.91	-17.31	-0.691
17.92	-17.38	-0.691
17.92	-17.45	-0.692
17.93	-17.51	-0.692
17.93	-17.58	-0.692
17.94	-17.65	-0.692
17.95	-17.71	-0.693
17.96	-17.78	-0.693
17.96	-17.85	-0.694
17.97	-17.91	-0.694
17.98	-17.98	-0.694
17.98	-18.05	-0.695
17.99	-18.11	-0.698
17.99	-18.18	-1.141
18.00	-18.21	-3.539
18.01	-18.11	-6.463
18.02	-18.02	-5.987
18.02	-18.02	-4.136
18.03	-18.06	-3.023
18.03	-18.13	-2.321
18.04	-18.20	-1.884
18.05	-18.28	-1.627
18.06	-18.37	-1.464
18.06	-18.45	-1.357
18.07	-18.54	-1.287
18.08	-18.62	-1.241
18.08	-18.71	-1.210
18.09	-18.79	-1.187
18.09	-18.87	-1.168
18.10	-18.95	-1.153
18.11	-19.03	-1.134
18.12	-19.11	-1.117
18.12	-19.19	-1.102
18.13	-19.27	-1.088
18.13	-19.35	-1.073
18.14	-19.43	-1.057
18.15	-19.50	-1.043
18.16	-19.58	-1.029
18.16	-19.65	-1.017
18.17	-19.73	-1.004
18.18	-19.80	-0.990
18.18	-19.88	-0.978
18.19	-19.95	-0.966
18.19	-20.03	-0.956
18.20	-20.10	-0.944
18.21	-20.17	-0.931
18.22	-20.24	-0.921
18.22	-20.32	-0.913
18.23	-20.39	-0.905
18.23	-20.46	-0.895
18.24	-20.53	-0.886
18.25	-20.60	-0.881
18.26	-20.68	-0.874
18.26	-20.75	-0.865
18.27	-20.82	-0.859
18.28	-20.89	-0.853
18.28	-20.96	-0.849
18.29	-21.03	-0.843
18.29	-21.10	-1.292
18.30	-21.14	-8.059
18.31	-20.65	-37.695
18.32	-18.77	-63.624
18.32	-17.34	-57.290
18.33	-16.48	-46.906
18.33	-15.92	-39.630
18.34	-15.60	-33.645
18.35	-15.44	-28.617
18.36	-15.42	-24.304
18.36	-15.51	-20.536
18.37	-15.68	-17.078
18.38	-15.93	-13.999
18.38	-16.23	-11.541
18.39	-16.55	-9.768
18.39	-16.89	-8.589
18.40	-17.22	-7.750
18.41	-17.55	-7.113
18.42	-17.87	-6.613
18.42	-18.17	-6.202
18.43	-18.47	-5.851
18.43	-18.75	-5.539
18.44	-19.02	-5.263
18.45	-19.28	-5.012
18.46	-19.53	-4.768
18.46	-19.78	-4.538
18.47	-20.01	-4.334
18.48	-20.23	-4.181
18.48	-20.44	-4.060
18.49	-20.64	-3.866
18.49	-20.85	-3.634
18.50	-21.04	-3.451
18.51	-21.22	-3.281
18.52	-21.41	-3.118
18.52	-21.58	-2.970
18.53	-21.75	-2.832
18.53	-21.91	-2.709
18.54	-22.07	-2.603
18.55	-22.22	-2.512
18.56	-22.37	-2.401
18.56	-22.52	-2.274
18.57	-22.66	-2.171
18.58	-22.80	-2.083
18.58	-22.93	-1.999
18.59	-23.06	-1.914
18.59	-23.19	-1.860
18.60	-23.31	-1.927
18.61	-23.42	-1.952
18.62	-23.53	-1.784
18.62	-23.65	-1.638
18.63	-23.76	-1.545
18.63	-23.87	-1.478
18.64	-23.98	-1.427
18.65	-24.08	-1.377
18.66	-24.19	-1.317
18.66	-24.29	-1.258
18.67	-24.39	-1.208
18.68	-24.49	-1.161
18.68	-24.59	-1.114
18.69	-24.68	-1.073
18.69	-24.78	-1.038
18.70	-24.87	-1.004
18.71	-24.96	-0.978
18.72	-25.05	-0.982
18.72	-25.14	-1.039
18.73	-25.22	-1.031
18.73	-25.31	-0.955
18.74	-25.39	-0.936
18.75	-25.47	-0.913
18.76	-25.55	-0.900
18.76	-25.63	-1.052
18.77	-25.70	-1.172
18.78	-25.78	-1.014
18.78	-25.86	-0.912
18.79	-25.93	-0.895
18.79	-26.01	-0.833
18.80	-26.09	-0.784
18.81	-26.17	-0.764
18.82	-26.25	-0.748
18.82	-26.32	-0.729
18.83	-26.40	-0.698
18.83	-26.48	-0.683
18.84	-26.55	-0.681
18.85	-26.63	-0.664
18.86	-26.70	-0.689
18.86	-26.77	-0.811
18.87	-26.84	-0.955
18.88	-26.90	-0.918
18.88	-26.97	-0.787
18.89	-27.05	-0.773
18.89	-27.12	-0.770
18.90	-27.19	-0.856
18.91	-27.25	-0.996
18.92	-27.31	-0.873
18.92	-27.39	-0.711
18.93	-27.46	-0.657
18.93	-27.53	-0.625
18.94	-27.60	-0.601
18.95	-27.68	-0.574
18.96	-27.75	-0.558
18.96	-27.83	-0.545
18.97	-27.90	-0.544
18.98	-27.97	-0.555
18.98	-28.04	-0.619
18.99	-28.11	-0.699
18.99	-28.17	-0.671
19.00	-28.24	-0.604
19.01	-28.31	-0.565
19.02	-28.38	-0.532
19.02	-28.45	-0.531
19.03	-28.52	-0.624
19.03	-28.59	-0.667
19.04	-28.66	-0.606
19.05	-28.73	-0.556
19.06	-28.79	-0.552
19.06	-28.87	-0.565
19.07	-28.93	-0.549
19.08	-29.00	-0.516
19.08	-29.07	-0.509
19.09	-29.14	-0.506
19.09	-29.21	-0.495
19.10	-29.28	-0.494
19.11	-29.35	-0.483
19.12	-29.42	-0.467
19.12	-29.49	-0.463
19.13	-29.56	-0.479
19.13	-29.63	-0.519
19.14	-29.69	-0.519
19.15	-29.76	-0.476
19.16	-29.83	-0.455
19.16	-29.90	-0.443
19.17	-29.97	-0.442
19.18	-30.03	-0.442
19.18	-30.10	-0.443
19.19	-30.17	-0.448
19.19	-30.24	-0.443
19.20	-30.31	-0.434
19.21	-30.38	-0.436
19.22	-30.44	-0.437
19.22	-30.51	-0.444
19.23	-30.58	-0.444
19.23	-30.65	-0.415
19.24	-30.72	-0.413
19.25	-30.78	-0.415
19.26	-30.85	-0.423
19.26	-30.92	-0.427
19.27	-30.99	-0.423
19.28	-31.05	-0.415
19.28	-31.12	-0.410
19.29	-31.19	-0.403
19.29	-31.26	-0.394
19.30	-31.33	-0.390
19.31	-31.39	-0.384
19.32	-31.46	-0.377
19.32	-31.53	-0.373
19.33	-31.60	-0.373
19.33	-31.67	-0.374
19.34	-31.73	-0.383
19.35	-31.80	-0.395
19.36	-31.87	-0.396
19.36	-31.93	-0.395
19.37	-32.00	-0.380
19.38	-32.07	-0.372
19.38	-32.14	-0.371
19.39	-32.20	-0.372
19.39	-32.27	-0.370
19.40	-32.34	-0.370
19.41	-32.41	-0.373
19.42	-32.47	-0.374
19.42	-32.54	-0.374
19.43	-32.61	-0.382
19.43	-32.67	-0.392
19.44	-32.74	-0.407
19.45	-32.80	-0.432
19.46	-32.87	-0.438
19.46	-32.94	-0.422
19.47	-33.00	-0.415
19.48	-33.07	-0.420
19.48	-33.14	-0.420
19.49	-33.20	-0.418
19.49	-33.27	-0.410
19.50	-33.33	-0.416
19.51	-33.40	-0.443
19.52	-33.47	-0.439
19.52	-33.53	-0.436
19.53	-33.60	-0.434
19.53	-33.66	-0.439
19.54	-33.73	-0.449
19.55	-33.79	-0.450
19.56	-33.86	-0.446
19.56	-33.93	-0.443
19.57	-33.99	-0.439
19.58	-34.06	-0.438
19.58	-34.13	-0.438
19.59	-34.19	-0.438
19.59	-34.26	-0.468
19.60	-34.32	-0.477
19.61	-34.39	-0.466
19.62	-34.46	-0.459
19.62	-34.52	-0.457
19.63	-34.59	-0.455
19.63	-34.65	-0.453
19.64	-34.72	-0.450
19.65	-34.79	-0.444
19.66	-34.86	-0.430
19.66	-34.92	-0.417
19.67	-34.99	-0.408
19.68	-35.06	-0.398
19.68	-35.13	-0.393
19.69	-35.19	-0.383
19.69	-35.26	-0.373
19.70	-35.33	-0.368
19.71	-35.40	-0.361
19.72	-35.47	-0.354
19.72	-35.53	-0.349
19.73	-35.60	-0.346
19.73	-35.67	-0.342
19.74	-35.74	-0.336
19.75	-35.81	-0.335
19.76	-35.88	-0.332
19.76	-35.94	-0.328
19.77	-36.01	-0.326
19.78	-36.08	-0.323
19.78	-36.15	-0.320
19.79	-36.21	-0.318
19.79	-36.28	-0.318
19.80	-36.35	-0.315
19.81	-36.42	-0.314
19.82	-36.49	-0.313
19.82	-36.55	-0.312
19.83	-36.62	-0.310
19.83	-36.69	-0.309
19.84	-36.76	-0.307
19.85	-36.82	-0.307
19.86	-36.89	-0.306
19.86	-36.96	-0.304
19.87	-37.03	-0.303
19.88	-37.09	-0.303
19.88	-37.16	-0.302
19.89	-37.23	-0.302
19.89	-37.29	-0.302
19.90	-37.36	-0.301
19.91	-37.43	-0.301
19.92	-37.50	-0.300
19.92	-37.56	-0.300
19.93	-37.63	-0.300
19.93	-37.70	-0.299
19.94	-37.77	-0.299
19.95	-37.83	-0.299
19.96	-37.90	-0.298
19.96	-37.96	-0.297
19.97	-38.03	-0.296
19.98	-38.10	-0.296
19.98	-38.17	-0.296
19.99	-38.23	-0.296
19.99	-38.30	-0.295
20.00	-38.37	-0.295
20.01	-38.43	-0.295
20.02	-38.50	-0.294
20.02	-38.57	-0.294
20.03	-38.63	-0.294
20.03	-38.70	-0.294
20.04	-38.77	-0.293
20.05	-38.84	-0.293
20.06	-38.90	-0.293
20.06	-38.97	-0.293
20.07	-39.03	-0.293
20.08	-39.10	-0.292
20.08	-39.17	-0.292
20.09	-39.24	-0.292
20.09	-39.30	-0.292
20.10	-39.37	-0.292
20.11	-39.44	-0.291
20.12	-39.50	-0.291
20.12	-39.57	-0.291
20.13	-39.64	-0.291
20.13	-39.70	-0.291
20.14	-39.77	-0.291
20.15	-39.84	-0.290
20.16	-39.90	-0.290
20.16	-39.97	-0.290
20.17	-40.04	-0.290
20.18	-40.10	-0.290
20.18	-40.17	-0.289
20.19	-40.24	-0.289
20.19	-40.30	-0.289
20.20	-40.37	-0.289
20.21	-40.44	-0.289
20.22	-40.50	-0.289
20.22	-40.57	-0.288
20.23	-40.64	-0.288
20.23	-40.70	-0.288
20.24	-40.77	-0.288
20.25	-40.84	-0.288
20.26	-40.90	-0.288
20.26	-40.97	-0.287
20.27	-41.04	-0.287
20.28	-41.10	-0.287
20.28	-41.17	-0.287
20.29	-41.24	-0.287
20.29	-41.30	-0.287
20.30	-41.37	-0.286
20.31	-41.44	-0.286
20.32	-41.50	-0.286
20.32	-41.57	-0.286
20.33	-41.64	-0.286
20.33	-41.70	-0.286
20.34	-41.77	-0.286
20.35	-41.84	-0.285
20.36	-41.91	-0.285
20.36	-41.97	-0.285
20.37	-42.04	-0.285
20.38	-42.11	-0.285
20.38	-42.17	-0.285
20.39	-42.24	-0.285
20.39	-42.30	-0.284
20.40	-42.37	-0.284
20.41	-42.44	-0.284
20.42	-42.51	-0.284
20.42	-42.57	-0.283
20.43	-42.64	-0.283
20.43	-42.71	-0.283
20.44	-42.77	-0.283
20.45	-42.84	-0.283
20.46	-42.91	-0.283
20.46	-42.97	-0.283
20.47	-43.04	-0.283
20.48	-43.11	-0.283
20.48	-43.17	-0.282
20.49	-43.24	-0.282
20.49	-43.31	-0.282
20.50	-43.37	-0.282
20.51	-43.44	-0.282
20.52	-43.50	-0.282
20.52	-43.57	-0.282
20.53	-43.64	-0.281
20.53	-43.70	-0.281
20.54	-43.77	-0.281
20.55	-43.84	-0.281
20.56	-43.91	-0.281
20.56	-43.97	-0.281
20.57	-44.04	-0.281
20.58	-44.10	-0.281
20.58	-44.17	-0.280
20.59	-44.24	-0.280
20.59	-44.31	-0.280
20.60	-44.37	-0.280
20.61	-44.44	-0.280
20.62	-44.51	-0.280
20.62	-44.57	-0.280
20.63	-44.64	-0.280
20.63	-44.71	-0.280
20.64	-44.77	-0.279
20.65	-44.84	-0.279
20.66	-44.91	-0.279
20.66	-44.97	-0.279
20.67	-45.04	-0.279
20.68	-45.11	-0.279
20.68	-45.17	-0.279
20.69	-45.24	-0.279
20.69	-45.31	-0.279
20.70	-45.37	-0.278
20.71	-45.44	-0.278
20.72	-45.51	-0.278
20.72	-45.57	-0.278
20.73	-45.64	-0.278
20.73	-45.71	-0.278
20.74	-45.77	-0.278
20.75	-45.84	-0.278
20.76	-45.91	-0.278
20.76	-45.97	-0.277
20.77	-46.04	-0.277
20.78	-46.11	-0.277
20.78	-46.17	-0.277
20.79	-46.24	-0.277
20.79	-46.31	-0.277
20.80	-46.37	-0.277
20.81	-46.44	-0.276
20.82	-46.51	-0.276
20.82	-46.57	-0.276
20.83	-46.64	-0.276
20.83	-46.71	-0.276
20.84	-46.77	-0.276
20.85	-46.84	-0.275
20.86	-46.91	-0.275
20.86	-46.97	-0.275
20.87	-47.04	-0.275
20.88	-47.11	-0.275
20.88	-47.17	-0.275
20.89	-47.24	-0.275
20.89	-47.31	-0.275
20.90	-47.37	-0.275
20.91	-47.44	-0.275
20.92	-47.51	-0.275
20.92	-47.57	-0.274
20.93	-47.64	-0.274
20.93	-47.71	-0.274
20.94	-47.77
20.95	-47.84
20.96	-47.91
20.96	-47.97
20.97	-48.04
20.98	-48.11
20.98	-48.17
20.99
20.99