File: Data/2024_09_17_Empty_DSC.txt
Filename	2024_09_17_Empty_DSC
Instrument name	DSC2A-00468 (192.168.1.100)
Operator	CHM343
rundate	9/18/2024
Sample name	2024_09_17_Empty_DSC
proceduresegments	Equilibrate 30.00 °C; Ramp 10.00 °C/min to 210.00 °C; Isothermal 1.0 min; Ramp 10.00 °C/min to 30.00 °C; Isothermal 1.0 min; Ramp 10.00 °C/min to 210.00 °C
[File Parameters]
Run date	9/18/2024 1:46:12 AM
Trios version	5.1.1.46572
Original File Name
Current File Name	C:\ProgramData\TA Instruments\TRIOS\Data\2024_09_17_Empty_DSC.tri
[Procedure]
Procedure Name	CHM343_Fall2024_Indium
Sample Name	2024_09_17_Empty_DSC
Sample Mass	0 mg
Reference Sample Mass	0 mg
Pan Mass	54.56 mg
Pan Number	24
Reference Pan Mass	54 mg
Reference Pan Number	19
Pan Type	Aluminum
Comments	Empty Pans - Al Hermetic Sealed Pan, with ref Al pan.  ASU Online CHM343, Remote DSC experimental lab. Fall 2024.  Group Zoom Data Collection, Sept 17, 2024 from 9-11 pm.  TA Instruments DSC2500.
Project Name	Lab 4 - Fall 2024
Operator	CHM343
Test	Custom
Unload Max Temperature	30
Unload Min Temperature	30
Load Max Temperature	30
Load Min Temperature	30
Stop on Gas Flow Error	Yes
[Signal List]
Signal #1	Time (min)
Signal #2	Temperature (°C)
Signal #3	Heat Flow (mW)
Signal #4	Delta T (µV)
Signal #5	Delta Tzero (µV)
Signal #6	Tzero Temperature (°C)
Signal #7	Cell Purge (mL/min)
Signal #8	Heater Temp (°C)
Signal #9	Power Delivered (W)
Signal #10	Reference Junction Temperature (°C)
Signal #11	Flange Temperature (°C)
Signal #12	Heat Flow Phase (rad)
Signal #13	Total Heat Capacity (J/°C)
Signal #14	Heat Capacity (J/°C)
[Configuration]
Company Name	ASU
Instrument Name	DSC2A-00468
Instrument Type	DSC2500
Serial Number	DSC2A-00468
IP	192.168.1.100
Location of Instrument	MRRC
DisplayType	Unknown
Sample Interval 	0.1 s/pt
Selected Heat Flow	T4P
Exotherm Direction	Down
Cell Serial	DRC2-00792
Lid Type	Standard
Cooler	RCS 90
Leave Cooler on at End of Sequence	On
Gas 2	Nitrogen
Gas Selected	Channel 1
Flow Rate	50 mL/min
Secondary Purge	On
Licensed Heat Flow	Heat Flow T4P
Modulation Licensed	Yes
[Versions]
Common IDD Version	1
Cortex Version	VER 2.10.2.31
Driver	5.0.0.6
GDM Version	1.0.3.3
TouchscreenVersion	1.0.0.16145
FEP Version	1.2.1.21
FEP Bootloader	2.0.0.5
AutoSampler Version	2.1.1.26
Auto Sampler Bootloader	2.0.0.5
FCM Version	1.1.0.3
FCM Bootloader	2.0.0.5
[Experiment Logs]
Experiment Log Entry # 1	Equilibrate Segment 30 (C) Started
Experiment Log Entry # 3	Air Cool is off.
Experiment Log Entry # 5	Ramp Segment 10 C/min to 210 Started
Experiment Log Entry # 7	Isothermal Segment 1 min started
Experiment Log Entry # 9	Ramp Segment 10 C/min to 30 Started
Experiment Log Entry # 11	Isothermal Segment 1 min started
Experiment Log Entry # 13	Ramp Segment 10 C/min to 210 Started
[Method Log]
Method Log Entry # 1	Equilibrate 30 °C
Method Log Entry # 2	(Ramp 108282) Ramp 10 °C/minute to 210 °C
Method Log Entry # 3	Isothermal 1 minutes
Method Log Entry # 4	(Ramp 108284) Ramp 10 °C/minute to 30 °C
Method Log Entry # 5	Isothermal 1 minutes
Method Log Entry # 6	(Ramp 108286) Ramp 10 °C/minute to 210 °C
Cell Serial	DRC2-00792
[T1 Calibration]
Slope	-0.008529666
Offset	9.636258
Initial Temperature	98.23
GUID	f8bfdadc-4977-4fdf-ba6d-0ba9134940c3
[TZero Calibration]
Date Applied	11/29/2022 4:06:13 PM
Description	From -89.059 °C to 396.009 °C at 20.000°C/min
Gas Type	Nitrogen
Pan Type	None
Source Files 1	C:\Users\yargerlab\Desktop\DSC Data\General\TZero_calibration_11_29_22_2nd(2).tri
Source Files 2	C:\Users\yargerlab\Desktop\DSC Data\General\TZero_calibration_11_29_22_2nd(3).tri
Delta T Offset	13.05235
Delta T Slope	-0.007271007
Delta T0 Offset	-13.69128
Delta T0 Slope	0.06063341
[Temperature Calibration]
Date Applied	11/29/2022 7:12:28 PM
Description	From 106.590 °C to 186.590 °C at 10.000°C/min
Gas Type	Nitrogen
Pan Type	Tzero Aluminum Hermetic
Source Files 1	C:\Users\yargerlab\Desktop\DSC Data\General\Indium(6).tri
Measured 1	157.391
Known 1	156.598
[Cell Constant Calibration]
Date Applied	11/29/2022 7:12:29 PM
Description	From 106.590 °C to 186.590 °C at 10.000°C/min
Gas Type	Nitrogen
Pan Type	Tzero Aluminum Hermetic
Source Files 1	C:\Users\yargerlab\Desktop\DSC Data\General\Indium(6).tri
T4P KCell	1.006051
Onset Slope	63.26126 mW/°C
[Direct Cp Calibration]
Date Applied	11/30/2022 11:04:51 AM
Description	From -79.983 °C to 298.409 °C at 10.000°C/min
Gas Type	Nitrogen
Pan Type	Tzero Aluminum Hermetic
Source Files 1	C:\Users\yargerlab\Desktop\DSC Data\General\Sapphire_Heat_Capacity_11_30_22.tri
[Rev Cp Calibration]
Date Applied	11/30/2022 1:58:51 PM
Description	From -79.996 °C to 292.812 °C at 3.000°C/min
Gas Type	Nitrogen
Pan Type	Tzero Aluminum Hermetic
Source Files 1	C:\Users\yargerlab\Desktop\DSC Data\General\Sapphire_MDSC_Calibration_11_30_22.tri
[step]
Ramp 10.00 °C/min to 210.00 °C
Time	Temperature	Heat Flow (Normalized)
min	°C	W/g
0.00	30.07
0.01	30.07
0.03	30.08
0.04	30.08
0.05	30.09
0.07	30.11
0.08	30.14
0.09	30.18
0.11	30.24
0.12	30.31
0.13	30.39
0.15	30.47
0.16	30.57
0.17	30.67
0.19	30.77
0.20	30.88
0.21	30.98
0.23	31.10
0.24	31.21
0.25	31.33
0.27	31.44
0.28	31.56
0.29	31.68
0.31	31.81
0.32	31.93
0.33	32.06
0.35	32.18
0.36	32.31
0.37	32.43
0.39	32.56
0.40	32.69
0.41	32.82
0.43	32.95
0.44	33.08
0.45	33.21
0.47	33.34
0.48	33.47
0.49	33.60
0.51	33.73
0.52	33.86
0.53	33.99
0.55	34.12
0.56	34.25
0.57	34.38
0.59	34.52
0.60	34.65
0.61	34.78
0.63	34.91
0.64	35.04
0.65	35.17
0.67	35.31
0.68	35.44
0.69	35.57
0.71	35.70
0.72	35.83
0.73	35.97
0.75	36.10
0.76	36.23
0.77	36.36
0.79	36.49
0.80	36.63
0.81	36.76
0.83	36.89
0.84	37.02
0.85	37.16
0.87	37.29
0.88	37.42
0.89	37.55
0.91	37.69
0.92	37.82
0.93	37.95
0.95	38.08
0.96	38.22
0.97	38.35
0.99	38.48
1.00	38.62
1.01	38.75
1.03	38.88
1.04	39.01
1.05	39.15
1.07	39.28
1.08	39.41
1.09	39.54
1.11	39.68
1.12	39.81
1.13	39.94
1.15	40.08
1.16	40.21
1.17	40.34
1.19	40.48
1.20	40.61
1.21	40.74
1.23	40.87
1.24	41.01
1.25	41.14
1.27	41.27
1.28	41.41
1.29	41.54
1.31	41.67
1.32	41.81
1.33	41.94
1.35	42.07
1.36	42.21
1.37	42.34
1.39	42.47
1.40	42.61
1.41	42.74
1.43	42.87
1.44	43.01
1.45	43.14
1.47	43.27
1.48	43.40
1.49	43.54
1.51	43.67
1.52	43.80
1.53	43.94
1.55	44.07
1.56	44.20
1.57	44.34
1.59	44.47
1.60	44.60
1.61	44.74
1.63	44.87
1.64	45.00
1.65	45.14
1.67	45.27
1.68	45.40
1.69	45.54
1.71	45.67
1.72	45.80
1.73	45.94
1.75	46.07
1.76	46.20
1.77	46.34
1.79	46.47
1.80	46.60
1.81	46.74
1.83	46.87
1.84	47.00
1.85	47.14
1.87	47.27
1.88	47.40
1.89	47.54
1.91	47.67
1.92	47.80
1.93	47.94
1.95	48.07
1.96	48.20
1.97	48.34
1.99	48.47
2.00	48.60
2.01	48.74
2.03	48.87
2.04	49.00
2.05	49.14
2.07	49.27
2.08	49.40
2.09	49.54
2.11	49.67
2.12	49.81
2.13	49.94
2.15	50.07
2.16	50.21
2.17	50.34
2.19	50.47
2.20	50.61
2.21	50.74
2.23	50.87
2.24	51.01
2.25	51.14
2.27	51.27
2.28	51.41
2.29	51.54
2.31	51.67
2.32	51.80
2.33	51.94
2.35	52.07
2.36	52.21
2.37	52.34
2.39	52.47
2.40	52.61
2.41	52.74
2.43	52.87
2.44	53.01
2.45	53.14
2.47	53.27
2.48	53.41
2.49	53.54
2.51	53.67
2.52	53.81
2.53	53.94
2.55	54.07
2.56	54.21
2.57	54.34
2.59	54.47
2.60	54.61
2.61	54.74
2.63	54.87
2.64	55.01
2.65	55.14
2.67	55.28
2.68	55.41
2.69	55.54
2.71	55.68
2.72	55.81
2.73	55.94
2.75	56.08
2.76	56.21
2.77	56.34
2.79	56.48
2.80	56.61
2.81	56.74
2.83	56.88
2.84	57.01
2.85	57.14
2.87	57.28
2.88	57.41
2.89	57.54
2.91	57.68
2.92	57.81
2.93	57.94
2.95	58.08
2.96	58.21
2.97	58.34
2.99	58.48
3.00	58.61
3.01	58.74
3.03	58.88
3.04	59.01
3.05	59.14
3.07	59.28
3.08	59.41
3.09	59.55
3.11	59.68
3.12	59.81
3.13	59.95
3.15	60.08
3.16	60.21
3.17	60.35
3.19	60.48
3.20	60.61
3.21	60.75
3.23	60.88
3.24	61.01
3.25	61.15
3.27	61.28
3.28	61.41
3.29	61.55
3.31	61.68
3.32	61.81
3.33	61.95
3.35	62.08
3.36	62.21
3.37	62.35
3.39	62.48
3.40	62.61
3.41	62.75
3.43	62.88
3.44	63.01
3.45	63.15
3.47	63.28
3.48	63.41
3.49	63.55
3.51	63.68
3.52	63.82
3.53	63.95
3.55	64.08
3.56	64.22
3.57	64.35
3.59	64.48
3.60	64.62
3.61	64.75
3.63	64.88
3.64	65.02
3.65	65.15
3.67	65.28
3.68	65.42
3.69	65.55
3.71	65.68
3.72	65.82
3.73	65.95
3.75	66.08
3.76	66.22
3.77	66.35
3.79	66.48
3.80	66.62
3.81	66.75
3.83	66.88
3.84	67.02
3.85	67.15
3.87	67.28
3.88	67.42
3.89	67.55
3.91	67.69
3.92	67.82
3.93	67.95
3.95	68.09
3.96	68.22
3.97	68.35
3.99	68.49
4.00	68.62
4.01	68.75
4.03	68.89
4.04	69.02
4.05	69.15
4.07	69.29
4.08	69.42
4.09	69.55
4.11	69.69
4.12	69.82
4.13	69.95
4.15	70.09
4.16	70.22
4.17	70.35
4.19	70.49
4.20	70.62
4.21	70.75
4.23	70.89
4.24	71.02
4.25	71.16
4.27	71.29
4.28	71.42
4.29	71.55
4.31	71.69
4.32	71.82
4.33	71.96
4.35	72.09
4.36	72.22
4.37	72.36
4.39	72.49
4.40	72.62
4.41	72.76
4.43	72.89
4.44	73.02
4.45	73.16
4.47	73.29
4.48	73.42
4.49	73.56
4.51	73.69
4.52	73.82
4.53	73.96
4.55	74.09
4.56	74.22
4.57	74.36
4.59	74.49
4.60	74.62
4.61	74.76
4.63	74.89
4.64	75.02
4.65	75.16
4.67	75.29
4.68	75.43
4.69	75.56
4.71	75.69
4.72	75.83
4.73	75.96
4.75	76.09
4.76	76.23
4.77	76.36
4.79	76.49
4.80	76.63
4.81	76.76
4.83	76.89
4.84	77.03
4.85	77.16
4.87	77.29
4.88	77.43
4.89	77.56
4.91	77.69
4.92	77.83
4.93	77.96
4.95	78.09
4.96	78.23
4.97	78.36
4.99	78.49
5.00	78.63
5.01	78.76
5.03	78.90
5.04	79.03
5.05	79.16
5.07	79.30
5.08	79.43
5.09	79.56
5.11	79.70
5.12	79.83
5.13	79.96
5.15	80.10
5.16	80.23
5.17	80.36
5.19	80.50
5.20	80.63
5.21	80.76
5.23	80.90
5.24	81.03
5.25	81.16
5.27	81.30
5.28	81.43
5.29	81.56
5.31	81.70
5.32	81.83
5.33	81.96
5.35	82.10
5.36	82.23
5.37	82.36
5.39	82.50
5.40	82.63
5.41	82.76
5.43	82.90
5.44	83.03
5.45	83.17
5.47	83.30
5.48	83.43
5.49	83.57
5.51	83.70
5.52	83.83
5.53	83.97
5.55	84.10
5.56	84.23
5.57	84.37
5.59	84.50
5.60	84.63
5.61	84.77
5.63	84.90
5.64	85.03
5.65	85.17
5.67	85.30
5.68	85.43
5.69	85.57
5.71	85.70
5.72	85.83
5.73	85.97
5.75	86.10
5.76	86.23
5.77	86.37
5.79	86.50
5.80	86.63
5.81	86.77
5.83	86.90
5.84	87.03
5.85	87.17
5.87	87.30
5.88	87.43
5.89	87.57
5.91	87.70
5.92	87.84
5.93	87.97
5.95	88.10
5.96	88.24
5.97	88.37
5.99	88.50
6.00	88.63
6.01	88.77
6.03	88.90
6.04	89.04
6.05	89.17
6.07	89.30
6.08	89.44
6.09	89.57
6.11	89.70
6.12	89.84
6.13	89.97
6.15	90.10
6.16	90.24
6.17	90.37
6.19	90.50
6.20	90.64
6.21	90.77
6.23	90.90
6.24	91.04
6.25	91.17
6.27	91.30
6.28	91.44
6.29	91.57
6.31	91.70
6.32	91.84
6.33	91.97
6.35	92.10
6.36	92.24
6.37	92.37
6.39	92.50
6.40	92.64
6.41	92.77
6.43	92.90
6.44	93.04
6.45	93.17
6.47	93.30
6.48	93.44
6.49	93.57
6.51	93.71
6.52	93.84
6.53	93.97
6.55	94.11
6.56	94.24
6.57	94.37
6.59	94.51
6.60	94.64
6.61	94.77
6.63	94.91
6.64	95.04
6.65	95.17
6.67	95.31
6.68	95.44
6.69	95.57
6.71	95.71
6.72	95.84
6.73	95.97
6.75	96.11
6.76	96.24
6.77	96.37
6.79	96.51
6.80	96.64
6.81	96.78
6.83	96.91
6.84	97.04
6.85	97.17
6.87	97.31
6.88	97.44
6.89	97.58
6.91	97.71
6.92	97.84
6.93	97.98
6.95	98.11
6.96	98.24
6.97	98.38
6.99	98.51
7.00	98.64
7.01	98.78
7.03	98.91
7.04	99.04
7.05	99.18
7.07	99.31
7.08	99.44
7.09	99.58
7.11	99.71
7.12	99.84
7.13	99.98
7.15	100.11
7.16	100.24
7.17	100.38
7.19	100.51
7.20	100.64
7.21	100.78
7.23	100.91
7.24	101.05
7.25	101.18
7.27	101.31
7.28	101.44
7.29	101.58
7.31	101.71
7.32	101.84
7.33	101.98
7.35	102.11
7.36	102.24
7.37	102.38
7.39	102.51
7.40	102.64
7.41	102.78
7.43	102.91
7.44	103.04
7.45	103.18
7.47	103.31
7.48	103.44
7.49	103.58
7.51	103.71
7.52	103.84
7.53	103.98
7.55	104.11
7.56	104.24
7.57	104.38
7.59	104.51
7.60	104.65
7.61	104.78
7.63	104.91
7.64	105.05
7.65	105.18
7.67	105.31
7.68	105.45
7.69	105.58
7.71	105.71
7.72	105.85
7.73	105.98
7.75	106.11
7.76	106.25
7.77	106.38
7.79	106.52
7.80	106.65
7.81	106.78
7.83	106.91
7.84	107.05
7.85	107.18
7.87	107.31
7.88	107.45
7.89	107.58
7.91	107.72
7.92	107.85
7.93	107.98
7.95	108.12
7.96	108.25
7.97	108.38
7.99	108.52
8.00	108.65
8.01	108.78
8.03	108.92
8.04	109.05
8.05	109.18
8.07	109.32
8.08	109.45
8.09	109.58
8.11	109.72
8.12	109.85
8.13	109.98
8.15	110.12
8.16	110.25
8.17	110.38
8.19	110.52
8.20	110.65
8.21	110.78
8.23	110.92
8.24	111.05
8.25	111.18
8.27	111.32
8.28	111.45
8.29	111.58
8.31	111.72
8.32	111.85
8.33	111.98
8.35	112.12
8.36	112.25
8.37	112.38
8.39	112.52
8.40	112.65
8.41	112.79
8.43	112.92
8.44	113.05
8.45	113.19
8.47	113.32
8.48	113.45
8.49	113.58
8.51	113.72
8.52	113.85
8.53	113.99
8.55	114.12
8.56	114.25
8.57	114.39
8.59	114.52
8.60	114.65
8.61	114.79
8.63	114.92
8.64	115.05
8.65	115.19
8.67	115.32
8.68	115.45
8.69	115.59
8.71	115.72
8.72	115.85
8.73	115.99
8.75	116.12
8.76	116.25
8.77	116.39
8.79	116.52
8.80	116.65
8.81	116.79
8.83	116.92
8.84	117.05
8.85	117.19
8.87	117.32
8.88	117.46
8.89	117.59
8.91	117.72
8.92	117.85
8.93	117.99
8.95	118.12
8.96	118.25
8.97	118.39
8.99	118.52
9.00	118.66
9.01	118.79
9.03	118.92
9.04	119.05
9.05	119.19
9.07	119.32
9.08	119.46
9.09	119.59
9.11	119.72
9.12	119.86
9.13	119.99
9.15	120.12
9.16	120.26
9.17	120.39
9.19	120.52
9.20	120.66
9.21	120.79
9.23	120.92
9.24	121.06
9.25	121.19
9.27	121.32
9.28	121.46
9.29	121.59
9.31	121.72
9.32	121.86
9.33	121.99
9.35	122.13
9.36	122.26
9.37	122.39
9.39	122.52
9.40	122.66
9.41	122.79
9.43	122.93
9.44	123.06
9.45	123.19
9.47	123.32
9.48	123.46
9.49	123.59
9.51	123.73
9.52	123.86
9.53	123.99
9.55	124.13
9.56	124.26
9.57	124.39
9.59	124.53
9.60	124.66
9.61	124.79
9.63	124.93
9.64	125.06
9.65	125.19
9.67	125.33
9.68	125.46
9.69	125.59
9.71	125.73
9.72	125.86
9.73	125.99
9.75	126.13
9.76	126.26
9.77	126.39
9.79	126.53
9.80	126.66
9.81	126.79
9.83	126.93
9.84	127.06
9.85	127.19
9.87	127.33
9.88	127.46
9.89	127.59
9.91	127.73
9.92	127.86
9.93	127.99
9.95	128.13
9.96	128.26
9.97	128.39
9.99	128.53
10.00	128.66
10.01	128.79
10.03	128.93
10.04	129.06
10.05	129.19
10.07	129.33
10.08	129.46
10.09	129.59
10.11	129.73
10.12	129.86
10.13	129.99
10.15	130.13
10.16	130.26
10.17	130.40
10.19	130.53
10.20	130.66
10.21	130.80
10.23	130.93
10.24	131.06
10.25	131.20
10.27	131.33
10.28	131.46
10.29	131.60
10.31	131.73
10.32	131.86
10.33	132.00
10.35	132.13
10.36	132.26
10.37	132.40
10.39	132.53
10.40	132.66
10.41	132.80
10.43	132.93
10.44	133.06
10.45	133.20
10.47	133.33
10.48	133.46
10.49	133.60
10.51	133.73
10.52	133.86
10.53	134.00
10.55	134.13
10.56	134.26
10.57	134.40
10.59	134.53
10.60	134.66
10.61	134.80
10.63	134.93
10.64	135.06
10.65	135.20
10.67	135.33
10.68	135.46
10.69	135.60
10.71	135.73
10.72	135.87
10.73	136.00
10.75	136.13
10.76	136.27
10.77	136.40
10.79	136.53
10.80	136.67
10.81	136.80
10.83	136.93
10.84	137.07
10.85	137.20
10.87	137.33
10.88	137.47
10.89	137.60
10.91	137.73
10.92	137.87
10.93	138.00
10.95	138.13
10.96	138.27
10.97	138.40
10.99	138.53
11.00	138.67
11.01	138.80
11.03	138.93
11.04	139.07
11.05	139.20
11.07	139.33
11.08	139.47
11.09	139.60
11.11	139.73
11.12	139.87
11.13	140.00
11.15	140.13
11.16	140.27
11.17	140.40
11.19	140.53
11.20	140.67
11.21	140.80
11.23	140.93
11.24	141.07
11.25	141.20
11.27	141.33
11.28	141.47
11.29	141.60
11.31	141.73
11.32	141.87
11.33	142.00
11.35	142.13
11.36	142.27
11.37	142.40
11.39	142.53
11.40	142.67
11.41	142.80
11.43	142.93
11.44	143.07
11.45	143.20
11.47	143.34
11.48	143.47
11.49	143.60
11.51	143.74
11.52	143.87
11.53	144.00
11.55	144.14
11.56	144.27
11.57	144.40
11.59	144.54
11.60	144.67
11.61	144.80
11.63	144.94
11.64	145.07
11.65	145.20
11.67	145.34
11.68	145.47
11.69	145.60
11.71	145.74
11.72	145.87
11.73	146.00
11.75	146.14
11.76	146.27
11.77	146.40
11.79	146.54
11.80	146.67
11.81	146.80
11.83	146.94
11.84	147.07
11.85	147.20
11.87	147.34
11.88	147.47
11.89	147.60
11.91	147.74
11.92	147.87
11.93	148.00
11.95	148.14
11.96	148.27
11.97	148.40
11.99	148.54
12.00	148.67
12.01	148.81
12.03	148.94
12.04	149.07
12.05	149.21
12.07	149.34
12.08	149.47
12.09	149.61
12.11	149.74
12.12	149.87
12.13	150.01
12.15	150.14
12.16	150.27
12.17	150.41
12.19	150.54
12.20	150.67
12.21	150.81
12.23	150.94
12.24	151.07
12.25	151.20
12.27	151.34
12.28	151.47
12.29	151.61
12.31	151.74
12.32	151.87
12.33	152.01
12.35	152.14
12.36	152.27
12.37	152.41
12.39	152.54
12.40	152.67
12.41	152.81
12.43	152.94
12.44	153.07
12.45	153.21
12.47	153.34
12.48	153.47
12.49	153.61
12.51	153.74
12.52	153.87
12.53	154.01
12.55	154.14
12.56	154.27
12.57	154.41
12.59	154.54
12.60	154.67
12.61	154.81
12.63	154.94
12.64	155.07
12.65	155.21
12.67	155.34
12.68	155.47
12.69	155.61
12.71	155.74
12.72	155.87
12.73	156.01
12.75	156.14
12.76	156.28
12.77	156.41
12.79	156.54
12.80	156.68
12.81	156.81
12.83	156.94
12.84	157.08
12.85	157.21
12.87	157.34
12.88	157.48
12.89	157.61
12.91	157.74
12.92	157.88
12.93	158.01
12.95	158.14
12.96	158.28
12.97	158.41
12.99	158.54
13.00	158.68
13.01	158.81
13.03	158.94
13.04	159.08
13.05	159.21
13.07	159.34
13.08	159.48
13.09	159.61
13.11	159.74
13.12	159.88
13.13	160.01
13.15	160.14
13.16	160.28
13.17	160.41
13.19	160.54
13.20	160.68
13.21	160.81
13.23	160.94
13.24	161.08
13.25	161.21
13.27	161.35
13.28	161.48
13.29	161.61
13.31	161.74
13.32	161.88
13.33	162.01
13.35	162.14
13.36	162.28
13.37	162.41
13.39	162.54
13.40	162.68
13.41	162.81
13.43	162.94
13.44	163.08
13.45	163.21
13.47	163.34
13.48	163.48
13.49	163.61
13.51	163.75
13.52	163.88
13.53	164.01
13.55	164.14
13.56	164.28
13.57	164.41
13.59	164.55
13.60	164.68
13.61	164.81
13.63	164.95
13.64	165.08
13.65	165.21
13.67	165.35
13.68	165.48
13.69	165.61
13.71	165.75
13.72	165.88
13.73	166.01
13.75	166.15
13.76	166.28
13.77	166.41
13.79	166.55
13.80	166.68
13.81	166.81
13.83	166.95
13.84	167.08
13.85	167.21
13.87	167.35
13.88	167.48
13.89	167.61
13.91	167.75
13.92	167.88
13.93	168.01
13.95	168.15
13.96	168.28
13.97	168.41
13.99	168.55
14.00	168.68
14.01	168.81
14.03	168.95
14.04	169.08
14.05	169.21
14.07	169.35
14.08	169.48
14.09	169.61
14.11	169.75
14.12	169.88
14.13	170.01
14.15	170.15
14.16	170.28
14.17	170.42
14.19	170.55
14.20	170.68
14.21	170.82
14.23	170.95
14.24	171.08
14.25	171.22
14.27	171.35
14.28	171.48
14.29	171.62
14.31	171.75
14.32	171.88
14.33	172.02
14.35	172.15
14.36	172.28
14.37	172.41
14.39	172.55
14.40	172.68
14.41	172.82
14.43	172.95
14.44	173.08
14.45	173.22
14.47	173.35
14.48	173.48
14.49	173.62
14.51	173.75
14.52	173.88
14.53	174.02
14.55	174.15
14.56	174.28
14.57	174.42
14.59	174.55
14.60	174.68
14.61	174.82
14.63	174.95
14.64	175.08
14.65	175.22
14.67	175.35
14.68	175.48
14.69	175.62
14.71	175.75
14.72	175.88
14.73	176.02
14.75	176.15
14.76	176.28
14.77	176.42
14.79	176.55
14.80	176.68
14.81	176.82
14.83	176.95
14.84	177.08
14.85	177.22
14.87	177.35
14.88	177.48
14.89	177.62
14.91	177.75
14.92	177.89
14.93	178.02
14.95	178.15
14.96	178.29
14.97	178.42
14.99	178.55
15.00	178.68
15.01	178.82
15.03	178.95
15.04	179.09
15.05	179.22
15.07	179.35
15.08	179.49
15.09	179.62
15.11	179.75
15.12	179.89
15.13	180.02
15.15	180.15
15.16	180.29
15.17	180.42
15.19	180.55
15.20	180.69
15.21	180.82
15.23	180.95
15.24	181.09
15.25	181.22
15.27	181.35
15.28	181.49
15.29	181.62
15.31	181.75
15.32	181.89
15.33	182.02
15.35	182.15
15.36	182.29
15.37	182.42
15.39	182.55
15.40	182.69
15.41	182.82
15.43	182.95
15.44	183.09
15.45	183.22
15.47	183.35
15.48	183.49
15.49	183.62
15.51	183.75
15.52	183.89
15.53	184.02
15.55	184.15
15.56	184.29
15.57	184.42
15.59	184.55
15.60	184.69
15.61	184.82
15.63	184.95
15.64	185.09
15.65	185.22
15.67	185.36
15.68	185.49
15.69	185.62
15.71	185.76
15.72	185.89
15.73	186.02
15.75	186.16
15.76	186.29
15.77	186.42
15.79	186.55
15.80	186.69
15.81	186.82
15.83	186.96
15.84	187.09
15.85	187.22
15.87	187.36
15.88	187.49
15.89	187.62
15.91	187.75
15.92	187.89
15.93	188.02
15.95	188.16
15.96	188.29
15.97	188.42
15.99	188.56
16.00	188.69
16.01	188.82
16.03	188.96
16.04	189.09
16.05	189.22
16.07	189.36
16.08	189.49
16.09	189.62
16.11	189.76
16.12	189.89
16.13	190.02
16.15	190.16
16.16	190.29
16.17	190.42
16.19	190.56
16.20	190.69
16.21	190.82
16.23	190.96
16.24	191.09
16.25	191.22
16.27	191.36
16.28	191.49
16.29	191.62
16.31	191.76
16.32	191.89
16.33	192.02
16.35	192.16
16.36	192.29
16.37	192.42
16.39	192.56
16.40	192.69
16.41	192.82
16.43	192.96
16.44	193.09
16.45	193.22
16.47	193.36
16.48	193.49
16.49	193.62
16.51	193.76
16.52	193.89
16.53	194.02
16.55	194.16
16.56	194.29
16.57	194.42
16.59	194.56
16.60	194.69
16.61	194.83
16.63	194.96
16.64	195.09
16.65	195.23
16.67	195.36
16.68	195.49
16.69	195.62
16.71	195.76
16.72	195.89
16.73	196.03
16.75	196.16
16.76	196.29
16.77	196.43
16.79	196.56
16.80	196.69
16.81	196.83
16.83	196.96
16.84	197.09
16.85	197.23
16.87	197.36
16.88	197.49
16.89	197.63
16.91	197.76
16.92	197.89
16.93	198.03
16.95	198.16
16.96	198.29
16.97	198.43
16.99	198.56
17.00	198.69
17.01	198.83
17.03	198.96
17.04	199.09
17.05	199.23
17.07	199.36
17.08	199.49
17.09	199.63
17.11	199.76
17.12	199.89
17.13	200.03
17.15	200.16
17.16	200.29
17.17	200.43
17.19	200.56
17.20	200.69
17.21	200.83
17.23	200.96
17.24	201.09
17.25	201.23
17.27	201.36
17.28	201.49
17.29	201.63
17.31	201.76
17.32	201.89
17.33	202.03
17.35	202.16
17.36	202.29
17.37	202.43
17.39	202.56
17.40	202.69
17.41	202.83
17.43	202.96
17.44	203.09
17.45	203.23
17.47	203.36
17.48	203.50
17.49	203.63
17.51	203.76
17.52	203.90
17.53	204.03
17.55	204.16
17.56	204.30
17.57	204.43
17.59	204.56
17.60	204.70
17.61	204.83
17.63	204.96
17.64	205.09
17.65	205.23
17.67	205.36
17.68	205.49
17.69	205.63
17.71	205.76
17.72	205.89
17.73	206.03
17.75	206.16
17.76	206.29
17.77	206.43
17.79	206.56
17.80	206.70
17.81	206.83
17.83	206.96
17.84	207.09
17.85	207.23
17.87	207.36
17.88	207.50
17.89	207.63
17.91	207.76
17.92	207.90
17.93	208.03
17.95	208.16
17.96	208.30
17.97	208.43
17.99	208.56
18.00	208.70
18.00	208.71

[step]
Ramp 10.00 °C/min to 30.00 °C
Time	Temperature	Heat Flow (Normalized)
min	°C	W/g
19.00	210.07
19.02	210.07
19.03	210.07
19.04	210.07
19.06	210.06
19.07	210.04
19.08	210.02
19.10	209.98
19.11	209.93
19.12	209.87
19.14	209.79
19.15	209.71
19.16	209.62
19.18	209.52
19.19	209.41
19.20	209.30
19.22	209.19
19.23	209.07
19.24	208.95
19.26	208.83
19.27	208.71
19.28	208.59
19.30	208.46
19.31	208.34
19.32	208.21
19.34	208.08
19.35	207.96
19.36	207.83
19.38	207.70
19.39	207.57
19.40	207.44
19.42	207.31
19.43	207.18
19.44	207.05
19.46	206.92
19.47	206.79
19.48	206.66
19.50	206.53
19.51	206.40
19.52	206.27
19.54	206.14
19.55	206.01
19.56	205.87
19.58	205.74
19.59	205.61
19.60	205.48
19.62	205.35
19.63	205.22
19.64	205.08
19.66	204.95
19.67	204.82
19.68	204.69
19.70	204.56
19.71	204.43
19.72	204.30
19.74	204.16
19.75	204.03
19.76	203.90
19.78	203.77
19.79	203.63
19.80	203.50
19.82	203.37
19.83	203.24
19.84	203.10
19.86	202.97
19.87	202.84
19.88	202.71
19.90	202.58
19.91	202.44
19.92	202.31
19.94	202.18
19.95	202.05
19.96	201.91
19.98	201.78
19.99	201.65
20.00	201.52
20.02	201.38
20.03	201.25
20.04	201.12
20.06	200.99
20.07	200.86
20.08	200.72
20.10	200.59
20.11	200.46
20.12	200.32
20.14	200.19
20.15	200.06
20.16	199.92
20.18	199.79
20.19	199.66
20.20	199.53
20.22	199.39
20.23	199.26
20.24	199.13
20.26	199.00
20.27	198.86
20.28	198.73
20.30	198.60
20.31	198.46
20.32	198.33
20.34	198.20
20.35	198.07
20.36	197.93
20.38	197.80
20.39	197.67
20.40	197.53
20.42	197.40
20.43	197.27
20.44	197.13
20.46	197.00
20.47	196.87
20.48	196.73
20.50	196.60
20.51	196.47
20.52	196.34
20.54	196.20
20.55	196.07
20.56	195.94
20.58	195.81
20.59	195.67
20.60	195.54
20.62	195.41
20.63	195.27
20.64	195.14
20.66	195.01
20.67	194.87
20.68	194.74
20.70	194.61
20.71	194.47
20.72	194.34
20.74	194.21
20.75	194.08
20.76	193.94
20.78	193.81
20.79	193.68
20.80	193.54
20.82	193.41
20.83	193.28
20.84	193.14
20.86	193.01
20.87	192.88
20.88	192.74
20.90	192.61
20.91	192.48
20.92	192.34
20.94	192.21
20.95	192.08
20.96	191.94
20.98	191.81
20.99	191.68
21.00	191.55
21.02	191.41
21.03	191.28
21.04	191.15
21.06	191.01
21.07	190.88
21.08	190.75
21.10	190.61
21.11	190.48
21.12	190.35
21.14	190.21
21.15	190.08
21.16	189.95
21.18	189.82
21.19	189.68
21.20	189.55
21.22	189.42
21.23	189.28
21.24	189.15
21.26	189.02
21.27	188.88
21.28	188.75
21.30	188.62
21.31	188.48
21.32	188.35
21.34	188.22
21.35	188.08
21.36	187.95
21.38	187.82
21.39	187.68
21.40	187.55
21.42	187.42
21.43	187.28
21.44	187.15
21.46	187.02
21.47	186.88
21.48	186.75
21.50	186.62
21.51	186.49
21.52	186.35
21.54	186.22
21.55	186.09
21.56	185.96
21.58	185.82
21.59	185.69
21.60	185.55
21.62	185.42
21.63	185.29
21.64	185.16
21.66	185.02
21.67	184.89
21.68	184.76
21.70	184.62
21.71	184.49
21.72	184.35
21.74	184.22
21.75	184.09
21.76	183.96
21.78	183.82
21.79	183.69
21.80	183.56
21.82	183.42
21.83	183.29
21.84	183.16
21.86	183.02
21.87	182.89
21.88	182.76
21.90	182.62
21.91	182.49
21.92	182.36
21.94	182.22
21.95	182.09
21.96	181.96
21.98	181.82
21.99	181.69
22.00	181.56
22.02	181.43
22.03	181.29
22.04	181.16
22.06	181.03
22.07	180.89
22.08	180.76
22.10	180.63
22.11	180.49
22.12	180.36
22.14	180.23
22.15	180.09
22.16	179.96
22.18	179.83
22.19	179.69
22.20	179.56
22.22	179.43
22.23	179.29
22.24	179.16
22.26	179.03
22.27	178.89
22.28	178.76
22.30	178.63
22.31	178.49
22.32	178.36
22.34	178.23
22.35	178.09
22.36	177.96
22.38	177.83
22.39	177.70
22.40	177.56
22.42	177.43
22.43	177.30
22.44	177.16
22.46	177.03
22.47	176.90
22.48	176.76
22.50	176.63
22.51	176.50
22.52	176.36
22.54	176.23
22.55	176.10
22.56	175.96
22.58	175.83
22.59	175.70
22.60	175.56
22.62	175.43
22.63	175.30
22.64	175.16
22.66	175.03
22.67	174.90
22.68	174.77
22.70	174.63
22.71	174.50
22.72	174.37
22.74	174.23
22.75	174.10
22.76	173.97
22.78	173.83
22.79	173.70
22.80	173.57
22.82	173.43
22.83	173.30
22.84	173.17
22.86	173.03
22.87	172.90
22.88	172.77
22.90	172.63
22.91	172.50
22.92	172.37
22.94	172.23
22.95	172.10
22.96	171.97
22.98	171.83
22.99	171.70
23.00	171.57
23.02	171.43
23.03	171.30
23.04	171.17
23.06	171.03
23.07	170.90
23.08	170.77
23.10	170.63
23.11	170.50
23.12	170.37
23.14	170.24
23.15	170.10
23.16	169.97
23.18	169.84
23.19	169.70
23.20	169.57
23.22	169.44
23.23	169.30
23.24	169.17
23.26	169.04
23.27	168.90
23.28	168.77
23.30	168.64
23.31	168.50
23.32	168.37
23.34	168.24
23.35	168.10
23.36	167.97
23.38	167.84
23.39	167.71
23.40	167.57
23.42	167.44
23.43	167.31
23.44	167.17
23.46	167.04
23.47	166.91
23.48	166.77
23.50	166.64
23.51	166.51
23.52	166.37
23.54	166.24
23.55	166.11
23.56	165.97
23.58	165.84
23.59	165.71
23.60	165.57
23.62	165.44
23.63	165.31
23.64	165.17
23.66	165.04
23.67	164.91
23.68	164.78
23.70	164.64
23.71	164.51
23.72	164.38
23.74	164.24
23.75	164.11
23.76	163.98
23.78	163.84
23.79	163.71
23.80	163.58
23.82	163.44
23.83	163.31
23.84	163.18
23.86	163.04
23.87	162.91
23.88	162.78
23.90	162.64
23.91	162.51
23.92	162.38
23.94	162.24
23.95	162.11
23.96	161.98
23.98	161.84
23.99	161.71
24.00	161.58
24.02	161.44
24.03	161.31
24.04	161.18
24.06	161.04
24.07	160.91
24.08	160.78
24.10	160.65
24.11	160.51
24.12	160.38
24.14	160.25
24.15	160.11
24.16	159.98
24.18	159.85
24.19	159.71
24.20	159.58
24.22	159.45
24.23	159.31
24.24	159.18
24.26	159.05
24.27	158.91
24.28	158.78
24.30	158.65
24.31	158.51
24.32	158.38
24.34	158.25
24.35	158.11
24.36	157.98
24.38	157.85
24.39	157.71
24.40	157.58
24.42	157.45
24.43	157.32
24.44	157.18
24.46	157.05
24.47	156.92
24.48	156.78
24.50	156.65
24.51	156.52
24.52	156.38
24.54	156.25
24.55	156.12
24.56	155.98
24.58	155.85
24.59	155.72
24.60	155.58
24.62	155.45
24.63	155.32
24.64	155.18
24.66	155.05
24.67	154.92
24.68	154.78
24.70	154.65
24.71	154.52
24.72	154.39
24.74	154.25
24.75	154.12
24.76	153.99
24.78	153.85
24.79	153.72
24.80	153.59
24.82	153.45
24.83	153.32
24.84	153.19
24.86	153.05
24.87	152.92
24.88	152.79
24.90	152.65
24.91	152.52
24.92	152.39
24.94	152.25
24.95	152.12
24.96	151.99
24.98	151.85
24.99	151.72
25.00	151.59
25.02	151.45
25.03	151.32
25.04	151.19
25.06	151.05
25.07	150.92
25.08	150.79
25.10	150.65
25.11	150.52
25.12	150.39
25.14	150.25
25.15	150.12
25.16	149.99
25.18	149.86
25.19	149.72
25.20	149.59
25.22	149.46
25.23	149.32
25.24	149.19
25.26	149.06
25.27	148.92
25.28	148.79
25.30	148.66
25.31	148.52
25.32	148.39
25.34	148.26
25.35	148.12
25.36	147.99
25.38	147.86
25.39	147.73
25.40	147.59
25.42	147.46
25.43	147.32
25.44	147.19
25.46	147.06
25.47	146.93
25.48	146.79
25.50	146.66
25.51	146.53
25.52	146.39
25.54	146.26
25.55	146.13
25.56	145.99
25.58	145.86
25.59	145.73
25.60	145.59
25.62	145.46
25.63	145.33
25.64	145.19
25.66	145.06
25.67	144.93
25.68	144.79
25.70	144.66
25.71	144.53
25.72	144.39
25.74	144.26
25.75	144.13
25.76	144.00
25.78	143.86
25.79	143.73
25.80	143.60
25.82	143.46
25.83	143.33
25.84	143.20
25.86	143.06
25.87	142.93
25.88	142.80
25.90	142.66
25.91	142.53
25.92	142.40
25.94	142.26
25.95	142.13
25.96	142.00
25.98	141.86
25.99	141.73
26.00	141.60
26.02	141.46
26.03	141.33
26.04	141.20
26.06	141.06
26.07	140.93
26.08	140.80
26.10	140.66
26.11	140.53
26.12	140.40
26.14	140.26
26.15	140.13
26.16	140.00
26.18	139.87
26.19	139.73
26.20	139.60
26.22	139.46
26.23	139.33
26.24	139.20
26.26	139.07
26.27	138.93
26.28	138.80
26.30	138.67
26.31	138.53
26.32	138.40
26.34	138.27
26.35	138.13
26.36	138.00
26.38	137.87
26.39	137.73
26.40	137.60
26.42	137.47
26.43	137.33
26.44	137.20
26.46	137.07
26.47	136.93
26.48	136.80
26.50	136.67
26.51	136.54
26.52	136.40
26.54	136.27
26.55	136.14
26.56	136.00
26.58	135.87
26.59	135.73
26.60	135.60
26.62	135.47
26.63	135.34
26.64	135.20
26.66	135.07
26.67	134.94
26.68	134.80
26.70	134.67
26.71	134.54
26.72	134.40
26.74	134.27
26.75	134.14
26.76	134.00
26.78	133.87
26.79	133.74
26.80	133.60
26.82	133.47
26.83	133.34
26.84	133.20
26.86	133.07
26.87	132.94
26.88	132.80
26.90	132.67
26.91	132.54
26.92	132.41
26.94	132.27
26.95	132.14
26.96	132.01
26.98	131.87
26.99	131.74
27.00	131.61
27.02	131.47
27.03	131.34
27.04	131.21
27.06	131.07
27.07	130.94
27.08	130.81
27.10	130.67
27.11	130.54
27.12	130.41
27.14	130.27
27.15	130.14
27.16	130.01
27.18	129.87
27.19	129.74
27.20	129.61
27.22	129.47
27.23	129.34
27.24	129.21
27.26	129.07
27.27	128.94
27.28	128.81
27.30	128.68
27.31	128.54
27.32	128.41
27.34	128.28
27.35	128.14
27.36	128.01
27.38	127.88
27.39	127.74
27.40	127.61
27.42	127.48
27.43	127.34
27.44	127.21
27.46	127.08
27.47	126.94
27.48	126.81
27.50	126.68
27.51	126.54
27.52	126.41
27.54	126.28
27.55	126.14
27.56	126.01
27.58	125.88
27.59	125.74
27.60	125.61
27.62	125.48
27.63	125.34
27.64	125.21
27.66	125.08
27.67	124.94
27.68	124.81
27.70	124.68
27.71	124.55
27.72	124.41
27.74	124.28
27.75	124.15
27.76	124.01
27.78	123.88
27.79	123.75
27.80	123.61
27.82	123.48
27.83	123.35
27.84	123.21
27.86	123.08
27.87	122.95
27.88	122.81
27.90	122.68
27.91	122.55
27.92	122.41
27.94	122.28
27.95	122.15
27.96	122.01
27.98	121.88
27.99	121.75
28.00	121.61
28.02	121.48
28.03	121.35
28.04	121.22
28.06	121.08
28.07	120.95
28.08	120.82
28.10	120.68
28.11	120.55
28.12	120.42
28.14	120.28
28.15	120.15
28.16	120.02
28.18	119.88
28.19	119.75
28.20	119.62
28.22	119.48
28.23	119.35
28.24	119.22
28.26	119.08
28.27	118.95
28.28	118.82
28.30	118.68
28.31	118.55
28.32	118.42
28.34	118.29
28.35	118.15
28.36	118.02
28.38	117.89
28.39	117.75
28.40	117.62
28.42	117.48
28.43	117.35
28.44	117.22
28.46	117.09
28.47	116.95
28.48	116.82
28.50	116.69
28.51	116.55
28.52	116.42
28.54	116.29
28.55	116.15
28.56	116.02
28.58	115.89
28.59	115.75
28.60	115.62
28.62	115.49
28.63	115.35
28.64	115.22
28.66	115.09
28.67	114.95
28.68	114.82
28.70	114.69
28.71	114.56
28.72	114.42
28.74	114.29
28.75	114.16
28.76	114.02
28.78	113.89
28.79	113.75
28.80	113.62
28.82	113.49
28.83	113.36
28.84	113.22
28.86	113.09
28.87	112.96
28.88	112.82
28.90	112.69
28.91	112.56
28.92	112.42
28.94	112.29
28.95	112.16
28.96	112.02
28.98	111.89
28.99	111.76
29.00	111.62
29.02	111.49
29.03	111.36
29.04	111.22
29.06	111.09
29.07	110.96
29.08	110.82
29.10	110.69
29.11	110.56
29.12	110.43
29.14	110.29
29.15	110.16
29.16	110.03
29.18	109.89
29.19	109.76
29.20	109.63
29.22	109.49
29.23	109.36
29.24	109.23
29.26	109.09
29.27	108.96
29.28	108.83
29.30	108.69
29.31	108.56
29.32	108.43
29.34	108.29
29.35	108.16
29.36	108.03
29.38	107.89
29.39	107.76
29.40	107.63
29.42	107.49
29.43	107.36
29.44	107.23
29.46	107.09
29.47	106.96
29.48	106.83
29.50	106.69
29.51	106.56
29.52	106.43
29.54	106.29
29.55	106.16
29.56	106.03
29.58	105.90
29.59	105.76
29.60	105.63
29.62	105.50
29.63	105.36
29.64	105.23
29.66	105.10
29.67	104.96
29.68	104.83
29.70	104.69
29.71	104.56
29.72	104.43
29.74	104.30
29.75	104.16
29.76	104.03
29.78	103.90
29.79	103.76
29.80	103.63
29.82	103.50
29.83	103.36
29.84	103.23
29.86	103.10
29.87	102.96
29.88	102.83
29.90	102.70
29.91	102.56
29.92	102.43
29.94	102.30
29.95	102.17
29.96	102.03
29.98	101.90
29.99	101.76
30.00	101.63
30.02	101.50
30.03	101.36
30.04	101.23
30.06	101.10
30.07	100.97
30.08	100.83
30.10	100.70
30.11	100.57
30.12	100.43
30.14	100.30
30.15	100.17
30.16	100.03
30.18	99.90
30.19	99.77
30.20	99.63
30.22	99.50
30.23	99.37
30.24	99.23
30.26	99.10
30.27	98.97
30.28	98.83
30.30	98.70
30.31	98.57
30.32	98.44
30.34	98.30
30.35	98.17
30.36	98.04
30.38	97.90
30.39	97.77
30.40	97.64
30.42	97.50
30.43	97.37
30.44	97.24
30.46	97.10
30.47	96.97
30.48	96.84
30.50	96.70
30.51	96.57
30.52	96.44
30.54	96.30
30.55	96.17
30.56	96.04
30.58	95.90
30.59	95.77
30.60	95.64
30.62	95.50
30.63	95.37
30.64	95.24
30.66	95.10
30.67	94.97
30.68	94.84
30.70	94.70
30.71	94.57
30.72	94.44
30.74	94.30
30.75	94.17
30.76	94.04
30.78	93.91
30.79	93.77
30.80	93.64
30.82	93.51
30.83	93.37
30.84	93.24
30.86	93.11
30.87	92.97
30.88	92.84
30.90	92.71
30.91	92.57
30.92	92.44
30.94	92.31
30.95	92.17
30.96	92.04
30.98	91.91
30.99	91.77
31.00	91.64
31.02	91.51
31.03	91.37
31.04	91.24
31.06	91.11
31.07	90.98
31.08	90.84
31.10	90.71
31.11	90.58
31.12	90.44
31.14	90.31
31.15	90.18
31.16	90.04
31.18	89.91
31.19	89.78
31.20	89.64
31.22	89.51
31.23	89.38
31.24	89.24
31.26	89.11
31.27	88.98
31.28	88.84
31.30	88.71
31.31	88.58
31.32	88.44
31.34	88.31
31.35	88.18
31.36	88.05
31.38	87.91
31.39	87.78
31.40	87.64
31.42	87.51
31.43	87.38
31.44	87.25
31.46	87.11
31.47	86.98
31.48	86.84
31.50	86.71
31.51	86.58
31.52	86.45
31.54	86.31
31.55	86.18
31.56	86.05
31.58	85.91
31.59	85.78
31.60	85.65
31.62	85.51
31.63	85.38
31.64	85.25
31.66	85.11
31.67	84.98
31.68	84.85
31.70	84.71
31.71	84.58
31.72	84.45
31.74	84.31
31.75	84.18
31.76	84.05
31.78	83.91
31.79	83.78
31.80	83.65
31.82	83.51
31.83	83.38
31.84	83.25
31.86	83.12
31.87	82.98
31.88	82.85
31.90	82.72
31.91	82.58
31.92	82.45
31.94	82.32
31.95	82.18
31.96	82.05
31.98	81.92
31.99	81.78
32.00	81.65
32.02	81.52
32.03	81.38
32.04	81.25
32.06	81.12
32.07	80.98
32.08	80.85
32.10	80.72
32.11	80.58
32.12	80.45
32.14	80.32
32.15	80.18
32.16	80.05
32.18	79.92
32.19	79.79
32.20	79.65
32.22	79.52
32.23	79.39
32.24	79.25
32.26	79.12
32.27	78.99
32.28	78.85
32.30	78.72
32.31	78.59
32.32	78.45
32.34	78.32
32.35	78.19
32.36	78.05
32.38	77.92
32.39	77.79
32.40	77.65
32.42	77.52
32.43	77.39
32.44	77.25
32.46	77.12
32.47	76.99
32.48	76.85
32.50	76.72
32.51	76.59
32.52	76.45
32.54	76.32
32.55	76.19
32.56	76.05
32.58	75.92
32.59	75.79
32.60	75.66
32.62	75.52
32.63	75.39
32.64	75.26
32.66	75.12
32.67	74.99
32.68	74.86
32.70	74.72
32.71	74.59
32.72	74.46
32.74	74.32
32.75	74.19
32.76	74.06
32.78	73.92
32.79	73.79
32.80	73.66
32.82	73.52
32.83	73.39
32.84	73.26
32.86	73.12
32.87	72.99
32.88	72.86
32.90	72.72
32.91	72.59
32.92	72.46
32.94	72.32
32.95	72.19
32.96	72.06
32.98	71.92
32.99	71.79
33.00	71.66
33.02	71.52
33.03	71.39
33.04	71.26
33.06	71.13
33.07	70.99
33.08	70.86
33.10	70.73
33.11	70.59
33.12	70.46
33.14	70.33
33.15	70.19
33.16	70.06
33.18	69.93
33.19	69.79
33.20	69.66
33.22	69.53
33.23	69.39
33.24	69.26
33.26	69.13
33.27	68.99
33.28	68.86
33.30	68.73
33.31	68.59
33.32	68.46
33.34	68.33
33.35	68.19
33.36	68.06
33.38	67.93
33.39	67.79
33.40	67.66
33.42	67.53
33.43	67.40
33.44	67.26
33.46	67.13
33.47	67.00
33.48	66.86
33.50	66.73
33.51	66.60
33.52	66.46
33.54	66.33
33.55	66.20
33.56	66.06
33.58	65.93
33.59	65.80
33.60	65.66
33.62	65.53
33.63	65.40
33.64	65.26
33.66	65.13
33.67	65.00
33.68	64.87
33.70	64.73
33.71	64.60
33.72	64.47
33.74	64.33
33.75	64.20
33.76	64.06
33.78	63.93
33.79	63.80
33.80	63.67
33.82	63.53
33.83	63.40
33.84	63.27
33.86	63.13
33.87	63.00
33.88	62.87
33.90	62.73
33.91	62.60
33.92	62.47
33.94	62.33
33.95	62.20
33.96	62.07
33.98	61.93
33.99	61.80
34.00	61.67
34.02	61.53
34.03	61.40
34.04	61.27
34.06	61.14
34.07	61.00
34.08	60.87
34.10	60.74
34.11	60.60
34.12	60.47
34.14	60.34
34.15	60.20
34.16	60.07
34.18	59.94
34.19	59.80
34.20	59.67
34.22	59.54
34.23	59.40
34.24	59.27
34.26	59.14
34.27	59.00
34.28	58.87
34.30	58.74
34.31	58.60
34.32	58.47
34.34	58.34
34.35	58.20
34.36	58.07
34.38	57.94
34.39	57.80
34.40	57.67
34.42	57.54
34.43	57.40
34.44	57.27
34.46	57.14
34.47	57.00
34.48	56.87
34.50	56.74
34.51	56.60
34.52	56.47
34.54	56.34
34.55	56.21
34.56	56.07
34.58	55.94
34.59	55.81
34.60	55.67
34.62	55.54
34.63	55.41
34.64	55.27
34.66	55.14
34.67	55.01
34.68	54.87
34.70	54.74
34.71	54.61
34.72	54.47
34.74	54.34
34.75	54.21
34.76	54.07
34.78	53.94
34.79	53.81
34.80	53.67
34.82	53.54
34.83	53.41
34.84	53.27
34.86	53.14
34.87	53.01
34.88	52.87
34.90	52.74
34.91	52.61
34.92	52.48
34.94	52.34
34.95	52.21
34.96	52.08
34.98	51.94
34.99	51.81
35.00	51.68
35.02	51.54
35.03	51.41
35.04	51.28
35.06	51.14
35.07	51.01
35.08	50.88
35.10	50.74
35.11	50.61
35.12	50.48
35.14	50.34
35.15	50.21
35.16	50.08
35.18	49.94
35.19	49.81
35.20	49.68
35.22	49.54
35.23	49.41
35.24	49.28
35.26	49.14
35.27	49.01
35.28	48.88
35.30	48.74
35.31	48.61
35.32	48.48
35.34	48.35
35.35	48.21
35.36	48.08
35.38	47.95
35.39	47.81
35.40	47.68
35.42	47.55
35.43	47.41
35.44	47.28
35.46	47.15
35.47	47.01
35.48	46.88
35.50	46.75
35.51	46.61
35.52	46.48
35.54	46.35
35.55	46.21
35.56	46.08
35.58	45.95
35.59	45.81
35.60	45.68
35.62	45.55
35.63	45.41
35.64	45.28
35.66	45.15
35.67	45.01
35.68	44.88
35.70	44.75
35.71	44.62
35.72	44.48
35.74	44.35
35.75	44.22
35.76	44.08
35.78	43.95
35.79	43.82
35.80	43.68
35.82	43.55
35.83	43.42
35.84	43.28
35.86	43.15
35.87	43.02
35.88	42.88
35.90	42.75
35.91	42.62
35.92	42.48
35.94	42.35
35.95	42.22
35.96	42.08
35.98	41.95
35.99	41.82
36.00	41.68
36.02	41.55
36.03	41.42
36.04	41.28
36.06	41.15
36.07	41.02
36.08	40.89
36.10	40.75
36.11	40.62
36.12	40.48
36.14	40.35
36.15	40.22
36.16	40.09
36.18	39.95
36.19	39.82
36.20	39.69
36.22	39.55
36.23	39.42
36.24	39.29
36.26	39.15
36.27	39.02
36.28	38.89
36.30	38.75
36.31	38.62
36.32	38.49
36.34	38.35
36.35	38.22
36.36	38.09
36.38	37.95
36.39	37.82
36.40	37.69
36.42	37.56
36.43	37.42
36.44	37.29
36.46	37.16
36.47	37.02
36.48	36.89
36.50	36.76
36.51	36.62
36.52	36.49
36.54	36.36
36.55	36.22
36.56	36.09
36.58	35.96
36.59	35.82
36.60	35.69
36.62	35.56
36.63	35.42
36.64	35.29
36.66	35.16
36.67	35.02
36.68	34.89
36.70	34.76
36.71	34.62
36.72	34.49
36.74	34.36
36.75	34.22
36.76	34.09
36.78	33.96
36.79	33.82
36.80	33.69
36.82	33.56
36.83	33.42
36.84	33.29
36.86	33.16
36.87	33.02
36.88	32.89
36.90	32.76
36.91	32.62
36.92	32.49
36.94	32.36
36.95	32.22
36.96	32.09
36.98	31.96
36.99	31.83
37.00	31.71

[step]
Ramp 10.00 °C/min to 210.00 °C
Time	Temperature	Heat Flow (Normalized)	Heat Flow
min	°C	W/g	mW
38.00	30.14		-0.111
38.02	30.14		-0.110
38.03	30.14		-0.109
38.04	30.14		-0.109
38.06	30.15		-0.119
38.07	30.17		-0.209
38.08	30.20		-0.316
38.10	30.25		-0.422
38.11	30.30		-0.521
38.12	30.37		-0.585
38.14	30.45		-0.613
38.15	30.54		-0.599
38.16	30.63		-0.565
38.18	30.73		-0.519
38.19	30.83		-0.467
38.20	30.94		-0.394
38.22	31.05		-0.349
38.23	31.16		-0.313
38.24	31.27		-0.276
38.26	31.38		-0.256
38.27	31.50		-0.228
38.28	31.62		-0.208
38.30	31.74		-0.182
38.31	31.86		-0.169
38.32	31.99		-0.149
38.34	32.11		-0.133
38.35	32.24		-0.112
38.36	32.36		-0.102
38.38	32.49		-0.089
38.39	32.62		-0.079
38.40	32.74		-0.074
38.42	32.87		-0.060
38.43	33.00		-0.056
38.44	33.13		-0.049
38.46	33.26		-0.044
38.47	33.39		-0.039
38.48	33.52		-0.036
38.50	33.64		-0.033
38.51	33.77		-0.029
38.52	33.91		-0.025
38.54	34.04		-0.024
38.55	34.17		-0.022
38.56	34.30		-0.021
38.58	34.43		-0.020
38.59	34.56		-0.019
38.60	34.69		-0.017
38.62	34.82		-0.016
38.63	34.95		-0.015
38.64	35.08		-0.014
38.66	35.21		-0.012
38.67	35.35		-0.011
38.68	35.48		-0.010
38.70	35.61		-0.009
38.71	35.74		-0.008
38.72	35.87		-0.007
38.74	36.01		-0.006
38.75	36.14		-0.005
38.76	36.27		-0.004
38.78	36.40		-0.003
38.79	36.53		-0.002
38.80	36.67		-0.001
38.82	36.80		0.000
38.83	36.93		0.000
38.84	37.06		0.001
38.86	37.20		0.002
38.87	37.33		0.002
38.88	37.46		0.003
38.90	37.59		0.004
38.91	37.72		0.004
38.92	37.86		0.004
38.94	37.99		0.005
38.95	38.12		0.005
38.96	38.25		0.006
38.98	38.39		0.006
38.99	38.52		0.006
39.00	38.65		0.007
39.02	38.79		0.007
39.03	38.92		0.007
39.04	39.05		0.008
39.06	39.18		0.008
39.07	39.32		0.008
39.08	39.45		0.008
39.10	39.58		0.009
[...]
43.20	80.66		-0.035
43.22	80.80		-0.035
43.23	80.93		-0.035
43.24	81.06		-0.035
43.26	81.20		-0.035
43.27	81.33		-0.036
43.28	81.46		-0.036
43.30	81.60		-0.036
43.31	81.73		-0.036
43.32	81.86		-0.036
43.34	82.00		-0.036
43.35	82.13		-0.036
43.36	82.26		-0.037
43.38	82.40		-0.037
43.39	82.53		-0.037
43.40	82.67		-0.037
43.42	82.80		-0.037
43.43	82.93		-0.037
43.44	83.07		-0.038
43.46	83.20		-0.038
43.47	83.33		-0.038
43.48	83.47		-0.038
43.50	83.60		-0.038
43.51	83.73		-0.038
43.52	83.87		-0.038
43.54	84.00		-0.039
43.55	84.13		-0.039
43.56	84.27		-0.039
43.58	84.40		-0.039
43.59	84.53		-0.039
43.60	84.67		-0.040
43.62	84.80		-0.040
43.63	84.93		-0.040
43.64	85.07		-0.040
43.66	85.20		-0.040
43.67	85.33		-0.040
43.68	85.47		-0.040
43.70	85.60		-0.041
43.71	85.73		-0.041
43.72	85.87		-0.041
43.74	86.00		-0.041
43.75	86.13		-0.041
43.76	86.27		-0.042
43.78	86.40		-0.042
43.79	86.53		-0.042
43.80	86.67		-0.043
43.82	86.80		-0.043
43.83	86.93		-0.043
43.84	87.07		-0.043
43.86	87.20		-0.043
43.87	87.34		-0.044
43.88	87.47		-0.044
43.90	87.60		-0.044
43.91	87.74		-0.044
43.92	87.87		-0.044
43.94	88.00		-0.044
43.95	88.14		-0.044
43.96	88.27		-0.044
43.98	88.40		-0.044
43.99	88.54		-0.045
44.00	88.67		-0.045
44.02	88.80		-0.045
44.03	88.94		-0.045
44.04	89.07		-0.045
44.06	89.20		-0.045
44.07	89.34		-0.045
44.08	89.47		-0.045
44.10	89.60		-0.045
44.11	89.74		-0.045
44.12	89.87		-0.045
44.14	90.00		-0.045
44.15	90.14		-0.046
44.16	90.27		-0.046
44.18	90.40		-0.046
44.19	90.54		-0.046
44.20	90.67		-0.046
44.22	90.80		-0.046
44.23	90.94		-0.046
44.24	91.07		-0.046
44.26	91.21		-0.046
44.27	91.34		-0.046
44.28	91.47		-0.046
44.30	91.61		-0.046
44.31	91.74		-0.046
44.32	91.87		-0.046
44.34	92.01		-0.046
44.35	92.14		-0.046
44.36	92.27		-0.046
44.38	92.41		-0.046
44.39	92.54		-0.046
44.40	92.67		-0.046
44.42	92.81		-0.046
44.43	92.94		-0.046
44.44	93.07		-0.046
44.46	93.21		-0.046
44.47	93.34		-0.046
44.48	93.47		-0.046
44.50	93.61		-0.046
44.51	93.74		-0.046
44.52	93.87		-0.046
44.54	94.01		-0.046
44.55	94.14		-0.046
44.56	94.27		-0.046
44.58	94.41		-0.046
44.59	94.54		-0.046
44.60	94.67		-0.046
44.62	94.81		-0.046
44.63	94.94		-0.046
44.64	95.07		-0.046
44.66	95.21		-0.047
44.67	95.34		-0.047
44.68	95.47		-0.047
44.70	95.61		-0.047
44.71	95.74		-0.047
44.72	95.87		-0.047
44.74	96.01		-0.047
44.75	96.14		-0.047
44.76	96.28		-0.047
44.78	96.41		-0.047
44.79	96.54		-0.047
44.80	96.68		-0.047
44.82	96.81		-0.047
44.83	96.94		-0.047
44.84	97.08		-0.047
44.86	97.21		-0.047
44.87	97.34		-0.047
44.88	97.48		-0.047
44.90	97.61		-0.047
44.91	97.74		-0.047
44.92	97.88		-0.048
44.94	98.01		-0.048
44.95	98.14		-0.048
44.96	98.28		-0.048
44.98	98.41		-0.048
44.99	98.54		-0.048
45.00	98.68		-0.048
45.02	98.81		-0.048
45.03	98.94		-0.048
45.04	99.08		-0.048
45.06	99.21		-0.048
45.07	99.34		-0.049
45.08	99.48		-0.049
45.10	99.61		-0.049
45.11	99.74		-0.049
45.12	99.88		-0.049
45.14	100.01		-0.049
45.15	100.14		-0.050
45.16	100.28		-0.050
45.18	100.41		-0.050
45.19	100.55		-0.050
45.20	100.68		-0.050
45.22	100.81		-0.050
45.23	100.94		-0.050
45.24	101.08		-0.050
45.26	101.21		-0.050
45.27	101.35		-0.050
45.28	101.48		-0.050
45.30	101.61		-0.050
45.31	101.75		-0.050
45.32	101.88		-0.051
45.34	102.01		-0.051
45.35	102.15		-0.051
45.36	102.28		-0.051
45.38	102.41		-0.051
45.39	102.55		-0.051
45.40	102.68		-0.051
45.42	102.81		-0.051
45.43	102.95		-0.051
45.44	103.08		-0.051
45.46	103.21		-0.051
45.47	103.35		-0.051
45.48	103.48		-0.051
45.50	103.61		-0.051
45.51	103.75		-0.051
45.52	103.88		-0.052
45.54	104.01		-0.051
45.55	104.15		-0.051
45.56	104.28		-0.052
45.58	104.41		-0.052
45.59	104.55		-0.052
45.60	104.68		-0.052
45.62	104.82		-0.052
45.63	104.95		-0.052
45.64	105.08		-0.052
45.66	105.22		-0.052
45.67	105.35		-0.052
45.68	105.48		-0.052
45.70	105.61		-0.052
45.71	105.75		-0.052
45.72	105.88		-0.052
45.74	106.02		-0.052
45.75	106.15		-0.053
45.76	106.28		-0.053
45.78	106.42		-0.053
45.79	106.55		-0.053
45.80	106.68		-0.053
45.82	106.82		-0.053
45.83	106.95		-0.053
45.84	107.08		-0.053
45.86	107.22		-0.053
45.87	107.35		-0.053
45.88	107.48		-0.053
45.90	107.62		-0.054
45.91	107.75		-0.053
45.92	107.88		-0.054
45.94	108.02		-0.054
45.95	108.15		-0.054
45.96	108.28		-0.054
45.98	108.42		-0.054
45.99	108.55		-0.054
46.00	108.68		-0.054
46.02	108.82		-0.054
46.03	108.95		-0.054
46.04	109.08		-0.054
46.06	109.22		-0.054
46.07	109.35		-0.054
46.08	109.48		-0.055
46.10	109.62		-0.055
46.11	109.75		-0.055
46.12	109.88		-0.055
46.14	110.02		-0.054
46.15	110.15		-0.054
46.16	110.28		-0.054
46.18	110.42		-0.054
46.19	110.55		-0.055
46.20	110.68		-0.055
46.22	110.82		-0.055
46.23	110.95		-0.055
46.24	111.08		-0.055
46.26	111.22		-0.055
46.27	111.35		-0.055
46.28	111.48		-0.056
46.30	111.62		-0.056
46.31	111.75		-0.056
46.32	111.89		-0.056
46.34	112.02		-0.056
46.35	112.15		-0.057
46.36	112.29		-0.057
46.38	112.42		-0.057
46.39	112.55		-0.056
46.40	112.69		-0.057
46.42	112.82		-0.057
46.43	112.95		-0.057
46.44	113.09		-0.057
46.46	113.22		-0.057
46.47	113.35		-0.057
46.48	113.49		-0.057
46.50	113.62		-0.057
46.51	113.75		-0.057
46.52	113.89		-0.057
46.54	114.02		-0.058
46.55	114.15		-0.058
46.56	114.29		-0.058
46.58	114.42		-0.058
46.59	114.55		-0.058
46.60	114.69		-0.058
46.62	114.82		-0.058
46.63	114.95		-0.058
46.64	115.09		-0.058
46.66	115.22		-0.058
46.67	115.35		-0.058
46.68	115.49		-0.058
46.70	115.62		-0.059
46.71	115.75		-0.059
46.72	115.89		-0.059
46.74	116.02		-0.059
46.75	116.16		-0.059
46.76	116.29		-0.059
46.78	116.42		-0.059
46.79	116.56		-0.059
46.80	116.69		-0.059
46.82	116.82		-0.059
46.83	116.95		-0.059
46.84	117.09		-0.059
46.86	117.22		-0.059
46.87	117.35		-0.060
46.88	117.49		-0.060
46.90	117.62		-0.060
46.91	117.76		-0.060
46.92	117.89		-0.060
46.94	118.02		-0.061
46.95	118.16		-0.061
46.96	118.29		-0.061
46.98	118.42		-0.061
46.99	118.56		-0.061
47.00	118.69		-0.061
47.02	118.82		-0.062
47.03	118.96		-0.061
47.04	119.09		-0.062
47.06	119.22		-0.062
47.07	119.36		-0.062
47.08	119.49		-0.062
47.10	119.62		-0.062
47.11	119.76		-0.062
47.12	119.89		-0.062
47.14	120.02		-0.062
47.15	120.16		-0.062
47.16	120.29		-0.062
47.18	120.42		-0.062
47.19	120.56		-0.063
47.20	120.69		-0.063
47.22	120.83		-0.063
47.23	120.96		-0.063
47.24	121.09		-0.063
47.26	121.23		-0.063
47.27	121.36		-0.063
47.28	121.49		-0.063
47.30	121.63		-0.063
47.31	121.76		-0.063
47.32	121.89		-0.063
47.34	122.03		-0.064
47.35	122.16		-0.064
47.36	122.29		-0.064
47.38	122.42		-0.064
47.39	122.56		-0.064
47.40	122.69		-0.064
47.42	122.83		-0.064
47.43	122.96		-0.064
47.44	123.09		-0.064
47.46	123.23		-0.064
47.47	123.36		-0.064
47.48	123.49		-0.064
47.50	123.63		-0.064
47.51	123.76		-0.064
47.52	123.89		-0.065
47.54	124.03		-0.065
47.55	124.16		-0.065
47.56	124.29		-0.065
47.58	124.43		-0.065
47.59	124.56		-0.066
47.60	124.69		-0.066
47.62	124.83		-0.066
47.63	124.96		-0.066
47.64	125.09		-0.066
47.66	125.23		-0.066
47.67	125.36		-0.066
47.68	125.49		-0.066
47.70	125.63		-0.066
47.71	125.76		-0.067
47.72	125.89		-0.067
47.74	126.03		-0.067
47.75	126.16		-0.067
47.76	126.29		-0.067
47.78	126.43		-0.067
47.79	126.56		-0.067
47.80	126.70		-0.067
47.82	126.83		-0.067
47.83	126.96		-0.067
47.84	127.09		-0.067
47.86	127.23		-0.067
47.87	127.36		-0.067
47.88	127.50		-0.068
47.90	127.63		-0.068
47.91	127.76		-0.068
47.92	127.90		-0.068
47.94	128.03		-0.068
47.95	128.16		-0.068
47.96	128.30		-0.069
47.98	128.43		-0.069
47.99	128.56		-0.069
48.00	128.70		-0.069
48.02	128.83		-0.069
48.03	128.96		-0.069
48.04	129.10		-0.069
48.06	129.23		-0.069
48.07	129.36		-0.069
48.08	129.50		-0.070
48.10	129.63		-0.070
48.11	129.76		-0.070
48.12	129.90		-0.070
48.14	130.03		-0.070
48.15	130.16		-0.070
48.16	130.30		-0.070
48.18	130.43		-0.071
48.19	130.56		-0.071
48.20	130.70		-0.071
48.22	130.83		-0.071
48.23	130.96		-0.071
48.24	131.10		-0.071
48.26	131.23		-0.071
48.27	131.36		-0.071
48.28	131.50		-0.072
48.30	131.63		-0.072
48.31	131.76		-0.072
48.32	131.90		-0.072
48.34	132.03		-0.072
48.35	132.16		-0.072
48.36	132.30		-0.072
48.38	132.43		-0.072
48.39	132.57		-0.072
48.40	132.70		-0.072
48.42	132.83		-0.072
48.43	132.96		-0.073
48.44	133.10		-0.072
48.46	133.23		-0.073
48.47	133.37		-0.073
48.48	133.50		-0.073
48.50	133.63		-0.073
48.51	133.76		-0.073
48.52	133.90		-0.073
48.54	134.03		-0.073
48.55	134.17		-0.073
48.56	134.30		-0.073
48.58	134.43		-0.073
48.59	134.57		-0.074
48.60	134.70		-0.074
48.62	134.83		-0.074
48.63	134.96		-0.074
48.64	135.10		-0.074
48.66	135.23		-0.074
48.67	135.36		-0.074
48.68	135.50		-0.074
48.70	135.63		-0.074
48.71	135.77		-0.075
48.72	135.90		-0.075
48.74	136.03		-0.075
48.75	136.17		-0.075
48.76	136.30		-0.075
48.78	136.43		-0.075
48.79	136.57		-0.075
48.80	136.70		-0.076
48.82	136.83		-0.076
48.83	136.97		-0.076
48.84	137.10		-0.076
48.86	137.23		-0.076
48.87	137.37		-0.076
48.88	137.50		-0.077
48.90	137.63		-0.077
48.91	137.77		-0.077
48.92	137.90		-0.077
48.94	138.03		-0.077
48.95	138.17		-0.077
48.96	138.30		-0.077
48.98	138.43		-0.077
48.99	138.57		-0.078
49.00	138.70		-0.078
49.02	138.84		-0.078
49.03	138.97		-0.078
49.04	139.10		-0.078
49.06	139.23		-0.078
49.07	139.37		-0.078
49.08	139.50		-0.078
49.10	139.63		-0.078
49.11	139.77		-0.078
49.12	139.90		-0.079
49.14	140.04		-0.079
49.15	140.17		-0.079
49.16	140.30		-0.079
49.18	140.44		-0.079
49.19	140.57		-0.079
49.20	140.70		-0.079
49.22	140.83		-0.079
49.23	140.97		-0.079
49.24	141.10		-0.079
49.26	141.24		-0.079
49.27	141.37		-0.079
49.28	141.50		-0.080
49.30	141.64		-0.080
49.31	141.77		-0.080
49.32	141.90		-0.080
49.34	142.04		-0.080
49.35	142.17		-0.080
49.36	142.30		-0.081
49.38	142.44		-0.081
49.39	142.57		-0.081
49.40	142.70		-0.081
49.42	142.84		-0.081
49.43	142.97		-0.081
49.44	143.10		-0.081
49.46	143.24		-0.081
49.47	143.37		-0.081
49.48	143.50		-0.082
49.50	143.64		-0.082
49.51	143.77		-0.082
49.52	143.90		-0.082
49.54	144.04		-0.082
49.55	144.17		-0.082
49.56	144.30		-0.082
49.58	144.44		-0.082
49.59	144.57		-0.082
49.60	144.70		-0.083
49.62	144.84		-0.083
49.63	144.97		-0.083
49.64	145.10		-0.083
49.66	145.24		-0.083
49.67	145.37		-0.083
49.68	145.50		-0.083
49.70	145.64		-0.083
49.71	145.77		-0.084
49.72	145.90		-0.084
49.74	146.04		-0.084
49.75	146.17		-0.084
49.76	146.30		-0.084
49.78	146.44		-0.084
49.79	146.57		-0.084
49.80	146.71		-0.084
49.82	146.84		-0.085
49.83	146.97		-0.085
49.84	147.11		-0.085
49.86	147.24		-0.085
49.87	147.37		-0.085
49.88	147.51		-0.085
49.90	147.64		-0.085
49.91	147.77		-0.085
49.92	147.91		-0.085
49.94	148.04		-0.085
49.95	148.17		-0.085
49.96	148.31		-0.085
49.98	148.44		-0.085
49.99	148.57		-0.086
50.00	148.71		-0.086
50.02	148.84		-0.086
50.03	148.97		-0.086
50.04	149.11		-0.086
50.06	149.24		-0.087
50.07	149.37		-0.087
50.08	149.51		-0.087
50.10	149.64		-0.087
50.11	149.77		-0.087
50.12	149.91		-0.087
50.14	150.04		-0.087
50.15	150.17		-0.088
50.16	150.31		-0.088
50.18	150.44		-0.088
50.19	150.57		-0.088
50.20	150.71		-0.088
50.22	150.84		-0.088
50.23	150.97		-0.088
50.24	151.11		-0.088
50.26	151.24		-0.088
50.27	151.37		-0.088
50.28	151.51		-0.088
50.30	151.64		-0.088
50.31	151.77		-0.089
50.32	151.91		-0.089
50.34	152.04		-0.089
50.35	152.17		-0.089
50.36	152.31		-0.089
50.38	152.44		-0.089
50.39	152.57		-0.089
50.40	152.71		-0.089
50.42	152.84		-0.089
50.43	152.97		-0.089
50.44	153.11		-0.089
50.46	153.24		-0.089
50.47	153.37		-0.089
50.48	153.51		-0.089
50.50	153.64		-0.089
50.51	153.78		-0.089
50.52	153.91		-0.089
50.54	154.04		-0.089
50.55	154.17		-0.089
50.56	154.31		-0.089
50.58	154.44		-0.089
50.59	154.58		-0.089
50.60	154.71		-0.090
50.62	154.84		-0.090
50.63	154.97		-0.090
50.64	155.11		-0.090
50.66	155.24		-0.090
50.67	155.37		-0.090
50.68	155.51		-0.090
50.70	155.64		-0.091
50.71	155.78		-0.091
50.72	155.91		-0.091
50.74	156.04		-0.091
50.75	156.18		-0.091
50.76	156.31		-0.091
50.78	156.44		-0.091
50.79	156.58		-0.091
50.80	156.71		-0.091
50.82	156.84		-0.091
50.83	156.98		-0.091
50.84	157.11		-0.091
50.86	157.24		-0.092
50.87	157.38		-0.091
50.88	157.51		-0.092
50.90	157.64		-0.092
50.91	157.78		-0.092
50.92	157.91		-0.092
50.94	158.04		-0.092
50.95	158.18		-0.092
50.96	158.31		-0.092
50.98	158.44		-0.092
50.99	158.58		-0.093
51.00	158.71		-0.093
51.02	158.84		-0.093
51.03	158.98		-0.093
51.04	159.11		-0.093
51.06	159.24		-0.094
51.07	159.38		-0.094
51.08	159.51		-0.094
51.10	159.64		-0.094
51.11	159.78		-0.094
51.12	159.91		-0.094
51.14	160.04		-0.094
51.15	160.18		-0.094
51.16	160.31		-0.094
51.18	160.44		-0.094
51.19	160.58		-0.094
51.20	160.71		-0.094
51.22	160.84		-0.095
51.23	160.98		-0.095
51.24	161.11		-0.095
51.26	161.25		-0.095
51.27	161.38		-0.095
51.28	161.51		-0.095
51.30	161.65		-0.095
51.31	161.78		-0.095
51.32	161.91		-0.095
51.34	162.05		-0.095
51.35	162.18		-0.095
51.36	162.31		-0.095
51.38	162.45		-0.095
51.39	162.58		-0.095
51.40	162.71		-0.095
51.42	162.84		-0.096
51.43	162.98		-0.096
51.44	163.11		-0.096
51.46	163.25		-0.096
51.47	163.38		-0.097
51.48	163.51		-0.097
51.50	163.65		-0.097
51.51	163.78		-0.097
51.52	163.91		-0.097
51.54	164.05		-0.097
51.55	164.18		-0.097
51.56	164.31		-0.097
51.58	164.45		-0.098
51.59	164.58		-0.097
51.60	164.71		-0.097
51.62	164.85		-0.097
51.63	164.98		-0.097
51.64	165.11		-0.097
51.66	165.25		-0.097
51.67	165.38		-0.097
51.68	165.51		-0.098
51.70	165.65		-0.098
51.71	165.78		-0.098
51.72	165.91		-0.099
51.74	166.05		-0.099
51.75	166.18		-0.099
51.76	166.31		-0.099
51.78	166.45		-0.099
51.79	166.58		-0.100
51.80	166.71		-0.100
51.82	166.85		-0.100
51.83	166.98		-0.100
51.84	167.11		-0.100
51.86	167.25		-0.100
51.87	167.38		-0.100
51.88	167.52		-0.100
51.90	167.65		-0.100
51.91	167.78		-0.100
51.92	167.92		-0.100
51.94	168.05		-0.100
51.95	168.18		-0.100
51.96	168.32		-0.100
51.98	168.45		-0.100
51.99	168.58		-0.100
52.00	168.72		-0.100
52.02	168.85		-0.100
52.03	168.98		-0.100
52.04	169.12		-0.100
52.06	169.25		-0.101
52.07	169.38		-0.101
52.08	169.52		-0.101
52.10	169.65		-0.101
52.11	169.78		-0.102
52.12	169.92		-0.102
52.14	170.05		-0.102
52.15	170.18		-0.102
52.16	170.32		-0.102
52.18	170.45		-0.102
52.19	170.58		-0.102
52.20	170.72		-0.102
52.22	170.85		-0.102
52.23	170.98		-0.102
52.24	171.12		-0.102
52.26	171.25		-0.102
52.27	171.38		-0.102
52.28	171.52		-0.102
52.30	171.65		-0.102
52.31	171.78		-0.102
52.32	171.92		-0.102
52.34	172.05		-0.102
52.35	172.18		-0.102
52.36	172.32		-0.103
52.38	172.45		-0.103
52.39	172.58		-0.103
52.40	172.72		-0.103
52.42	172.85		-0.103
52.43	172.98		-0.103
52.44	173.12		-0.103
52.46	173.25		-0.103
52.47	173.38		-0.104
52.48	173.52		-0.104
52.50	173.65		-0.104
52.51	173.78		-0.104
52.52	173.92		-0.104
52.54	174.05		-0.104
52.55	174.18		-0.104
52.56	174.32		-0.104
52.58	174.45		-0.104
52.59	174.58		-0.104
52.60	174.72		-0.104
52.62	174.85		-0.104
52.63	174.98		-0.104
52.64	175.12		-0.105
52.66	175.25		-0.105
52.67	175.38		-0.105
52.68	175.52		-0.105
52.70	175.65		-0.105
52.71	175.78		-0.105
52.72	175.92		-0.105
52.74	176.05		-0.105
52.75	176.19		-0.105
52.76	176.32		-0.105
52.78	176.45		-0.105
52.79	176.58		-0.105
52.80	176.72		-0.105
52.82	176.85		-0.105
52.83	176.99		-0.106
52.84	177.12		-0.106
52.86	177.25		-0.106
52.87	177.39		-0.106
52.88	177.52		-0.106
52.90	177.65		-0.106
52.91	177.79		-0.106
52.92	177.92		-0.106
52.94	178.05		-0.106
52.95	178.19		-0.106
52.96	178.32		-0.106
52.98	178.45		-0.106
52.99	178.59		-0.107
53.00	178.72		-0.107
53.02	178.85		-0.107
53.03	178.99		-0.108
53.04	179.12		-0.108
53.06	179.25		-0.108
53.07	179.39		-0.108
53.08	179.52		-0.108
53.10	179.65		-0.108
53.11	179.79		-0.108
53.12	179.92		-0.108
53.14	180.05		-0.108
53.15	180.19		-0.108
53.16	180.32		-0.108
53.18	180.45		-0.108
53.19	180.59		-0.108
53.20	180.72		-0.108
53.22	180.85		-0.109
53.23	180.99		-0.109
53.24	181.12		-0.109
53.26	181.25		-0.109
53.27	181.39		-0.109
53.28	181.52		-0.109
53.30	181.65		-0.109
53.31	181.79		-0.109
53.32	181.92		-0.110
53.34	182.05		-0.110
53.35	182.19		-0.110
53.36	182.32		-0.110
53.38	182.45		-0.110
53.39	182.59		-0.110
53.40	182.72		-0.110
53.42	182.86		-0.110
53.43	182.99		-0.110
53.44	183.12		-0.110
53.46	183.25		-0.110
53.47	183.39		-0.110
53.48	183.52		-0.110
53.50	183.65		-0.110
53.51	183.79		-0.110
53.52	183.92		-0.110
53.54	184.05		-0.111
53.55	184.19		-0.111
53.56	184.32		-0.111
53.58	184.46		-0.111
53.59	184.59		-0.112
53.60	184.72		-0.112
53.62	184.86		-0.112
53.63	184.99		-0.112
53.64	185.12		-0.112
53.66	185.26		-0.112
53.67	185.39		-0.112
53.68	185.52		-0.111
53.70	185.66		-0.111
53.71	185.79		-0.111
53.72	185.92		-0.111
53.74	186.06		-0.111
53.75	186.19		-0.111
53.76	186.32		-0.112
53.78	186.46		-0.112
53.79	186.59		-0.112
53.80	186.72		-0.112
53.82	186.86		-0.112
53.83	186.99		-0.113
53.84	187.12		-0.113
53.86	187.25		-0.113
53.87	187.39		-0.113
53.88	187.52		-0.113
53.90	187.66		-0.113
53.91	187.79		-0.113
53.92	187.92		-0.113
53.94	188.06		-0.113
53.95	188.19		-0.113
53.96	188.32		-0.113
53.98	188.46		-0.113
53.99	188.59		-0.114
54.00	188.72		-0.114
54.02	188.86		-0.114
54.03	188.99		-0.114
54.04	189.12		-0.114
54.06	189.26		-0.114
54.07	189.39		-0.114
54.08	189.52		-0.114
54.10	189.66		-0.114
54.11	189.79		-0.115
54.12	189.92		-0.115
54.14	190.06		-0.115
54.15	190.19		-0.115
54.16	190.32		-0.115
54.18	190.46		-0.115
54.19	190.59		-0.115
54.20	190.72		-0.115
54.22	190.86		-0.116
54.23	190.99		-0.116
54.24	191.12		-0.116
54.26	191.26		-0.116
54.27	191.39		-0.116
54.28	191.52		-0.116
54.30	191.66		-0.116
54.31	191.79		-0.116
54.32	191.92		-0.116
54.34	192.06		-0.116
54.35	192.19		-0.116
54.36	192.32		-0.116
54.38	192.46		-0.116
54.39	192.59		-0.116
54.40	192.72		-0.116
54.42	192.86		-0.116
54.43	192.99		-0.117
54.44	193.12		-0.117
54.46	193.26		-0.117
54.47	193.39		-0.117
54.48	193.53		-0.117
54.50	193.66		-0.117
54.51	193.79		-0.117
54.52	193.93		-0.118
54.54	194.06		-0.118
54.55	194.19		-0.118
54.56	194.33		-0.118
54.58	194.46		-0.118
54.59	194.59		-0.118
54.60	194.73		-0.118
54.62	194.86		-0.118
54.63	194.99		-0.118
54.64	195.13		-0.118
54.66	195.26		-0.118
54.67	195.39		-0.118
54.68	195.53		-0.119
54.70	195.66		-0.118
54.71	195.79		-0.119
54.72	195.93		-0.119
54.74	196.06		-0.119
54.75	196.19		-0.119
54.76	196.33		-0.119
54.78	196.46		-0.119
54.79	196.59		-0.119
54.80	196.73		-0.119
54.82	196.86		-0.120
54.83	196.99		-0.120
54.84	197.13		-0.120
54.86	197.26		-0.120
54.87	197.39		-0.120
54.88	197.53		-0.120
54.90	197.66		-0.120
54.91	197.79		-0.120
54.92	197.93		-0.121
54.94	198.06		-0.121
54.95	198.19		-0.120
54.96	198.33		-0.121
54.98	198.46		-0.121
54.99	198.59		-0.121
55.00	198.73		-0.121
55.02	198.86		-0.122
55.03	198.99		-0.122
55.04	199.13		-0.122
55.06	199.26		-0.122
55.07	199.39		-0.122
55.08	199.53		-0.123
55.10	199.66		-0.122
55.11	199.79		-0.122
55.12	199.93		-0.122
55.14	200.06		-0.122
55.15	200.19		-0.122
55.16	200.33		-0.122
55.18	200.46		-0.122
55.19	200.59		-0.122
55.20	200.73		-0.122
55.22	200.86		-0.122
55.23	201.00		-0.122
55.24	201.13		-0.123
55.26	201.26		-0.123
55.27	201.39		-0.122
55.28	201.53		-0.123
55.30	201.66		-0.123
55.31	201.79		-0.123
55.32	201.93		-0.123
55.34	202.06		-0.123
55.35	202.19		-0.123
55.36	202.33		-0.123
55.38	202.46		-0.123
55.39	202.59		-0.124
55.40	202.73		-0.124
55.42	202.86		-0.124
55.43	202.99		-0.124
55.44	203.13		-0.124
55.46	203.26		-0.125
55.47	203.40		-0.125
55.48	203.53		-0.125
55.50	203.66		-0.125
55.51	203.80		-0.125
55.52	203.93		-0.125
55.54	204.06		-0.125
55.55	204.20		-0.125
55.56	204.33		-0.124
55.58	204.46		-0.124
55.59	204.60		-0.125
55.60	204.73		-0.125
55.62	204.86		-0.125
55.63	205.00		-0.125
55.64	205.13		-0.125
55.66	205.26		-0.126
55.67	205.40		-0.126
55.68	205.53		-0.126
55.70	205.66		-0.126
55.71	205.80		-0.126
55.72	205.93		-0.126
55.74	206.06		-0.126
55.75	206.20		-0.126
55.76	206.33		-0.127
55.78	206.46		-0.127
55.79	206.60		-0.127
55.80	206.73		-0.127
55.82	206.86		-0.127
55.83	206.99		-0.127
55.84	207.13		-0.127
55.86	207.26		-0.127
55.87	207.40		-0.128
55.88	207.53		-0.128
55.90	207.66		-0.128
55.91	207.80		-0.128
55.92	207.93		-0.128
55.94	208.06		-0.128
55.95	208.20
55.96	208.33
55.98	208.46
55.99	208.60
56.00