File: Data/2024_09_19_Naph_CHM343_DSC.txt
Filename	2024_09_19_Naph_CHM343_DSC
Instrument name	DSC2A-00468 (192.168.1.100)
Operator	CHM343
rundate	9/19/2024
Sample name	2024_09_19_Naph_CHM343_DSC
proceduresegments	Equilibrate 30.00 °C; Ramp 10.00 °C/min to 160.00 °C; Isothermal 1.0 min; Ramp 10.00 °C/min to 30.00 °C
[File Parameters]
Run date	9/19/2024 6:12:05 PM
Trios version	5.1.1.46572
Original File Name	C:\ProgramData\TA Instruments\TRIOS\Data\2024_09_19_Naph_CHM343_DSC.tri
Current File Name	D:\DSC2500\CHM343\2024_09_19_Naph_CHM343_DSC.tri
[Procedure]
Procedure Name	CHM343_Fall2024_Azulene
Sample Name	2024_09_19_Naph_CHM343_DSC
Sample Mass	1.01 mg
Reference Sample Mass	0 mg
Pan Mass	53.87 mg
Pan Number	22
Reference Pan Mass	54 mg
Reference Pan Number	19
Pan Type	Aluminum
Comments	Naphthalene - Al Hermetic Sealed Pan, with ref Al pan.  ASU Online CHM343, Remote DSC experimental lab. Fall 2024.  Group Zoom Data Collection, Sept 19, 2024 from 5-7 pm.  TA Instruments DSC2500.
Project Name	Lab 4 - Fall 2024
Operator	CHM343
Test	Custom
Unload Max Temperature	30
Unload Min Temperature	30
Load Max Temperature	30
Load Min Temperature	30
Stop on Gas Flow Error	Yes
[Signal List]
Signal #1	Time (min)
Signal #2	Temperature (°C)
Signal #3	Heat Flow (mW)
Signal #4	Delta T (µV)
Signal #5	Delta Tzero (µV)
Signal #6	Tzero Temperature (°C)
Signal #7	Cell Purge (mL/min)
Signal #8	Heater Temp (°C)
Signal #9	Power Delivered (W)
Signal #10	Reference Junction Temperature (°C)
Signal #11	Flange Temperature (°C)
Signal #12	Heat Flow Phase (rad)
Signal #13	Total Heat Capacity (J/°C)
Signal #14	Heat Capacity (J/°C)
[Configuration]
Company Name	ASU
Instrument Name	DSC2A-00468
Instrument Type	DSC2500
Serial Number	DSC2A-00468
IP	192.168.1.100
Location of Instrument	MRRC
DisplayType	Unknown
Sample Interval 	0.1 s/pt
Selected Heat Flow	T4P
Exotherm Direction	Down
Cell Serial	DRC2-00792
Lid Type	Standard
Cooler	RCS 90
Leave Cooler on at End of Sequence	On
Gas 2	Nitrogen
Gas Selected	Channel 1
Flow Rate	50 mL/min
Secondary Purge	On
Licensed Heat Flow	Heat Flow T4P
Modulation Licensed	Yes
[Versions]
Common IDD Version	1
Cortex Version	VER 2.10.2.31
Driver	5.0.0.6
GDM Version	1.0.3.3
TouchscreenVersion	1.0.0.16145
FEP Version	1.2.1.21
FEP Bootloader	2.0.0.5
AutoSampler Version	2.1.1.26
Auto Sampler Bootloader	2.0.0.5
FCM Version	1.1.0.3
FCM Bootloader	2.0.0.5
[Experiment Logs]
Experiment Log Entry # 1	Equilibrate Segment 30 (C) Started
Experiment Log Entry # 3	Air Cool is off.
Experiment Log Entry # 5	Ramp Segment 10 C/min to 160 Started
Experiment Log Entry # 7	Isothermal Segment 1 min started
Experiment Log Entry # 9	Ramp Segment 10 C/min to 30 Started
[Method Log]
Method Log Entry # 1	Equilibrate 30 °C
Method Log Entry # 2	(Ramp 9897) Ramp 10 °C/minute to 160 °C
Method Log Entry # 3	Isothermal 1 minutes
Method Log Entry # 4	(Ramp 9899) Ramp 10 °C/minute to 30 °C
Cell Serial	DRC2-00792
[T1 Calibration]
Slope	-0.008529666
Offset	9.636258
Initial Temperature	98.23
GUID	f8bfdadc-4977-4fdf-ba6d-0ba9134940c3
[TZero Calibration]
Date Applied	11/29/2022 4:06:13 PM
Description	From -89.059 °C to 396.009 °C at 20.000°C/min
Gas Type	Nitrogen
Pan Type	None
Source Files 1	C:\Users\yargerlab\Desktop\DSC Data\General\TZero_calibration_11_29_22_2nd(2).tri
Source Files 2	C:\Users\yargerlab\Desktop\DSC Data\General\TZero_calibration_11_29_22_2nd(3).tri
Delta T Offset	13.05235
Delta T Slope	-0.007271007
Delta T0 Offset	-13.69128
Delta T0 Slope	0.06063341
[Temperature Calibration]
Date Applied	11/29/2022 7:12:28 PM
Description	From 106.590 °C to 186.590 °C at 10.000°C/min
Gas Type	Nitrogen
Pan Type	Tzero Aluminum Hermetic
Source Files 1	C:\Users\yargerlab\Desktop\DSC Data\General\Indium(6).tri
Measured 1	157.391
Known 1	156.598
[Cell Constant Calibration]
Date Applied	11/29/2022 7:12:29 PM
Description	From 106.590 °C to 186.590 °C at 10.000°C/min
Gas Type	Nitrogen
Pan Type	Tzero Aluminum Hermetic
Source Files 1	C:\Users\yargerlab\Desktop\DSC Data\General\Indium(6).tri
T4P KCell	1.006051
Onset Slope	63.26126 mW/°C
[Direct Cp Calibration]
Date Applied	11/30/2022 11:04:51 AM
Description	From -79.983 °C to 298.409 °C at 10.000°C/min
Gas Type	Nitrogen
Pan Type	Tzero Aluminum Hermetic
Source Files 1	C:\Users\yargerlab\Desktop\DSC Data\General\Sapphire_Heat_Capacity_11_30_22.tri
[Rev Cp Calibration]
Date Applied	11/30/2022 1:58:51 PM
Description	From -79.996 °C to 292.812 °C at 3.000°C/min
Gas Type	Nitrogen
Pan Type	Tzero Aluminum Hermetic
Source Files 1	C:\Users\yargerlab\Desktop\DSC Data\General\Sapphire_MDSC_Calibration_11_30_22.tri
[step]
Ramp 10.00 °C/min to 160.00 °C
Time	Temperature	Heat Flow (Normalized)
min	°C	W/g
0.00	30.05	-0.039
0.01	30.05	-0.040
0.02	30.05	-0.041
0.03	30.06	-0.041
0.04	30.06	-0.042
0.05	30.07	-0.043
0.06	30.08	-0.049
0.07	30.10	-0.059
0.08	30.12	-0.074
0.09	30.15	-0.093
0.10	30.19	-0.107
0.11	30.23	-0.111
0.12	30.28	-0.112
0.13	30.34	-0.110
0.14	30.40	-0.100
0.15	30.46	-0.048
0.16	30.53	-0.002
0.17	30.61	0.027
0.18	30.68	0.063
0.19	30.76	0.106
0.20	30.84	0.125
0.21	30.93	0.152
0.22	31.01	0.173
0.23	31.09	0.193
0.24	31.18	0.210
0.25	31.27	0.220
0.26	31.36	0.236
0.27	31.45	0.255
0.28	31.54	0.264
0.29	31.63	0.272
0.30	31.72	0.281
0.31	31.82	0.290
0.32	31.91	0.301
0.33	32.01	0.317
0.34	32.10	0.319
0.35	32.20	0.325
0.36	32.29	0.333
0.37	32.39	0.340
0.38	32.48	0.344
0.39	32.58	0.347
0.40	32.68	0.352
0.41	32.77	0.356
0.42	32.87	0.361
0.43	32.97	0.363
0.44	33.07	0.367
0.45	33.16	0.368
0.46	33.26	0.372
0.47	33.36	0.373
0.48	33.46	0.375
0.49	33.56	0.377
0.50	33.65	0.378
0.51	33.75	0.382
0.52	33.85	0.383
0.53	33.95	0.384
0.54	34.05	0.386
0.55	34.15	0.386
0.56	34.24	0.387
0.57	34.34	0.388
0.58	34.44	0.389
0.59	34.54	0.390
0.60	34.64	0.391
0.61	34.74	0.392
0.62	34.84	0.393
0.63	34.94	0.394
0.64	35.03	0.395
0.65	35.13	0.396
0.66	35.23	0.397
0.67	35.33	0.398
0.68	35.43	0.399
0.69	35.53	0.400
0.70	35.63	0.401
0.71	35.73	0.402
0.72	35.83	0.402
0.73	35.93	0.403
0.74	36.03	0.404
0.75	36.13	0.405
0.76	36.23	0.406
0.77	36.33	0.407
0.78	36.42	0.408
0.79	36.52	0.408
0.80	36.62	0.409
0.81	36.72	0.410
0.82	36.82	0.410
0.83	36.92	0.411
0.84	37.02	0.412
0.85	37.12	0.413
0.86	37.22	0.413
0.87	37.32	0.414
0.88	37.42	0.414
0.89	37.52	0.415
0.90	37.62	0.416
0.91	37.72	0.416
0.92	37.82	0.417
0.93	37.92	0.417
0.94	38.01	0.418
0.95	38.12	0.419
0.96	38.21	0.419
0.97	38.31	0.420
0.98	38.41	0.420
0.99	38.51	0.421
1.00	38.61	0.421
1.01	38.71	0.422
1.02	38.81	0.422
1.03	38.91	0.422
1.04	39.01	0.423
1.05	39.11	0.423
1.06	39.21	0.424
1.07	39.31	0.424
1.08	39.41	0.425
1.09	39.51	0.425
1.10	39.61	0.426
1.11	39.71	0.426
1.12	39.81	0.426
1.13	39.91	0.426
1.14	40.01	0.427
1.15	40.11	0.427
1.16	40.21	0.428
1.17	40.31	0.428
1.18	40.41	0.428
1.19	40.51	0.429
1.20	40.61	0.429
1.21	40.70	0.429
1.22	40.81	0.430
1.23	40.91	0.430
1.24	41.01	0.430
1.25	41.10	0.430
1.26	41.21	0.430
1.27	41.30	0.430
1.28	41.40	0.431
1.29	41.51	0.431
1.30	41.60	0.431
1.31	41.70	0.431
1.32	41.80	0.432
1.33	41.90	0.432
1.34	42.00	0.432
1.35	42.10	0.432
1.36	42.20	0.432
1.37	42.30	0.433
1.38	42.40	0.433
1.39	42.50	0.433
1.40	42.60	0.433
1.41	42.70	0.433
1.42	42.80	0.433
1.43	42.90	0.434
1.44	43.00	0.434
1.45	43.10	0.434
1.46	43.20	0.434
1.47	43.30	0.434
1.48	43.40	0.435
1.49	43.50	0.435
1.50	43.60	0.435
1.51	43.70	0.434
1.52	43.80	0.435
1.53	43.90	0.435
1.54	44.00	0.435
1.55	44.10	0.435
1.56	44.20	0.435
1.57	44.30	0.436
1.58	44.40	0.436
1.59	44.50	0.436
1.60	44.60	0.436
1.61	44.70	0.436
1.62	44.80	0.436
1.63	44.90	0.436
1.64	45.00	0.436
1.65	45.10	0.437
1.66	45.20	0.437
1.67	45.30	0.437
1.68	45.40	0.437
1.69	45.50	0.437
1.70	45.60	0.437
1.71	45.70	0.437
1.72	45.80	0.437
1.73	45.90	0.437
1.74	46.00	0.438
1.75	46.10	0.437
1.76	46.20	0.438
1.77	46.30	0.438
1.78	46.40	0.438
1.79	46.50	0.438
1.80	46.60	0.438
1.81	46.70	0.438
1.82	46.80	0.438
1.83	46.90	0.438
1.84	47.00	0.438
1.85	47.10	0.438
1.86	47.20	0.438
1.87	47.30	0.438
1.88	47.40	0.438
1.89	47.50	0.438
1.90	47.60	0.438
1.91	47.70	0.439
1.92	47.80	0.439
1.93	47.90	0.439
1.94	48.00	0.439
1.95	48.10	0.439
1.96	48.20	0.439
1.97	48.30	0.439
1.98	48.40	0.440
1.99	48.50	0.440
2.00	48.60	0.439
2.01	48.70	0.439
2.02	48.80	0.439
2.03	48.90	0.440
2.04	49.00	0.440
2.05	49.10	0.440
2.06	49.20	0.440
2.07	49.30	0.440
2.08	49.40	0.440
2.09	49.50	0.440
2.10	49.60	0.440
2.11	49.70	0.440
2.12	49.80	0.440
2.13	49.90	0.440
2.14	50.00	0.440
2.15	50.10	0.440
2.16	50.20	0.440
2.17	50.30	0.440
2.18	50.40	0.441
2.19	50.50	0.440
2.20	50.60	0.440
2.21	50.70	0.440
2.22	50.80	0.440
2.23	50.90	0.440
2.24	51.00	0.440
2.25	51.10	0.440
2.26	51.20	0.441
2.27	51.30	0.441
2.28	51.40	0.440
2.29	51.50	0.441
2.30	51.60	0.440
2.31	51.70	0.441
2.32	51.80	0.441
2.33	51.90	0.441
2.34	52.00	0.441
2.35	52.10	0.441
2.36	52.20	0.441
2.37	52.30	0.441
2.38	52.40	0.441
2.39	52.50	0.441
2.40	52.60	0.441
2.41	52.70	0.441
2.42	52.80	0.441
2.43	52.90	0.441
2.44	53.00	0.441
2.45	53.10	0.442
2.46	53.20	0.442
2.47	53.30	0.442
2.48	53.40	0.442
2.49	53.50	0.442
2.50	53.60	0.442
2.51	53.70	0.442
2.52	53.80	0.442
2.53	53.90	0.442
2.54	54.00	0.442
2.55	54.10	0.442
2.56	54.20	0.442
2.57	54.30	0.442
2.58	54.40	0.443
2.59	54.50	0.443
2.60	54.61	0.443
2.61	54.70	0.443
2.62	54.80	0.443
2.63	54.90	0.443
2.64	55.00	0.443
2.65	55.10	0.443
2.66	55.20	0.443
2.67	55.30	0.443
2.68	55.40	0.443
2.69	55.50	0.443
2.70	55.60	0.444
2.71	55.71	0.444
2.72	55.80	0.444
2.73	55.90	0.444
2.74	56.01	0.444
2.75	56.11	0.444
2.76	56.21	0.444
2.77	56.31	0.444
2.78	56.41	0.444
2.79	56.51	0.444
2.80	56.60	0.444
2.81	56.71	0.444
2.82	56.80	0.445
2.83	56.91	0.445
2.84	57.00	0.445
2.85	57.11	0.445
2.86	57.20	0.445
2.87	57.30	0.445
2.88	57.40	0.445
2.89	57.51	0.445
2.90	57.61	0.445
2.91	57.71	0.445
2.92	57.81	0.445
2.93	57.91	0.446
2.94	58.01	0.446
2.95	58.11	0.446
2.96	58.21	0.446
2.97	58.31	0.446
2.98	58.41	0.446
2.99	58.51	0.446
3.00	58.61	0.446
3.01	58.71	0.446
3.02	58.81	0.446
3.03	58.91	0.447
3.04	59.01	0.447
3.05	59.11	0.447
3.06	59.21	0.447
3.07	59.31	0.447
3.08	59.41	0.447
3.09	59.51	0.447
3.10	59.61	0.448
3.11	59.71	0.447
3.12	59.81	0.448
3.13	59.91	0.448
3.14	60.01	0.448
3.15	60.11	0.448
3.16	60.21	0.449
3.17	60.31	0.449
3.18	60.41	0.449
3.19	60.51	0.449
3.20	60.61	0.449
3.21	60.71	0.449
3.22	60.81	0.449
3.23	60.91	0.449
3.24	61.01	0.449
3.25	61.11	0.449
3.26	61.21	0.450
3.27	61.31	0.450
3.28	61.41	0.450
3.29	61.51	0.450
3.30	61.61	0.450
3.31	61.71	0.450
3.32	61.81	0.450
3.33	61.91	0.451
3.34	62.01	0.450
3.35	62.11	0.450
3.36	62.21	0.451
3.37	62.31	0.451
3.38	62.41	0.451
3.39	62.51	0.451
3.40	62.61	0.451
3.41	62.71	0.451
3.42	62.81	0.451
3.43	62.91	0.452
3.44	63.01	0.452
3.45	63.11	0.452
3.46	63.21	0.452
3.47	63.31	0.452
3.48	63.41	0.453
3.49	63.51	0.453
3.50	63.61	0.453
3.51	63.71	0.453
3.52	63.81	0.453
3.53	63.91	0.453
3.54	64.01	0.454
3.55	64.11	0.454
3.56	64.21	0.454
3.57	64.31	0.454
3.58	64.41	0.455
3.59	64.51	0.455
3.60	64.61	0.455
3.61	64.71	0.455
3.62	64.81	0.455
3.63	64.91	0.455
3.64	65.01	0.455
3.65	65.11	0.456
3.66	65.21	0.456
3.67	65.31	0.456
3.68	65.41	0.456
3.69	65.51	0.457
3.70	65.61	0.457
3.71	65.71	0.457
3.72	65.81	0.457
3.73	65.91	0.457
3.74	66.01	0.457
3.75	66.11	0.458
3.76	66.21	0.458
3.77	66.31	0.458
3.78	66.41	0.458
3.79	66.51	0.458
3.80	66.61	0.459
3.81	66.71	0.459
3.82	66.81	0.459
3.83	66.91	0.459
3.84	67.01	0.459
3.85	67.11	0.460
3.86	67.21	0.460
3.87	67.31	0.460
3.88	67.41	0.460
3.89	67.51	0.460
3.90	67.61	0.461
3.91	67.71	0.461
3.92	67.81	0.461
3.93	67.91	0.461
3.94	68.01	0.461
3.95	68.11	0.461
3.96	68.21	0.462
3.97	68.31	0.462
3.98	68.41	0.462
3.99	68.51	0.462
4.00	68.61	0.462
4.01	68.71	0.463
4.02	68.81	0.463
4.03	68.91	0.463
4.04	69.01	0.463
4.05	69.11	0.464
4.06	69.21	0.464
4.07	69.31	0.464
4.08	69.41	0.464
4.09	69.51	0.465
4.10	69.61	0.465
4.11	69.71	0.465
4.12	69.81	0.465
4.13	69.91	0.465
4.14	70.01	0.465
4.15	70.11	0.466
4.16	70.21	0.466
4.17	70.31	0.466
4.18	70.42	0.466
4.19	70.52	0.467
4.20	70.62	0.467
4.21	70.72	0.467
4.22	70.82	0.468
4.23	70.92	0.468
4.24	71.02	0.468
4.25	71.12	0.468
4.26	71.22	0.469
4.27	71.32	0.469
4.28	71.42	0.469
4.29	71.52	0.469
4.30	71.62	0.470
4.31	71.72	0.470
4.32	71.82	0.470
4.33	71.92	0.470
4.34	72.02	0.470
4.35	72.12	0.471
4.36	72.22	0.471
4.37	72.32	0.471
4.38	72.42	0.472
4.39	72.52	0.472
4.40	72.62	0.472
4.41	72.72	0.473
4.42	72.82	0.473
4.43	72.92	0.473
4.44	73.02	0.473
4.45	73.12	0.474
4.46	73.22	0.474
4.47	73.32	0.474
4.48	73.42	0.474
4.49	73.52	0.475
4.50	73.62	0.475
4.51	73.72	0.475
4.52	73.82	0.475
4.53	73.92	0.476
4.54	74.02	0.476
4.55	74.12	0.476
4.56	74.22	0.476
4.57	74.32	0.477
4.58	74.42	0.477
4.59	74.52	0.477
4.60	74.62	0.478
4.61	74.72	0.478
4.62	74.82	0.478
4.63	74.92	0.478
4.64	75.02	0.479
4.65	75.12	0.479
4.66	75.22	0.479
4.67	75.32	0.479
4.68	75.42	0.480
4.69	75.52	0.480
4.70	75.62	0.480
4.71	75.72	0.481
4.72	75.82	0.481
4.73	75.92	0.481
4.74	76.02	0.481
4.75	76.12	0.482
4.76	76.22	0.482
4.77	76.32	0.483
4.78	76.42	0.483
4.79	76.52	0.483
4.80	76.62	0.484
4.81	76.72	0.484
4.82	76.82	0.484
4.83	76.92	0.485
4.84	77.02	0.485
4.85	77.12	0.486
4.86	77.22	0.486
4.87	77.32	0.486
4.88	77.42	0.487
4.89	77.52	0.487
4.90	77.62	0.488
4.91	77.72	0.488
4.92	77.82	0.489
4.93	77.92	0.489
4.94	78.02	0.489
4.95	78.12	0.490
4.96	78.22	0.490
4.97	78.32	0.491
4.98	78.42	0.491
4.99	78.52	0.492
5.00	78.62	0.492
5.01	78.72	0.493
5.02	78.82	0.493
5.03	78.92	0.494
5.04	79.02	0.495
5.05	79.12	0.496
5.06	79.22	0.502
5.07	79.32	0.516
5.08	79.42	0.635
5.09	79.52	0.924
5.10	79.61	1.918
5.11	79.68	3.768
5.12	79.74	5.411
5.13	79.79	6.185
5.14	79.85	6.427
5.15	79.91	6.823
5.16	79.97	7.010
5.17	80.05	6.839
5.18	80.13	6.793
5.19	80.21	6.756
5.20	80.29	6.609
5.21	80.38	6.500
5.22	80.47	6.255
5.23	80.57	5.925
5.24	80.67	5.677
5.25	80.78	5.249
5.26	80.89	4.524
5.27	81.01	3.460
5.28	81.14	2.493
5.29	81.26	1.971
5.30	81.39	1.729
5.31	81.52	1.564
5.32	81.64	1.446
5.33	81.76	1.333
5.34	81.88	1.243
5.35	82.00	1.156
5.36	82.11	1.083
5.37	82.22	1.020
5.38	82.33	0.958
5.39	82.45	0.910
5.40	82.55	0.860
5.41	82.66	0.822
5.42	82.77	0.784
5.43	82.88	0.751
5.44	82.98	0.722
5.45	83.09	0.701
5.46	83.19	0.677
5.47	83.29	0.656
5.48	83.40	0.637
5.49	83.50	0.625
5.50	83.60	0.609
5.51	83.70	0.600
5.52	83.81	0.585
5.53	83.91	0.581
5.54	84.01	0.568
5.55	84.11	0.565
5.56	84.21	0.560
5.57	84.32	0.551
5.58	84.42	0.549
5.59	84.52	0.545
5.60	84.62	0.542
5.61	84.72	0.538
5.62	84.82	0.536
5.63	84.92	0.534
5.64	85.02	0.532
5.65	85.12	0.531
5.66	85.22	0.528
5.67	85.32	0.526
5.68	85.42	0.525
5.69	85.52	0.523
5.70	85.62	0.523
5.71	85.72	0.522
5.72	85.82	0.521
5.73	85.93	0.520
5.74	86.02	0.520
5.75	86.12	0.519
5.76	86.23	0.519
5.77	86.32	0.518
5.78	86.42	0.518
5.79	86.53	0.517
5.80	86.63	0.517
5.81	86.73	0.517
5.82	86.83	0.516
5.83	86.93	0.516
5.84	87.03	0.516
5.85	87.13	0.515
5.86	87.23	0.515
5.87	87.33	0.515
5.88	87.43	0.514
5.89	87.53	0.514
5.90	87.63	0.514
5.91	87.73	0.513
5.92	87.83	0.513
5.93	87.93	0.513
5.94	88.03	0.513
5.95	88.13	0.513
5.96	88.23	0.512
5.97	88.33	0.512
5.98	88.43	0.512
5.99	88.53	0.512
6.00	88.63	0.512
6.01	88.73	0.512
6.02	88.83	0.512
6.03	88.93	0.512
6.04	89.03	0.512
6.05	89.13	0.512
6.06	89.23	0.512
6.07	89.33	0.512
6.08	89.43	0.512
6.09	89.53	0.512
6.10	89.63	0.513
6.11	89.73	0.513
6.12	89.83	0.513
6.13	89.93	0.513
6.14	90.03	0.513
6.15	90.13	0.513
6.16	90.23	0.513
6.17	90.33	0.514
6.18	90.43	0.514
6.19	90.53	0.514
6.20	90.63	0.514
6.21	90.73	0.515
6.22	90.83	0.515
6.23	90.93	0.515
6.24	91.03	0.515
6.25	91.13	0.515
6.26	91.23	0.516
6.27	91.33	0.516
6.28	91.43	0.516
6.29	91.53	0.516
6.30	91.63	0.517
6.31	91.73	0.517
6.32	91.83	0.517
6.33	91.93	0.518
6.34	92.03	0.518
6.35	92.13	0.518
6.36	92.23	0.518
6.37	92.33	0.519
6.38	92.43	0.519
6.39	92.53	0.519
6.40	92.63	0.520
6.41	92.73	0.520
6.42	92.83	0.520
6.43	92.93	0.520
6.44	93.03	0.521
6.45	93.13	0.521
6.46	93.23	0.521
6.47	93.33	0.522
6.48	93.43	0.522
6.49	93.53	0.522
6.50	93.63	0.523
6.51	93.73	0.523
6.52	93.83	0.523
6.53	93.93	0.524
6.54	94.03	0.524
6.55	94.13	0.524
6.56	94.23	0.525
6.57	94.33	0.525
6.58	94.43	0.526
6.59	94.53	0.526
6.60	94.63	0.526
6.61	94.73	0.527
6.62	94.83	0.527
6.63	94.93	0.527
6.64	95.03	0.528
6.65	95.13	0.528
6.66	95.23	0.529
6.67	95.33	0.529
6.68	95.43	0.529
6.69	95.53	0.530
6.70	95.63	0.530
6.71	95.73	0.530
6.72	95.83	0.531
6.73	95.93	0.531
6.74	96.03	0.531
6.75	96.13	0.532
6.76	96.23	0.532
6.77	96.33	0.533
6.78	96.43	0.533
6.79	96.53	0.534
6.80	96.63	0.534
6.81	96.73	0.535
6.82	96.83	0.535
6.83	96.93	0.535
6.84	97.03	0.535
6.85	97.13	0.536
6.86	97.23	0.536
6.87	97.33	0.537
6.88	97.43	0.537
6.89	97.53	0.537
6.90	97.63	0.538
6.91	97.73	0.538
6.92	97.83	0.539
6.93	97.93	0.539
6.94	98.03	0.539
6.95	98.13	0.540
6.96	98.23	0.540
6.97	98.33	0.541
6.98	98.43	0.541
6.99	98.53	0.541
7.00	98.63	0.542
7.01	98.73	0.542
7.02	98.83	0.542
7.03	98.93	0.543
7.04	99.03	0.543
7.05	99.13	0.543
7.06	99.23	0.544
7.07	99.33	0.544
7.08	99.43	0.545
7.09	99.53	0.545
7.10	99.63	0.545
7.11	99.73	0.546
7.12	99.83	0.546
7.13	99.93	0.547
7.14	100.03	0.547
7.15	100.13	0.548
7.16	100.23	0.548
7.17	100.33	0.549
7.18	100.43	0.549
7.19	100.53	0.550
7.20	100.63	0.550
7.21	100.73	0.550
7.22	100.83	0.551
7.23	100.93	0.551
7.24	101.03	0.552
7.25	101.13	0.552
7.26	101.23	0.552
7.27	101.33	0.553
7.28	101.43	0.553
7.29	101.53	0.554
7.30	101.63	0.554
7.31	101.73	0.555
7.32	101.83	0.555
7.33	101.93	0.556
7.34	102.03	0.556
7.35	102.13	0.557
7.36	102.23	0.557
7.37	102.33	0.558
7.38	102.43	0.558
7.39	102.53	0.558
7.40	102.63	0.559
7.41	102.73	0.559
7.42	102.83	0.560
7.43	102.93	0.560
7.44	103.03	0.560
7.45	103.14	0.561
7.46	103.23	0.562
7.47	103.33	0.562
7.48	103.44	0.562
7.49	103.53	0.563
7.50	103.64	0.563
7.51	103.73	0.564
7.52	103.84	0.564
7.53	103.94	0.565
7.54	104.03	0.565
7.55	104.13	0.566
7.56	104.23	0.566
7.57	104.33	0.567
7.58	104.44	0.567
7.59	104.53	0.568
7.60	104.63	0.568
7.61	104.74	0.569
7.62	104.83	0.570
7.63	104.94	0.570
7.64	105.04	0.570
7.65	105.14	0.571
7.66	105.24	0.571
7.67	105.34	0.572
7.68	105.44	0.572
7.69	105.54	0.573
7.70	105.64	0.573
7.71	105.74	0.574
7.72	105.84	0.574
7.73	105.93	0.575
7.74	106.03	0.575
7.75	106.13	0.575
7.76	106.24	0.576
7.77	106.33	0.576
7.78	106.43	0.577
7.79	106.54	0.577
7.80	106.64	0.578
7.81	106.74	0.578
7.82	106.84	0.579
7.83	106.93	0.579
7.84	107.04	0.580
7.85	107.14	0.580
7.86	107.24	0.581
7.87	107.34	0.581
7.88	107.44	0.581
7.89	107.54	0.582
7.90	107.64	0.582
7.91	107.73	0.583
7.92	107.83	0.583
7.93	107.94	0.584
7.94	108.04	0.585
7.95	108.14	0.586
7.96	108.24	0.586
7.97	108.34	0.587
7.98	108.44	0.587
7.99	108.54	0.588
8.00	108.64	0.589
8.01	108.74	0.589
8.02	108.84	0.590
8.03	108.94	0.590
8.04	109.04	0.591
8.05	109.14	0.591
8.06	109.24	0.593
8.07	109.34	0.593
8.08	109.44	0.594
8.09	109.54	0.595
8.10	109.64	0.595
8.11	109.74	0.595
8.12	109.84	0.596
8.13	109.94	0.597
8.14	110.04	0.597
8.15	110.14	0.598
8.16	110.24	0.598
8.17	110.34	0.599
8.18	110.44	0.600
8.19	110.54	0.601
8.20	110.64	0.601
8.21	110.74	0.602
8.22	110.84	0.602
8.23	110.94	0.603
8.24	111.04	0.604
8.25	111.14	0.605
8.26	111.24	0.605
8.27	111.34	0.606
8.28	111.44	0.607
8.29	111.54	0.607
8.30	111.64	0.608
8.31	111.74	0.608
8.32	111.84	0.609
8.33	111.94	0.610
8.34	112.04	0.611
8.35	112.14	0.611
8.36	112.24	0.612
8.37	112.34	0.615
8.38	112.44	0.616
8.39	112.54	0.616
8.40	112.64	0.617
8.41	112.74	0.617
8.42	112.84	0.618
8.43	112.94	0.619
8.44	113.04	0.619
8.45	113.14	0.620
8.46	113.24	0.621
8.47	113.34	0.622
8.48	113.44	0.623
8.49	113.54	0.623
8.50	113.64	0.624
8.51	113.74	0.625
8.52	113.84	0.625
8.53	113.94	0.626
8.54	114.04	0.627
8.55	114.14	0.628
8.56	114.24	0.628
8.57	114.34	0.629
8.58	114.44	0.630
8.59	114.54	0.630
8.60	114.64	0.631
8.61	114.74	0.632
8.62	114.84	0.633
8.63	114.94	0.634
8.64	115.04	0.635
8.65	115.14	0.635
8.66	115.24	0.636
8.67	115.34	0.637
8.68	115.44	0.638
8.69	115.54	0.638
8.70	115.64	0.639
8.71	115.74	0.640
8.72	115.84	0.640
8.73	115.94	0.641
8.74	116.04	0.642
8.75	116.14	0.643
8.76	116.24	0.644
8.77	116.34	0.645
8.78	116.44	0.645
8.79	116.54	0.646
8.80	116.64	0.647
8.81	116.74	0.648
8.82	116.84	0.649
8.83	116.94	0.650
8.84	117.04	0.651
8.85	117.14	0.651
8.86	117.24	0.652
8.87	117.34	0.653
8.88	117.44	0.654
8.89	117.54	0.655
8.90	117.64	0.656
8.91	117.74	0.656
8.92	117.84	0.657
8.93	117.94	0.658
8.94	118.04	0.659
8.95	118.14	0.660
8.96	118.24	0.661
8.97	118.34	0.661
8.98	118.44	0.662
8.99	118.54	0.663
9.00	118.64	0.664
9.01	118.74	0.666
9.02	118.84	0.666
9.03	118.94	0.667
9.04	119.04	0.668
9.05	119.14	0.669
9.06	119.24	0.670
9.07	119.34	0.671
9.08	119.44	0.672
9.09	119.54	0.673
9.10	119.64	0.674
9.11	119.74	0.674
9.12	119.84	0.675
9.13	119.94	0.676
9.14	120.04	0.677
9.15	120.14	0.678
9.16	120.24	0.678
9.17	120.34	0.679
9.18	120.44	0.680
9.19	120.54	0.681
9.20	120.64	0.682
9.21	120.74	0.683
9.22	120.84	0.684
9.23	120.94	0.685
9.24	121.04	0.686
9.25	121.14	0.687
9.26	121.24	0.688
9.27	121.34	0.689
9.28	121.44	0.689
9.29	121.54	0.690
9.30	121.64	0.691
9.31	121.74	0.692
9.32	121.84	0.693
9.33	121.94	0.694
9.34	122.04	0.695
9.35	122.14	0.696
9.36	122.24	0.696
9.37	122.34	0.697
9.38	122.44	0.699
9.39	122.54	0.700
9.40	122.64	0.701
9.41	122.74	0.702
9.42	122.84	0.702
9.43	122.94	0.703
9.44	123.04	0.704
9.45	123.14	0.705
9.46	123.24	0.707
9.47	123.34	0.707
9.48	123.44	0.708
9.49	123.54	0.709
9.50	123.64	0.710
9.51	123.74	0.711
9.52	123.84	0.712
9.53	123.94	0.713
9.54	124.04	0.714
9.55	124.14	0.715
9.56	124.24	0.716
9.57	124.34	0.717
9.58	124.44	0.718
9.59	124.54	0.719
9.60	124.64	0.720
9.61	124.74	0.721
9.62	124.84	0.722
9.63	124.94	0.723
9.64	125.04	0.724
9.65	125.14	0.725
9.66	125.24	0.727
9.67	125.34	0.727
9.68	125.44	0.728
9.69	125.54	0.729
9.70	125.64	0.730
9.71	125.74	0.732
9.72	125.84	0.732
9.73	125.94	0.734
9.74	126.04	0.734
9.75	126.14	0.736
9.76	126.24	0.736
9.77	126.34	0.737
9.78	126.44	0.739
9.79	126.54	0.740
9.80	126.64	0.741
9.81	126.74	0.743
9.82	126.84	0.744
9.83	126.94	0.745
9.84	127.04	0.746
9.85	127.14	0.747
9.86	127.24	0.748
9.87	127.34	0.750
9.88	127.44	0.751
9.89	127.54	0.751
9.90	127.64	0.752
9.91	127.74	0.757
9.92	127.84	0.758
9.93	127.94	0.758
9.94	128.04	0.759
9.95	128.14	0.760
9.96	128.24	0.761
9.97	128.34	0.762
9.98	128.44	0.763
9.99	128.54	0.764
10.00	128.64	0.765
10.01	128.74	0.766
10.02	128.84	0.767
10.03	128.94	0.768
10.04	129.04	0.769
10.05	129.14	0.770
10.06	129.24	0.772
10.07	129.34	0.773
10.08	129.44	0.774
10.09	129.54	0.775
10.10	129.64	0.776
10.11	129.74	0.777
10.12	129.84	0.778
10.13	129.94	0.779
10.14	130.04	0.781
10.15	130.14	0.782
10.16	130.24	0.784
10.17	130.34	0.784
10.18	130.44	0.785
10.19	130.54	0.786
10.20	130.64	0.787
10.21	130.74	0.788
10.22	130.84	0.790
10.23	130.94	0.791
10.24	131.04	0.792
10.25	131.14	0.793
10.26	131.24	0.794
10.27	131.34	0.795
10.28	131.44	0.796
10.29	131.54	0.797
10.30	131.64	0.799
10.31	131.74	0.800
10.32	131.84	0.801
10.33	131.94	0.802
10.34	132.04	0.803
10.35	132.14	0.805
10.36	132.24	0.807
10.37	132.34	0.808
10.38	132.44	0.809
10.39	132.54	0.811
10.40	132.64	0.812
10.41	132.74	0.813
10.42	132.84	0.814
10.43	132.94	0.815
10.44	133.04	0.817
10.45	133.14	0.818
10.46	133.24	0.819
10.47	133.34	0.821
10.48	133.44	0.822
10.49	133.54	0.823
10.50	133.64	0.825
10.51	133.74	0.827
10.52	133.84	0.828
10.53	133.94	0.829
10.54	134.04	0.830
10.55	134.14	0.831
10.56	134.24	0.834
10.57	134.34	0.835
10.58	134.44	0.836
10.59	134.54	0.838
10.60	134.64	0.839
10.61	134.74	0.840
10.62	134.84	0.842
10.63	134.94	0.843
10.64	135.04	0.844
10.65	135.14	0.846
10.66	135.24	0.847
10.67	135.34	0.849
10.68	135.44	0.850
10.69	135.54	0.851
10.70	135.64	0.853
10.71	135.74	0.854
10.72	135.84	0.856
10.73	135.94	0.857
10.74	136.04	0.858
10.75	136.14	0.860
10.76	136.24	0.861
10.77	136.34	0.862
10.78	136.44	0.863
10.79	136.54	0.865
10.80	136.64	0.866
10.81	136.74	0.868
10.82	136.84	0.869
10.83	136.94	0.871
10.84	137.04	0.872
10.85	137.13	0.873
10.86	137.24	0.875
10.87	137.33	0.876
10.88	137.43	0.878
10.89	137.53	0.880
10.90	137.63	0.881
10.91	137.73	0.882
10.92	137.83	0.884
10.93	137.94	0.885
10.94	138.03	0.887
10.95	138.14	0.889
10.96	138.23	0.890
10.97	138.33	0.892
10.98	138.43	0.893
10.99	138.54	0.895
11.00	138.64	0.896
11.01	138.74	0.898
11.02	138.84	0.899
11.03	138.94	0.901
11.04	139.04	0.902
11.05	139.13	0.904
11.06	139.23	0.906
11.07	139.34	0.907
11.08	139.44	0.910
11.09	139.54	0.912
11.10	139.63	0.914
11.11	139.73	0.915
11.12	139.83	0.917
11.13	139.93	0.918
11.14	140.03	0.920
11.15	140.13	0.921
11.16	140.23	0.922
11.17	140.33	0.924
11.18	140.44	0.927
11.19	140.53	0.928
11.20	140.63	0.929
11.21	140.73	0.932
11.22	140.83	0.933
11.23	140.93	0.935
11.24	141.03	0.937
11.25	141.13	0.941
11.26	141.23	0.942
11.27	141.33	0.943
11.28	141.43	0.946
11.29	141.53	0.948
11.30	141.63	0.950
11.31	141.73	0.953
11.32	141.83	0.954
11.33	141.93	0.957
11.34	142.03	0.958
11.35	142.13	0.960
11.36	142.23	0.962
11.37	142.33	0.964
11.38	142.43	0.966
11.39	142.53	0.967
11.40	142.63	0.969
11.41	142.73	0.971
11.42	142.83	0.972
11.43	142.93	0.974
11.44	143.03	0.975
11.45	143.13	0.977
11.46	143.23	0.978
11.47	143.33	0.983
11.48	143.43	0.986
11.49	143.53	0.987
11.50	143.63	0.988
11.51	143.73	0.990
11.52	143.83	0.991
11.53	143.93	0.993
11.54	144.03	0.996
11.55	144.13	0.999
11.56	144.23	1.001
11.57	144.33	1.003
11.58	144.43	1.004
11.59	144.53	1.006
11.60	144.63	1.007
11.61	144.73	1.009
11.62	144.83	1.011
11.63	144.93	1.014
11.64	145.03	1.015
11.65	145.13	1.017
11.66	145.23	1.021
11.67	145.33	1.024
11.68	145.43	1.025
11.69	145.53	1.027
11.70	145.63	1.029
11.71	145.73	1.033
11.72	145.83	1.034
11.73	145.93	1.036
11.74	146.03	1.038
11.75	146.13	1.039
11.76	146.23	1.043
11.77	146.33	1.045
11.78	146.43	1.046
11.79	146.53	1.048
11.80	146.63	1.050
11.81	146.73	1.052
11.82	146.83	1.055
11.83	146.93	1.056
11.84	147.03	1.058
11.85	147.13	1.060
11.86	147.23	1.063
11.87	147.33	1.064
11.88	147.43	1.066
11.89	147.53	1.068
11.90	147.63	1.070
11.91	147.73	1.072
11.92	147.83	1.074
11.93	147.93	1.076
11.94	148.03	1.078
11.95	148.13	1.079
11.96	148.23	1.081
11.97	148.33	1.083
11.98	148.43	1.085
11.99	148.53	1.087
12.00	148.63	1.089
12.01	148.73	1.092
12.02	148.83	1.094
12.03	148.93	1.101
12.04	149.03	1.102
12.05	149.13	1.104
12.06	149.23	1.105
12.07	149.33	1.107
12.08	149.43	1.109
12.09	149.53	1.111
12.10	149.63	1.116
12.11	149.73	1.119
12.12	149.83	1.121
12.13	149.93	1.123
12.14	150.03	1.125
12.15	150.13	1.129
12.16	150.23	1.130
12.17	150.33	1.132
12.18	150.43	1.134
12.19	150.53	1.136
12.20	150.63	1.138
12.21	150.73	1.139
12.22	150.83	1.142
12.23	150.93	1.143
12.24	151.03	1.150
12.25	151.13	1.152
12.26	151.23	1.154
12.27	151.33	1.159
12.28	151.43	1.161
12.29	151.53	1.163
12.30	151.63	1.166
12.31	151.73	1.168
12.32	151.83	1.172
12.33	151.93	1.174
12.34	152.03	1.176
12.35	152.13	1.179
12.36	152.23	1.181
12.37	152.33	1.184
12.38	152.43	1.188
12.39	152.53	1.190
12.40	152.63	1.192
12.41	152.72	1.194
12.42	152.83	1.196
12.43	152.93	1.198
12.44	153.02	1.200
12.45	153.13	1.203
12.46	153.22	1.208
12.47	153.32	1.210
12.48	153.42	1.216
12.49	153.52	1.218
12.50	153.63	1.219
12.51	153.72	1.224
12.52	153.82	1.226
12.53	153.92	1.228
12.54	154.02	1.230
12.55	154.12	1.232
12.56	154.22	1.233
12.57	154.32	1.235
12.58	154.42	1.239
12.59	154.52	1.242
12.60	154.62	1.243
12.61	154.72	1.245
12.62	154.82	1.247
12.63	154.92	1.249
12.64	155.02	1.252
12.65	155.12	1.254
12.66	155.22	1.255
12.67	155.32	1.258
12.68	155.42	1.262
12.69	155.52	1.264
12.70	155.62	1.266
12.71	155.72	1.268
12.72	155.82	1.273
12.73	155.92	1.275
12.74	156.02	1.278
12.75	156.12	1.279
12.76	156.22	1.283
12.77	156.32	1.288
12.78	156.42	1.290
12.79	156.52	1.293
12.80	156.62	1.296
12.81	156.72	1.298
12.82	156.82	1.300
12.83	156.92	1.305
12.84	157.02	1.307
12.85	157.12	1.309
12.86	157.22	1.312
12.87	157.32	1.315
12.88	157.42	1.318
12.89	157.52	1.320
12.90	157.62	1.323
12.91	157.72	1.327
12.92	157.82	1.330
12.93	157.92	1.332
12.94	158.02	1.336
12.95	158.12	1.339
12.96	158.22	1.341
12.97	158.32	1.344
12.98	158.42	1.348
12.99	158.52	1.350
13.00	158.62	1.355

[step]
Ramp 10.00 °C/min to 30.00 °C
Time	Temperature	Heat Flow (Normalized)
min	°C	W/g
14.00	160.08	-0.072
14.01	160.08	-0.073
14.02	160.08	-0.074
14.03	160.08	-0.074
14.04	160.08	-0.075
14.05	160.07	-0.075
14.06	160.06	-0.075
14.07	160.05	-0.073
14.08	160.03	-0.067
14.09	160.00	-0.059
14.10	159.97	-0.054
14.11	159.92	-0.053
14.12	159.88	-0.054
14.13	159.82	-0.061
14.14	159.76	-0.096
14.15	159.70	-0.149
14.16	159.62	-0.187
14.17	159.55	-0.231
14.18	159.47	-0.258
14.19	159.40	-0.290
14.20	159.31	-0.314
14.21	159.23	-0.346
14.22	159.14	-0.360
14.23	159.06	-0.388
14.24	158.97	-0.403
14.25	158.88	-0.416
14.26	158.79	-0.428
14.27	158.70	-0.440
14.28	158.60	-0.453
14.29	158.51	-0.467
14.30	158.42	-0.471
14.31	158.33	-0.481
14.32	158.23	-0.488
14.33	158.14	-0.492
14.34	158.04	-0.499
14.35	157.95	-0.508
14.36	157.85	-0.511
14.37	157.75	-0.513
14.38	157.66	-0.520
14.39	157.56	-0.523
14.40	157.46	-0.526
14.41	157.37	-0.529
14.42	157.27	-0.533
14.43	157.17	-0.535
14.44	157.07	-0.538
14.45	156.98	-0.542
14.46	156.88	-0.543
14.47	156.78	-0.544
14.48	156.68	-0.546
14.49	156.59	-0.548
14.50	156.49	-0.549
14.51	156.39	-0.550
14.52	156.29	-0.551
14.53	156.19	-0.552
14.54	156.09	-0.553
14.55	156.00	-0.554
14.56	155.90	-0.555
14.57	155.80	-0.556
14.58	155.70	-0.558
14.59	155.60	-0.559
14.60	155.50	-0.560
14.61	155.41	-0.560
14.62	155.31	-0.562
14.63	155.21	-0.563
14.64	155.11	-0.564
14.65	155.01	-0.565
14.66	154.91	-0.566
14.67	154.81	-0.567
14.68	154.72	-0.568
14.69	154.62	-0.569
14.70	154.52	-0.570
14.71	154.42	-0.571
14.72	154.32	-0.572
14.73	154.22	-0.573
14.74	154.12	-0.574
14.75	154.02	-0.574
14.76	153.92	-0.576
14.77	153.83	-0.576
14.78	153.73	-0.577
14.79	153.63	-0.578
14.80	153.53	-0.579
14.81	153.43	-0.579
14.82	153.33	-0.580
14.83	153.23	-0.581
14.84	153.13	-0.581
14.85	153.03	-0.582
14.86	152.93	-0.583
14.87	152.83	-0.584
14.88	152.73	-0.585
14.89	152.63	-0.586
14.90	152.54	-0.586
14.91	152.44	-0.587
14.92	152.34	-0.588
14.93	152.24	-0.588
14.94	152.14	-0.588
14.95	152.04	-0.589
14.96	151.94	-0.590
14.97	151.84	-0.590
14.98	151.74	-0.591
14.99	151.64	-0.591
15.00	151.54	-0.591
15.01	151.44	-0.593
15.02	151.34	-0.593
15.03	151.24	-0.593
15.04	151.14	-0.594
15.05	151.04	-0.594
15.06	150.95	-0.595
15.07	150.85	-0.595
15.08	150.75	-0.596
15.09	150.65	-0.596
15.10	150.55	-0.596
15.11	150.45	-0.596
15.12	150.35	-0.597
15.13	150.25	-0.597
15.14	150.15	-0.597
15.15	150.05	-0.598
15.16	149.95	-0.598
15.17	149.85	-0.598
15.18	149.75	-0.599
15.19	149.65	-0.599
15.20	149.55	-0.599
15.21	149.45	-0.599
15.22	149.35	-0.599
15.23	149.25	-0.600
15.24	149.15	-0.600
15.25	149.05	-0.600
15.26	148.95	-0.601
15.27	148.85	-0.601
15.28	148.75	-0.601
15.29	148.65	-0.601
15.30	148.56	-0.601
15.31	148.46	-0.601
15.32	148.36	-0.601
15.33	148.26	-0.601
15.34	148.16	-0.602
15.35	148.06	-0.602
15.36	147.96	-0.602
15.37	147.86	-0.602
15.38	147.76	-0.602
15.39	147.66	-0.602
15.40	147.56	-0.602
15.41	147.46	-0.602
15.42	147.36	-0.602
15.43	147.26	-0.602
15.44	147.16	-0.603
15.45	147.06	-0.603
15.46	146.96	-0.603
15.47	146.86	-0.603
15.48	146.76	-0.603
15.49	146.66	-0.603
15.50	146.56	-0.603
15.51	146.46	-0.603
15.52	146.36	-0.603
15.53	146.26	-0.603
15.54	146.16	-0.603
15.55	146.06	-0.603
15.56	145.96	-0.603
15.57	145.86	-0.603
15.58	145.76	-0.603
15.59	145.66	-0.603
15.60	145.56	-0.603
15.61	145.46	-0.603
15.62	145.36	-0.603
15.63	145.26	-0.603
15.64	145.16	-0.603
15.65	145.06	-0.603
15.66	144.96	-0.603
15.67	144.86	-0.603
15.68	144.76	-0.603
15.69	144.66	-0.603
15.70	144.56	-0.603
15.71	144.46	-0.603
15.72	144.36	-0.603
15.73	144.26	-0.603
15.74	144.17	-0.603
15.75	144.07	-0.603
15.76	143.97	-0.603
15.77	143.87	-0.603
15.78	143.77	-0.603
15.79	143.67	-0.603
15.80	143.57	-0.603
15.81	143.47	-0.603
15.82	143.37	-0.603
15.83	143.27	-0.603
15.84	143.17	-0.603
15.85	143.07	-0.603
15.86	142.97	-0.602
15.87	142.87	-0.602
15.88	142.77	-0.602
15.89	142.67	-0.602
15.90	142.57	-0.602
15.91	142.47	-0.602
15.92	142.37	-0.602
15.93	142.27	-0.602
15.94	142.17	-0.602
15.95	142.07	-0.602
15.96	141.97	-0.602
15.97	141.87	-0.602
15.98	141.77	-0.602
15.99	141.67	-0.602
16.00	141.57	-0.602
16.01	141.47	-0.602
16.02	141.37	-0.602
16.03	141.27	-0.602
16.04	141.17	-0.602
16.05	141.07	-0.602
16.06	140.97	-0.602
16.07	140.87	-0.602
16.08	140.77	-0.602
16.09	140.67	-0.601
16.10	140.57	-0.602
16.11	140.47	-0.602
16.12	140.37	-0.601
16.13	140.27	-0.601
16.14	140.17	-0.601
16.15	140.07	-0.601
16.16	139.97	-0.601
16.17	139.87	-0.601
16.18	139.77	-0.601
16.19	139.67	-0.601
16.20	139.57	-0.601
16.21	139.47	-0.601
16.22	139.37	-0.601
16.23	139.27	-0.601
16.24	139.17	-0.601
16.25	139.07	-0.600
16.26	138.97	-0.600
16.27	138.87	-0.600
16.28	138.77	-0.600
16.29	138.67	-0.600
16.30	138.57	-0.600
16.31	138.47	-0.600
16.32	138.37	-0.600
16.33	138.27	-0.600
16.34	138.17	-0.599
16.35	138.07	-0.600
16.36	137.97	-0.600
16.37	137.87	-0.600
16.38	137.77	-0.600
16.39	137.67	-0.600
16.40	137.57	-0.600
16.41	137.47	-0.599
16.42	137.37	-0.599
16.43	137.27	-0.599
16.44	137.17	-0.599
16.45	137.07	-0.599
16.46	136.97	-0.599
16.47	136.88	-0.599
16.48	136.78	-0.599
16.49	136.68	-0.599
16.50	136.58	-0.599
16.51	136.48	-0.599
16.52	136.38	-0.599
16.53	136.28	-0.599
16.54	136.18	-0.599
16.55	136.08	-0.599
16.56	135.98	-0.599
16.57	135.88	-0.599
16.58	135.78	-0.599
16.59	135.68	-0.599
16.60	135.58	-0.599
16.61	135.48	-0.599
16.62	135.38	-0.599
16.63	135.28	-0.599
16.64	135.18	-0.599
16.65	135.08	-0.598
16.66	134.98	-0.599
16.67	134.88	-0.599
16.68	134.78	-0.599
16.69	134.68	-0.599
16.70	134.58	-0.598
16.71	134.48	-0.599
16.72	134.38	-0.598
16.73	134.28	-0.598
16.74	134.18	-0.598
16.75	134.08	-0.598
16.76	133.98	-0.598
16.77	133.88	-0.598
16.78	133.78	-0.598
16.79	133.68	-0.598
16.80	133.58	-0.598
16.81	133.48	-0.598
16.82	133.38	-0.598
16.83	133.28	-0.598
16.84	133.18	-0.598
16.85	133.08	-0.598
16.86	132.98	-0.598
16.87	132.88	-0.598
16.88	132.78	-0.598
16.89	132.68	-0.598
16.90	132.58	-0.598
16.91	132.48	-0.598
16.92	132.38	-0.598
16.93	132.28	-0.598
16.94	132.18	-0.597
16.95	132.08	-0.597
16.96	131.98	-0.597
16.97	131.88	-0.597
16.98	131.78	-0.597
16.99	131.68	-0.597
17.00	131.58	-0.598
17.01	131.48	-0.597
17.02	131.38	-0.597
17.03	131.28	-0.597
17.04	131.18	-0.597
17.05	131.08	-0.597
17.06	130.98	-0.597
17.07	130.88	-0.597
17.08	130.78	-0.597
17.09	130.68	-0.597
17.10	130.58	-0.597
17.11	130.48	-0.597
17.12	130.38	-0.597
17.13	130.28	-0.597
17.14	130.18	-0.597
17.15	130.08	-0.597
17.16	129.98	-0.597
17.17	129.88	-0.597
17.18	129.78	-0.597
17.19	129.68	-0.597
17.20	129.58	-0.597
17.21	129.48	-0.597
17.22	129.38	-0.597
17.23	129.28	-0.597
17.24	129.18	-0.597
17.25	129.08	-0.597
17.26	128.98	-0.597
17.27	128.88	-0.597
17.28	128.78	-0.597
17.29	128.68	-0.597
17.30	128.58	-0.597
17.31	128.48	-0.597
17.32	128.38	-0.597
17.33	128.28	-0.597
17.34	128.18	-0.597
17.35	128.08	-0.597
17.36	127.98	-0.597
17.37	127.88	-0.597
17.38	127.78	-0.597
17.39	127.69	-0.597
17.40	127.59	-0.597
17.41	127.49	-0.597
17.42	127.39	-0.597
17.43	127.29	-0.597
17.44	127.19	-0.597
17.45	127.09	-0.597
17.46	126.99	-0.597
17.47	126.89	-0.597
17.48	126.79	-0.597
17.49	126.69	-0.597
17.50	126.59	-0.597
17.51	126.49	-0.597
17.52	126.39	-0.597
17.53	126.29	-0.597
17.54	126.19	-0.597
17.55	126.09	-0.597
17.56	125.99	-0.597
17.57	125.89	-0.597
17.58	125.79	-0.596
17.59	125.69	-0.597
17.60	125.59	-0.597
17.61	125.49	-0.597
17.62	125.39	-0.597
17.63	125.29	-0.597
17.64	125.19	-0.597
17.65	125.09	-0.597
17.66	124.99	-0.597
17.67	124.89	-0.597
17.68	124.79	-0.597
17.69	124.69	-0.597
17.70	124.59	-0.597
17.71	124.49	-0.597
17.72	124.39	-0.597
17.73	124.29	-0.597
17.74	124.19	-0.597
17.75	124.09	-0.597
17.76	123.99	-0.597
17.77	123.89	-0.597
17.78	123.79	-0.597
17.79	123.69	-0.597
17.80	123.59	-0.597
17.81	123.49	-0.597
17.82	123.39	-0.597
17.83	123.29	-0.597
17.84	123.19	-0.597
17.85	123.09	-0.597
17.86	122.99	-0.597
17.87	122.89	-0.597
17.88	122.79	-0.597
17.89	122.69	-0.597
17.90	122.59	-0.597
17.91	122.49	-0.597
17.92	122.39	-0.597
17.93	122.29	-0.597
17.94	122.19	-0.597
17.95	122.09	-0.597
17.96	121.99	-0.596
17.97	121.89	-0.597
17.98	121.79	-0.597
17.99	121.69	-0.597
18.00	121.59	-0.597
18.01	121.49	-0.597
18.02	121.39	-0.596
18.03	121.29	-0.597
18.04	121.19	-0.597
18.05	121.09	-0.597
18.06	120.99	-0.597
18.07	120.89	-0.597
18.08	120.79	-0.597
18.09	120.69	-0.597
18.10	120.59	-0.597
18.11	120.49	-0.597
18.12	120.39	-0.597
18.13	120.29	-0.597
18.14	120.19	-0.597
18.15	120.09	-0.597
18.16	119.99	-0.597
18.17	119.89	-0.597
18.18	119.79	-0.597
18.19	119.69	-0.597
18.20	119.59	-0.597
18.21	119.49	-0.597
18.22	119.39	-0.597
18.23	119.29	-0.597
18.24	119.19	-0.597
18.25	119.09	-0.597
18.26	118.99	-0.597
18.27	118.89	-0.597
18.28	118.79	-0.597
18.29	118.69	-0.597
18.30	118.59	-0.597
18.31	118.49	-0.597
18.32	118.39	-0.597
18.33	118.29	-0.597
18.34	118.19	-0.597
18.35	118.09	-0.597
18.36	117.99	-0.597
18.37	117.89	-0.597
18.38	117.79	-0.597
18.39	117.69	-0.597
18.40	117.60	-0.598
18.41	117.49	-0.598
18.42	117.40	-0.598
18.43	117.30	-0.598
18.44	117.20	-0.598
18.45	117.10	-0.598
18.46	117.00	-0.598
18.47	116.90	-0.598
18.48	116.80	-0.598
18.49	116.70	-0.598
18.50	116.60	-0.598
18.51	116.50	-0.598
18.52	116.40	-0.598
18.53	116.30	-0.598
18.54	116.20	-0.598
18.55	116.10	-0.598
18.56	116.00	-0.598
18.57	115.90	-0.598
18.58	115.80	-0.598
18.59	115.70	-0.598
18.60	115.60	-0.598
18.61	115.50	-0.598
18.62	115.40	-0.598
18.63	115.30	-0.598
18.64	115.20	-0.598
18.65	115.10	-0.598
18.66	115.00	-0.598
18.67	114.90	-0.598
18.68	114.80	-0.598
18.69	114.70	-0.599
18.70	114.60	-0.599
18.71	114.50	-0.599
18.72	114.40	-0.599
18.73	114.30	-0.599
18.74	114.20	-0.599
18.75	114.10	-0.599
18.76	114.00	-0.599
18.77	113.90	-0.600
18.78	113.80	-0.599
18.79	113.70	-0.599
18.80	113.60	-0.599
18.81	113.50	-0.599
18.82	113.40	-0.600
18.83	113.30	-0.600
18.84	113.20	-0.600
18.85	113.10	-0.599
18.86	113.00	-0.600
18.87	112.90	-0.599
18.88	112.80	-0.599
18.89	112.70	-0.600
18.90	112.60	-0.600
18.91	112.50	-0.600
18.92	112.40	-0.600
18.93	112.30	-0.600
18.94	112.20	-0.600
18.95	112.10	-0.600
18.96	112.00	-0.600
18.97	111.90	-0.600
18.98	111.80	-0.599
18.99	111.70	-0.599
19.00	111.60	-0.600
19.01	111.50	-0.600
19.02	111.40	-0.600
19.03	111.30	-0.600
19.04	111.20	-0.600
19.05	111.10	-0.600
19.06	111.00	-0.600
19.07	110.90	-0.600
19.08	110.80	-0.600
19.09	110.70	-0.600
19.10	110.60	-0.600
19.11	110.50	-0.600
19.12	110.40	-0.600
19.13	110.30	-0.600
19.14	110.20	-0.600
19.15	110.10	-0.600
19.16	110.00	-0.600
19.17	109.90	-0.600
19.18	109.80	-0.600
19.19	109.70	-0.600
19.20	109.60	-0.600
19.21	109.50	-0.600
19.22	109.40	-0.600
19.23	109.30	-0.600
19.24	109.20	-0.600
19.25	109.10	-0.600
19.26	109.00	-0.600
19.27	108.90	-0.600
19.28	108.80	-0.600
19.29	108.71	-0.600
19.30	108.60	-0.601
19.31	108.50	-0.601
19.32	108.40	-0.601
19.33	108.31	-0.601
19.34	108.21	-0.601
19.35	108.11	-0.601
19.36	108.01	-0.601
19.37	107.91	-0.601
19.38	107.80	-0.600
19.39	107.71	-0.601
19.40	107.61	-0.601
19.41	107.51	-0.601
19.42	107.41	-0.601
19.43	107.31	-0.601
19.44	107.21	-0.601
19.45	107.11	-0.601
19.46	107.01	-0.601
19.47	106.91	-0.601
19.48	106.81	-0.601
19.49	106.71	-0.601
19.50	106.61	-0.601
19.51	106.51	-0.601
19.52	106.41	-0.601
19.53	106.31	-0.601
19.54	106.21	-0.601
19.55	106.11	-0.601
19.56	106.01	-0.601
19.57	105.91	-0.601
19.58	105.81	-0.601
19.59	105.71	-0.601
19.60	105.61	-0.601
19.61	105.51	-0.601
19.62	105.41	-0.601
19.63	105.31	-0.601
19.64	105.21	-0.601
19.65	105.11	-0.601
19.66	105.01	-0.601
19.67	104.91	-0.601
19.68	104.81	-0.601
19.69	104.71	-0.601
19.70	104.61	-0.601
19.71	104.51	-0.602
19.72	104.41	-0.601
19.73	104.31	-0.601
19.74	104.21	-0.601
19.75	104.11	-0.601
19.76	104.01	-0.601
19.77	103.91	-0.601
19.78	103.81	-0.601
19.79	103.71	-0.601
19.80	103.61	-0.601
19.81	103.51	-0.601
19.82	103.41	-0.601
19.83	103.31	-0.601
19.84	103.21	-0.601
19.85	103.11	-0.601
19.86	103.01	-0.601
19.87	102.91	-0.601
19.88	102.81	-0.601
19.89	102.71	-0.601
19.90	102.61	-0.601
19.91	102.51	-0.601
19.92	102.41	-0.601
19.93	102.31	-0.602
19.94	102.21	-0.602
19.95	102.11	-0.602
19.96	102.01	-0.601
19.97	101.91	-0.602
19.98	101.81	-0.602
19.99	101.71	-0.602
20.00	101.61	-0.601
20.01	101.51	-0.601
20.02	101.41	-0.601
20.03	101.31	-0.602
20.04	101.21	-0.602
20.05	101.11	-0.601
20.06	101.01	-0.602
20.07	100.91	-0.602
20.08	100.81	-0.602
20.09	100.71	-0.602
20.10	100.61	-0.602
20.11	100.51	-0.602
20.12	100.41	-0.602
20.13	100.31	-0.602
20.14	100.21	-0.602
20.15	100.11	-0.602
20.16	100.01	-0.602
20.17	99.91	-0.602
20.18	99.81	-0.602
20.19	99.71	-0.602
20.20	99.61	-0.602
20.21	99.51	-0.602
20.22	99.41	-0.602
20.23	99.31	-0.602
20.24	99.21	-0.602
20.25	99.11	-0.602
20.26	99.01	-0.602
20.27	98.91	-0.602
20.28	98.81	-0.602
20.29	98.71	-0.602
20.30	98.62	-0.602
20.31	98.51	-0.602
20.32	98.41	-0.602
20.33	98.32	-0.603
20.34	98.22	-0.602
20.35	98.12	-0.603
20.36	98.01	-0.603
20.37	97.91	-0.603
20.38	97.82	-0.603
20.39	97.72	-0.603
20.40	97.62	-0.602
20.41	97.52	-0.602
20.42	97.41	-0.603
20.43	97.32	-0.602
20.44	97.22	-0.602
20.45	97.12	-0.603
20.46	97.02	-0.603
20.47	96.92	-0.603
20.48	96.82	-0.603
20.49	96.72	-0.603
20.50	96.62	-0.602
20.51	96.52	-0.602
20.52	96.42	-0.603
20.53	96.32	-0.603
20.54	96.22	-0.602
20.55	96.12	-0.603
20.56	96.02	-0.603
20.57	95.92	-0.603
20.58	95.82	-0.603
20.59	95.72	-0.603
20.60	95.62	-0.603
20.61	95.52	-0.603
20.62	95.42	-0.603
20.63	95.32	-0.603
20.64	95.22	-0.603
20.65	95.12	-0.603
20.66	95.02	-0.603
20.67	94.92	-0.603
20.68	94.82	-0.603
20.69	94.72	-0.603
20.70	94.62	-0.603
20.71	94.52	-0.603
20.72	94.42	-0.603
20.73	94.32	-0.603
20.74	94.22	-0.603
20.75	94.12	-0.603
20.76	94.02	-0.603
20.77	93.92	-0.603
20.78	93.82	-0.603
20.79	93.72	-0.603
20.80	93.62	-0.603
20.81	93.52	-0.603
20.82	93.42	-0.603
20.83	93.32	-0.603
20.84	93.22	-0.603
20.85	93.12	-0.603
20.86	93.02	-0.603
20.87	92.92	-0.603
20.88	92.82	-0.603
20.89	92.72	-0.603
20.90	92.62	-0.603
20.91	92.52	-0.603
20.92	92.42	-0.603
20.93	92.32	-0.603
20.94	92.22	-0.603
20.95	92.12	-0.603
20.96	92.02	-0.603
20.97	91.92	-0.603
20.98	91.82	-0.603
20.99	91.72	-0.603
21.00	91.62	-0.603
21.01	91.52	-0.603
21.02	91.42	-0.603
21.03	91.32	-0.603
21.04	91.22	-0.603
21.05	91.12	-0.603
21.06	91.02	-0.603
21.07	90.92	-0.603
21.08	90.82	-0.603
21.09	90.72	-0.603
21.10	90.62	-0.603
21.11	90.52	-0.603
21.12	90.42	-0.602
21.13	90.32	-0.602
21.14	90.22	-0.602
21.15	90.12	-0.603
21.16	90.02	-0.603
21.17	89.92	-0.603
21.18	89.82	-0.602
21.19	89.72	-0.602
21.20	89.62	-0.602
21.21	89.52	-0.602
21.22	89.42	-0.602
21.23	89.32	-0.602
21.24	89.22	-0.602
21.25	89.12	-0.602
21.26	89.02	-0.602
21.27	88.92	-0.602
21.28	88.82	-0.602
21.29	88.72	-0.601
21.30	88.62	-0.601
21.31	88.52	-0.601
21.32	88.42	-0.601
21.33	88.33	-0.601
21.34	88.22	-0.601
21.35	88.13	-0.601
21.36	88.03	-0.601
21.37	87.93	-0.601
21.38	87.83	-0.601
21.39	87.72	-0.601
21.40	87.63	-0.601
21.41	87.53	-0.601
21.42	87.43	-0.601
21.43	87.33	-0.601
21.44	87.23	-0.601
21.45	87.13	-0.601
21.46	87.03	-0.601
21.47	86.93	-0.601
21.48	86.83	-0.601
21.49	86.73	-0.600
21.50	86.63	-0.600
21.51	86.53	-0.601
21.52	86.43	-0.601
21.53	86.33	-0.601
21.54	86.23	-0.601
21.55	86.13	-0.601
21.56	86.03	-0.601
21.57	85.93	-0.601
21.58	85.83	-0.601
21.59	85.73	-0.601
21.60	85.63	-0.600
21.61	85.53	-0.600
21.62	85.43	-0.600
21.63	85.33	-0.600
21.64	85.23	-0.600
21.65	85.13	-0.600
21.66	85.03	-0.600
21.67	84.93	-0.600
21.68	84.83	-0.601
21.69	84.73	-0.601
21.70	84.63	-0.601
21.71	84.53	-0.601
21.72	84.43	-0.600
21.73	84.33	-0.601
21.74	84.23	-0.601
21.75	84.13	-0.601
21.76	84.03	-0.601
21.77	83.93	-0.601
21.78	83.83	-0.601
21.79	83.73	-0.601
21.80	83.63	-0.601
21.81	83.53	-0.602
21.82	83.43	-0.602
21.83	83.33	-0.602
21.84	83.23	-0.602
21.85	83.13	-0.602
21.86	83.03	-0.602
21.87	82.93	-0.602
21.88	82.83	-0.602
21.89	82.73	-0.603
21.90	82.63	-0.603
21.91	82.53	-0.603
21.92	82.43	-0.602
21.93	82.33	-0.603
21.94	82.23	-0.603
21.95	82.13	-0.603
21.96	82.03	-0.603
21.97	81.93	-0.603
21.98	81.83	-0.603
21.99	81.73	-0.603
22.00	81.63	-0.604
22.01	81.53	-0.604
22.02	81.43	-0.604
22.03	81.33	-0.604
22.04	81.23	-0.604
22.05	81.13	-0.604
22.06	81.03	-0.604
22.07	80.93	-0.604
22.08	80.83	-0.604
22.09	80.73	-0.605
22.10	80.63	-0.605
22.11	80.53	-0.605
22.12	80.43	-0.605
22.13	80.33	-0.605
22.14	80.23	-0.605
22.15	80.13	-0.605
22.16	80.03	-0.605
22.17	79.93	-0.605
22.18	79.83	-0.606
22.19	79.73	-0.606
22.20	79.63	-0.606
22.21	79.53	-0.606
22.22	79.43	-0.606
22.23	79.33	-0.606
22.24	79.23	-0.606
22.25	79.13	-0.606
22.26	79.03	-0.606
22.27	78.93	-0.607
22.28	78.83	-0.607
22.29	78.73	-0.607
22.30	78.63	-0.607
22.31	78.53	-0.607
22.32	78.43	-0.607
22.33	78.33	-0.607
22.34	78.24	-0.607
22.35	78.14	-0.607
22.36	78.03	-0.608
22.37	77.94	-0.608
22.38	77.83	-0.608
22.39	77.74	-0.608
22.40	77.64	-0.608
22.41	77.54	-0.608
22.42	77.44	-0.608
22.43	77.34	-0.608
22.44	77.24	-0.608
22.45	77.14	-0.608
22.46	77.04	-0.608
22.47	76.94	-0.608
22.48	76.84	-0.608
22.49	76.74	-0.609
22.50	76.64	-0.609
22.51	76.54	-0.609
22.52	76.44	-0.609
22.53	76.34	-0.609
22.54	76.24	-0.608
22.55	76.14	-0.609
22.56	76.04	-0.608
22.57	75.94	-0.609
22.58	75.84	-0.609
22.59	75.74	-0.609
22.60	75.64	-0.609
22.61	75.54	-0.609
22.62	75.44	-0.609
22.63	75.34	-0.609
22.64	75.24	-0.609
22.65	75.14	-0.609
22.66	75.04	-0.610
22.67	74.94	-0.610
22.68	74.84	-0.610
22.69	74.74	-0.610
22.70	74.64	-0.610
22.71	74.54	-0.610
22.72	74.44	-0.610
22.73	74.34	-0.610
22.74	74.24	-0.610
22.75	74.14	-0.609
22.76	74.04	-0.610
22.77	73.94	-0.610
22.78	73.84	-0.610
22.79	73.74	-0.610
22.80	73.64	-0.610
22.81	73.54	-0.610
22.82	73.44	-0.610
22.83	73.34	-0.610
22.84	73.24	-0.610
22.85	73.14	-0.610
22.86	73.04	-0.610
22.87	72.94	-0.610
22.88	72.84	-0.610
22.89	72.74	-0.610
22.90	72.64	-0.610
22.91	72.54	-0.610
22.92	72.44	-0.610
22.93	72.34	-0.610
22.94	72.24	-0.610
22.95	72.14	-0.610
22.96	72.04	-0.610
22.97	71.94	-0.610
22.98	71.84	-0.610
22.99	71.74	-0.610
23.00	71.64	-0.610
23.01	71.54	-0.610
23.02	71.44	-0.610
23.03	71.34	-0.610
23.04	71.24	-0.610
23.05	71.14	-0.610
23.06	71.04	-0.610
23.07	70.94	-0.610
23.08	70.84	-0.610
23.09	70.74	-0.610
23.10	70.64	-0.610
23.11	70.54	-0.610
23.12	70.44	-0.610
23.13	70.34	-0.610
23.14	70.24	-0.610
23.15	70.14	-0.610
23.16	70.04	-0.610
23.17	69.94	-0.610
23.18	69.84	-0.610
23.19	69.74	-0.610
23.20	69.64	-0.610
23.21	69.54	-0.610
23.22	69.44	-0.610
23.23	69.34	-0.610
23.24	69.24	-0.610
23.25	69.14	-0.610
23.26	69.04	-0.610
23.27	68.94	-0.610
23.28	68.84	-0.610
23.29	68.74	-0.610
23.30	68.64	-0.610
23.31	68.55	-0.610
23.32	68.45	-0.610
23.33	68.35	-0.609
23.34	68.25	-0.609
23.35	68.15	-0.609
23.36	68.04	-0.609
23.37	67.94	-0.609
23.38	67.84	-0.609
23.39	67.74	-0.609
23.40	67.65	-0.609
23.41	67.55	-0.609
23.42	67.45	-0.609
23.43	67.35	-0.609
23.44	67.25	-0.609
23.45	67.15	-0.610
23.46	67.05	-0.610
23.47	66.95	-0.609
23.48	66.85	-0.609
23.49	66.75	-0.609
23.50	66.65	-0.609
23.51	66.55	-0.609
23.52	66.45	-0.609
23.53	66.35	-0.609
23.54	66.25	-0.609
23.55	66.15	-0.609
23.56	66.05	-0.609
23.57	65.95	-0.609
23.58	65.85	-0.609
23.59	65.75	-0.609
23.60	65.65	-0.609
23.61	65.55	-0.610
23.62	65.45	-0.610
23.63	65.35	-0.610
23.64	65.25	-0.610
23.65	65.15	-0.610
23.66	65.05	-0.610
23.67	64.95	-0.610
23.68	64.85	-0.609
23.69	64.75	-0.610
23.70	64.65	-0.610
23.71	64.55	-0.610
23.72	64.45	-0.610
23.73	64.35	-0.610
23.74	64.25	-0.610
23.75	64.15	-0.609
23.76	64.05	-0.610
23.77	63.95	-0.610
23.78	63.85	-0.609
23.79	63.75	-0.609
23.80	63.65	-0.609
23.81	63.55	-0.609
23.82	63.45	-0.609
23.83	63.35	-0.609
23.84	63.25	-0.610
23.85	63.15	-0.610
23.86	63.05	-0.609
23.87	62.95	-0.609
23.88	62.85	-0.610
23.89	62.75	-0.610
23.90	62.65	-0.610
23.91	62.55	-0.609
23.92	62.45	-0.609
23.93	62.35	-0.610
23.94	62.25	-0.610
23.95	62.15	-0.610
23.96	62.05	-0.610
23.97	61.95	-0.610
23.98	61.85	-0.610
23.99	61.75	-0.610
24.00	61.65	-0.609
24.01	61.55	-0.610
24.02	61.45	-0.610
24.03	61.35	-0.610
24.04	61.25	-0.610
24.05	61.15	-0.610
24.06	61.05	-0.610
24.07	60.95	-0.610
24.08	60.85	-0.610
24.09	60.75	-0.610
24.10	60.65	-0.610
24.11	60.55	-0.610
24.12	60.45	-0.610
24.13	60.35	-0.610
24.14	60.25	-0.610
24.15	60.15	-0.610
24.16	60.05	-0.610
24.17	59.95	-0.610
24.18	59.85	-0.610
24.19	59.75	-0.610
24.20	59.65	-0.610
24.21	59.55	-0.610
24.22	59.45	-0.610
24.23	59.35	-0.610
24.24	59.25	-0.610
24.25	59.15	-0.610
24.26	59.05	-0.610
24.27	58.95	-0.610
24.28	58.85	-0.610
24.29	58.75	-0.610
24.30	58.65	-0.610
24.31	58.55	-0.610
24.32	58.45	-0.610
24.33	58.35	-0.610
24.34	58.25	-0.610
24.35	58.15	-0.611
24.36	58.05	-0.611
24.37	57.95	-0.611
24.38	57.85	-0.610
24.39	57.75	-0.610
24.40	57.65	-0.610
24.41	57.55	-0.610
24.42	57.46	-0.610
24.43	57.36	-0.610
24.44	57.25	-0.610
24.45	57.15	-0.610
24.46	57.05	-0.610
24.47	56.95	-0.610
24.48	56.85	-0.610
24.49	56.75	-0.610
24.50	56.66	-0.610
24.51	56.56	-0.610
24.52	56.46	-0.610
24.53	56.36	-0.610
24.54	56.26	-0.610
24.55	56.16	-0.610
24.56	56.06	-0.610
24.57	55.96	-0.609
24.58	55.86	-0.609
24.59	55.76	-0.609
24.60	55.66	-0.609
24.61	55.56	-0.609
24.62	55.46	-0.609
24.63	55.36	-0.609
24.64	55.26	-0.610
24.65	55.16	-0.609
24.66	55.06	-0.609
24.67	54.96	-0.609
24.68	54.86	-0.610
24.69	54.76	-0.610
24.70	54.66	-0.610
24.71	54.56	-0.610
24.72	54.46	-0.610
24.73	54.36	-0.610
24.74	54.26	-0.610
24.75	54.16	-0.610
24.76	54.06	-0.610
24.77	53.96	-0.610
24.78	53.86	-0.609
24.79	53.76	-0.610
24.80	53.66	-0.610
24.81	53.56	-0.609
24.82	53.46	-0.610
24.83	53.36	-0.609
24.84	53.26	-0.609
24.85	53.16	-0.609
24.86	53.06	-0.609
24.87	52.96	-0.609
24.88	52.86	-0.609
24.89	52.76	-0.609
24.90	52.66	-0.609
24.91	52.56	-0.609
24.92	52.46	-0.609
24.93	52.36	-0.609
24.94	52.26	-0.609
24.95	52.16	-0.609
24.96	52.06	-0.610
24.97	51.96	-0.610
24.98	51.86	-0.610
24.99	51.76	-0.609
25.00	51.66	-0.610
25.01	51.56	-0.610
25.02	51.46	-0.609
25.03	51.36	-0.609
25.04	51.26	-0.609
25.05	51.16	-0.609
25.06	51.06	-0.609
25.07	50.96	-0.609
25.08	50.86	-0.610
25.09	50.76	-0.610
25.10	50.66	-0.609
25.11	50.56	-0.609
25.12	50.46	-0.609
25.13	50.36	-0.609
25.14	50.26	-0.610
25.15	50.16	-0.609
25.16	50.06	-0.609
25.17	49.96	-0.609
25.18	49.86	-0.609
25.19	49.76	-0.609
25.20	49.66	-0.609
25.21	49.56	-0.609
25.22	49.46	-0.609
25.23	49.36	-0.609
25.24	49.26	-0.609
25.25	49.16	-0.609
25.26	49.06	-0.609
25.27	48.96	-0.609
25.28	48.86	-0.609
25.29	48.76	-0.609
25.30	48.66	-0.609
25.31	48.56	-0.609
25.32	48.46	-0.609
25.33	48.36	-0.609
25.34	48.26	-0.609
25.35	48.16	-0.609
25.36	48.06	-0.609
25.37	47.96	-0.609
25.38	47.86	-0.609
25.39	47.76	-0.609
25.40	47.66	-0.609
25.41	47.56	-0.609
25.42	47.46	-0.609
25.43	47.37	-0.609
25.44	47.26	-0.609
25.45	47.16	-0.609
25.46	47.07	-0.609
25.47	46.96	-0.609
25.48	46.86	-0.609
25.49	46.76	-0.608
25.50	46.67	-0.609
25.51	46.57	-0.608
25.52	46.46	-0.609
25.53	46.36	-0.609
25.54	46.27	-0.608
25.55	46.16	-0.608
25.56	46.07	-0.608
25.57	45.97	-0.608
25.58	45.87	-0.608
25.59	45.77	-0.608
25.60	45.67	-0.608
25.61	45.57	-0.608
25.62	45.47	-0.608
25.63	45.37	-0.608
25.64	45.27	-0.608
25.65	45.17	-0.608
25.66	45.07	-0.608
25.67	44.97	-0.608
25.68	44.87	-0.608
25.69	44.77	-0.608
25.70	44.67	-0.608
25.71	44.57	-0.608
25.72	44.47	-0.608
25.73	44.37	-0.608
25.74	44.27	-0.608
25.75	44.17	-0.608
25.76	44.07	-0.608
25.77	43.97	-0.608
25.78	43.87	-0.608
25.79	43.77	-0.607
25.80	43.67	-0.608
25.81	43.57	-0.608
25.82	43.47	-0.608
25.83	43.37	-0.608
25.84	43.27	-0.608
25.85	43.17	-0.608
25.86	43.07	-0.608
25.87	42.97	-0.607
25.88	42.87	-0.608
25.89	42.77	-0.608
25.90	42.67	-0.607
25.91	42.57	-0.607
25.92	42.47	-0.608
25.93	42.37	-0.607
25.94	42.27	-0.608
25.95	42.17	-0.607
25.96	42.07	-0.607
25.97	41.97	-0.607
25.98	41.87	-0.607
25.99	41.77	-0.607
26.00	41.67	-0.607
26.01	41.57	-0.607
26.02	41.47	-0.607
26.03	41.37	-0.607
26.04	41.27	-0.607
26.05	41.17	-0.607
26.06	41.07	-0.607
26.07	40.97	-0.607
26.08	40.87	-0.607
26.09	40.77	-0.607
26.10	40.67	-0.607
26.11	40.57	-0.607
26.12	40.47	-0.607
26.13	40.37	-0.607
26.14	40.27	-0.607
26.15	40.17	-0.607
26.16	40.07	-0.607
26.17	39.97	-0.607
26.18	39.87	-0.607
26.19	39.77	-0.607
26.20	39.67	-0.607
26.21	39.57	-0.607
26.22	39.47	-0.606
26.23	39.37	-0.606
26.24	39.27	-0.606
26.25	39.17	-0.606
26.26	39.07	-0.606
26.27	38.97	-0.606
26.28	38.87	-0.606
26.29	38.77	-0.606
26.30	38.67	-0.606
26.31	38.57	-0.606
26.32	38.47	-0.606
26.33	38.37	-0.606
26.34	38.27	-0.606
26.35	38.17	-0.606
26.36	38.08	-0.606
26.37	37.97	-0.606
26.38	37.87	-0.606
26.39	37.77	-0.606
26.40	37.67	-0.606
26.41	37.58	-0.606
26.42	37.47	-0.606
26.43	37.37	-0.606
26.44	37.27	-0.606
26.45	37.18	-0.606
26.46	37.07	-0.606
26.47	36.97	-0.606
26.48	36.88	-0.606
26.49	36.77	-0.606
26.50	36.67	-0.606
26.51	36.58	-0.606
26.52	36.48	-0.605
26.53	36.37	-0.606
26.54	36.28	-0.606
26.55	36.18	-0.605
26.56	36.08	-0.605
26.57	35.98	-0.605
26.58	35.88	-0.605
26.59	35.78	-0.605
26.60	35.68	-0.605
26.61	35.58	-0.605
26.62	35.48	-0.605
26.63	35.38	-0.605
26.64	35.28	-0.605
26.65	35.18	-0.605
26.66	35.08	-0.605
26.67	34.98	-0.605
26.68	34.88	-0.606
26.69	34.78	-0.606
26.70	34.68	-0.605
26.71	34.58	-0.605
26.72	34.48	-0.605
26.73	34.38	-0.605
26.74	34.28	-0.605
26.75	34.18	-0.605
26.76	34.08	-0.605
26.77	33.98	-0.605
26.78	33.88	-0.605
26.79	33.78	-0.605
26.80	33.68	-0.605
26.81	33.58	-0.605
26.82	33.48	-0.605
26.83	33.38	-0.605
26.84	33.28	-0.605
26.85	33.18	-0.605
26.86	33.08	-0.605
26.87	32.98	-0.605
26.88	32.88	-0.604
26.89	32.78	-0.605
26.90	32.68	-0.604
26.91	32.58	-0.604
26.92	32.48	-0.604
26.93	32.38	-0.604
26.94	32.28	-0.605
26.95	32.18
26.96	32.08
26.97	31.98
26.98	31.88
26.99	31.78
27.00