File: Data/2024_09_17_Empty_Pans_CHM343_DSC_Baseline_n40C_210C.txt
Filename	2024_09_17_Empty_Pans_CHM343_DSC_Baseline_n40C_210C
Instrument name	DSC2A-00468 (192.168.1.100)
Operator	CHM343
rundate	9/17/2024
Sample name	2024_09_17_Empty_Pans_CHM343_DSC_Baseline_n40C_210C
proceduresegments	Equilibrate -40.00 °C; Ramp 10.00 °C/min to 210.00 °C; Isothermal 1.0 min; Ramp 10.00 °C/min to -40.00 °C; Isothermal 1.0 min; Ramp 10.00 °C/min to 210.00 °C
[File Parameters]
Run date	9/17/2024 6:08:39 PM
Trios version	5.1.1.46572
Original File Name	C:\ProgramData\TA Instruments\TRIOS\Data\2024_09_17_Empty_Pans_CHM343_DSC_Baseline_n40C_210C.tri
Current File Name	D:\DSC2500\CHM343\2024_09_17_Empty_Pans_CHM343_DSC_Baseline_n40C_210C.tri
[Procedure]
Procedure Name	CHM343_Fall2024_Empty
Sample Name	2024_09_17_Empty_Pans_CHM343_DSC_Baseline_n40C_210C
Sample Mass	0 mg
Reference Sample Mass	0 mg
Pan Mass	54.56 mg
Pan Number	24
Reference Pan Mass	54 mg
Reference Pan Number	19
Pan Type	Aluminum
Comments	Empty Al Hermetic Sealed Pan, with ref Al pan.- Baseline
Project Name	Lab 4 - Fall 2024
Operator	CHM343
Test	Custom
Unload Max Temperature	30
Unload Min Temperature	30
Load Max Temperature	30
Load Min Temperature	30
Stop on Gas Flow Error	Yes
[Signal List]
Signal #1	Time (min)
Signal #2	Temperature (°C)
Signal #3	Heat Flow (mW)
Signal #4	Delta T (µV)
Signal #5	Delta Tzero (µV)
Signal #6	Tzero Temperature (°C)
Signal #7	Cell Purge (mL/min)
Signal #8	Heater Temp (°C)
Signal #9	Power Delivered (W)
Signal #10	Reference Junction Temperature (°C)
Signal #11	Flange Temperature (°C)
Signal #12	Heat Flow Phase (rad)
Signal #13	Total Heat Capacity (J/°C)
Signal #14	Heat Capacity (J/°C)
[Configuration]
Company Name	ASU
Instrument Name	DSC2A-00468
Instrument Type	DSC2500
Serial Number	DSC2A-00468
IP	192.168.1.100
Location of Instrument	MRRC
DisplayType	Unknown
Sample Interval 	0.1 s/pt
Selected Heat Flow	T4P
Exotherm Direction	Down
Cell Serial	DRC2-00792
Lid Type	Standard
Cooler	RCS 90
Leave Cooler on at End of Sequence	On
Gas 2	Nitrogen
Gas Selected	Channel 1
Flow Rate	50 mL/min
Secondary Purge	On
Licensed Heat Flow	Heat Flow T4P
Modulation Licensed	Yes
[Versions]
Common IDD Version	1
Cortex Version	VER 2.10.2.31
Driver	5.0.0.6
GDM Version	1.0.3.3
TouchscreenVersion	1.0.0.16145
FEP Version	1.2.1.21
FEP Bootloader	2.0.0.5
AutoSampler Version	2.1.1.26
Auto Sampler Bootloader	2.0.0.5
FCM Version	1.1.0.3
FCM Bootloader	2.0.0.5
[Experiment Logs]
Experiment Log Entry # 1	Equilibrate Segment -40 (C) Started
Experiment Log Entry # 3	Ramp Segment 10 C/min to 210 Started
Experiment Log Entry # 5	Isothermal Segment 1 min started
Experiment Log Entry # 7	Ramp Segment 10 C/min to -40 Started
Experiment Log Entry # 9	Isothermal Segment 1 min started
Experiment Log Entry # 11	Ramp Segment 10 C/min to 210 Started
[Method Log]
Method Log Entry # 1	Equilibrate -40 °C
Method Log Entry # 2	(Ramp 40691) Ramp 10 °C/minute to 210 °C
Method Log Entry # 3	Isothermal 1 minutes
Method Log Entry # 4	(Ramp 40693) Ramp 10 °C/minute to -40 °C
Method Log Entry # 5	Isothermal 1 minutes
Method Log Entry # 6	(Ramp 40695) Ramp 10 °C/minute to 210 °C
Cell Serial	DRC2-00792
[T1 Calibration]
Slope	-0.008529666
Offset	9.636258
Initial Temperature	98.23
GUID	f8bfdadc-4977-4fdf-ba6d-0ba9134940c3
[TZero Calibration]
Date Applied	11/29/2022 4:06:13 PM
Description	From -89.059 °C to 396.009 °C at 20.000°C/min
Gas Type	Nitrogen
Pan Type	None
Source Files 1	C:\Users\yargerlab\Desktop\DSC Data\General\TZero_calibration_11_29_22_2nd(2).tri
Source Files 2	C:\Users\yargerlab\Desktop\DSC Data\General\TZero_calibration_11_29_22_2nd(3).tri
Delta T Offset	13.05235
Delta T Slope	-0.007271007
Delta T0 Offset	-13.69128
Delta T0 Slope	0.06063341
[Temperature Calibration]
Date Applied	11/29/2022 7:12:28 PM
Description	From 106.590 °C to 186.590 °C at 10.000°C/min
Gas Type	Nitrogen
Pan Type	Tzero Aluminum Hermetic
Source Files 1	C:\Users\yargerlab\Desktop\DSC Data\General\Indium(6).tri
Measured 1	157.391
Known 1	156.598
[Cell Constant Calibration]
Date Applied	11/29/2022 7:12:29 PM
Description	From 106.590 °C to 186.590 °C at 10.000°C/min
Gas Type	Nitrogen
Pan Type	Tzero Aluminum Hermetic
Source Files 1	C:\Users\yargerlab\Desktop\DSC Data\General\Indium(6).tri
T4P KCell	1.006051
Onset Slope	63.26126 mW/°C
[Direct Cp Calibration]
Date Applied	11/30/2022 11:04:51 AM
Description	From -79.983 °C to 298.409 °C at 10.000°C/min
Gas Type	Nitrogen
Pan Type	Tzero Aluminum Hermetic
Source Files 1	C:\Users\yargerlab\Desktop\DSC Data\General\Sapphire_Heat_Capacity_11_30_22.tri
[Rev Cp Calibration]
Date Applied	11/30/2022 1:58:51 PM
Description	From -79.996 °C to 292.812 °C at 3.000°C/min
Gas Type	Nitrogen
Pan Type	Tzero Aluminum Hermetic
Source Files 1	C:\Users\yargerlab\Desktop\DSC Data\General\Sapphire_MDSC_Calibration_11_30_22.tri
[step]
Ramp 10.00 °C/min to 210.00 °C
Time	Temperature	Heat Flow (Normalized)
min	°C	W/g
0.00	-39.68
0.02	-39.69
0.03	-39.69
0.05	-39.70
0.07	-39.69
0.08	-39.66
0.10	-39.62
0.12	-39.56
0.13	-39.48
0.15	-39.38
0.17	-39.28
0.18	-39.16
0.20	-39.04
0.22	-38.90
0.23	-38.77
0.25	-38.63
0.27	-38.49
0.28	-38.34
0.30	-38.20
0.32	-38.05
0.33	-37.90
0.35	-37.74
0.37	-37.59
0.38	-37.43
0.40	-37.28
0.42	-37.12
0.43	-36.96
0.45	-36.80
0.47	-36.64
0.48	-36.48
0.50	-36.32
0.52	-36.16
0.53	-36.00
0.55	-35.84
0.57	-35.68
0.58	-35.51
0.60	-35.35
0.62	-35.19
0.63	-35.03
0.65	-34.87
0.67	-34.70
0.68	-34.54
0.70	-34.37
0.72	-34.21
0.73	-34.05
0.75	-33.88
0.77	-33.72
0.78	-33.56
0.80	-33.39
0.82	-33.23
0.83	-33.06
0.85	-32.90
0.87	-32.73
0.88	-32.57
0.90	-32.41
0.92	-32.24
0.93	-32.07
0.95	-31.91
0.97	-31.75
0.98	-31.58
1.00	-31.41
1.02	-31.25
1.03	-31.08
1.05	-30.92
1.07	-30.75
1.08	-30.59
1.10	-30.42
1.12	-30.26
1.13	-30.09
1.15	-29.93
1.17	-29.76
1.18	-29.60
1.20	-29.43
1.22	-29.26
1.23	-29.10
1.25	-28.93
1.27	-28.77
1.28	-28.60
1.30	-28.43
1.32	-28.27
1.33	-28.10
1.35	-27.94
1.37	-27.77
1.38	-27.60
1.40	-27.44
1.42	-27.27
1.43	-27.11
1.45	-26.94
1.47	-26.77
1.48	-26.61
1.50	-26.44
1.52	-26.28
1.53	-26.11
1.55	-25.94
1.57	-25.78
1.58	-25.61
1.60	-25.44
1.62	-25.28
1.63	-25.11
1.65	-24.94
1.67	-24.78
1.68	-24.61
1.70	-24.44
1.72	-24.28
1.73	-24.11
1.75	-23.94
1.77	-23.78
1.78	-23.61
1.80	-23.44
1.82	-23.28
1.83	-23.11
1.85	-22.95
1.87	-22.78
1.88	-22.61
1.90	-22.45
1.92	-22.28
1.93	-22.11
1.95	-21.95
1.97	-21.78
1.98	-21.61
2.00	-21.45
2.02	-21.28
2.03	-21.11
2.05	-20.95
2.07	-20.78
2.08	-20.61
2.10	-20.45
2.12	-20.28
2.13	-20.11
2.15	-19.95
2.17	-19.78
2.18	-19.61
2.20	-19.45
2.22	-19.28
2.23	-19.11
2.25	-18.95
2.27	-18.78
2.28	-18.61
2.30	-18.44
2.32	-18.28
2.33	-18.11
2.35	-17.94
2.37	-17.78
2.38	-17.61
2.40	-17.44
2.42	-17.28
2.43	-17.11
2.45	-16.94
2.47	-16.78
2.48	-16.61
2.50	-16.44
2.52	-16.28
2.53	-16.11
2.55	-15.94
2.57	-15.78
2.58	-15.61
2.60	-15.44
2.62	-15.28
2.63	-15.11
2.65	-14.94
2.67	-14.78
2.68	-14.61
2.70	-14.44
2.72	-14.28
2.73	-14.11
2.75	-13.94
2.77	-13.77
2.78	-13.61
2.80	-13.44
2.82	-13.28
2.83	-13.11
2.85	-12.94
2.87	-12.77
2.88	-12.61
2.90	-12.44
2.92	-12.27
2.93	-12.11
2.95	-11.94
2.97	-11.77
2.98	-11.61
3.00	-11.44
3.02	-11.27
3.03	-11.11
3.05	-10.94
3.07	-10.77
3.08	-10.61
3.10	-10.44
3.12	-10.27
3.13	-10.11
3.15	-9.94
3.17	-9.77
3.18	-9.61
3.20	-9.44
3.22	-9.27
3.23	-9.10
3.25	-8.94
3.27	-8.77
3.28	-8.60
3.30	-8.44
3.32	-8.27
3.33	-8.10
3.35	-7.94
3.37	-7.77
3.38	-7.60
3.40	-7.44
3.42	-7.27
3.43	-7.11
3.45	-6.94
3.47	-6.77
3.48	-6.60
3.50	-6.44
3.52	-6.27
3.53	-6.10
3.55	-5.93
3.57	-5.77
3.58	-5.60
3.60	-5.44
3.62	-5.27
3.63	-5.10
3.65	-4.93
3.67	-4.77
3.68	-4.60
3.70	-4.43
3.72	-4.27
3.73	-4.10
3.75	-3.93
3.77	-3.77
3.78	-3.60
3.80	-3.43
3.82	-3.27
3.83	-3.10
3.85	-2.93
3.87	-2.77
3.88	-2.60
3.90	-2.43
3.92	-2.26
3.93	-2.10
3.95	-1.93
3.97	-1.76
3.98	-1.60
4.00	-1.43
4.02	-1.26
4.03	-1.10
4.05	-0.93
4.07	-0.76
4.08	-0.60
4.10	-0.43
4.12	-0.26
4.13	-0.10
4.15	0.07
4.17	0.24
4.18	0.40
4.20	0.57
4.22	0.74
4.23	0.91
4.25	1.07
4.27	1.24
4.28	1.41
4.30	1.57
4.32	1.74
4.33	1.91
4.35	2.07
4.37	2.24
4.38	2.41
4.40	2.57
4.42	2.74
4.43	2.91
4.45	3.07
4.47	3.24
4.48	3.41
4.50	3.57
4.52	3.74
4.53	3.91
4.55	4.07
4.57	4.24
4.58	4.41
4.60	4.58
4.62	4.74
4.63	4.91
4.65	5.07
4.67	5.24
4.68	5.41
4.70	5.58
4.72	5.74
4.73	5.91
4.75	6.08
4.77	6.24
4.78	6.41
4.80	6.58
4.82	6.74
4.83	6.91
4.85	7.08
4.87	7.24
4.88	7.41
4.90	7.58
4.92	7.75
4.93	7.91
4.95	8.08
4.97	8.25
4.98	8.41
5.00	8.58
5.02	8.75
5.03	8.91
5.05	9.08
5.07	9.24
5.08	9.41
5.10	9.58
5.12	9.75
5.13	9.91
5.15	10.08
5.17	10.25
5.18	10.41
5.20	10.58
5.22	10.75
5.23	10.91
5.25	11.08
5.27	11.25
5.28	11.41
5.30	11.58
5.32	11.75
5.33	11.91
5.35	12.08
5.37	12.25
5.38	12.42
5.40	12.58
5.42	12.75
5.43	12.91
5.45	13.08
5.47	13.25
5.48	13.42
5.50	13.58
5.52	13.75
5.53	13.92
5.55	14.08
5.57	14.25
5.58	14.42
5.60	14.58
5.62	14.75
5.63	14.92
5.65	15.08
5.67	15.25
5.68	15.42
5.70	15.58
5.72	15.75
5.73	15.92
5.75	16.09
5.77	16.25
5.78	16.42
5.80	16.58
5.82	16.75
5.83	16.92
5.85	17.09
5.87	17.25
5.88	17.42
5.90	17.59
5.92	17.75
5.93	17.92
5.95	18.09
5.97	18.25
5.98	18.42
6.00	18.59
6.02	18.75
6.03	18.92
6.05	19.09
6.07	19.26
6.08	19.42
6.10	19.59
6.12	19.76
6.13	19.92
6.15	20.09
6.17	20.26
6.18	20.42
6.20	20.59
6.22	20.76
6.23	20.92
6.25	21.09
6.27	21.26
6.28	21.42
6.30	21.59
6.32	21.76
6.33	21.92
6.35	22.09
6.37	22.26
6.38	22.42
6.40	22.59
6.42	22.76
6.43	22.93
6.45	23.09
6.47	23.26
6.48	23.43
6.50	23.59
6.52	23.76
6.53	23.93
6.55	24.09
6.57	24.26
6.58	24.43
6.60	24.59
6.62	24.76
6.63	24.93
6.65	25.09
6.67	25.26
6.68	25.43
6.70	25.59
6.72	25.76
6.73	25.93
6.75	26.10
6.77	26.26
6.78	26.43
6.80	26.60
6.82	26.76
6.83	26.93
6.85	27.10
6.87	27.26
6.88	27.43
6.90	27.60
6.92	27.76
6.93	27.93
6.95	28.10
6.97	28.26
6.98	28.43
7.00	28.60
7.02	28.76
7.03	28.93
7.05	29.10
7.07	29.26
7.08	29.43
7.10	29.60
7.12	29.76
7.13	29.93
7.15	30.10
7.17	30.27
7.18	30.43
7.20	30.60
7.22	30.76
7.23	30.93
7.25	31.10
7.27	31.27
7.28	31.43
7.30	31.60
7.32	31.77
7.33	31.93
7.35	32.10
7.37	32.27
7.38	32.43
7.40	32.60
7.42	32.77
7.43	32.93
7.45	33.10
7.47	33.27
7.48	33.43
7.50	33.60
7.52	33.77
7.53	33.94
7.55	34.10
7.57	34.27
7.58	34.44
7.60	34.60
7.62	34.77
7.63	34.94
7.65	35.10
7.67	35.27
7.68	35.44
7.70	35.60
7.72	35.77
7.73	35.94
7.75	36.10
7.77	36.27
7.78	36.44
7.80	36.60
7.82	36.77
7.83	36.94
7.85	37.10
7.87	37.27
7.88	37.44
7.90	37.61
7.92	37.77
7.93	37.94
7.95	38.11
7.97	38.27
7.98	38.44
8.00	38.61
8.02	38.77
8.03	38.94
8.05	39.11
8.07	39.27
8.08	39.44
8.10	39.61
8.12	39.77
8.13	39.94
8.15	40.11
8.17	40.27
8.18	40.44
8.20	40.61
8.22	40.77
8.23	40.94
8.25	41.11
8.27	41.27
8.28	41.44
8.30	41.61
8.32	41.78
8.33	41.94
8.35	42.11
8.37	42.28
8.38	42.44
8.40	42.61
8.42	42.78
8.43	42.94
8.45	43.11
8.47	43.28
8.48	43.44
8.50	43.61
8.52	43.78
8.53	43.94
8.55	44.11
8.57	44.28
8.58	44.44
8.60	44.61
8.62	44.78
8.63	44.94
8.65	45.11
8.67	45.28
8.68	45.44
8.70	45.61
8.72	45.78
8.73	45.94
8.75	46.11
8.77	46.28
8.78	46.45
8.80	46.61
8.82	46.78
8.83	46.95
8.85	47.11
8.87	47.28
8.88	47.45
8.90	47.61
8.92	47.78
8.93	47.95
8.95	48.11
8.97	48.28
8.98	48.45
9.00	48.61
9.02	48.78
9.03	48.95
9.05	49.12
9.07	49.28
9.08	49.45
9.10	49.62
9.12	49.78
9.13	49.95
9.15	50.12
9.17	50.28
9.18	50.45
9.20	50.62
9.22	50.78
9.23	50.95
9.25	51.12
9.27	51.28
9.28	51.45
9.30	51.62
9.32	51.78
9.33	51.95
9.35	52.12
9.37	52.28
9.38	52.45
9.40	52.62
9.42	52.78
9.43	52.95
9.45	53.12
9.47	53.29
9.48	53.45
9.50	53.62
9.52	53.79
9.53	53.95
9.55	54.12
9.57	54.29
9.58	54.45
9.60	54.62
9.62	54.79
9.63	54.95
9.65	55.12
9.67	55.29
9.68	55.45
9.70	55.62
9.72	55.79
9.73	55.95
9.75	56.12
9.77	56.29
9.78	56.45
9.80	56.62
9.82	56.79
9.83	56.95
9.85	57.12
9.87	57.29
9.88	57.45
9.90	57.62
9.92	57.79
9.93	57.95
9.95	58.12
9.97	58.29
9.98	58.46
10.00	58.62
10.02	58.79
10.03	58.96
10.05	59.12
10.07	59.29
10.08	59.46
10.10	59.62
10.12	59.79
10.13	59.96
10.15	60.12
10.17	60.29
10.18	60.46
10.20	60.62
10.22	60.79
10.23	60.96
10.25	61.13
10.27	61.29
10.28	61.46
10.30	61.63
10.32	61.79
10.33	61.96
10.35	62.13
10.37	62.29
10.38	62.46
10.40	62.63
10.42	62.79
10.43	62.96
10.45	63.13
10.47	63.29
10.48	63.46
10.50	63.63
10.52	63.79
10.53	63.96
10.55	64.13
10.57	64.29
10.58	64.46
10.60	64.63
10.62	64.79
10.63	64.96
10.65	65.13
10.67	65.29
10.68	65.46
10.70	65.63
10.72	65.80
10.73	65.96
10.75	66.13
10.77	66.30
10.78	66.46
10.80	66.63
10.82	66.80
10.83	66.96
10.85	67.13
10.87	67.30
10.88	67.46
10.90	67.63
10.92	67.80
10.93	67.96
10.95	68.13
10.97	68.30
10.98	68.47
11.00	68.63
11.02	68.80
11.03	68.96
11.05	69.13
11.07	69.30
11.08	69.47
11.10	69.63
11.12	69.80
11.13	69.96
11.15	70.13
11.17	70.30
11.18	70.47
11.20	70.63
11.22	70.80
11.23	70.97
11.25	71.13
11.27	71.30
11.28	71.47
11.30	71.63
11.32	71.80
11.33	71.97
11.35	72.13
11.37	72.30
11.38	72.47
11.40	72.63
11.42	72.80
11.43	72.97
11.45	73.14
11.47	73.30
11.48	73.47
11.50	73.63
11.52	73.80
11.53	73.97
11.55	74.14
11.57	74.30
11.58	74.47
11.60	74.64
11.62	74.80
11.63	74.97
11.65	75.14
11.67	75.30
11.68	75.47
11.70	75.64
11.72	75.80
11.73	75.97
11.75	76.14
11.77	76.30
11.78	76.47
11.80	76.64
11.82	76.81
11.83	76.97
11.85	77.14
11.87	77.31
11.88	77.47
11.90	77.64
11.92	77.81
11.93	77.97
11.95	78.14
11.97	78.31
11.98	78.47
12.00	78.64
12.02	78.81
12.03	78.97
12.05	79.14
12.07	79.31
12.08	79.47
12.10	79.64
12.12	79.81
12.13	79.97
12.15	80.14
12.17	80.31
12.18	80.48
12.20	80.64
12.22	80.81
12.23	80.98
12.25	81.14
12.27	81.31
12.28	81.48
12.30	81.64
12.32	81.81
12.33	81.98
12.35	82.14
12.37	82.31
12.38	82.48
12.40	82.64
12.42	82.81
12.43	82.98
12.45	83.15
12.47	83.31
12.48	83.48
12.50	83.64
12.52	83.81
12.53	83.98
12.55	84.14
12.57	84.31
12.58	84.48
12.60	84.65
12.62	84.81
12.63	84.98
12.65	85.15
12.67	85.31
12.68	85.48
12.70	85.65
12.72	85.81
12.73	85.98
12.75	86.15
12.77	86.31
12.78	86.48
12.80	86.65
12.82	86.81
12.83	86.98
12.85	87.15
12.87	87.31
12.88	87.48
12.90	87.65
12.92	87.82
12.93	87.98
12.95	88.15
12.97	88.31
12.98	88.48
13.00	88.65
13.02	88.81
13.03	88.98
13.05	89.15
13.07	89.31
13.08	89.48
13.10	89.65
13.12	89.82
13.13	89.98
13.15	90.15
13.17	90.32
13.18	90.48
13.20	90.65
13.22	90.82
13.23	90.98
13.25	91.15
13.27	91.32
13.28	91.48
13.30	91.65
13.32	91.82
13.33	91.98
13.35	92.15
13.37	92.32
13.38	92.48
13.40	92.65
13.42	92.82
13.43	92.98
13.45	93.15
13.47	93.32
13.48	93.49
13.50	93.65
13.52	93.82
13.53	93.99
13.55	94.15
13.57	94.32
13.58	94.49
13.60	94.65
13.62	94.82
13.63	94.99
13.65	95.15
13.67	95.32
13.68	95.49
13.70	95.65
13.72	95.82
13.73	95.99
13.75	96.15
13.77	96.32
13.78	96.49
13.80	96.65
13.82	96.82
13.83	96.99
13.85	97.15
13.87	97.32
13.88	97.49
13.90	97.66
13.92	97.82
13.93	97.99
13.95	98.16
13.97	98.32
13.98	98.49
14.00	98.65
14.02	98.82
14.03	98.99
14.05	99.16
14.07	99.32
14.08	99.49
14.10	99.66
14.12	99.82
14.13	99.99
14.15	100.16
14.17	100.32
14.18	100.49
14.20	100.66
14.22	100.82
14.23	100.99
14.25	101.16
14.27	101.32
14.28	101.49
14.30	101.66
14.32	101.82
14.33	101.99
14.35	102.16
14.37	102.32
14.38	102.49
14.40	102.66
14.42	102.82
14.43	102.99
14.45	103.16
14.47	103.33
14.48	103.49
14.50	103.66
14.52	103.83
14.53	103.99
14.55	104.16
14.57	104.33
14.58	104.49
14.60	104.66
14.62	104.83
14.63	104.99
14.65	105.16
14.67	105.33
14.68	105.49
14.70	105.66
14.72	105.83
14.73	105.99
14.75	106.16
14.77	106.33
14.78	106.49
14.80	106.66
14.82	106.83
14.83	106.99
14.85	107.16
14.87	107.33
14.88	107.49
14.90	107.66
14.92	107.83
14.93	107.99
14.95	108.16
14.97	108.33
14.98	108.50
15.00	108.66
15.02	108.83
15.03	109.00
15.05	109.16
15.07	109.33
15.08	109.50
15.10	109.66
15.12	109.83
15.13	110.00
15.15	110.17
15.17	110.33
15.18	110.50
15.20	110.66
15.22	110.83
15.23	111.00
15.25	111.16
15.27	111.33
15.28	111.50
15.30	111.66
15.32	111.83
15.33	112.00
15.35	112.16
15.37	112.33
15.38	112.50
15.40	112.67
15.42	112.83
15.43	113.00
15.45	113.16
15.47	113.33
15.48	113.50
15.50	113.66
15.52	113.83
15.53	114.00
15.55	114.17
15.57	114.33
15.58	114.50
15.60	114.67
15.62	114.83
15.63	115.00
15.65	115.17
15.67	115.33
15.68	115.50
15.70	115.67
15.72	115.83
15.73	116.00
15.75	116.17
15.77	116.33
15.78	116.50
15.80	116.67
15.82	116.83
15.83	117.00
15.85	117.17
15.87	117.34
15.88	117.50
15.90	117.67
15.92	117.83
15.93	118.00
15.95	118.17
15.97	118.33
15.98	118.50
16.00	118.67
16.02	118.83
16.03	119.00
16.05	119.17
16.07	119.34
16.08	119.50
16.10	119.67
16.12	119.84
16.13	120.00
16.15	120.17
16.17	120.34
16.18	120.50
16.20	120.67
16.22	120.84
16.23	121.00
16.25	121.17
16.27	121.34
16.28	121.50
16.30	121.67
16.32	121.84
16.33	122.00
16.35	122.17
16.37	122.34
16.38	122.50
16.40	122.67
16.42	122.84
16.43	123.00
16.45	123.17
16.47	123.34
16.48	123.50
16.50	123.67
16.52	123.84
16.53	124.00
16.55	124.17
16.57	124.34
16.58	124.50
16.60	124.67
16.62	124.84
16.63	125.01
16.65	125.17
16.67	125.34
16.68	125.51
16.70	125.67
16.72	125.84
16.73	126.01
16.75	126.17
16.77	126.34
16.78	126.51
16.80	126.67
16.82	126.84
16.83	127.01
16.85	127.17
16.87	127.34
16.88	127.51
16.90	127.67
16.92	127.84
16.93	128.01
16.95	128.17
16.97	128.34
16.98	128.51
17.00	128.67
17.02	128.84
17.03	129.01
17.05	129.17
17.07	129.34
17.08	129.51
17.10	129.67
17.12	129.84
17.13	130.01
17.15	130.18
17.17	130.34
17.18	130.51
17.20	130.68
17.22	130.84
17.23	131.01
17.25	131.18
17.27	131.34
17.28	131.51
17.30	131.68
17.32	131.84
17.33	132.01
17.35	132.18
17.37	132.34
17.38	132.51
17.40	132.68
17.42	132.84
17.43	133.01
17.45	133.18
17.47	133.34
17.48	133.51
17.50	133.68
17.52	133.84
17.53	134.01
17.55	134.18
17.57	134.34
17.58	134.51
17.60	134.68
17.62	134.84
17.63	135.01
17.65	135.18
17.67	135.34
17.68	135.51
17.70	135.68
17.72	135.84
17.73	136.01
17.75	136.18
17.77	136.34
17.78	136.51
17.80	136.68
17.82	136.85
17.83	137.01
17.85	137.18
17.87	137.35
17.88	137.51
17.90	137.68
17.92	137.84
17.93	138.01
17.95	138.18
17.97	138.35
17.98	138.51
18.00	138.68
18.02	138.85
18.03	139.01
18.05	139.18
18.07	139.35
18.08	139.51
18.10	139.68
18.12	139.85
18.13	140.01
18.15	140.18
18.17	140.35
18.18	140.51
18.20	140.68
18.22	140.85
18.23	141.01
18.25	141.18
18.27	141.35
18.28	141.51
18.30	141.68
18.32	141.85
18.33	142.01
18.35	142.18
18.37	142.35
18.38	142.52
18.40	142.68
18.42	142.85
18.43	143.02
18.45	143.18
18.47	143.35
18.48	143.52
18.50	143.68
18.52	143.85
18.53	144.02
18.55	144.18
18.57	144.35
18.58	144.52
18.60	144.68
18.62	144.85
18.63	145.02
18.65	145.18
18.67	145.35
18.68	145.52
18.70	145.68
18.72	145.85
18.73	146.02
18.75	146.18
18.77	146.35
18.78	146.52
18.80	146.68
18.82	146.85
18.83	147.02
18.85	147.18
18.87	147.35
18.88	147.52
18.90	147.69
18.92	147.85
18.93	148.02
18.95	148.19
18.97	148.35
18.98	148.52
19.00	148.69
19.02	148.85
19.03	149.02
19.05	149.19
19.07	149.35
19.08	149.52
19.10	149.69
19.12	149.85
19.13	150.02
19.15	150.18
19.17	150.35
19.18	150.52
19.20	150.68
19.22	150.85
19.23	151.02
19.25	151.19
19.27	151.35
19.28	151.52
19.30	151.69
19.32	151.85
19.33	152.02
19.35	152.19
19.37	152.35
19.38	152.52
19.40	152.69
19.42	152.85
19.43	153.02
19.45	153.19
19.47	153.35
19.48	153.52
19.50	153.69
19.52	153.85
19.53	154.02
19.55	154.19
19.57	154.35
19.58	154.52
19.60	154.69
19.62	154.85
19.63	155.02
19.65	155.19
19.67	155.35
19.68	155.52
19.70	155.69
19.72	155.85
19.73	156.02
19.75	156.19
19.77	156.36
19.78	156.52
19.80	156.69
19.82	156.86
19.83	157.02
19.85	157.19
19.87	157.36
19.88	157.52
19.90	157.69
19.92	157.86
19.93	158.02
19.95	158.19
19.97	158.36
19.98	158.52
20.00	158.69
20.02	158.86
20.03	159.02
20.05	159.19
20.07	159.36
20.08	159.52
20.10	159.69
20.12	159.86
20.13	160.02
20.15	160.19
20.17	160.36
20.18	160.52
20.20	160.69
20.22	160.86
20.23	161.02
20.25	161.19
20.27	161.36
20.28	161.52
20.30	161.69
20.32	161.86
20.33	162.02
20.35	162.19
20.37	162.36
20.38	162.52
20.40	162.69
20.42	162.86
20.43	163.02
20.45	163.19
20.47	163.36
20.48	163.52
20.50	163.69
20.52	163.86
20.53	164.03
20.55	164.19
20.57	164.36
20.58	164.53
20.60	164.69
20.62	164.86
20.63	165.03
20.65	165.19
20.67	165.36
20.68	165.53
20.70	165.69
20.72	165.86
20.73	166.03
20.75	166.19
20.77	166.36
20.78	166.53
20.80	166.69
20.82	166.86
20.83	167.03
20.85	167.19
20.87	167.36
20.88	167.53
20.90	167.69
20.92	167.86
20.93	168.03
20.95	168.19
20.97	168.36
20.98	168.53
21.00	168.69
21.02	168.86
21.03	169.03
21.05	169.19
21.07	169.36
21.08	169.53
21.10	169.69
21.12	169.86
21.13	170.03
21.15	170.19
21.17	170.36
21.18	170.53
21.20	170.70
21.22	170.86
21.23	171.03
21.25	171.20
21.27	171.36
21.28	171.53
21.30	171.70
21.32	171.86
21.33	172.03
21.35	172.20
21.37	172.36
21.38	172.53
21.40	172.70
21.42	172.86
21.43	173.03
21.45	173.20
21.47	173.36
21.48	173.53
21.50	173.70
21.52	173.86
21.53	174.03
21.55	174.20
21.57	174.36
21.58	174.53
21.60	174.70
21.62	174.86
21.63	175.03
21.65	175.20
21.67	175.36
21.68	175.53
21.70	175.70
21.72	175.86
21.73	176.03
21.75	176.20
21.77	176.36
21.78	176.53
21.80	176.70
21.82	176.86
21.83	177.03
21.85	177.20
21.87	177.37
21.88	177.53
21.90	177.70
21.92	177.86
21.93	178.03
21.95	178.20
21.97	178.36
21.98	178.53
22.00	178.70
22.02	178.86
22.03	179.03
22.05	179.20
22.07	179.36
22.08	179.53
22.10	179.70
22.12	179.87
22.13	180.03
22.15	180.20
22.17	180.37
22.18	180.53
22.20	180.70
22.22	180.87
22.23	181.03
22.25	181.20
22.27	181.37
22.28	181.53
22.30	181.70
22.32	181.87
22.33	182.03
22.35	182.20
22.37	182.37
22.38	182.53
22.40	182.70
22.42	182.87
22.43	183.03
22.45	183.20
22.47	183.37
22.48	183.53
22.50	183.70
22.52	183.87
22.53	184.03
22.55	184.20
22.57	184.37
22.58	184.53
22.60	184.70
22.62	184.87
22.63	185.03
22.65	185.20
22.67	185.37
22.68	185.53
22.70	185.70
22.72	185.87
22.73	186.04
22.75	186.20
22.77	186.37
22.78	186.54
22.80	186.70
22.82	186.87
22.83	187.04
22.85	187.20
22.87	187.37
22.88	187.54
22.90	187.70
22.92	187.87
22.93	188.04
22.95	188.20
22.97	188.37
22.98	188.54
23.00	188.70
23.02	188.87
23.03	189.04
23.05	189.20
23.07	189.37
23.08	189.54
23.10	189.70
23.12	189.87
23.13	190.04
23.15	190.20
23.17	190.37
23.18	190.54
23.20	190.70
23.22	190.87
23.23	191.04
23.25	191.20
23.27	191.37
23.28	191.54
23.30	191.70
23.32	191.87
23.33	192.04
23.35	192.20
23.37	192.37
23.38	192.54
23.40	192.70
23.42	192.87
23.43	193.04
23.45	193.20
23.47	193.37
23.48	193.54
23.50	193.70
23.52	193.87
23.53	194.04
23.55	194.20
23.57	194.37
23.58	194.54
23.60	194.70
23.62	194.87
23.63	195.04
23.65	195.20
23.67	195.37
23.68	195.54
23.70	195.70
23.72	195.87
23.73	196.04
23.75	196.21
23.77	196.37
23.78	196.54
23.80	196.71
23.82	196.87
23.83	197.04
23.85	197.21
23.87	197.37
23.88	197.54
23.90	197.71
23.92	197.87
23.93	198.04
23.95	198.21
23.97	198.37
23.98	198.54
24.00	198.71
24.02	198.87
24.03	199.04
24.05	199.21
24.07	199.37
24.08	199.54
24.10	199.71
24.12	199.87
24.13	200.04
24.15	200.21
24.17	200.37
24.18	200.54
24.20	200.71
24.22	200.87
24.23	201.04
24.25	201.21
24.27	201.37
24.28	201.54
24.30	201.71
24.32	201.87
24.33	202.04
24.35	202.21
24.37	202.37
24.38	202.54
24.40	202.71
24.42	202.87
24.43	203.04
24.45	203.21
24.47	203.37
24.48	203.54
24.50	203.71
24.52	203.88
24.53	204.04
24.55	204.21
24.57	204.38
24.58	204.54
24.60	204.71
24.62	204.88
24.63	205.04
24.65	205.21
24.67	205.38
24.68	205.54
24.70	205.71
24.72	205.87
24.73	206.04
24.75	206.21
24.77	206.38
24.78	206.54
24.80	206.71
24.82	206.87
24.83	207.04
24.85	207.21
24.87	207.38
24.88	207.54
24.90	207.71
24.92	207.88
24.93	208.04
24.95	208.21
24.97	208.38
24.98	208.54
24.99	208.61

[step]
Ramp 10.00 °C/min to -40.00 °C
Time	Temperature	Heat Flow (Normalized)
min	°C	W/g
25.99	210.06
26.01	210.06
26.03	210.06
26.04	210.05
26.06	210.03
26.08	210.00
26.09	209.95
26.11	209.88
26.13	209.79
26.14	209.68
26.16	209.56
26.18	209.43
26.19	209.30
26.21	209.15
26.23	209.01
26.24	208.85
26.26	208.70
26.28	208.55
26.29	208.39
26.31	208.23
26.33	208.07
26.34	207.91
26.36	207.75
26.38	207.59
26.39	207.43
26.41	207.27
26.43	207.11
26.44	206.94
26.46	206.78
26.48	206.62
26.49	206.45
26.51	206.29
26.53	206.13
26.54	205.96
26.56	205.80
26.58	205.63
26.59	205.47
26.61	205.31
26.63	205.14
26.64	204.98
26.66	204.81
26.68	204.65
26.69	204.48
26.71	204.32
26.73	204.15
26.74	203.99
26.76	203.82
26.78	203.66
26.79	203.49
26.81	203.33
26.83	203.16
26.84	203.00
26.86	202.83
26.88	202.66
26.89	202.50
26.91	202.33
26.93	202.17
26.94	202.00
26.96	201.84
26.98	201.67
26.99	201.51
27.01	201.34
27.03	201.17
27.04	201.01
27.06	200.84
27.08	200.68
27.09	200.51
27.11	200.34
27.13	200.18
27.14	200.01
27.16	199.85
27.18	199.68
27.19	199.52
27.21	199.35
27.23	199.18
27.24	199.02
27.26	198.85
27.28	198.69
27.29	198.52
27.31	198.35
27.33	198.19
27.34	198.02
27.36	197.86
27.38	197.69
27.39	197.52
27.41	197.36
27.43	197.19
27.44	197.02
27.46	196.86
27.48	196.69
27.49	196.52
27.51	196.36
27.53	196.19
27.54	196.03
27.56	195.86
27.58	195.69
27.59	195.53
27.61	195.36
27.63	195.19
27.64	195.03
27.66	194.86
27.68	194.70
27.69	194.53
27.71	194.36
27.73	194.20
27.74	194.03
27.76	193.86
27.78	193.70
27.79	193.53
27.81	193.37
27.83	193.20
27.84	193.03
27.86	192.87
27.88	192.70
27.89	192.53
27.91	192.37
27.93	192.20
27.94	192.04
27.96	191.87
27.98	191.70
27.99	191.54
28.01	191.37
28.03	191.20
28.04	191.04
28.06	190.87
28.08	190.70
28.09	190.54
28.11	190.37
28.13	190.20
28.14	190.04
28.16	189.87
28.18	189.70
28.19	189.54
28.21	189.37
28.23	189.21
28.24	189.04
28.26	188.87
28.28	188.71
28.29	188.54
28.31	188.37
28.33	188.20
28.34	188.04
28.36	187.87
28.38	187.71
28.39	187.54
28.41	187.37
28.43	187.21
28.44	187.04
28.46	186.88
28.48	186.71
28.49	186.54
28.51	186.38
28.53	186.21
28.54	186.04
28.56	185.88
28.58	185.71
28.59	185.54
28.61	185.38
28.63	185.21
28.64	185.04
28.66	184.88
28.68	184.71
28.69	184.54
28.71	184.38
28.73	184.21
28.74	184.04
28.76	183.88
28.78	183.71
28.79	183.54
28.81	183.38
28.83	183.21
28.84	183.05
28.86	182.88
28.88	182.71
28.89	182.55
28.91	182.38
28.93	182.21
28.94	182.05
28.96	181.88
28.98	181.71
28.99	181.55
29.01	181.38
29.03	181.21
29.04	181.05
29.06	180.88
29.08	180.71
29.09	180.55
29.11	180.38
29.13	180.21
29.14	180.05
29.16	179.88
29.18	179.72
29.19	179.55
29.21	179.38
29.23	179.22
29.24	179.05
29.26	178.88
29.28	178.72
29.29	178.55
29.31	178.38
29.33	178.22
29.34	178.05
29.36	177.88
29.38	177.72
29.39	177.55
29.41	177.39
29.43	177.22
29.44	177.05
29.46	176.89
29.48	176.72
29.49	176.55
29.51	176.39
29.53	176.22
29.54	176.05
29.56	175.89
29.58	175.72
29.59	175.55
29.61	175.39
29.63	175.22
29.64	175.05
29.66	174.89
29.68	174.72
29.69	174.56
29.71	174.39
29.73	174.22
29.74	174.05
29.76	173.89
29.78	173.72
29.79	173.56
29.81	173.39
29.83	173.22
29.84	173.06
29.86	172.89
29.88	172.72
29.89	172.56
29.91	172.39
29.93	172.22
29.94	172.05
29.96	171.89
29.98	171.72
29.99	171.56
30.01	171.39
30.03	171.22
30.04	171.06
30.06	170.89
30.08	170.72
30.09	170.56
30.11	170.39
30.13	170.22
30.14	170.06
30.16	169.89
30.18	169.73
30.19	169.56
30.21	169.39
30.23	169.23
30.24	169.06
30.26	168.89
30.28	168.73
30.29	168.56
30.31	168.39
30.33	168.23
30.34	168.06
30.36	167.89
30.38	167.73
30.39	167.56
30.41	167.39
30.43	167.23
30.44	167.06
30.46	166.90
30.48	166.73
30.49	166.56
30.51	166.40
30.53	166.23
30.54	166.06
30.56	165.90
30.58	165.73
30.59	165.56
30.61	165.40
30.63	165.23
30.64	165.06
30.66	164.90
30.68	164.73
30.69	164.56
30.71	164.40
30.73	164.23
30.74	164.07
30.76	163.90
30.78	163.73
30.79	163.57
30.81	163.40
30.83	163.23
30.84	163.07
30.86	162.90
30.88	162.73
30.89	162.57
30.91	162.40
30.93	162.23
30.94	162.07
30.96	161.90
30.98	161.73
30.99	161.57
31.01	161.40
31.03	161.23
31.04	161.07
31.06	160.90
31.08	160.73
31.09	160.57
31.11	160.40
31.13	160.23
31.14	160.07
31.16	159.90
31.18	159.74
31.19	159.57
31.21	159.40
31.23	159.24
31.24	159.07
31.26	158.90
31.28	158.74
31.29	158.57
31.31	158.40
31.33	158.24
31.34	158.07
31.36	157.90
31.38	157.74
31.39	157.57
31.41	157.40
31.43	157.24
31.44	157.07
31.46	156.90
31.48	156.74
31.49	156.57
31.51	156.41
31.53	156.24
31.54	156.07
31.56	155.91
31.58	155.74
31.59	155.57
31.61	155.41
31.63	155.24
31.64	155.07
31.66	154.91
31.68	154.74
31.69	154.57
31.71	154.41
31.73	154.24
31.74	154.07
31.76	153.91
31.78	153.74
31.79	153.57
31.81	153.41
31.83	153.24
31.84	153.08
31.86	152.91
31.88	152.74
31.89	152.58
31.91	152.41
31.93	152.24
31.94	152.08
31.96	151.91
31.98	151.74
31.99	151.58
32.01	151.41
32.03	151.24
32.04	151.08
32.06	150.91
32.08	150.74
32.09	150.58
32.11	150.41
32.13	150.25
32.14	150.08
32.16	149.91
32.18	149.75
32.19	149.58
32.21	149.41
32.23	149.25
32.24	149.08
32.26	148.91
32.28	148.75
32.29	148.58
32.31	148.41
32.33	148.25
32.34	148.08
32.36	147.91
32.38	147.75
32.39	147.58
32.41	147.41
32.43	147.25
32.44	147.08
32.46	146.91
32.48	146.75
32.49	146.58
32.51	146.41
32.53	146.25
32.54	146.08
32.56	145.92
32.58	145.75
32.59	145.58
32.61	145.42
32.63	145.25
32.64	145.08
32.66	144.92
32.68	144.75
32.69	144.58
32.71	144.42
32.73	144.25
32.74	144.08
32.76	143.92
32.78	143.75
32.79	143.58
32.81	143.42
32.83	143.25
32.84	143.08
32.86	142.92
32.88	142.75
32.89	142.59
32.91	142.42
32.93	142.25
32.94	142.09
32.96	141.92
32.98	141.75
32.99	141.59
33.01	141.42
33.03	141.25
33.04	141.09
33.06	140.92
33.08	140.75
33.09	140.59
33.11	140.42
33.13	140.25
33.14	140.09
33.16	139.92
33.18	139.75
33.19	139.59
33.21	139.42
33.23	139.25
33.24	139.09
33.26	138.92
33.28	138.76
33.29	138.59
33.31	138.42
33.33	138.26
33.34	138.09
33.36	137.92
33.38	137.76
33.39	137.59
33.41	137.42
33.43	137.26
33.44	137.09
33.46	136.92
33.48	136.76
33.49	136.59
33.51	136.42
33.53	136.26
33.54	136.09
33.56	135.92
33.58	135.76
33.59	135.59
33.61	135.43
33.63	135.26
33.64	135.09
33.66	134.93
33.68	134.76
33.69	134.59
33.71	134.43
33.73	134.26
33.74	134.09
33.76	133.93
33.78	133.76
33.79	133.59
33.81	133.43
33.83	133.26
33.84	133.09
33.86	132.93
33.88	132.76
33.89	132.59
33.91	132.43
33.93	132.26
33.94	132.09
33.96	131.93
33.98	131.76
33.99	131.59
34.01	131.43
34.03	131.26
34.04	131.09
34.06	130.93
34.08	130.76
34.09	130.60
34.11	130.43
34.13	130.26
34.14	130.10
34.16	129.93
34.18	129.76
34.19	129.60
34.21	129.43
34.23	129.26
34.24	129.10
34.26	128.93
34.28	128.76
34.29	128.60
34.31	128.43
34.33	128.27
34.34	128.10
34.36	127.93
34.38	127.77
34.39	127.60
34.41	127.43
34.43	127.27
34.44	127.10
34.46	126.93
34.48	126.77
34.49	126.60
34.51	126.43
34.53	126.27
34.54	126.10
34.56	125.93
34.58	125.77
34.59	125.60
34.61	125.44
34.63	125.27
34.64	125.10
34.66	124.94
34.68	124.77
34.69	124.60
34.71	124.44
34.73	124.27
34.74	124.10
34.76	123.94
34.78	123.77
34.79	123.60
34.81	123.44
34.83	123.27
34.84	123.10
34.86	122.94
34.88	122.77
34.89	122.60
34.91	122.44
34.93	122.27
34.94	122.10
34.96	121.94
34.98	121.77
34.99	121.61
35.01	121.44
35.03	121.27
35.04	121.11
35.06	120.94
35.08	120.77
35.09	120.61
35.11	120.44
35.13	120.27
35.14	120.11
35.16	119.94
35.18	119.77
35.19	119.61
35.21	119.44
35.23	119.27
35.24	119.11
35.26	118.94
35.28	118.77
35.29	118.61
35.31	118.44
35.33	118.27
35.34	118.11
35.36	117.94
35.38	117.77
35.39	117.61
35.41	117.44
35.43	117.27
35.44	117.11
35.46	116.94
35.48	116.78
35.49	116.61
35.51	116.44
35.53	116.28
35.54	116.11
35.56	115.94
35.58	115.78
35.59	115.61
35.61	115.44
35.63	115.28
35.64	115.11
35.66	114.94
35.68	114.78
35.69	114.61
35.71	114.44
35.73	114.28
35.74	114.11
35.76	113.94
35.78	113.78
35.79	113.61
35.81	113.44
35.83	113.28
35.84	113.11
35.86	112.95
35.88	112.78
35.89	112.61
35.91	112.45
35.93	112.28
35.94	112.11
35.96	111.95
35.98	111.78
35.99	111.61
36.01	111.45
36.03	111.28
36.04	111.11
36.06	110.95
36.08	110.78
36.09	110.61
36.11	110.45
36.13	110.28
36.14	110.11
36.16	109.95
36.18	109.78
36.19	109.62
36.21	109.45
36.23	109.28
36.24	109.11
36.26	108.95
36.28	108.78
36.29	108.62
36.31	108.45
36.33	108.28
36.34	108.11
36.36	107.95
36.38	107.78
36.39	107.62
36.41	107.45
36.43	107.28
36.44	107.12
36.46	106.95
36.48	106.78
36.49	106.62
36.51	106.45
36.53	106.28
36.54	106.12
36.56	105.95
36.58	105.78
36.59	105.62
36.61	105.45
36.63	105.28
36.64	105.12
36.66	104.95
36.68	104.79
36.69	104.62
36.71	104.45
36.73	104.29
36.74	104.12
36.76	103.95
36.78	103.79
36.79	103.62
36.81	103.45
36.83	103.29
36.84	103.12
36.86	102.95
36.88	102.79
36.89	102.62
36.91	102.45
36.93	102.29
36.94	102.12
36.96	101.96
36.98	101.79
36.99	101.62
37.01	101.46
37.03	101.29
37.04	101.12
37.06	100.96
37.08	100.79
37.09	100.62
37.11	100.46
37.13	100.29
37.14	100.12
37.16	99.96
37.18	99.79
37.19	99.62
37.21	99.46
37.23	99.29
37.24	99.12
37.26	98.96
37.28	98.79
37.29	98.62
37.31	98.46
37.33	98.29
37.34	98.13
37.36	97.96
37.38	97.79
37.39	97.63
37.41	97.46
37.43	97.29
37.44	97.13
37.46	96.96
37.48	96.79
37.49	96.63
37.51	96.46
37.53	96.29
37.54	96.13
37.56	95.96
37.58	95.79
37.59	95.63
37.61	95.46
37.63	95.29
37.64	95.13
37.66	94.96
37.68	94.79
37.69	94.63
37.71	94.46
37.73	94.29
37.74	94.13
37.76	93.96
37.78	93.79
37.79	93.63
37.81	93.46
37.83	93.30
37.84	93.13
37.86	92.96
37.88	92.80
37.89	92.63
37.91	92.46
37.93	92.30
37.94	92.13
37.96	91.96
37.98	91.80
37.99	91.63
38.01	91.46
38.03	91.30
38.04	91.13
38.06	90.96
38.08	90.80
38.09	90.63
38.11	90.47
38.13	90.30
38.14	90.13
38.16	89.97
38.18	89.80
38.19	89.63
38.21	89.47
38.23	89.30
38.24	89.13
38.26	88.97
38.28	88.80
38.29	88.63
38.31	88.47
38.33	88.30
38.34	88.13
38.36	87.97
38.38	87.80
38.39	87.63
38.41	87.47
38.43	87.30
38.44	87.13
38.46	86.97
38.48	86.80
38.49	86.64
38.51	86.47
38.53	86.30
38.54	86.13
38.56	85.97
38.58	85.80
38.59	85.64
38.61	85.47
38.63	85.30
38.64	85.14
38.66	84.97
38.68	84.80
38.69	84.64
38.71	84.47
38.73	84.30
38.74	84.14
38.76	83.97
38.78	83.80
38.79	83.64
38.81	83.47
38.83	83.30
38.84	83.14
38.86	82.97
38.88	82.80
38.89	82.64
38.91	82.47
38.93	82.31
38.94	82.14
38.96	81.97
38.98	81.81
38.99	81.64
39.01	81.47
39.03	81.31
39.04	81.14
39.06	80.97
39.08	80.81
39.09	80.64
39.11	80.47
39.13	80.31
39.14	80.14
39.16	79.97
39.18	79.81
39.19	79.64
39.21	79.48
39.23	79.31
39.24	79.14
39.26	78.98
39.28	78.81
39.29	78.64
39.31	78.48
39.33	78.31
39.34	78.14
39.36	77.98
39.38	77.81
39.39	77.64
39.41	77.48
39.43	77.31
39.44	77.14
39.46	76.98
39.48	76.81
39.49	76.64
39.51	76.48
39.53	76.31
39.54	76.15
39.56	75.98
39.58	75.81
39.59	75.65
39.61	75.48
39.63	75.31
39.64	75.15
39.66	74.98
39.68	74.81
39.69	74.65
39.71	74.48
39.73	74.31
39.74	74.15
39.76	73.98
39.78	73.81
39.79	73.65
39.81	73.48
39.83	73.31
39.84	73.15
39.86	72.98
39.88	72.81
39.89	72.65
39.91	72.48
39.93	72.31
39.94	72.15
39.96	71.98
39.98	71.81
39.99	71.65
40.01	71.48
40.03	71.32
40.04	71.15
40.06	70.98
40.08	70.82
40.09	70.65
40.11	70.48
40.13	70.32
40.14	70.15
40.16	69.98
40.18	69.82
40.19	69.65
40.21	69.48
40.23	69.32
40.24	69.15
40.26	68.98
40.28	68.82
40.29	68.65
40.31	68.48
40.33	68.32
40.34	68.15
40.36	67.99
40.38	67.82
40.39	67.65
40.41	67.48
40.43	67.32
40.44	67.15
40.46	66.99
40.48	66.82
40.49	66.65
40.51	66.49
40.53	66.32
40.54	66.15
40.56	65.99
40.58	65.82
40.59	65.65
40.61	65.49
40.63	65.32
40.64	65.15
40.66	64.99
40.68	64.82
40.69	64.66
40.71	64.49
40.73	64.32
40.74	64.16
40.76	63.99
40.78	63.82
40.79	63.66
40.81	63.49
40.83	63.32
40.84	63.16
40.86	62.99
40.88	62.82
40.89	62.66
40.91	62.49
40.93	62.32
40.94	62.16
40.96	61.99
40.98	61.82
40.99	61.66
41.01	61.49
41.03	61.32
41.04	61.16
41.06	60.99
41.08	60.82
41.09	60.66
41.11	60.49
41.13	60.32
41.14	60.16
41.16	59.99
41.18	59.82
41.19	59.66
41.21	59.49
41.23	59.33
41.24	59.16
41.26	58.99
41.28	58.83
41.29	58.66
41.31	58.49
41.33	58.33
41.34	58.16
41.36	57.99
41.38	57.83
41.39	57.66
41.41	57.49
41.43	57.33
41.44	57.16
41.46	56.99
41.48	56.83
41.49	56.66
41.51	56.50
41.53	56.33
41.54	56.16
41.56	56.00
41.58	55.83
41.59	55.66
41.61	55.50
41.63	55.33
41.64	55.16
41.66	55.00
41.68	54.83
41.69	54.66
41.71	54.50
41.73	54.33
41.74	54.16
41.76	54.00
41.78	53.83
41.79	53.66
41.81	53.50
41.83	53.33
41.84	53.16
41.86	53.00
41.88	52.83
41.89	52.67
41.91	52.50
41.93	52.33
41.94	52.16
41.96	52.00
41.98	51.83
41.99	51.67
42.01	51.50
42.03	51.33
42.04	51.17
42.06	51.00
42.08	50.83
42.09	50.67
42.11	50.50
42.13	50.33
42.14	50.17
42.16	50.00
42.18	49.83
42.19	49.67
42.21	49.50
42.23	49.33
42.24	49.17
42.26	49.00
42.28	48.83
42.29	48.67
42.31	48.50
42.33	48.34
42.34	48.17
42.36	48.00
42.38	47.84
42.39	47.67
42.41	47.50
42.43	47.34
42.44	47.17
42.46	47.00
42.48	46.84
42.49	46.67
42.51	46.50
42.53	46.34
42.54	46.17
42.56	46.01
42.58	45.84
42.59	45.67
42.61	45.51
42.63	45.34
42.64	45.17
42.66	45.00
42.68	44.84
42.69	44.67
42.71	44.50
42.73	44.34
42.74	44.17
42.76	44.00
42.78	43.84
42.79	43.67
42.81	43.51
42.83	43.34
42.84	43.17
42.86	43.01
42.88	42.84
42.89	42.67
42.91	42.51
42.93	42.34
42.94	42.17
42.96	42.01
42.98	41.84
42.99	41.67
43.01	41.51
43.03	41.34
43.04	41.17
43.06	41.01
43.08	40.84
43.09	40.68
43.11	40.51
43.13	40.34
43.14	40.18
43.16	40.01
43.18	39.84
43.19	39.68
43.21	39.51
43.23	39.34
43.24	39.18
43.26	39.01
43.28	38.84
43.29	38.68
43.31	38.51
43.33	38.34
43.34	38.18
43.36	38.01
43.38	37.84
43.39	37.68
43.41	37.51
43.43	37.35
43.44	37.18
43.46	37.01
43.48	36.85
43.49	36.68
43.51	36.51
43.53	36.35
43.54	36.18
43.56	36.01
43.58	35.85
43.59	35.68
43.61	35.51
43.63	35.35
43.64	35.18
43.66	35.01
43.68	34.85
43.69	34.68
43.71	34.51
43.73	34.35
43.74	34.18
43.76	34.01
43.78	33.85
43.79	33.68
43.81	33.51
43.83	33.35
43.84	33.18
43.86	33.01
43.88	32.85
43.89	32.68
43.91	32.52
43.93	32.35
43.94	32.18
43.96	32.02
43.98	31.85
43.99	31.68
44.01	31.52
44.03	31.35
44.04	31.18
44.06	31.02
44.08	30.85
44.09	30.68
44.11	30.52
44.13	30.35
44.14	30.18
44.16	30.02
44.18	29.85
44.19	29.68
44.21	29.52
44.23	29.35
44.24	29.19
44.26	29.02
44.28	28.85
44.29	28.69
44.31	28.52
44.33	28.35
44.34	28.19
44.36	28.02
44.38	27.85
44.39	27.69
44.41	27.52
44.43	27.35
44.44	27.19
44.46	27.02
44.48	26.85
44.49	26.69
44.51	26.52
44.53	26.36
44.54	26.19
44.56	26.02
44.58	25.86
44.59	25.69
44.61	25.52
44.63	25.36
44.64	25.19
44.66	25.02
44.68	24.86
44.69	24.69
44.71	24.52
44.73	24.36
44.74	24.19
44.76	24.02
44.78	23.86
44.79	23.69
44.81	23.53
44.83	23.36
44.84	23.19
44.86	23.03
44.88	22.86
44.89	22.69
44.91	22.53
44.93	22.36
44.94	22.19
44.96	22.03
44.98	21.86
44.99	21.70
45.01	21.53
45.03	21.36
45.04	21.20
45.06	21.03
45.08	20.86
45.09	20.70
45.11	20.53
45.13	20.36
45.14	20.20
45.16	20.03
45.18	19.86
45.19	19.70
45.21	19.53
45.23	19.36
45.24	19.20
45.26	19.03
45.28	18.86
45.29	18.70
45.31	18.53
45.33	18.37
45.34	18.20
45.36	18.03
45.38	17.87
45.39	17.70
45.41	17.53
45.43	17.37
45.44	17.20
45.46	17.03
45.48	16.87
45.49	16.70
45.51	16.53
45.53	16.37
45.54	16.20
45.56	16.03
45.58	15.87
45.59	15.70
45.61	15.54
45.63	15.37
45.64	15.20
45.66	15.04
45.68	14.87
45.69	14.70
45.71	14.54
45.73	14.37
45.74	14.20
45.76	14.04
45.78	13.87
45.79	13.71
45.81	13.54
45.83	13.37
45.84	13.21
45.86	13.04
45.88	12.87
45.89	12.71
45.91	12.54
45.93	12.37
45.94	12.21
45.96	12.04
45.98	11.87
45.99	11.71
46.01	11.54
46.03	11.37
46.04	11.21
46.06	11.04
46.08	10.88
46.09	10.71
46.11	10.54
46.13	10.38
46.14	10.21
46.16	10.04
46.18	9.88
46.19	9.71
46.21	9.54
46.23	9.38
46.24	9.21
46.26	9.05
46.28	8.88
46.29	8.71
46.31	8.55
46.33	8.38
46.34	8.21
46.36	8.05
46.38	7.88
46.39	7.71
46.41	7.55
46.43	7.38
46.44	7.21
46.46	7.05
46.48	6.88
46.49	6.71
46.51	6.55
46.53	6.38
46.54	6.21
46.56	6.05
46.58	5.88
46.59	5.71
46.61	5.55
46.63	5.38
46.64	5.21
46.66	5.05
46.68	4.88
46.69	4.72
46.71	4.55
46.73	4.38
46.74	4.22
46.76	4.05
46.78	3.88
46.79	3.72
46.81	3.55
46.83	3.38
46.84	3.22
46.86	3.05
46.88	2.88
46.89	2.72
46.91	2.55
46.93	2.38
46.94	2.21
46.96	2.05
46.98	1.88
46.99	1.72
47.01	1.55
47.03	1.38
47.04	1.22
47.06	1.05
47.08	0.88
47.09	0.71
47.11	0.55
47.13	0.38
47.14	0.21
47.16	0.05
47.18	-0.12
47.19	-0.29
47.21	-0.45
47.23	-0.62
47.24	-0.79
47.26	-0.95
47.28	-1.12
47.29	-1.29
47.31	-1.45
47.33	-1.62
47.34	-1.79
47.36	-1.96
47.38	-2.12
47.39	-2.29
47.41	-2.45
47.43	-2.62
47.44	-2.79
47.46	-2.96
47.48	-3.12
47.49	-3.29
47.51	-3.46
47.53	-3.62
47.54	-3.79
47.56	-3.96
47.58	-4.12
47.59	-4.29
47.61	-4.46
47.63	-4.62
47.64	-4.79
47.66	-4.96
47.68	-5.12
47.69	-5.29
47.71	-5.46
47.73	-5.62
47.74	-5.79
47.76	-5.96
47.78	-6.13
47.79	-6.29
47.81	-6.46
47.83	-6.63
47.84	-6.79
47.86	-6.96
47.88	-7.13
47.89	-7.29
47.91	-7.46
47.93	-7.63
47.94	-7.79
47.96	-7.96
47.98	-8.13
47.99	-8.29
48.01	-8.46
48.03	-8.63
48.04	-8.79
48.06	-8.96
48.08	-9.13
48.09	-9.29
48.11	-9.46
48.13	-9.63
48.14	-9.79
48.16	-9.96
48.18	-10.13
48.19	-10.29
48.21	-10.46
48.23	-10.63
48.24	-10.79
48.26	-10.96
48.28	-11.13
48.29	-11.29
48.31	-11.46
48.33	-11.63
48.34	-11.80
48.36	-11.96
48.38	-12.13
48.39	-12.30
48.41	-12.46
48.43	-12.63
48.44	-12.80
48.46	-12.96
48.48	-13.13
48.49	-13.30
48.51	-13.46
48.53	-13.63
48.54	-13.80
[...]
60.01	38.64	-0.051
60.03	38.81	-0.051
60.04	38.97	-0.051
60.06	39.14	-0.051
60.08	39.31	-0.052
60.09	39.48	-0.052
60.11	39.64	-0.052
60.13	39.81	-0.052
60.14	39.98	-0.052
60.16	40.14	-0.052
60.18	40.31	-0.052
60.19	40.47	-0.052
60.21	40.64	-0.052
60.23	40.81	-0.052
60.24	40.98	-0.053
60.26	41.14	-0.052
60.28	41.31	-0.052
60.29	41.48	-0.053
60.31	41.64	-0.053
60.33	41.81	-0.053
60.34	41.98	-0.053
60.36	42.14	-0.053
60.38	42.31	-0.053
60.39	42.48	-0.053
60.41	42.64	-0.053
60.43	42.81	-0.053
60.44	42.98	-0.053
60.46	43.15	-0.053
60.48	43.31	-0.053
60.49	43.48	-0.053
60.51	43.64	-0.053
60.53	43.81	-0.053
60.54	43.98	-0.053
60.56	44.15	-0.053
60.58	44.31	-0.054
60.59	44.48	-0.053
60.61	44.65	-0.054
60.63	44.81	-0.054
60.64	44.98	-0.054
60.66	45.15	-0.054
60.68	45.31	-0.054
60.69	45.48	-0.054
60.71	45.65	-0.054
60.73	45.81	-0.054
60.74	45.98	-0.054
60.76	46.15	-0.054
60.78	46.31	-0.054
60.79	46.48	-0.054
60.81	46.65	-0.054
60.83	46.82	-0.054
60.84	46.98	-0.055
60.86	47.15	-0.055
60.88	47.32	-0.055
60.89	47.48	-0.055
60.91	47.65	-0.055
60.93	47.82	-0.054
60.94	47.98	-0.054
60.96	48.15	-0.054
60.98	48.31	-0.054
60.99	48.48	-0.055
61.01	48.65	-0.055
61.03	48.82	-0.055
61.04	48.98	-0.055
61.06	49.15	-0.056
61.08	49.32	-0.056
61.09	49.48	-0.056
61.11	49.65	-0.056
61.13	49.82	-0.056
61.14	49.99	-0.056
61.16	50.15	-0.055
61.18	50.32	-0.055
61.19	50.48	-0.055
61.21	50.65	-0.055
61.23	50.82	-0.056
61.24	50.98	-0.056
61.26	51.15	-0.056
61.28	51.32	-0.056
61.29	51.48	-0.056
61.31	51.65	-0.056
61.33	51.82	-0.056
61.34	51.99	-0.056
61.36	52.15	-0.056
61.38	52.32	-0.056
61.39	52.49	-0.057
61.41	52.65	-0.057
61.43	52.82	-0.057
61.44	52.99	-0.057
61.46	53.15	-0.057
61.48	53.32	-0.057
61.49	53.49	-0.057
61.51	53.65	-0.057
61.53	53.82	-0.057
61.54	53.99	-0.057
61.56	54.15	-0.057
61.58	54.32	-0.057
61.59	54.49	-0.057
61.61	54.66	-0.057
61.63	54.82	-0.057
61.64	54.99	-0.058
61.66	55.16	-0.058
61.68	55.32	-0.058
61.69	55.49	-0.058
61.71	55.66	-0.058
61.73	55.82	-0.058
61.74	55.99	-0.058
61.76	56.16	-0.058
61.78	56.32	-0.058
61.79	56.49	-0.058
61.81	56.66	-0.058
61.83	56.82	-0.058
61.84	56.99	-0.058
61.86	57.16	-0.058
61.88	57.32	-0.058
61.89	57.49	-0.058
61.91	57.66	-0.058
61.93	57.82	-0.058
61.94	57.99	-0.058
61.96	58.16	-0.058
61.98	58.33	-0.059
61.99	58.49	-0.059
62.01	58.66	-0.059
62.03	58.82	-0.059
62.04	58.99	-0.059
62.06	59.16	-0.059
62.08	59.33	-0.059
62.09	59.49	-0.059
62.11	59.66	-0.059
62.13	59.83	-0.059
62.14	59.99	-0.059
62.16	60.16	-0.059
62.18	60.33	-0.059
62.19	60.49	-0.060
62.21	60.66	-0.060
62.23	60.83	-0.060
62.24	60.99	-0.060
62.26	61.16	-0.060
62.28	61.33	-0.060
62.29	61.49	-0.060
62.31	61.66	-0.060
62.33	61.83	-0.060
62.34	61.99	-0.060
62.36	62.16	-0.060
62.38	62.33	-0.060
62.39	62.49	-0.060
62.41	62.66	-0.060
62.43	62.83	-0.060
62.44	63.00	-0.060
62.46	63.16	-0.060
62.48	63.33	-0.060
62.49	63.50	-0.061
62.51	63.66	-0.061
62.53	63.83	-0.061
62.54	64.00	-0.061
62.56	64.16	-0.061
62.58	64.33	-0.061
62.59	64.50	-0.061
62.61	64.66	-0.061
62.63	64.83	-0.061
62.64	65.00	-0.061
62.66	65.16	-0.061
62.68	65.33	-0.061
62.69	65.50	-0.061
62.71	65.66	-0.061
62.73	65.83	-0.061
62.74	66.00	-0.061
62.76	66.16	-0.061
62.78	66.33	-0.061
62.79	66.50	-0.061
62.81	66.66	-0.061
62.83	66.83	-0.062
62.84	67.00	-0.062
62.86	67.17	-0.062
62.88	67.33	-0.062
62.89	67.50	-0.062
62.91	67.67	-0.062
62.93	67.83	-0.062
62.94	68.00	-0.062
62.96	68.17	-0.062
62.98	68.33	-0.062
62.99	68.50	-0.062
63.01	68.67	-0.062
63.03	68.83	-0.062
63.04	69.00	-0.062
63.06	69.17	-0.062
63.08	69.33	-0.062
63.09	69.50	-0.062
63.11	69.67	-0.063
63.13	69.83	-0.063
63.14	70.00	-0.063
63.16	70.17	-0.063
63.18	70.33	-0.063
63.19	70.50	-0.063
63.21	70.67	-0.063
63.23	70.84	-0.064
63.24	71.00	-0.063
63.26	71.17	-0.064
63.28	71.34	-0.064
63.29	71.50	-0.064
63.31	71.67	-0.064
63.33	71.84	-0.064
63.34	72.00	-0.064
63.36	72.17	-0.064
63.38	72.34	-0.064
63.39	72.50	-0.064
63.41	72.67	-0.064
63.43	72.84	-0.064
63.44	73.00	-0.064
63.46	73.17	-0.064
63.48	73.34	-0.064
63.49	73.51	-0.065
63.51	73.67	-0.065
63.53	73.84	-0.065
63.54	74.00	-0.065
63.56	74.17	-0.065
63.58	74.34	-0.065
63.59	74.51	-0.065
63.61	74.67	-0.065
63.63	74.84	-0.065
63.64	75.01	-0.065
63.66	75.17	-0.065
63.68	75.34	-0.065
63.69	75.51	-0.065
63.71	75.67	-0.065
63.73	75.84	-0.065
63.74	76.01	-0.065
63.76	76.18	-0.066
63.78	76.34	-0.066
63.79	76.51	-0.066
63.81	76.68	-0.065
63.83	76.84	-0.066
63.84	77.01	-0.066
63.86	77.18	-0.066
63.88	77.34	-0.066
63.89	77.51	-0.066
63.91	77.68	-0.066
63.93	77.85	-0.066
63.94	78.01	-0.066
63.96	78.18	-0.066
63.98	78.35	-0.066
63.99	78.51	-0.066
64.01	78.68	-0.066
64.03	78.84	-0.066
64.04	79.01	-0.066
64.06	79.18	-0.066
64.08	79.35	-0.066
64.09	79.51	-0.066
64.11	79.68	-0.066
64.13	79.85	-0.066
64.14	80.01	-0.066
64.16	80.18	-0.066
64.18	80.35	-0.067
64.19	80.51	-0.067
64.21	80.68	-0.067
64.23	80.85	-0.067
64.24	81.01	-0.067
64.26	81.18	-0.067
64.28	81.35	-0.067
64.29	81.51	-0.067
64.31	81.68	-0.067
64.33	81.85	-0.067
64.34	82.01	-0.068
64.36	82.18	-0.068
64.38	82.35	-0.068
64.39	82.51	-0.068
64.41	82.68	-0.068
64.43	82.85	-0.068
64.44	83.02	-0.069
64.46	83.18	-0.069
64.48	83.35	-0.069
64.49	83.52	-0.070
64.51	83.68	-0.070
64.53	83.85	-0.070
64.54	84.02	-0.070
64.56	84.18	-0.070
64.58	84.35	-0.071
64.59	84.52	-0.071
64.61	84.68	-0.071
64.63	84.85	-0.071
64.64	85.02	-0.071
64.66	85.18	-0.071
64.68	85.35	-0.072
64.69	85.52	-0.072
64.71	85.68	-0.072
64.73	85.85	-0.072
64.74	86.02	-0.072
64.76	86.18	-0.072
64.78	86.35	-0.072
64.79	86.52	-0.072
64.81	86.68	-0.073
64.83	86.85	-0.073
64.84	87.02	-0.073
64.86	87.18	-0.073
64.88	87.35	-0.073
64.89	87.52	-0.074
64.91	87.68	-0.074
64.93	87.85	-0.074
64.94	88.02	-0.074
64.96	88.18	-0.074
64.98	88.35	-0.074
64.99	88.52	-0.075
65.01	88.68	-0.075
65.03	88.85	-0.075
65.04	89.02	-0.075
65.06	89.18	-0.075
65.08	89.35	-0.074
65.09	89.52	-0.075
65.11	89.68	-0.075
65.13	89.85	-0.075
65.14	90.02	-0.075
65.16	90.18	-0.075
65.18	90.35	-0.075
65.19	90.52	-0.075
65.21	90.68	-0.075
65.23	90.85	-0.075
65.24	91.02	-0.075
65.26	91.18	-0.075
65.28	91.35	-0.075
65.29	91.52	-0.075
65.31	91.69	-0.075
65.33	91.85	-0.075
65.34	92.02	-0.074
65.36	92.18	-0.075
65.38	92.35	-0.075
65.39	92.52	-0.075
65.41	92.69	-0.075
65.43	92.85	-0.075
65.44	93.02	-0.075
65.46	93.19	-0.075
65.48	93.35	-0.075
65.49	93.52	-0.075
65.51	93.69	-0.075
65.53	93.85	-0.075
65.54	94.02	-0.075
65.56	94.19	-0.075
65.58	94.35	-0.075
65.59	94.52	-0.075
65.61	94.69	-0.075
65.63	94.85	-0.075
65.64	95.02	-0.075
65.66	95.19	-0.075
65.68	95.35	-0.075
65.69	95.52	-0.075
65.71	95.69	-0.075
65.73	95.86	-0.075
65.74	96.02	-0.075
65.76	96.19	-0.075
65.78	96.36	-0.075
65.79	96.52	-0.075
65.81	96.69	-0.075
65.83	96.86	-0.075
65.84	97.02	-0.075
65.86	97.19	-0.075
65.88	97.36	-0.076
65.89	97.52	-0.076
65.91	97.69	-0.076
65.93	97.86	-0.076
65.94	98.02	-0.076
65.96	98.19	-0.076
65.98	98.36	-0.076
65.99	98.53	-0.076
66.01	98.69	-0.076
66.03	98.86	-0.076
66.04	99.03	-0.076
66.06	99.19	-0.076
66.08	99.36	-0.076
66.09	99.53	-0.076
66.11	99.69	-0.077
66.13	99.86	-0.077
66.14	100.03	-0.077
66.16	100.19	-0.077
66.18	100.36	-0.077
66.19	100.53	-0.077
66.21	100.69	-0.077
66.23	100.86	-0.077
66.24	101.03	-0.077
66.26	101.19	-0.077
66.28	101.36	-0.077
66.29	101.53	-0.077
66.31	101.69	-0.077
66.33	101.86	-0.077
66.34	102.03	-0.077
66.36	102.19	-0.077
66.38	102.36	-0.077
66.39	102.53	-0.077
66.41	102.69	-0.077
66.43	102.86	-0.078
66.44	103.03	-0.078
66.46	103.19	-0.078
66.48	103.36	-0.078
66.49	103.53	-0.077
66.51	103.70	-0.078
66.53	103.86	-0.077
66.54	104.03	-0.077
66.56	104.20	-0.077
66.58	104.36	-0.077
66.59	104.53	-0.077
66.61	104.70	-0.077
66.63	104.86	-0.077
66.64	105.03	-0.077
66.66	105.20	-0.077
66.68	105.36	-0.077
66.69	105.53	-0.077
66.71	105.70	-0.077
66.73	105.86	-0.076
66.74	106.03	-0.076
66.76	106.20	-0.075
66.78	106.36	-0.076
66.79	106.53	-0.075
66.81	106.70	-0.075
66.83	106.86	-0.075
66.84	107.03	-0.075
66.86	107.20	-0.075
66.88	107.36	-0.075
66.89	107.53	-0.075
66.91	107.70	-0.075
66.93	107.86	-0.075
66.94	108.03	-0.075
66.96	108.20	-0.075
66.98	108.36	-0.075
66.99	108.53	-0.075
67.01	108.70	-0.075
67.03	108.86	-0.075
67.04	109.03	-0.075
67.06	109.20	-0.075
67.08	109.37	-0.075
67.09	109.53	-0.075
67.11	109.70	-0.075
67.13	109.87	-0.075
67.14	110.03	-0.075
67.16	110.20	-0.075
67.18	110.37	-0.074
67.19	110.53	-0.075
67.21	110.70	-0.075
67.23	110.87	-0.075
67.24	111.03	-0.075
67.26	111.20	-0.075
67.28	111.37	-0.075
67.29	111.53	-0.076
67.31	111.70	-0.076
67.33	111.87	-0.076
67.34	112.03	-0.076
67.36	112.20	-0.076
67.38	112.37	-0.076
67.39	112.53	-0.076
67.41	112.70	-0.077
67.43	112.87	-0.077
67.44	113.03	-0.077
67.46	113.20	-0.077
67.48	113.37	-0.077
67.49	113.53	-0.077
67.51	113.70	-0.077
67.53	113.87	-0.077
67.54	114.03	-0.077
67.56	114.20	-0.077
67.58	114.37	-0.077
67.59	114.54	-0.077
67.61	114.70	-0.078
67.63	114.87	-0.078
67.64	115.03	-0.078
67.66	115.20	-0.078
67.68	115.37	-0.078
67.69	115.54	-0.078
67.71	115.70	-0.078
67.73	115.87	-0.078
67.74	116.03	-0.078
67.76	116.20	-0.078
67.78	116.37	-0.078
67.79	116.54	-0.078
67.81	116.70	-0.078
67.83	116.87	-0.079
67.84	117.04	-0.079
67.86	117.20	-0.079
67.88	117.37	-0.079
67.89	117.54	-0.079
67.91	117.70	-0.079
67.93	117.87	-0.079
67.94	118.04	-0.079
67.96	118.20	-0.079
67.98	118.37	-0.079
67.99	118.54	-0.079
68.01	118.70	-0.079
68.03	118.87	-0.079
68.04	119.04	-0.080
68.06	119.20	-0.080
68.08	119.37	-0.080
68.09	119.54	-0.080
68.11	119.70	-0.080
68.13	119.87	-0.080
68.14	120.04	-0.080
68.16	120.20	-0.080
68.18	120.37	-0.080
68.19	120.54	-0.080
68.21	120.70	-0.080
68.23	120.87	-0.081
68.24	121.04	-0.081
68.26	121.21	-0.081
68.28	121.37	-0.081
68.29	121.54	-0.081
68.31	121.71	-0.081
68.33	121.87	-0.082
68.34	122.04	-0.082
68.36	122.21	-0.082
68.38	122.37	-0.082
68.39	122.54	-0.082
68.41	122.71	-0.082
68.43	122.87	-0.082
68.44	123.04	-0.082
68.46	123.21	-0.082
68.48	123.37	-0.082
68.49	123.54	-0.082
68.51	123.71	-0.082
68.53	123.87	-0.082
68.54	124.04	-0.082
68.56	124.21	-0.082
68.58	124.37	-0.082
68.59	124.54	-0.082
68.61	124.71	-0.082
68.63	124.87	-0.082
68.64	125.04	-0.083
68.66	125.21	-0.083
68.68	125.37	-0.083
68.69	125.54	-0.083
68.71	125.71	-0.083
68.73	125.87	-0.083
68.74	126.04	-0.082
68.76	126.21	-0.082
68.78	126.38	-0.083
68.79	126.54	-0.082
68.81	126.71	-0.082
68.83	126.88	-0.083
68.84	127.04	-0.083
68.86	127.21	-0.083
68.88	127.38	-0.082
68.89	127.54	-0.083
68.91	127.71	-0.083
68.93	127.88	-0.083
68.94	128.04	-0.083
68.96	128.21	-0.083
68.98	128.38	-0.083
68.99	128.54	-0.083
69.01	128.71	-0.083
69.03	128.88	-0.083
69.04	129.04	-0.083
69.06	129.21	-0.083
69.08	129.38	-0.083
69.09	129.54	-0.083
69.11	129.71	-0.084
69.13	129.88	-0.084
69.14	130.04	-0.084
69.16	130.21	-0.084
69.18	130.38	-0.084
69.19	130.55	-0.084
69.21	130.71	-0.084
69.23	130.88	-0.084
69.24	131.05	-0.084
69.26	131.21	-0.084
69.28	131.38	-0.084
69.29	131.55	-0.084
69.31	131.71	-0.084
69.33	131.88	-0.085
69.34	132.05	-0.085
69.36	132.21	-0.085
69.38	132.38	-0.085
69.39	132.55	-0.085
69.41	132.71	-0.085
69.43	132.88	-0.085
69.44	133.05	-0.085
69.46	133.21	-0.085
69.48	133.38	-0.085
69.49	133.55	-0.085
69.51	133.71	-0.085
69.53	133.88	-0.085
69.54	134.05	-0.085
69.56	134.21	-0.086
69.58	134.38	-0.086
69.59	134.55	-0.086
69.61	134.71	-0.086
69.63	134.88	-0.086
69.64	135.05	-0.086
69.66	135.21	-0.086
69.68	135.38	-0.086
69.69	135.55	-0.086
69.71	135.71	-0.086
69.73	135.88	-0.087
69.74	136.05	-0.086
69.76	136.22	-0.087
69.78	136.38	-0.086
69.79	136.55	-0.086
69.81	136.72	-0.086
69.83	136.88	-0.086
69.84	137.05	-0.086
69.86	137.21	-0.086
69.88	137.38	-0.087
69.89	137.55	-0.087
69.91	137.71	-0.087
69.93	137.88	-0.087
69.94	138.05	-0.087
69.96	138.22	-0.087
69.98	138.38	-0.087
69.99	138.55	-0.087
70.01	138.72	-0.087
70.03	138.88	-0.088
70.04	139.05	-0.087
70.06	139.22	-0.088
70.08	139.38	-0.088
70.09	139.55	-0.088
70.11	139.72	-0.088
70.13	139.88	-0.088
70.14	140.05	-0.088
70.16	140.22	-0.088
70.18	140.38	-0.088
70.19	140.55	-0.088
70.21	140.72	-0.088
70.23	140.88	-0.088
70.24	141.05	-0.088
70.26	141.22	-0.088
70.28	141.38	-0.088
70.29	141.55	-0.088
70.31	141.72	-0.088
70.33	141.88	-0.088
70.34	142.05	-0.088
70.36	142.22	-0.089
70.38	142.39	-0.088
70.39	142.55	-0.088
70.41	142.72	-0.088
70.43	142.88	-0.089
70.44	143.05	-0.088
70.46	143.22	-0.089
70.48	143.38	-0.089
70.49	143.55	-0.088
70.51	143.72	-0.088
70.53	143.88	-0.089
70.54	144.05	-0.089
70.56	144.22	-0.089
70.58	144.39	-0.089
70.59	144.55	-0.089
70.61	144.72	-0.089
70.63	144.89	-0.089
70.64	145.05	-0.089
70.66	145.22	-0.089
70.68	145.39	-0.089
70.69	145.55	-0.089
70.71	145.72	-0.089
70.73	145.89	-0.089
70.74	146.05	-0.089
70.76	146.22	-0.089
70.78	146.39	-0.089
70.79	146.55	-0.090
70.81	146.72	-0.090
70.83	146.89	-0.090
70.84	147.05	-0.090
70.86	147.22	-0.090
70.88	147.39	-0.090
70.89	147.55	-0.090
70.91	147.72	-0.089
70.93	147.89	-0.089
70.94	148.05	-0.089
70.96	148.22	-0.090
70.98	148.39	-0.090
70.99	148.55	-0.090
71.01	148.72	-0.090
71.03	148.89	-0.090
71.04	149.05	-0.090
71.06	149.22	-0.090
71.08	149.39	-0.090
71.09	149.55	-0.090
71.11	149.72	-0.090
71.13	149.89	-0.090
71.14	150.05	-0.090
71.16	150.22	-0.090
71.18	150.39	-0.090
71.19	150.55	-0.090
71.21	150.72	-0.090
71.23	150.89	-0.091
71.24	151.05	-0.091
71.26	151.22	-0.091
71.28	151.39	-0.090
71.29	151.55	-0.091
71.31	151.72	-0.091
71.33	151.89	-0.091
71.34	152.06	-0.091
71.36	152.22	-0.091
71.38	152.39	-0.091
71.39	152.56	-0.091
71.41	152.72	-0.091
71.43	152.89	-0.091
71.44	153.06	-0.091
71.46	153.22	-0.091
71.48	153.39	-0.091
71.49	153.56	-0.091
71.51	153.72	-0.091
71.53	153.89	-0.091
71.54	154.06	-0.091
71.56	154.22	-0.091
71.58	154.39	-0.092
71.59	154.56	-0.092
71.61	154.72	-0.092
71.63	154.89	-0.092
71.64	155.06	-0.092
71.66	155.22	-0.092
71.68	155.39	-0.092
71.69	155.56	-0.092
71.71	155.72	-0.093
71.73	155.89	-0.093
71.74	156.06	-0.093
71.76	156.22	-0.093
71.78	156.39	-0.093
71.79	156.56	-0.093
71.81	156.73	-0.093
71.83	156.89	-0.093
71.84	157.06	-0.093
71.86	157.23	-0.094
71.88	157.39	-0.093
71.89	157.56	-0.094
71.91	157.72	-0.094
71.93	157.89	-0.094
71.94	158.06	-0.094
71.96	158.23	-0.094
71.98	158.39	-0.094
71.99	158.56	-0.094
72.01	158.73	-0.094
72.03	158.89	-0.094
72.04	159.06	-0.094
72.06	159.23	-0.094
72.08	159.39	-0.094
72.09	159.56	-0.095
72.11	159.73	-0.095
72.13	159.89	-0.095
72.14	160.06	-0.095
72.16	160.23	-0.094
72.18	160.39	-0.095
72.19	160.56	-0.095
72.21	160.73	-0.095
72.23	160.89	-0.095
72.24	161.06	-0.095
72.26	161.23	-0.095
72.28	161.39	-0.095
72.29	161.56	-0.095
72.31	161.73	-0.095
72.33	161.89	-0.096
72.34	162.06	-0.095
72.36	162.23	-0.095
72.38	162.39	-0.095
72.39	162.56	-0.095
72.41	162.73	-0.095
72.43	162.89	-0.095
72.44	163.06	-0.096
72.46	163.23	-0.096
72.48	163.39	-0.096
72.49	163.56	-0.096
72.51	163.73	-0.096
72.53	163.89	-0.096
72.54	164.06	-0.097
72.56	164.23	-0.096
72.58	164.40	-0.096
72.59	164.56	-0.096
72.61	164.73	-0.096
72.63	164.89	-0.096
72.64	165.06	-0.096
72.66	165.23	-0.096
72.68	165.40	-0.096
72.69	165.56	-0.097
72.71	165.73	-0.097
72.73	165.90	-0.097
72.74	166.06	-0.098
72.76	166.23	-0.098
72.78	166.40	-0.098
72.79	166.56	-0.098
72.81	166.73	-0.098
72.83	166.90	-0.098
72.84	167.06	-0.097
72.86	167.23	-0.097
72.88	167.40	-0.097
72.89	167.56	-0.097
72.91	167.73	-0.097
72.93	167.90	-0.097
72.94	168.06	-0.097
72.96	168.23	-0.097
72.98	168.40	-0.097
72.99	168.56	-0.097
73.01	168.73	-0.097
73.03	168.90	-0.097
73.04	169.06	-0.097
73.06	169.23	-0.097
73.08	169.40	-0.097
73.09	169.56	-0.098
73.11	169.73	-0.098
73.13	169.90	-0.098
73.14	170.06	-0.098
73.16	170.23	-0.098
73.18	170.40	-0.098
73.19	170.57	-0.099
73.21	170.73	-0.099
73.23	170.90	-0.099
73.24	171.07	-0.099
73.26	171.23	-0.099
73.28	171.40	-0.099
73.29	171.57	-0.099
73.31	171.73	-0.099
73.33	171.90	-0.099
73.34	172.07	-0.099
73.36	172.23	-0.099
73.38	172.40	-0.100
73.39	172.57	-0.099
73.41	172.73	-0.100
73.43	172.90	-0.100
73.44	173.07	-0.100
73.46	173.23	-0.100
73.48	173.40	-0.101
73.49	173.57	-0.101
73.51	173.73	-0.101
73.53	173.90	-0.101
73.54	174.07	-0.101
73.56	174.23	-0.101
73.58	174.40	-0.101
73.59	174.57	-0.101
73.61	174.73	-0.101
73.63	174.90	-0.101
73.64	175.07	-0.101
73.66	175.23	-0.101
73.68	175.40	-0.101
73.69	175.57	-0.101
73.71	175.73	-0.102
73.73	175.90	-0.102
73.74	176.07	-0.102
73.76	176.23	-0.102
73.78	176.40	-0.102
73.79	176.57	-0.102
73.81	176.73	-0.102
73.83	176.90	-0.102
73.84	177.07	-0.102
73.86	177.23	-0.102
73.88	177.40	-0.102
73.89	177.57	-0.102
73.91	177.73	-0.102
73.93	177.90	-0.102
73.94	178.07	-0.102
73.96	178.23	-0.103
73.98	178.40	-0.103
73.99	178.57	-0.103
74.01	178.73	-0.103
74.03	178.90	-0.103
74.04	179.07	-0.103
74.06	179.23	-0.104
74.08	179.40	-0.104
74.09	179.57	-0.103
74.11	179.74	-0.103
74.13	179.90	-0.104
74.14	180.07	-0.104
74.16	180.23	-0.103
74.18	180.40	-0.104
74.19	180.57	-0.104
74.21	180.73	-0.104
74.23	180.90	-0.104
74.24	181.07	-0.104
74.26	181.24	-0.104
74.28	181.40	-0.104
74.29	181.57	-0.104
74.31	181.74	-0.104
74.33	181.90	-0.104
74.34	182.07	-0.104
74.36	182.24	-0.104
74.38	182.40	-0.105
74.39	182.57	-0.105
74.41	182.74	-0.105
74.43	182.90	-0.105
74.44	183.07	-0.105
74.46	183.24	-0.105
74.48	183.40	-0.105
74.49	183.57	-0.105
74.51	183.74	-0.105
74.53	183.90	-0.105
74.54	184.07	-0.105
74.56	184.24	-0.105
74.58	184.40	-0.106
74.59	184.57	-0.106
74.61	184.74	-0.106
74.63	184.90	-0.106
74.64	185.07	-0.106
74.66	185.24	-0.106
74.68	185.41	-0.106
74.69	185.57	-0.106
74.71	185.74	-0.105
74.73	185.91	-0.105
74.74	186.07	-0.105
74.76	186.24	-0.105
74.78	186.41	-0.105
74.79	186.57	-0.105
74.81	186.74	-0.106
74.83	186.90	-0.106
74.84	187.07	-0.106
74.86	187.24	-0.106
74.88	187.40	-0.107
74.89	187.57	-0.106
74.91	187.74	-0.107
74.93	187.90	-0.106
74.94	188.07	-0.107
74.96	188.24	-0.107
74.98	188.41	-0.107
74.99	188.57	-0.107
75.01	188.74	-0.108
75.03	188.91	-0.108
75.04	189.07	-0.108
75.06	189.24	-0.108
75.08	189.41	-0.108
75.09	189.57	-0.108
75.11	189.74	-0.108
75.13	189.91	-0.108
75.14	190.07	-0.108
75.16	190.24	-0.108
75.18	190.41	-0.108
75.19	190.57	-0.108
75.21	190.74	-0.108
75.23	190.91	-0.108
75.24	191.07	-0.108
75.26	191.24	-0.108
75.28	191.41	-0.108
75.29	191.57	-0.108
75.31	191.74	-0.108
75.33	191.91	-0.108
75.34	192.07	-0.109
75.36	192.24	-0.109
75.38	192.41	-0.108
75.39	192.57	-0.109
75.41	192.74	-0.109
75.43	192.91	-0.109
75.44	193.07	-0.109
75.46	193.24	-0.109
75.48	193.41	-0.109
75.49	193.57	-0.109
75.51	193.74	-0.109
75.53	193.91	-0.109
75.54	194.07	-0.110
75.56	194.24	-0.110
75.58	194.41	-0.110
75.59	194.57	-0.110
75.61	194.74	-0.110
75.63	194.91	-0.110
75.64	195.07	-0.110
75.66	195.24	-0.109
75.68	195.41	-0.109
75.69	195.57	-0.109
75.71	195.74	-0.109
75.73	195.91	-0.110
75.74	196.07	-0.110
75.76	196.24	-0.110
75.78	196.41	-0.110
75.79	196.57	-0.110
75.81	196.74	-0.110
75.83	196.91	-0.110
75.84	197.08	-0.111
75.86	197.24	-0.111
75.88	197.41	-0.111
75.89	197.58	-0.111
75.91	197.74	-0.111
75.93	197.91	-0.111
75.94	198.08	-0.111
75.96	198.24	-0.111
75.98	198.41	-0.111
75.99	198.58	-0.111
76.01	198.74	-0.111
76.03	198.91	-0.111
76.04	199.07	-0.111
76.06	199.24	-0.112
76.08	199.41	-0.112
76.09	199.57	-0.112
76.11	199.74	-0.112
76.13	199.91	-0.112
76.14	200.08	-0.112
76.16	200.24	-0.112
76.18	200.41	-0.112
76.19	200.58	-0.112
76.21	200.74	-0.112
76.23	200.91	-0.112
76.24	201.08	-0.113
76.26	201.24	-0.113
76.28	201.41	-0.113
76.29	201.58	-0.113
76.31	201.74	-0.113
76.33	201.91	-0.113
76.34	202.08	-0.113
76.36	202.24	-0.113
76.38	202.41	-0.113
76.39	202.58	-0.113
76.41	202.74	-0.113
76.43	202.91	-0.114
76.44	203.08	-0.114
76.46	203.24	-0.114
76.48	203.41	-0.115
76.49	203.58	-0.115
76.51	203.75	-0.115
76.53	203.91	-0.115
76.54	204.08	-0.115
76.56	204.25	-0.115
76.58	204.41	-0.115
76.59	204.58	-0.114
76.61	204.75	-0.114
76.63	204.91	-0.114
76.64	205.08	-0.114
76.66	205.25	-0.114
76.68	205.41	-0.114
76.69	205.58	-0.114
76.71	205.74	-0.115
76.73	205.91	-0.115
76.74	206.08	-0.115
76.76	206.24	-0.115
76.78	206.41	-0.115
76.79	206.58	-0.115
76.81	206.75	-0.116
76.83	206.91	-0.116
76.84	207.08	-0.116
76.86	207.25	-0.116
76.88	207.41	-0.116
76.89	207.58	-0.116
76.91	207.74	-0.116
76.93	207.91	-0.116
76.94	208.08
76.96	208.25
76.98	208.41
76.99