File: Data/2024_09_19_Empty_CHM343_DSC.txt
Filename	2024_09_19_Empty_CHM343_DSC
Instrument name	DSC2A-00468 (192.168.1.100)
Operator	CHM343
rundate	9/19/2024
Sample name	2024_09_19_Empty_CHM343_DSC
proceduresegments	Equilibrate 30.00 °C; Ramp 10.00 °C/min to 220.00 °C; Isothermal 1.0 min; Ramp 10.00 °C/min to 30.00 °C
[File Parameters]
Run date	9/19/2024 7:22:15 PM
Trios version	5.1.1.46572
Original File Name
Current File Name	C:\ProgramData\TA Instruments\TRIOS\Data\2024_09_19_Empty_CHM343_DSC.tri
[Procedure]
Procedure Name	CHM343_Fall2024_Empty
Sample Name	2024_09_19_Empty_CHM343_DSC
Sample Mass	0 mg
Reference Sample Mass	0 mg
Pan Mass	54.56 mg
Pan Number	24
Reference Pan Mass	54 mg
Reference Pan Number	19
Pan Type	Aluminum
Comments	Empty- Al Hermetic Sealed Pan, with ref Al pan.  ASU Online CHM343, Remote DSC experimental lab. Fall 2024.  Group Zoom Data Collection, Sept 19, 2024 from 5-7 pm.  TA Instruments DSC2500.
Project Name	Lab 4 - Fall 2024
Operator	CHM343
Test	Custom
Unload Max Temperature	30
Unload Min Temperature	30
Load Max Temperature	30
Load Min Temperature	30
Stop on Gas Flow Error	Yes
[Signal List]
Signal #1	Time (min)
Signal #2	Temperature (°C)
Signal #3	Heat Flow (mW)
Signal #4	Delta T (µV)
Signal #5	Delta Tzero (µV)
Signal #6	Tzero Temperature (°C)
Signal #7	Cell Purge (mL/min)
Signal #8	Heater Temp (°C)
Signal #9	Power Delivered (W)
Signal #10	Reference Junction Temperature (°C)
Signal #11	Flange Temperature (°C)
Signal #12	Heat Flow Phase (rad)
Signal #13	Total Heat Capacity (J/°C)
Signal #14	Heat Capacity (J/°C)
[Configuration]
Company Name	ASU
Instrument Name	DSC2A-00468
Instrument Type	DSC2500
Serial Number	DSC2A-00468
IP	192.168.1.100
Location of Instrument	MRRC
DisplayType	Unknown
Sample Interval 	0.1 s/pt
Selected Heat Flow	T4P
Exotherm Direction	Down
Cell Serial	DRC2-00792
Lid Type	Standard
Cooler	RCS 90
Leave Cooler on at End of Sequence	On
Gas 2	Nitrogen
Gas Selected	Channel 1
Flow Rate	50 mL/min
Secondary Purge	On
Licensed Heat Flow	Heat Flow T4P
Modulation Licensed	Yes
[Versions]
Common IDD Version	1
Cortex Version	VER 2.10.2.31
Driver	5.0.0.6
GDM Version	1.0.3.3
TouchscreenVersion	1.0.0.16145
FEP Version	1.2.1.21
FEP Bootloader	2.0.0.5
AutoSampler Version	2.1.1.26
Auto Sampler Bootloader	2.0.0.5
FCM Version	1.1.0.3
FCM Bootloader	2.0.0.5
[Experiment Logs]
Experiment Log Entry # 1	Equilibrate Segment 30 (C) Started
Experiment Log Entry # 3	Air Cool is off.
Experiment Log Entry # 5	Ramp Segment 10 C/min to 220 Started
Experiment Log Entry # 7	Auto sampler has detected that FEP has gone offline
Experiment Log Entry # 9	Isothermal Segment 1 min started
Experiment Log Entry # 11	Ramp Segment 10 C/min to 30 Started
Experiment Log Entry # 13	Auto sampler has detected that FEP has gone offline
[Method Log]
Method Log Entry # 1	Equilibrate 30 °C
Method Log Entry # 2	(Ramp 19911) Ramp 10 °C/minute to 220 °C
Method Log Entry # 3	Isothermal 1 minutes
Method Log Entry # 4	(Ramp 19913) Ramp 10 °C/minute to 30 °C
Cell Serial	DRC2-00792
[T1 Calibration]
Slope	-0.008529666
Offset	9.636258
Initial Temperature	98.23
GUID	f8bfdadc-4977-4fdf-ba6d-0ba9134940c3
[TZero Calibration]
Date Applied	11/29/2022 4:06:13 PM
Description	From -89.059 °C to 396.009 °C at 20.000°C/min
Gas Type	Nitrogen
Pan Type	None
Source Files 1	C:\Users\yargerlab\Desktop\DSC Data\General\TZero_calibration_11_29_22_2nd(2).tri
Source Files 2	C:\Users\yargerlab\Desktop\DSC Data\General\TZero_calibration_11_29_22_2nd(3).tri
Delta T Offset	13.05235
Delta T Slope	-0.007271007
Delta T0 Offset	-13.69128
Delta T0 Slope	0.06063341
[Temperature Calibration]
Date Applied	11/29/2022 7:12:28 PM
Description	From 106.590 °C to 186.590 °C at 10.000°C/min
Gas Type	Nitrogen
Pan Type	Tzero Aluminum Hermetic
Source Files 1	C:\Users\yargerlab\Desktop\DSC Data\General\Indium(6).tri
Measured 1	157.391
Known 1	156.598
[Cell Constant Calibration]
Date Applied	11/29/2022 7:12:29 PM
Description	From 106.590 °C to 186.590 °C at 10.000°C/min
Gas Type	Nitrogen
Pan Type	Tzero Aluminum Hermetic
Source Files 1	C:\Users\yargerlab\Desktop\DSC Data\General\Indium(6).tri
T4P KCell	1.006051
Onset Slope	63.26126 mW/°C
[Direct Cp Calibration]
Date Applied	11/30/2022 11:04:51 AM
Description	From -79.983 °C to 298.409 °C at 10.000°C/min
Gas Type	Nitrogen
Pan Type	Tzero Aluminum Hermetic
Source Files 1	C:\Users\yargerlab\Desktop\DSC Data\General\Sapphire_Heat_Capacity_11_30_22.tri
[Rev Cp Calibration]
Date Applied	11/30/2022 1:58:51 PM
Description	From -79.996 °C to 292.812 °C at 3.000°C/min
Gas Type	Nitrogen
Pan Type	Tzero Aluminum Hermetic
Source Files 1	C:\Users\yargerlab\Desktop\DSC Data\General\Sapphire_MDSC_Calibration_11_30_22.tri
[step]
Ramp 10.00 °C/min to 220.00 °C
Time	Temperature	Heat Flow (Normalized)
min	°C	W/g
0.00	30.08
0.01	30.08
0.03	30.08
0.04	30.09
0.05	30.10
0.07	30.12
0.08	30.15
0.09	30.19
0.11	30.24
0.12	30.31
0.13	30.38
0.15	30.47
0.16	30.56
0.17	30.66
0.19	30.77
0.20	30.87
0.21	30.98
0.23	31.09
0.24	31.21
0.25	31.32
0.27	31.44
0.28	31.56
0.29	31.68
0.31	31.81
0.32	31.93
0.33	32.06
0.35	32.18
0.36	32.31
0.37	32.44
0.39	32.56
0.40	32.69
0.41	32.82
0.43	32.95
0.44	33.08
0.45	33.21
0.47	33.34
0.48	33.47
0.49	33.60
0.51	33.73
0.52	33.87
0.53	33.99
0.55	34.13
0.56	34.26
0.57	34.39
0.59	34.52
0.60	34.65
0.61	34.78
0.63	34.92
0.64	35.05
0.65	35.18
0.67	35.31
0.68	35.44
0.69	35.58
0.71	35.71
0.72	35.84
0.73	35.97
0.75	36.10
0.76	36.24
0.77	36.37
0.79	36.50
0.80	36.63
0.81	36.77
0.83	36.90
0.84	37.03
0.85	37.16
0.87	37.30
0.88	37.43
0.89	37.56
0.91	37.69
0.92	37.82
0.93	37.96
0.95	38.09
0.96	38.22
0.97	38.36
0.99	38.49
1.00	38.62
1.01	38.75
1.03	38.89
1.04	39.02
1.05	39.15
1.07	39.29
1.08	39.42
1.09	39.55
1.11	39.68
1.12	39.82
1.13	39.95
1.15	40.08
1.16	40.21
1.17	40.35
1.19	40.48
1.20	40.61
1.21	40.75
1.23	40.88
1.24	41.01
1.25	41.15
1.27	41.28
1.28	41.41
1.29	41.55
1.31	41.68
1.32	41.81
1.33	41.95
1.35	42.08
1.36	42.21
1.37	42.34
1.39	42.48
1.40	42.61
1.41	42.74
1.43	42.88
1.44	43.01
1.45	43.14
1.47	43.28
1.48	43.41
1.49	43.54
1.51	43.68
1.52	43.81
1.53	43.94
1.55	44.08
1.56	44.21
1.57	44.34
1.59	44.48
1.60	44.61
1.61	44.74
1.63	44.88
1.64	45.01
1.65	45.14
1.67	45.28
1.68	45.41
1.69	45.54
1.71	45.68
1.72	45.81
1.73	45.94
1.75	46.08
1.76	46.21
1.77	46.34
1.79	46.48
1.80	46.61
1.81	46.74
1.83	46.88
1.84	47.01
1.85	47.14
1.87	47.28
1.88	47.41
1.89	47.54
1.91	47.68
1.92	47.81
1.93	47.94
1.95	48.08
1.96	48.21
1.97	48.34
1.99	48.48
2.00	48.61
2.01	48.74
2.03	48.88
2.04	49.01
2.05	49.14
2.07	49.28
2.08	49.41
2.09	49.54
2.11	49.68
2.12	49.81
2.13	49.94
2.15	50.08
2.16	50.21
2.17	50.34
2.19	50.48
2.20	50.61
2.21	50.74
2.23	50.88
2.24	51.01
2.25	51.15
2.27	51.28
2.28	51.41
2.29	51.54
2.31	51.68
2.32	51.81
2.33	51.94
2.35	52.08
2.36	52.21
2.37	52.34
2.39	52.48
2.40	52.61
2.41	52.75
2.43	52.88
2.44	53.01
2.45	53.14
2.47	53.28
2.48	53.41
2.49	53.54
2.51	53.68
2.52	53.81
2.53	53.95
2.55	54.08
2.56	54.21
2.57	54.35
2.59	54.48
2.60	54.61
2.61	54.75
2.63	54.88
2.64	55.01
2.65	55.15
2.67	55.28
2.68	55.41
2.69	55.55
2.71	55.68
2.72	55.81
2.73	55.95
2.75	56.08
2.76	56.22
2.77	56.35
2.79	56.48
2.80	56.62
2.81	56.75
2.83	56.88
2.84	57.02
2.85	57.15
2.87	57.28
2.88	57.42
2.89	57.55
2.91	57.68
2.92	57.82
2.93	57.95
2.95	58.08
2.96	58.22
2.97	58.35
2.99	58.48
3.00	58.62
3.01	58.75
3.03	58.88
3.04	59.02
3.05	59.15
3.07	59.28
3.08	59.42
3.09	59.55
3.11	59.68
3.12	59.82
3.13	59.95
3.15	60.09
3.16	60.22
3.17	60.35
3.19	60.48
3.20	60.62
3.21	60.75
3.23	60.89
3.24	61.02
3.25	61.15
3.27	61.29
3.28	61.42
3.29	61.55
3.31	61.68
3.32	61.82
3.33	61.95
3.35	62.09
3.36	62.22
3.37	62.35
3.39	62.49
3.40	62.62
3.41	62.75
3.43	62.89
3.44	63.02
3.45	63.15
3.47	63.29
3.48	63.42
3.49	63.55
3.51	63.69
3.52	63.82
3.53	63.95
3.55	64.09
3.56	64.22
3.57	64.35
3.59	64.49
3.60	64.62
3.61	64.75
3.63	64.89
3.64	65.02
3.65	65.15
3.67	65.29
3.68	65.42
3.69	65.56
3.71	65.69
3.72	65.82
3.73	65.96
3.75	66.09
3.76	66.22
3.77	66.36
3.79	66.49
3.80	66.62
3.81	66.76
3.83	66.89
3.84	67.02
3.85	67.16
3.87	67.29
3.88	67.42
3.89	67.56
3.91	67.69
3.92	67.82
3.93	67.96
3.95	68.09
3.96	68.23
3.97	68.36
3.99	68.49
4.00	68.62
4.01	68.76
4.03	68.89
4.04	69.02
4.05	69.16
4.07	69.29
4.08	69.43
4.09	69.56
4.11	69.69
4.12	69.83
4.13	69.96
4.15	70.09
4.16	70.23
4.17	70.36
4.19	70.49
4.20	70.63
4.21	70.76
4.23	70.89
4.24	71.03
4.25	71.16
4.27	71.29
4.28	71.43
4.29	71.56
4.31	71.70
4.32	71.83
4.33	71.96
4.35	72.09
4.36	72.23
4.37	72.36
4.39	72.49
4.40	72.63
4.41	72.76
4.43	72.90
4.44	73.03
4.45	73.16
4.47	73.30
4.48	73.43
4.49	73.56
4.51	73.70
4.52	73.83
4.53	73.96
4.55	74.10
4.56	74.23
4.57	74.36
4.59	74.50
4.60	74.63
4.61	74.76
4.63	74.90
4.64	75.03
4.65	75.16
4.67	75.30
4.68	75.43
4.69	75.56
4.71	75.70
4.72	75.83
4.73	75.96
4.75	76.10
4.76	76.23
4.77	76.37
4.79	76.50
4.80	76.63
4.81	76.77
4.83	76.90
4.84	77.03
4.85	77.17
4.87	77.30
4.88	77.43
4.89	77.57
4.91	77.70
4.92	77.83
4.93	77.97
4.95	78.10
4.96	78.23
4.97	78.37
4.99	78.50
5.00	78.63
5.01	78.77
5.03	78.90
5.04	79.03
5.05	79.17
5.07	79.30
5.08	79.43
5.09	79.57
5.11	79.70
5.12	79.84
5.13	79.97
5.15	80.10
5.16	80.24
5.17	80.37
5.19	80.50
5.20	80.63
5.21	80.77
5.23	80.90
5.24	81.04
5.25	81.17
5.27	81.30
5.28	81.44
5.29	81.57
5.31	81.70
5.32	81.84
5.33	81.97
5.35	82.10
5.36	82.24
5.37	82.37
5.39	82.50
5.40	82.64
5.41	82.77
5.43	82.90
5.44	83.04
5.45	83.17
5.47	83.30
5.48	83.44
5.49	83.57
5.51	83.70
5.52	83.84
5.53	83.97
5.55	84.10
5.56	84.24
5.57	84.37
5.59	84.50
5.60	84.64
5.61	84.77
5.63	84.91
5.64	85.04
5.65	85.17
5.67	85.31
5.68	85.44
5.69	85.57
5.71	85.71
5.72	85.84
5.73	85.97
5.75	86.11
5.76	86.24
5.77	86.37
5.79	86.51
5.80	86.64
5.81	86.77
5.83	86.91
5.84	87.04
5.85	87.17
5.87	87.31
5.88	87.44
5.89	87.57
5.91	87.71
5.92	87.84
5.93	87.97
5.95	88.11
5.96	88.24
5.97	88.37
5.99	88.51
6.00	88.64
6.01	88.77
6.03	88.91
6.04	89.04
6.05	89.17
6.07	89.31
6.08	89.44
6.09	89.57
6.11	89.71
6.12	89.84
6.13	89.98
6.15	90.11
6.16	90.24
6.17	90.38
6.19	90.51
6.20	90.64
6.21	90.78
6.23	90.91
6.24	91.04
6.25	91.18
6.27	91.31
6.28	91.44
6.29	91.57
6.31	91.71
6.32	91.84
6.33	91.98
6.35	92.11
6.36	92.24
6.37	92.38
6.39	92.51
6.40	92.64
6.41	92.78
6.43	92.91
6.44	93.04
6.45	93.18
6.47	93.31
6.48	93.44
6.49	93.58
6.51	93.71
6.52	93.85
6.53	93.98
6.55	94.11
6.56	94.25
6.57	94.38
6.59	94.51
6.60	94.65
6.61	94.78
6.63	94.91
6.64	95.05
6.65	95.18
6.67	95.31
6.68	95.45
6.69	95.58
6.71	95.71
6.72	95.85
6.73	95.98
6.75	96.11
6.76	96.25
6.77	96.38
6.79	96.51
6.80	96.65
6.81	96.78
6.83	96.91
6.84	97.05
6.85	97.18
6.87	97.31
6.88	97.45
6.89	97.58
6.91	97.71
6.92	97.85
6.93	97.98
6.95	98.11
6.96	98.25
6.97	98.38
6.99	98.51
7.00	98.65
7.01	98.78
7.03	98.91
7.04	99.05
7.05	99.18
7.07	99.32
7.08	99.45
7.09	99.58
7.11	99.72
7.12	99.85
7.13	99.98
7.15	100.11
7.16	100.25
7.17	100.38
7.19	100.52
7.20	100.65
7.21	100.78
7.23	100.92
7.24	101.05
7.25	101.18
7.27	101.32
7.28	101.45
7.29	101.58
7.31	101.72
7.32	101.85
7.33	101.98
7.35	102.12
7.36	102.25
7.37	102.38
7.39	102.52
7.40	102.65
7.41	102.78
7.43	102.92
7.44	103.05
7.45	103.18
7.47	103.32
7.48	103.45
7.49	103.58
7.51	103.72
7.52	103.85
7.53	103.99
7.55	104.12
7.56	104.25
7.57	104.39
7.59	104.52
7.60	104.65
7.61	104.79
7.63	104.92
7.64	105.05
7.65	105.19
7.67	105.32
7.68	105.45
7.69	105.59
7.71	105.72
7.72	105.85
7.73	105.99
7.75	106.12
7.76	106.25
7.77	106.39
7.79	106.52
7.80	106.65
7.81	106.79
7.83	106.92
7.84	107.05
7.85	107.19
7.87	107.32
7.88	107.45
7.89	107.59
7.91	107.72
7.92	107.85
7.93	107.99
7.95	108.12
7.96	108.25
7.97	108.39
7.99	108.52
8.00	108.66
8.01	108.79
8.03	108.92
8.04	109.06
8.05	109.19
8.07	109.32
8.08	109.45
8.09	109.59
8.11	109.72
8.12	109.86
8.13	109.99
8.15	110.12
8.16	110.25
8.17	110.39
8.19	110.52
8.20	110.66
8.21	110.79
8.23	110.92
8.24	111.06
8.25	111.19
8.27	111.32
8.28	111.46
8.29	111.59
8.31	111.72
8.32	111.86
8.33	111.99
8.35	112.12
8.36	112.26
8.37	112.39
8.39	112.52
8.40	112.66
8.41	112.79
8.43	112.92
8.44	113.06
8.45	113.19
8.47	113.32
8.48	113.46
8.49	113.59
8.51	113.72
8.52	113.86
8.53	113.99
8.55	114.13
8.56	114.26
8.57	114.39
8.59	114.52
8.60	114.66
8.61	114.79
8.63	114.93
8.64	115.06
8.65	115.19
8.67	115.33
8.68	115.46
8.69	115.59
8.71	115.73
8.72	115.86
8.73	115.99
8.75	116.12
8.76	116.26
8.77	116.39
8.79	116.53
8.80	116.66
8.81	116.79
8.83	116.93
8.84	117.06
8.85	117.19
8.87	117.33
8.88	117.46
8.89	117.59
8.91	117.73
8.92	117.86
8.93	117.99
8.95	118.13
8.96	118.26
8.97	118.39
8.99	118.53
9.00	118.66
9.01	118.79
9.03	118.93
9.04	119.06
9.05	119.19
9.07	119.33
9.08	119.46
9.09	119.59
9.11	119.73
9.12	119.86
9.13	119.99
9.15	120.13
9.16	120.26
9.17	120.39
9.19	120.53
9.20	120.66
9.21	120.80
9.23	120.93
9.24	121.06
9.25	121.20
9.27	121.33
9.28	121.46
9.29	121.60
9.31	121.73
9.32	121.86
9.33	122.00
9.35	122.13
9.36	122.26
9.37	122.40
9.39	122.53
9.40	122.66
9.41	122.80
9.43	122.93
9.44	123.06
9.45	123.20
9.47	123.33
9.48	123.46
9.49	123.60
9.51	123.73
9.52	123.86
9.53	124.00
9.55	124.13
9.56	124.26
9.57	124.40
9.59	124.53
9.60	124.67
9.61	124.80
9.63	124.93
9.64	125.06
9.65	125.20
9.67	125.33
9.68	125.46
9.69	125.60
9.71	125.73
9.72	125.87
9.73	126.00
9.75	126.13
9.76	126.26
9.77	126.40
9.79	126.53
9.80	126.67
9.81	126.80
9.83	126.93
9.84	127.07
9.85	127.20
9.87	127.33
9.88	127.47
9.89	127.60
9.91	127.73
9.92	127.87
9.93	128.00
9.95	128.13
9.96	128.27
9.97	128.40
9.99	128.53
10.00	128.67
10.01	128.80
10.03	128.93
10.04	129.07
10.05	129.20
10.07	129.33
10.08	129.47
10.09	129.60
10.11	129.73
10.12	129.87
10.13	130.00
10.15	130.14
10.16	130.27
10.17	130.40
10.19	130.53
10.20	130.67
10.21	130.80
10.23	130.93
10.24	131.07
10.25	131.20
10.27	131.33
10.28	131.47
10.29	131.60
10.31	131.74
10.32	131.87
10.33	132.00
10.35	132.14
10.36	132.27
10.37	132.40
10.39	132.54
10.40	132.67
10.41	132.80
10.43	132.94
10.44	133.07
10.45	133.20
10.47	133.34
10.48	133.47
10.49	133.60
10.51	133.74
10.52	133.87
10.53	134.00
10.55	134.14
10.56	134.27
10.57	134.40
10.59	134.54
10.60	134.67
10.61	134.80
10.63	134.94
10.64	135.07
10.65	135.20
10.67	135.34
10.68	135.47
10.69	135.60
10.71	135.74
10.72	135.87
10.73	136.01
10.75	136.14
10.76	136.27
10.77	136.40
10.79	136.54
10.80	136.67
10.81	136.80
10.83	136.94
10.84	137.07
10.85	137.20
10.87	137.34
10.88	137.47
10.89	137.60
10.91	137.74
10.92	137.87
10.93	138.00
10.95	138.14
10.96	138.27
10.97	138.40
10.99	138.54
11.00	138.67
11.01	138.81
11.03	138.94
11.04	139.07
11.05	139.21
11.07	139.34
11.08	139.47
11.09	139.61
11.11	139.74
11.12	139.87
11.13	140.01
11.15	140.14
11.16	140.27
11.17	140.41
11.19	140.54
11.20	140.67
11.21	140.81
11.23	140.94
11.24	141.07
11.25	141.21
11.27	141.34
11.28	141.47
11.29	141.61
11.31	141.74
11.32	141.87
11.33	142.01
11.35	142.14
11.36	142.27
11.37	142.41
11.39	142.54
11.40	142.67
11.41	142.81
11.43	142.94
11.44	143.07
11.45	143.21
11.47	143.34
11.48	143.47
11.49	143.61
11.51	143.74
11.52	143.87
11.53	144.01
11.55	144.14
11.56	144.28
11.57	144.41
11.59	144.54
11.60	144.68
11.61	144.81
11.63	144.94
11.64	145.08
11.65	145.21
11.67	145.34
11.68	145.48
11.69	145.61
11.71	145.74
11.72	145.88
11.73	146.01
11.75	146.14
11.76	146.28
11.77	146.41
11.79	146.54
11.80	146.68
11.81	146.81
11.83	146.94
11.84	147.08
11.85	147.21
11.87	147.34
11.88	147.48
11.89	147.61
11.91	147.74
11.92	147.88
11.93	148.01
11.95	148.14
11.96	148.28
11.97	148.41
11.99	148.55
12.00	148.68
12.01	148.81
12.03	148.94
12.04	149.08
12.05	149.21
12.07	149.34
12.08	149.48
12.09	149.61
12.11	149.74
12.12	149.88
12.13	150.01
12.15	150.14
12.16	150.28
12.17	150.41
12.19	150.54
12.20	150.68
12.21	150.81
12.23	150.94
12.24	151.08
12.25	151.21
12.27	151.35
12.28	151.48
12.29	151.61
12.31	151.75
12.32	151.88
12.33	152.01
12.35	152.15
12.36	152.28
12.37	152.41
12.39	152.55
12.40	152.68
12.41	152.81
12.43	152.95
12.44	153.08
12.45	153.21
12.47	153.35
12.48	153.48
12.49	153.61
12.51	153.75
12.52	153.88
12.53	154.01
12.55	154.15
12.56	154.28
12.57	154.41
12.59	154.55
12.60	154.68
12.61	154.81
12.63	154.95
12.64	155.08
12.65	155.21
12.67	155.35
12.68	155.48
12.69	155.61
12.71	155.75
12.72	155.88
12.73	156.01
12.75	156.15
12.76	156.28
12.77	156.41
12.79	156.55
12.80	156.68
12.81	156.81
12.83	156.95
12.84	157.08
12.85	157.22
12.87	157.35
12.88	157.48
12.89	157.61
12.91	157.75
12.92	157.88
12.93	158.02
12.95	158.15
12.96	158.28
12.97	158.41
12.99	158.55
13.00	158.68
13.01	158.82
13.03	158.95
13.04	159.08
13.05	159.22
13.07	159.35
13.08	159.48
13.09	159.61
13.11	159.75
13.12	159.88
13.13	160.01
13.15	160.15
13.16	160.28
13.17	160.41
13.19	160.55
13.20	160.68
13.21	160.82
13.23	160.95
13.24	161.08
13.25	161.22
13.27	161.35
13.28	161.48
13.29	161.62
13.31	161.75
13.32	161.88
13.33	162.02
13.35	162.15
13.36	162.28
13.37	162.42
13.39	162.55
13.40	162.68
13.41	162.82
13.43	162.95
13.44	163.08
13.45	163.22
13.47	163.35
13.48	163.48
13.49	163.62
13.51	163.75
13.52	163.88
13.53	164.02
13.55	164.15
13.56	164.28
13.57	164.42
13.59	164.55
13.60	164.68
13.61	164.82
13.63	164.95
13.64	165.08
13.65	165.22
13.67	165.35
13.68	165.48
13.69	165.62
13.71	165.75
13.72	165.88
13.73	166.02
13.75	166.15
13.76	166.28
13.77	166.42
13.79	166.55
13.80	166.69
13.81	166.82
13.83	166.95
13.84	167.09
13.85	167.22
13.87	167.35
13.88	167.48
13.89	167.62
13.91	167.75
13.92	167.88
13.93	168.02
13.95	168.15
13.96	168.28
13.97	168.42
13.99	168.55
14.00	168.69
14.01	168.82
14.03	168.95
14.04	169.08
14.05	169.22
14.07	169.35
14.08	169.49
14.09	169.62
14.11	169.75
14.12	169.89
14.13	170.02
14.15	170.15
14.16	170.29
14.17	170.42
14.19	170.55
14.20	170.69
14.21	170.82
14.23	170.95
14.24	171.09
14.25	171.22
14.27	171.35
14.28	171.49
14.29	171.62
14.31	171.75
14.32	171.89
14.33	172.02
14.35	172.15
14.36	172.29
14.37	172.42
14.39	172.55
14.40	172.69
14.41	172.82
14.43	172.95
14.44	173.09
14.45	173.22
14.47	173.35
14.48	173.49
14.49	173.62
14.51	173.75
14.52	173.89
14.53	174.02
14.55	174.15
14.56	174.29
14.57	174.42
14.59	174.55
14.60	174.69
14.61	174.82
14.63	174.96
14.64	175.09
14.65	175.22
14.67	175.35
14.68	175.49
14.69	175.62
14.71	175.75
14.72	175.89
14.73	176.02
14.75	176.15
14.76	176.29
14.77	176.42
14.79	176.55
14.80	176.69
14.81	176.82
14.83	176.96
14.84	177.09
14.85	177.22
14.87	177.35
14.88	177.49
14.89	177.62
14.91	177.75
14.92	177.89
14.93	178.02
14.95	178.16
14.96	178.29
14.97	178.42
14.99	178.55
15.00	178.69
15.01	178.82
15.03	178.95
15.04	179.09
15.05	179.22
15.07	179.36
15.08	179.49
15.09	179.62
15.11	179.76
15.12	179.89
15.13	180.02
15.15	180.16
15.16	180.29
15.17	180.42
15.19	180.56
15.20	180.69
15.21	180.82
15.23	180.96
15.24	181.09
15.25	181.22
15.27	181.36
15.28	181.49
15.29	181.62
15.31	181.76
15.32	181.89
15.33	182.02
15.35	182.16
15.36	182.29
15.37	182.42
15.39	182.56
15.40	182.69
15.41	182.82
15.43	182.96
15.44	183.09
15.45	183.22
15.47	183.36
15.48	183.49
15.49	183.62
15.51	183.76
15.52	183.89
15.53	184.02
15.55	184.16
15.56	184.29
15.57	184.42
15.59	184.56
15.60	184.69
15.61	184.82
15.63	184.96
15.64	185.09
15.65	185.22
15.67	185.36
15.68	185.49
15.69	185.62
15.71	185.76
15.72	185.89
15.73	186.02
15.75	186.16
15.76	186.29
15.77	186.42
15.79	186.56
15.80	186.69
15.81	186.82
15.83	186.96
15.84	187.09
15.85	187.22
15.87	187.36
15.88	187.49
15.89	187.62
15.91	187.76
15.92	187.89
15.93	188.02
15.95	188.16
15.96	188.29
15.97	188.42
15.99	188.56
16.00	188.69
16.01	188.82
16.03	188.96
16.04	189.09
16.05	189.22
16.07	189.36
16.08	189.49
16.09	189.62
16.11	189.76
16.12	189.89
16.13	190.02
16.15	190.16
16.16	190.29
16.17	190.42
16.19	190.56
16.20	190.69
16.21	190.82
16.23	190.96
16.24	191.09
16.25	191.23
16.27	191.36
16.28	191.49
16.29	191.63
16.31	191.76
16.32	191.89
16.33	192.02
16.35	192.16
16.36	192.29
16.37	192.43
16.39	192.56
16.40	192.69
16.41	192.83
16.43	192.96
16.44	193.09
16.45	193.23
16.47	193.36
16.48	193.49
16.49	193.63
16.51	193.76
16.52	193.89
16.53	194.03
16.55	194.16
16.56	194.29
16.57	194.43
16.59	194.56
16.60	194.69
16.61	194.83
16.63	194.96
16.64	195.09
16.65	195.23
16.67	195.36
16.68	195.49
16.69	195.63
16.71	195.76
16.72	195.89
16.73	196.03
16.75	196.16
16.76	196.29
16.77	196.43
16.79	196.56
16.80	196.69
16.81	196.83
16.83	196.96
16.84	197.09
16.85	197.23
16.87	197.36
16.88	197.49
16.89	197.63
16.91	197.76
16.92	197.89
16.93	198.03
16.95	198.16
16.96	198.29
16.97	198.43
16.99	198.56
17.00	198.69
17.01	198.83
17.03	198.96
17.04	199.09
17.05	199.23
17.07	199.36
17.08	199.49
17.09	199.63
17.11	199.76
17.12	199.89
17.13	200.03
17.15	200.16
17.16	200.29
17.17	200.43
17.19	200.56
17.20	200.69
17.21	200.83
17.23	200.96
17.24	201.09
17.25	201.23
17.27	201.36
17.28	201.49
17.29	201.63
17.31	201.76
17.32	201.89
17.33	202.03
17.35	202.16
17.36	202.29
17.37	202.43
17.39	202.56
17.40	202.69
17.41	202.83
17.43	202.96
17.44	203.10
17.45	203.23
17.47	203.36
17.48	203.50
17.49	203.63
17.51	203.76
17.52	203.90
17.53	204.03
17.55	204.16
17.56	204.29
17.57	204.43
17.59	204.56
17.60	204.69
17.61	204.83
17.63	204.96
17.64	205.09
17.65	205.23
17.67	205.36
17.68	205.49
17.69	205.63
17.71	205.76
17.72	205.90
17.73	206.03
17.75	206.16
17.76	206.30
17.77	206.43
17.79	206.56
17.80	206.70
17.81	206.83
17.83	206.96
17.84	207.09
17.85	207.23
17.87	207.36
17.88	207.50
17.89	207.63
17.91	207.76
17.92	207.90
17.93	208.03
17.95	208.16
17.96	208.30
17.97	208.43
17.99	208.56
18.00	208.70
18.01	208.83
18.03	208.96
18.04	209.10
18.05	209.23
18.07	209.36
18.08	209.50
18.09	209.63
18.11	209.76
18.12	209.90
18.13	210.03
18.15	210.16
18.16	210.30
18.17	210.43
18.19	210.56
18.20	210.70
18.21	210.83
18.23	210.96
18.24	211.10
18.25	211.23
18.27	211.36
18.28	211.50
18.29	211.63
18.31	211.76
18.32	211.90
18.33	212.03
18.35	212.16
18.36	212.30
18.37	212.43
18.39	212.56
18.40	212.70
18.41	212.83
18.43	212.96
18.44	213.10
18.45	213.23
18.47	213.36
18.48	213.50
18.49	213.63
18.51	213.76
18.52	213.90
18.53	214.03
18.55	214.16
18.56	214.30
18.57	214.43
18.59	214.56
18.60	214.70
18.61	214.83
18.63	214.96
18.64	215.10
18.65	215.23
18.67	215.36
18.68	215.50
18.69	215.63
18.71	215.76
18.72	215.90
18.73	216.03
18.75	216.16
18.76	216.30
18.77	216.43
18.79	216.56
18.80	216.70
18.81	216.83
18.83	216.96
18.84	217.10
18.85	217.23
18.87	217.36
18.88	217.50
18.89	217.63
18.91	217.77
18.92	217.90
18.93	218.03
18.95	218.16
18.96	218.30
18.97	218.43
18.99	218.57
19.00	218.70

[step]
Ramp 10.00 °C/min to 30.00 °C
Time	Temperature	Heat Flow (Normalized)	Heat Flow
min	°C	W/g	mW
20.00	220.07		-0.199
20.02	220.07		-0.200
20.03	220.07		-0.200
20.04	220.06		-0.200
20.06	220.05		-0.198
20.07	220.04		-0.180
20.08	220.02		-0.137
20.09	219.98		-0.101
20.11	219.93		-0.079
20.12	219.88		-0.075
20.13	219.81		-0.082
20.15	219.72		-0.088
20.16	219.63		-0.130
20.18	219.53		-0.190
20.19	219.43		-0.239
20.20	219.32		-0.283
20.22	219.21		-0.321
20.23	219.09		-0.352
20.24	218.97		-0.382
20.26	218.85		-0.402
20.27	218.73		-0.418
20.28	218.60		-0.439
20.29	218.48		-0.445
20.31	218.35		-0.455
20.32	218.22		-0.469
20.33	218.10		-0.470
20.35	217.97		-0.476
20.36	217.84		-0.479
20.38	217.71		-0.481
20.39	217.58		-0.486
20.40	217.45		-0.487
20.42	217.32		-0.490
20.43	217.19		-0.491
20.44	217.06		-0.492
20.46	216.93		-0.492
20.47	216.80		-0.494
20.48	216.67		-0.495
20.49	216.54		-0.496
20.51	216.41		-0.496
20.52	216.28		-0.497
20.53	216.15		-0.498
20.55	216.01		-0.499
20.56	215.88		-0.500
20.58	215.75		-0.501
20.59	215.62		-0.502
20.60	215.49		-0.503
20.62	215.36		-0.503
20.63	215.22		-0.504
20.64	215.09		-0.505
20.66	214.96		-0.506
20.67	214.83		-0.506
20.68	214.70		-0.507
20.69	214.56		-0.507
20.71	214.43		-0.508
20.72	214.30		-0.508
20.73	214.17		-0.508
20.75	214.04		-0.509
20.76	213.90		-0.509
20.78	213.77		-0.510
20.79	213.64		-0.510
20.80	213.51		-0.510
20.82	213.38		-0.511
20.83	213.24		-0.511
20.84	213.11		-0.511
20.86	212.98		-0.511
20.87	212.85		-0.512
20.88	212.71		-0.512
20.89	212.58		-0.512
20.91	212.45		-0.512
20.92	212.32		-0.512
20.93	212.19		-0.512
20.95	212.05		-0.512
20.96	211.92		-0.512
20.98	211.79		-0.512
20.99	211.66		-0.512
21.00	211.52		-0.512
21.02	211.39		-0.512
21.03	211.26		-0.512
21.04	211.13		-0.512
21.06	210.99		-0.512
21.07	210.86		-0.512
21.08	210.73		-0.512
21.09	210.60		-0.512
21.11	210.46		-0.512
21.12	210.33		-0.512
21.13	210.20		-0.512
21.15	210.07		-0.512
21.16	209.93		-0.512
21.18	209.80		-0.512
21.19	209.67		-0.511
21.20	209.53		-0.511
21.22	209.40		-0.511
21.23	209.27		-0.511
21.24	209.14		-0.511
21.26	209.00		-0.511
21.27	208.87		-0.510
21.28	208.74		-0.510
21.29	208.60		-0.510
21.31	208.47		-0.510
21.32	208.34		-0.510
21.33	208.21		-0.510
21.35	208.07		-0.509
21.36	207.94		-0.509
21.38	207.81		-0.509
21.39	207.67		-0.508
21.40	207.54		-0.508
21.42	207.41		-0.508
21.43	207.28		-0.508
21.44	207.14		-0.508
21.46	207.01		-0.507
21.47	206.88		-0.507
21.48	206.74		-0.507
21.49	206.61		-0.507
21.51	206.48		-0.507
21.52	206.34		-0.507
21.53	206.21		-0.506
21.55	206.08		-0.506
21.56	205.95		-0.506
21.58	205.81		-0.506
21.59	205.68		-0.505
21.60	205.55		-0.505
21.62	205.41		-0.505
21.63	205.28		-0.504
21.64	205.15		-0.504
21.66	205.01		-0.504
21.67	204.88		-0.504
21.68	204.75		-0.503
21.69	204.62		-0.504
21.71	204.48		-0.503
21.72	204.35		-0.503
21.73	204.22		-0.503
21.75	204.08		-0.503
21.76	203.95		-0.503
21.78	203.82		-0.502
21.79	203.68		-0.502
21.80	203.55		-0.502
21.82	203.42		-0.501
21.83	203.29		-0.501
21.84	203.15		-0.501
21.86	203.02		-0.501
21.87	202.89		-0.501
21.88	202.75		-0.500
21.89	202.62		-0.500
21.91	202.49		-0.500
21.92	202.35		-0.499
21.93	202.22		-0.499
21.95	202.09		-0.499
21.96	201.95		-0.499
21.98	201.82		-0.499
21.99	201.69		-0.499
22.00	201.55		-0.499
22.02	201.42		-0.498
22.03	201.29		-0.498
22.04	201.16		-0.498
22.06	201.02		-0.497
22.07	200.89		-0.497
22.08	200.76		-0.497
22.09	200.62		-0.497
22.11	200.49		-0.497
22.12	200.36		-0.496
22.13	200.22		-0.496
22.15	200.09		-0.496
22.16	199.96		-0.496
22.18	199.82		-0.496
22.19	199.69		-0.496
22.20	199.56		-0.495
22.22	199.42		-0.495
22.23	199.29		-0.495
22.24	199.16		-0.495
22.26	199.02		-0.494
22.27	198.89		-0.494
22.28	198.76		-0.494
22.29	198.63		-0.494
22.31	198.49		-0.494
22.32	198.36		-0.494
22.33	198.23		-0.493
22.35	198.09		-0.493
22.36	197.96		-0.493
22.38	197.83		-0.493
22.39	197.69		-0.493
22.40	197.56		-0.492
22.42	197.43		-0.492
22.43	197.29		-0.493
22.44	197.16		-0.492
22.46	197.03		-0.492
22.47	196.89		-0.492
22.48	196.76		-0.493
22.49	196.63		-0.492
22.51	196.50		-0.492
22.52	196.36		-0.492
22.53	196.23		-0.491
22.55	196.10		-0.491
22.56	195.96		-0.491
22.58	195.83		-0.491
22.59	195.70		-0.490
22.60	195.56		-0.491
22.62	195.43		-0.490
22.63	195.30		-0.490
22.64	195.16		-0.490
22.66	195.03		-0.490
22.67	194.90		-0.490
22.68	194.76		-0.490
22.69	194.63		-0.489
22.71	194.50		-0.489
22.72	194.37		-0.489
22.73	194.23		-0.489
22.75	194.10		-0.489
22.76	193.96		-0.489
22.78	193.83		-0.489
22.79	193.70		-0.489
22.80	193.57		-0.489
22.82	193.43		-0.489
22.83	193.30		-0.488
22.84	193.17		-0.489
22.86	193.03		-0.488
22.87	192.90		-0.488
22.88	192.77		-0.488
22.89	192.63		-0.488
22.91	192.50		-0.487
22.92	192.37		-0.487
22.93	192.23		-0.487
22.95	192.10		-0.487
22.96	191.97		-0.487
22.98	191.83		-0.486
22.99	191.70		-0.486
23.00	191.57		-0.486
23.02	191.44		-0.486
23.03	191.30		-0.485
23.04	191.17		-0.485
23.06	191.03		-0.485
23.07	190.90		-0.485
23.08	190.77		-0.485
23.09	190.64		-0.485
23.11	190.50		-0.485
23.12	190.37		-0.485
23.13	190.24		-0.485
23.15	190.10		-0.485
23.16	189.97		-0.485
23.18	189.84		-0.484
23.19	189.70		-0.484
23.20	189.57		-0.484
23.22	189.44		-0.484
23.23	189.30		-0.484
23.24	189.17		-0.483
23.26	189.04		-0.484
23.27	188.91		-0.483
23.28	188.77		-0.483
23.29	188.64		-0.483
23.31	188.51		-0.483
23.32	188.37		-0.483
23.33	188.24		-0.483
23.35	188.11		-0.483
23.36	187.97		-0.482
23.38	187.84		-0.482
23.39	187.71		-0.482
23.40	187.57		-0.482
23.42	187.44		-0.482
23.43	187.31		-0.482
23.44	187.17		-0.482
23.46	187.04		-0.482
23.47	186.91		-0.482
23.48	186.77		-0.482
23.49	186.64		-0.482
23.51	186.51		-0.481
23.52	186.37		-0.481
23.53	186.24		-0.481
23.55	186.11		-0.481
23.56	185.97		-0.481
23.58	185.84		-0.481
23.59	185.71		-0.481
23.60	185.58		-0.481
23.62	185.44		-0.481
23.63	185.31		-0.481
23.64	185.18		-0.480
23.66	185.04		-0.480
23.67	184.91		-0.480
23.68	184.78		-0.479
23.69	184.64		-0.479
23.71	184.51		-0.479
23.72	184.38		-0.479
23.73	184.24		-0.479
23.75	184.11		-0.479
23.76	183.98		-0.479
23.78	183.84		-0.479
23.79	183.71		-0.479
23.80	183.58		-0.479
23.82	183.44		-0.479
23.83	183.31		-0.479
23.84	183.18		-0.478
23.86	183.04		-0.478
23.87	182.91		-0.478
23.88	182.78		-0.478
23.89	182.64		-0.478
23.91	182.51		-0.478
23.92	182.38		-0.478
23.93	182.25		-0.478
23.95	182.11		-0.478
23.96	181.98		-0.478
23.98	181.85		-0.478
23.99	181.71		-0.477
24.00	181.58		-0.477
24.02	181.45		-0.477
24.03	181.31		-0.477
24.04	181.18		-0.477
24.06	181.05		-0.477
24.07	180.91		-0.477
24.08	180.78		-0.477
24.09	180.65		-0.477
24.11	180.51		-0.477
24.12	180.38		-0.476
24.13	180.25		-0.476
24.15	180.11		-0.476
24.16	179.98		-0.476
24.18	179.85		-0.476
24.19	179.71		-0.476
24.20	179.58		-0.476
24.22	179.45		-0.476
24.23	179.31		-0.475
24.24	179.18		-0.476
24.26	179.05		-0.475
24.27	178.91		-0.475
24.28	178.78		-0.475
24.29	178.65		-0.475
24.31	178.52		-0.475
24.32	178.38		-0.475
24.33	178.25		-0.475
24.35	178.12		-0.475
24.36	177.98		-0.475
24.38	177.85		-0.475
24.39	177.72		-0.475
24.40	177.58		-0.474
24.42	177.45		-0.475
24.43	177.32		-0.475
24.44	177.19		-0.474
24.46	177.05		-0.474
24.47	176.92		-0.474
24.48	176.78		-0.474
24.49	176.65		-0.474
24.51	176.52		-0.474
24.52	176.38		-0.474
24.53	176.25		-0.474
24.55	176.12		-0.474
24.56	175.99		-0.474
24.58	175.85		-0.473
24.59	175.72		-0.473
24.60	175.59		-0.473
24.62	175.45		-0.473
24.63	175.32		-0.473
24.64	175.19		-0.473
24.66	175.05		-0.473
24.67	174.92		-0.473
24.68	174.79		-0.473
24.69	174.65		-0.473
24.71	174.52		-0.473
24.72	174.39		-0.473
24.73	174.25		-0.473
24.75	174.12		-0.473
24.76	173.99		-0.473
24.78	173.85		-0.473
24.79	173.72		-0.473
24.80	173.59		-0.473
24.82	173.45		-0.472
24.83	173.32		-0.473
24.84	173.19		-0.473
24.86	173.05		-0.472
24.87	172.92		-0.472
24.88	172.79		-0.472
24.89	172.66		-0.472
24.91	172.52		-0.472
24.92	172.39		-0.472
24.93	172.25		-0.472
24.95	172.12		-0.472
24.96	171.99		-0.472
24.98	171.86		-0.472
24.99	171.72		-0.472
25.00	171.59		-0.471
25.02	171.46		-0.471
25.03	171.32		-0.471
25.04	171.19		-0.471
25.06	171.06		-0.471
25.07	170.92		-0.471
25.08	170.79		-0.471
25.09	170.66		-0.471
25.11	170.52		-0.471
25.12	170.39		-0.471
25.13	170.26		-0.471
25.15	170.12		-0.471
25.16	169.99		-0.471
25.18	169.86		-0.471
25.19	169.72		-0.471
25.20	169.59		-0.471
25.22	169.46		-0.471
25.23	169.32		-0.471
25.24	169.19		-0.471
25.26	169.06		-0.471
25.27	168.93		-0.470
25.28	168.79		-0.470
25.29	168.66		-0.470
25.31	168.53		-0.471
25.32	168.39		-0.470
25.33	168.26		-0.470
25.35	168.13		-0.471
25.36	167.99		-0.470
25.38	167.86		-0.470
25.39	167.73		-0.470
25.40	167.59		-0.470
25.42	167.46		-0.470
25.43	167.33		-0.470
25.44	167.19		-0.470
25.46	167.06		-0.470
25.47	166.93		-0.470
25.48	166.79		-0.470
25.49	166.66		-0.470
25.51	166.53		-0.470
25.52	166.40		-0.470
25.53	166.26		-0.470
25.55	166.13		-0.470
25.56	166.00		-0.470
25.58	165.86		-0.470
25.59	165.73		-0.470
25.60	165.60		-0.470
25.62	165.46		-0.469
25.63	165.33		-0.470
25.64	165.20		-0.469
25.66	165.06		-0.469
25.67	164.93		-0.469
25.68	164.80		-0.469
25.69	164.66		-0.469
25.71	164.53		-0.469
25.72	164.40		-0.469
25.73	164.26		-0.469
25.75	164.13		-0.469
25.76	164.00		-0.469
25.78	163.87		-0.469
25.79	163.73		-0.469
25.80	163.60		-0.469
25.82	163.47		-0.469
25.83	163.33		-0.469
25.84	163.20		-0.469
25.86	163.07		-0.469
25.87	162.93		-0.469
25.88	162.80		-0.469
25.89	162.67		-0.468
25.91	162.53		-0.469
25.92	162.40		-0.468
25.93	162.27		-0.468
25.95	162.13		-0.468
25.96	162.00		-0.468
25.98	161.87		-0.468
25.99	161.73		-0.468
26.00	161.60		-0.468
26.02	161.47		-0.468
26.03	161.33		-0.468
26.04	161.20		-0.467
26.06	161.07		-0.467
26.07	160.93		-0.468
26.08	160.80		-0.467
26.09	160.67		-0.467
26.11	160.53		-0.467
26.12	160.40		-0.467
26.13	160.27		-0.467
26.15	160.13		-0.467
26.16	160.00		-0.467
26.18	159.87		-0.467
26.19	159.73		-0.467
26.20	159.60		-0.467
26.22	159.47		-0.467
26.23	159.34		-0.467
26.24	159.20		-0.467
26.26	159.07		-0.467
26.27	158.93		-0.467
26.28	158.80		-0.467
26.29	158.67		-0.467
26.31	158.54		-0.467
26.32	158.40		-0.467
26.33	158.27		-0.467
26.35	158.14		-0.467
26.36	158.00		-0.467
26.38	157.87		-0.467
26.39	157.74		-0.466
26.40	157.60		-0.466
26.42	157.47		-0.467
26.43	157.34		-0.466
26.44	157.20		-0.466
26.46	157.07		-0.466
26.47	156.94		-0.466
26.48	156.80		-0.466
26.49	156.67		-0.466
26.51	156.54		-0.466
26.52	156.40		-0.466
26.53	156.27		-0.466
26.55	156.14		-0.466
26.56	156.00		-0.466
26.58	155.87		-0.466
26.59	155.74		-0.466
26.60	155.60		-0.466
26.62	155.47		-0.466
26.63	155.34		-0.466
26.64	155.21		-0.466
26.66	155.07		-0.466
26.67	154.94		-0.466
26.68	154.81		-0.465
26.69	154.67		-0.465
26.71	154.54		-0.465
26.72	154.41		-0.465
26.73	154.27		-0.465
26.75	154.14		-0.465
26.76	154.01		-0.465
26.78	153.87		-0.465
26.79	153.74		-0.465
26.80	153.61		-0.465
26.82	153.47		-0.465
26.83	153.34		-0.465
26.84	153.21		-0.465
26.86	153.07		-0.465
26.87	152.94		-0.465
26.88	152.81		-0.465
26.89	152.67		-0.464
26.91	152.54		-0.464
26.92	152.41		-0.465
26.93	152.28		-0.464
26.95	152.14		-0.465
26.96	152.01		-0.464
26.98	151.88		-0.464
26.99	151.74		-0.464
27.00	151.61		-0.464
27.02	151.48		-0.464
27.03	151.34		-0.464
27.04	151.21		-0.464
27.06	151.08		-0.464
27.07	150.94		-0.464
27.08	150.81		-0.464
27.09	150.68		-0.464
27.11	150.54		-0.464
27.12	150.41		-0.464
27.13	150.28		-0.464
27.15	150.14		-0.464
27.16	150.01		-0.465
27.18	149.88		-0.464
27.19	149.75		-0.465
27.20	149.61		-0.465
27.22	149.48		-0.464
27.23	149.35		-0.464
27.24	149.21		-0.464
27.26	149.08		-0.464
27.27	148.94		-0.464
27.28	148.81		-0.464
27.29	148.68		-0.464
27.31	148.55		-0.464
27.32	148.41		-0.463
27.33	148.28		-0.463
27.35	148.15		-0.463
27.36	148.01		-0.463
27.38	147.88		-0.463
27.39	147.75		-0.463
27.40	147.61		-0.463
27.42	147.48		-0.463
27.43	147.35		-0.463
27.44	147.21		-0.463
27.46	147.08		-0.463
27.47	146.95		-0.463
27.48	146.81		-0.463
27.49	146.68		-0.463
27.51	146.55		-0.463
27.52	146.41		-0.463
27.53	146.28		-0.463
27.55	146.15		-0.463
27.56	146.02		-0.462
27.58	145.88		-0.462
27.59	145.75		-0.462
27.60	145.61		-0.462
27.62	145.48		-0.462
27.63	145.35		-0.462
27.64	145.21		-0.462
27.66	145.08		-0.462
27.67	144.95		-0.462
27.68	144.81		-0.462
27.69	144.68		-0.462
27.71	144.55		-0.462
27.72	144.41		-0.462
27.73	144.28		-0.461
27.75	144.15		-0.461
27.76	144.02		-0.461
27.78	143.88		-0.461
27.79	143.75		-0.461
27.80	143.62		-0.461
27.82	143.48		-0.461
27.83	143.35		-0.461
27.84	143.22		-0.461
27.86	143.08		-0.461
27.87	142.95		-0.461
27.88	142.82		-0.461
27.89	142.68		-0.461
27.91	142.55		-0.461
27.92	142.42		-0.461
27.93	142.28		-0.461
27.95	142.15		-0.461
27.96	142.02		-0.461
27.98	141.89		-0.461
27.99	141.75		-0.460
28.00	141.62		-0.460
28.02	141.49		-0.460
28.03	141.35		-0.460
28.04	141.22		-0.460
28.06	141.09		-0.460
28.07	140.95		-0.460
28.08	140.82		-0.460
28.09	140.69		-0.460
28.11	140.55		-0.460
28.12	140.42		-0.460
28.13	140.29		-0.460
28.15	140.15		-0.459
28.16	140.02		-0.459
28.18	139.89		-0.459
28.19	139.75		-0.460
28.20	139.62		-0.459
28.22	139.49		-0.459
28.23	139.36		-0.459
28.24	139.22		-0.459
28.26	139.09		-0.459
28.27	138.96		-0.459
28.28	138.82		-0.459
28.29	138.69		-0.459
28.31	138.56		-0.459
28.32	138.42		-0.459
28.33	138.29		-0.459
28.35	138.16		-0.458
28.36	138.02		-0.458
28.38	137.89		-0.458
28.39	137.76		-0.458
28.40	137.62		-0.458
28.42	137.49		-0.458
28.43	137.36		-0.458
28.44	137.22		-0.457
28.46	137.09		-0.459
28.47	136.96		-0.458
28.48	136.82		-0.458
28.49	136.69		-0.459
28.51	136.56		-0.458
28.52	136.42		-0.458
28.53	136.29		-0.458
28.55	136.16		-0.458
28.56	136.02		-0.458
28.58	135.89		-0.458
28.59	135.76		-0.458
28.60	135.62		-0.458
28.62	135.49		-0.458
28.63	135.36		-0.458
28.64	135.22		-0.458
28.66	135.09		-0.458
28.67	134.96		-0.458
28.68	134.83		-0.457
28.69	134.69		-0.457
28.71	134.56		-0.457
28.72	134.43		-0.458
28.73	134.29		-0.457
28.75	134.16		-0.457
28.76	134.03		-0.457
28.78	133.89		-0.457
28.79	133.76		-0.457
28.80	133.63		-0.457
28.82	133.49		-0.457
28.83	133.36		-0.457
28.84	133.23		-0.457
28.86	133.09		-0.457
28.87	132.96		-0.457
28.88	132.83		-0.456
28.89	132.69		-0.456
28.91	132.56		-0.456
28.92	132.43		-0.456
28.93	132.29		-0.456
28.95	132.16		-0.456
28.96	132.03		-0.456
28.98	131.89		-0.456
28.99	131.76		-0.456
29.00	131.63		-0.456
29.02	131.49		-0.456
29.03	131.36		-0.456
29.04	131.23		-0.456
29.06	131.09		-0.456
29.07	130.96		-0.456
29.08	130.83		-0.456
29.09	130.70		-0.455
29.11	130.56		-0.455
29.12	130.43		-0.455
29.13	130.30		-0.456
29.15	130.16		-0.455
29.16	130.03		-0.455
29.18	129.90		-0.455
29.19	129.76		-0.455
29.20	129.63		-0.455
29.22	129.50		-0.455
29.23	129.36		-0.455
29.24	129.23		-0.455
29.26	129.10		-0.455
29.27	128.96		-0.455
29.28	128.83		-0.455
29.29	128.70		-0.455
29.31	128.56		-0.455
29.32	128.43		-0.455
29.33	128.30		-0.454
29.35	128.16		-0.455
29.36	128.03		-0.455
29.38	127.90		-0.455
29.39	127.76		-0.455
29.40	127.63		-0.455
29.42	127.50		-0.455
29.43	127.37		-0.455
29.44	127.23		-0.454
29.46	127.10		-0.454
29.47	126.97		-0.454
29.48	126.83		-0.454
29.49	126.70		-0.454
29.51	126.57		-0.454
29.52	126.43		-0.454
29.53	126.30		-0.454
29.55	126.17		-0.454
29.56	126.03		-0.454
29.58	125.90		-0.454
29.59	125.77		-0.454
29.60	125.63		-0.454
29.62	125.50		-0.454
29.63	125.37		-0.453
29.64	125.23		-0.453
29.66	125.10		-0.453
29.67	124.97		-0.453
29.68	124.83		-0.454
29.69	124.70		-0.453
29.71	124.57		-0.454
29.72	124.43		-0.453
29.73	124.30		-0.454
29.75	124.17		-0.454
29.76	124.03		-0.453
29.78	123.90		-0.454
29.79	123.77		-0.453
29.80	123.64		-0.453
29.82	123.50		-0.453
29.83	123.37		-0.453
29.84	123.24		-0.453
29.86	123.10		-0.453
29.87	122.97		-0.453
29.88	122.84		-0.453
29.89	122.70		-0.453
29.91	122.57		-0.453
29.92	122.44		-0.453
29.93	122.30		-0.453
29.95	122.17		-0.453
29.96	122.04		-0.453
29.98	121.90		-0.453
29.99	121.77		-0.453
30.00	121.64		-0.453
30.02	121.50		-0.453
30.03	121.37		-0.453
30.04	121.24		-0.452
30.06	121.10		-0.452
30.07	120.97		-0.452
30.08	120.84		-0.452
30.09	120.71		-0.452
30.11	120.57		-0.452
30.12	120.44		-0.452
30.13	120.31		-0.452
30.15	120.17		-0.452
30.16	120.04		-0.452
30.18	119.91		-0.452
30.19	119.77		-0.452
30.20	119.64		-0.452
30.22	119.51		-0.452
30.23	119.37		-0.452
30.24	119.24		-0.451
30.26	119.11		-0.451
30.27	118.97		-0.451
30.28	118.84		-0.452
30.29	118.71		-0.451
30.31	118.57		-0.451
30.32	118.44		-0.451
30.33	118.31		-0.451
30.35	118.17		-0.451
30.36	118.04		-0.451
30.38	117.91		-0.451
30.39	117.77		-0.451
30.40	117.64		-0.451
30.42	117.51		-0.451
30.43	117.37		-0.451
30.44	117.24		-0.450
30.46	117.11		-0.451
30.47	116.97		-0.451
30.48	116.84		-0.450
30.49	116.71		-0.450
30.51	116.58		-0.450
30.52	116.44		-0.450
30.53	116.31		-0.450
30.55	116.18		-0.450
30.56	116.04		-0.450
30.58	115.91		-0.450
30.59	115.78		-0.450
30.60	115.64		-0.450
30.62	115.51		-0.450
30.63	115.38		-0.450
30.64	115.24		-0.449
30.66	115.11		-0.449
30.67	114.98		-0.450
30.68	114.84		-0.449
30.69	114.71		-0.449
30.71	114.58		-0.449
30.72	114.44		-0.449
30.73	114.31		-0.449
30.75	114.18		-0.449
30.76	114.04		-0.449
30.78	113.91		-0.449
30.79	113.78		-0.449
30.80	113.65		-0.449
30.82	113.51		-0.448
30.83	113.38		-0.448
30.84	113.24		-0.448
30.86	113.11		-0.448
30.87	112.98		-0.448
30.88	112.85		-0.448
30.89	112.71		-0.448
30.91	112.58		-0.448
30.92	112.45		-0.448
30.93	112.31		-0.448
30.95	112.18		-0.448
30.96	112.05		-0.448
30.98	111.91		-0.448
30.99	111.78		-0.448
31.00	111.65		-0.448
31.02	111.51		-0.448
31.03	111.38		-0.448
31.04	111.25		-0.448
31.06	111.11		-0.447
31.07	110.98		-0.447
31.08	110.85		-0.447
31.09	110.71		-0.447
31.11	110.58		-0.447
31.12	110.45		-0.448
31.13	110.31		-0.447
31.15	110.18		-0.447
31.16	110.05		-0.447
31.18	109.92		-0.447
31.19	109.78		-0.447
31.20	109.65		-0.447
31.22	109.51		-0.447
31.23	109.38		-0.447
31.24	109.25		-0.446
31.26	109.11		-0.446
31.27	108.98		-0.446
31.28	108.85		-0.446
31.29	108.72		-0.446
31.31	108.58		-0.446
31.32	108.45		-0.446
31.33	108.32		-0.446
31.35	108.18		-0.446
31.36	108.05		-0.446
31.38	107.92		-0.447
31.39	107.78		-0.447
31.40	107.65		-0.447
31.42	107.52		-0.447
31.43	107.38		-0.446
31.44	107.25		-0.447
31.46	107.12		-0.446
31.47	106.98		-0.446
31.48	106.85		-0.446
31.49	106.72		-0.446
31.51	106.58		-0.446
31.52	106.45		-0.446
31.53	106.32		-0.446
31.55	106.18		-0.446
31.56	106.05		-0.446
31.58	105.92		-0.445
31.59	105.79		-0.445
31.60	105.65		-0.445
31.62	105.52		-0.445
31.63	105.39		-0.445
31.64	105.25		-0.445
31.66	105.12		-0.445
31.67	104.99		-0.445
31.68	104.85		-0.445
31.69	104.72		-0.445
31.71	104.59		-0.445
31.72	104.45		-0.445
31.73	104.32		-0.445
31.75	104.19		-0.445
31.76	104.05		-0.445
31.78	103.92		-0.445
31.79	103.79		-0.444
31.80	103.65		-0.444
31.82	103.52		-0.444
31.83	103.39		-0.444
31.84	103.26		-0.444
31.86	103.12		-0.444
31.87	102.99		-0.444
31.88	102.85		-0.444
31.89	102.72		-0.444
31.91	102.59		-0.444
31.92	102.45		-0.444
31.93	102.32		-0.444
31.95	102.19		-0.444
31.96	102.05		-0.444
31.98	101.92		-0.444
31.99	101.79		-0.444
32.00	101.65		-0.444
32.02	101.52		-0.444
32.03	101.39		-0.444
32.04	101.26		-0.444
32.06	101.12		-0.444
32.07	100.99		-0.444
32.08	100.86		-0.443
32.09	100.72		-0.444
32.11	100.59		-0.444
32.12	100.46		-0.443
32.13	100.32		-0.443
32.15	100.19		-0.443
32.16	100.06		-0.443
32.18	99.92		-0.443
32.19	99.79		-0.443
32.20	99.66		-0.443
32.22	99.52		-0.443
32.23	99.39		-0.443
32.24	99.26		-0.443
32.26	99.12		-0.443
32.27	98.99		-0.443
32.28	98.86		-0.443
32.29	98.72		-0.442
32.31	98.59		-0.443
32.32	98.46		-0.442
32.33	98.33		-0.442
32.35	98.19		-0.442
32.36	98.06		-0.442
32.38	97.93		-0.442
32.39	97.79		-0.442
32.40	97.66		-0.442
32.42	97.53		-0.441
32.43	97.39		-0.441
32.44	97.26		-0.441
32.46	97.13		-0.441
32.47	96.99		-0.441
32.48	96.86		-0.441
32.49	96.73		-0.441
32.51	96.59		-0.441
32.52	96.46		-0.441
32.53	96.33		-0.441
32.55	96.19		-0.441
32.56	96.06		-0.441
32.58	95.93		-0.441
32.59	95.79		-0.441
32.60	95.66		-0.440
32.62	95.53		-0.440
32.63	95.39		-0.440
32.64	95.26		-0.440
32.66	95.13		-0.440
32.67	94.99		-0.440
32.68	94.86		-0.440
32.69	94.73		-0.439
32.71	94.59		-0.439
32.72	94.46		-0.439
32.73	94.33		-0.439
32.75	94.19		-0.439
32.76	94.06		-0.439
32.78	93.93		-0.439
32.79	93.80		-0.439
32.80	93.66		-0.439
32.82	93.53		-0.438
32.83	93.40		-0.438
32.84	93.26		-0.438
32.86	93.13		-0.438
32.87	93.00		-0.438
32.88	92.86		-0.438
32.89	92.73		-0.438
32.91	92.60		-0.438
32.92	92.46		-0.438
32.93	92.33		-0.437
32.95	92.20		-0.438
32.96	92.06		-0.438
32.98	91.93		-0.438
32.99	91.80		-0.437
33.00	91.66		-0.437
33.02	91.53		-0.437
33.03	91.40		-0.437
33.04	91.26		-0.437
33.06	91.13		-0.436
33.07	91.00		-0.437
33.08	90.86		-0.436
33.09	90.73		-0.436
33.11	90.60		-0.436
33.12	90.46		-0.436
33.13	90.33		-0.436
33.15	90.20		-0.434
33.16	90.07		-0.434
33.18	89.93		-0.434
33.19	89.80		-0.434
33.20	89.67		-0.434
33.22	89.53		-0.434
33.23	89.40		-0.434
33.24	89.27		-0.433
33.26	89.13		-0.433
33.27	89.00		-0.433
33.28	88.87		-0.433
33.29	88.73		-0.433
33.31	88.60		-0.433
33.32	88.47		-0.432
33.33	88.33		-0.432
33.35	88.20		-0.432
33.36	88.07		-0.432
33.38	87.93		-0.432
33.39	87.80		-0.432
33.40	87.67		-0.432
33.42	87.54		-0.431
33.43	87.40		-0.432
33.44	87.27		-0.431
33.46	87.14		-0.431
33.47	87.00		-0.430
33.48	86.87		-0.430
33.49	86.74		-0.430
33.51	86.60		-0.430
33.52	86.47		-0.430
33.53	86.34		-0.430
33.55	86.20		-0.430
33.56	86.07		-0.430
33.58	85.94		-0.430
33.59	85.80		-0.430
33.60	85.67		-0.430
33.62	85.54		-0.430
33.63	85.40		-0.430
33.64	85.27		-0.431
33.66	85.14		-0.431
33.67	85.00		-0.430
33.68	84.87		-0.430
33.69	84.74		-0.430
33.71	84.60		-0.430
33.72	84.47		-0.430
33.73	84.34		-0.430
33.75	84.20		-0.430
33.76	84.07		-0.430
33.78	83.94		-0.430
33.79	83.81		-0.430
33.80	83.67		-0.430
33.82	83.54		-0.430
33.83	83.40		-0.430
33.84	83.27		-0.430
33.86	83.14		-0.430
33.87	83.01		-0.430
33.88	82.87		-0.430
33.89	82.74		-0.430
33.91	82.61		-0.430
33.92	82.47		-0.430
33.93	82.34		-0.431
33.95	82.21		-0.431
33.96	82.07		-0.430
33.98	81.94		-0.431
33.99	81.81		-0.431
34.00	81.67		-0.431
34.02	81.54		-0.431
34.03	81.41		-0.431
34.04	81.27		-0.431
34.06	81.14		-0.431
34.07	81.01		-0.431
34.08	80.87		-0.431
34.09	80.74		-0.431
34.11	80.61		-0.431
34.12	80.47		-0.431
34.14	80.34		-0.432
34.15	80.21		-0.432
34.16	80.07		-0.432
34.18	79.94		-0.432
34.19	79.81		-0.432
34.20	79.68		-0.432
34.21	79.54		-0.432
34.23	79.41		-0.432
34.24	79.28		-0.432
34.26	79.14		-0.432
34.27	79.01		-0.432
34.28	78.88		-0.432
34.29	78.74		-0.433
34.31	78.61		-0.432
34.32	78.48		-0.432
34.34	78.34		-0.432
34.35	78.21		-0.432
34.36	78.08		-0.432
34.38	77.94		-0.432
34.39	77.81		-0.432
34.40	77.68		-0.433
34.41	77.54		-0.433
34.43	77.41		-0.432
34.44	77.28		-0.432
34.46	77.14		-0.432
34.47	77.01		-0.432
34.48	76.88		-0.433
34.49	76.74		-0.432
34.51	76.61		-0.432
34.52	76.48		-0.432
34.54	76.34		-0.432
34.55	76.21		-0.432
34.56	76.08		-0.432
34.58	75.95		-0.432
34.59	75.81		-0.432
34.60	75.68		-0.432
34.61	75.55		-0.432
34.63	75.41		-0.431
34.64	75.28		-0.431
34.66	75.15		-0.431
34.67	75.01		-0.431
34.68	74.88		-0.431
34.69	74.75		-0.431
34.71	74.61		-0.431
34.72	74.48		-0.431
34.74	74.35		-0.430
34.75	74.21		-0.431
34.76	74.08		-0.430
34.78	73.95		-0.430
34.79	73.81		-0.430
34.80	73.68		-0.430
34.81	73.55		-0.430
34.83	73.41		-0.430
34.84	73.28		-0.430
34.86	73.15		-0.430
34.87	73.01		-0.430
34.88	72.88		-0.430
34.89	72.75		-0.430
34.91	72.61		-0.430
34.92	72.48		-0.430
34.94	72.35		-0.430
34.95	72.21		-0.430
34.96	72.08		-0.430
34.98	71.95		-0.429
34.99	71.81		-0.429
35.00	71.68		-0.429
35.01	71.55		-0.430
35.03	71.42		-0.430
35.04	71.28		-0.430
35.06	71.15		-0.430
35.07	71.02		-0.430
35.08	70.88		-0.430
35.09	70.75		-0.429
35.11	70.62		-0.430
35.12	70.48		-0.429
35.14	70.35		-0.429
35.15	70.22		-0.429
35.16	70.08		-0.429
35.18	69.95		-0.429
35.19	69.82		-0.429
35.20	69.68		-0.429
35.21	69.55		-0.429
35.23	69.42		-0.429
35.24	69.28		-0.429
35.26	69.15		-0.429
35.27	69.02		-0.429
35.28	68.88		-0.429
35.29	68.75		-0.429
35.31	68.62		-0.429
35.32	68.48		-0.429
35.34	68.35		-0.429
35.35	68.22		-0.429
35.36	68.08		-0.429
35.38	67.95		-0.429
35.39	67.82		-0.429
35.40	67.69		-0.429
35.41	67.55		-0.428
35.43	67.42		-0.428
35.44	67.29		-0.428
35.46	67.15		-0.428
35.47	67.02		-0.428
35.48	66.89		-0.428
35.49	66.75		-0.428
35.51	66.62		-0.427
35.52	66.49		-0.427
35.54	66.35		-0.427
35.55	66.22		-0.427
35.56	66.09		-0.427
35.58	65.95		-0.427
35.59	65.82		-0.427
35.60	65.69		-0.427
35.61	65.55		-0.427
35.63	65.42		-0.426
35.64	65.29		-0.426
35.66	65.15		-0.426
35.67	65.02		-0.426
35.68	64.89		-0.426
35.69	64.76		-0.426
35.71	64.62		-0.425
35.72	64.49		-0.426
35.74	64.36		-0.426
35.75	64.22		-0.425
35.76	64.09		-0.425
35.78	63.96		-0.425
35.79	63.82		-0.425
35.80	63.69		-0.425
35.81	63.56		-0.425
35.83	63.42		-0.425
35.84	63.29		-0.425
35.86	63.16		-0.425
35.87	63.02		-0.425
35.88	62.89		-0.425
35.89	62.76		-0.425
35.91	62.62		-0.424
35.92	62.49		-0.424
35.94	62.36		-0.424
35.95	62.22		-0.424
35.96	62.09		-0.424
35.98	61.96		-0.424
35.99	61.82		-0.424
36.00	61.69		-0.424
36.01	61.56		-0.424
36.03	61.42		-0.424
36.04	61.29		-0.424
36.06	61.16		-0.423
36.07	61.02		-0.423
36.08	60.89		-0.424
36.09	60.76		-0.423
36.11	60.62		-0.423
36.12	60.49		-0.423
36.14	60.36		-0.423
36.15	60.23		-0.423
36.16	60.09		-0.423
36.18	59.96		-0.422
36.19	59.83		-0.422
36.20	59.69		-0.422
36.21	59.56		-0.422
36.23	59.43		-0.422
36.24	59.29		-0.422
36.26	59.16		-0.422
36.27	59.03		-0.422
36.28	58.89		-0.421
36.29	58.76		-0.421
36.31	58.63		-0.421
36.32	58.49		-0.421
36.34	58.36		-0.421
36.35	58.23		-0.421
36.36	58.09		-0.421
36.38	57.96		-0.421
36.39	57.83		-0.421
36.40	57.69		-0.421
36.41	57.56		-0.421
36.43	57.43		-0.420
36.44	57.30		-0.421
36.46	57.16		-0.420
36.47	57.03		-0.420
36.48	56.90		-0.421
36.49	56.76		-0.421
36.51	56.63		-0.420
36.52	56.50		-0.420
36.54	56.36		-0.420
36.55	56.23		-0.420
36.56	56.10		-0.420
36.58	55.96		-0.420
36.59	55.83		-0.419
36.60	55.70		-0.419
36.61	55.56		-0.419
36.63	55.43		-0.419
36.64	55.30		-0.419
36.66	55.16		-0.419
36.67	55.03		-0.419
36.68	54.90		-0.419
36.69	54.76		-0.419
36.71	54.63		-0.418
36.72	54.50		-0.419
36.74	54.36		-0.418
36.75	54.23		-0.418
36.76	54.10		-0.418
36.78	53.96		-0.418
36.79	53.83		-0.418
36.80	53.70		-0.418
36.81	53.56		-0.418
36.83	53.43		-0.418
36.84	53.30		-0.418
36.86	53.16		-0.418
36.87	53.03		-0.418
36.88	52.90		-0.418
36.89	52.77		-0.418
36.91	52.63		-0.418
36.92	52.50		-0.417
36.94	52.37		-0.417
36.95	52.23		-0.417
36.96	52.10		-0.417
36.98	51.97		-0.417
36.99	51.83		-0.417
37.00	51.70		-0.417
37.01	51.57		-0.416
37.03	51.43		-0.417
37.04	51.30		-0.416
37.06	51.17		-0.416
37.07	51.03		-0.416
37.08	50.90		-0.416
37.09	50.77		-0.416
37.11	50.63		-0.416
37.12	50.50		-0.415
37.14	50.37		-0.415
37.15	50.23		-0.415
37.16	50.10		-0.415
37.18	49.97		-0.415
37.19	49.83		-0.415
37.20	49.70		-0.415
37.21	49.57		-0.414
37.23	49.43		-0.414
37.24	49.30		-0.414
37.26	49.17		-0.414
37.27	49.03		-0.413
37.28	48.90		-0.413
37.29	48.77		-0.413
37.31	48.63		-0.413
37.32	48.50		-0.413
37.34	48.37		-0.413
37.35	48.24		-0.413
37.36	48.10		-0.413
37.38	47.97		-0.412
37.39	47.84		-0.413
37.40	47.70		-0.413
37.41	47.57		-0.412
37.43	47.44		-0.412
37.44	47.30		-0.412
37.46	47.17		-0.412
37.47	47.04		-0.412
37.48	46.90		-0.412
37.49	46.77		-0.412
37.51	46.64		-0.412
37.52	46.50		-0.412
37.54	46.37		-0.411
37.55	46.24		-0.411
37.56	46.10		-0.411
37.58	45.97		-0.411
37.59	45.84		-0.411
37.60	45.70		-0.411
37.61	45.57		-0.411
37.63	45.44		-0.411
37.64	45.30		-0.411
37.66	45.17		-0.411
37.67	45.04		-0.411
37.68	44.91		-0.410
37.69	44.77		-0.410
37.71	44.64		-0.410
37.72	44.51		-0.410
37.74	44.37		-0.410
37.75	44.24		-0.410
37.76	44.11		-0.410
37.78	43.97		-0.410
37.79	43.84		-0.410
37.80	43.71		-0.410
37.81	43.57		-0.410
37.83	43.44		-0.409
37.84	43.31		-0.409
37.86	43.17		-0.409
37.87	43.04		-0.409
37.88	42.91		-0.409
37.89	42.78		-0.408
37.91	42.64		-0.408
37.92	42.51		-0.408
37.94	42.38		-0.408
37.95	42.24		-0.408
37.96	42.11		-0.408
37.98	41.98		-0.408
37.99	41.84		-0.408
38.00	41.71		-0.408
38.01	41.58		-0.408
38.03	41.44		-0.407
38.04	41.31		-0.407
38.06	41.18		-0.407
38.07	41.04		-0.407
38.08	40.91		-0.407
38.09	40.78		-0.407
38.11	40.64		-0.407
38.12	40.51		-0.407
38.14	40.38		-0.407
38.15	40.24		-0.407
38.16	40.11		-0.407
38.18	39.98		-0.407
38.19	39.84		-0.407
38.20	39.71		-0.407
38.21	39.58		-0.407
38.23	39.44		-0.407
38.24	39.31		-0.406
38.26	39.18		-0.407
38.27	39.04		-0.406
38.28	38.91		-0.405
38.29	38.78		-0.405
38.31	38.64		-0.405
38.32	38.51		-0.405
38.34	38.38		-0.405
38.35	38.24		-0.405
38.36	38.11		-0.405
38.38	37.98		-0.405
38.39	37.84		-0.405
38.40	37.71		-0.405
38.41	37.58		-0.405
38.43	37.45		-0.405
38.44	37.31		-0.405
38.46	37.18		-0.405
38.47	37.05		-0.404
38.48	36.91		-0.404
38.49	36.78		-0.404
38.51	36.65		-0.404
38.52	36.51		-0.404
38.54	36.38		-0.404
38.55	36.25		-0.404
38.56	36.11		-0.404
38.58	35.98		-0.404
38.59	35.85		-0.404
38.60	35.71		-0.404
38.61	35.58		-0.404
38.63	35.45		-0.403
38.64	35.31		-0.403
38.66	35.18		-0.403
38.67	35.05		-0.403
38.68	34.92		-0.403
38.69	34.78		-0.403
38.71	34.65		-0.403
38.72	34.51		-0.403
38.74	34.38		-0.402
38.75	34.25		-0.402
38.76	34.11		-0.402
38.78	33.98		-0.402
38.79	33.85		-0.402
38.80	33.71		-0.402
38.81	33.58		-0.402
38.83	33.45		-0.402
38.84	33.32		-0.402
38.86	33.18		-0.402
38.87	33.05		-0.401
38.88	32.92		-0.401
38.89	32.78		-0.401
38.91	32.65		-0.401
38.92	32.52		-0.401
38.94	32.38		-0.401
38.95	32.25
38.96	32.12
38.98	31.98
38.99	31.85
39.00