File: Data/2024_09_17_Indium_CHM343_DSC.txt
Filename	2024_09_17_Indium_CHM343_DSC
Instrument name	DSC2A-00468 (192.168.1.100)
Operator	CHM343
rundate	9/17/2024
Sample name	2024_09_17_Indium_CHM343_DSC
proceduresegments	Equilibrate 100.00 °C; Ramp 10.00 °C/min to 200.00 °C; Isothermal 1.0 min; Ramp 10.00 °C/min to 100.00 °C; Isothermal 1.0 min; Ramp 10.00 °C/min to 200.00 °C
[File Parameters]
Run date	9/17/2024 7:33:06 PM
Trios version	5.1.1.46572
Original File Name	C:\ProgramData\TA Instruments\TRIOS\Data\2024_09_17_Indium_CHM343_DSC.tri
Current File Name	D:\DSC2500\CHM343\2024_09_17_Indium_CHM343_DSC.tri
[Procedure]
Procedure Name	CHM343_Fall2024_Indium
Sample Name	2024_09_17_Indium_CHM343_DSC
Sample Mass	2.26 mg
Reference Sample Mass	0 mg
Pan Mass	54.24 mg
Pan Number	25
Reference Pan Mass	54 mg
Reference Pan Number	19
Pan Type	Aluminum
Comments	Indium Wire - Al Hermetic Sealed Pan, with ref Al pan.
Project Name	Lab 4 - Fall 2024
Operator	CHM343
Test	Custom
Unload Max Temperature	30
Unload Min Temperature	30
Load Max Temperature	30
Load Min Temperature	30
Stop on Gas Flow Error	Yes
[Signal List]
Signal #1	Time (min)
Signal #2	Temperature (°C)
Signal #3	Heat Flow (mW)
Signal #4	Delta T (µV)
Signal #5	Delta Tzero (µV)
Signal #6	Tzero Temperature (°C)
Signal #7	Cell Purge (mL/min)
Signal #8	Heater Temp (°C)
Signal #9	Power Delivered (W)
Signal #10	Reference Junction Temperature (°C)
Signal #11	Flange Temperature (°C)
Signal #12	Heat Flow Phase (rad)
Signal #13	Total Heat Capacity (J/°C)
Signal #14	Heat Capacity (J/°C)
[Configuration]
Company Name	ASU
Instrument Name	DSC2A-00468
Instrument Type	DSC2500
Serial Number	DSC2A-00468
IP	192.168.1.100
Location of Instrument	MRRC
DisplayType	Unknown
Sample Interval 	0.1 s/pt
Selected Heat Flow	T4P
Exotherm Direction	Down
Cell Serial	DRC2-00792
Lid Type	Standard
Cooler	RCS 90
Leave Cooler on at End of Sequence	On
Gas 2	Nitrogen
Gas Selected	Channel 1
Flow Rate	50 mL/min
Secondary Purge	On
Licensed Heat Flow	Heat Flow T4P
Modulation Licensed	Yes
[Versions]
Common IDD Version	1
Cortex Version	VER 2.10.2.31
Driver	5.0.0.6
GDM Version	1.0.3.3
TouchscreenVersion	1.0.0.16145
FEP Version	1.2.1.21
FEP Bootloader	2.0.0.5
AutoSampler Version	2.1.1.26
Auto Sampler Bootloader	2.0.0.5
FCM Version	1.1.0.3
FCM Bootloader	2.0.0.5
[Experiment Logs]
Experiment Log Entry # 1	Air Cool is off.
Experiment Log Entry # 3	Equilibrate Segment 100 (C) Started
Experiment Log Entry # 5	FCM module's Power Out A Current is out of range 3.729387
Experiment Log Entry # 7	FCM module's Power Out A Current is out of range 3.715376
Experiment Log Entry # 9	FCM module's Power Out A Current is out of range 3.700801
Experiment Log Entry # 11	FCM module's Power Out A Current is out of range 3.721943
Experiment Log Entry # 13	Ramp Segment 10 C/min to 200 Started
Experiment Log Entry # 15	Isothermal Segment 1 min started
Experiment Log Entry # 17	Ramp Segment 10 C/min to 100 Started
Experiment Log Entry # 19	Isothermal Segment 1 min started
Experiment Log Entry # 21	Ramp Segment 10 C/min to 200 Started
[Method Log]
Method Log Entry # 1	Equilibrate 100 °C
Method Log Entry # 2	(Ramp 53464) Ramp 10 °C/minute to 200 °C
Method Log Entry # 3	Isothermal 1 minutes
Method Log Entry # 4	(Ramp 53466) Ramp 10 °C/minute to 100 °C
Method Log Entry # 5	Isothermal 1 minutes
Method Log Entry # 6	(Ramp 53468) Ramp 10 °C/minute to 200 °C
Cell Serial	DRC2-00792
[T1 Calibration]
Slope	-0.008529666
Offset	9.636258
Initial Temperature	98.23
GUID	f8bfdadc-4977-4fdf-ba6d-0ba9134940c3
[TZero Calibration]
Date Applied	11/29/2022 4:06:13 PM
Description	From -89.059 °C to 396.009 °C at 20.000°C/min
Gas Type	Nitrogen
Pan Type	None
Source Files 1	C:\Users\yargerlab\Desktop\DSC Data\General\TZero_calibration_11_29_22_2nd(2).tri
Source Files 2	C:\Users\yargerlab\Desktop\DSC Data\General\TZero_calibration_11_29_22_2nd(3).tri
Delta T Offset	13.05235
Delta T Slope	-0.007271007
Delta T0 Offset	-13.69128
Delta T0 Slope	0.06063341
[Temperature Calibration]
Date Applied	11/29/2022 7:12:28 PM
Description	From 106.590 °C to 186.590 °C at 10.000°C/min
Gas Type	Nitrogen
Pan Type	Tzero Aluminum Hermetic
Source Files 1	C:\Users\yargerlab\Desktop\DSC Data\General\Indium(6).tri
Measured 1	157.391
Known 1	156.598
[Cell Constant Calibration]
Date Applied	11/29/2022 7:12:29 PM
Description	From 106.590 °C to 186.590 °C at 10.000°C/min
Gas Type	Nitrogen
Pan Type	Tzero Aluminum Hermetic
Source Files 1	C:\Users\yargerlab\Desktop\DSC Data\General\Indium(6).tri
T4P KCell	1.006051
Onset Slope	63.26126 mW/°C
[Direct Cp Calibration]
Date Applied	11/30/2022 11:04:51 AM
Description	From -79.983 °C to 298.409 °C at 10.000°C/min
Gas Type	Nitrogen
Pan Type	Tzero Aluminum Hermetic
Source Files 1	C:\Users\yargerlab\Desktop\DSC Data\General\Sapphire_Heat_Capacity_11_30_22.tri
[Rev Cp Calibration]
Date Applied	11/30/2022 1:58:51 PM
Description	From -79.996 °C to 292.812 °C at 3.000°C/min
Gas Type	Nitrogen
Pan Type	Tzero Aluminum Hermetic
Source Files 1	C:\Users\yargerlab\Desktop\DSC Data\General\Sapphire_MDSC_Calibration_11_30_22.tri
[step]
Ramp 10.00 °C/min to 200.00 °C
Time	Temperature	Heat Flow (Normalized)
min	°C	W/g
0.00	100.07	-0.028
0.01	100.07	-0.030
0.01	100.07	-0.034
0.02	100.08	-0.037
0.03	100.08	-0.041
0.03	100.08	-0.048
0.04	100.09	-0.061
0.05	100.09	-0.084
0.05	100.10	-0.109
0.06	100.11	-0.142
0.07	100.12	-0.180
0.07	100.14	-0.222
0.08	100.16	-0.269
0.09	100.18	-0.319
0.09	100.21	-0.367
0.10	100.24	-0.411
0.11	100.27	-0.452
0.11	100.30	-0.488
0.12	100.34	-0.519
0.13	100.38	-0.543
0.13	100.42	-0.561
0.14	100.47	-0.572
0.15	100.52	-0.574
0.15	100.56	-0.573
0.16	100.61	-0.567
0.17	100.67	-0.558
0.17	100.72	-0.544
0.18	100.77	-0.528
0.19	100.83	-0.512
0.19	100.88	-0.494
0.20	100.94	-0.473
0.21	100.99	-0.455
0.21	101.05	-0.438
0.22	101.11	-0.422
0.23	101.17	-0.406
0.23	101.23	-0.389
0.24	101.28	-0.376
0.25	101.34	-0.361
0.25	101.40	-0.349
0.26	101.46	-0.341
0.27	101.52	-0.331
0.27	101.58	-0.321
0.28	101.64	-0.311
0.29	101.71	-0.306
0.29	101.77	-0.300
0.30	101.83	-0.291
0.31	101.89	-0.284
0.31	101.95	-0.279
0.32	102.02	-0.274
0.33	102.08	-0.269
0.33	102.14	-0.266
0.34	102.21	-0.259
0.35	102.27	-0.255
0.35	102.33	-0.250
0.36	102.40	-0.244
0.37	102.46	-0.241
0.37	102.52	-0.239
0.38	102.59	-0.235
0.39	102.65	-0.229
0.39	102.72	-0.227
0.40	102.78	-0.225
0.41	102.85	-0.221
0.41	102.91	-0.219
0.42	102.98	-0.218
0.43	103.04	-0.215
0.43	103.10	-0.212
0.44	103.17	-0.211
0.45	103.23	-0.209
0.45	103.30	-0.207
0.46	103.36	-0.206
0.47	103.43	-0.205
0.47	103.49	-0.204
0.48	103.56	-0.202
0.49	103.63	-0.201
0.49	103.69	-0.200
0.50	103.76	-0.199
0.51	103.82	-0.198
0.51	103.89	-0.197
0.52	103.95	-0.196
0.53	104.02	-0.195
0.53	104.08	-0.194
0.54	104.15	-0.194
0.55	104.22	-0.193
0.55	104.28	-0.193
0.56	104.35	-0.192
0.57	104.41	-0.192
0.57	104.48	-0.191
0.58	104.54	-0.191
0.59	104.61	-0.190
0.59	104.68	-0.189
0.60	104.74	-0.189
0.61	104.81	-0.188
0.61	104.87	-0.188
0.62	104.94	-0.187
0.63	105.01	-0.187
0.63	105.07	-0.187
0.64	105.14	-0.186
0.65	105.20	-0.186
0.65	105.27	-0.185
0.66	105.33	-0.185
0.67	105.40	-0.185
0.67	105.47	-0.185
0.68	105.53	-0.184
0.69	105.60	-0.184
0.69	105.67	-0.184
0.70	105.73	-0.184
0.71	105.80	-0.183
0.71	105.86	-0.183
0.72	105.93	-0.183
0.73	106.00	-0.183
0.73	106.06	-0.182
0.74	106.13	-0.182
0.75	106.20	-0.182
0.75	106.26	-0.182
0.76	106.33	-0.181
0.77	106.39	-0.181
0.77	106.46	-0.181
0.78	106.53	-0.181
0.79	106.59	-0.180
0.79	106.66	-0.180
0.80	106.73	-0.180
0.81	106.79	-0.180
0.81	106.86	-0.179
0.82	106.92	-0.179
0.83	106.99	-0.179
0.83	107.06	-0.179
0.84	107.12	-0.178
0.85	107.19	-0.178
0.85	107.25	-0.178
0.86	107.32	-0.178
0.87	107.39	-0.178
0.87	107.45	-0.178
0.88	107.52	-0.178
0.89	107.59	-0.177
0.89	107.65	-0.177
0.90	107.72	-0.177
0.91	107.79	-0.177
0.91	107.85	-0.177
0.92	107.92	-0.177
0.93	107.98	-0.176
0.93	108.05	-0.176
0.94	108.12	-0.176
0.95	108.18	-0.176
0.95	108.25	-0.176
0.96	108.32	-0.176
0.97	108.38	-0.175
0.97	108.45	-0.175
0.98	108.52	-0.175
0.99	108.58	-0.175
0.99	108.65	-0.175
1.00	108.72	-0.175
1.01	108.78	-0.175
1.01	108.85	-0.174
1.02	108.92	-0.174
1.03	108.98	-0.174
1.03	109.05	-0.174
1.04	109.11	-0.174
1.05	109.18	-0.174
1.05	109.25	-0.174
1.06	109.31	-0.174
1.07	109.38	-0.173
1.07	109.45	-0.173
1.08	109.51	-0.173
1.09	109.58	-0.173
1.09	109.65	-0.173
1.10	109.71	-0.173
1.11	109.78	-0.173
1.11	109.85	-0.173
1.12	109.91	-0.173
1.13	109.98	-0.173
1.13	110.05	-0.173
1.14	110.11	-0.173
1.15	110.18	-0.173
1.15	110.25	-0.173
1.16	110.31	-0.172
1.17	110.38	-0.172
1.17	110.44	-0.172
1.18	110.51	-0.172
1.19	110.58	-0.172
1.19	110.64	-0.172
1.20	110.71	-0.172
1.21	110.78	-0.172
1.21	110.84	-0.172
1.22	110.91	-0.172
1.23	110.98	-0.172
1.23	111.04	-0.172
1.24	111.11	-0.171
1.25	111.18	-0.171
1.25	111.24	-0.171
1.26	111.31	-0.171
1.27	111.38	-0.171
1.27	111.44	-0.171
1.28	111.51	-0.171
1.29	111.58	-0.171
1.29	111.64	-0.171
1.30	111.71	-0.171
1.31	111.78	-0.171
1.31	111.84	-0.171
1.32	111.91	-0.171
1.33	111.98	-0.171
1.33	112.04	-0.171
1.34	112.11	-0.171
1.35	112.17	-0.171
1.35	112.24	-0.171
1.36	112.31	-0.171
1.37	112.38	-0.170
1.37	112.44	-0.170
1.38	112.51	-0.170
1.39	112.57	-0.170
1.39	112.64	-0.170
1.40	112.71	-0.170
1.41	112.78	-0.170
1.41	112.84	-0.170
1.42	112.91	-0.170
1.43	112.97	-0.170
1.43	113.04	-0.170
1.44	113.11	-0.170
1.45	113.17	-0.170
1.45	113.24	-0.170
1.46	113.31	-0.170
1.47	113.37	-0.170
1.47	113.44	-0.170
1.48	113.51	-0.170
1.49	113.58	-0.170
1.49	113.64	-0.170
1.50	113.71	-0.170
1.51	113.77	-0.170
1.51	113.84	-0.170
1.52	113.91	-0.170
1.53	113.97	-0.170
1.53	114.04	-0.170
1.54	114.11	-0.170
1.55	114.17	-0.170
1.55	114.24	-0.170
1.56	114.31	-0.170
1.57	114.37	-0.170
1.57	114.44	-0.170
1.58	114.51	-0.170
1.59	114.57	-0.170
1.59	114.64	-0.170
1.60	114.71	-0.170
1.61	114.77	-0.170
1.61	114.84	-0.170
1.62	114.91	-0.170
1.63	114.98	-0.170
1.63	115.04	-0.170
1.64	115.11	-0.170
1.65	115.17	-0.170
1.65	115.24	-0.170
1.66	115.31	-0.170
1.67	115.37	-0.170
1.67	115.44	-0.170
1.68	115.51	-0.170
1.69	115.57	-0.170
1.69	115.64	-0.170
1.70	115.71	-0.170
1.71	115.77	-0.170
1.71	115.84	-0.170
1.72	115.91	-0.170
1.73	115.97	-0.170
1.73	116.04	-0.170
1.74	116.11	-0.170
1.75	116.18	-0.170
1.75	116.24	-0.170
1.76	116.31	-0.170
1.77	116.38	-0.170
1.77	116.44	-0.170
1.78	116.51	-0.170
1.79	116.57	-0.170
1.79	116.64	-0.170
1.80	116.71	-0.170
1.81	116.77	-0.170
1.81	116.84	-0.170
1.82	116.91	-0.170
1.83	116.97	-0.169
1.83	117.04	-0.169
1.84	117.11	-0.169
1.85	117.17	-0.169
1.85	117.24	-0.169
1.86	117.31	-0.169
1.87	117.37	-0.169
1.87	117.44	-0.169
1.88	117.51	-0.169
1.89	117.57	-0.169
1.89	117.64	-0.169
1.90	117.71	-0.169
1.91	117.77	-0.170
1.91	117.84	-0.169
1.92	117.91	-0.169
1.93	117.97	-0.170
1.93	118.04	-0.170
1.94	118.11	-0.170
1.95	118.17	-0.170
1.95	118.24	-0.170
1.96	118.31	-0.169
1.97	118.37	-0.169
1.97	118.44	-0.169
1.98	118.51	-0.169
1.99	118.57	-0.169
1.99	118.64	-0.169
2.00	118.71	-0.169
2.01	118.77	-0.169
2.01	118.84	-0.169
2.02	118.91	-0.169
2.03	118.97	-0.169
2.03	119.04	-0.169
2.04	119.11	-0.169
2.05	119.17	-0.169
2.05	119.24	-0.169
2.06	119.31	-0.169
2.07	119.37	-0.169
2.07	119.44	-0.169
2.08	119.51	-0.169
2.09	119.57	-0.169
2.09	119.64	-0.169
2.10	119.71	-0.169
2.11	119.77	-0.169
2.11	119.84	-0.169
2.12	119.91	-0.169
2.13	119.97	-0.169
2.13	120.04	-0.169
2.14	120.11	-0.169
2.15	120.18	-0.169
2.15	120.24	-0.169
2.16	120.31	-0.169
2.17	120.37	-0.169
2.17	120.44	-0.169
2.18	120.51	-0.169
2.19	120.58	-0.169
2.19	120.64	-0.169
2.20	120.71	-0.169
2.21	120.78	-0.169
2.21	120.84	-0.169
2.22	120.91	-0.169
2.23	120.97	-0.169
2.23	121.04	-0.169
2.24	121.11	-0.169
2.25	121.18	-0.169
2.25	121.24	-0.169
2.26	121.31	-0.169
2.27	121.38	-0.169
2.27	121.44	-0.169
2.28	121.51	-0.169
2.29	121.58	-0.169
2.29	121.64	-0.168
2.30	121.71	-0.168
2.31	121.78	-0.168
2.31	121.84	-0.168
2.32	121.91	-0.168
2.33	121.98	-0.168
2.33	122.04	-0.168
2.34	122.11	-0.168
2.35	122.18	-0.168
2.35	122.24	-0.168
2.36	122.31	-0.168
2.37	122.38	-0.168
2.37	122.44	-0.168
2.38	122.51	-0.168
2.39	122.58	-0.168
2.39	122.64	-0.168
2.40	122.71	-0.168
2.41	122.78	-0.168
2.41	122.84	-0.168
2.42	122.91	-0.168
2.43	122.98	-0.168
2.43	123.04	-0.168
2.44	123.11	-0.168
2.45	123.18	-0.168
2.45	123.24	-0.168
2.46	123.31	-0.168
2.47	123.38	-0.168
2.47	123.44	-0.168
2.48	123.51	-0.168
2.49	123.58	-0.168
2.49	123.64	-0.168
2.50	123.71	-0.168
2.51	123.78	-0.168
2.51	123.84	-0.168
2.52	123.91	-0.168
2.53	123.98	-0.168
2.53	124.04	-0.168
2.54	124.11	-0.168
2.55	124.18	-0.168
2.55	124.24	-0.168
2.56	124.31	-0.168
2.57	124.38	-0.168
2.57	124.44	-0.168
2.58	124.51	-0.168
2.59	124.58	-0.168
2.59	124.64	-0.168
2.60	124.71	-0.168
2.61	124.78	-0.168
2.61	124.84	-0.168
2.62	124.91	-0.167
2.63	124.98	-0.167
2.63	125.04	-0.167
2.64	125.11	-0.167
2.65	125.18	-0.167
2.65	125.24	-0.167
2.66	125.31	-0.167
2.67	125.38	-0.167
2.67	125.44	-0.167
2.68	125.51	-0.167
2.69	125.58	-0.167
2.69	125.64	-0.167
2.70	125.71	-0.167
2.71	125.78	-0.167
2.71	125.84	-0.167
2.72	125.91	-0.167
2.73	125.98	-0.167
2.73	126.04	-0.167
2.74	126.11	-0.167
2.75	126.18	-0.167
2.75	126.24	-0.167
2.76	126.31	-0.167
2.77	126.38	-0.167
2.77	126.44	-0.167
2.78	126.51	-0.166
2.79	126.58	-0.165
2.79	126.64	-0.160
2.80	126.71	-0.147
2.81	126.78	-0.109
2.81	126.84	-0.077
2.82	126.91	-0.075
2.83	126.97	-0.079
2.83	127.04	-0.069
2.84	127.10	-0.031
2.85	127.17	0.202
2.85	127.22	0.711
2.86	127.27	0.747
2.87	127.34	0.347
2.87	127.40	0.197
2.88	127.47	0.121
2.89	127.54	0.075
2.89	127.61	0.050
2.90	127.67	0.037
2.91	127.74	0.026
2.91	127.81	0.019
2.92	127.88	0.012
2.93	127.95	0.003
2.93	128.01	0.002
2.94	128.08	0.000
2.95	128.15	-0.003
2.95	128.22	-0.004
2.96	128.28	-0.007
2.97	128.35	-0.009
2.97	128.42	-0.011
2.98	128.49	-0.012
2.99	128.55	-0.015
2.99	128.62	-0.017
3.00	128.69	-0.018
3.01	128.76	-0.021
3.01	128.82	-0.024
3.02	128.89	-0.025
3.03	128.96	-0.025
3.03	129.02	-0.026
3.04	129.09	-0.027
3.05	129.16	-0.028
3.05	129.22	-0.028
3.06	129.29	-0.029
3.07	129.36	-0.028
3.07	129.43	-0.028
3.08	129.49	-0.028
3.09	129.56	-0.028
3.09	129.63	-0.028
3.10	129.69	-0.028
3.11	129.76	-0.028
3.11	129.83	-0.028
3.12	129.89	-0.028
3.13	129.96	-0.028
3.13	130.03	-0.029
3.14	130.09	-0.029
3.15	130.16	-0.030
3.15	130.23	-0.031
3.16	130.29	-0.031
3.17	130.36	-0.032
3.17	130.43	-0.033
3.18	130.49	-0.033
3.19	130.56	-0.033
3.19	130.63	-0.034
3.20	130.70	-0.034
3.21	130.76	-0.034
3.21	130.83	-0.034
3.22	130.90	-0.035
3.23	130.96	-0.035
3.23	131.03	-0.035
3.24	131.10	-0.035
3.25	131.16	-0.035
3.25	131.23	-0.035
3.26	131.30	-0.035
3.27	131.36	-0.035
3.27	131.43	-0.036
3.28	131.50	-0.036
3.29	131.56	-0.036
3.29	131.63	-0.036
3.30	131.70	-0.036
3.31	131.76	-0.036
3.31	131.83	-0.036
3.32	131.90	-0.037
3.33	131.96	-0.037
3.33	132.03	-0.037
3.34	132.10	-0.037
3.35	132.16	-0.037
3.35	132.23	-0.037
3.36	132.30	-0.037
3.37	132.36	-0.037
3.37	132.43	-0.037
3.38	132.50	-0.038
3.39	132.56	-0.038
3.39	132.63	-0.038
3.40	132.70	-0.038
3.41	132.76	-0.038
3.41	132.83	-0.038
3.42	132.90	-0.038
3.43	132.96	-0.038
3.43	133.03	-0.038
3.44	133.10	-0.038
3.45	133.16	-0.038
3.45	133.23	-0.039
3.46	133.30	-0.039
3.47	133.36	-0.039
3.47	133.43	-0.039
3.48	133.50	-0.039
3.49	133.56	-0.039
3.49	133.63	-0.039
3.50	133.70	-0.039
3.51	133.76	-0.039
3.51	133.83	-0.039
3.52	133.90	-0.039
3.53	133.96	-0.039
3.53	134.03	-0.039
3.54	134.10	-0.039
3.55	134.17	-0.039
3.55	134.23	-0.039
3.56	134.30	-0.039
3.57	134.36	-0.039
3.57	134.43	-0.039
3.58	134.50	-0.039
3.59	134.57	-0.039
3.59	134.63	-0.039
3.60	134.70	-0.039
3.61	134.76	-0.039
3.61	134.83	-0.039
3.62	134.90	-0.039
3.63	134.96	-0.039
3.63	135.03	-0.039
3.64	135.10	-0.039
3.65	135.16	-0.039
3.65	135.23	-0.039
3.66	135.30	-0.039
3.67	135.36	-0.039
3.67	135.43	-0.039
3.68	135.50	-0.039
3.69	135.56	-0.039
3.69	135.63	-0.039
3.70	135.70	-0.040
3.71	135.77	-0.040
3.71	135.83	-0.040
3.72	135.90	-0.039
3.73	135.97	-0.039
3.73	136.03	-0.039
3.74	136.10	-0.039
3.75	136.17	-0.039
3.75	136.23	-0.039
3.76	136.30	-0.039
3.77	136.37	-0.039
3.77	136.43	-0.039
3.78	136.50	-0.040
3.79	136.57	-0.040
3.79	136.63	-0.040
3.80	136.70	-0.040
3.81	136.77	-0.040
3.81	136.83	-0.040
3.82	136.90	-0.040
3.83	136.97	-0.040
3.83	137.03	-0.040
3.84	137.10	-0.040
3.85	137.17	-0.040
3.85	137.23	-0.040
3.86	137.30	-0.040
3.87	137.37	-0.040
3.87	137.43	-0.040
3.88	137.50	-0.040
3.89	137.57	-0.039
3.89	137.63	-0.039
3.90	137.70	-0.039
3.91	137.77	-0.039
3.91	137.83	-0.039
3.92	137.90	-0.039
3.93	137.97	-0.039
3.93	138.03	-0.039
3.94	138.10	-0.039
3.95	138.17	-0.039
3.95	138.23	-0.039
3.96	138.30	-0.039
3.97	138.37	-0.039
3.97	138.43	-0.039
3.98	138.50	-0.039
3.99	138.57	-0.039
3.99	138.63	-0.039
4.00	138.70	-0.040
4.01	138.77	-0.039
4.01	138.83	-0.040
4.02	138.90	-0.040
4.03	138.97	-0.040
4.03	139.03	-0.040
4.04	139.10	-0.040
4.05	139.17	-0.040
4.05	139.23	-0.040
4.06	139.30	-0.040
4.07	139.37	-0.040
4.07	139.43	-0.040
4.08	139.50	-0.040
4.09	139.57	-0.040
4.09	139.63	-0.040
4.10	139.70	-0.040
4.11	139.77	-0.040
4.11	139.83	-0.040
4.12	139.90	-0.040
4.13	139.97	-0.040
4.13	140.03	-0.040
4.14	140.10	-0.040
4.15	140.17	-0.040
4.15	140.23	-0.040
4.16	140.30	-0.040
4.17	140.37	-0.040
4.17	140.43	-0.040
4.18	140.50	-0.040
4.19	140.57	-0.040
4.19	140.63	-0.040
4.20	140.70	-0.040
4.21	140.77	-0.040
4.21	140.84	-0.040
4.22	140.90	-0.040
4.23	140.97	-0.040
4.23	141.04	-0.040
4.24	141.10	-0.040
4.25	141.17	-0.040
4.25	141.23	-0.040
4.26	141.30	-0.040
4.27	141.37	-0.040
4.27	141.44	-0.040
4.28	141.50	-0.040
4.29	141.57	-0.039
4.29	141.63	-0.039
4.30	141.70	-0.039
4.31	141.77	-0.039
4.31	141.84	-0.039
4.32	141.90	-0.039
4.33	141.97	-0.039
4.33	142.04	-0.039
4.34	142.10	-0.039
4.35	142.17	-0.039
4.35	142.23	-0.039
4.36	142.30	-0.039
4.37	142.37	-0.039
4.37	142.44	-0.039
4.38	142.50	-0.039
4.39	142.57	-0.039
4.39	142.64	-0.039
4.40	142.70	-0.039
4.41	142.77	-0.039
4.41	142.84	-0.039
4.42	142.90	-0.039
4.43	142.97	-0.039
4.43	143.04	-0.039
4.44	143.10	-0.039
4.45	143.17	-0.039
4.45	143.24	-0.039
4.46	143.30	-0.039
4.47	143.37	-0.039
4.47	143.44	-0.039
4.48	143.50	-0.039
4.49	143.57	-0.039
4.49	143.64	-0.039
4.50	143.70	-0.039
4.51	143.77	-0.039
4.51	143.84	-0.039
4.52	143.90	-0.039
4.53	143.97	-0.039
4.53	144.04	-0.039
4.54	144.10	-0.039
4.55	144.17	-0.039
4.55	144.24	-0.039
4.56	144.30	-0.039
4.57	144.37	-0.039
4.57	144.44	-0.039
4.58	144.50	-0.039
4.59	144.57	-0.039
4.59	144.64	-0.039
4.60	144.70	-0.039
4.61	144.77	-0.039
4.61	144.84	-0.039
4.62	144.90	-0.039
4.63	144.97	-0.039
4.63	145.04	-0.039
4.64	145.10	-0.039
4.65	145.17	-0.039
4.65	145.24	-0.039
4.66	145.30	-0.039
4.67	145.37	-0.039
4.67	145.44	-0.039
4.68	145.50	-0.039
4.69	145.57	-0.039
4.69	145.64	-0.039
4.70	145.70	-0.039
4.71	145.77	-0.039
4.71	145.84	-0.039
4.72	145.90	-0.039
4.73	145.97	-0.039
4.73	146.04	-0.039
4.74	146.10	-0.039
4.75	146.17	-0.039
4.75	146.24	-0.039
4.76	146.30	-0.039
4.77	146.37	-0.039
4.77	146.44	-0.039
4.78	146.50	-0.039
4.79	146.57	-0.039
4.79	146.64	-0.039
4.80	146.70	-0.039
4.81	146.77	-0.039
4.81	146.84	-0.039
4.82	146.90	-0.039
4.83	146.97	-0.039
4.83	147.04	-0.039
4.84	147.10	-0.039
4.85	147.17	-0.039
4.85	147.24	-0.039
4.86	147.30	-0.039
4.87	147.37	-0.039
4.87	147.44	-0.039
4.88	147.50	-0.039
4.89	147.57	-0.039
4.89	147.64	-0.039
4.90	147.70	-0.039
4.91	147.77	-0.039
4.91	147.84	-0.039
4.92	147.90	-0.039
4.93	147.97	-0.039
4.93	148.04	-0.039
4.94	148.10	-0.039
4.95	148.17	-0.038
4.95	148.24	-0.038
4.96	148.31	-0.038
4.97	148.37	-0.038
4.97	148.44	-0.038
4.98	148.50	-0.038
4.99	148.57	-0.038
4.99	148.64	-0.038
5.00	148.71	-0.038
5.01	148.77	-0.038
5.01	148.84	-0.038
5.02	148.90	-0.038
5.03	148.97	-0.038
5.03	149.04	-0.038
5.04	149.11	-0.038
5.05	149.17	-0.038
5.05	149.24	-0.038
5.06	149.31	-0.038
5.07	149.37	-0.038
5.07	149.44	-0.038
5.08	149.50	-0.038
5.09	149.57	-0.038
5.09	149.64	-0.038
5.10	149.71	-0.038
5.11	149.77	-0.038
5.11	149.84	-0.038
5.12	149.90	-0.038
5.13	149.97	-0.038
5.13	150.04	-0.038
5.14	150.11	-0.038
5.15	150.17	-0.038
5.15	150.24	-0.038
5.16	150.31	-0.037
5.17	150.37	-0.037
5.17	150.44	-0.037
5.18	150.51	-0.037
5.19	150.57	-0.037
5.19	150.64	-0.037
5.20	150.71	-0.037
5.21	150.77	-0.037
5.21	150.84	-0.037
5.22	150.91	-0.037
5.23	150.97	-0.037
5.23	151.04	-0.037
5.24	151.11	-0.037
5.25	151.17	-0.037
5.25	151.24	-0.037
5.26	151.31	-0.037
5.27	151.37	-0.037
5.27	151.44	-0.037
5.28	151.51	-0.037
5.29	151.57	-0.037
5.29	151.64	-0.037
5.30	151.71	-0.037
5.31	151.77	-0.037
5.31	151.84	-0.037
5.32	151.91	-0.037
5.33	151.97	-0.037
5.33	152.04	-0.037
5.34	152.11	-0.037
5.35	152.17	-0.037
5.35	152.24	-0.037
5.36	152.31	-0.037
5.37	152.37	-0.037
5.37	152.44	-0.037
5.38	152.51	-0.037
5.39	152.57	-0.037
5.39	152.64	-0.037
5.40	152.71	-0.037
5.41	152.77	-0.037
5.41	152.84	-0.037
5.42	152.91	-0.037
5.43	152.97	-0.037
5.43	153.04	-0.036
5.44	153.11	-0.037
5.45	153.17	-0.037
5.45	153.24	-0.036
5.46	153.31	-0.036
5.47	153.37	-0.037
5.47	153.44	-0.036
5.48	153.51	-0.036
5.49	153.57	-0.036
5.49	153.64	-0.036
5.50	153.71	-0.036
5.51	153.77	-0.036
5.51	153.84	-0.036
5.52	153.91	-0.036
5.53	153.97	-0.036
5.53	154.04	-0.036
5.54	154.11	-0.036
5.55	154.17	-0.036
5.55	154.24	-0.036
5.56	154.31	-0.036
5.57	154.37	-0.036
5.57	154.44	-0.036
5.58	154.51	-0.036
5.59	154.57	-0.036
5.59	154.64	-0.036
5.60	154.71	-0.036
5.61	154.77	-0.035
5.61	154.84	-0.035
5.62	154.91	-0.035
5.63	154.98	-0.035
5.63	155.04	-0.035
5.64	155.11	-0.035
5.65	155.17	-0.035
5.65	155.24	-0.035
5.66	155.31	-0.035
5.67	155.37	-0.035
5.67	155.44	-0.035
5.68	155.51	-0.035
5.69	155.57	-0.035
5.69	155.64	-0.035
5.70	155.71	-0.035
5.71	155.77	-0.035
5.71	155.84	-0.035
5.72	155.91	-0.035
5.73	155.97	-0.035
5.73	156.04	-0.035
5.74	156.11	-0.035
5.75	156.17	-0.035
5.75	156.24	-0.035
5.76	156.31	-0.035
5.77	156.37	-0.035
5.77	156.44	-0.035
5.78	156.51	-0.034
5.79	156.57	-0.034
5.79	156.64	-0.034
5.80	156.71	-0.034
5.81	156.77	-0.034
5.81	156.84	-0.032
5.82	156.91	-0.026
5.83	156.97	0.003
5.83	157.04	0.036
5.84	157.11	0.062
5.85	157.17	0.099
5.85	157.23	0.153
5.86	157.30	0.218
5.87	157.36	0.299
5.87	157.42	0.412
5.88	157.48	0.540
5.89	157.54	0.669
5.89	157.60	0.823
5.90	157.66	1.023
5.91	157.71	1.297
5.91	157.76	1.668
5.92	157.80	2.074
5.93	157.85	2.408
5.93	157.89	2.658
5.94	157.93	2.874
5.95	157.97	3.033
5.95	158.01	3.148
5.96	158.05	3.250
5.97	158.10	3.336
5.97	158.14	3.389
5.98	158.19	3.413
5.99	158.24	3.403
5.99	158.29	3.363
6.00	158.35	3.317
6.01	158.41	3.186
6.01	158.47	2.656
6.02	158.55	1.829
6.03	158.64	1.303
6.03	158.73	1.058
6.04	158.82	0.897
6.05	158.91	0.795
6.05	158.99	0.714
6.06	159.08	0.646
6.07	159.16	0.590
6.07	159.25	0.543
6.08	159.33	0.494
6.09	159.41	0.453
6.09	159.49	0.420
6.10	159.57	0.384
6.11	159.64	0.353
6.11	159.72	0.322
6.12	159.80	0.297
6.13	159.87	0.271
6.13	159.95	0.247
6.14	160.02	0.227
6.15	160.09	0.206
6.15	160.17	0.185
6.16	160.24	0.170
6.17	160.31	0.157
6.17	160.38	0.143
6.18	160.45	0.127
6.19	160.52	0.114
6.19	160.60	0.103
6.20	160.67	0.093
6.21	160.74	0.086
6.21	160.81	0.075
6.22	160.88	0.070
6.23	160.95	0.061
6.23	161.02	0.050
6.24	161.08	0.046
6.25	161.15	0.041
6.25	161.22	0.034
6.26	161.29	0.029
6.27	161.36	0.025
6.27	161.43	0.019
6.28	161.49	0.017
6.29	161.56	0.014
6.29	161.63	0.009
6.30	161.70	0.004
6.31	161.76	0.002
6.31	161.83	0.001
6.32	161.90	0.001
6.33	161.97	-0.004
6.33	162.04	-0.006
6.34	162.10	-0.007
6.35	162.17	-0.010
6.35	162.24	-0.012
6.36	162.30	-0.013
6.37	162.37	-0.013
6.37	162.44	-0.014
6.38	162.51	-0.016
6.39	162.57	-0.017
6.39	162.64	-0.017
6.40	162.71	-0.018
6.41	162.77	-0.018
6.41	162.84	-0.018
6.42	162.91	-0.019
6.43	162.98	-0.020
6.43	163.04	-0.020
6.44	163.11	-0.021
6.45	163.18	-0.021
6.45	163.24	-0.021
6.46	163.31	-0.021
6.47	163.38	-0.021
6.47	163.44	-0.021
6.48	163.51	-0.022
6.49	163.58	-0.022
6.49	163.64	-0.022
6.50	163.71	-0.022
6.51	163.78	-0.023
6.51	163.84	-0.023
6.52	163.91	-0.023
6.53	163.98	-0.023
6.53	164.04	-0.023
6.54	164.11	-0.024
6.55	164.18	-0.024
6.55	164.24	-0.024
6.56	164.31	-0.024
6.57	164.38	-0.024
6.57	164.44	-0.025
6.58	164.51	-0.025
6.59	164.58	-0.025
6.59	164.64	-0.025
6.60	164.71	-0.025
6.61	164.78	-0.026
6.61	164.84	-0.026
6.62	164.91	-0.026
6.63	164.98	-0.026
6.63	165.04	-0.026
6.64	165.11	-0.026
6.65	165.18	-0.026
6.65	165.24	-0.027
6.66	165.31	-0.027
6.67	165.38	-0.027
6.67	165.45	-0.027
6.68	165.51	-0.027
6.69	165.58	-0.027
6.69	165.65	-0.027
6.70	165.71	-0.027
6.71	165.78	-0.027
6.71	165.85	-0.027
6.72	165.91	-0.028
6.73	165.98	-0.028
6.73	166.04	-0.028
6.74	166.11	-0.028
6.75	166.18	-0.028
6.75	166.24	-0.028
6.76	166.31	-0.028
6.77	166.38	-0.028
6.77	166.45	-0.028
6.78	166.51	-0.028
6.79	166.58	-0.028
6.79	166.64	-0.028
6.80	166.71	-0.028
6.81	166.78	-0.028
6.81	166.84	-0.029
6.82	166.91	-0.029
6.83	166.98	-0.029
6.83	167.05	-0.029
6.84	167.11	-0.029
6.85	167.18	-0.029
6.85	167.24	-0.029
6.86	167.31	-0.029
6.87	167.38	-0.029
6.87	167.45	-0.029
6.88	167.51	-0.029
6.89	167.58	-0.029
6.89	167.65	-0.029
6.90	167.71	-0.029
6.91	167.78	-0.029
6.91	167.85	-0.029
6.92	167.91	-0.029
6.93	167.98	-0.029
6.93	168.05	-0.029
6.94	168.11	-0.029
6.95	168.18	-0.029
6.95	168.25	-0.029
6.96	168.31	-0.029
6.97	168.38	-0.029
6.97	168.45	-0.029
6.98	168.51	-0.029
6.99	168.58	-0.029
6.99	168.65	-0.029
7.00	168.71	-0.029
7.01	168.78	-0.029
7.01	168.85	-0.029
7.02	168.91	-0.029
7.03	168.98	-0.029
7.03	169.05	-0.029
7.04	169.11	-0.029
7.05	169.18	-0.029
7.05	169.25	-0.029
7.06	169.31	-0.029
7.07	169.38	-0.029
7.07	169.45	-0.029
7.08	169.51	-0.029
7.09	169.58	-0.029
7.09	169.65	-0.029
7.10	169.71	-0.029
7.11	169.78	-0.029
7.11	169.85	-0.029
7.12	169.91	-0.029
7.13	169.98	-0.029
7.13	170.05	-0.029
7.14	170.11	-0.029
7.15	170.18	-0.030
7.15	170.25	-0.030
7.16	170.31	-0.030
7.17	170.38	-0.030
7.17	170.45	-0.030
7.18	170.51	-0.030
7.19	170.58	-0.030
7.19	170.65	-0.030
7.20	170.71	-0.030
7.21	170.78	-0.030
7.21	170.85	-0.030
7.22	170.91	-0.030
7.23	170.98	-0.030
7.23	171.05	-0.030
7.24	171.11	-0.030
7.25	171.18	-0.030
7.25	171.25	-0.030
7.26	171.31	-0.030
7.27	171.38	-0.030
7.27	171.45	-0.030
7.28	171.51	-0.030
7.29	171.58	-0.030
7.29	171.65	-0.030
7.30	171.71	-0.030
7.31	171.78	-0.030
7.31	171.85	-0.030
7.32	171.91	-0.030
7.33	171.98	-0.030
7.33	172.05	-0.030
7.34	172.11	-0.030
7.35	172.18	-0.030
7.35	172.25	-0.030
7.36	172.31	-0.030
7.37	172.38	-0.030
7.37	172.45	-0.030
7.38	172.51	-0.030
7.39	172.58	-0.030
7.39	172.65	-0.030
7.40	172.71	-0.030
7.41	172.78	-0.030
7.41	172.85	-0.030
7.42	172.91	-0.030
7.43	172.98	-0.030
7.43	173.05	-0.030
7.44	173.11	-0.030
7.45	173.18	-0.030
7.45	173.25	-0.030
7.46	173.31	-0.030
7.47	173.38	-0.030
7.47	173.45	-0.030
7.48	173.51	-0.030
7.49	173.58	-0.030
7.49	173.65	-0.030
7.50	173.71	-0.030
7.51	173.78	-0.030
7.51	173.85	-0.030
7.52	173.91	-0.030
7.53	173.98	-0.030
7.53	174.05	-0.030
7.54	174.11	-0.030
7.55	174.18	-0.030
7.55	174.25	-0.030
7.56	174.31	-0.030
7.57	174.38	-0.030
7.57	174.45	-0.030
7.58	174.52	-0.030
7.59	174.58	-0.030
7.59	174.65	-0.030
7.60	174.72	-0.030
7.61	174.78	-0.030
7.61	174.85	-0.030
7.62	174.92	-0.030
7.63	174.98	-0.030
7.63	175.05	-0.030
7.64	175.12	-0.030
7.65	175.18	-0.030
7.65	175.25	-0.030
7.66	175.32	-0.030
7.67	175.38	-0.030
7.67	175.45	-0.030
7.68	175.52	-0.029
7.69	175.58	-0.029
7.69	175.65	-0.029
7.70	175.72	-0.029
7.71	175.78	-0.029
7.71	175.85	-0.029
7.72	175.92	-0.029
7.73	175.98	-0.029
7.73	176.05	-0.029
7.74	176.12	-0.030
7.75	176.18	-0.030
7.75	176.25	-0.030
7.76	176.32	-0.030
7.77	176.38	-0.030
7.77	176.45	-0.030
7.78	176.52	-0.030
7.79	176.58	-0.030
7.79	176.65	-0.030
7.80	176.72	-0.030
7.81	176.78	-0.030
7.81	176.85	-0.030
7.82	176.92	-0.030
7.83	176.98	-0.030
7.83	177.05	-0.030
7.84	177.12	-0.030
7.85	177.18	-0.030
7.85	177.25	-0.030
7.86	177.32	-0.029
7.87	177.38	-0.029
7.87	177.45	-0.029
7.88	177.52	-0.029
7.89	177.58	-0.029
7.89	177.65	-0.030
7.90	177.72	-0.030
7.91	177.78	-0.030
7.91	177.85	-0.030
7.92	177.92	-0.030
7.93	177.98	-0.030
7.93	178.05	-0.030
7.94	178.12	-0.030
7.95	178.18	-0.030
7.95	178.25	-0.030
7.96	178.32	-0.030
7.97	178.38	-0.030
7.97	178.45	-0.030
7.98	178.52	-0.030
7.99	178.58	-0.030
7.99	178.65	-0.030
8.00	178.72	-0.030
8.01	178.78	-0.030
8.01	178.85	-0.030
8.02	178.92	-0.030
8.03	178.98	-0.030
8.03	179.05	-0.030
8.04	179.12	-0.030
8.05	179.18	-0.029
8.05	179.25	-0.029
8.06	179.32	-0.029
8.07	179.38	-0.029
8.07	179.45	-0.029
8.08	179.52	-0.029
8.09	179.58	-0.029
8.09	179.65	-0.029
8.10	179.72	-0.030
8.11	179.78	-0.030
8.11	179.85	-0.030
8.12	179.92	-0.030
8.13	179.98	-0.030
8.13	180.05	-0.030
8.14	180.12	-0.030
8.15	180.18	-0.030
8.15	180.25	-0.030
8.16	180.32	-0.030
8.17	180.38	-0.030
8.17	180.45	-0.030
8.18	180.52	-0.030
8.19	180.58	-0.030
8.19	180.65	-0.030
8.20	180.72	-0.030
8.21	180.78	-0.030
8.21	180.85	-0.030
8.22	180.92	-0.030
8.23	180.98	-0.030
8.23	181.05	-0.030
8.24	181.12	-0.029
8.25	181.18	-0.029
8.25	181.25	-0.029
8.26	181.32	-0.029
8.27	181.38	-0.029
8.27	181.45	-0.029
8.28	181.52	-0.029
8.29	181.58	-0.030
8.29	181.65	-0.030
8.30	181.72	-0.030
8.31	181.78	-0.029
8.31	181.85	-0.029
8.32	181.92	-0.029
8.33	181.98	-0.029
8.33	182.05	-0.029
8.34	182.12	-0.029
8.35	182.18	-0.029
8.35	182.25	-0.029
8.36	182.32	-0.029
8.37	182.38	-0.029
8.37	182.45	-0.029
8.38	182.52	-0.029
8.39	182.58	-0.029
8.39	182.65	-0.029
8.40	182.72	-0.029
8.41	182.78	-0.029
8.41	182.85	-0.029
8.42	182.92	-0.029
8.43	182.98	-0.029
8.43	183.05	-0.029
8.44	183.12	-0.029
8.45	183.18	-0.029
8.45	183.25	-0.029
8.46	183.32	-0.029
8.47	183.38	-0.029
8.47	183.45	-0.029
8.48	183.52	-0.029
8.49	183.58	-0.029
8.49	183.65	-0.029
8.50	183.72	-0.029
8.51	183.78	-0.029
8.51	183.85	-0.029
8.52	183.92	-0.029
8.53	183.99	-0.029
8.53	184.05	-0.029
8.54	184.12	-0.029
8.55	184.18	-0.029
8.55	184.25	-0.029
8.56	184.32	-0.029
8.57	184.38	-0.029
8.57	184.45	-0.029
8.58	184.52	-0.029
8.59	184.58	-0.029
8.59	184.65	-0.029
8.60	184.72	-0.029
8.61	184.78	-0.029
8.61	184.85	-0.029
8.62	184.92	-0.029
8.63	184.98	-0.029
8.63	185.05	-0.029
8.64	185.12	-0.030
8.65	185.19	-0.030
8.65	185.25	-0.030
8.66	185.32	-0.030
8.67	185.39	-0.030
8.67	185.45	-0.030
8.68	185.52	-0.030
8.69	185.59	-0.030
8.69	185.65	-0.030
8.70	185.72	-0.030
8.71	185.79	-0.030
8.71	185.85	-0.030
8.72	185.92	-0.030
8.73	185.99	-0.030
8.73	186.05	-0.029
8.74	186.12	-0.029
8.75	186.19	-0.029
8.75	186.25	-0.029
8.76	186.32	-0.029
8.77	186.39	-0.029
8.77	186.45	-0.029
8.78	186.52	-0.029
8.79	186.59	-0.029
8.79	186.65	-0.029
8.80	186.72	-0.029
8.81	186.79	-0.029
8.81	186.85	-0.029
8.82	186.92	-0.029
8.83	186.99	-0.029
8.83	187.05	-0.029
8.84	187.12	-0.029
8.85	187.19	-0.029
8.85	187.25	-0.029
8.86	187.32	-0.029
8.87	187.39	-0.029
8.87	187.45	-0.029
8.88	187.52	-0.029
8.89	187.59	-0.029
8.89	187.65	-0.029
8.90	187.72	-0.029
8.91	187.79	-0.029
8.91	187.85	-0.029
8.92	187.92	-0.029
8.93	187.99	-0.029
8.93	188.05	-0.029
8.94	188.12	-0.029
8.95	188.19	-0.029
8.95	188.25	-0.029
8.96	188.32	-0.029
8.97	188.39	-0.029
8.97	188.45	-0.029
8.98	188.52	-0.029
8.99	188.59	-0.029
8.99	188.65	-0.029
9.00	188.72	-0.029
9.01	188.79	-0.029
9.01	188.85	-0.029
9.02	188.92	-0.029
9.03	188.99	-0.029
9.03	189.05	-0.029
9.04	189.12	-0.029
9.05	189.19	-0.029
9.05	189.25	-0.029
9.06	189.32	-0.029
9.07	189.39	-0.029
9.07	189.45	-0.029
9.08	189.52	-0.029
9.09	189.59	-0.029
9.09	189.65	-0.029
9.10	189.72	-0.029
9.11	189.79	-0.029
9.11	189.85	-0.029
9.12	189.92	-0.029
9.13	189.99	-0.029
9.13	190.05	-0.029
9.14	190.12	-0.029
9.15	190.19	-0.029
9.15	190.25	-0.029
9.16	190.32	-0.029
9.17	190.39	-0.029
9.17	190.45	-0.029
9.18	190.52	-0.029
9.19	190.59	-0.029
9.19	190.65	-0.029
9.20	190.72	-0.029
9.21	190.79	-0.029
9.21	190.85	-0.029
9.22	190.92	-0.029
9.23	190.99	-0.029
9.23	191.05	-0.029
9.24	191.12	-0.029
9.25	191.19	-0.029
9.25	191.25	-0.029
9.26	191.32	-0.029
9.27	191.39	-0.029
9.27	191.45	-0.029
9.28	191.52	-0.029
9.29	191.59	-0.029
9.29	191.65	-0.029
9.30	191.72	-0.029
9.31	191.79	-0.029
9.31	191.85	-0.029
9.32	191.92	-0.029
9.33	191.99	-0.029
9.33	192.05	-0.029
9.34	192.12	-0.029
9.35	192.19	-0.029
9.35	192.25	-0.029
9.36	192.32	-0.029
9.37	192.39	-0.029
9.37	192.45	-0.029
9.38	192.52	-0.029
9.39	192.59	-0.029
9.39	192.65	-0.029
9.40	192.72	-0.029
9.41	192.79	-0.029
9.41	192.85	-0.029
9.42	192.92	-0.029
9.43	192.99	-0.029
9.43	193.06	-0.029
9.44	193.12	-0.029
9.45	193.19	-0.029
9.45	193.25	-0.029
9.46	193.32	-0.029
9.47	193.39	-0.029
9.47	193.46	-0.029
9.48	193.52	-0.029
9.49	193.59	-0.029
9.49	193.65	-0.029
9.50	193.72	-0.029
9.51	193.79	-0.029
9.51	193.85	-0.029
9.52	193.92	-0.029
9.53	193.99	-0.029
9.53	194.05	-0.029
9.54	194.12	-0.029
9.55	194.19	-0.029
9.55	194.25	-0.029
9.56	194.32	-0.029
9.57	194.39	-0.029
9.57	194.45	-0.029
9.58	194.52	-0.029
9.59	194.59	-0.029
9.59	194.65	-0.029
9.60	194.72	-0.029
9.61	194.79	-0.029
9.61	194.86	-0.029
9.62	194.92	-0.029
9.63	194.99	-0.029
9.63	195.06	-0.029
9.64	195.12	-0.029
9.65	195.19	-0.029
9.65	195.26	-0.029
9.66	195.32	-0.029
9.67	195.39	-0.029
9.67	195.45	-0.029
9.68	195.52	-0.029
9.69	195.59	-0.029
9.69	195.66	-0.029
9.70	195.72	-0.029
9.71	195.79	-0.029
9.71	195.85	-0.029
9.72	195.92	-0.029
9.73	195.99	-0.029
9.73	196.06	-0.029
9.74	196.12	-0.029
9.75	196.19	-0.029
9.75	196.26	-0.029
9.76	196.32	-0.029
9.77	196.39	-0.029
9.77	196.46	-0.029
9.78	196.52	-0.029
9.79	196.59	-0.029
9.79	196.66	-0.029
9.80	196.72	-0.029
9.81	196.79	-0.028
9.81	196.86	-0.028
9.82	196.92	-0.028
9.83	196.99	-0.028
9.83	197.06	-0.028
9.84	197.12	-0.029
9.85	197.19	-0.028
9.85	197.26	-0.028
9.86	197.32	-0.028
9.87	197.39	-0.028
9.87	197.46	-0.028
9.88	197.52	-0.028
9.89	197.59	-0.028
9.89	197.66	-0.028
9.90	197.72	-0.028
9.91	197.79	-0.028
9.91	197.86	-0.029
9.92	197.92	-0.028
9.93	197.99	-0.028
9.93	198.06	-0.029
9.94	198.12	-0.028
9.95	198.19	-0.028
9.95	198.26	-0.028
9.96	198.32	-0.028
9.97	198.39	-0.028
9.97	198.46	-0.028
9.98	198.52	-0.028
9.99	198.59	-0.028
9.99	198.66	-0.028
10.00	198.69	-0.028

[step]
Ramp 10.00 °C/min to 100.00 °C
Time	Temperature	Heat Flow (Normalized)
min	°C	W/g
11.00	200.08	-0.116
11.00	200.07	-0.116
11.01	200.07	-0.117
11.02	200.08	-0.117
11.03	200.07	-0.117
11.03	200.07	-0.117
11.04	200.07	-0.116
11.05	200.07	-0.111
11.05	200.06	-0.091
11.06	200.05	-0.067
11.07	200.04	-0.047
11.07	200.03	-0.020
11.08	200.02	0.007
11.08	200.00	0.032
11.09	199.98	0.060
11.10	199.96	0.083
11.10	199.93	0.102
11.11	199.90	0.117
11.12	199.87	0.131
11.13	199.83	0.140
11.13	199.79	0.141
11.14	199.75	0.137
11.15	199.71	0.132
11.15	199.66	0.121
11.16	199.62	0.109
11.17	199.57	0.099
11.17	199.52	0.082
11.18	199.46	0.062
11.18	199.41	0.043
11.19	199.36	0.025
11.20	199.30	0.004
11.20	199.25	-0.011
11.21	199.19	-0.023
11.22	199.13	-0.037
11.23	199.07	-0.053
11.23	199.01	-0.064
11.24	198.96	-0.075
11.25	198.90	-0.087
11.25	198.84	-0.095
11.26	198.78	-0.104
11.27	198.71	-0.115
11.27	198.65	-0.118
11.28	198.59	-0.125
11.28	198.53	-0.132
11.29	198.47	-0.135
11.30	198.41	-0.140
11.30	198.34	-0.147
11.31	198.28	-0.150
11.32	198.22	-0.151
11.33	198.15	-0.155
11.33	198.09	-0.159
11.34	198.03	-0.161
11.35	197.96	-0.164
11.35	197.90	-0.166
11.36	197.84	-0.168
11.37	197.77	-0.171
11.37	197.71	-0.173
11.38	197.64	-0.176
11.38	197.58	-0.177
11.39	197.51	-0.178
11.40	197.45	-0.178
11.40	197.38	-0.181
11.41	197.32	-0.183
11.42	197.26	-0.184
11.43	197.19	-0.185
11.43	197.13	-0.185
11.44	197.06	-0.186
11.45	196.99	-0.187
11.45	196.93	-0.188
11.46	196.86	-0.188
11.47	196.80	-0.188
11.47	196.73	-0.189
11.48	196.67	-0.189
11.48	196.60	-0.190
11.49	196.54	-0.191
11.50	196.47	-0.191
11.50	196.41	-0.192
11.51	196.34	-0.192
11.52	196.28	-0.193
11.53	196.21	-0.193
11.53	196.15	-0.193
11.54	196.08	-0.194
11.55	196.02	-0.194
11.55	195.95	-0.194
11.56	195.88	-0.194
11.57	195.82	-0.194
11.57	195.75	-0.195
11.58	195.69	-0.195
11.58	195.62	-0.195
11.59	195.56	-0.196
11.60	195.49	-0.196
11.60	195.42	-0.196
11.61	195.36	-0.196
11.62	195.29	-0.196
11.63	195.23	-0.197
11.63	195.16	-0.197
11.64	195.09	-0.197
11.65	195.03	-0.197
11.65	194.96	-0.197
11.66	194.90	-0.198
11.67	194.83	-0.198
11.67	194.77	-0.198
11.68	194.70	-0.198
11.68	194.63	-0.198
11.69	194.57	-0.199
11.70	194.50	-0.199
11.70	194.44	-0.199
11.71	194.37	-0.199
11.72	194.30	-0.199
11.73	194.24	-0.199
11.73	194.17	-0.199
11.74	194.11	-0.200
11.75	194.04	-0.200
11.75	193.97	-0.200
11.76	193.91	-0.200
11.77	193.84	-0.200
11.77	193.78	-0.200
11.78	193.71	-0.201
11.78	193.64	-0.201
11.79	193.58	-0.201
11.80	193.51	-0.201
11.80	193.45	-0.201
11.81	193.38	-0.201
11.82	193.31	-0.201
11.83	193.25	-0.201
11.83	193.18	-0.201
11.84	193.11	-0.201
11.85	193.05	-0.201
11.85	192.98	-0.201
11.86	192.92	-0.201
11.87	192.85	-0.201
11.87	192.78	-0.201
11.88	192.72	-0.201
11.88	192.65	-0.202
11.89	192.59	-0.202
11.90	192.52	-0.202
11.90	192.45	-0.202
11.91	192.39	-0.202
11.92	192.32	-0.202
11.93	192.25	-0.202
11.93	192.19	-0.202
11.94	192.12	-0.202
11.95	192.06	-0.202
11.95	191.99	-0.202
11.96	191.92	-0.203
11.97	191.86	-0.203
11.97	191.79	-0.203
11.98	191.73	-0.203
11.98	191.66	-0.203
11.99	191.59	-0.203
12.00	191.53	-0.203
12.00	191.46	-0.203
12.01	191.39	-0.203
12.02	191.33	-0.203
12.03	191.26	-0.203
12.03	191.19	-0.203
12.04	191.13	-0.203
12.05	191.06	-0.203
12.05	191.00	-0.203
12.06	190.93	-0.203
12.07	190.86	-0.203
12.07	190.80	-0.203
12.08	190.73	-0.203
12.08	190.67	-0.203
12.09	190.60	-0.203
12.10	190.53	-0.203
12.10	190.47	-0.203
12.11	190.40	-0.203
12.12	190.33	-0.203
12.13	190.27	-0.203
12.13	190.20	-0.203
12.14	190.13	-0.203
12.15	190.07	-0.203
12.15	190.00	-0.203
12.16	189.93	-0.203
12.17	189.87	-0.203
12.17	189.80	-0.203
12.18	189.74	-0.203
12.18	189.67	-0.203
12.19	189.60	-0.203
12.20	189.54	-0.203
12.20	189.47	-0.203
12.21	189.40	-0.203
12.22	189.34	-0.203
12.23	189.27	-0.202
12.23	189.20	-0.202
12.24	189.14	-0.202
12.25	189.07	-0.202
12.25	189.01	-0.202
12.26	188.94	-0.202
12.27	188.87	-0.202
12.27	188.81	-0.202
12.28	188.74	-0.202
12.28	188.67	-0.202
12.29	188.61	-0.202
12.30	188.54	-0.202
12.30	188.47	-0.202
12.31	188.41	-0.202
12.32	188.34	-0.202
12.33	188.27	-0.202
12.33	188.21	-0.202
12.34	188.14	-0.202
12.35	188.07	-0.202
12.35	188.01	-0.202
12.36	187.94	-0.202
12.37	187.88	-0.202
12.37	187.81	-0.202
12.38	187.74	-0.202
12.38	187.68	-0.202
12.39	187.61	-0.202
12.40	187.54	-0.202
12.40	187.48	-0.202
12.41	187.41	-0.201
12.42	187.34	-0.201
12.43	187.28	-0.201
12.43	187.21	-0.201
12.44	187.14	-0.201
12.45	187.08	-0.201
12.45	187.01	-0.201
12.46	186.94	-0.201
12.47	186.88	-0.201
12.47	186.81	-0.201
12.48	186.75	-0.201
12.48	186.68	-0.201
12.49	186.61	-0.201
12.50	186.55	-0.201
12.50	186.48	-0.201
12.51	186.41	-0.201
12.52	186.35	-0.200
12.53	186.28	-0.200
12.53	186.21	-0.200
12.54	186.15	-0.200
12.55	186.08	-0.200
12.55	186.01	-0.200
12.56	185.95	-0.200
12.57	185.88	-0.200
12.57	185.82	-0.200
12.58	185.75	-0.200
12.58	185.68	-0.200
12.59	185.62	-0.200
12.60	185.55	-0.200
12.60	185.48	-0.200
12.61	185.42	-0.200
12.62	185.35	-0.200
12.63	185.28	-0.199
12.63	185.22	-0.199
12.64	185.15	-0.199
12.65	185.08	-0.199
12.65	185.02	-0.199
12.66	184.95	-0.199
12.67	184.88	-0.199
12.67	184.82	-0.199
12.68	184.75	-0.199
12.68	184.68	-0.199
12.69	184.62	-0.199
12.70	184.55	-0.199
12.70	184.48	-0.199
12.71	184.42	-0.199
12.72	184.35	-0.199
12.73	184.28	-0.198
12.73	184.22	-0.198
12.74	184.15	-0.198
12.75	184.08	-0.198
12.75	184.02	-0.198
12.76	183.95	-0.198
12.77	183.88	-0.198
12.77	183.82	-0.198
12.78	183.75	-0.198
12.78	183.68	-0.198
12.79	183.62	-0.198
12.80	183.55	-0.198
12.80	183.48	-0.198
12.81	183.42	-0.198
12.82	183.35	-0.198
12.83	183.29	-0.198
12.83	183.22	-0.198
12.84	183.15	-0.198
12.85	183.09	-0.198
12.85	183.02	-0.198
12.86	182.95	-0.198
12.87	182.89	-0.197
12.87	182.82	-0.197
12.88	182.75	-0.197
12.88	182.69	-0.197
12.89	182.62	-0.197
12.90	182.55	-0.197
12.90	182.49	-0.197
12.91	182.42	-0.197
12.92	182.35	-0.197
12.93	182.29	-0.197
12.93	182.22	-0.197
12.94	182.15	-0.197
12.95	182.09	-0.197
12.95	182.02	-0.197
12.96	181.96	-0.196
12.97	181.89	-0.196
12.97	181.82	-0.196
12.98	181.76	-0.196
12.98	181.69	-0.196
12.99	181.62	-0.196
13.00	181.56	-0.196
13.00	181.49	-0.196
13.01	181.42	-0.196
13.02	181.36	-0.196
13.03	181.29	-0.196
13.03	181.22	-0.196
13.04	181.16	-0.196
13.05	181.09	-0.195
13.05	181.02	-0.195
13.06	180.96	-0.195
13.07	180.89	-0.195
13.07	180.82	-0.195
13.08	180.76	-0.195
13.08	180.69	-0.195
13.09	180.62	-0.195
13.10	180.56	-0.195
13.10	180.49	-0.195
13.11	180.42	-0.195
13.12	180.36	-0.195
[...]
25.28	131.53	-0.002
25.29	131.60	-0.002
25.30	131.67	-0.002
25.31	131.73	-0.002
25.31	131.80	-0.002
25.32	131.87	-0.002
25.33	131.93	-0.002
25.33	132.00	-0.002
25.34	132.07	-0.002
25.34	132.13	-0.002
25.35	132.20	-0.002
25.36	132.27	-0.002
25.37	132.33	-0.002
25.37	132.40	-0.002
25.38	132.47	-0.002
25.38	132.53	-0.002
25.39	132.60	-0.002
25.40	132.67	-0.003
25.41	132.73	-0.003
25.41	132.80	-0.003
25.42	132.87	-0.003
25.43	132.93	-0.003
25.43	133.00	-0.003
25.44	133.07	-0.003
25.44	133.13	-0.003
25.45	133.20	-0.003
25.46	133.27	-0.003
25.47	133.33	-0.003
25.47	133.40	-0.003
25.48	133.47	-0.003
25.48	133.53	-0.003
25.49	133.60	-0.003
25.50	133.67	-0.003
25.51	133.73	-0.003
25.51	133.80	-0.003
25.52	133.87	-0.003
25.53	133.93	-0.003
25.53	134.00	-0.003
25.54	134.07	-0.003
25.54	134.14	-0.003
25.55	134.20	-0.003
25.56	134.27	-0.003
25.57	134.33	-0.003
25.57	134.40	-0.003
25.58	134.47	-0.003
25.58	134.54	-0.003
25.59	134.60	-0.003
25.60	134.67	-0.004
25.61	134.74	-0.004
25.61	134.80	-0.004
25.62	134.87	-0.004
25.63	134.94	-0.004
25.63	135.00	-0.004
25.64	135.07	-0.004
25.64	135.14	-0.004
25.65	135.20	-0.004
25.66	135.27	-0.004
25.67	135.34	-0.004
25.67	135.40	-0.004
25.68	135.47	-0.004
25.68	135.54	-0.004
25.69	135.60	-0.004
25.70	135.67	-0.004
25.71	135.74	-0.004
25.71	135.80	-0.004
25.72	135.87	-0.004
25.73	135.94	-0.004
25.73	136.00	-0.004
25.74	136.07	-0.004
25.74	136.14	-0.004
25.75	136.20	-0.004
25.76	136.27	-0.004
25.77	136.34	-0.004
25.77	136.40	-0.004
25.78	136.47	-0.004
25.78	136.54	-0.004
25.79	136.60	-0.004
25.80	136.67	-0.004
25.81	136.74	-0.004
25.81	136.80	-0.004
25.82	136.87	-0.004
25.83	136.94	-0.005
25.83	137.00	-0.005
25.84	137.07	-0.005
25.84	137.14	-0.005
25.85	137.20	-0.005
25.86	137.27	-0.005
25.87	137.34	-0.005
25.87	137.40	-0.005
25.88	137.47	-0.005
25.88	137.54	-0.005
25.89	137.60	-0.005
25.90	137.67	-0.005
25.91	137.74	-0.005
25.91	137.80	-0.005
25.92	137.87	-0.005
25.93	137.94	-0.005
25.93	138.00	-0.005
25.94	138.07	-0.005
25.94	138.14	-0.005
25.95	138.20	-0.005
25.96	138.27	-0.005
25.97	138.34	-0.005
25.97	138.40	-0.005
25.98	138.47	-0.005
25.98	138.54	-0.005
25.99	138.61	-0.005
26.00	138.67	-0.005
26.01	138.74	-0.005
26.01	138.81	-0.005
26.02	138.87	-0.005
26.03	138.94	-0.005
26.03	139.01	-0.005
26.04	139.07	-0.005
26.04	139.14	-0.005
26.05	139.21	-0.005
26.06	139.27	-0.005
26.07	139.34	-0.005
26.07	139.41	-0.005
26.08	139.47	-0.005
26.08	139.54	-0.005
26.09	139.61	-0.005
26.10	139.67	-0.005
26.11	139.74	-0.006
26.11	139.80	-0.006
26.12	139.87	-0.006
26.13	139.94	-0.006
26.13	140.00	-0.006
26.14	140.07	-0.005
26.14	140.14	-0.005
26.15	140.20	-0.006
26.16	140.27	-0.006
26.17	140.34	-0.006
26.17	140.40	-0.006
26.18	140.47	-0.006
26.18	140.54	-0.006
26.19	140.60	-0.006
26.20	140.67	-0.006
26.21	140.74	-0.006
26.21	140.80	-0.006
26.22	140.87	-0.006
26.23	140.94	-0.006
26.23	141.01	-0.006
26.24	141.07	-0.006
26.24	141.14	-0.006
26.25	141.21	-0.006
26.26	141.27	-0.006
26.27	141.34	-0.006
26.27	141.41	-0.006
26.28	141.47	-0.006
26.28	141.54	-0.006
26.29	141.61	-0.006
26.30	141.67	-0.006
26.31	141.74	-0.006
26.31	141.81	-0.006
26.32	141.87	-0.006
26.33	141.94	-0.006
26.33	142.01	-0.006
26.34	142.07	-0.006
26.34	142.14	-0.006
26.35	142.21	-0.006
26.36	142.27	-0.006
26.37	142.34	-0.006
26.37	142.41	-0.006
26.38	142.47	-0.006
26.38	142.54	-0.006
26.39	142.61	-0.006
26.40	142.67	-0.006
26.41	142.74	-0.006
26.41	142.81	-0.006
26.42	142.87	-0.006
26.43	142.94	-0.006
26.43	143.01	-0.006
26.44	143.07	-0.006
26.44	143.14	-0.006
26.45	143.21	-0.006
26.46	143.27	-0.006
26.47	143.34	-0.006
26.47	143.41	-0.006
26.48	143.47	-0.006
26.48	143.54	-0.006
26.49	143.61	-0.006
26.50	143.67	-0.006
26.51	143.74	-0.007
26.51	143.81	-0.007
26.52	143.87	-0.007
26.53	143.94	-0.007
26.53	144.01	-0.007
26.54	144.07	-0.007
26.54	144.14	-0.007
26.55	144.21	-0.007
26.56	144.27	-0.007
26.57	144.34	-0.007
26.57	144.41	-0.007
26.58	144.47	-0.007
26.58	144.54	-0.007
26.59	144.61	-0.007
26.60	144.67	-0.007
26.61	144.74	-0.007
26.61	144.81	-0.007
26.62	144.87	-0.007
26.63	144.94	-0.007
26.63	145.01	-0.007
26.64	145.07	-0.007
26.64	145.14	-0.007
26.65	145.21	-0.007
26.66	145.27	-0.007
26.67	145.34	-0.007
26.67	145.41	-0.007
26.68	145.47	-0.007
26.68	145.54	-0.007
26.69	145.61	-0.007
26.70	145.67	-0.007
26.71	145.74	-0.007
26.71	145.81	-0.007
26.72	145.87	-0.007
26.73	145.94	-0.007
26.73	146.01	-0.007
26.74	146.07	-0.008
26.74	146.14	-0.008
26.75	146.21	-0.007
26.76	146.27	-0.007
26.77	146.34	-0.007
26.77	146.41	-0.007
26.78	146.47	-0.007
26.78	146.54	-0.008
26.79	146.61	-0.008
26.80	146.67	-0.008
26.81	146.74	-0.008
26.81	146.81	-0.008
26.82	146.87	-0.008
26.83	146.94	-0.008
26.83	147.01	-0.008
26.84	147.07	-0.008
26.84	147.14	-0.008
26.85	147.21	-0.008
26.86	147.27	-0.008
26.87	147.34	-0.008
26.87	147.41	-0.008
26.88	147.47	-0.008
26.88	147.54	-0.008
26.89	147.61	-0.008
26.90	147.67	-0.008
26.91	147.74	-0.008
26.91	147.81	-0.008
26.92	147.87	-0.008
26.93	147.94	-0.008
26.93	148.01	-0.008
26.94	148.07	-0.008
26.94	148.14	-0.008
26.95	148.21	-0.008
26.96	148.27	-0.008
26.97	148.34	-0.008
26.97	148.41	-0.008
26.98	148.48	-0.008
26.98	148.54	-0.008
26.99	148.61	-0.008
27.00	148.67	-0.008
27.01	148.74	-0.008
27.01	148.81	-0.008
27.02	148.87	-0.008
27.03	148.94	-0.008
27.03	149.01	-0.008
27.04	149.08	-0.008
27.04	149.14	-0.008
27.05	149.21	-0.008
27.06	149.28	-0.008
27.07	149.34	-0.008
27.07	149.41	-0.008
27.08	149.48	-0.008
27.08	149.54	-0.008
27.09	149.61	-0.008
27.10	149.68	-0.008
27.11	149.74	-0.008
27.11	149.81	-0.008
27.12	149.88	-0.008
27.13	149.94	-0.008
27.13	150.01	-0.009
27.14	150.08	-0.009
27.14	150.14	-0.008
27.15	150.21	-0.009
27.16	150.28	-0.009
27.17	150.34	-0.009
27.17	150.41	-0.009
27.18	150.48	-0.009
27.18	150.54	-0.009
27.19	150.61	-0.009
27.20	150.68	-0.009
27.21	150.74	-0.009
27.21	150.81	-0.009
27.22	150.88	-0.009
27.23	150.94	-0.009
27.23	151.01	-0.009
27.24	151.08	-0.009
27.24	151.14	-0.009
27.25	151.21	-0.009
27.26	151.28	-0.009
27.27	151.34	-0.009
27.27	151.41	-0.009
27.28	151.48	-0.009
27.28	151.54	-0.009
27.29	151.61	-0.009
27.30	151.68	-0.009
27.31	151.74	-0.009
27.31	151.81	-0.009
27.32	151.88	-0.009
27.33	151.94	-0.009
27.33	152.01	-0.009
27.34	152.08	-0.009
27.34	152.14	-0.009
27.35	152.21	-0.009
27.36	152.28	-0.009
27.37	152.34	-0.009
27.37	152.41	-0.009
27.38	152.48	-0.009
27.38	152.54	-0.009
27.39	152.61	-0.009
27.40	152.68	-0.009
27.41	152.74	-0.009
27.41	152.81	-0.009
27.42	152.88	-0.009
27.43	152.94	-0.009
27.43	153.01	-0.010
27.44	153.08	-0.010
27.44	153.14	-0.010
27.45	153.21	-0.010
27.46	153.28	-0.010
27.47	153.34	-0.010
27.47	153.41	-0.010
27.48	153.48	-0.010
27.48	153.54	-0.010
27.49	153.61	-0.010
27.50	153.68	-0.010
27.51	153.74	-0.010
27.51	153.81	-0.010
27.52	153.88	-0.010
27.53	153.94	-0.010
27.53	154.01	-0.010
27.54	154.08	-0.010
27.54	154.15	-0.010
27.55	154.21	-0.010
27.56	154.28	-0.010
27.57	154.34	-0.010
27.57	154.41	-0.010
27.58	154.48	-0.010
27.58	154.55	-0.010
27.59	154.61	-0.010
27.60	154.68	-0.010
27.61	154.74	-0.010
27.61	154.81	-0.010
27.62	154.88	-0.010
27.63	154.95	-0.010
27.63	155.01	-0.010
27.64	155.08	-0.010
27.64	155.15	-0.010
27.65	155.21	-0.010
27.66	155.28	-0.010
27.67	155.34	-0.010
27.67	155.41	-0.010
27.68	155.48	-0.010
27.68	155.54	-0.010
27.69	155.61	-0.010
27.70	155.68	-0.010
27.71	155.74	-0.010
27.71	155.81	-0.010
27.72	155.88	-0.010
27.73	155.94	-0.010
27.73	156.01	-0.010
27.74	156.08	-0.010
27.74	156.14	-0.010
27.75	156.21	-0.010
27.76	156.28	-0.010
27.77	156.34	-0.010
27.77	156.41	-0.010
27.78	156.48	-0.010
27.78	156.54	-0.010
27.79	156.61	-0.010
27.80	156.68	-0.008
27.81	156.75	0.010
27.81	156.81	0.087
27.82	156.88	0.238
27.83	156.94	0.460
27.83	156.99	0.712
27.84	157.05	0.964
27.84	157.10	1.204
27.85	157.15	1.433
27.86	157.20	1.651
27.87	157.25	1.860
27.87	157.29	2.057
27.88	157.34	2.237
27.88	157.38	2.390
27.89	157.43	2.497
27.90	157.48	2.566
27.91	157.53	2.627
27.91	157.58	2.698
27.92	157.63	2.768
27.93	157.68	2.832
27.93	157.73	2.881
27.94	157.79	2.911
27.94	157.84	2.938
27.95	157.90	2.964
27.96	157.96	2.971
27.97	158.02	2.950
27.97	158.08	2.876
27.98	158.14	2.623
27.98	158.21	2.008
27.99	158.30	1.357
28.00	158.38	1.038
28.01	158.47	0.878
28.01	158.56	0.775
28.02	158.64	0.690
28.03	158.73	0.624
28.03	158.81	0.574
28.04	158.89	0.526
28.04	158.98	0.484
28.05	159.06	0.445
28.06	159.14	0.409
28.07	159.21	0.375
28.07	159.29	0.345
28.08	159.37	0.320
28.08	159.44	0.297
28.09	159.52	0.270
28.10	159.59	0.250
28.11	159.66	0.227
28.11	159.74	0.206
28.12	159.81	0.192
28.13	159.88	0.176
28.13	159.95	0.163
28.14	160.03	0.148
28.14	160.10	0.135
28.15	160.17	0.124
28.16	160.24	0.115
28.17	160.31	0.105
28.17	160.38	0.097
28.18	160.45	0.090
28.18	160.52	0.080
28.19	160.58	0.073
28.20	160.65	0.067
28.21	160.72	0.060
28.21	160.79	0.054
28.22	160.86	0.050
28.23	160.93	0.045
28.23	161.00	0.039
28.24	161.06	0.035
28.24	161.13	0.034
28.25	161.20	0.031
28.26	161.27	0.025
28.27	161.34	0.023
28.27	161.40	0.021
28.28	161.47	0.015
28.28	161.54	0.013
28.29	161.61	0.014
28.30	161.67	0.011
28.31	161.74	0.007
28.31	161.81	0.007
28.32	161.88	0.007
28.33	161.94	0.007
28.33	162.01	0.006
28.34	162.08	0.005
28.34	162.14	0.004
28.35	162.21	0.003
28.36	162.28	0.002
28.37	162.34	0.002
28.37	162.41	0.001
28.38	162.48	0.001
28.38	162.55	0.000
28.39	162.61	0.000
28.40	162.68	0.000
28.41	162.75	-0.001
28.41	162.81	-0.001
28.42	162.88	-0.001
28.43	162.95	-0.001
28.43	163.01	-0.002
28.44	163.08	-0.002
28.44	163.15	-0.002
28.45	163.21	-0.002
28.46	163.28	-0.003
28.47	163.35	-0.003
28.47	163.41	-0.003
28.48	163.48	-0.004
28.48	163.55	-0.004
28.49	163.61	-0.004
28.50	163.68	-0.005
28.51	163.75	-0.005
28.51	163.82	-0.005
28.52	163.88	-0.005
28.53	163.95	-0.005
28.53	164.01	-0.005
28.54	164.08	-0.006
28.54	164.15	-0.006
28.55	164.21	-0.006
28.56	164.28	-0.006
28.57	164.35	-0.007
28.57	164.41	-0.007
28.58	164.48	-0.007
28.58	164.55	-0.007
28.59	164.61	-0.007
28.60	164.68	-0.008
28.61	164.75	-0.008
28.61	164.82	-0.008
28.62	164.88	-0.008
28.63	164.95	-0.008
28.63	165.02	-0.008
28.64	165.08	-0.008
28.64	165.15	-0.009
28.65	165.22	-0.009
28.66	165.28	-0.009
28.67	165.35	-0.009
28.67	165.42	-0.009
28.68	165.48	-0.009
28.68	165.55	-0.009
28.69	165.62	-0.009
28.70	165.68	-0.009
28.71	165.75	-0.009
28.71	165.82	-0.010
28.72	165.88	-0.010
28.73	165.95	-0.010
28.73	166.01	-0.010
28.74	166.08	-0.010
28.74	166.15	-0.010
28.75	166.22	-0.010
28.76	166.28	-0.011
28.77	166.35	-0.011
28.77	166.42	-0.011
28.78	166.48	-0.011
28.78	166.55	-0.011
28.79	166.62	-0.011
28.80	166.68	-0.011
28.81	166.75	-0.011
28.81	166.82	-0.011
28.82	166.88	-0.012
28.83	166.95	-0.012
28.83	167.02	-0.012
28.84	167.08	-0.012
28.84	167.15	-0.012
28.85	167.22	-0.012
28.86	167.28	-0.012
28.87	167.35	-0.012
28.87	167.42	-0.012
28.88	167.48	-0.012
28.88	167.55	-0.012
28.89	167.62	-0.012
28.90	167.68	-0.013
28.91	167.75	-0.013
28.91	167.82	-0.013
28.92	167.89	-0.013
28.93	167.95	-0.013
28.93	168.02	-0.013
28.94	168.08	-0.013
28.94	168.15	-0.013
28.95	168.22	-0.013
28.96	168.29	-0.013
28.97	168.35	-0.013
28.97	168.42	-0.013
28.98	168.48	-0.013
28.98	168.55	-0.013
28.99	168.62	-0.013
29.00	168.68	-0.013
29.01	168.75	-0.013
29.01	168.82	-0.013
29.02	168.88	-0.013
29.03	168.95	-0.013
29.03	169.02	-0.013
29.04	169.08	-0.014
29.04	169.15	-0.014
29.05	169.22	-0.014
29.06	169.28	-0.014
29.07	169.35	-0.014
29.07	169.42	-0.014
29.08	169.48	-0.014
29.08	169.55	-0.014
29.09	169.62	-0.014
29.10	169.68	-0.014
29.11	169.75	-0.014
29.11	169.82	-0.014
29.12	169.88	-0.014
29.13	169.95	-0.014
29.13	170.02	-0.014
29.14	170.08	-0.014
29.14	170.15	-0.014
29.15	170.22	-0.014
29.16	170.28	-0.015
29.17	170.35	-0.015
29.17	170.42	-0.015
29.18	170.48	-0.015
29.18	170.55	-0.015
29.19	170.62	-0.015
29.20	170.68	-0.015
29.21	170.75	-0.015
29.21	170.82	-0.015
29.22	170.89	-0.015
29.23	170.95	-0.015
29.23	171.02	-0.015
29.24	171.09	-0.015
29.24	171.15	-0.015
29.25	171.22	-0.015
29.26	171.28	-0.015
29.27	171.35	-0.015
29.27	171.42	-0.015
29.28	171.49	-0.015
29.28	171.55	-0.015
29.29	171.62	-0.015
29.30	171.69	-0.015
29.31	171.75	-0.015
29.31	171.82	-0.015
29.32	171.89	-0.015
29.33	171.95	-0.015
29.33	172.02	-0.015
29.34	172.09	-0.015
29.34	172.15	-0.015
29.35	172.22	-0.015
29.36	172.29	-0.015
29.37	172.35	-0.015
29.37	172.42	-0.015
29.38	172.49	-0.015
29.38	172.55	-0.015
29.39	172.62	-0.015
29.40	172.69	-0.015
29.41	172.75	-0.015
29.41	172.82	-0.015
29.42	172.89	-0.015
29.43	172.95	-0.015
29.43	173.02	-0.015
29.44	173.09	-0.015
29.44	173.15	-0.015
29.45	173.22	-0.015
29.46	173.29	-0.015
29.47	173.35	-0.015
29.47	173.42	-0.015
29.48	173.48	-0.015
29.48	173.55	-0.015
29.49	173.62	-0.015
29.50	173.69	-0.016
29.51	173.75	-0.016
29.51	173.82	-0.016
29.52	173.89	-0.016
29.53	173.95	-0.016
29.53	174.02	-0.016
29.54	174.09	-0.016
29.54	174.15	-0.016
29.55	174.22	-0.016
29.56	174.29	-0.016
29.57	174.35	-0.016
29.57	174.42	-0.016
29.58	174.49	-0.016
29.58	174.55	-0.016
29.59	174.62	-0.016
29.60	174.69	-0.016
29.61	174.75	-0.016
29.61	174.82	-0.016
29.62	174.89	-0.016
29.63	174.95	-0.016
29.63	175.02	-0.016
29.64	175.09	-0.016
29.64	175.15	-0.016
29.65	175.22	-0.016
29.66	175.29	-0.016
29.67	175.35	-0.016
29.67	175.42	-0.016
29.68	175.49	-0.016
29.68	175.55	-0.016
29.69	175.62	-0.016
29.70	175.69	-0.016
29.71	175.75	-0.016
29.71	175.82	-0.016
29.72	175.89	-0.016
29.73	175.95	-0.016
29.73	176.02	-0.016
29.74	176.09	-0.016
29.74	176.15	-0.016
29.75	176.22	-0.016
29.76	176.29	-0.016
29.77	176.35	-0.016
29.77	176.42	-0.016
29.78	176.49	-0.016
29.78	176.55	-0.017
29.79	176.62	-0.017
29.80	176.69	-0.017
29.81	176.75	-0.017
29.81	176.82	-0.017
29.82	176.89	-0.017
29.83	176.95	-0.017
29.83	177.02	-0.017
29.84	177.09	-0.017
29.84	177.15	-0.017
29.85	177.22	-0.017
29.86	177.29	-0.017
29.87	177.35	-0.017
29.87	177.42	-0.017
29.88	177.49	-0.017
29.88	177.55	-0.017
29.89	177.62	-0.017
29.90	177.69	-0.017
29.91	177.75	-0.017
29.91	177.82	-0.017
29.92	177.89	-0.017
29.93	177.95	-0.017
29.93	178.02	-0.017
29.94	178.09	-0.017
29.94	178.15	-0.017
29.95	178.22	-0.017
29.96	178.29	-0.017
29.97	178.35	-0.017
29.97	178.42	-0.017
29.98	178.49	-0.017
29.98	178.55	-0.017
29.99	178.62	-0.017
30.00	178.69	-0.017
30.01	178.76	-0.017
30.01	178.82	-0.017
30.02	178.89	-0.017
30.03	178.96	-0.017
30.03	179.02	-0.017
30.04	179.09	-0.017
30.04	179.16	-0.017
30.05	179.22	-0.017
30.06	179.29	-0.017
30.07	179.36	-0.017
30.07	179.42	-0.017
30.08	179.49	-0.017
30.08	179.56	-0.017
30.09	179.62	-0.017
30.10	179.69	-0.017
30.11	179.76	-0.017
30.11	179.82	-0.017
30.12	179.89	-0.017
30.13	179.96	-0.017
30.13	180.02	-0.017
30.14	180.09	-0.018
30.14	180.16	-0.018
30.15	180.22	-0.017
30.16	180.29	-0.018
30.17	180.35	-0.018
30.17	180.42	-0.018
30.18	180.49	-0.018
30.18	180.56	-0.018
30.19	180.62	-0.018
30.20	180.69	-0.018
30.21	180.75	-0.018
30.21	180.82	-0.018
30.22	180.89	-0.018
30.23	180.96	-0.018
30.23	181.02	-0.018
30.24	181.09	-0.018
30.24	181.16	-0.018
30.25	181.22	-0.018
30.26	181.29	-0.018
30.27	181.36	-0.018
30.27	181.42	-0.018
30.28	181.49	-0.018
30.28	181.56	-0.018
30.29	181.62	-0.018
30.30	181.69	-0.018
30.31	181.76	-0.018
30.31	181.82	-0.018
30.32	181.89	-0.018
30.33	181.96	-0.018
30.33	182.02	-0.018
30.34	182.09	-0.018
30.34	182.16	-0.018
30.35	182.22	-0.018
30.36	182.29	-0.018
30.37	182.36	-0.018
30.37	182.42	-0.018
30.38	182.49	-0.018
30.38	182.56	-0.018
30.39	182.62	-0.018
30.40	182.69	-0.018
30.41	182.76	-0.018
30.41	182.82	-0.018
30.42	182.89	-0.018
30.43	182.96	-0.018
30.43	183.02	-0.018
30.44	183.09	-0.018
30.44	183.16	-0.018
30.45	183.22	-0.018
30.46	183.29	-0.018
30.47	183.36	-0.019
30.47	183.42	-0.019
30.48	183.49	-0.019
30.48	183.56	-0.018
30.49	183.62	-0.018
30.50	183.69	-0.018
30.51	183.76	-0.018
30.51	183.82	-0.018
30.52	183.89	-0.018
30.53	183.96	-0.018
30.53	184.02	-0.018
30.54	184.09	-0.018
30.54	184.16	-0.018
30.55	184.22	-0.018
30.56	184.29	-0.019
30.57	184.36	-0.019
30.57	184.42	-0.019
30.58	184.49	-0.019
30.58	184.56	-0.019
30.59	184.62	-0.019
30.60	184.69	-0.019
30.61	184.76	-0.019
30.61	184.82	-0.019
30.62	184.89	-0.019
30.63	184.96	-0.019
30.63	185.02	-0.019
30.64	185.09	-0.019
30.64	185.16	-0.019
30.65	185.22	-0.019
30.66	185.29	-0.019
30.67	185.36	-0.019
30.67	185.42	-0.019
30.68	185.49	-0.019
30.68	185.56	-0.019
30.69	185.62	-0.019
30.70	185.69	-0.019
30.71	185.76	-0.019
30.71	185.83	-0.019
30.72	185.89	-0.019
30.73	185.96	-0.019
30.73	186.02	-0.019
30.74	186.09	-0.019
30.74	186.16	-0.019
30.75	186.22	-0.019
30.76	186.29	-0.019
30.77	186.36	-0.019
30.77	186.42	-0.019
30.78	186.49	-0.019
30.78	186.56	-0.019
30.79	186.62	-0.019
30.80	186.69	-0.019
30.81	186.76	-0.019
30.81	186.83	-0.019
30.82	186.89	-0.019
30.83	186.96	-0.019
30.83	187.02	-0.019
30.84	187.09	-0.019
30.84	187.16	-0.019
30.85	187.22	-0.019
30.86	187.29	-0.019
30.87	187.36	-0.020
30.87	187.42	-0.020
30.88	187.49	-0.020
30.88	187.56	-0.020
30.89	187.62	-0.020
30.90	187.69	-0.020
30.91	187.76	-0.020
30.91	187.82	-0.020
30.92	187.89	-0.020
30.93	187.96	-0.020
30.93	188.02	-0.020
30.94	188.09	-0.020
30.94	188.16	-0.020
30.95	188.22	-0.020
30.96	188.29	-0.020
30.97	188.36	-0.020
30.97	188.42	-0.020
30.98	188.49	-0.020
30.98	188.56	-0.020
30.99	188.62	-0.020
31.00	188.69	-0.020
31.01	188.76	-0.020
31.01	188.82	-0.020
31.02	188.89	-0.020
31.03	188.96	-0.020
31.03	189.03	-0.020
31.04	189.09	-0.020
31.04	189.16	-0.020
31.05	189.22	-0.020
31.06	189.29	-0.020
31.07	189.36	-0.020
31.07	189.42	-0.020
31.08	189.49	-0.020
31.08	189.56	-0.020
31.09	189.63	-0.020
31.10	189.69	-0.020
31.11	189.76	-0.020
31.11	189.83	-0.020
31.12	189.89	-0.020
31.13	189.96	-0.020
31.13	190.02	-0.020
31.14	190.09	-0.020
31.14	190.16	-0.020
31.15	190.23	-0.020
31.16	190.29	-0.020
31.17	190.36	-0.020
31.17	190.43	-0.020
31.18	190.49	-0.020
31.18	190.56	-0.020
31.19	190.63	-0.020
31.20	190.69	-0.020
31.21	190.76	-0.020
31.21	190.83	-0.021
31.22	190.89	-0.021
31.23	190.96	-0.021
31.23	191.03	-0.021
31.24	191.09	-0.021
31.24	191.16	-0.021
31.25	191.23	-0.021
31.26	191.29	-0.021
31.27	191.36	-0.021
31.27	191.43	-0.021
31.28	191.49	-0.021
31.28	191.56	-0.021
31.29	191.63	-0.021
31.30	191.69	-0.021
31.31	191.76	-0.021
31.31	191.83	-0.021
31.32	191.89	-0.021
31.33	191.96	-0.021
31.33	192.03	-0.021
31.34	192.09	-0.021
31.34	192.16	-0.021
31.35	192.23	-0.021
31.36	192.29	-0.021
31.37	192.36	-0.021
31.37	192.43	-0.021
31.38	192.49	-0.021
31.38	192.56	-0.021
31.39	192.63	-0.021
31.40	192.69	-0.021
31.41	192.76	-0.021
31.41	192.83	-0.021
31.42	192.89	-0.021
31.43	192.96	-0.021
31.43	193.03	-0.021
31.44	193.09	-0.021
31.44	193.16	-0.021
31.45	193.23	-0.021
31.46	193.29	-0.021
31.47	193.36	-0.021
31.47	193.43	-0.021
31.48	193.49	-0.021
31.48	193.56	-0.021
31.49	193.63	-0.021
31.50	193.69	-0.021
31.51	193.76	-0.021
31.51	193.83	-0.021
31.52	193.89	-0.021
31.53	193.96	-0.021
31.53	194.03	-0.021
31.54	194.09	-0.021
31.54	194.16	-0.021
31.55	194.23	-0.021
31.56	194.29	-0.021
31.57	194.36	-0.021
31.57	194.43	-0.021
31.58	194.49	-0.022
31.58	194.56	-0.022
31.59	194.63	-0.022
31.60	194.69	-0.022
31.61	194.76	-0.022
31.61	194.83	-0.022
31.62	194.89	-0.022
31.63	194.96	-0.022
31.63	195.03	-0.022
31.64	195.09	-0.022
31.64	195.16	-0.022
31.65	195.23	-0.022
31.66	195.29	-0.022
31.67	195.36	-0.022
31.67	195.43	-0.022
31.68	195.49	-0.022
31.68	195.56	-0.022
31.69	195.63	-0.022
31.70	195.69	-0.022
31.71	195.76	-0.022
31.71	195.83	-0.022
31.72	195.89	-0.022
31.73	195.96	-0.022
31.73	196.03	-0.022
31.74	196.09	-0.022
31.74	196.16	-0.022
31.75	196.23	-0.022
31.76	196.29	-0.022
31.77	196.36	-0.022
31.77	196.43	-0.022
31.78	196.49	-0.022
31.78	196.56	-0.022
31.79	196.63	-0.022
31.80	196.69	-0.022
31.81	196.76	-0.022
31.81	196.83	-0.022
31.82	196.89	-0.022
31.83	196.96	-0.022
31.83	197.03	-0.022
31.84	197.09	-0.022
31.84	197.16	-0.022
31.85	197.23	-0.022
31.86	197.29	-0.022
31.87	197.36	-0.022
31.87	197.43	-0.022
31.88	197.49	-0.022
31.88	197.56	-0.022
31.89	197.63	-0.022
31.90	197.69	-0.022
31.91	197.76	-0.022
31.91	197.83	-0.022
31.92	197.89	-0.022
31.93	197.96	-0.022
31.93	198.03	-0.023
31.94	198.09	-0.022
31.94	198.16
31.95	198.23
31.96	198.30
31.97	198.36
31.97	198.43
31.98	198.49
31.98	198.56
31.99
32.00