File: Data/2024_09_19_Indium_CHM343_DSC.txt
Filename	2024_09_19_Indium_CHM343_DSC
Instrument name	DSC2A-00468 (192.168.1.100)
Operator	CHM343
rundate	9/19/2024
Sample name	2024_09_19_Indium_CHM343_DSC
proceduresegments	Equilibrate 30.00 °C; Ramp 10.00 °C/min to 220.00 °C; Isothermal 1.0 min; Ramp 10.00 °C/min to 30.00 °C
[File Parameters]
Run date	9/19/2024 8:03:20 PM
Trios version	5.1.1.46572
Original File Name
Current File Name	C:\ProgramData\TA Instruments\TRIOS\Data\2024_09_19_Indium_CHM343_DSC.tri
[Procedure]
Procedure Name	CHM343_Fall2024_Indium
Sample Name	2024_09_19_Indium_CHM343_DSC
Sample Mass	2.26 mg
Reference Sample Mass	0 mg
Pan Mass	54.24 mg
Pan Number	25
Reference Pan Mass	54 mg
Reference Pan Number	19
Pan Type	Aluminum
Comments	Indium - Al Hermetic Sealed Pan, with ref Al pan.  ASU Online CHM343, Remote DSC experimental lab. Fall 2024.  Group Zoom Data Collection, Sept 19, 2024 from 5-7 pm.  TA Instruments DSC2500.
Project Name	Lab 4 - Fall 2024
Operator	CHM343
Test	Custom
Unload Max Temperature	30
Unload Min Temperature	30
Load Max Temperature	30
Load Min Temperature	30
Stop on Gas Flow Error	Yes
[Signal List]
Signal #1	Time (min)
Signal #2	Temperature (°C)
Signal #3	Heat Flow (mW)
Signal #4	Delta T (µV)
Signal #5	Delta Tzero (µV)
Signal #6	Tzero Temperature (°C)
Signal #7	Cell Purge (mL/min)
Signal #8	Heater Temp (°C)
Signal #9	Power Delivered (W)
Signal #10	Reference Junction Temperature (°C)
Signal #11	Flange Temperature (°C)
Signal #12	Heat Flow Phase (rad)
Signal #13	Total Heat Capacity (J/°C)
Signal #14	Heat Capacity (J/°C)
[Configuration]
Company Name	ASU
Instrument Name	DSC2A-00468
Instrument Type	DSC2500
Serial Number	DSC2A-00468
IP	192.168.1.100
Location of Instrument	MRRC
DisplayType	Unknown
Sample Interval 	0.1 s/pt
Selected Heat Flow	T4P
Exotherm Direction	Down
Cell Serial	DRC2-00792
Lid Type	Standard
Cooler	RCS 90
Leave Cooler on at End of Sequence	On
Gas 2	Nitrogen
Gas Selected	Channel 1
Flow Rate	50 mL/min
Secondary Purge	On
Licensed Heat Flow	Heat Flow T4P
Modulation Licensed	Yes
[Versions]
Common IDD Version	1
Cortex Version	VER 2.10.2.31
Driver	5.0.0.6
GDM Version	1.0.3.3
TouchscreenVersion	1.0.0.16145
FEP Version	1.2.1.21
FEP Bootloader	2.0.0.5
AutoSampler Version	2.1.1.26
Auto Sampler Bootloader	2.0.0.5
FCM Version	1.1.0.3
FCM Bootloader	2.0.0.5
[Experiment Logs]
Experiment Log Entry # 1	Equilibrate Segment 30 (C) Started
Experiment Log Entry # 3	Air Cool is off.
Experiment Log Entry # 5	Ramp Segment 10 C/min to 220 Started
Experiment Log Entry # 7	Isothermal Segment 1 min started
Experiment Log Entry # 9	Ramp Segment 10 C/min to 30 Started
[Method Log]
Method Log Entry # 1	Equilibrate 30 °C
Method Log Entry # 2	(Ramp 25434) Ramp 10 °C/minute to 220 °C
Method Log Entry # 3	Isothermal 1 minutes
Method Log Entry # 4	(Ramp 25436) Ramp 10 °C/minute to 30 °C
Cell Serial	DRC2-00792
[T1 Calibration]
Slope	-0.008529666
Offset	9.636258
Initial Temperature	98.23
GUID	f8bfdadc-4977-4fdf-ba6d-0ba9134940c3
[TZero Calibration]
Date Applied	11/29/2022 4:06:13 PM
Description	From -89.059 °C to 396.009 °C at 20.000°C/min
Gas Type	Nitrogen
Pan Type	None
Source Files 1	C:\Users\yargerlab\Desktop\DSC Data\General\TZero_calibration_11_29_22_2nd(2).tri
Source Files 2	C:\Users\yargerlab\Desktop\DSC Data\General\TZero_calibration_11_29_22_2nd(3).tri
Delta T Offset	13.05235
Delta T Slope	-0.007271007
Delta T0 Offset	-13.69128
Delta T0 Slope	0.06063341
[Temperature Calibration]
Date Applied	11/29/2022 7:12:28 PM
Description	From 106.590 °C to 186.590 °C at 10.000°C/min
Gas Type	Nitrogen
Pan Type	Tzero Aluminum Hermetic
Source Files 1	C:\Users\yargerlab\Desktop\DSC Data\General\Indium(6).tri
Measured 1	157.391
Known 1	156.598
[Cell Constant Calibration]
Date Applied	11/29/2022 7:12:29 PM
Description	From 106.590 °C to 186.590 °C at 10.000°C/min
Gas Type	Nitrogen
Pan Type	Tzero Aluminum Hermetic
Source Files 1	C:\Users\yargerlab\Desktop\DSC Data\General\Indium(6).tri
T4P KCell	1.006051
Onset Slope	63.26126 mW/°C
[Direct Cp Calibration]
Date Applied	11/30/2022 11:04:51 AM
Description	From -79.983 °C to 298.409 °C at 10.000°C/min
Gas Type	Nitrogen
Pan Type	Tzero Aluminum Hermetic
Source Files 1	C:\Users\yargerlab\Desktop\DSC Data\General\Sapphire_Heat_Capacity_11_30_22.tri
[Rev Cp Calibration]
Date Applied	11/30/2022 1:58:51 PM
Description	From -79.996 °C to 292.812 °C at 3.000°C/min
Gas Type	Nitrogen
Pan Type	Tzero Aluminum Hermetic
Source Files 1	C:\Users\yargerlab\Desktop\DSC Data\General\Sapphire_MDSC_Calibration_11_30_22.tri
[step]
Ramp 10.00 °C/min to 220.00 °C
Time	Temperature	Heat Flow (Normalized)
min	°C	W/g
0.00	30.04	-0.071
0.01	30.05	-0.069
0.03	30.05	-0.068
0.04	30.06	-0.067
0.05	30.07	-0.067
0.07	30.09	-0.083
0.08	30.12	-0.118
0.09	30.16	-0.152
0.11	30.21	-0.179
0.12	30.28	-0.195
0.13	30.36	-0.197
0.15	30.45	-0.186
0.16	30.54	-0.175
0.17	30.64	-0.150
0.19	30.74	-0.118
0.20	30.85	-0.090
0.21	30.96	-0.070
0.23	31.07	-0.058
0.24	31.19	-0.042
0.25	31.30	-0.032
0.27	31.42	-0.021
0.28	31.54	-0.014
0.29	31.67	-0.004
0.31	31.79	0.002
0.32	31.91	0.007
0.33	32.04	0.019
0.35	32.17	0.022
0.36	32.29	0.027
0.37	32.42	0.032
0.39	32.55	0.035
0.40	32.68	0.039
0.41	32.81	0.041
0.43	32.94	0.043
0.44	33.07	0.045
0.45	33.20	0.046
0.47	33.33	0.047
0.48	33.46	0.048
0.49	33.59	0.050
0.51	33.72	0.051
0.52	33.85	0.051
0.53	33.98	0.052
0.55	34.12	0.053
0.56	34.25	0.054
0.57	34.38	0.055
0.59	34.51	0.055
0.60	34.64	0.056
0.61	34.77	0.056
0.63	34.91	0.056
0.64	35.04	0.057
0.65	35.17	0.057
0.67	35.30	0.058
0.68	35.44	0.058
0.69	35.57	0.059
0.71	35.70	0.059
0.72	35.83	0.059
0.73	35.96	0.060
0.75	36.10	0.060
0.76	36.23	0.060
0.77	36.36	0.061
0.79	36.49	0.061
0.80	36.63	0.061
0.81	36.76	0.061
0.83	36.89	0.061
0.84	37.02	0.062
0.85	37.16	0.062
0.87	37.29	0.062
0.88	37.42	0.062
0.89	37.56	0.062
0.91	37.69	0.063
0.92	37.82	0.063
0.93	37.95	0.063
0.95	38.09	0.063
0.96	38.22	0.063
0.97	38.35	0.063
0.99	38.49	0.063
1.00	38.62	0.063
1.01	38.75	0.063
1.03	38.88	0.063
1.04	39.02	0.063
1.05	39.15	0.063
1.07	39.28	0.063
1.08	39.42	0.063
1.09	39.55	0.064
1.11	39.68	0.064
1.12	39.81	0.063
1.13	39.95	0.063
1.15	40.08	0.063
1.16	40.21	0.063
1.17	40.35	0.063
1.19	40.48	0.063
1.20	40.61	0.063
1.21	40.74	0.063
1.23	40.88	0.063
1.24	41.01	0.063
1.25	41.14	0.063
1.27	41.28	0.063
1.28	41.41	0.063
1.29	41.54	0.063
1.31	41.68	0.063
1.32	41.81	0.063
1.33	41.94	0.063
1.35	42.08	0.063
1.36	42.21	0.063
1.37	42.34	0.063
1.39	42.48	0.063
1.40	42.61	0.063
1.41	42.74	0.063
1.43	42.87	0.062
1.44	43.01	0.062
1.45	43.14	0.062
1.47	43.27	0.062
1.48	43.41	0.062
1.49	43.54	0.062
1.51	43.67	0.062
1.52	43.81	0.062
1.53	43.94	0.062
1.55	44.07	0.062
1.56	44.21	0.062
1.57	44.34	0.062
1.59	44.47	0.062
1.60	44.61	0.062
1.61	44.74	0.061
1.63	44.87	0.061
1.64	45.01	0.061
1.65	45.14	0.061
1.67	45.27	0.061
1.68	45.41	0.061
1.69	45.54	0.061
1.71	45.67	0.061
1.72	45.81	0.061
1.73	45.94	0.061
1.75	46.07	0.061
1.76	46.21	0.060
1.77	46.34	0.060
1.79	46.47	0.060
1.80	46.61	0.060
1.81	46.74	0.060
1.83	46.87	0.060
1.84	47.01	0.060
1.85	47.14	0.060
1.87	47.27	0.060
1.88	47.41	0.060
1.89	47.54	0.060
1.91	47.67	0.060
1.92	47.81	0.060
1.93	47.94	0.059
1.95	48.08	0.059
1.96	48.21	0.059
1.97	48.34	0.059
1.99	48.47	0.059
2.00	48.61	0.059
2.01	48.74	0.059
2.03	48.88	0.059
2.04	49.01	0.058
2.05	49.14	0.058
2.07	49.27	0.058
2.08	49.41	0.058
2.09	49.54	0.058
2.11	49.68	0.058
2.12	49.81	0.058
2.13	49.94	0.058
2.15	50.08	0.058
2.16	50.21	0.058
2.17	50.34	0.058
2.19	50.48	0.058
2.20	50.61	0.058
2.21	50.74	0.057
2.23	50.88	0.057
2.24	51.01	0.057
2.25	51.14	0.057
2.27	51.28	0.057
2.28	51.41	0.057
2.29	51.54	0.057
2.31	51.68	0.057
2.32	51.81	0.057
2.33	51.94	0.057
2.35	52.08	0.057
2.36	52.21	0.057
2.37	52.34	0.057
2.39	52.48	0.056
2.40	52.61	0.056
2.41	52.74	0.056
2.43	52.88	0.056
2.44	53.01	0.056
2.45	53.14	0.056
2.47	53.28	0.056
2.48	53.41	0.056
2.49	53.54	0.056
2.51	53.68	0.056
2.52	53.81	0.056
2.53	53.94	0.056
2.55	54.08	0.056
2.56	54.21	0.055
2.57	54.34	0.055
2.59	54.48	0.055
2.60	54.61	0.055
2.61	54.75	0.055
2.63	54.88	0.055
2.64	55.01	0.055
2.65	55.15	0.055
2.67	55.28	0.055
2.68	55.41	0.055
2.69	55.55	0.055
2.71	55.68	0.055
2.72	55.81	0.055
2.73	55.95	0.054
2.75	56.08	0.054
2.76	56.21	0.054
2.77	56.35	0.054
2.79	56.48	0.054
2.80	56.61	0.054
2.81	56.75	0.054
2.83	56.88	0.054
2.84	57.01	0.054
2.85	57.15	0.054
2.87	57.28	0.054
2.88	57.41	0.054
2.89	57.55	0.054
2.91	57.68	0.054
2.92	57.81	0.054
2.93	57.95	0.054
2.95	58.08	0.054
2.96	58.21	0.054
2.97	58.35	0.053
2.99	58.48	0.053
3.00	58.62	0.053
3.01	58.75	0.053
3.03	58.88	0.053
3.04	59.02	0.053
3.05	59.15	0.053
3.07	59.28	0.053
3.08	59.42	0.053
3.09	59.55	0.053
3.11	59.68	0.053
3.12	59.82	0.053
3.13	59.95	0.053
3.15	60.08	0.053
3.16	60.22	0.053
3.17	60.35	0.053
3.19	60.48	0.053
3.20	60.62	0.052
3.21	60.75	0.052
3.23	60.88	0.052
3.24	61.02	0.052
3.25	61.15	0.052
3.27	61.28	0.052
3.28	61.42	0.052
3.29	61.55	0.052
3.31	61.69	0.052
3.32	61.82	0.052
3.33	61.95	0.052
3.35	62.08	0.052
3.36	62.22	0.052
3.37	62.35	0.052
3.39	62.48	0.052
3.40	62.62	0.052
3.41	62.75	0.051
3.43	62.88	0.051
3.44	63.02	0.051
3.45	63.15	0.051
3.47	63.28	0.051
3.48	63.42	0.051
3.49	63.55	0.051
3.51	63.68	0.051
3.52	63.82	0.051
3.53	63.95	0.051
3.55	64.09	0.051
3.56	64.22	0.051
3.57	64.35	0.051
3.59	64.49	0.051
3.60	64.62	0.051
3.61	64.75	0.051
3.63	64.89	0.051
3.64	65.02	0.051
3.65	65.15	0.051
3.67	65.29	0.050
3.68	65.42	0.050
3.69	65.55	0.050
3.71	65.69	0.050
3.72	65.82	0.050
3.73	65.95	0.050
3.75	66.09	0.050
3.76	66.22	0.050
3.77	66.35	0.050
3.79	66.49	0.050
3.80	66.62	0.050
3.81	66.75	0.050
3.83	66.89	0.050
3.84	67.02	0.050
3.85	67.16	0.050
3.87	67.29	0.050
3.88	67.42	0.050
3.89	67.56	0.050
3.91	67.69	0.050
3.92	67.82	0.049
3.93	67.96	0.049
3.95	68.09	0.049
3.96	68.22	0.049
3.97	68.36	0.049
3.99	68.49	0.049
4.00	68.62	0.049
4.01	68.76	0.049
4.03	68.89	0.049
4.04	69.02	0.049
4.05	69.16	0.049
4.07	69.29	0.049
4.08	69.42	0.049
4.09	69.56	0.049
4.11	69.69	0.049
4.12	69.82	0.049
4.13	69.96	0.048
4.15	70.09	0.048
4.16	70.22	0.049
4.17	70.36	0.048
4.19	70.49	0.048
4.20	70.63	0.048
4.21	70.76	0.048
4.23	70.89	0.048
4.24	71.03	0.048
4.25	71.16	0.048
4.27	71.29	0.048
4.28	71.43	0.048
4.29	71.56	0.048
4.31	71.69	0.048
4.32	71.83	0.048
4.33	71.96	0.048
4.35	72.09	0.048
4.36	72.23	0.048
4.37	72.36	0.048
4.39	72.49	0.048
4.40	72.63	0.048
4.41	72.76	0.048
4.43	72.90	0.048
4.44	73.03	0.048
4.45	73.16	0.048
4.47	73.29	0.048
4.48	73.43	0.048
4.49	73.56	0.047
4.51	73.69	0.047
4.52	73.83	0.047
4.53	73.96	0.047
4.55	74.10	0.047
4.56	74.23	0.047
4.57	74.36	0.047
4.59	74.49	0.047
4.60	74.63	0.047
4.61	74.76	0.047
4.63	74.90	0.047
4.64	75.03	0.047
4.65	75.16	0.047
4.67	75.30	0.047
4.68	75.43	0.047
4.69	75.56	0.047
4.71	75.70	0.047
4.72	75.83	0.046
4.73	75.96	0.046
4.75	76.10	0.046
4.76	76.23	0.046
4.77	76.36	0.046
4.79	76.50	0.046
4.80	76.63	0.046
4.81	76.76	0.046
4.83	76.90	0.046
4.84	77.03	0.046
4.85	77.16	0.046
4.87	77.30	0.046
4.88	77.43	0.046
4.89	77.56	0.046
4.91	77.70	0.046
4.92	77.83	0.046
4.93	77.97	0.046
4.95	78.10	0.046
4.96	78.23	0.046
4.97	78.36	0.046
4.99	78.50	0.046
5.00	78.63	0.046
5.01	78.77	0.046
5.03	78.90	0.046
5.04	79.03	0.046
5.05	79.17	0.045
5.07	79.30	0.045
5.08	79.43	0.045
5.09	79.57	0.045
5.11	79.70	0.045
5.12	79.83	0.045
5.13	79.97	0.045
5.15	80.10	0.045
5.16	80.23	0.045
5.17	80.37	0.045
5.19	80.50	0.045
5.20	80.63	0.045
5.21	80.77	0.045
5.23	80.90	0.045
5.24	81.03	0.045
5.25	81.17	0.045
5.27	81.30	0.045
5.28	81.43	0.045
5.29	81.57	0.045
5.31	81.70	0.045
5.32	81.83	0.044
5.33	81.97	0.044
5.35	82.10	0.044
5.36	82.23	0.044
5.37	82.37	0.044
5.39	82.50	0.044
5.40	82.64	0.044
5.41	82.77	0.044
5.43	82.90	0.044
5.44	83.04	0.044
5.45	83.17	0.044
5.47	83.30	0.043
5.48	83.44	0.043
5.49	83.57	0.043
5.51	83.70	0.043
5.52	83.84	0.043
5.53	83.97	0.043
5.55	84.10	0.043
5.56	84.24	0.043
5.57	84.37	0.043
5.59	84.50	0.043
5.60	84.64	0.043
5.61	84.77	0.043
5.63	84.90	0.042
5.64	85.04	0.042
5.65	85.17	0.042
5.67	85.30	0.042
5.68	85.44	0.042
5.69	85.57	0.042
5.71	85.70	0.042
5.72	85.84	0.042
5.73	85.97	0.042
5.75	86.10	0.042
5.76	86.24	0.042
5.77	86.37	0.041
5.79	86.51	0.041
5.80	86.64	0.041
5.81	86.77	0.041
5.83	86.91	0.041
5.84	87.04	0.041
5.85	87.17	0.041
5.87	87.31	0.041
5.88	87.44	0.041
5.89	87.57	0.041
5.91	87.71	0.041
5.92	87.84	0.041
5.93	87.97	0.041
5.95	88.11	0.041
5.96	88.24	0.040
5.97	88.37	0.040
5.99	88.51	0.040
6.00	88.64	0.040
6.01	88.77	0.040
6.03	88.91	0.040
6.04	89.04	0.040
6.05	89.17	0.040
6.07	89.31	0.040
6.08	89.44	0.040
6.09	89.57	0.040
6.11	89.71	0.040
6.12	89.84	0.040
6.13	89.97	0.040
6.15	90.11	0.040
6.16	90.24	0.040
6.17	90.37	0.040
6.19	90.51	0.040
6.20	90.64	0.040
6.21	90.78	0.040
6.23	90.91	0.040
6.24	91.04	0.040
6.25	91.18	0.040
6.27	91.31	0.040
6.28	91.44	0.040
6.29	91.58	0.040
6.31	91.71	0.040
6.32	91.84	0.040
6.33	91.98	0.040
6.35	92.11	0.040
6.36	92.24	0.040
6.37	92.38	0.040
6.39	92.51	0.040
6.40	92.64	0.040
6.41	92.78	0.040
6.43	92.91	0.040
6.44	93.04	0.040
6.45	93.18	0.040
6.47	93.31	0.040
6.48	93.44	0.040
6.49	93.58	0.040
6.51	93.71	0.040
6.52	93.84	0.040
6.53	93.98	0.040
6.55	94.11	0.040
6.56	94.24	0.040
6.57	94.38	0.040
6.59	94.51	0.040
6.60	94.64	0.040
6.61	94.78	0.039
6.63	94.91	0.039
6.64	95.04	0.039
6.65	95.18	0.039
6.67	95.31	0.039
6.68	95.45	0.039
6.69	95.58	0.039
6.71	95.71	0.039
6.72	95.85	0.039
6.73	95.98	0.039
6.75	96.11	0.039
6.76	96.25	0.039
6.77	96.38	0.039
6.79	96.51	0.039
6.80	96.65	0.039
6.81	96.78	0.039
6.83	96.91	0.039
6.84	97.05	0.039
6.85	97.18	0.039
6.87	97.31	0.039
6.88	97.45	0.039
6.89	97.58	0.039
6.91	97.71	0.039
6.92	97.85	0.039
6.93	97.98	0.039
6.95	98.11	0.039
6.96	98.25	0.039
6.97	98.38	0.039
6.99	98.51	0.039
7.00	98.65	0.039
7.01	98.78	0.039
7.03	98.91	0.039
7.04	99.05	0.039
7.05	99.18	0.039
7.07	99.31	0.039
7.08	99.45	0.038
7.09	99.58	0.039
7.11	99.72	0.038
7.12	99.85	0.038
7.13	99.98	0.039
7.15	100.11	0.038
7.16	100.25	0.039
7.17	100.38	0.039
7.19	100.52	0.039
7.20	100.65	0.038
7.21	100.78	0.038
7.23	100.92	0.038
7.24	101.05	0.038
7.25	101.18	0.038
7.27	101.32	0.038
7.28	101.45	0.038
7.29	101.58	0.038
7.31	101.72	0.038
7.32	101.85	0.038
7.33	101.98	0.038
7.35	102.12	0.038
7.36	102.25	0.038
7.37	102.38	0.038
7.39	102.52	0.038
7.40	102.65	0.038
7.41	102.78	0.038
7.43	102.92	0.038
7.44	103.05	0.038
7.45	103.18	0.038
7.47	103.32	0.038
7.48	103.45	0.038
7.49	103.58	0.038
7.51	103.72	0.038
7.52	103.85	0.038
7.53	103.98	0.038
7.55	104.12	0.038
7.56	104.25	0.038
7.57	104.38	0.038
7.59	104.52	0.038
7.60	104.65	0.038
7.61	104.78	0.037
7.63	104.92	0.037
7.64	105.05	0.037
7.65	105.19	0.037
7.67	105.32	0.037
7.68	105.45	0.037
7.69	105.59	0.037
7.71	105.72	0.037
7.72	105.85	0.037
7.73	105.99	0.037
7.75	106.12	0.037
7.76	106.25	0.037
7.77	106.39	0.037
7.79	106.52	0.037
7.80	106.65	0.037
7.81	106.79	0.037
7.83	106.92	0.037
7.84	107.05	0.037
7.85	107.19	0.037
7.87	107.32	0.037
7.88	107.45	0.037
7.89	107.59	0.037
7.91	107.72	0.037
7.92	107.85	0.037
7.93	107.99	0.037
7.95	108.12	0.036
7.96	108.25	0.036
7.97	108.39	0.036
7.99	108.52	0.036
8.00	108.66	0.036
8.01	108.79	0.037
8.03	108.92	0.037
8.04	109.06	0.036
8.05	109.19	0.037
8.07	109.32	0.037
8.08	109.46	0.037
8.09	109.59	0.037
8.11	109.72	0.036
8.12	109.85	0.036
8.13	109.99	0.036
8.15	110.12	0.036
8.16	110.25	0.036
8.17	110.39	0.036
8.19	110.52	0.036
8.20	110.66	0.036
8.21	110.79	0.036
8.23	110.92	0.036
8.24	111.05	0.036
8.25	111.19	0.036
8.27	111.32	0.036
8.28	111.46	0.036
8.29	111.59	0.036
8.31	111.72	0.036
8.32	111.86	0.036
8.33	111.99	0.036
8.35	112.12	0.036
8.36	112.26	0.036
8.37	112.39	0.035
8.39	112.52	0.035
8.40	112.66	0.035
8.41	112.79	0.035
8.43	112.92	0.035
8.44	113.06	0.035
8.45	113.19	0.035
8.47	113.32	0.035
8.48	113.46	0.035
8.49	113.59	0.035
8.51	113.72	0.035
8.52	113.86	0.035
8.53	113.99	0.035
8.55	114.12	0.035
8.56	114.26	0.035
8.57	114.39	0.035
8.59	114.53	0.035
8.60	114.66	0.035
8.61	114.79	0.035
8.63	114.93	0.035
8.64	115.06	0.035
8.65	115.19	0.035
8.67	115.33	0.035
8.68	115.46	0.035
8.69	115.59	0.035
8.71	115.72	0.035
8.72	115.86	0.035
8.73	115.99	0.035
8.75	116.13	0.035
8.76	116.26	0.035
8.77	116.39	0.035
8.79	116.53	0.035
8.80	116.66	0.035
8.81	116.79	0.035
8.83	116.92	0.034
8.84	117.06	0.035
8.85	117.19	0.034
8.87	117.33	0.034
8.88	117.46	0.034
8.89	117.59	0.034
8.91	117.73	0.034
8.92	117.86	0.034
8.93	117.99	0.034
8.95	118.13	0.034
8.96	118.26	0.034
8.97	118.39	0.034
8.99	118.53	0.034
9.00	118.66	0.034
9.01	118.79	0.034
9.03	118.93	0.034
9.04	119.06	0.034
9.05	119.19	0.034
9.07	119.33	0.034
9.08	119.46	0.034
9.09	119.59	0.033
9.11	119.73	0.033
9.12	119.86	0.033
9.13	119.99	0.033
9.15	120.13	0.033
9.16	120.26	0.033
9.17	120.39	0.033
9.19	120.53	0.033
9.20	120.66	0.033
9.21	120.80	0.033
9.23	120.93	0.033
9.24	121.06	0.033
9.25	121.20	0.033
9.27	121.33	0.033
9.28	121.46	0.033
9.29	121.60	0.033
9.31	121.73	0.033
9.32	121.86	0.033
9.33	122.00	0.033
9.35	122.13	0.033
9.36	122.26	0.033
9.37	122.40	0.033
9.39	122.53	0.033
9.40	122.66	0.033
9.41	122.80	0.033
9.43	122.93	0.033
9.44	123.06	0.033
9.45	123.20	0.033
9.47	123.33	0.033
9.48	123.46	0.033
9.49	123.60	0.033
9.51	123.73	0.033
9.52	123.86	0.033
9.53	124.00	0.033
9.55	124.13	0.032
9.56	124.26	0.032
9.57	124.40	0.032
9.59	124.53	0.032
9.60	124.67	0.032
9.61	124.80	0.032
9.63	124.93	0.032
9.64	125.07	0.032
9.65	125.20	0.032
9.67	125.33	0.032
9.68	125.47	0.032
9.69	125.60	0.032
9.71	125.73	0.032
9.72	125.86	0.032
9.73	126.00	0.032
9.75	126.13	0.032
9.76	126.26	0.032
9.77	126.40	0.032
9.79	126.53	0.032
9.80	126.67	0.032
9.81	126.80	0.031
9.83	126.93	0.031
9.84	127.07	0.031
9.85	127.20	0.031
9.87	127.33	0.031
9.88	127.47	0.031
9.89	127.60	0.031
9.91	127.73	0.031
9.92	127.87	0.031
9.93	128.00	0.031
9.95	128.13	0.031
9.96	128.27	0.031
9.97	128.40	0.031
9.99	128.53	0.031
10.00	128.67	0.031
10.01	128.80	0.031
10.03	128.93	0.031
10.04	129.07	0.031
10.05	129.20	0.031
10.07	129.33	0.031
10.08	129.47	0.031
10.09	129.60	0.031
10.11	129.73	0.031
10.12	129.87	0.031
10.13	130.00	0.030
10.15	130.13	0.031
10.16	130.27	0.030
10.17	130.40	0.030
10.19	130.53	0.030
10.20	130.67	0.030
10.21	130.80	0.030
10.23	130.93	0.030
10.24	131.07	0.030
10.25	131.20	0.030
10.27	131.33	0.030
10.28	131.47	0.030
10.29	131.60	0.030
10.31	131.74	0.030
10.32	131.87	0.030
10.33	132.00	0.030
10.35	132.14	0.030
10.36	132.27	0.030
10.37	132.40	0.030
10.39	132.54	0.030
10.40	132.67	0.030
10.41	132.80	0.030
10.43	132.94	0.030
10.44	133.07	0.030
10.45	133.20	0.029
10.47	133.34	0.029
10.48	133.47	0.029
10.49	133.60	0.029
10.51	133.74	0.029
10.52	133.87	0.029
10.53	134.00	0.029
10.55	134.14	0.029
10.56	134.27	0.029
10.57	134.40	0.029
10.59	134.54	0.029
10.60	134.67	0.029
10.61	134.80	0.029
10.63	134.94	0.029
10.64	135.07	0.029
10.65	135.20	0.029
10.67	135.34	0.029
10.68	135.47	0.029
10.69	135.60	0.029
10.71	135.74	0.029
10.72	135.87	0.029
10.73	136.00	0.029
10.75	136.14	0.029
10.76	136.27	0.029
10.77	136.40	0.029
10.79	136.54	0.029
10.80	136.67	0.029
10.81	136.80	0.029
10.83	136.94	0.028
10.84	137.07	0.029
10.85	137.21	0.028
10.87	137.34	0.028
10.88	137.47	0.028
10.89	137.60	0.028
10.91	137.74	0.028
10.92	137.87	0.028
10.93	138.00	0.028
10.95	138.14	0.028
10.96	138.27	0.028
10.97	138.40	0.028
10.99	138.54	0.028
11.00	138.67	0.028
11.01	138.81	0.028
11.03	138.94	0.028
11.04	139.07	0.028
11.05	139.21	0.028
11.07	139.34	0.028
11.08	139.47	0.028
11.09	139.61	0.028
11.11	139.74	0.028
11.12	139.87	0.028
11.13	140.01	0.028
11.15	140.14	0.028
11.16	140.27	0.027
11.17	140.41	0.027
11.19	140.54	0.027
11.20	140.67	0.027
11.21	140.81	0.027
11.23	140.94	0.027
11.24	141.07	0.027
11.25	141.21	0.027
11.27	141.34	0.027
11.28	141.47	0.027
11.29	141.61	0.027
11.31	141.74	0.027
11.32	141.87	0.027
11.33	142.01	0.027
11.35	142.14	0.027
11.36	142.28	0.027
11.37	142.41	0.027
11.39	142.54	0.027
11.40	142.67	0.027
11.41	142.81	0.027
11.43	142.94	0.027
11.44	143.07	0.027
11.45	143.21	0.027
11.47	143.34	0.027
11.48	143.47	0.027
11.49	143.61	0.026
11.51	143.74	0.026
11.52	143.88	0.026
11.53	144.01	0.026
11.55	144.14	0.026
11.56	144.27	0.026
11.57	144.41	0.026
11.59	144.54	0.026
11.60	144.68	0.026
11.61	144.81	0.026
11.63	144.94	0.026
11.64	145.08	0.026
11.65	145.21	0.026
11.67	145.34	0.026
11.68	145.48	0.026
11.69	145.61	0.026
11.71	145.74	0.026
11.72	145.88	0.026
11.73	146.01	0.026
11.75	146.14	0.026
11.76	146.28	0.026
11.77	146.41	0.026
11.79	146.54	0.026
11.80	146.68	0.026
11.81	146.81	0.026
11.83	146.94	0.026
11.84	147.08	0.026
11.85	147.21	0.026
11.87	147.34	0.026
11.88	147.48	0.026
11.89	147.61	0.026
11.91	147.74	0.026
11.92	147.88	0.026
11.93	148.01	0.026
11.95	148.14	0.025
11.96	148.28	0.026
11.97	148.41	0.025
11.99	148.54	0.025
12.00	148.68	0.025
12.01	148.81	0.025
12.03	148.94	0.025
12.04	149.08	0.025
12.05	149.21	0.025
12.07	149.35	0.025
12.08	149.48	0.025
12.09	149.61	0.025
12.11	149.75	0.025
12.12	149.88	0.025
12.13	150.01	0.025
12.15	150.15	0.025
12.16	150.28	0.025
12.17	150.41	0.025
12.19	150.55	0.025
12.20	150.68	0.025
12.21	150.81	0.025
12.23	150.95	0.025
12.24	151.08	0.025
12.25	151.21	0.025
12.27	151.35	0.024
12.28	151.48	0.024
12.29	151.61	0.024
12.31	151.75	0.024
12.32	151.88	0.024
12.33	152.01	0.024
12.35	152.15	0.024
12.36	152.28	0.024
12.37	152.41	0.024
12.39	152.55	0.024
12.40	152.68	0.024
12.41	152.81	0.024
12.43	152.95	0.024
12.44	153.08	0.024
12.45	153.22	0.024
12.47	153.35	0.024
12.48	153.48	0.024
12.49	153.61	0.024
12.51	153.75	0.024
12.52	153.88	0.024
12.53	154.01	0.024
12.55	154.15	0.024
12.56	154.28	0.024
12.57	154.41	0.024
12.59	154.55	0.024
12.60	154.68	0.023
12.61	154.81	0.023
12.63	154.95	0.023
12.64	155.08	0.023
12.65	155.21	0.023
12.67	155.35	0.023
12.68	155.48	0.023
12.69	155.62	0.023
12.71	155.75	0.023
12.72	155.88	0.023
12.73	156.02	0.023
12.75	156.15	0.023
12.76	156.28	0.023
12.77	156.42	0.023
12.79	156.55	0.023
12.80	156.68	0.024
12.81	156.81	0.067
12.83	156.95	0.193
12.84	157.07	0.433
12.85	157.19	0.696
12.87	157.30	0.928
12.88	157.42	1.147
12.89	157.53	1.369
12.91	157.64	1.591
12.92	157.74	1.819
12.93	157.85	2.047
12.95	157.96	2.269
12.96	158.06	2.489
12.97	158.17	2.707
12.99	158.27	2.925
13.00	158.38	3.122
13.01	158.49	3.225
13.03	158.61	2.488
13.04	158.78	1.135
13.05	158.95	0.806
13.07	159.13	0.649
13.08	159.29	0.546
13.09	159.46	0.467
13.11	159.61	0.394
13.12	159.77	0.341
13.13	159.92	0.292
13.15	160.07	0.249
13.16	160.21	0.214
13.17	160.36	0.182
13.19	160.50	0.161
13.20	160.64	0.136
13.21	160.78	0.119
13.23	160.92	0.105
13.24	161.06	0.091
13.25	161.20	0.082
13.27	161.33	0.071
13.28	161.47	0.063
13.29	161.61	0.060
13.31	161.74	0.052
13.32	161.88	0.049
13.33	162.01	0.046
13.35	162.14	0.042
13.36	162.28	0.040
13.37	162.41	0.038
13.39	162.55	0.035
13.40	162.68	0.033
13.41	162.82	0.032
13.43	162.95	0.031
13.44	163.08	0.031
13.45	163.22	0.029
13.47	163.35	0.029
13.48	163.48	0.028
13.49	163.62	0.028
13.51	163.75	0.027
13.52	163.89	0.027
13.53	164.02	0.026
13.55	164.15	0.026
13.56	164.29	0.026
13.57	164.42	0.025
13.59	164.55	0.025
13.60	164.69	0.025
13.61	164.82	0.025
13.63	164.95	0.024
13.64	165.09	0.024
13.65	165.22	0.024
13.67	165.35	0.023
13.68	165.49	0.023
13.69	165.62	0.023
13.71	165.75	0.022
13.72	165.89	0.022
13.73	166.02	0.022
13.75	166.15	0.022
13.76	166.29	0.022
13.77	166.42	0.021
13.79	166.55	0.021
13.80	166.69	0.021
13.81	166.82	0.021
13.83	166.95	0.021
13.84	167.09	0.021
13.85	167.22	0.021
13.87	167.35	0.021
13.88	167.49	0.020
13.89	167.62	0.020
13.91	167.75	0.020
13.92	167.89	0.020
13.93	168.02	0.020
13.95	168.15	0.020
13.96	168.29	0.020
13.97	168.42	0.020
13.99	168.55	0.019
14.00	168.69	0.019
14.01	168.82	0.019
14.03	168.95	0.019
14.04	169.09	0.019
14.05	169.22	0.019
14.07	169.35	0.019
14.08	169.49	0.019
14.09	169.62	0.019
14.11	169.75	0.019
14.12	169.89	0.018
14.13	170.02	0.018
14.15	170.16	0.019
14.16	170.29	0.018
14.17	170.42	0.018
14.19	170.55	0.018
14.20	170.69	0.018
14.21	170.82	0.018
14.23	170.96	0.018
14.24	171.09	0.018
14.25	171.22	0.018
14.27	171.35	0.018
14.28	171.49	0.018
14.29	171.62	0.018
14.31	171.76	0.018
14.32	171.89	0.018
14.33	172.02	0.018
14.35	172.16	0.018
14.36	172.29	0.018
14.37	172.42	0.018
14.39	172.56	0.017
14.40	172.69	0.017
14.41	172.82	0.017
14.43	172.96	0.017
14.44	173.09	0.017
14.45	173.22	0.017
14.47	173.36	0.017
14.48	173.49	0.017
14.49	173.62	0.017
14.51	173.76	0.017
14.52	173.89	0.017
14.53	174.02	0.017
14.55	174.16	0.017
14.56	174.29	0.017
14.57	174.42	0.017
14.59	174.56	0.017
14.60	174.69	0.017
14.61	174.82	0.017
14.63	174.96	0.017
14.64	175.09	0.017
14.65	175.22	0.017
14.67	175.36	0.017
14.68	175.49	0.017
14.69	175.62	0.017
14.71	175.76	0.017
14.72	175.89	0.017
14.73	176.02	0.017
14.75	176.16	0.017
14.76	176.29	0.017
14.77	176.42	0.017
14.79	176.56	0.017
14.80	176.69	0.017
14.81	176.83	0.017
14.83	176.96	0.016
14.84	177.09	0.016
14.85	177.22	0.016
14.87	177.36	0.016
14.88	177.49	0.016
14.89	177.62	0.016
14.91	177.76	0.016
14.92	177.89	0.016
14.93	178.03	0.016
14.95	178.16	0.016
14.96	178.29	0.016
14.97	178.42	0.016
14.99	178.56	0.016
15.00	178.69	0.016
15.01	178.83	0.016
15.03	178.96	0.016
15.04	179.09	0.016
15.05	179.23	0.016
15.07	179.36	0.016
15.08	179.49	0.016
15.09	179.63	0.016
15.11	179.76	0.016
15.12	179.89	0.016
15.13	180.03	0.016
15.15	180.16	0.016
15.16	180.29	0.016
15.17	180.43	0.016
15.19	180.56	0.016
15.20	180.69	0.015
15.21	180.83	0.015
15.23	180.96	0.015
15.24	181.09	0.015
15.25	181.23	0.015
15.27	181.36	0.015
15.28	181.49	0.015
15.29	181.63	0.015
15.31	181.76	0.015
15.32	181.89	0.015
15.33	182.03	0.015
15.35	182.16	0.015
15.36	182.29	0.015
15.37	182.43	0.015
15.39	182.56	0.015
15.40	182.69	0.015
15.41	182.83	0.015
15.43	182.96	0.015
15.44	183.09	0.015
15.45	183.23	0.015
15.47	183.36	0.015
15.48	183.49	0.015
15.49	183.63	0.015
15.51	183.76	0.015
15.52	183.89	0.015
15.53	184.03	0.015
15.55	184.16	0.015
15.56	184.29	0.015
15.57	184.43	0.015
15.59	184.56	0.015
15.60	184.69	0.015
15.61	184.83	0.015
15.63	184.96	0.015
15.64	185.10	0.015
15.65	185.23	0.015
15.67	185.36	0.015
15.68	185.50	0.015
15.69	185.63	0.015
15.71	185.76	0.015
15.72	185.90	0.015
15.73	186.03	0.015
15.75	186.16	0.015
15.76	186.29	0.015
15.77	186.43	0.015
15.79	186.56	0.015
15.80	186.69	0.015
15.81	186.83	0.015
15.83	186.96	0.014
15.84	187.10	0.015
15.85	187.23	0.015
15.87	187.36	0.015
15.88	187.50	0.014
15.89	187.63	0.014
15.91	187.76	0.014
15.92	187.90	0.014
15.93	188.03	0.014
15.95	188.16	0.014
15.96	188.30	0.014
15.97	188.43	0.014
15.99	188.56	0.014
16.00	188.70	0.014
16.01	188.83	0.014
16.03	188.96	0.014
16.04	189.10	0.014
16.05	189.23	0.014
16.07	189.36	0.014
16.08	189.50	0.015
16.09	189.63	0.014
16.11	189.76	0.014
16.12	189.90	0.014
16.13	190.03	0.014
16.15	190.16	0.015
16.16	190.30	0.014
16.17	190.43	0.014
16.19	190.56	0.014
16.20	190.70	0.014
16.21	190.83	0.014
16.23	190.96	0.014
16.24	191.10	0.014
16.25	191.23	0.014
16.27	191.36	0.014
16.28	191.50	0.014
16.29	191.63	0.014
16.31	191.76	0.014
16.32	191.90	0.014
16.33	192.03	0.014
16.35	192.16	0.014
16.36	192.30	0.014
16.37	192.43	0.014
16.39	192.56	0.014
16.40	192.70	0.014
16.41	192.83	0.014
16.43	192.96	0.014
16.44	193.10	0.014
16.45	193.23	0.014
16.47	193.37	0.014
16.48	193.50	0.014
16.49	193.63	0.014
16.51	193.76	0.014
16.52	193.90	0.014
16.53	194.03	0.014
16.55	194.17	0.014
16.56	194.30	0.014
16.57	194.43	0.014
16.59	194.57	0.014
16.60	194.70	0.014
16.61	194.83	0.014
16.63	194.97	0.014
16.64	195.10	0.014
16.65	195.23	0.014
16.67	195.37	0.014
16.68	195.50	0.014
16.69	195.63	0.014
16.71	195.77	0.014
16.72	195.90	0.014
16.73	196.03	0.014
16.75	196.17	0.014
16.76	196.30	0.014
16.77	196.43	0.014
16.79	196.57	0.014
16.80	196.70	0.014
16.81	196.83	0.014
16.83	196.97	0.014
16.84	197.10	0.014
16.85	197.23	0.014
16.87	197.37	0.014
16.88	197.50	0.014
16.89	197.63	0.014
16.91	197.77	0.014
16.92	197.90	0.014
16.93	198.03	0.014
16.95	198.17	0.014
16.96	198.30	0.014
16.97	198.43	0.014
16.99	198.57	0.014
17.00	198.70	0.014
17.01	198.83	0.014
17.03	198.97	0.014
17.04	199.10	0.014
17.05	199.23	0.014
17.07	199.37	0.014
17.08	199.50	0.014
17.09	199.63	0.014
17.11	199.77	0.014
17.12	199.90	0.014
17.13	200.03	0.014
17.15	200.17	0.014
17.16	200.30	0.014
17.17	200.43	0.014
17.19	200.57	0.014
17.20	200.70	0.015
17.21	200.83	0.014
17.23	200.97	0.014
17.24	201.10	0.014
17.25	201.23	0.015
17.27	201.37	0.015
17.28	201.50	0.015
17.29	201.64	0.015
17.31	201.77	0.015
17.32	201.90	0.015
17.33	202.03	0.014
17.35	202.17	0.014
17.36	202.30	0.014
17.37	202.43	0.014
17.39	202.57	0.014
17.40	202.70	0.014
17.41	202.83	0.014
17.43	202.97	0.014
17.44	203.10	0.014
17.45	203.23	0.014
17.47	203.37	0.014
17.48	203.50	0.014
17.49	203.64	0.014
17.51	203.77	0.014
17.52	203.90	0.014
17.53	204.04	0.014
17.55	204.17	0.014
17.56	204.30	0.014
17.57	204.44	0.014
17.59	204.57	0.014
17.60	204.70	0.014
17.61	204.83	0.014
17.63	204.97	0.014
17.64	205.10	0.014
17.65	205.24	0.014
17.67	205.37	0.014
17.68	205.50	0.014
17.69	205.64	0.014
17.71	205.77	0.014
17.72	205.90	0.014
17.73	206.04	0.014
17.75	206.17	0.014
17.76	206.30	0.014
17.77	206.44	0.014
17.79	206.57	0.014
17.80	206.70	0.014
17.81	206.84	0.014
17.83	206.97	0.014
17.84	207.10	0.014
17.85	207.24	0.014
17.87	207.37	0.014
17.88	207.50	0.014
17.89	207.64	0.014
17.91	207.77	0.014
17.92	207.90	0.014
17.93	208.04	0.014
17.95	208.17	0.014
17.96	208.30	0.014
17.97	208.44	0.014
17.99	208.57	0.014
18.00	208.70	0.014
18.01	208.84	0.014
18.03	208.97	0.014
18.04	209.10	0.014
18.05	209.24	0.014
18.07	209.37	0.014
18.08	209.50	0.014
18.09	209.64	0.014
18.11	209.77	0.014
18.12	209.90	0.014
18.13	210.04	0.014
18.15	210.17	0.014
18.16	210.30	0.014
18.17	210.44	0.014
18.19	210.57	0.014
18.20	210.70	0.014
18.21	210.84	0.014
18.23	210.97	0.014
18.24	211.10	0.014
18.25	211.24	0.014
18.27	211.37	0.014
18.28	211.50	0.014
18.29	211.64	0.014
18.31	211.77	0.014
18.32	211.90	0.013
18.33	212.04	0.013
18.35	212.17	0.013
18.36	212.30	0.013
18.37	212.44	0.013
18.39	212.57	0.013
18.40	212.70	0.013
18.41	212.84	0.013
18.43	212.97	0.013
18.44	213.10	0.013
18.45	213.24	0.013
18.47	213.37	0.013
18.48	213.50	0.013
18.49	213.64	0.013
18.51	213.77	0.013
18.52	213.90	0.013
18.53	214.04	0.013
18.55	214.17	0.013
18.56	214.30	0.013
18.57	214.44	0.013
18.59	214.57	0.013
18.60	214.70	0.013
18.61	214.84	0.013
18.63	214.97	0.013
18.64	215.10	0.013
18.65	215.24	0.013
18.67	215.37	0.013
18.68	215.50	0.013
18.69	215.64	0.013
18.71	215.77	0.012
18.72	215.90	0.013
18.73	216.04	0.013
18.75	216.17	0.013
18.76	216.30	0.013
18.77	216.44	0.013
18.79	216.57	0.012
18.80	216.71	0.013
18.81	216.84	0.012
18.83	216.97	0.012
18.84	217.10	0.012
18.85	217.24	0.012
18.87	217.37	0.012
18.88	217.50	0.012
18.89	217.64	0.012
18.91	217.77	0.012
18.92	217.91	0.012
18.93	218.04	0.012
18.95	218.17	0.012
18.96	218.31	0.012
18.97	218.44	0.012
18.99	218.57	0.012
19.00	218.71	0.012

[step]
Ramp 10.00 °C/min to 30.00 °C
Time	Temperature	Heat Flow (Normalized)
min	°C	W/g
20.00	220.07	-0.116
20.02	220.07	-0.117
20.03	220.07	-0.117
20.04	220.07	-0.116
20.06	220.06	-0.109
20.07	220.04	-0.079
20.08	220.02	-0.049
20.09	219.98	-0.019
20.11	219.93	0.001
20.12	219.87	0.015
20.13	219.80	0.013
20.15	219.72	0.005
20.16	219.63	-0.005
20.18	219.53	-0.037
20.19	219.43	-0.064
20.20	219.32	-0.093
20.22	219.20	-0.114
20.23	219.08	-0.135
20.24	218.97	-0.154
20.26	218.85	-0.167
20.27	218.72	-0.180
20.28	218.60	-0.190
20.29	218.47	-0.198
20.31	218.35	-0.204
20.32	218.22	-0.208
20.33	218.09	-0.214
20.35	217.97	-0.215
20.36	217.84	-0.218
20.38	217.71	-0.220
20.39	217.58	-0.222
20.40	217.45	-0.224
20.42	217.32	-0.225
20.43	217.19	-0.227
20.44	217.06	-0.228
20.46	216.93	-0.228
20.47	216.80	-0.229
20.48	216.67	-0.230
20.49	216.54	-0.231
20.51	216.41	-0.231
20.52	216.27	-0.232
20.53	216.14	-0.232
20.55	216.01	-0.233
20.56	215.88	-0.233
20.58	215.75	-0.233
20.59	215.62	-0.234
20.60	215.49	-0.234
20.62	215.35	-0.234
20.63	215.22	-0.235
20.64	215.09	-0.235
20.66	214.96	-0.235
20.67	214.83	-0.236
20.68	214.70	-0.236
20.69	214.56	-0.236
20.71	214.43	-0.236
20.72	214.30	-0.237
20.73	214.17	-0.237
20.75	214.04	-0.237
20.76	213.90	-0.237
20.78	213.77	-0.237
20.79	213.64	-0.238
20.80	213.51	-0.238
20.82	213.38	-0.238
20.83	213.24	-0.238
20.84	213.11	-0.238
20.86	212.98	-0.238
20.87	212.85	-0.238
20.88	212.71	-0.239
20.89	212.58	-0.239
20.91	212.45	-0.239
20.92	212.32	-0.239
20.93	212.19	-0.239
20.95	212.05	-0.239
20.96	211.92	-0.239
20.98	211.79	-0.239
20.99	211.66	-0.239
21.00	211.52	-0.239
21.02	211.39	-0.239
21.03	211.26	-0.239
21.04	211.13	-0.239
21.06	210.99	-0.239
21.07	210.86	-0.239
21.08	210.73	-0.239
21.09	210.59	-0.239
21.11	210.46	-0.239
21.12	210.33	-0.239
21.13	210.20	-0.239
21.15	210.06	-0.239
21.16	209.93	-0.239
21.18	209.80	-0.239
21.19	209.67	-0.239
21.20	209.53	-0.238
21.22	209.40	-0.238
21.23	209.27	-0.238
21.24	209.13	-0.238
21.26	209.00	-0.238
21.27	208.87	-0.238
21.28	208.74	-0.238
21.29	208.60	-0.238
21.31	208.47	-0.238
21.32	208.34	-0.238
21.33	208.20	-0.238
21.35	208.07	-0.238
21.36	207.94	-0.237
21.38	207.81	-0.237
21.39	207.67	-0.237
21.40	207.54	-0.237
21.42	207.41	-0.237
21.43	207.27	-0.237
21.44	207.14	-0.237
21.46	207.01	-0.237
21.47	206.88	-0.237
21.48	206.74	-0.237
21.49	206.61	-0.236
21.51	206.48	-0.236
21.52	206.34	-0.236
21.53	206.21	-0.236
21.55	206.08	-0.236
21.56	205.94	-0.236
21.58	205.81	-0.236
21.59	205.68	-0.236
21.60	205.55	-0.235
21.62	205.41	-0.235
21.63	205.28	-0.235
21.64	205.15	-0.235
21.66	205.01	-0.235
21.67	204.88	-0.234
21.68	204.75	-0.234
21.69	204.61	-0.234
21.71	204.48	-0.234
21.72	204.35	-0.234
21.73	204.21	-0.234
21.75	204.08	-0.234
21.76	203.95	-0.234
21.78	203.82	-0.234
21.79	203.68	-0.233
21.80	203.55	-0.233
21.82	203.42	-0.233
21.83	203.28	-0.233
21.84	203.15	-0.233
21.86	203.02	-0.233
21.87	202.88	-0.233
21.88	202.75	-0.233
21.89	202.62	-0.232
21.91	202.48	-0.233
21.92	202.35	-0.232
21.93	202.22	-0.232
21.95	202.09	-0.232
21.96	201.95	-0.232
21.98	201.82	-0.232
21.99	201.69	-0.232
22.00	201.55	-0.232
22.02	201.42	-0.232
22.03	201.29	-0.232
22.04	201.15	-0.231
22.06	201.02	-0.231
22.07	200.89	-0.231
22.08	200.75	-0.231
22.09	200.62	-0.231
22.11	200.49	-0.231
22.12	200.36	-0.231
22.13	200.22	-0.231
22.15	200.09	-0.231
22.16	199.96	-0.231
22.18	199.82	-0.230
22.19	199.69	-0.230
22.20	199.56	-0.230
22.22	199.42	-0.230
22.23	199.29	-0.230
22.24	199.16	-0.230
22.26	199.02	-0.230
22.27	198.89	-0.230
22.28	198.76	-0.230
22.29	198.63	-0.230
22.31	198.49	-0.230
22.32	198.36	-0.230
22.33	198.23	-0.229
22.35	198.09	-0.229
22.36	197.96	-0.229
22.38	197.83	-0.229
22.39	197.69	-0.229
22.40	197.56	-0.229
22.42	197.43	-0.229
22.43	197.29	-0.229
22.44	197.16	-0.228
22.46	197.03	-0.228
22.47	196.89	-0.228
22.48	196.76	-0.228
22.49	196.63	-0.228
22.51	196.49	-0.228
22.52	196.36	-0.228
22.53	196.23	-0.228
22.55	196.09	-0.228
22.56	195.96	-0.228
22.58	195.83	-0.228
22.59	195.69	-0.228
22.60	195.56	-0.227
22.62	195.43	-0.227
22.63	195.29	-0.227
22.64	195.16	-0.227
22.66	195.03	-0.227
22.67	194.90	-0.227
22.68	194.76	-0.227
22.69	194.63	-0.227
22.71	194.50	-0.227
22.72	194.36	-0.227
22.73	194.23	-0.226
22.75	194.10	-0.226
22.76	193.96	-0.226
22.78	193.83	-0.226
22.79	193.70	-0.226
22.80	193.56	-0.226
22.82	193.43	-0.226
22.83	193.30	-0.226
22.84	193.16	-0.226
22.86	193.03	-0.226
22.87	192.90	-0.226
22.88	192.77	-0.226
22.89	192.63	-0.226
22.91	192.50	-0.225
22.92	192.37	-0.225
22.93	192.23	-0.225
22.95	192.10	-0.225
22.96	191.97	-0.225
22.98	191.83	-0.225
22.99	191.70	-0.225
23.00	191.57	-0.225
23.02	191.43	-0.225
23.03	191.30	-0.225
23.04	191.17	-0.225
23.06	191.03	-0.225
23.07	190.90	-0.225
23.08	190.77	-0.224
23.09	190.63	-0.224
23.11	190.50	-0.224
23.12	190.37	-0.224
23.13	190.23	-0.224
23.15	190.10	-0.224
23.16	189.97	-0.224
23.18	189.83	-0.224
23.19	189.70	-0.224
23.20	189.57	-0.224
23.22	189.44	-0.224
23.23	189.30	-0.224
23.24	189.17	-0.224
23.26	189.04	-0.224
23.27	188.90	-0.223
23.28	188.77	-0.223
23.29	188.64	-0.223
23.31	188.50	-0.223
23.32	188.37	-0.223
23.33	188.24	-0.223
23.35	188.10	-0.223
23.36	187.97	-0.223
23.38	187.84	-0.223
23.39	187.70	-0.223
23.40	187.57	-0.223
23.42	187.44	-0.223
23.43	187.30	-0.223
23.44	187.17	-0.223
23.46	187.04	-0.223
23.47	186.91	-0.223
23.48	186.77	-0.222
23.49	186.64	-0.222
23.51	186.50	-0.222
23.52	186.37	-0.222
23.53	186.24	-0.222
23.55	186.11	-0.222
23.56	185.97	-0.222
23.58	185.84	-0.222
23.59	185.71	-0.222
23.60	185.57	-0.222
23.62	185.44	-0.222
23.63	185.31	-0.221
23.64	185.17	-0.221
23.66	185.04	-0.221
23.67	184.91	-0.221
23.68	184.77	-0.221
23.69	184.64	-0.221
23.71	184.51	-0.221
23.72	184.37	-0.221
23.73	184.24	-0.221
23.75	184.11	-0.221
23.76	183.97	-0.221
23.78	183.84	-0.221
23.79	183.71	-0.221
23.80	183.57	-0.221
23.82	183.44	-0.221
23.83	183.31	-0.221
23.84	183.17	-0.221
23.86	183.04	-0.221
23.87	182.91	-0.220
23.88	182.77	-0.221
23.89	182.64	-0.220
23.91	182.51	-0.220
23.92	182.37	-0.220
23.93	182.24	-0.220
23.95	182.11	-0.220
23.96	181.98	-0.220
23.98	181.84	-0.220
23.99	181.71	-0.220
24.00	181.58	-0.220
24.02	181.44	-0.220
24.03	181.31	-0.220
24.04	181.18	-0.220
24.06	181.04	-0.220
24.07	180.91	-0.220
24.08	180.78	-0.220
24.09	180.64	-0.220
24.11	180.51	-0.219
24.12	180.38	-0.219
24.13	180.24	-0.219
24.15	180.11	-0.219
24.16	179.98	-0.219
24.18	179.85	-0.219
24.19	179.71	-0.219
24.20	179.58	-0.219
24.22	179.45	-0.219
24.23	179.31	-0.219
24.24	179.18	-0.219
24.26	179.05	-0.219
24.27	178.91	-0.219
24.28	178.78	-0.219
24.29	178.65	-0.219
24.31	178.51	-0.219
24.32	178.38	-0.219
24.33	178.25	-0.219
24.35	178.11	-0.219
24.36	177.98	-0.219
24.38	177.85	-0.219
24.39	177.71	-0.219
24.40	177.58	-0.219
24.42	177.45	-0.219
24.43	177.32	-0.219
24.44	177.18	-0.219
24.46	177.05	-0.219
24.47	176.91	-0.219
24.48	176.78	-0.218
24.49	176.65	-0.218
24.51	176.52	-0.218
24.52	176.38	-0.218
24.53	176.25	-0.218
24.55	176.12	-0.218
24.56	175.98	-0.218
24.58	175.85	-0.218
24.59	175.72	-0.218
24.60	175.58	-0.218
24.62	175.45	-0.218
24.63	175.32	-0.218
24.64	175.18	-0.218
24.66	175.05	-0.218
24.67	174.92	-0.218
24.68	174.78	-0.218
24.69	174.65	-0.218
24.71	174.52	-0.218
24.72	174.38	-0.218
24.73	174.25	-0.218
24.75	174.12	-0.218
24.76	173.98	-0.218
24.78	173.85	-0.218
24.79	173.72	-0.218
24.80	173.59	-0.217
24.82	173.45	-0.217
24.83	173.32	-0.217
24.84	173.19	-0.217
24.86	173.05	-0.217
24.87	172.92	-0.217
24.88	172.79	-0.217
24.89	172.65	-0.217
24.91	172.52	-0.217
24.92	172.39	-0.217
24.93	172.25	-0.217
24.95	172.12	-0.217
24.96	171.99	-0.217
24.98	171.85	-0.217
24.99	171.72	-0.217
25.00	171.59	-0.217
25.02	171.45	-0.217
25.03	171.32	-0.217
25.04	171.19	-0.217
25.06	171.06	-0.217
25.07	170.92	-0.216
25.08	170.79	-0.216
25.09	170.65	-0.216
25.11	170.52	-0.216
25.12	170.39	-0.216
25.13	170.26	-0.216
25.15	170.12	-0.216
25.16	169.99	-0.216
25.18	169.85	-0.216
25.19	169.72	-0.216
25.20	169.59	-0.216
25.22	169.45	-0.216
25.23	169.32	-0.216
25.24	169.19	-0.216
25.26	169.06	-0.216
25.27	168.92	-0.216
25.28	168.79	-0.216
25.29	168.66	-0.216
25.31	168.52	-0.216
25.32	168.39	-0.216
25.33	168.26	-0.216
25.35	168.12	-0.216
25.36	167.99	-0.216
25.38	167.86	-0.216
25.39	167.72	-0.216
25.40	167.59	-0.216
25.42	167.46	-0.216
25.43	167.32	-0.216
25.44	167.19	-0.216
25.46	167.06	-0.215
25.47	166.92	-0.215
25.48	166.79	-0.215
25.49	166.66	-0.215
25.51	166.53	-0.215
25.52	166.39	-0.215
25.53	166.26	-0.215
25.55	166.13	-0.215
25.56	165.99	-0.215
25.58	165.86	-0.215
25.59	165.72	-0.215
25.60	165.59	-0.215
25.62	165.46	-0.215
25.63	165.33	-0.215
25.64	165.19	-0.215
25.66	165.06	-0.215
25.67	164.93	-0.215
25.68	164.79	-0.215
25.69	164.66	-0.215
25.71	164.53	-0.215
25.72	164.39	-0.215
25.73	164.26	-0.215
25.75	164.13	-0.215
25.76	163.99	-0.215
25.78	163.86	-0.215
25.79	163.73	-0.215
25.80	163.59	-0.215
25.82	163.46	-0.215
25.83	163.33	-0.214
25.84	163.20	-0.214
25.86	163.06	-0.214
25.87	162.93	-0.214
25.88	162.80	-0.214
25.89	162.66	-0.214
25.91	162.53	-0.214
25.92	162.40	-0.215
25.93	162.26	-0.215
25.95	162.13	-0.214
25.96	162.00	-0.214
25.98	161.86	-0.214
25.99	161.73	-0.214
26.00	161.60	-0.214
26.02	161.46	-0.214
26.03	161.33	-0.214
26.04	161.20	-0.214
26.06	161.06	-0.214
26.07	160.93	-0.214
26.08	160.80	-0.214
26.09	160.66	-0.214
26.11	160.53	-0.214
26.12	160.40	-0.214
26.13	160.26	-0.214
26.15	160.13	-0.214
26.16	160.00	-0.214
26.18	159.87	-0.214
26.19	159.73	-0.214
26.20	159.60	-0.214
26.22	159.47	-0.214
26.23	159.33	-0.214
26.24	159.20	-0.214
26.26	159.06	-0.214
26.27	158.93	-0.214
26.28	158.80	-0.214
26.29	158.67	-0.214
26.31	158.53	-0.214
26.32	158.40	-0.214
26.33	158.27	-0.214
26.35	158.13	-0.214
26.36	158.00	-0.214
26.38	157.87	-0.214
26.39	157.73	-0.214
26.40	157.60	-0.214
26.42	157.47	-0.214
26.43	157.33	-0.214
26.44	157.20	-0.214
26.46	157.07	-0.214
26.47	156.93	-0.213
26.48	156.80	-0.213
26.49	156.67	-0.213
26.51	156.54	-0.213
26.52	156.40	-0.213
26.53	156.27	-0.213
26.55	156.14	-0.213
26.56	156.00	-0.213
26.58	155.87	-0.213
26.59	155.74	-0.213
26.60	155.60	-0.213
26.62	155.47	-0.213
26.63	155.34	-0.213
26.64	155.20	-0.213
26.66	155.07	-0.213
26.67	154.94	-0.213
26.68	154.80	-0.213
26.69	154.67	-0.213
26.71	154.54	-0.213
26.72	154.40	-0.213
26.73	154.27	-0.213
26.75	154.14	-0.213
26.76	154.00	-0.213
26.78	153.87	-0.213
26.79	153.74	-0.322
26.80	153.64	-3.219
26.82	153.62	-5.273
26.83	153.59	-5.487
26.84	153.54	-5.578
26.86	153.48	-5.676
26.87	153.41	-5.151
26.88	153.26	-1.964
26.89	153.06	-1.027
26.91	152.87	-0.786
26.92	152.69	-0.670
26.93	152.51	-0.593
26.95	152.34	-0.537
26.96	152.18	-0.487
26.98	152.02	-0.445
26.99	151.86	-0.408
27.00	151.71	-0.380
27.02	151.56	-0.354
27.03	151.42	-0.329
27.04	151.27	-0.315
27.06	151.13	-0.300
27.07	150.99	-0.282
27.08	150.85	-0.273
27.09	150.71	-0.264
27.11	150.57	-0.257
27.12	150.43	-0.251
27.13	150.29	-0.242
27.15	150.16	-0.241
27.16	150.02	-0.238
27.18	149.89	-0.236
27.19	149.75	-0.229
27.20	149.62	-0.226
27.22	149.48	-0.225
27.23	149.35	-0.225
27.24	149.21	-0.223
27.26	149.08	-0.222
27.27	148.95	-0.222
27.28	148.81	-0.221
27.29	148.68	-0.220
27.31	148.54	-0.219
27.32	148.41	-0.219
27.33	148.28	-0.218
27.35	148.14	-0.218
27.36	148.01	-0.217
27.38	147.88	-0.217
27.39	147.74	-0.217
27.40	147.61	-0.216
27.42	147.48	-0.216
27.43	147.34	-0.216
27.44	147.21	-0.216
27.46	147.08	-0.215
27.47	146.94	-0.215
27.48	146.81	-0.215
27.49	146.68	-0.215
27.51	146.54	-0.215
27.52	146.41	-0.214
27.53	146.28	-0.214
27.55	146.14	-0.214
27.56	146.01	-0.214
27.58	145.88	-0.213
27.59	145.75	-0.213
27.60	145.61	-0.213
27.62	145.48	-0.212
27.63	145.35	-0.212
27.64	145.21	-0.212
27.66	145.08	-0.212
27.67	144.95	-0.212
27.68	144.81	-0.212
27.69	144.68	-0.212
27.71	144.55	-0.212
27.72	144.41	-0.212
27.73	144.28	-0.211
27.75	144.15	-0.211
27.76	144.01	-0.211
27.78	143.88	-0.211
27.79	143.75	-0.211
27.80	143.61	-0.211
27.82	143.48	-0.211
27.83	143.35	-0.211
27.84	143.21	-0.211
27.86	143.08	-0.211
27.87	142.95	-0.211
27.88	142.81	-0.211
27.89	142.68	-0.211
27.91	142.55	-0.210
27.92	142.41	-0.210
27.93	142.28	-0.210
27.95	142.15	-0.210
27.96	142.02	-0.210
27.98	141.88	-0.210
27.99	141.75	-0.210
28.00	141.62	-0.210
28.02	141.48	-0.210
28.03	141.35	-0.210
28.04	141.22	-0.210
28.06	141.08	-0.210
28.07	140.95	-0.210
28.08	140.82	-0.209
28.09	140.68	-0.209
28.11	140.55	-0.209
28.12	140.42	-0.209
28.13	140.28	-0.209
28.15	140.15	-0.209
28.16	140.02	-0.209
28.18	139.88	-0.209
28.19	139.75	-0.209
28.20	139.62	-0.209
28.22	139.49	-0.209
28.23	139.35	-0.209
28.24	139.22	-0.209
28.26	139.08	-0.209
28.27	138.95	-0.209
28.28	138.82	-0.209
28.29	138.68	-0.209
28.31	138.55	-0.209
28.32	138.42	-0.209
28.33	138.29	-0.209
28.35	138.15	-0.209
28.36	138.02	-0.209
28.38	137.89	-0.209
28.39	137.75	-0.209
28.40	137.62	-0.208
28.42	137.49	-0.208
28.43	137.35	-0.208
28.44	137.22	-0.208
28.46	137.09	-0.208
28.47	136.95	-0.208
28.48	136.82	-0.208
28.49	136.69	-0.208
28.51	136.55	-0.208
28.52	136.42	-0.208
28.53	136.29	-0.208
28.55	136.15	-0.208
28.56	136.02	-0.208
28.58	135.89	-0.208
28.59	135.75	-0.208
28.60	135.62	-0.208
28.62	135.49	-0.208
28.63	135.35	-0.208
28.64	135.22	-0.208
28.66	135.09	-0.208
28.67	134.95	-0.208
28.68	134.82	-0.208
28.69	134.69	-0.208
28.71	134.55	-0.208
28.72	134.42	-0.208
28.73	134.29	-0.208
28.75	134.16	-0.208
28.76	134.02	-0.208
28.78	133.89	-0.208
28.79	133.76	-0.208
28.80	133.62	-0.207
28.82	133.49	-0.207
28.83	133.36	-0.207
28.84	133.22	-0.207
28.86	133.09	-0.207
28.87	132.96	-0.207
28.88	132.82	-0.207
28.89	132.69	-0.207
28.91	132.56	-0.207
28.92	132.42	-0.207
28.93	132.29	-0.207
28.95	132.16	-0.207
28.96	132.03	-0.207
28.98	131.89	-0.207
28.99	131.76	-0.207
29.00	131.62	-0.207
29.02	131.49	-0.207
29.03	131.36	-0.207
29.04	131.23	-0.207
29.06	131.09	-0.207
29.07	130.96	-0.207
29.08	130.83	-0.207
29.09	130.69	-0.207
29.11	130.56	-0.207
29.12	130.43	-0.207
29.13	130.29	-0.206
29.15	130.16	-0.206
29.16	130.03	-0.207
29.18	129.89	-0.207
29.19	129.76	-0.207
29.20	129.63	-0.206
29.22	129.49	-0.206
29.23	129.36	-0.206
29.24	129.23	-0.206
29.26	129.09	-0.206
29.27	128.96	-0.206
29.28	128.83	-0.206
29.29	128.69	-0.206
29.31	128.56	-0.206
29.32	128.43	-0.206
29.33	128.30	-0.206
29.35	128.16	-0.206
29.36	128.03	-0.206
29.38	127.89	-0.206
29.39	127.76	-0.206
29.40	127.63	-0.206
29.42	127.50	-0.206
29.43	127.36	-0.206
29.44	127.23	-0.206
29.46	127.10	-0.206
29.47	126.96	-0.206
29.48	126.83	-0.206
29.49	126.70	-0.206
29.51	126.56	-0.206
29.52	126.43	-0.206
29.53	126.30	-0.206
29.55	126.16	-0.206
29.56	126.03	-0.206
29.58	125.90	-0.206
29.59	125.76	-0.206
29.60	125.63	-0.206
29.62	125.50	-0.206
29.63	125.36	-0.206
29.64	125.23	-0.206
29.66	125.10	-0.206
29.67	124.96	-0.206
29.68	124.83	-0.205
29.69	124.70	-0.205
29.71	124.56	-0.206
29.72	124.43	-0.205
29.73	124.30	-0.205
29.75	124.17	-0.205
29.76	124.03	-0.205
29.78	123.90	-0.205
29.79	123.76	-0.205
29.80	123.63	-0.205
29.82	123.50	-0.205
29.83	123.36	-0.205
29.84	123.23	-0.205
29.86	123.10	-0.205
29.87	122.97	-0.205
29.88	122.83	-0.205
29.89	122.70	-0.205
29.91	122.57	-0.205
29.92	122.43	-0.205
29.93	122.30	-0.205
29.95	122.17	-0.205
29.96	122.03	-0.205
29.98	121.90	-0.205
29.99	121.77	-0.205
30.00	121.63	-0.204
30.02	121.50	-0.204
30.03	121.37	-0.205
30.04	121.23	-0.204
30.06	121.10	-0.204
30.07	120.97	-0.204
30.08	120.83	-0.205
30.09	120.70	-0.205
30.11	120.57	-0.204
30.12	120.43	-0.204
30.13	120.30	-0.204
30.15	120.17	-0.204
30.16	120.04	-0.204
30.18	119.90	-0.204
30.19	119.77	-0.204
30.20	119.64	-0.204
30.22	119.50	-0.204
30.23	119.37	-0.204
30.24	119.24	-0.204
30.26	119.10	-0.204
30.27	118.97	-0.204
30.28	118.84	-0.204
30.29	118.70	-0.204
30.31	118.57	-0.204
30.32	118.44	-0.204
30.33	118.30	-0.204
30.35	118.17	-0.204
30.36	118.04	-0.204
30.38	117.90	-0.204
30.39	117.77	-0.203
30.40	117.64	-0.203
30.42	117.50	-0.203
30.43	117.37	-0.203
30.44	117.24	-0.203
30.46	117.11	-0.203
30.47	116.97	-0.203
30.48	116.84	-0.203
30.49	116.70	-0.203
30.51	116.57	-0.203
30.52	116.44	-0.203
30.53	116.31	-0.203
30.55	116.17	-0.203
30.56	116.04	-0.203
30.58	115.91	-0.203
30.59	115.77	-0.203
30.60	115.64	-0.203
30.62	115.51	-0.203
30.63	115.37	-0.203
30.64	115.24	-0.203
30.66	115.11	-0.203
30.67	114.97	-0.203
30.68	114.84	-0.203
30.69	114.71	-0.203
30.71	114.57	-0.203
30.72	114.44	-0.203
30.73	114.31	-0.203
30.75	114.17	-0.203
30.76	114.04	-0.203
30.78	113.91	-0.203
30.79	113.77	-0.202
30.80	113.64	-0.202
30.82	113.51	-0.202
30.83	113.38	-0.202
30.84	113.24	-0.202
30.86	113.11	-0.202
30.87	112.97	-0.202
30.88	112.84	-0.202
30.89	112.71	-0.202
30.91	112.57	-0.202
30.92	112.44	-0.202
30.93	112.31	-0.202
30.95	112.18	-0.202
30.96	112.04	-0.202
30.98	111.91	-0.202
30.99	111.78	-0.202
31.00	111.64	-0.202
31.02	111.51	-0.202
31.03	111.38	-0.202
31.04	111.24	-0.202
31.06	111.11	-0.202
31.07	110.98	-0.202
31.08	110.84	-0.202
31.09	110.71	-0.202
31.11	110.58	-0.202
31.12	110.44	-0.202
31.13	110.31	-0.202
31.15	110.18	-0.202
31.16	110.04	-0.202
31.18	109.91	-0.202
31.19	109.78	-0.202
31.20	109.64	-0.202
31.22	109.51	-0.202
31.23	109.38	-0.202
31.24	109.25	-0.202
31.26	109.11	-0.201
31.27	108.98	-0.201
31.28	108.85	-0.201
31.29	108.71	-0.202
31.31	108.58	-0.202
31.32	108.45	-0.201
31.33	108.31	-0.201
31.35	108.18	-0.201
31.36	108.05	-0.201
31.38	107.91	-0.201
31.39	107.78	-0.201
31.40	107.65	-0.201
31.42	107.51	-0.201
31.43	107.38	-0.201
31.44	107.25	-0.201
31.46	107.11	-0.201
31.47	106.98	-0.201
31.48	106.85	-0.201
31.49	106.71	-0.201
31.51	106.58	-0.201
31.52	106.45	-0.201
31.53	106.31	-0.201
31.55	106.18	-0.201
31.56	106.05	-0.201
31.58	105.92	-0.201
31.59	105.78	-0.201
31.60	105.65	-0.201
31.62	105.51	-0.201
31.63	105.38	-0.201
31.64	105.25	-0.201
31.66	105.12	-0.201
31.67	104.98	-0.201
31.68	104.85	-0.201
31.69	104.72	-0.201
31.71	104.58	-0.200
31.72	104.45	-0.200
31.73	104.32	-0.200
31.75	104.18	-0.200
31.76	104.05	-0.200
31.78	103.92	-0.200
31.79	103.78	-0.200
31.80	103.65	-0.200
31.82	103.52	-0.200
31.83	103.38	-0.200
31.84	103.25	-0.200
31.86	103.12	-0.200
31.87	102.98	-0.200
31.88	102.85	-0.200
31.89	102.72	-0.200
31.91	102.58	-0.200
31.92	102.45	-0.200
31.93	102.32	-0.200
31.95	102.18	-0.200
31.96	102.05	-0.200
31.98	101.92	-0.200
31.99	101.79	-0.200
32.00	101.65	-0.200
32.02	101.52	-0.200
32.03	101.38	-0.199
32.04	101.25	-0.199
32.06	101.12	-0.199
32.07	100.99	-0.199
32.08	100.85	-0.199
32.09	100.72	-0.199
32.11	100.59	-0.199
32.12	100.45	-0.199
32.13	100.32	-0.199
32.15	100.19	-0.199
32.16	100.05	-0.199
32.18	99.92	-0.199
32.19	99.79	-0.199
32.20	99.65	-0.199
32.22	99.52	-0.199
32.23	99.39	-0.199
32.24	99.25	-0.199
32.26	99.12	-0.199
32.27	98.99	-0.199
32.28	98.85	-0.199
32.29	98.72	-0.199
32.31	98.59	-0.198
32.32	98.46	-0.199
32.33	98.32	-0.199
32.35	98.19	-0.198
32.36	98.05	-0.198
32.38	97.92	-0.198
32.39	97.79	-0.198
32.40	97.66	-0.198
32.42	97.52	-0.198
32.43	97.39	-0.198
32.44	97.26	-0.198
32.46	97.12	-0.198
32.47	96.99	-0.198
32.48	96.86	-0.198
32.49	96.72	-0.198
32.51	96.59	-0.198
32.52	96.46	-0.198
32.53	96.32	-0.198
32.55	96.19	-0.197
32.56	96.05	-0.198
32.58	95.92	-0.198
32.59	95.79	-0.198
32.60	95.66	-0.198
32.62	95.52	-0.197
32.63	95.39	-0.197
32.64	95.26	-0.197
32.66	95.12	-0.197
32.67	94.99	-0.197
32.68	94.86	-0.197
32.69	94.72	-0.197
32.71	94.59	-0.197
32.72	94.46	-0.197
32.73	94.32	-0.197
32.75	94.19	-0.197
32.76	94.06	-0.197
32.78	93.93	-0.197
32.79	93.79	-0.197
32.80	93.66	-0.197
32.82	93.52	-0.197
32.83	93.39	-0.196
32.84	93.26	-0.196
32.86	93.13	-0.196
32.87	92.99	-0.196
32.88	92.86	-0.196
32.89	92.73	-0.196
32.91	92.59	-0.196
32.92	92.46	-0.196
32.93	92.33	-0.196
32.95	92.19	-0.196
32.96	92.06	-0.196
32.98	91.93	-0.196
32.99	91.79	-0.196
33.00	91.66	-0.196
33.02	91.53	-0.195
33.03	91.39	-0.195
33.04	91.26	-0.195
33.06	91.13	-0.195
33.07	90.99	-0.195
33.08	90.86	-0.195
33.09	90.73	-0.195
33.11	90.59	-0.195
33.12	90.46	-0.195
33.13	90.33	-0.195
33.15	90.19	-0.195
33.16	90.06	-0.195
33.18	89.93	-0.195
33.19	89.80	-0.195
33.20	89.66	-0.195
33.22	89.53	-0.194
33.23	89.40	-0.194
33.24	89.26	-0.194
33.26	89.13	-0.194
33.27	89.00	-0.194
33.28	88.86	-0.194
33.29	88.73	-0.194
33.31	88.60	-0.194
33.32	88.46	-0.194
33.33	88.33	-0.194
33.35	88.20	-0.194
33.36	88.06	-0.194
33.38	87.93	-0.193
33.39	87.80	-0.193
33.40	87.66	-0.193
33.42	87.53	-0.193
33.43	87.40	-0.193
33.44	87.26	-0.193
33.46	87.13	-0.193
33.47	87.00	-0.193
33.48	86.86	-0.193
33.49	86.73	-0.192
33.51	86.60	-0.192
33.52	86.47	-0.192
33.53	86.33	-0.192
33.55	86.20	-0.192
33.56	86.07	-0.192
33.58	85.93	-0.192
33.59	85.80	-0.192
33.60	85.66	-0.192
33.62	85.53	-0.192
33.63	85.40	-0.192
33.64	85.27	-0.192
33.66	85.13	-0.192
33.67	85.00	-0.192
33.68	84.87	-0.192
33.69	84.73	-0.192
33.71	84.60	-0.191
33.72	84.47	-0.191
33.73	84.33	-0.192
33.75	84.20	-0.192
33.76	84.07	-0.192
33.78	83.93	-0.192
33.79	83.80	-0.192
33.80	83.67	-0.192
33.82	83.53	-0.192
33.83	83.40	-0.192
33.84	83.27	-0.192
33.86	83.14	-0.191
33.87	83.00	-0.192
33.88	82.87	-0.192
33.89	82.73	-0.192
33.91	82.60	-0.192
33.92	82.47	-0.192
33.93	82.34	-0.192
33.95	82.20	-0.192
33.96	82.07	-0.192
33.98	81.94	-0.192
33.99	81.80	-0.192
34.00	81.67	-0.192
34.02	81.54	-0.192
34.03	81.40	-0.192
34.04	81.27	-0.192
34.06	81.14	-0.192
34.07	81.00	-0.192
34.08	80.87	-0.192
34.09	80.74	-0.192
34.11	80.60	-0.192
34.12	80.47	-0.192
34.14	80.34	-0.192
34.15	80.20	-0.192
34.16	80.07	-0.192
34.18	79.94	-0.192
34.19	79.80	-0.192
34.20	79.67	-0.192
34.21	79.54	-0.192
34.23	79.40	-0.192
34.24	79.27	-0.192
34.26	79.14	-0.192
34.27	79.00	-0.192
34.28	78.87	-0.192
34.29	78.74	-0.192
34.31	78.61	-0.192
34.32	78.47	-0.192
34.34	78.34	-0.192
34.35	78.21	-0.192
34.36	78.07	-0.192
34.38	77.94	-0.192
34.39	77.81	-0.192
34.40	77.67	-0.192
34.41	77.54	-0.192
34.43	77.41	-0.192
34.44	77.27	-0.192
34.46	77.14	-0.192
34.47	77.01	-0.192
34.48	76.87	-0.192
34.49	76.74	-0.192
34.51	76.61	-0.192
34.52	76.47	-0.192
34.54	76.34	-0.192
34.55	76.21	-0.192
34.56	76.07	-0.192
34.58	75.94	-0.192
34.59	75.81	-0.192
34.60	75.67	-0.191
34.61	75.54	-0.191
34.63	75.41	-0.191
34.64	75.27	-0.191
34.66	75.14	-0.191
34.67	75.01	-0.191
34.68	74.87	-0.191
34.69	74.74	-0.191
34.71	74.61	-0.191
34.72	74.47	-0.191
34.74	74.34	-0.191
34.75	74.21	-0.191
34.76	74.08	-0.191
34.78	73.94	-0.191
34.79	73.81	-0.191
34.80	73.68	-0.191
34.81	73.54	-0.191
34.83	73.41	-0.191
34.84	73.28	-0.190
34.86	73.14	-0.190
34.87	73.01	-0.190
34.88	72.88	-0.190
34.89	72.74	-0.190
34.91	72.61	-0.190
34.92	72.48	-0.190
34.94	72.34	-0.190
34.95	72.21	-0.190
34.96	72.08	-0.190
34.98	71.94	-0.190
34.99	71.81	-0.190
35.00	71.68	-0.190
35.01	71.54	-0.190
35.03	71.41	-0.190
35.04	71.28	-0.190
35.06	71.14	-0.190
35.07	71.01	-0.190
35.08	70.88	-0.190
35.09	70.74	-0.190
35.11	70.61	-0.190
35.12	70.48	-0.190
35.14	70.35	-0.190
35.15	70.21	-0.190
35.16	70.08	-0.189
35.18	69.95	-0.189
35.19	69.81	-0.189
35.20	69.68	-0.189
35.21	69.55	-0.189
35.23	69.41	-0.189
35.24	69.28	-0.189
35.26	69.15	-0.189
35.27	69.01	-0.189
35.28	68.88	-0.189
35.29	68.75	-0.189
35.31	68.61	-0.189
35.32	68.48	-0.189
35.34	68.35	-0.189
35.35	68.21	-0.189
35.36	68.08	-0.189
35.38	67.95	-0.189
35.39	67.81	-0.189
35.40	67.68	-0.189
35.41	67.55	-0.189
35.43	67.41	-0.189
35.44	67.28	-0.189
35.46	67.15	-0.189
35.47	67.02	-0.189
35.48	66.88	-0.189
35.49	66.75	-0.188
35.51	66.61	-0.188
35.52	66.48	-0.188
35.54	66.35	-0.188
35.55	66.21	-0.188
35.56	66.08	-0.188
35.58	65.95	-0.188
35.59	65.82	-0.188
35.60	65.68	-0.188
35.61	65.55	-0.188
35.63	65.42	-0.188
35.64	65.28	-0.188
35.66	65.15	-0.188
35.67	65.02	-0.188
35.68	64.88	-0.188
35.69	64.75	-0.188
35.71	64.62	-0.188
35.72	64.48	-0.188
35.74	64.35	-0.188
35.75	64.22	-0.188
35.76	64.08	-0.188
35.78	63.95	-0.188
35.79	63.82	-0.188
35.80	63.68	-0.188
35.81	63.55	-0.188
35.83	63.42	-0.187
35.84	63.28	-0.187
35.86	63.15	-0.187
35.87	63.02	-0.187
35.88	62.89	-0.187
35.89	62.75	-0.187
35.91	62.62	-0.187
35.92	62.49	-0.187
35.94	62.35	-0.187
35.95	62.22	-0.187
35.96	62.09	-0.187
35.98	61.95	-0.187
35.99	61.82	-0.187
36.00	61.69	-0.187
36.01	61.55	-0.187
36.03	61.42	-0.187
36.04	61.29	-0.187
36.06	61.15	-0.187
36.07	61.02	-0.187
36.08	60.89	-0.187
36.09	60.75	-0.187
36.11	60.62	-0.187
36.12	60.49	-0.187
36.14	60.35	-0.186
36.15	60.22	-0.186
36.16	60.09	-0.186
36.18	59.95	-0.186
36.19	59.82	-0.186
36.20	59.69	-0.186
36.21	59.55	-0.186
36.23	59.42	-0.186
36.24	59.29	-0.186
36.26	59.15	-0.186
36.27	59.02	-0.186
36.28	58.89	-0.186
36.29	58.76	-0.186
36.31	58.62	-0.186
36.32	58.49	-0.186
36.34	58.36	-0.186
36.35	58.22	-0.186
36.36	58.09	-0.186
36.38	57.96	-0.186
36.39	57.82	-0.186
36.40	57.69	-0.185
36.41	57.56	-0.186
36.43	57.42	-0.186
36.44	57.29	-0.186
36.46	57.16	-0.185
36.47	57.02	-0.185
36.48	56.89	-0.185
36.49	56.76	-0.185
36.51	56.62	-0.185
36.52	56.49	-0.185
36.54	56.36	-0.185
36.55	56.22	-0.185
36.56	56.09	-0.185
36.58	55.96	-0.185
36.59	55.82	-0.185
36.60	55.69	-0.185
36.61	55.56	-0.185
36.63	55.42	-0.185
36.64	55.29	-0.185
36.66	55.16	-0.185
36.67	55.02	-0.185
36.68	54.89	-0.185
36.69	54.76	-0.185
36.71	54.62	-0.185
36.72	54.49	-0.185
36.74	54.36	-0.185
36.75	54.23	-0.185
36.76	54.09	-0.184
36.78	53.96	-0.184
36.79	53.83	-0.184
36.80	53.69	-0.185
36.81	53.56	-0.184
36.83	53.43	-0.184
36.84	53.29	-0.184
36.86	53.16	-0.184
36.87	53.03	-0.184
36.88	52.89	-0.184
36.89	52.76	-0.184
36.91	52.63	-0.184
36.92	52.49	-0.184
36.94	52.36	-0.184
36.95	52.23	-0.184
36.96	52.09	-0.184
36.98	51.96	-0.184
36.99	51.83	-0.184
37.00	51.69	-0.184
37.01	51.56	-0.184
37.03	51.43	-0.184
37.04	51.29	-0.183
37.06	51.16	-0.183
37.07	51.03	-0.183
37.08	50.90	-0.183
37.09	50.76	-0.183
37.11	50.63	-0.183
37.12	50.50	-0.183
37.14	50.36	-0.183
37.15	50.23	-0.183
37.16	50.10	-0.183
37.18	49.96	-0.183
37.19	49.83	-0.183
37.20	49.70	-0.183
37.21	49.56	-0.183
37.23	49.43	-0.182
37.24	49.30	-0.182
37.26	49.16	-0.182
37.27	49.03	-0.182
37.28	48.90	-0.182
37.29	48.76	-0.182
37.31	48.63	-0.182
37.32	48.50	-0.182
37.34	48.36	-0.182
37.35	48.23	-0.182
37.36	48.10	-0.182
37.38	47.96	-0.182
37.39	47.83	-0.182
37.40	47.70	-0.182
37.41	47.57	-0.182
37.43	47.43	-0.182
37.44	47.30	-0.182
37.46	47.16	-0.182
37.47	47.03	-0.182
37.48	46.90	-0.182
37.49	46.77	-0.182
37.51	46.63	-0.182
37.52	46.50	-0.182
37.54	46.37	-0.182
37.55	46.23	-0.182
37.56	46.10	-0.181
37.58	45.96	-0.181
37.59	45.83	-0.181
37.60	45.70	-0.181
37.61	45.57	-0.181
37.63	45.43	-0.181
37.64	45.30	-0.181
37.66	45.17	-0.181
37.67	45.03	-0.181
37.68	44.90	-0.181
37.69	44.77	-0.181
37.71	44.63	-0.181
37.72	44.50	-0.181
37.74	44.37	-0.181
37.75	44.23	-0.181
37.76	44.10	-0.181
37.78	43.97	-0.181
37.79	43.84	-0.180
37.80	43.70	-0.181
37.81	43.57	-0.181
37.83	43.44	-0.181
37.84	43.30	-0.180
37.86	43.17	-0.180
37.87	43.04	-0.180
37.88	42.90	-0.180
37.89	42.77	-0.180
37.91	42.63	-0.180
37.92	42.50	-0.180
37.94	42.37	-0.180
37.95	42.24	-0.180
37.96	42.10	-0.180
37.98	41.97	-0.180
37.99	41.84	-0.180
38.00	41.70	-0.180
38.01	41.57	-0.180
38.03	41.44	-0.180
38.04	41.30	-0.179
38.06	41.17	-0.179
38.07	41.04	-0.179
38.08	40.90	-0.179
38.09	40.77	-0.179
38.11	40.64	-0.179
38.12	40.50	-0.179
38.14	40.37	-0.179
38.15	40.24	-0.179
38.16	40.11	-0.179
38.18	39.97	-0.179
38.19	39.84	-0.179
38.20	39.71	-0.179
38.21	39.57	-0.179
38.23	39.44	-0.179
38.24	39.31	-0.179
38.26	39.17	-0.179
38.27	39.04	-0.178
38.28	38.91	-0.178
38.29	38.77	-0.178
38.31	38.64	-0.178
38.32	38.51	-0.178
38.34	38.37	-0.178
38.35	38.24	-0.178
38.36	38.11	-0.178
38.38	37.97	-0.178
38.39	37.84	-0.178
38.40	37.71	-0.178
38.41	37.57	-0.178
38.43	37.44	-0.178
38.44	37.31	-0.178
38.46	37.18	-0.178
38.47	37.04	-0.178
38.48	36.91	-0.178
38.49	36.78	-0.178
38.51	36.64	-0.178
38.52	36.51	-0.178
38.54	36.38	-0.178
38.55	36.24	-0.178
38.56	36.11	-0.178
38.58	35.97	-0.178
38.59	35.84	-0.178
38.60	35.71	-0.178
38.61	35.57	-0.178
38.63	35.44	-0.177
38.64	35.31	-0.177
38.66	35.18	-0.177
38.67	35.04	-0.177
38.68	34.91	-0.177
38.69	34.78	-0.177
38.71	34.64	-0.177
38.72	34.51	-0.177
38.74	34.38	-0.177
38.75	34.25	-0.177
38.76	34.11	-0.177
38.78	33.98	-0.177
38.79	33.84	-0.177
38.80	33.71	-0.177
38.81	33.58	-0.177
38.83	33.44	-0.177
38.84	33.31	-0.177
38.86	33.18	-0.177
38.87	33.04	-0.176
38.88	32.91	-0.176
38.89	32.78	-0.176
38.91	32.64	-0.176
38.92	32.51	-0.176
38.94	32.38	-0.176
38.95	32.24
38.96	32.11
38.98	31.98
38.99	31.84
39.00