File: Data/2024_09_17_Sucrose_DSC.txt
Filename	2024_09_17_Sucrose_DSC
Instrument name	DSC2A-00468 (192.168.1.100)
Operator	CHM343
rundate	9/17/2024
Sample name	2024_09_17_Sucrose_DSC
proceduresegments	Equilibrate 30.00 °C; Ramp 10.00 °C/min to 210.00 °C; Isothermal 1.0 min; Ramp 10.00 °C/min to 30.00 °C; Isothermal 1.0 min; Ramp 10.00 °C/min to 210.00 °C
[File Parameters]
Run date	9/17/2024 11:42:08 PM
Trios version	5.1.1.46572
Original File Name
Current File Name	C:\ProgramData\TA Instruments\TRIOS\Data\2024_09_17_Sucrose_DSC.tri
[Procedure]
Procedure Name	CHM343_Fall2024_Sucrose
Sample Name	2024_09_17_Sucrose_DSC
Sample Mass	3.13 mg
Reference Sample Mass	0 mg
Pan Mass	53.68 mg
Pan Number	23
Reference Pan Mass	54 mg
Reference Pan Number	19
Pan Type	Aluminum
Comments	Sucrose - Al Hermetic Sealed Pan, with ref Al pan.  ASU Online CHM343, Remote DSC experimental lab. Fall 2024.  Group Zoom Data Collection, Sept 17, 2024 from 9-11 pm.  TA Instruments DSC2500.
Project Name	Lab 4 - Fall 2024
Operator	CHM343
Test	Custom
Unload Max Temperature	30
Unload Min Temperature	30
Load Max Temperature	30
Load Min Temperature	30
Stop on Gas Flow Error	Yes
[Signal List]
Signal #1	Time (min)
Signal #2	Temperature (°C)
Signal #3	Heat Flow (mW)
Signal #4	Delta T (µV)
Signal #5	Delta Tzero (µV)
Signal #6	Tzero Temperature (°C)
Signal #7	Cell Purge (mL/min)
Signal #8	Heater Temp (°C)
Signal #9	Power Delivered (W)
Signal #10	Reference Junction Temperature (°C)
Signal #11	Flange Temperature (°C)
Signal #12	Heat Flow Phase (rad)
Signal #13	Total Heat Capacity (J/°C)
Signal #14	Heat Capacity (J/°C)
[Configuration]
Company Name	ASU
Instrument Name	DSC2A-00468
Instrument Type	DSC2500
Serial Number	DSC2A-00468
IP	192.168.1.100
Location of Instrument	MRRC
DisplayType	Unknown
Sample Interval 	0.1 s/pt
Selected Heat Flow	T4P
Exotherm Direction	Down
Cell Serial	DRC2-00792
Lid Type	Standard
Cooler	RCS 90
Leave Cooler on at End of Sequence	On
Gas 2	Nitrogen
Gas Selected	Channel 1
Flow Rate	50 mL/min
Secondary Purge	On
Licensed Heat Flow	Heat Flow T4P
Modulation Licensed	Yes
[Versions]
Common IDD Version	1
Cortex Version	VER 2.10.2.31
Driver	5.0.0.6
GDM Version	1.0.3.3
TouchscreenVersion	1.0.0.16145
FEP Version	1.2.1.21
FEP Bootloader	2.0.0.5
AutoSampler Version	2.1.1.26
Auto Sampler Bootloader	2.0.0.5
FCM Version	1.1.0.3
FCM Bootloader	2.0.0.5
[Experiment Logs]
Experiment Log Entry # 1	Air Cool is off.
Experiment Log Entry # 3	Equilibrate Segment 30 (C) Started
Experiment Log Entry # 5	Ramp Segment 10 C/min to 210 Started
Experiment Log Entry # 7	Isothermal Segment 1 min started
Experiment Log Entry # 9	Ramp Segment 10 C/min to 30 Started
Experiment Log Entry # 11	Isothermal Segment 1 min started
Experiment Log Entry # 13	Ramp Segment 10 C/min to 210 Started
[Method Log]
Method Log Entry # 1	Equilibrate 30 °C
Method Log Entry # 2	(Ramp 90416) Ramp 10 °C/minute to 210 °C
Method Log Entry # 3	Isothermal 1 minutes
Method Log Entry # 4	(Ramp 90418) Ramp 10 °C/minute to 30 °C
Method Log Entry # 5	Isothermal 1 minutes
Method Log Entry # 6	(Ramp 90420) Ramp 10 °C/minute to 210 °C
Cell Serial	DRC2-00792
[T1 Calibration]
Slope	-0.008529666
Offset	9.636258
Initial Temperature	98.23
GUID	f8bfdadc-4977-4fdf-ba6d-0ba9134940c3
[TZero Calibration]
Date Applied	11/29/2022 4:06:13 PM
Description	From -89.059 °C to 396.009 °C at 20.000°C/min
Gas Type	Nitrogen
Pan Type	None
Source Files 1	C:\Users\yargerlab\Desktop\DSC Data\General\TZero_calibration_11_29_22_2nd(2).tri
Source Files 2	C:\Users\yargerlab\Desktop\DSC Data\General\TZero_calibration_11_29_22_2nd(3).tri
Delta T Offset	13.05235
Delta T Slope	-0.007271007
Delta T0 Offset	-13.69128
Delta T0 Slope	0.06063341
[Temperature Calibration]
Date Applied	11/29/2022 7:12:28 PM
Description	From 106.590 °C to 186.590 °C at 10.000°C/min
Gas Type	Nitrogen
Pan Type	Tzero Aluminum Hermetic
Source Files 1	C:\Users\yargerlab\Desktop\DSC Data\General\Indium(6).tri
Measured 1	157.391
Known 1	156.598
[Cell Constant Calibration]
Date Applied	11/29/2022 7:12:29 PM
Description	From 106.590 °C to 186.590 °C at 10.000°C/min
Gas Type	Nitrogen
Pan Type	Tzero Aluminum Hermetic
Source Files 1	C:\Users\yargerlab\Desktop\DSC Data\General\Indium(6).tri
T4P KCell	1.006051
Onset Slope	63.26126 mW/°C
[Direct Cp Calibration]
Date Applied	11/30/2022 11:04:51 AM
Description	From -79.983 °C to 298.409 °C at 10.000°C/min
Gas Type	Nitrogen
Pan Type	Tzero Aluminum Hermetic
Source Files 1	C:\Users\yargerlab\Desktop\DSC Data\General\Sapphire_Heat_Capacity_11_30_22.tri
[Rev Cp Calibration]
Date Applied	11/30/2022 1:58:51 PM
Description	From -79.996 °C to 292.812 °C at 3.000°C/min
Gas Type	Nitrogen
Pan Type	Tzero Aluminum Hermetic
Source Files 1	C:\Users\yargerlab\Desktop\DSC Data\General\Sapphire_MDSC_Calibration_11_30_22.tri
[step]
Ramp 10.00 °C/min to 210.00 °C
Time	Temperature	Heat Flow (Normalized)
min	°C	W/g
0.00	30.07	-0.047
0.01	30.07	-0.046
0.03	30.07	-0.045
0.04	30.08	-0.043
0.05	30.09	-0.043
0.07	30.10	-0.043
0.08	30.13	-0.043
0.09	30.17	-0.046
0.11	30.22	-0.046
0.12	30.28	-0.038
0.13	30.35	-0.004
0.15	30.44	0.027
0.16	30.52	0.063
0.17	30.62	0.099
0.19	30.72	0.134
0.20	30.82	0.167
0.21	30.93	0.192
0.23	31.03	0.218
0.24	31.14	0.237
0.25	31.26	0.256
0.27	31.37	0.274
0.28	31.49	0.287
0.29	31.61	0.303
0.31	31.73	0.315
0.32	31.85	0.329
0.33	31.98	0.337
0.35	32.10	0.349
0.36	32.23	0.357
0.37	32.35	0.365
0.39	32.48	0.372
0.40	32.61	0.378
0.41	32.74	0.385
0.43	32.86	0.389
0.44	32.99	0.394
0.45	33.12	0.398
0.47	33.25	0.403
0.48	33.38	0.407
0.49	33.51	0.410
0.51	33.64	0.412
0.52	33.77	0.414
0.53	33.90	0.417
0.55	34.03	0.420
0.56	34.16	0.421
0.57	34.29	0.423
0.59	34.42	0.425
0.60	34.55	0.426
0.61	34.68	0.428
0.63	34.82	0.428
0.64	34.95	0.430
0.65	35.08	0.431
0.67	35.21	0.432
0.68	35.34	0.433
0.69	35.47	0.434
0.71	35.61	0.435
0.72	35.74	0.435
0.73	35.87	0.436
0.75	36.00	0.437
0.76	36.13	0.438
0.77	36.27	0.439
0.79	36.40	0.440
0.80	36.53	0.440
0.81	36.66	0.441
0.83	36.80	0.442
0.84	36.93	0.442
0.85	37.06	0.443
0.87	37.19	0.444
0.88	37.33	0.444
0.89	37.46	0.445
0.91	37.59	0.445
0.92	37.72	0.446
0.93	37.85	0.446
0.95	37.99	0.447
0.96	38.12	0.447
0.97	38.25	0.448
0.99	38.38	0.448
1.00	38.52	0.449
1.01	38.65	0.449
1.03	38.78	0.450
1.04	38.92	0.450
1.05	39.05	0.451
1.07	39.18	0.451
1.08	39.31	0.452
1.09	39.44	0.452
1.11	39.58	0.453
1.12	39.71	0.453
1.13	39.84	0.454
1.15	39.98	0.454
1.16	40.11	0.455
1.17	40.24	0.455
1.19	40.38	0.456
1.20	40.51	0.456
1.21	40.64	0.456
1.23	40.77	0.457
1.24	40.91	0.457
1.25	41.04	0.458
1.27	41.17	0.458
1.28	41.31	0.458
1.29	41.44	0.459
1.31	41.57	0.459
1.32	41.71	0.459
1.33	41.84	0.460
1.35	41.97	0.460
1.36	42.11	0.460
1.37	42.24	0.461
1.39	42.37	0.461
1.40	42.50	0.461
1.41	42.64	0.462
1.43	42.77	0.462
1.44	42.91	0.463
1.45	43.04	0.463
1.47	43.17	0.463
1.48	43.31	0.463
1.49	43.44	0.464
1.51	43.57	0.464
1.52	43.70	0.464
1.53	43.84	0.465
1.55	43.97	0.465
1.56	44.10	0.465
1.57	44.24	0.466
1.59	44.37	0.466
1.60	44.50	0.466
1.61	44.64	0.466
1.63	44.77	0.466
1.64	44.90	0.467
1.65	45.04	0.467
1.67	45.17	0.467
1.68	45.30	0.468
1.69	45.44	0.468
1.71	45.57	0.468
1.72	45.70	0.468
1.73	45.84	0.469
1.75	45.97	0.469
1.76	46.10	0.469
1.77	46.24	0.469
1.79	46.37	0.470
1.80	46.50	0.470
1.81	46.64	0.470
1.83	46.77	0.470
1.84	46.90	0.470
1.85	47.04	0.471
1.87	47.17	0.471
1.88	47.30	0.471
1.89	47.44	0.471
1.91	47.57	0.472
1.92	47.70	0.472
1.93	47.84	0.472
1.95	47.97	0.472
1.96	48.10	0.473
1.97	48.23	0.473
1.99	48.37	0.473
2.00	48.50	0.473
2.01	48.64	0.474
2.03	48.77	0.474
2.04	48.90	0.474
2.05	49.03	0.474
2.07	49.17	0.474
2.08	49.30	0.475
2.09	49.44	0.475
2.11	49.57	0.475
2.12	49.70	0.475
2.13	49.84	0.475
2.15	49.97	0.476
2.16	50.10	0.476
2.17	50.24	0.476
2.19	50.37	0.476
2.20	50.50	0.476
2.21	50.64	0.476
2.23	50.77	0.477
2.24	50.90	0.477
2.25	51.04	0.477
2.27	51.17	0.477
2.28	51.30	0.477
2.29	51.44	0.478
2.31	51.57	0.478
2.32	51.70	0.478
2.33	51.84	0.478
2.35	51.97	0.479
2.36	52.10	0.479
2.37	52.24	0.479
2.39	52.37	0.479
2.40	52.50	0.479
2.41	52.64	0.479
2.43	52.77	0.480
2.44	52.90	0.480
2.45	53.04	0.480
2.47	53.17	0.480
2.48	53.30	0.480
2.49	53.44	0.480
2.51	53.57	0.481
2.52	53.71	0.481
2.53	53.84	0.481
2.55	53.97	0.481
2.56	54.11	0.481
2.57	54.24	0.481
2.59	54.37	0.482
2.60	54.51	0.482
2.61	54.64	0.482
2.63	54.77	0.482
2.64	54.90	0.483
2.65	55.04	0.483
2.67	55.17	0.483
2.68	55.31	0.483
2.69	55.44	0.483
2.71	55.57	0.484
2.72	55.71	0.484
2.73	55.84	0.484
2.75	55.97	0.484
2.76	56.11	0.484
2.77	56.24	0.485
2.79	56.37	0.485
2.80	56.50	0.485
2.81	56.64	0.485
2.83	56.77	0.485
2.84	56.91	0.486
2.85	57.04	0.486
2.87	57.17	0.486
2.88	57.31	0.486
2.89	57.44	0.486
2.91	57.57	0.487
2.92	57.71	0.487
2.93	57.84	0.487
2.95	57.97	0.487
2.96	58.11	0.487
2.97	58.24	0.488
2.99	58.37	0.488
3.00	58.51	0.488
3.01	58.64	0.488
3.03	58.77	0.488
3.04	58.91	0.488
3.05	59.04	0.489
3.07	59.17	0.489
3.08	59.31	0.489
3.09	59.44	0.489
3.11	59.57	0.490
3.12	59.71	0.490
3.13	59.84	0.490
3.15	59.98	0.490
3.16	60.11	0.490
3.17	60.24	0.491
3.19	60.38	0.491
3.20	60.51	0.491
3.21	60.64	0.491
3.23	60.78	0.492
3.24	60.91	0.492
3.25	61.04	0.492
3.27	61.18	0.492
3.28	61.31	0.492
3.29	61.44	0.492
3.31	61.58	0.493
3.32	61.71	0.493
3.33	61.84	0.493
3.35	61.98	0.493
3.36	62.11	0.494
3.37	62.24	0.494
3.39	62.38	0.494
3.40	62.51	0.494
3.41	62.64	0.494
3.43	62.78	0.495
3.44	62.91	0.495
3.45	63.04	0.495
3.47	63.18	0.495
3.48	63.31	0.495
3.49	63.44	0.496
3.51	63.58	0.496
3.52	63.71	0.496
3.53	63.84	0.496
3.55	63.98	0.497
3.56	64.11	0.497
3.57	64.24	0.497
3.59	64.38	0.497
3.60	64.51	0.497
3.61	64.64	0.497
3.63	64.78	0.498
3.64	64.91	0.498
3.65	65.04	0.498
3.67	65.18	0.498
3.68	65.31	0.499
3.69	65.45	0.499
3.71	65.58	0.499
3.72	65.71	0.499
3.73	65.84	0.499
3.75	65.98	0.500
3.76	66.11	0.500
3.77	66.25	0.500
3.79	66.38	0.500
3.80	66.51	0.501
3.81	66.65	0.501
3.83	66.78	0.501
3.84	66.91	0.501
3.85	67.05	0.501
3.87	67.18	0.502
3.88	67.31	0.502
3.89	67.45	0.502
3.91	67.58	0.503
3.92	67.71	0.503
3.93	67.85	0.503
3.95	67.98	0.503
3.96	68.11	0.503
3.97	68.25	0.503
3.99	68.38	0.504
4.00	68.51	0.504
4.01	68.65	0.504
4.03	68.78	0.504
4.04	68.91	0.505
4.05	69.05	0.505
4.07	69.18	0.505
4.08	69.31	0.505
4.09	69.45	0.505
4.11	69.58	0.506
4.12	69.71	0.506
4.13	69.85	0.506
4.15	69.98	0.506
4.16	70.11	0.506
4.17	70.25	0.507
4.19	70.38	0.507
4.20	70.51	0.507
4.21	70.65	0.507
4.23	70.78	0.507
4.24	70.92	0.508
4.25	71.05	0.508
4.27	71.18	0.508
4.28	71.32	0.508
4.29	71.45	0.509
4.31	71.58	0.509
4.32	71.72	0.509
4.33	71.85	0.509
4.35	71.98	0.509
4.36	72.12	0.510
4.37	72.25	0.510
4.39	72.38	0.510
4.40	72.52	0.510
4.41	72.65	0.511
4.43	72.78	0.511
4.44	72.92	0.511
4.45	73.05	0.511
4.47	73.18	0.511
4.48	73.32	0.512
4.49	73.45	0.512
4.51	73.58	0.512
4.52	73.72	0.512
4.53	73.85	0.512
4.55	73.98	0.513
4.56	74.12	0.513
4.57	74.25	0.513
4.59	74.38	0.513
4.60	74.52	0.514
4.61	74.65	0.514
4.63	74.78	0.514
4.64	74.92	0.514
4.65	75.05	0.514
4.67	75.18	0.514
4.68	75.32	0.515
4.69	75.45	0.515
4.71	75.58	0.515
4.72	75.72	0.515
4.73	75.85	0.516
4.75	75.98	0.516
4.76	76.12	0.516
4.77	76.25	0.516
4.79	76.38	0.516
4.80	76.52	0.517
4.81	76.65	0.517
4.83	76.78	0.517
4.84	76.92	0.517
4.85	77.05	0.517
4.87	77.19	0.518
4.88	77.32	0.518
4.89	77.45	0.518
4.91	77.59	0.518
4.92	77.72	0.518
4.93	77.85	0.519
4.95	77.99	0.519
4.96	78.12	0.519
4.97	78.25	0.519
4.99	78.39	0.520
5.00	78.52	0.520
5.01	78.65	0.520
5.03	78.79	0.520
5.04	78.92	0.520
5.05	79.05	0.520
5.07	79.19	0.521
5.08	79.32	0.521
5.09	79.45	0.521
5.11	79.59	0.521
5.12	79.72	0.521
5.13	79.85	0.522
5.15	79.99	0.522
5.16	80.12	0.522
5.17	80.25	0.522
5.19	80.39	0.522
5.20	80.52	0.523
5.21	80.65	0.523
5.23	80.79	0.523
5.24	80.92	0.523
5.25	81.06	0.523
5.27	81.19	0.524
5.28	81.32	0.524
5.29	81.45	0.524
5.31	81.59	0.524
5.32	81.72	0.524
5.33	81.86	0.525
5.35	81.99	0.525
5.36	82.12	0.525
5.37	82.26	0.525
5.39	82.39	0.525
5.40	82.52	0.525
5.41	82.66	0.526
5.43	82.79	0.526
5.44	82.92	0.526
5.45	83.06	0.526
5.47	83.19	0.526
5.48	83.32	0.526
5.49	83.46	0.526
5.51	83.59	0.527
5.52	83.72	0.527
5.53	83.86	0.527
5.55	83.99	0.527
5.56	84.12	0.527
5.57	84.26	0.527
5.59	84.39	0.528
5.60	84.52	0.528
5.61	84.66	0.528
5.63	84.79	0.528
5.64	84.92	0.528
5.65	85.06	0.528
5.67	85.19	0.529
5.68	85.32	0.529
5.69	85.46	0.529
5.71	85.59	0.529
5.72	85.73	0.529
5.73	85.86	0.530
5.75	85.99	0.530
5.76	86.13	0.530
5.77	86.26	0.530
5.79	86.39	0.530
5.80	86.52	0.530
5.81	86.66	0.531
5.83	86.79	0.531
5.84	86.93	0.531
5.85	87.06	0.531
5.87	87.19	0.531
5.88	87.32	0.531
5.89	87.46	0.532
5.91	87.59	0.532
5.92	87.73	0.532
5.93	87.86	0.532
5.95	87.99	0.532
5.96	88.13	0.533
5.97	88.26	0.533
5.99	88.39	0.533
6.00	88.53	0.533
6.01	88.66	0.533
6.03	88.79	0.534
6.04	88.93	0.534
6.05	89.06	0.534
6.07	89.19	0.534
6.08	89.33	0.534
6.09	89.46	0.535
6.11	89.59	0.535
6.12	89.73	0.535
6.13	89.86	0.535
6.15	89.99	0.535
6.16	90.13	0.536
6.17	90.26	0.536
6.19	90.39	0.536
6.20	90.53	0.536
6.21	90.66	0.536
6.23	90.79	0.537
6.24	90.93	0.537
6.25	91.06	0.537
6.27	91.19	0.537
6.28	91.33	0.538
6.29	91.46	0.538
6.31	91.59	0.538
6.32	91.73	0.538
6.33	91.86	0.539
6.35	91.99	0.539
6.36	92.13	0.539
6.37	92.26	0.539
6.39	92.39	0.539
6.40	92.53	0.540
6.41	92.66	0.540
6.43	92.79	0.540
6.44	92.93	0.540
6.45	93.06	0.541
6.47	93.20	0.541
6.48	93.33	0.541
6.49	93.46	0.541
6.51	93.60	0.541
6.52	93.73	0.542
6.53	93.86	0.542
6.55	94.00	0.542
6.56	94.13	0.542
6.57	94.26	0.543
6.59	94.40	0.543
6.60	94.53	0.543
6.61	94.66	0.543
6.63	94.80	0.543
6.64	94.93	0.544
6.65	95.06	0.544
6.67	95.20	0.544
6.68	95.33	0.544
6.69	95.46	0.544
6.71	95.60	0.545
6.72	95.73	0.545
6.73	95.86	0.545
6.75	96.00	0.545
6.76	96.13	0.546
6.77	96.26	0.546
6.79	96.40	0.546
6.80	96.53	0.546
6.81	96.66	0.547
6.83	96.80	0.547
6.84	96.93	0.547
6.85	97.06	0.547
6.87	97.20	0.547
6.88	97.33	0.548
6.89	97.46	0.548
6.91	97.60	0.548
6.92	97.73	0.548
6.93	97.86	0.549
6.95	98.00	0.549
6.96	98.13	0.549
6.97	98.26	0.549
6.99	98.40	0.549
7.00	98.53	0.550
7.01	98.66	0.550
7.03	98.80	0.550
7.04	98.93	0.550
7.05	99.06	0.551
7.07	99.20	0.551
7.08	99.33	0.551
7.09	99.46	0.551
7.11	99.60	0.551
7.12	99.73	0.552
7.13	99.87	0.552
7.15	100.00	0.552
7.16	100.13	0.552
7.17	100.27	0.553
7.19	100.40	0.553
7.20	100.53	0.553
7.21	100.67	0.553
7.23	100.80	0.554
7.24	100.93	0.554
7.25	101.06	0.554
7.27	101.20	0.554
7.28	101.33	0.554
7.29	101.47	0.555
7.31	101.60	0.555
7.32	101.73	0.555
7.33	101.87	0.555
7.35	102.00	0.555
7.36	102.13	0.556
7.37	102.27	0.556
7.39	102.40	0.556
7.40	102.53	0.556
7.41	102.67	0.557
7.43	102.80	0.557
7.44	102.93	0.557
7.45	103.07	0.557
7.47	103.20	0.557
7.48	103.33	0.558
7.49	103.47	0.558
7.51	103.60	0.558
7.52	103.73	0.558
7.53	103.87	0.559
7.55	104.00	0.559
7.56	104.13	0.559
7.57	104.27	0.559
7.59	104.40	0.559
7.60	104.53	0.560
7.61	104.67	0.560
7.63	104.80	0.560
7.64	104.94	0.560
7.65	105.07	0.561
7.67	105.20	0.561
7.68	105.34	0.561
7.69	105.47	0.561
7.71	105.60	0.561
7.72	105.74	0.562
7.73	105.87	0.562
7.75	106.00	0.562
7.76	106.14	0.562
7.77	106.27	0.562
7.79	106.40	0.563
7.80	106.54	0.563
7.81	106.67	0.563
7.83	106.80	0.563
7.84	106.94	0.563
7.85	107.07	0.563
7.87	107.20	0.564
7.88	107.34	0.564
7.89	107.47	0.564
7.91	107.60	0.564
7.92	107.74	0.564
7.93	107.87	0.565
7.95	108.00	0.565
7.96	108.14	0.565
7.97	108.27	0.565
7.99	108.40	0.565
8.00	108.54	0.566
8.01	108.67	0.566
8.03	108.80	0.566
8.04	108.94	0.566
8.05	109.07	0.566
8.07	109.20	0.567
8.08	109.34	0.567
8.09	109.47	0.567
8.11	109.60	0.567
8.12	109.74	0.567
8.13	109.87	0.568
8.15	110.00	0.568
8.16	110.14	0.568
8.17	110.27	0.568
8.19	110.40	0.568
8.20	110.54	0.569
8.21	110.67	0.569
8.23	110.80	0.569
8.24	110.94	0.569
8.25	111.07	0.569
8.27	111.20	0.570
8.28	111.34	0.570
8.29	111.47	0.570
8.31	111.60	0.570
8.32	111.74	0.570
8.33	111.87	0.571
8.35	112.01	0.571
8.36	112.14	0.571
8.37	112.27	0.571
8.39	112.40	0.572
8.40	112.54	0.572
8.41	112.67	0.572
8.43	112.80	0.572
8.44	112.94	0.572
8.45	113.07	0.573
8.47	113.20	0.573
8.48	113.34	0.573
8.49	113.47	0.573
8.51	113.60	0.573
8.52	113.74	0.574
8.53	113.87	0.574
8.55	114.01	0.574
8.56	114.14	0.574
8.57	114.27	0.574
8.59	114.41	0.575
8.60	114.54	0.575
8.61	114.67	0.575
8.63	114.81	0.575
8.64	114.94	0.576
8.65	115.07	0.576
8.67	115.21	0.576
8.68	115.34	0.576
8.69	115.47	0.576
8.71	115.61	0.577
8.72	115.74	0.577
8.73	115.87	0.577
8.75	116.01	0.577
8.76	116.14	0.577
8.77	116.27	0.578
8.79	116.41	0.578
8.80	116.54	0.578
8.81	116.68	0.578
8.83	116.81	0.579
8.84	116.94	0.579
8.85	117.07	0.579
8.87	117.21	0.579
8.88	117.34	0.579
8.89	117.47	0.580
8.91	117.61	0.580
8.92	117.74	0.580
8.93	117.87	0.580
8.95	118.01	0.580
8.96	118.14	0.581
8.97	118.27	0.581
8.99	118.41	0.581
9.00	118.54	0.581
9.01	118.67	0.581
9.03	118.81	0.581
9.04	118.94	0.582
9.05	119.07	0.582
9.07	119.21	0.582
9.08	119.34	0.582
9.09	119.47	0.582
9.11	119.61	0.583
9.12	119.74	0.583
9.13	119.88	0.583
9.15	120.01	0.583
9.16	120.14	0.583
9.17	120.28	0.584
9.19	120.41	0.584
9.20	120.54	0.584
9.21	120.68	0.584
9.23	120.81	0.584
9.24	120.94	0.585
9.25	121.07	0.585
9.27	121.21	0.585
9.28	121.34	0.585
9.29	121.48	0.585
9.31	121.61	0.586
9.32	121.74	0.586
9.33	121.88	0.586
9.35	122.01	0.586
9.36	122.14	0.587
9.37	122.28	0.587
9.39	122.41	0.587
9.40	122.54	0.587
9.41	122.68	0.587
9.43	122.81	0.588
9.44	122.94	0.588
9.45	123.08	0.588
9.47	123.21	0.588
9.48	123.34	0.588
9.49	123.48	0.589
9.51	123.61	0.589
9.52	123.74	0.589
9.53	123.88	0.589
9.55	124.01	0.590
9.56	124.14	0.590
9.57	124.28	0.590
9.59	124.41	0.590
9.60	124.54	0.590
9.61	124.68	0.590
9.63	124.81	0.591
9.64	124.94	0.591
9.65	125.08	0.591
9.67	125.21	0.591
9.68	125.34	0.591
9.69	125.48	0.592
9.71	125.61	0.592
9.72	125.74	0.592
9.73	125.88	0.592
9.75	126.01	0.592
9.76	126.14	0.593
9.77	126.28	0.593
9.79	126.41	0.593
9.80	126.54	0.593
9.81	126.68	0.593
9.83	126.81	0.594
9.84	126.94	0.594
9.85	127.08	0.594
9.87	127.21	0.594
9.88	127.35	0.594
9.89	127.48	0.594
9.91	127.61	0.595
9.92	127.74	0.595
9.93	127.88	0.595
9.95	128.01	0.595
9.96	128.15	0.595
9.97	128.28	0.596
9.99	128.41	0.596
10.00	128.55	0.596
10.01	128.68	0.596
10.03	128.81	0.597
10.04	128.95	0.597
10.05	129.08	0.597
10.07	129.21	0.597
10.08	129.35	0.597
10.09	129.48	0.597
10.11	129.61	0.598
10.12	129.75	0.598
10.13	129.88	0.598
10.15	130.01	0.598
10.16	130.15	0.598
10.17	130.28	0.598
10.19	130.41	0.599
10.20	130.55	0.599
10.21	130.68	0.599
10.23	130.81	0.600
10.24	130.95	0.600
10.25	131.08	0.600
10.27	131.21	0.600
10.28	131.35	0.600
10.29	131.48	0.600
10.31	131.61	0.601
10.32	131.75	0.601
10.33	131.88	0.601
10.35	132.01	0.601
10.36	132.15	0.601
10.37	132.28	0.601
10.39	132.41	0.602
10.40	132.55	0.602
10.41	132.68	0.602
10.43	132.81	0.602
10.44	132.95	0.602
10.45	133.08	0.603
10.47	133.21	0.603
10.48	133.35	0.603
10.49	133.48	0.603
10.51	133.62	0.603
10.52	133.75	0.603
10.53	133.88	0.604
10.55	134.02	0.604
10.56	134.15	0.604
10.57	134.28	0.604
10.59	134.42	0.604
10.60	134.55	0.605
10.61	134.68	0.605
10.63	134.82	0.605
10.64	134.95	0.605
10.65	135.08	0.605
10.67	135.22	0.605
10.68	135.35	0.605
10.69	135.48	0.606
10.71	135.62	0.606
10.72	135.75	0.606
10.73	135.88	0.606
10.75	136.01	0.606
10.76	136.15	0.607
10.77	136.28	0.607
10.79	136.42	0.607
10.80	136.55	0.607
10.81	136.68	0.607
10.83	136.82	0.608
10.84	136.95	0.608
10.85	137.08	0.608
10.87	137.22	0.608
10.88	137.35	0.608
10.89	137.48	0.608
10.91	137.62	0.609
10.92	137.75	0.609
10.93	137.88	0.609
10.95	138.02	0.609
10.96	138.15	0.609
10.97	138.28	0.609
10.99	138.42	0.609
11.00	138.55	0.610
11.01	138.68	0.610
11.03	138.82	0.610
11.04	138.95	0.610
11.05	139.08	0.610
11.07	139.22	0.610
11.08	139.35	0.610
11.09	139.48	0.611
11.11	139.62	0.611
11.12	139.75	0.611
11.13	139.88	0.611
11.15	140.02	0.611
11.16	140.15	0.612
11.17	140.28	0.612
11.19	140.42	0.612
11.20	140.55	0.612
11.21	140.68	0.612
11.23	140.82	0.613
11.24	140.95	0.613
11.25	141.08	0.613
11.27	141.22	0.613
11.28	141.35	0.613
11.29	141.48	0.613
11.31	141.62	0.614
11.32	141.75	0.614
11.33	141.88	0.614
11.35	142.02	0.614
11.36	142.15	0.614
11.37	142.28	0.614
11.39	142.42	0.615
11.40	142.55	0.615
11.41	142.69	0.615
11.43	142.82	0.615
11.44	142.95	0.615
11.45	143.09	0.616
11.47	143.22	0.616
11.48	143.35	0.616
11.49	143.49	0.616
11.51	143.62	0.616
11.52	143.75	0.617
11.53	143.88	0.617
11.55	144.02	0.617
11.56	144.15	0.617
11.57	144.29	0.617
11.59	144.42	0.617
11.60	144.55	0.618
11.61	144.69	0.618
11.63	144.82	0.618
11.64	144.95	0.618
11.65	145.09	0.618
11.67	145.22	0.618
11.68	145.35	0.619
11.69	145.49	0.619
11.71	145.62	0.619
11.72	145.75	0.619
11.73	145.89	0.619
11.75	146.02	0.619
11.76	146.15	0.620
11.77	146.29	0.620
11.79	146.42	0.620
11.80	146.55	0.620
11.81	146.69	0.620
11.83	146.82	0.620
11.84	146.95	0.620
11.85	147.09	0.621
11.87	147.22	0.621
11.88	147.35	0.621
11.89	147.49	0.621
11.91	147.62	0.621
11.92	147.75	0.621
11.93	147.89	0.621
11.95	148.02	0.622
11.96	148.15	0.622
11.97	148.29	0.622
11.99	148.42	0.622
12.00	148.55	0.622
12.01	148.69	0.622
12.03	148.82	0.623
12.04	148.95	0.623
12.05	149.09	0.623
12.07	149.22	0.623
12.08	149.36	0.623
12.09	149.49	0.623
12.11	149.62	0.624
12.12	149.76	0.624
12.13	149.89	0.624
12.15	150.02	0.624
12.16	150.16	0.624
12.17	150.29	0.624
12.19	150.42	0.624
12.20	150.56	0.625
12.21	150.69	0.625
12.23	150.82	0.625
12.24	150.96	0.625
12.25	151.09	0.625
12.27	151.22	0.625
12.28	151.36	0.626
12.29	151.49	0.626
12.31	151.62	0.626
12.32	151.76	0.626
12.33	151.89	0.626
12.35	152.02	0.626
12.36	152.16	0.626
12.37	152.29	0.627
12.39	152.42	0.627
12.40	152.56	0.627
12.41	152.69	0.627
12.43	152.82	0.627
12.44	152.96	0.627
12.45	153.09	0.628
12.47	153.22	0.628
12.48	153.36	0.628
12.49	153.49	0.628
12.51	153.62	0.628
12.52	153.76	0.628
12.53	153.89	0.628
12.55	154.02	0.629
12.56	154.16	0.629
12.57	154.29	0.629
12.59	154.42	0.629
12.60	154.56	0.629
12.61	154.69	0.629
12.63	154.82	0.629
12.64	154.96	0.629
12.65	155.09	0.629
12.67	155.22	0.630
12.68	155.36	0.630
12.69	155.49	0.630
12.71	155.62	0.630
12.72	155.76	0.630
12.73	155.89	0.630
12.75	156.02	0.630
12.76	156.16	0.630
12.77	156.29	0.631
12.79	156.42	0.631
12.80	156.56	0.631
12.81	156.69	0.631
12.83	156.83	0.631
12.84	156.96	0.631
12.85	157.09	0.631
12.87	157.23	0.632
12.88	157.36	0.632
12.89	157.49	0.632
12.91	157.63	0.632
12.92	157.76	0.632
12.93	157.89	0.632
12.95	158.02	0.632
12.96	158.16	0.632
12.97	158.29	0.632
12.99	158.42	0.633
13.00	158.56	0.633
13.01	158.69	0.633
13.03	158.82	0.633
13.04	158.96	0.633
13.05	159.09	0.633
13.07	159.22	0.633
13.08	159.36	0.633
13.09	159.49	0.634
13.11	159.63	0.634
13.12	159.76	0.634
13.13	159.89	0.634
13.15	160.03	0.634
13.16	160.16	0.634
13.17	160.29	0.634
13.19	160.43	0.635
13.20	160.56	0.635
13.21	160.69	0.635
13.23	160.83	0.635
13.24	160.96	0.635
13.25	161.09	0.635
13.27	161.23	0.635
13.28	161.36	0.635
13.29	161.49	0.635
13.31	161.63	0.635
13.32	161.76	0.636
13.33	161.89	0.636
13.35	162.03	0.636
13.36	162.16	0.636
13.37	162.29	0.636
13.39	162.43	0.636
13.40	162.56	0.636
13.41	162.69	0.636
13.43	162.83	0.637
13.44	162.96	0.637
13.45	163.09	0.637
13.47	163.23	0.637
13.48	163.36	0.637
13.49	163.49	0.637
13.51	163.63	0.637
13.52	163.76	0.637
13.53	163.89	0.637
13.55	164.03	0.637
13.56	164.16	0.638
13.57	164.30	0.638
13.59	164.43	0.638
13.60	164.56	0.638
13.61	164.70	0.638
13.63	164.83	0.638
13.64	164.96	0.638
13.65	165.10	0.638
13.67	165.23	0.639
13.68	165.36	0.639
13.69	165.49	0.639
13.71	165.63	0.639
13.72	165.76	0.639
13.73	165.90	0.639
13.75	166.03	0.639
13.76	166.16	0.639
13.77	166.30	0.639
13.79	166.43	0.639
13.80	166.56	0.640
13.81	166.70	0.640
13.83	166.83	0.640
13.84	166.96	0.640
13.85	167.10	0.640
13.87	167.23	0.640
13.88	167.36	0.640
13.89	167.50	0.640
13.91	167.63	0.641
13.92	167.76	0.641
13.93	167.90	0.641
13.95	168.03	0.641
13.96	168.16	0.641
13.97	168.30	0.641
13.99	168.43	0.641
14.00	168.56	0.641
14.01	168.70	0.641
14.03	168.83	0.641
14.04	168.96	0.641
14.05	169.10	0.641
14.07	169.23	0.641
14.08	169.36	0.641
14.09	169.50	0.642
14.11	169.63	0.642
14.12	169.76	0.642
14.13	169.90	0.642
14.15	170.03	0.642
14.16	170.16	0.642
14.17	170.30	0.642
14.19	170.43	0.642
14.20	170.56	0.642
14.21	170.70	0.643
14.23	170.83	0.643
14.24	170.96	0.643
14.25	171.10	0.643
14.27	171.23	0.643
14.28	171.36	0.643
14.29	171.50	0.643
14.31	171.63	0.643
14.32	171.76	0.643
14.33	171.90	0.643
14.35	172.03	0.644
14.36	172.16	0.644
14.37	172.30	0.644
14.39	172.43	0.644
14.40	172.56	0.644
14.41	172.70	0.644
14.43	172.83	0.644
14.44	172.96	0.644
14.45	173.10	0.644
14.47	173.23	0.644
14.48	173.37	0.644
14.49	173.50	0.644
14.51	173.63	0.644
14.52	173.77	0.645
14.53	173.90	0.645
14.55	174.03	0.645
14.56	174.17	0.645
14.57	174.30	0.645
14.59	174.43	0.645
14.60	174.57	0.646
14.61	174.70	0.646
14.63	174.83	0.646
14.64	174.97	0.646
14.65	175.10	0.646
14.67	175.23	0.646
14.68	175.37	0.646
14.69	175.50	0.646
14.71	175.63	0.646
14.72	175.77	0.646
14.73	175.90	0.646
14.75	176.03	0.647
14.76	176.17	0.647
14.77	176.30	0.647
14.79	176.43	0.647
14.80	176.57	0.647
14.81	176.70	0.647
14.83	176.83	0.647
14.84	176.97	0.647
14.85	177.10	0.647
14.87	177.23	0.647
14.88	177.37	0.647
14.89	177.50	0.648
14.91	177.63	0.648
14.92	177.77	0.648
14.93	177.90	0.648
14.95	178.03	0.648
14.96	178.17	0.648
14.97	178.30	0.648
14.99	178.43	0.648
15.00	178.57	0.648
15.01	178.70	0.648
15.03	178.83	0.648
15.04	178.97	0.649
15.05	179.10	0.649
15.07	179.23	0.649
15.08	179.37	0.649
15.09	179.50	0.649
15.11	179.63	0.649
15.12	179.77	0.649
15.13	179.90	0.650
15.15	180.03	0.650
15.16	180.17	0.650
15.17	180.30	0.650
15.19	180.43	0.650
15.20	180.57	0.650
15.21	180.70	0.650
15.23	180.83	0.650
15.24	180.97	0.650
15.25	181.10	0.650
15.27	181.23	0.651
15.28	181.37	0.651
15.29	181.50	0.651
15.31	181.63	0.651
15.32	181.77	0.651
15.33	181.90	0.651
15.35	182.03	0.651
15.36	182.17	0.652
15.37	182.30	0.652
15.39	182.43	0.652
15.40	182.57	0.652
15.41	182.70	0.652
15.43	182.84	0.652
15.44	182.97	0.652
15.45	183.10	0.653
15.47	183.24	0.653
15.48	183.37	0.653
15.49	183.50	0.653
15.51	183.63	0.653
15.52	183.77	0.653
15.53	183.90	0.654
15.55	184.04	0.654
15.56	184.17	0.654
15.57	184.30	0.654
15.59	184.44	0.654
15.60	184.57	0.654
15.61	184.70	0.654
15.63	184.84	0.655
15.64	184.97	0.655
15.65	185.10	0.655
15.67	185.24	0.655
15.68	185.37	0.656
15.69	185.50	0.656
15.71	185.64	0.656
15.72	185.77	0.656
15.73	185.90	0.656
15.75	186.04	0.657
15.76	186.17	0.657
15.77	186.30	0.657
15.79	186.44	0.657
15.80	186.57	0.657
15.81	186.70	0.657
15.83	186.84	0.657
15.84	186.97	0.657
15.85	187.10	0.658
15.87	187.24	0.658
15.88	187.37	0.659
15.89	187.50	0.659
15.91	187.64	0.659
15.92	187.77	0.659
15.93	187.90	0.659
15.95	188.04	0.659
15.96	188.17	0.659
15.97	188.30	0.660
15.99	188.44	0.660
16.00	188.57	0.660
16.01	188.70	0.660
16.03	188.84	0.660
16.04	188.97	0.660
16.05	189.10	0.660
16.07	189.24	0.661
16.08	189.37	0.661
16.09	189.51	0.661
16.11	189.64	0.661
16.12	189.77	0.661
16.13	189.90	0.661
16.15	190.04	0.661
16.16	190.17	0.662
16.17	190.30	0.662
16.19	190.44	0.662
16.20	190.57	0.662
16.21	190.70	0.662
16.23	190.84	0.662
16.24	190.97	0.662
16.25	191.11	0.662
16.27	191.24	0.662
16.28	191.37	0.663
16.29	191.50	0.663
16.31	191.64	0.663
16.32	191.77	0.663
16.33	191.91	0.663
16.35	192.04	0.663
16.36	192.17	0.663
16.37	192.31	0.663
16.39	192.44	0.663
16.40	192.57	0.664
16.41	192.70	0.664
16.43	192.84	0.664
16.44	192.97	0.664
16.45	193.11	0.664
16.47	193.24	0.664
16.48	193.37	0.664
16.49	193.50	0.664
16.51	193.64	0.664
16.52	193.77	0.664
16.53	193.91	0.664
16.55	194.04	0.664
16.56	194.17	0.664
16.57	194.31	0.664
16.59	194.44	0.664
16.60	194.57	0.664
16.61	194.71	0.664
16.63	194.84	0.664
16.64	194.97	0.664
16.65	195.11	0.664
16.67	195.24	0.665
16.68	195.37	0.665
16.69	195.51	0.665
16.71	195.64	0.665
16.72	195.77	0.665
16.73	195.91	0.665
16.75	196.04	0.665
16.76	196.17	0.665
16.77	196.31	0.665
16.79	196.44	0.665
16.80	196.57	0.665
16.81	196.71	0.665
16.83	196.84	0.665
16.84	196.97	0.664
16.85	197.11	0.664
16.87	197.24	0.664
16.88	197.38	0.664
16.89	197.51	0.663
16.91	197.64	0.663
16.92	197.78	0.663
16.93	197.91	0.662
16.95	198.04	0.662
16.96	198.18	0.661
16.97	198.31	0.660
16.99	198.44	0.658
17.00	198.58	0.657
17.01	198.71	0.656
17.03	198.84	0.654
17.04	198.98	0.653
17.05	199.11	0.650
17.07	199.24	0.646
17.08	199.38	0.643
17.09	199.51	0.638
17.11	199.65	0.634
17.12	199.78	0.630
17.13	199.91	0.627
17.15	200.05	0.625
17.16	200.18	0.622
17.17	200.32	0.616
17.19	200.45	0.614
17.20	200.58	0.612
17.21	200.72	0.611
17.23	200.85	0.608
17.24	200.99	0.602
17.25	201.12	0.599
17.27	201.25	0.597
17.28	201.39	0.595
17.29	201.52	0.593
17.31	201.65	0.590
17.32	201.79	0.589
17.33	201.92	0.587
17.35	202.06	0.586
17.36	202.19	0.583
17.37	202.32	0.580
17.39	202.46	0.577
17.40	202.59	0.574
17.41	202.72	0.572
17.43	202.86	0.572
17.44	202.99	0.571
17.45	203.13	0.571
17.47	203.26	0.568
17.48	203.39	0.568
17.49	203.53	0.566
17.51	203.66	0.563
17.52	203.80	0.558
17.53	203.93	0.552
17.55	204.06	0.548
17.56	204.20	0.546
17.57	204.33	0.545
17.59	204.46	0.543
17.60	204.60	0.541
17.61	204.73	0.538
17.63	204.86	0.534
17.64	205.00	0.532
17.65	205.13	0.530
17.67	205.27	0.527
17.68	205.40	0.525
17.69	205.53	0.523
17.71	205.67	0.522
17.72	205.80	0.516
17.73	205.94	0.510
17.75	206.07	0.507
17.76	206.20	0.505
17.77	206.34	0.500
17.79	206.47	0.495
17.80	206.60	0.495
17.81	206.74	0.493
17.83	206.87	0.491
17.84	207.01	0.488
17.85	207.14	0.483
17.87	207.27	0.479
17.88	207.41	0.475
17.89	207.54	0.472
17.91	207.68	0.472
17.92	207.81	0.470
17.93	207.94	0.468
17.95	208.08	0.467
17.96	208.21	0.466
17.97	208.34	0.459
17.99	208.48	0.453
18.00	208.61	0.451
18.00	208.63	0.450

[step]
Ramp 10.00 °C/min to 30.00 °C
Time	Temperature	Heat Flow (Normalized)
min	°C	W/g
19.00	209.77	1.627
19.02	209.77	1.578
19.03	209.78	1.539
19.04	209.78	1.507
19.06	209.78	1.497
19.07	209.77	1.508
19.08	209.74	1.537
19.10	209.71	1.572
19.11	209.66	1.598
19.12	209.60	1.607
19.14	209.53	1.597
19.15	209.44	1.548
19.16	209.35	1.486
19.18	209.26	1.405
19.19	209.16	1.318
19.20	209.06	1.231
19.22	208.95	1.145
19.23	208.85	1.063
19.24	208.74	0.988
19.26	208.62	0.917
19.27	208.51	0.859
19.28	208.40	0.813
19.30	208.28	0.763
19.31	208.16	0.713
19.32	208.04	0.665
19.34	207.93	0.623
19.35	207.81	0.582
19.36	207.68	0.568
19.38	207.56	0.556
19.39	207.44	0.524
19.40	207.31	0.483
19.42	207.19	0.451
19.43	207.06	0.417
19.44	206.94	0.394
19.46	206.81	0.380
19.47	206.69	0.349
19.48	206.56	0.317
19.50	206.44	0.291
19.51	206.31	0.270
19.52	206.18	0.251
19.54	206.05	0.230
19.55	205.93	0.213
19.56	205.80	0.195
19.58	205.67	0.192
19.59	205.54	0.165
19.60	205.41	0.146
19.62	205.29	0.129
19.63	205.16	0.114
19.64	205.03	0.098
19.66	204.90	0.086
19.67	204.77	0.074
19.68	204.64	0.060
19.70	204.51	0.054
19.71	204.38	0.040
19.72	204.25	0.032
19.74	204.12	0.017
19.75	203.99	0.007
19.76	203.87	-0.001
19.78	203.74	-0.007
19.79	203.60	-0.017
19.80	203.47	-0.027
19.82	203.34	-0.041
19.83	203.21	-0.047
19.84	203.08	-0.056
19.86	202.95	-0.066
19.87	202.82	-0.070
19.88	202.69	-0.080
19.90	202.56	-0.084
19.91	202.43	-0.093
19.92	202.30	-0.097
19.94	202.17	-0.105
19.95	202.04	-0.108
19.96	201.90	-0.114
19.98	201.77	-0.121
19.99	201.64	-0.124
20.00	201.51	-0.132
20.02	201.38	-0.136
20.03	201.25	-0.139
20.04	201.12	-0.144
20.06	200.98	-0.148
20.07	200.85	-0.151
20.08	200.72	-0.156
20.10	200.59	-0.160
20.11	200.45	-0.164
20.12	200.32	-0.169
20.14	200.19	-0.172
20.15	200.06	-0.175
20.16	199.93	-0.178
20.18	199.80	-0.182
20.19	199.66	-0.185
20.20	199.53	-0.187
20.22	199.40	-0.189
20.23	199.27	-0.191
20.24	199.14	-0.194
20.26	199.00	-0.197
20.27	198.87	-0.197
20.28	198.74	-0.198
20.30	198.61	-0.200
20.31	198.47	-0.202
20.32	198.34	-0.205
20.34	198.21	-0.206
20.35	198.08	-0.208
20.36	197.94	-0.210
20.38	197.81	-0.212
20.39	197.68	-0.213
20.40	197.55	-0.215
20.42	197.41	-0.217
20.43	197.28	-0.220
20.44	197.15	-0.222
20.46	197.01	-0.222
20.47	196.88	-0.223
20.48	196.75	-0.224
20.50	196.62	-0.225
20.51	196.48	-0.226
20.52	196.35	-0.227
20.54	196.22	-0.228
20.55	196.09	-0.229
20.56	195.95	-0.230
20.58	195.82	-0.234
20.59	195.69	-0.235
20.60	195.55	-0.237
20.62	195.42	-0.237
20.63	195.29	-0.237
20.64	195.16	-0.238
20.66	195.02	-0.238
20.67	194.89	-0.238
20.68	194.76	-0.240
20.70	194.62	-0.241
20.71	194.49	-0.241
20.72	194.36	-0.243
20.74	194.23	-0.244
20.75	194.09	-0.244
20.76	193.96	-0.245
20.78	193.83	-0.247
20.79	193.69	-0.248
20.80	193.56	-0.249
20.82	193.43	-0.249
20.83	193.30	-0.250
20.84	193.16	-0.250
20.86	193.03	-0.251
20.87	192.90	-0.251
20.88	192.76	-0.252
20.90	192.63	-0.252
20.91	192.50	-0.253
20.92	192.36	-0.253
20.94	192.23	-0.254
20.95	192.10	-0.254
20.96	191.97	-0.255
20.98	191.83	-0.255
20.99	191.70	-0.255
21.00	191.57	-0.256
21.02	191.44	-0.256
21.03	191.30	-0.257
21.04	191.17	-0.257
21.06	191.03	-0.257
21.07	190.90	-0.258
21.08	190.77	-0.259
21.10	190.64	-0.259
21.11	190.50	-0.260
21.12	190.37	-0.260
21.14	190.24	-0.261
21.15	190.10	-0.261
21.16	189.97	-0.262
21.18	189.84	-0.262
21.19	189.71	-0.263
21.20	189.57	-0.263
21.22	189.44	-0.263
21.23	189.30	-0.264
21.24	189.17	-0.264
21.26	189.04	-0.265
21.27	188.91	-0.265
21.28	188.77	-0.265
21.30	188.64	-0.266
21.31	188.51	-0.266
21.32	188.37	-0.266
21.34	188.24	-0.267
21.35	188.11	-0.267
21.36	187.97	-0.267
21.38	187.84	-0.268
21.39	187.71	-0.268
21.40	187.57	-0.269
21.42	187.44	-0.269
21.43	187.31	-0.269
21.44	187.18	-0.270
21.46	187.04	-0.270
21.47	186.91	-0.270
21.48	186.78	-0.270
21.50	186.64	-0.271
21.51	186.51	-0.271
21.52	186.38	-0.271
21.54	186.24	-0.272
21.55	186.11	-0.272
21.56	185.98	-0.272
21.58	185.85	-0.273
21.59	185.71	-0.273
21.60	185.58	-0.273
21.62	185.45	-0.273
21.63	185.31	-0.273
21.64	185.18	-0.273
21.66	185.05	-0.273
21.67	184.91	-0.273
21.68	184.78	-0.274
21.70	184.65	-0.274
21.71	184.51	-0.274
21.72	184.38	-0.275
21.74	184.25	-0.275
21.75	184.11	-0.275
21.76	183.98	-0.276
21.78	183.85	-0.276
21.79	183.71	-0.276
21.80	183.58	-0.276
21.82	183.45	-0.276
21.83	183.31	-0.277
21.84	183.18	-0.277
21.86	183.05	-0.277
21.87	182.92	-0.277
21.88	182.78	-0.277
21.90	182.65	-0.278
21.91	182.52	-0.278
21.92	182.38	-0.278
21.94	182.25	-0.278
21.95	182.12	-0.278
21.96	181.98	-0.278
21.98	181.85	-0.278
21.99	181.72	-0.278
22.00	181.58	-0.279
22.02	181.45	-0.279
22.03	181.32	-0.279
22.04	181.18	-0.279
22.06	181.05	-0.279
22.07	180.92	-0.279
22.08	180.78	-0.280
22.10	180.65	-0.280
22.11	180.52	-0.280
22.12	180.39	-0.280
22.14	180.25	-0.280
22.15	180.12	-0.280
22.16	179.99	-0.280
22.18	179.85	-0.281
22.19	179.72	-0.281
22.20	179.59	-0.281
22.22	179.45	-0.281
22.23	179.32	-0.281
22.24	179.19	-0.281
22.26	179.05	-0.281
22.27	178.92	-0.282
22.28	178.79	-0.282
22.30	178.66	-0.282
22.31	178.52	-0.282
22.32	178.39	-0.282
22.34	178.26	-0.282
22.35	178.12	-0.282
22.36	177.99	-0.282
22.38	177.86	-0.282
22.39	177.72	-0.283
22.40	177.59	-0.283
22.42	177.46	-0.283
22.43	177.32	-0.283
22.44	177.19	-0.283
22.46	177.06	-0.283
22.47	176.92	-0.283
22.48	176.79	-0.283
22.50	176.66	-0.283
22.51	176.52	-0.283
22.52	176.39	-0.283
22.54	176.26	-0.283
22.55	176.12	-0.284
22.56	175.99	-0.284
22.58	175.86	-0.284
22.59	175.73	-0.284
22.60	175.59	-0.284
22.62	175.46	-0.285
22.63	175.33	-0.285
22.64	175.19	-0.285
22.66	175.06	-0.285
22.67	174.93	-0.285
22.68	174.79	-0.285
22.70	174.66	-0.285
22.71	174.53	-0.285
22.72	174.39	-0.285
22.74	174.26	-0.285
22.75	174.13	-0.285
22.76	173.99	-0.285
22.78	173.86	-0.286
22.79	173.73	-0.286
22.80	173.59	-0.286
22.82	173.46	-0.286
22.83	173.33	-0.286
22.84	173.20	-0.286
22.86	173.06	-0.286
22.87	172.93	-0.286
22.88	172.80	-0.287
22.90	172.66	-0.287
22.91	172.53	-0.287
22.92	172.40	-0.287
22.94	172.26	-0.287
22.95	172.13	-0.287
22.96	172.00	-0.287
22.98	171.86	-0.287
22.99	171.73	-0.287
23.00	171.60	-0.287
23.02	171.46	-0.287
23.03	171.33	-0.287
23.04	171.20	-0.287
23.06	171.06	-0.287
23.07	170.93	-0.288
23.08	170.80	-0.288
23.10	170.66	-0.288
23.11	170.53	-0.288
23.12	170.40	-0.288
23.14	170.27	-0.288
23.15	170.13	-0.288
23.16	170.00	-0.288
23.18	169.87	-0.288
23.19	169.73	-0.288
23.20	169.60	-0.288
23.22	169.47	-0.288
23.23	169.33	-0.288
23.24	169.20	-0.288
23.26	169.07	-0.288
23.27	168.93	-0.288
23.28	168.80	-0.288
23.30	168.67	-0.289
23.31	168.53	-0.289
23.32	168.40	-0.289
23.34	168.27	-0.289
23.35	168.14	-0.289
23.36	168.00	-0.289
23.38	167.87	-0.289
23.39	167.74	-0.289
23.40	167.60	-0.289
23.42	167.47	-0.289
23.43	167.34	-0.289
23.44	167.20	-0.289
23.46	167.07	-0.289
23.47	166.94	-0.289
23.48	166.80	-0.289
23.50	166.67	-0.289
23.51	166.54	-0.290
23.52	166.40	-0.290
23.54	166.27	-0.290
23.55	166.14	-0.290
23.56	166.00	-0.290
23.58	165.87	-0.290
23.59	165.74	-0.290
23.60	165.61	-0.290
23.62	165.47	-0.290
23.63	165.34	-0.290
23.64	165.20	-0.290
23.66	165.07	-0.290
23.67	164.94	-0.290
23.68	164.81	-0.291
23.70	164.67	-0.291
23.71	164.54	-0.291
23.72	164.41	-0.291
23.74	164.27	-0.291
23.75	164.14	-0.291
23.76	164.01	-0.291
23.78	163.87	-0.291
23.79	163.74	-0.291
23.80	163.61	-0.291
23.82	163.47	-0.291
23.83	163.34	-0.291
23.84	163.21	-0.291
23.86	163.07	-0.291
23.87	162.94	-0.291
23.88	162.81	-0.291
23.90	162.67	-0.292
23.91	162.54	-0.292
23.92	162.41	-0.292
23.94	162.27	-0.292
23.95	162.14	-0.292
23.96	162.01	-0.292
23.98	161.88	-0.292
23.99	161.74	-0.292
24.00	161.61	-0.292
24.02	161.48	-0.292
24.03	161.34	-0.292
24.04	161.21	-0.292
24.06	161.08	-0.292
24.07	160.94	-0.292
24.08	160.81	-0.293
24.10	160.68	-0.293
24.11	160.54	-0.293
24.12	160.41	-0.293
24.14	160.28	-0.293
24.15	160.14	-0.293
24.16	160.01	-0.293
24.18	159.88	-0.293
24.19	159.74	-0.293
24.20	159.61	-0.293
24.22	159.48	-0.293
24.23	159.34	-0.293
24.24	159.21	-0.293
24.26	159.08	-0.293
24.27	158.95	-0.293
24.28	158.81	-0.293
24.30	158.68	-0.293
24.31	158.55	-0.293
24.32	158.41	-0.293
24.34	158.28	-0.293
24.35	158.15	-0.294
24.36	158.01	-0.294
24.38	157.88	-0.294
24.39	157.75	-0.294
24.40	157.61	-0.294
24.42	157.48	-0.294
24.43	157.35	-0.294
24.44	157.21	-0.294
24.46	157.08	-0.294
24.47	156.95	-0.294
24.48	156.81	-0.294
24.50	156.68	-0.294
24.51	156.55	-0.294
24.52	156.42	-0.294
24.54	156.28	-0.294
24.55	156.15	-0.294
24.56	156.01	-0.294
24.58	155.88	-0.294
24.59	155.75	-0.294
24.60	155.61	-0.294
24.62	155.48	-0.295
24.63	155.35	-0.295
24.64	155.22	-0.295
24.66	155.08	-0.295
24.67	154.95	-0.295
24.68	154.82	-0.295
24.70	154.68	-0.295
24.71	154.55	-0.295
24.72	154.42	-0.295
24.74	154.28	-0.295
24.75	154.15	-0.295
24.76	154.02	-0.295
24.78	153.88	-0.295
24.79	153.75	-0.295
24.80	153.62	-0.295
24.82	153.48	-0.295
24.83	153.35	-0.295
24.84	153.22	-0.295
24.86	153.08	-0.295
24.87	152.95	-0.295
24.88	152.82	-0.296
24.90	152.69	-0.296
24.91	152.55	-0.296
24.92	152.42	-0.296
24.94	152.29	-0.296
24.95	152.15	-0.296
24.96	152.02	-0.296
24.98	151.89	-0.296
24.99	151.75	-0.296
25.00	151.62	-0.296
25.02	151.49	-0.296
25.03	151.35	-0.296
25.04	151.22	-0.296
25.06	151.09	-0.296
25.07	150.95	-0.296
25.08	150.82	-0.296
25.10	150.69	-0.296
25.11	150.55	-0.296
25.12	150.42	-0.297
25.14	150.29	-0.297
25.15	150.15	-0.297
25.16	150.02	-0.297
25.18	149.89	-0.297
25.19	149.76	-0.297
25.20	149.62	-0.297
25.22	149.49	-0.297
25.23	149.36	-0.297
25.24	149.22	-0.297
25.26	149.09	-0.297
25.27	148.96	-0.297
25.28	148.82	-0.297
25.30	148.69	-0.297
25.31	148.56	-0.297
25.32	148.42	-0.297
25.34	148.29	-0.297
25.35	148.16	-0.297
25.36	148.02	-0.297
25.38	147.89	-0.297
25.39	147.76	-0.297
25.40	147.62	-0.297
25.42	147.49	-0.297
25.43	147.36	-0.298
25.44	147.22	-0.298
25.46	147.09	-0.298
25.47	146.96	-0.298
25.48	146.82	-0.298
25.50	146.69	-0.298
25.51	146.56	-0.298
25.52	146.43	-0.298
25.54	146.29	-0.298
25.55	146.16	-0.298
25.56	146.03	-0.298
25.58	145.89	-0.298
25.59	145.76	-0.299
25.60	145.63	-0.299
25.62	145.49	-0.299
25.63	145.36	-0.299
25.64	145.23	-0.299
25.66	145.09	-0.299
25.67	144.96	-0.299
25.68	144.83	-0.299
25.70	144.69	-0.299
25.71	144.56	-0.299
25.72	144.43	-0.299
25.74	144.29	-0.299
25.75	144.16	-0.299
25.76	144.03	-0.299
25.78	143.89	-0.299
25.79	143.76	-0.299
25.80	143.63	-0.299
25.82	143.50	-0.299
25.83	143.36	-0.299
25.84	143.23	-0.299
25.86	143.10	-0.299
25.87	142.96	-0.299
25.88	142.83	-0.299
25.90	142.70	-0.299
25.91	142.56	-0.299
25.92	142.43	-0.299
25.94	142.30	-0.299
25.95	142.16	-0.299
25.96	142.03	-0.299
25.98	141.90	-0.299
25.99	141.76	-0.299
26.00	141.63	-0.299
26.02	141.50	-0.300
26.03	141.36	-0.299
26.04	141.23	-0.299
26.06	141.10	-0.299
26.07	140.96	-0.299
26.08	140.83	-0.299
26.10	140.70	-0.300
26.11	140.57	-0.300
26.12	140.43	-0.300
26.14	140.30	-0.300
[...]
41.79	66.48	0.182
41.80	66.61	0.182
41.82	66.75	0.183
41.83	66.88	0.183
41.84	67.02	0.183
41.86	67.15	0.184
41.87	67.28	0.184
41.88	67.41	0.185
41.90	67.55	0.185
41.91	67.68	0.186
41.92	67.82	0.186
41.94	67.95	0.186
41.95	68.08	0.187
41.96	68.22	0.187
41.98	68.35	0.188
41.99	68.48	0.189
42.00	68.62	0.189
42.02	68.75	0.189
42.03	68.88	0.190
42.04	69.02	0.191
42.06	69.15	0.191
42.07	69.28	0.192
42.08	69.42	0.192
42.10	69.55	0.193
42.11	69.68	0.193
42.12	69.82	0.194
42.14	69.95	0.194
42.15	70.08	0.195
42.16	70.21	0.195
42.18	70.35	0.196
42.19	70.48	0.197
42.20	70.62	0.198
42.22	70.75	0.198
42.23	70.88	0.199
42.24	71.01	0.199
42.26	71.15	0.200
42.27	71.28	0.200
42.28	71.41	0.201
42.30	71.55	0.201
42.31	71.68	0.203
42.32	71.81	0.204
42.34	71.95	0.204
42.35	72.08	0.205
42.36	72.21	0.206
42.38	72.35	0.206
42.39	72.48	0.207
42.40	72.61	0.208
42.42	72.75	0.208
42.43	72.88	0.209
42.44	73.02	0.210
42.46	73.15	0.210
42.47	73.28	0.211
42.48	73.41	0.211
42.50	73.55	0.212
42.51	73.68	0.213
42.52	73.81	0.214
42.54	73.95	0.214
42.55	74.08	0.216
42.56	74.22	0.216
42.58	74.35	0.217
42.59	74.48	0.217
42.60	74.61	0.218
42.62	74.75	0.219
42.63	74.88	0.219
42.64	75.01	0.220
42.66	75.15	0.221
42.67	75.28	0.222
42.68	75.41	0.222
42.70	75.55	0.223
42.71	75.68	0.224
42.72	75.81	0.226
42.74	75.95	0.227
42.75	76.08	0.227
42.76	76.21	0.228
42.78	76.35	0.229
42.79	76.48	0.229
42.80	76.61	0.230
42.82	76.75	0.230
42.83	76.88	0.231
42.84	77.01	0.231
42.86	77.15	0.232
42.87	77.28	0.232
42.88	77.41	0.233
42.90	77.55	0.233
42.91	77.68	0.234
42.92	77.81	0.235
42.94	77.95	0.235
42.95	78.08	0.236
42.96	78.21	0.236
42.98	78.35	0.237
42.99	78.48	0.237
43.00	78.61	0.238
43.02	78.75	0.239
43.03	78.88	0.239
43.04	79.01	0.239
43.06	79.15	0.240
43.07	79.28	0.240
43.08	79.41	0.241
43.10	79.55	0.241
43.11	79.68	0.242
43.12	79.81	0.242
43.14	79.95	0.242
43.15	80.08	0.243
43.16	80.21	0.243
43.18	80.35	0.243
43.19	80.48	0.244
43.20	80.61	0.244
43.22	80.75	0.245
43.23	80.88	0.245
43.24	81.01	0.245
43.26	81.15	0.246
43.27	81.28	0.246
43.28	81.41	0.246
43.30	81.55	0.247
43.31	81.68	0.247
43.32	81.81	0.247
43.34	81.95	0.247
43.35	82.08	0.248
43.36	82.21	0.248
43.38	82.35	0.248
43.39	82.48	0.248
43.40	82.61	0.249
43.42	82.75	0.249
43.43	82.88	0.249
43.44	83.02	0.249
43.46	83.15	0.249
43.47	83.28	0.249
43.48	83.42	0.250
43.50	83.55	0.250
43.51	83.68	0.250
43.52	83.82	0.250
43.54	83.95	0.250
43.55	84.08	0.250
43.56	84.22	0.251
43.58	84.35	0.251
43.59	84.48	0.251
43.60	84.62	0.251
43.62	84.75	0.251
43.63	84.88	0.251
43.64	85.02	0.251
43.66	85.15	0.251
43.67	85.28	0.251
43.68	85.42	0.251
43.70	85.55	0.252
43.71	85.68	0.252
43.72	85.82	0.252
43.74	85.95	0.252
43.75	86.08	0.252
43.76	86.22	0.252
43.78	86.35	0.252
43.79	86.48	0.252
43.80	86.62	0.252
43.82	86.75	0.252
43.83	86.89	0.252
43.84	87.02	0.252
43.86	87.15	0.252
43.87	87.29	0.252
43.88	87.42	0.252
43.90	87.55	0.252
43.91	87.69	0.253
43.92	87.82	0.253
43.94	87.95	0.253
43.95	88.09	0.253
43.96	88.22	0.253
43.98	88.35	0.253
43.99	88.49	0.253
44.00	88.62	0.253
44.02	88.75	0.253
44.03	88.89	0.253
44.04	89.02	0.253
44.06	89.15	0.253
44.07	89.29	0.253
44.08	89.42	0.253
44.10	89.55	0.253
44.11	89.69	0.253
44.12	89.82	0.253
44.14	89.95	0.253
44.15	90.09	0.253
44.16	90.22	0.254
44.18	90.35	0.254
44.19	90.49	0.254
44.20	90.62	0.254
44.22	90.75	0.254
44.23	90.89	0.254
44.24	91.02	0.254
44.26	91.15	0.254
44.27	91.29	0.254
44.28	91.42	0.254
44.30	91.55	0.255
44.31	91.69	0.255
44.32	91.82	0.255
44.34	91.95	0.255
44.35	92.09	0.255
44.36	92.22	0.255
44.38	92.36	0.255
44.39	92.49	0.255
44.40	92.62	0.255
44.42	92.75	0.255
44.43	92.89	0.255
44.44	93.02	0.256
44.46	93.16	0.256
44.47	93.29	0.256
44.48	93.42	0.256
44.50	93.56	0.256
44.51	93.69	0.256
44.52	93.82	0.256
44.54	93.96	0.256
44.55	94.09	0.256
44.56	94.22	0.256
44.58	94.36	0.257
44.59	94.49	0.257
44.60	94.62	0.257
44.62	94.76	0.257
44.63	94.89	0.257
44.64	95.02	0.257
44.66	95.16	0.257
44.67	95.29	0.257
44.68	95.42	0.257
44.70	95.56	0.257
44.71	95.69	0.257
44.72	95.82	0.257
44.74	95.96	0.257
44.75	96.09	0.257
44.76	96.22	0.257
44.78	96.36	0.258
44.79	96.49	0.258
44.80	96.62	0.258
44.82	96.76	0.258
44.83	96.89	0.258
44.84	97.02	0.258
44.86	97.16	0.258
44.87	97.29	0.259
44.88	97.42	0.259
44.90	97.56	0.259
44.91	97.69	0.259
44.92	97.83	0.259
44.94	97.96	0.259
44.95	98.09	0.259
44.96	98.23	0.259
44.98	98.36	0.259
44.99	98.49	0.260
45.00	98.63	0.260
45.02	98.76	0.260
45.03	98.89	0.260
45.04	99.03	0.260
45.06	99.16	0.260
45.07	99.29	0.260
45.08	99.43	0.260
45.10	99.56	0.261
45.11	99.69	0.260
45.12	99.83	0.261
45.14	99.96	0.261
45.15	100.09	0.261
45.16	100.23	0.261
45.18	100.36	0.261
45.19	100.49	0.261
45.20	100.63	0.261
45.22	100.76	0.261
45.23	100.89	0.261
45.24	101.03	0.261
45.26	101.16	0.262
45.27	101.29	0.262
45.28	101.43	0.262
45.30	101.56	0.262
45.31	101.69	0.262
45.32	101.83	0.262
45.34	101.96	0.262
45.35	102.09	0.262
45.36	102.23	0.262
45.38	102.36	0.263
45.39	102.49	0.263
45.40	102.63	0.263
45.42	102.76	0.263
45.43	102.89	0.263
45.44	103.03	0.263
45.46	103.16	0.263
45.47	103.29	0.263
45.48	103.43	0.263
45.50	103.56	0.263
45.51	103.69	0.264
45.52	103.83	0.264
45.54	103.96	0.264
45.55	104.09	0.264
45.56	104.23	0.264
45.58	104.36	0.264
45.59	104.49	0.264
45.60	104.63	0.265
45.62	104.76	0.265
45.63	104.89	0.265
45.64	105.03	0.265
45.66	105.16	0.265
45.67	105.29	0.265
45.68	105.43	0.265
45.70	105.56	0.265
45.71	105.70	0.265
45.72	105.83	0.265
45.74	105.96	0.265
45.75	106.09	0.265
45.76	106.23	0.265
45.78	106.36	0.266
45.79	106.50	0.266
45.80	106.63	0.266
45.82	106.76	0.266
45.83	106.90	0.266
45.84	107.03	0.266
45.86	107.16	0.266
45.87	107.30	0.266
45.88	107.43	0.266
45.90	107.56	0.266
45.91	107.70	0.267
45.92	107.83	0.267
45.94	107.96	0.267
45.95	108.10	0.267
45.96	108.23	0.267
45.98	108.36	0.267
45.99	108.50	0.267
46.00	108.63	0.267
46.02	108.76	0.267
46.03	108.90	0.267
46.04	109.03	0.267
46.06	109.16	0.267
46.07	109.30	0.268
46.08	109.43	0.268
46.10	109.57	0.268
46.11	109.70	0.268
46.12	109.83	0.268
46.14	109.97	0.269
46.15	110.10	0.269
46.16	110.23	0.269
46.18	110.36	0.269
46.19	110.50	0.269
46.20	110.63	0.269
46.22	110.76	0.269
46.23	110.90	0.269
46.24	111.03	0.270
46.26	111.16	0.270
46.27	111.30	0.270
46.28	111.43	0.270
46.30	111.57	0.270
46.31	111.70	0.270
46.32	111.83	0.270
46.34	111.97	0.270
46.35	112.10	0.270
46.36	112.23	0.271
46.38	112.37	0.271
46.39	112.50	0.271
46.40	112.63	0.271
46.42	112.77	0.271
46.43	112.90	0.271
46.44	113.03	0.271
46.46	113.17	0.271
46.47	113.30	0.271
46.48	113.43	0.271
46.50	113.57	0.271
46.51	113.70	0.271
46.52	113.83	0.272
46.54	113.97	0.272
46.55	114.10	0.272
46.56	114.23	0.272
46.58	114.37	0.272
46.59	114.50	0.272
46.60	114.63	0.272
46.62	114.77	0.273
46.63	114.90	0.273
46.64	115.03	0.273
46.66	115.17	0.273
46.67	115.30	0.273
46.68	115.43	0.273
46.70	115.57	0.273
46.71	115.70	0.273
46.72	115.83	0.273
46.74	115.97	0.274
46.75	116.10	0.274
46.76	116.23	0.274
46.78	116.37	0.274
46.79	116.50	0.274
46.80	116.63	0.274
46.82	116.77	0.274
46.83	116.90	0.274
46.84	117.03	0.274
46.86	117.17	0.274
46.87	117.30	0.275
46.88	117.43	0.275
46.90	117.57	0.275
46.91	117.70	0.275
46.92	117.84	0.275
46.94	117.97	0.275
46.95	118.10	0.275
46.96	118.24	0.276
46.98	118.37	0.276
46.99	118.50	0.276
47.00	118.64	0.276
47.02	118.77	0.276
47.03	118.90	0.276
47.04	119.04	0.276
47.06	119.17	0.276
47.07	119.30	0.276
47.08	119.44	0.276
47.10	119.57	0.277
47.11	119.70	0.277
47.12	119.84	0.277
47.14	119.97	0.277
47.15	120.10	0.277
47.16	120.24	0.277
47.18	120.37	0.277
47.19	120.50	0.277
47.20	120.64	0.277
47.22	120.77	0.278
47.23	120.90	0.278
47.24	121.04	0.278
47.26	121.17	0.278
47.27	121.30	0.278
47.28	121.44	0.278
47.30	121.57	0.278
47.31	121.70	0.278
47.32	121.84	0.278
47.34	121.97	0.278
47.35	122.10	0.278
47.36	122.24	0.278
47.38	122.37	0.278
47.39	122.51	0.279
47.40	122.64	0.279
47.42	122.77	0.279
47.43	122.90	0.279
47.44	123.04	0.279
47.46	123.17	0.279
47.47	123.31	0.280
47.48	123.44	0.280
47.50	123.57	0.280
47.51	123.71	0.280
47.52	123.84	0.280
47.54	123.97	0.281
47.55	124.10	0.281
47.56	124.24	0.281
47.58	124.37	0.281
47.59	124.50	0.281
47.60	124.64	0.281
47.62	124.77	0.281
47.63	124.90	0.281
47.64	125.04	0.281
47.66	125.17	0.281
47.67	125.31	0.281
47.68	125.44	0.281
47.70	125.57	0.282
47.71	125.71	0.282
47.72	125.84	0.282
47.74	125.97	0.282
47.75	126.10	0.282
47.76	126.24	0.282
47.78	126.37	0.282
47.79	126.51	0.283
47.80	126.64	0.283
47.82	126.77	0.283
47.83	126.91	0.283
47.84	127.04	0.283
47.86	127.17	0.284
47.87	127.31	0.284
47.88	127.44	0.284
47.90	127.57	0.284
47.91	127.71	0.284
47.92	127.84	0.284
47.94	127.97	0.284
47.95	128.11	0.284
47.96	128.24	0.284
47.98	128.37	0.284
47.99	128.51	0.284
48.00	128.64	0.284
48.02	128.77	0.285
48.03	128.91	0.285
48.04	129.04	0.285
48.06	129.17	0.285
48.07	129.31	0.285
48.08	129.44	0.285
48.10	129.57	0.285
48.11	129.71	0.285
48.12	129.84	0.285
48.14	129.97	0.285
48.15	130.11	0.286
48.16	130.24	0.286
48.18	130.37	0.286
48.19	130.51	0.286
48.20	130.64	0.286
48.22	130.78	0.286
48.23	130.91	0.286
48.24	131.04	0.287
48.26	131.17	0.287
48.27	131.31	0.287
48.28	131.44	0.287
48.30	131.57	0.287
48.31	131.71	0.287
48.32	131.84	0.287
48.34	131.98	0.287
48.35	132.11	0.288
48.36	132.24	0.288
48.38	132.38	0.288
48.39	132.51	0.288
48.40	132.64	0.288
48.42	132.78	0.288
48.43	132.91	0.288
48.44	133.04	0.288
48.46	133.17	0.289
48.47	133.31	0.289
48.48	133.44	0.289
48.50	133.57	0.289
48.51	133.71	0.289
48.52	133.84	0.289
48.54	133.98	0.289
48.55	134.11	0.289
48.56	134.24	0.289
48.58	134.38	0.289
48.59	134.51	0.289
48.60	134.64	0.289
48.62	134.78	0.289
48.63	134.91	0.290
48.64	135.04	0.290
48.66	135.18	0.290
48.67	135.31	0.290
48.68	135.44	0.290
48.70	135.58	0.290
48.71	135.71	0.290
48.72	135.84	0.290
48.74	135.98	0.290
48.75	136.11	0.290
48.76	136.24	0.291
48.78	136.38	0.291
48.79	136.51	0.291
48.80	136.64	0.291
48.82	136.78	0.291
48.83	136.91	0.291
48.84	137.04	0.292
48.86	137.18	0.292
48.87	137.31	0.292
48.88	137.44	0.292
48.90	137.58	0.292
48.91	137.71	0.292
48.92	137.84	0.292
48.94	137.98	0.292
48.95	138.11	0.292
48.96	138.24	0.292
48.98	138.38	0.293
48.99	138.51	0.293
49.00	138.64	0.293
49.02	138.78	0.293
49.03	138.91	0.293
49.04	139.04	0.293
49.06	139.18	0.293
49.07	139.31	0.293
49.08	139.45	0.293
49.10	139.58	0.293
49.11	139.71	0.294
49.12	139.84	0.294
49.14	139.98	0.294
49.15	140.11	0.294
49.16	140.24	0.294
49.18	140.38	0.294
49.19	140.51	0.295
49.20	140.64	0.295
49.22	140.78	0.295
49.23	140.91	0.295
49.24	141.05	0.295
49.26	141.18	0.295
49.27	141.31	0.295
49.28	141.45	0.296
49.30	141.58	0.296
49.31	141.71	0.296
49.32	141.85	0.296
49.34	141.98	0.296
49.35	142.11	0.296
49.36	142.25	0.296
49.38	142.38	0.296
49.39	142.51	0.296
49.40	142.65	0.297
49.42	142.78	0.297
49.43	142.91	0.297
49.44	143.05	0.297
49.46	143.18	0.297
49.47	143.31	0.297
49.48	143.44	0.297
49.50	143.58	0.297
49.51	143.71	0.297
49.52	143.85	0.298
49.54	143.98	0.298
49.55	144.11	0.298
49.56	144.25	0.298
49.58	144.38	0.298
49.59	144.51	0.298
49.60	144.65	0.298
49.62	144.78	0.298
49.63	144.91	0.298
49.64	145.05	0.299
49.66	145.18	0.299
49.67	145.31	0.299
49.68	145.45	0.299
49.70	145.58	0.299
49.71	145.71	0.299
49.72	145.85	0.299
49.74	145.98	0.299
49.75	146.11	0.300
49.76	146.25	0.300
49.78	146.38	0.300
49.79	146.51	0.300
49.80	146.65	0.300
49.82	146.78	0.300
49.83	146.91	0.300
49.84	147.05	0.300
49.86	147.18	0.300
49.87	147.32	0.300
49.88	147.45	0.300
49.90	147.58	0.301
49.91	147.71	0.301
49.92	147.85	0.301
49.94	147.98	0.301
49.95	148.12	0.301
49.96	148.25	0.301
49.98	148.38	0.302
49.99	148.52	0.302
50.00	148.65	0.302
50.02	148.78	0.302
50.03	148.92	0.302
50.04	149.05	0.302
50.06	149.18	0.302
50.07	149.32	0.302
50.08	149.45	0.302
50.10	149.58	0.302
50.11	149.72	0.302
50.12	149.85	0.302
50.14	149.98	0.303
50.15	150.12	0.303
50.16	150.25	0.303
50.18	150.38	0.303
50.19	150.52	0.303
50.20	150.65	0.303
50.22	150.78	0.303
50.23	150.92	0.303
50.24	151.05	0.304
50.26	151.18	0.304
50.27	151.32	0.304
50.28	151.45	0.304
50.30	151.58	0.304
50.31	151.72	0.304
50.32	151.85	0.304
50.34	151.98	0.304
50.35	152.12	0.304
50.36	152.25	0.304
50.38	152.38	0.304
50.39	152.52	0.304
50.40	152.65	0.304
50.42	152.78	0.304
50.43	152.92	0.305
50.44	153.05	0.305
50.46	153.18	0.305
50.47	153.32	0.305
50.48	153.45	0.305
50.50	153.58	0.305
50.51	153.72	0.306
50.52	153.85	0.306
50.54	153.98	0.306
50.55	154.12	0.306
50.56	154.25	0.306
50.58	154.38	0.306
50.59	154.52	0.306
50.60	154.65	0.306
50.62	154.78	0.306
50.63	154.92	0.307
50.64	155.05	0.307
50.66	155.19	0.307
50.67	155.32	0.307
50.68	155.45	0.307
50.70	155.58	0.307
50.71	155.72	0.307
50.72	155.85	0.307
50.74	155.99	0.307
50.75	156.12	0.307
50.76	156.25	0.307
50.78	156.38	0.307
50.79	156.52	0.307
50.80	156.65	0.307
50.82	156.79	0.307
50.83	156.92	0.307
50.84	157.05	0.308
50.86	157.19	0.308
50.87	157.32	0.308
50.88	157.45	0.308
50.90	157.59	0.308
50.91	157.72	0.308
50.92	157.85	0.308
50.94	157.99	0.308
50.95	158.12	0.308
50.96	158.25	0.309
50.98	158.39	0.309
50.99	158.52	0.309
51.00	158.65	0.309
51.02	158.78	0.309
51.03	158.92	0.309
51.04	159.05	0.309
51.06	159.18	0.309
51.07	159.32	0.309
51.08	159.45	0.309
51.10	159.59	0.309
51.11	159.72	0.309
51.12	159.85	0.309
51.14	159.99	0.309
51.15	160.12	0.310
51.16	160.25	0.310
51.18	160.39	0.310
51.19	160.52	0.310
51.20	160.65	0.310
51.22	160.79	0.310
51.23	160.92	0.310
51.24	161.05	0.311
51.26	161.19	0.311
51.27	161.32	0.311
51.28	161.45	0.311
51.30	161.59	0.311
51.31	161.72	0.311
51.32	161.85	0.311
51.34	161.99	0.311
51.35	162.12	0.311
51.36	162.25	0.311
51.38	162.39	0.311
51.39	162.52	0.311
51.40	162.65	0.312
51.42	162.79	0.312
51.43	162.92	0.312
51.44	163.05	0.312
51.46	163.19	0.312
51.47	163.32	0.312
51.48	163.45	0.312
51.50	163.59	0.312
51.51	163.72	0.312
51.52	163.85	0.313
51.54	163.99	0.313
51.55	164.12	0.313
51.56	164.25	0.313
51.58	164.39	0.313
51.59	164.52	0.313
51.60	164.65	0.313
51.62	164.79	0.313
51.63	164.92	0.313
51.64	165.05	0.313
51.66	165.19	0.314
51.67	165.32	0.314
51.68	165.45	0.314
51.70	165.59	0.314
51.71	165.72	0.314
51.72	165.85	0.314
51.74	165.99	0.314
51.75	166.12	0.314
51.76	166.26	0.314
51.78	166.39	0.314
51.79	166.52	0.314
51.80	166.66	0.314
51.82	166.79	0.314
51.83	166.92	0.315
51.84	167.06	0.315
51.86	167.19	0.315
51.87	167.32	0.315
51.88	167.46	0.315
51.90	167.59	0.316
51.91	167.72	0.316
51.92	167.86	0.316
51.94	167.99	0.316
51.95	168.12	0.316
51.96	168.26	0.316
51.98	168.39	0.316
51.99	168.52	0.316
52.00	168.66	0.316
52.02	168.79	0.316
52.03	168.92	0.316
52.04	169.06	0.317
52.06	169.19	0.317
52.07	169.32	0.316
52.08	169.46	0.316
52.10	169.59	0.316
52.11	169.72	0.316
52.12	169.86	0.316
52.14	169.99	0.316
52.15	170.12	0.317
52.16	170.26	0.317
52.18	170.39	0.317
52.19	170.52	0.317
52.20	170.66	0.317
52.22	170.79	0.317
52.23	170.92	0.317
52.24	171.06	0.317
52.26	171.19	0.317
52.27	171.32	0.317
52.28	171.46	0.317
52.30	171.59	0.318
52.31	171.72	0.318
52.32	171.86	0.318
52.34	171.99	0.318
52.35	172.12	0.318
52.36	172.26	0.318
52.38	172.39	0.318
52.39	172.52	0.318
52.40	172.66	0.318
52.42	172.79	0.319
52.43	172.92	0.318
52.44	173.06	0.318
52.46	173.19	0.318
52.47	173.32	0.318
52.48	173.46	0.318
52.50	173.59	0.318
52.51	173.72	0.319
52.52	173.86	0.319
52.54	173.99	0.319
52.55	174.12	0.319
52.56	174.26	0.319
52.58	174.39	0.320
52.59	174.52	0.320
52.60	174.66	0.320
52.62	174.79	0.320
52.63	174.92	0.320
52.64	175.06	0.320
52.66	175.19	0.320
52.67	175.32	0.320
52.68	175.46	0.320
52.70	175.59	0.320
52.71	175.73	0.320
52.72	175.86	0.320
52.74	175.99	0.320
52.75	176.13	0.321
52.76	176.26	0.321
52.78	176.39	0.321
52.79	176.53	0.321
52.80	176.66	0.321
52.82	176.79	0.321
52.83	176.93	0.321
52.84	177.06	0.321
52.86	177.19	0.322
52.87	177.32	0.322
52.88	177.46	0.322
52.90	177.59	0.322
52.91	177.72	0.322
52.92	177.86	0.322
52.94	177.99	0.322
52.95	178.13	0.322
52.96	178.26	0.322
52.98	178.39	0.322
52.99	178.53	0.322
53.00	178.66	0.323
53.02	178.79	0.323
53.03	178.93	0.323
53.04	179.06	0.323
53.06	179.19	0.323
53.07	179.33	0.323
53.08	179.46	0.323
53.10	179.59	0.323
53.11	179.73	0.323
53.12	179.86	0.323
53.14	179.99	0.323
53.15	180.12	0.323
53.16	180.26	0.323
53.18	180.39	0.323
53.19	180.53	0.323
53.20	180.66	0.323
53.22	180.79	0.324
53.23	180.93	0.323
53.24	181.06	0.324
53.26	181.19	0.324
53.27	181.33	0.324
53.28	181.46	0.324
53.30	181.59	0.324
53.31	181.73	0.324
53.32	181.86	0.324
53.34	181.99	0.324
53.35	182.13	0.324
53.36	182.26	0.324
53.38	182.39	0.324
53.39	182.53	0.325
53.40	182.66	0.325
53.42	182.79	0.325
53.43	182.93	0.325
53.44	183.06	0.325
53.46	183.19	0.325
53.47	183.33	0.325
53.48	183.46	0.325
53.50	183.59	0.325
53.51	183.73	0.325
53.52	183.86	0.325
53.54	183.99	0.325
53.55	184.13	0.325
53.56	184.26	0.325
53.58	184.39	0.325
53.59	184.53	0.325
53.60	184.66	0.325
53.62	184.80	0.325
53.63	184.93	0.325
53.64	185.06	0.326
53.66	185.19	0.326
53.67	185.33	0.326
53.68	185.46	0.326
53.70	185.60	0.326
53.71	185.73	0.327
53.72	185.86	0.327
53.74	186.00	0.327
53.75	186.13	0.327
53.76	186.26	0.327
53.78	186.39	0.327
53.79	186.53	0.327
53.80	186.66	0.327
53.82	186.80	0.327
53.83	186.93	0.327
53.84	187.06	0.327
53.86	187.20	0.327
53.87	187.33	0.327
53.88	187.46	0.327
53.90	187.59	0.328
53.91	187.73	0.328
53.92	187.86	0.328
53.94	188.00	0.328
53.95	188.13	0.328
53.96	188.26	0.328
53.98	188.40	0.328
53.99	188.53	0.328
54.00	188.66	0.328
54.02	188.80	0.328
54.03	188.93	0.328
54.04	189.06	0.328
54.06	189.20	0.328
54.07	189.33	0.328
54.08	189.46	0.328
54.10	189.60	0.329
54.11	189.73	0.329
54.12	189.86	0.329
54.14	190.00	0.329
54.15	190.13	0.329
54.16	190.26	0.329
54.18	190.40	0.329
54.19	190.53	0.329
54.20	190.66	0.329
54.22	190.80	0.329
54.23	190.93	0.329
54.24	191.06	0.329
54.26	191.20	0.329
54.27	191.33	0.329
54.28	191.46	0.329
54.30	191.60	0.329
54.31	191.73	0.329
54.32	191.86	0.329
54.34	192.00	0.330
54.35	192.13	0.330
54.36	192.26	0.330
54.38	192.40	0.330
54.39	192.53	0.330
54.40	192.66	0.330
54.42	192.80	0.330
54.43	192.93	0.330
54.44	193.06	0.330
54.46	193.20	0.330
54.47	193.33	0.330
54.48	193.46	0.330
54.50	193.60	0.330
54.51	193.73	0.330
54.52	193.86	0.330
54.54	194.00	0.330
54.55	194.13	0.330
54.56	194.27	0.331
54.58	194.40	0.331
54.59	194.53	0.331
54.60	194.67	0.331
54.62	194.80	0.331
54.63	194.93	0.331
54.64	195.07	0.331
54.66	195.20	0.331
54.67	195.33	0.331
54.68	195.47	0.331
54.70	195.60	0.331
54.71	195.73	0.331
54.72	195.87	0.332
54.74	196.00	0.332
54.75	196.13	0.332
54.76	196.27	0.332
54.78	196.40	0.332
54.79	196.53	0.332
54.80	196.66	0.332
54.82	196.80	0.332
54.83	196.93	0.332
54.84	197.06	0.332
54.86	197.20	0.332
54.87	197.33	0.332
54.88	197.47	0.332
54.90	197.60	0.332
54.91	197.73	0.332
54.92	197.87	0.332
54.94	198.00	0.332
54.95	198.13	0.333
54.96	198.27	0.333
54.98	198.40	0.333
54.99	198.53	0.333
55.00	198.67	0.333
55.02	198.80	0.333
55.03	198.93	0.333
55.04	199.07	0.333
55.06	199.20	0.333
55.07	199.33	0.333
55.08	199.47	0.333
55.10	199.60	0.333
55.11	199.73	0.333
55.12	199.87	0.333
55.14	200.00	0.333
55.15	200.13	0.334
55.16	200.27	0.334
55.18	200.40	0.334
55.19	200.53	0.334
55.20	200.67	0.334
55.22	200.80	0.334
55.23	200.93	0.334
55.24	201.07	0.334
55.26	201.20	0.334
55.27	201.33	0.334
55.28	201.47	0.334
55.30	201.60	0.334
55.31	201.73	0.334
55.32	201.87	0.334
55.34	202.00	0.334
55.35	202.13	0.334
55.36	202.27	0.334
55.38	202.40	0.334
55.39	202.53	0.334
55.40	202.67	0.334
55.42	202.80	0.334
55.43	202.93	0.334
55.44	203.07	0.334
55.46	203.20	0.334
55.47	203.34	0.335
55.48	203.47	0.335
55.50	203.60	0.335
55.51	203.74	0.335
55.52	203.87	0.335
55.54	204.00	0.335
55.55	204.14	0.335
55.56	204.27	0.336
55.58	204.40	0.336
55.59	204.53	0.336
55.60	204.67	0.336
55.62	204.80	0.336
55.63	204.93	0.336
55.64	205.07	0.336
55.66	205.20	0.336
55.67	205.34	0.336
55.68	205.47	0.336
55.70	205.60	0.336
55.71	205.74	0.336
55.72	205.87	0.336
55.74	206.00	0.336
55.75	206.14	0.336
55.76	206.27	0.336
55.78	206.40	0.336
55.79	206.54	0.336
55.80	206.67	0.337
55.82	206.80	0.337
55.83	206.93	0.337
55.84	207.07	0.337
55.86	207.20	0.337
55.87	207.34	0.337
55.88	207.47	0.336
55.90	207.60	0.336
55.91	207.74	0.336
55.92	207.87	0.336
55.94	208.00	0.336
55.95	208.14
55.96	208.27
55.98	208.40
55.99	208.54
56.00