File: Data/2024_09_17_H2O_DSC.txt
Filename	2024_09_17_H2O_DSC
Instrument name	DSC2A-00468 (192.168.1.100)
Operator	CHM343
rundate	9/17/2024
Sample name	2024_09_17_H2O_DSC
proceduresegments	Equilibrate -40.00 °C; Ramp 10.00 °C/min to 40.00 °C; Isothermal 1.0 min; Ramp 10.00 °C/min to -40.00 °C; Isothermal 1.0 min; Ramp 10.00 °C/min to 40.00 °C
[File Parameters]
Run date	9/17/2024 9:27:22 PM
Trios version	5.1.1.46572
Original File Name	C:\ProgramData\TA Instruments\TRIOS\Data\2024_09_17_H2O_DSC.tri
Current File Name	D:\DSC2500\CHM343\2024_09_17_H2O_DSC.tri
[Procedure]
Procedure Name	CHM343_Fall2024_Water
Sample Name	2024_09_17_H2O_DSC
Sample Mass	3.47 mg
Reference Sample Mass	0 mg
Pan Mass	54.2 mg
Pan Number	26
Reference Pan Mass	54 mg
Reference Pan Number	19
Pan Type	Aluminum
Comments	Water - H2O - Al Hermetic Sealed Pan, with ref Al pan.  ASU Online CHM343, Remote DSC experimental lab. Fall 2024.  Group Zoom Data Collection, Sept 17, 2024 from 9-11 pm.  TA Instruments DSC2500.
Project Name	Lab 4 - Fall 2024
Operator	CHM343
Test	Custom
Unload Max Temperature	30
Unload Min Temperature	30
Load Max Temperature	30
Load Min Temperature	30
Stop on Gas Flow Error	Yes
[Signal List]
Signal #1	Time (min)
Signal #2	Temperature (°C)
Signal #3	Heat Flow (mW)
Signal #4	Delta T (µV)
Signal #5	Delta Tzero (µV)
Signal #6	Tzero Temperature (°C)
Signal #7	Cell Purge (mL/min)
Signal #8	Heater Temp (°C)
Signal #9	Power Delivered (W)
Signal #10	Reference Junction Temperature (°C)
Signal #11	Flange Temperature (°C)
Signal #12	Heat Flow Phase (rad)
Signal #13	Total Heat Capacity (J/°C)
Signal #14	Heat Capacity (J/°C)
[Configuration]
Company Name	ASU
Instrument Name	DSC2A-00468
Instrument Type	DSC2500
Serial Number	DSC2A-00468
IP	192.168.1.100
Location of Instrument	MRRC
DisplayType	Unknown
Sample Interval 	0.1 s/pt
Selected Heat Flow	T4P
Exotherm Direction	Down
Cell Serial	DRC2-00792
Lid Type	Standard
Cooler	RCS 90
Leave Cooler on at End of Sequence	On
Gas 2	Nitrogen
Gas Selected	Channel 1
Flow Rate	50 mL/min
Secondary Purge	On
Licensed Heat Flow	Heat Flow T4P
Modulation Licensed	Yes
[Versions]
Common IDD Version	1
Cortex Version	VER 2.10.2.31
Driver	5.0.0.6
GDM Version	1.0.3.3
TouchscreenVersion	1.0.0.16145
FEP Version	1.2.1.21
FEP Bootloader	2.0.0.5
AutoSampler Version	2.1.1.26
Auto Sampler Bootloader	2.0.0.5
FCM Version	1.1.0.3
FCM Bootloader	2.0.0.5
[Experiment Logs]
Experiment Log Entry # 1	Equilibrate Segment -40 (C) Started
Experiment Log Entry # 3	Air Cool is off.
Experiment Log Entry # 5	Ramp Segment 10 C/min to 40 Started
Experiment Log Entry # 7	Isothermal Segment 1 min started
Experiment Log Entry # 9	Ramp Segment 10 C/min to -40 Started
Experiment Log Entry # 11	Isothermal Segment 1 min started
Experiment Log Entry # 13	Ramp Segment 10 C/min to 40 Started
[Method Log]
Method Log Entry # 1	Equilibrate -40 °C
Method Log Entry # 2	(Ramp 69679) Ramp 10 °C/minute to 40 °C
Method Log Entry # 3	Isothermal 1 minutes
Method Log Entry # 4	(Ramp 69681) Ramp 10 °C/minute to -40 °C
Method Log Entry # 5	Isothermal 1 minutes
Method Log Entry # 6	(Ramp 69683) Ramp 10 °C/minute to 40 °C
Cell Serial	DRC2-00792
[T1 Calibration]
Slope	-0.008529666
Offset	9.636258
Initial Temperature	98.23
GUID	f8bfdadc-4977-4fdf-ba6d-0ba9134940c3
[TZero Calibration]
Date Applied	11/29/2022 4:06:13 PM
Description	From -89.059 °C to 396.009 °C at 20.000°C/min
Gas Type	Nitrogen
Pan Type	None
Source Files 1	C:\Users\yargerlab\Desktop\DSC Data\General\TZero_calibration_11_29_22_2nd(2).tri
Source Files 2	C:\Users\yargerlab\Desktop\DSC Data\General\TZero_calibration_11_29_22_2nd(3).tri
Delta T Offset	13.05235
Delta T Slope	-0.007271007
Delta T0 Offset	-13.69128
Delta T0 Slope	0.06063341
[Temperature Calibration]
Date Applied	11/29/2022 7:12:28 PM
Description	From 106.590 °C to 186.590 °C at 10.000°C/min
Gas Type	Nitrogen
Pan Type	Tzero Aluminum Hermetic
Source Files 1	C:\Users\yargerlab\Desktop\DSC Data\General\Indium(6).tri
Measured 1	157.391
Known 1	156.598
[Cell Constant Calibration]
Date Applied	11/29/2022 7:12:29 PM
Description	From 106.590 °C to 186.590 °C at 10.000°C/min
Gas Type	Nitrogen
Pan Type	Tzero Aluminum Hermetic
Source Files 1	C:\Users\yargerlab\Desktop\DSC Data\General\Indium(6).tri
T4P KCell	1.006051
Onset Slope	63.26126 mW/°C
[Direct Cp Calibration]
Date Applied	11/30/2022 11:04:51 AM
Description	From -79.983 °C to 298.409 °C at 10.000°C/min
Gas Type	Nitrogen
Pan Type	Tzero Aluminum Hermetic
Source Files 1	C:\Users\yargerlab\Desktop\DSC Data\General\Sapphire_Heat_Capacity_11_30_22.tri
[Rev Cp Calibration]
Date Applied	11/30/2022 1:58:51 PM
Description	From -79.996 °C to 292.812 °C at 3.000°C/min
Gas Type	Nitrogen
Pan Type	Tzero Aluminum Hermetic
Source Files 1	C:\Users\yargerlab\Desktop\DSC Data\General\Sapphire_MDSC_Calibration_11_30_22.tri
[step]
Ramp 10.00 °C/min to 40.00 °C
Time	Temperature	Heat Flow (Normalized)
min	°C	W/g
0.00	-39.73	-0.112
0.01	-39.73	-0.116
0.01	-39.74	-0.111
0.02	-39.74	-0.106
0.03	-39.74	-0.102
0.03	-39.74	-0.098
0.04	-39.75	-0.094
0.05	-39.75	-0.092
0.05	-39.75	-0.089
0.06	-39.74	-0.087
0.07	-39.74	-0.087
0.07	-39.73	-0.086
0.08	-39.73	-0.086
0.09	-39.71	-0.086
0.09	-39.70	-0.086
0.10	-39.68	-0.087
0.11	-39.66	-0.087
0.11	-39.64	-0.087
0.12	-39.62	-0.087
0.13	-39.59	-0.085
0.13	-39.56	-0.080
0.14	-39.53	-0.071
0.15	-39.49	-0.059
0.15	-39.45	-0.047
0.16	-39.41	-0.036
0.17	-39.37	-0.024
0.17	-39.33	-0.010
0.18	-39.28	0.004
0.19	-39.24	0.017
0.19	-39.19	0.032
0.20	-39.14	0.046
0.21	-39.09	0.061
0.21	-39.04	0.075
0.22	-38.99	0.087
0.23	-38.94	0.101
0.23	-38.89	0.113
0.24	-38.84	0.125
0.25	-38.78	0.135
0.25	-38.73	0.146
0.26	-38.68	0.155
0.27	-38.62	0.163
0.27	-38.57	0.172
0.28	-38.51	0.182
0.29	-38.45	0.191
0.29	-38.40	0.197
0.30	-38.34	0.204
0.31	-38.28	0.209
0.31	-38.22	0.216
0.32	-38.16	0.223
0.33	-38.11	0.229
0.33	-38.04	0.232
0.34	-37.99	0.237
0.35	-37.92	0.244
0.35	-37.86	0.249
0.36	-37.80	0.253
0.37	-37.74	0.257
0.37	-37.68	0.261
0.38	-37.62	0.264
0.39	-37.56	0.269
0.39	-37.50	0.273
0.40	-37.43	0.277
0.41	-37.37	0.278
0.41	-37.31	0.281
0.42	-37.25	0.284
0.43	-37.18	0.286
0.43	-37.12	0.289
0.44	-37.06	0.293
0.45	-37.00	0.294
0.45	-36.93	0.298
0.46	-36.87	0.300
0.47	-36.81	0.301
0.47	-36.74	0.302
0.48	-36.68	0.304
0.49	-36.62	0.306
0.49	-36.55	0.308
0.50	-36.49	0.311
0.51	-36.43	0.311
0.51	-36.36	0.312
0.52	-36.30	0.313
0.53	-36.23	0.314
0.53	-36.17	0.315
0.54	-36.11	0.316
0.55	-36.04	0.316
0.55	-35.98	0.317
0.56	-35.91	0.318
0.57	-35.85	0.319
0.57	-35.78	0.320
0.58	-35.72	0.320
0.59	-35.65	0.321
0.59	-35.59	0.322
0.60	-35.52	0.323
0.61	-35.46	0.324
0.61	-35.39	0.324
0.62	-35.33	0.325
0.63	-35.26	0.326
0.63	-35.20	0.326
0.64	-35.14	0.327
0.65	-35.07	0.327
0.65	-35.01	0.328
0.66	-34.94	0.328
0.67	-34.88	0.329
0.67	-34.81	0.329
0.68	-34.74	0.329
0.69	-34.68	0.330
0.69	-34.61	0.330
0.70	-34.55	0.330
0.71	-34.48	0.331
0.71	-34.42	0.332
0.72	-34.35	0.332
0.73	-34.29	0.332
0.73	-34.22	0.332
0.74	-34.16	0.332
0.75	-34.09	0.332
0.75	-34.03	0.333
0.76	-33.96	0.333
0.77	-33.90	0.333
0.77	-33.83	0.333
0.78	-33.76	0.333
0.79	-33.70	0.333
0.79	-33.63	0.334
0.80	-33.57	0.334
0.81	-33.50	0.334
0.81	-33.44	0.334
0.82	-33.37	0.335
0.83	-33.31	0.335
0.83	-33.24	0.335
0.84	-33.17	0.335
0.85	-33.11	0.335
0.85	-33.04	0.335
0.86	-32.97	0.336
0.87	-32.91	0.336
0.87	-32.85	0.336
0.88	-32.78	0.336
0.89	-32.71	0.337
0.89	-32.65	0.337
0.90	-32.58	0.337
0.91	-32.52	0.337
0.91	-32.45	0.337
0.92	-32.38	0.337
0.93	-32.32	0.338
0.93	-32.25	0.338
0.94	-32.19	0.338
0.95	-32.12	0.338
0.95	-32.05	0.338
0.96	-31.99	0.338
0.97	-31.92	0.339
0.97	-31.86	0.339
0.98	-31.79	0.339
0.99	-31.72	0.339
0.99	-31.66	0.339
1.00	-31.59	0.340
1.01	-31.53	0.340
1.01	-31.46	0.340
1.02	-31.39	0.340
1.03	-31.33	0.340
1.03	-31.26	0.340
1.04	-31.20	0.341
1.05	-31.13	0.341
1.05	-31.06	0.341
1.06	-31.00	0.341
1.07	-30.93	0.341
1.07	-30.87	0.341
1.08	-30.80	0.341
1.09	-30.73	0.342
1.09	-30.67	0.342
1.10	-30.60	0.342
1.11	-30.53	0.342
1.11	-30.47	0.342
1.12	-30.40	0.342
1.13	-30.34	0.343
1.13	-30.27	0.343
1.14	-30.21	0.343
1.15	-30.14	0.343
1.15	-30.07	0.343
1.16	-30.01	0.343
1.17	-29.94	0.343
1.17	-29.87	0.343
1.18	-29.81	0.344
1.19	-29.74	0.344
1.19	-29.67	0.344
1.20	-29.61	0.344
1.21	-29.54	0.344
1.21	-29.48	0.344
1.22	-29.41	0.344
1.23	-29.34	0.344
1.23	-29.28	0.345
1.24	-29.21	0.345
1.25	-29.14	0.345
1.25	-29.08	0.345
1.26	-29.01	0.345
1.27	-28.94	0.345
1.27	-28.88	0.345
1.28	-28.81	0.346
1.29	-28.74	0.346
1.29	-28.68	0.346
1.30	-28.61	0.346
1.31	-28.54	0.346
1.31	-28.48	0.346
1.32	-28.41	0.346
1.33	-28.35	0.346
1.33	-28.28	0.346
1.34	-28.21	0.347
1.35	-28.15	0.347
1.35	-28.08	0.347
1.36	-28.01	0.347
1.37	-27.95	0.347
1.37	-27.88	0.347
1.38	-27.82	0.347
1.39	-27.75	0.347
1.39	-27.68	0.347
1.40	-27.62	0.347
1.41	-27.55	0.348
1.41	-27.48	0.348
1.42	-27.42	0.348
1.43	-27.35	0.348
1.43	-27.28	0.348
1.44	-27.22	0.348
1.45	-27.15	0.349
1.45	-27.09	0.349
1.46	-27.02	0.349
1.47	-26.95	0.349
1.47	-26.89	0.349
1.48	-26.82	0.349
1.49	-26.75	0.349
1.49	-26.69	0.349
1.50	-26.62	0.349
1.51	-26.55	0.349
1.51	-26.49	0.350
1.52	-26.42	0.350
1.53	-26.35	0.350
1.53	-26.29	0.350
1.54	-26.22	0.350
1.55	-26.15	0.350
1.55	-26.09	0.350
1.56	-26.02	0.350
1.57	-25.95	0.350
1.57	-25.89	0.350
1.58	-25.82	0.350
1.59	-25.75	0.350
1.59	-25.69	0.350
1.60	-25.62	0.350
1.61	-25.56	0.350
1.61	-25.49	0.350
1.62	-25.42	0.351
1.63	-25.36	0.351
1.63	-25.29	0.351
1.64	-25.22	0.351
1.65	-25.16	0.351
1.65	-25.09	0.351
1.66	-25.02	0.351
1.67	-24.96	0.351
1.67	-24.89	0.351
1.68	-24.82	0.351
1.69	-24.76	0.351
1.69	-24.69	0.351
1.70	-24.62	0.351
1.71	-24.56	0.352
1.71	-24.49	0.352
1.72	-24.42	0.352
1.73	-24.36	0.352
1.73	-24.29	0.352
1.74	-24.22	0.352
1.75	-24.16	0.352
1.75	-24.09	0.352
1.76	-24.02	0.352
1.77	-23.96	0.352
1.77	-23.89	0.352
1.78	-23.82	0.352
1.79	-23.76	0.352
1.79	-23.69	0.352
1.80	-23.62	0.352
1.81	-23.56	0.352
1.81	-23.49	0.352
1.82	-23.42	0.353
1.83	-23.36	0.353
1.83	-23.29	0.353
1.84	-23.22	0.353
1.85	-23.16	0.353
1.85	-23.09	0.353
1.86	-23.02	0.353
1.87	-22.96	0.353
1.87	-22.89	0.353
1.88	-22.82	0.353
1.89	-22.76	0.353
1.89	-22.69	0.353
1.90	-22.63	0.353
1.91	-22.56	0.353
1.91	-22.49	0.353
1.92	-22.43	0.354
1.93	-22.36	0.354
1.93	-22.29	0.354
1.94	-22.22	0.354
1.95	-22.16	0.354
1.95	-22.09	0.354
1.96	-22.03	0.354
1.97	-21.96	0.354
1.97	-21.89	0.354
1.98	-21.82	0.354
1.99	-21.76	0.354
1.99	-21.69	0.354
2.00	-21.62	0.354
2.01	-21.56	0.354
2.01	-21.49	0.354
2.02	-21.42	0.354
2.03	-21.36	0.354
2.03	-21.29	0.354
2.04	-21.22	0.354
2.05	-21.16	0.355
2.05	-21.09	0.355
2.06	-21.03	0.355
2.07	-20.96	0.355
2.07	-20.89	0.355
2.08	-20.82	0.355
2.09	-20.76	0.355
2.09	-20.69	0.355
2.10	-20.63	0.355
2.11	-20.56	0.355
2.11	-20.49	0.355
2.12	-20.43	0.355
2.13	-20.36	0.355
2.13	-20.29	0.355
2.14	-20.23	0.355
2.15	-20.16	0.355
2.15	-20.09	0.355
2.16	-20.02	0.355
2.17	-19.96	0.355
2.17	-19.89	0.356
2.18	-19.83	0.356
2.19	-19.76	0.356
2.19	-19.69	0.356
2.20	-19.63	0.356
2.21	-19.56	0.356
2.21	-19.49	0.356
2.22	-19.42	0.356
2.23	-19.36	0.356
2.23	-19.29	0.356
2.24	-19.23	0.356
2.25	-19.16	0.356
2.25	-19.09	0.356
2.26	-19.03	0.356
2.27	-18.96	0.356
2.27	-18.89	0.356
2.28	-18.83	0.356
2.29	-18.76	0.356
2.29	-18.69	0.357
2.30	-18.62	0.357
2.31	-18.56	0.357
2.31	-18.49	0.357
2.32	-18.43	0.357
2.33	-18.36	0.357
2.33	-18.29	0.357
2.34	-18.23	0.357
2.35	-18.16	0.357
2.35	-18.09	0.357
2.36	-18.02	0.357
2.37	-17.96	0.357
2.37	-17.89	0.357
2.38	-17.83	0.357
2.39	-17.76	0.357
2.39	-17.69	0.357
2.40	-17.63	0.357
2.41	-17.56	0.357
2.41	-17.49	0.358
2.42	-17.43	0.358
2.43	-17.36	0.358
2.43	-17.29	0.358
2.44	-17.23	0.358
2.45	-17.16	0.358
2.45	-17.09	0.358
2.46	-17.03	0.358
2.47	-16.96	0.358
2.47	-16.89	0.358
2.48	-16.82	0.358
2.49	-16.76	0.358
2.49	-16.69	0.358
2.50	-16.62	0.358
2.51	-16.56	0.358
2.51	-16.49	0.358
2.52	-16.43	0.358
2.53	-16.36	0.359
2.53	-16.29	0.359
2.54	-16.23	0.359
2.55	-16.16	0.359
2.55	-16.09	0.359
2.56	-16.03	0.359
2.57	-15.96	0.359
2.57	-15.89	0.359
2.58	-15.82	0.359
2.59	-15.76	0.359
2.59	-15.69	0.359
2.60	-15.62	0.359
2.61	-15.56	0.359
2.61	-15.49	0.359
2.62	-15.43	0.360
2.63	-15.36	0.360
2.63	-15.29	0.360
2.64	-15.23	0.360
2.65	-15.16	0.360
2.65	-15.09	0.360
2.66	-15.02	0.360
2.67	-14.96	0.360
2.67	-14.89	0.360
2.68	-14.82	0.360
2.69	-14.76	0.360
2.69	-14.69	0.360
2.70	-14.62	0.360
2.71	-14.56	0.360
2.71	-14.49	0.361
2.72	-14.42	0.361
2.73	-14.36	0.361
2.73	-14.29	0.361
2.74	-14.22	0.361
2.75	-14.16	0.361
2.75	-14.09	0.361
2.76	-14.02	0.361
2.77	-13.96	0.361
2.77	-13.89	0.361
2.78	-13.82	0.361
2.79	-13.76	0.361
2.79	-13.69	0.361
2.80	-13.62	0.361
2.81	-13.56	0.361
2.81	-13.49	0.362
2.82	-13.42	0.362
2.83	-13.36	0.362
2.83	-13.29	0.362
2.84	-13.22	0.362
2.85	-13.16	0.362
2.85	-13.09	0.362
2.86	-13.02	0.362
2.87	-12.96	0.362
2.87	-12.89	0.362
2.88	-12.82	0.362
2.89	-12.76	0.362
2.89	-12.69	0.362
2.90	-12.62	0.362
2.91	-12.56	0.363
2.91	-12.49	0.363
2.92	-12.42	0.363
2.93	-12.36	0.363
2.93	-12.29	0.363
2.94	-12.22	0.363
2.95	-12.15	0.363
2.95	-12.09	0.363
2.96	-12.02	0.363
2.97	-11.96	0.363
2.97	-11.89	0.363
2.98	-11.82	0.363
2.99	-11.76	0.363
2.99	-11.69	0.363
3.00	-11.62	0.363
3.01	-11.56	0.364
3.01	-11.49	0.364
3.02	-11.42	0.364
3.03	-11.35	0.364
3.03	-11.29	0.364
3.04	-11.22	0.364
3.05	-11.15	0.364
3.05	-11.09	0.364
3.06	-11.02	0.364
3.07	-10.95	0.364
3.07	-10.89	0.364
3.08	-10.82	0.364
3.09	-10.75	0.364
3.09	-10.69	0.364
3.10	-10.62	0.364
3.11	-10.55	0.365
3.11	-10.49	0.365
3.12	-10.42	0.365
3.13	-10.35	0.365
3.13	-10.29	0.365
3.14	-10.22	0.365
3.15	-10.15	0.365
3.15	-10.09	0.365
3.16	-10.02	0.365
3.17	-9.95	0.365
3.17	-9.89	0.366
3.18	-9.82	0.366
3.19	-9.75	0.366
3.19	-9.69	0.366
3.20	-9.62	0.366
3.21	-9.56	0.366
3.21	-9.49	0.366
3.22	-9.42	0.366
3.23	-9.35	0.366
3.23	-9.29	0.366
3.24	-9.22	0.366
3.25	-9.15	0.366
3.25	-9.09	0.367
3.26	-9.02	0.367
3.27	-8.95	0.367
3.27	-8.89	0.367
3.28	-8.82	0.367
3.29	-8.75	0.367
3.29	-8.69	0.367
3.30	-8.62	0.367
3.31	-8.55	0.367
3.31	-8.49	0.367
3.32	-8.42	0.367
3.33	-8.35	0.367
3.33	-8.29	0.368
3.34	-8.22	0.368
3.35	-8.15	0.368
3.35	-8.09	0.368
3.36	-8.02	0.368
3.37	-7.95	0.368
3.37	-7.89	0.368
3.38	-7.82	0.368
3.39	-7.75	0.368
3.39	-7.69	0.368
3.40	-7.62	0.369
3.41	-7.55	0.369
3.41	-7.49	0.369
3.42	-7.42	0.369
3.43	-7.35	0.369
3.43	-7.28	0.369
3.44	-7.22	0.369
3.45	-7.15	0.369
3.45	-7.09	0.369
3.46	-7.02	0.370
3.47	-6.95	0.370
3.47	-6.89	0.370
3.48	-6.82	0.370
3.49	-6.75	0.370
3.49	-6.69	0.370
3.50	-6.62	0.370
3.51	-6.55	0.370
3.51	-6.48	0.370
3.52	-6.42	0.370
3.53	-6.35	0.371
3.53	-6.29	0.371
3.54	-6.22	0.371
3.55	-6.15	0.371
3.55	-6.09	0.371
3.56	-6.02	0.371
3.57	-5.95	0.371
3.57	-5.89	0.372
3.58	-5.82	0.372
3.59	-5.75	0.372
3.59	-5.69	0.372
3.60	-5.62	0.372
3.61	-5.55	0.372
3.61	-5.49	0.372
3.62	-5.42	0.373
3.63	-5.35	0.373
3.63	-5.29	0.373
3.64	-5.22	0.373
3.65	-5.15	0.374
3.65	-5.08	0.374
3.66	-5.02	0.374
3.67	-4.95	0.374
3.67	-4.89	0.375
3.68	-4.82	0.375
3.69	-4.75	0.375
3.69	-4.69	0.375
3.70	-4.62	0.375
3.71	-4.55	0.376
3.71	-4.48	0.376
3.72	-4.42	0.376
3.73	-4.35	0.376
3.73	-4.28	0.377
3.74	-4.22	0.377
3.75	-4.15	0.377
3.75	-4.08	0.378
3.76	-4.02	0.378
3.77	-3.95	0.379
3.77	-3.89	0.380
3.78	-3.82	0.380
3.79	-3.75	0.381
3.79	-3.69	0.382
3.80	-3.62	0.383
3.81	-3.55	0.385
3.81	-3.49	0.386
3.82	-3.42	0.389
3.83	-3.35	0.390
3.83	-3.29	0.391
3.84	-3.22	0.393
3.85	-3.15	0.396
3.85	-3.09	0.399
3.86	-3.02	0.401
3.87	-2.95	0.404
3.87	-2.89	0.410
3.88	-2.82	0.413
3.89	-2.76	0.415
3.89	-2.69	0.419
3.90	-2.62	0.426
3.91	-2.56	0.430
3.91	-2.49	0.435
3.92	-2.43	0.444
3.93	-2.36	0.454
3.93	-2.29	0.462
3.94	-2.23	0.474
3.95	-2.16	0.486
3.95	-2.10	0.502
3.96	-2.03	0.522
3.97	-1.97	0.547
3.97	-1.90	0.577
3.98	-1.84	0.616
3.99	-1.78	0.665
3.99	-1.72	0.728
4.00	-1.66	0.810
4.01	-1.60	0.910
4.01	-1.55	1.035
4.02	-1.49	1.189
4.03	-1.44	1.366
4.03	-1.40	1.560
4.04	-1.36	1.765
4.05	-1.32	1.976
4.05	-1.28	2.180
4.06	-1.25	2.377
4.07	-1.21	2.569
4.07	-1.18	2.753
4.08	-1.15	2.933
4.09	-1.12	3.131
4.09	-1.09	3.327
4.10	-1.07	3.507
4.11	-1.04	3.694
4.11	-1.01	3.863
4.12	-0.99	4.025
4.13	-0.96	4.181
4.13	-0.94	4.333
4.14	-0.91	4.481
4.15	-0.89	4.625
4.15	-0.86	4.765
4.16	-0.83	4.902
4.17	-0.80	5.034
4.17	-0.77	5.170
4.18	-0.75	5.300
4.19	-0.72	5.428
4.19	-0.69	5.554
4.20	-0.66	5.678
4.21	-0.62	5.800
4.21	-0.59	5.918
4.22	-0.56	6.035
4.23	-0.53	6.151
4.23	-0.50	6.262
4.24	-0.46	6.370
4.25	-0.43	6.479
4.25	-0.39	6.582
4.26	-0.36	6.685
4.27	-0.32	6.787
4.27	-0.29	6.887
4.28	-0.25	6.981
4.29	-0.21	7.072
4.29	-0.17	7.160
4.30	-0.13	7.244
4.31	-0.09	7.327
4.31	-0.05	7.408
4.32	-0.01	7.486
4.33	0.03	7.562
4.33	0.07	7.637
4.34	0.11	7.705
4.35	0.16	7.770
4.35	0.20	7.832
4.36	0.25	7.891
4.37	0.29	7.952
4.37	0.34	8.012
4.38	0.39	8.069
4.39	0.43	8.133
4.39	0.48	8.204
4.40	0.53	8.274
4.41	0.58	8.339
4.41	0.63	8.429
4.42	0.67	8.763
4.43	0.70	9.692
4.43	0.69	10.866
4.44	0.67	11.661
4.45	0.64	11.989
4.45	0.63	11.893
4.46	0.63	11.570
4.47	0.65	11.203
4.47	0.69	10.914
4.48	0.74	10.744
4.49	0.78	10.673
4.49	0.83	10.657
4.50	0.89	10.670
4.51	0.94	10.692
4.51	0.99	10.717
4.52	1.04	10.739
4.53	1.10	10.760
4.53	1.15	10.777
4.54	1.21	10.783
4.55	1.27	10.787
4.55	1.33	10.785
4.56	1.38	10.776
4.57	1.45	10.756
4.57	1.51	10.717
4.58	1.57	10.666
4.59	1.64	10.605
4.59	1.71	10.533
4.60	1.78	10.444
4.61	1.85	10.344
4.61	1.92	10.241
4.62	2.00	10.127
4.63	2.08	9.984
4.63	2.16	9.803
4.64	2.25	9.617
4.65	2.34	9.427
4.65	2.43	9.214
4.66	2.53	8.989
4.67	2.62	8.745
4.67	2.73	8.505
4.68	2.83	8.278
4.69	2.94	8.039
4.69	3.05	7.775
4.70	3.16	7.483
4.71	3.27	7.167
4.71	3.39	6.828
4.72	3.52	6.461
4.73	3.65	6.065
4.73	3.78	5.643
4.74	3.92	5.195
4.75	4.06	4.731
4.75	4.21	4.304
4.76	4.35	3.969
4.77	4.50	3.717
4.77	4.65	3.513
4.78	4.79	3.334
4.79	4.92	3.177
4.79	5.06	3.032
4.80	5.19	2.903
4.81	5.31	2.781
4.81	5.44	2.668
4.82	5.56	2.565
4.83	5.68	2.463
4.83	5.79	2.370
4.84	5.90	2.283
4.85	6.01	2.198
4.85	6.12	2.117
4.86	6.23	2.042
4.87	6.33	1.971
4.87	6.43	1.904
4.88	6.53	1.840
4.89	6.63	1.778
4.89	6.73	1.721
4.90	6.82	1.668
4.91	6.91	1.617
4.91	7.01	1.567
4.92	7.10	1.521
4.93	7.19	1.478
4.93	7.27	1.435
4.94	7.36	1.394
4.95	7.45	1.358
4.95	7.53	1.330
4.96	7.61	1.296
4.97	7.70	1.253
4.97	7.78	1.220
4.98	7.86	1.204
4.99	7.94	1.185
4.99	8.02	1.156
5.00	8.10	1.125
5.01	8.18	1.101
5.01	8.26	1.083
5.02	8.33	1.063
5.03	8.41	1.046
5.03	8.48	1.027
5.04	8.56	1.008
5.05	8.63	0.992
5.05	8.71	0.978
5.06	8.78	0.964
5.07	8.86	0.949
5.07	8.93	0.937
5.08	9.00	0.925
5.09	9.08	0.911
5.09	9.15	0.900
5.10	9.22	0.892
5.11	9.29	0.883
5.11	9.36	0.871
5.12	9.44	0.863
5.13	9.51	0.856
5.13	9.58	0.846
5.14	9.65	0.838
5.15	9.72	0.833
5.15	9.79	0.827
5.16	9.86	0.820
5.17	9.93	0.814
5.17	10.00	0.806
5.18	10.07	0.802
5.19	10.14	0.798
5.19	10.21	0.793
5.20	10.28	0.788
5.21	10.34	0.785
5.21	10.41	0.780
5.22	10.48	0.775
5.23	10.55	0.775
5.23	10.62	0.768
5.24	10.69	0.764
5.25	10.75	0.764
5.25	10.82	0.761
5.26	10.89	0.757
5.27	10.96	0.755
5.27	11.03	0.754
5.28	11.09	0.750
5.29	11.16	0.747
5.29	11.23	0.746
5.30	11.30	0.744
5.31	11.37	0.741
5.31	11.43	0.741
5.32	11.50	0.740
5.33	11.57	0.739
5.33	11.64	0.738
5.34	11.70	0.734
5.35	11.77	0.732
5.35	11.84	0.732
5.36	11.91	0.731
5.37	11.97	0.731
5.37	12.04	0.730
5.38	12.11	0.729
5.39	12.17	0.728
5.39	12.24	0.728
5.40	12.31	0.727
5.41	12.38	0.726
5.41	12.44	0.725
5.42	12.51	0.725
5.43	12.58	0.725
5.43	12.65	0.724
5.44	12.71	0.724
5.45	12.78	0.724
5.45	12.85	0.723
5.46	12.91	0.723
5.47	12.98	0.722
5.47	13.05	0.722
5.48	13.12	0.721
5.49	13.18	0.721
5.49	13.25	0.721
5.50	13.32	0.721
5.51	13.38	0.720
5.51	13.45	0.720
5.52	13.52	0.720
5.53	13.58	0.720
5.53	13.65	0.720
5.54	13.72	0.719
5.55	13.78	0.719
5.55	13.85	0.719
5.56	13.92	0.719
5.57	13.98	0.718
5.57	14.05	0.718
5.58	14.12	0.718
5.59	14.18	0.718
5.59	14.25	0.718
5.60	14.32	0.717
5.61	14.39	0.717
5.61	14.45	0.717
5.62	14.52	0.717
5.63	14.58	0.717
5.63	14.65	0.716
5.64	14.72	0.716
5.65	14.79	0.716
5.65	14.85	0.716
5.66	14.92	0.716
5.67	14.99	0.716
5.67	15.05	0.715
5.68	15.12	0.715
5.69	15.19	0.715
5.69	15.25	0.715
5.70	15.32	0.715
5.71	15.39	0.715
5.71	15.45	0.714
5.72	15.52	0.714
5.73	15.59	0.714
5.73	15.65	0.714
5.74	15.72	0.714
5.75	15.79	0.714
5.75	15.86	0.714
5.76	15.92	0.714
5.77	15.99	0.713
5.77	16.05	0.713
5.78	16.12	0.713
5.79	16.19	0.713
5.79	16.26	0.713
5.80	16.32	0.713
5.81	16.39	0.713
5.81	16.46	0.713
5.82	16.52	0.713
5.83	16.59	0.712
5.83	16.66	0.712
5.84	16.72	0.712
5.85	16.79	0.712
5.85	16.86	0.712
5.86	16.92	0.712
5.87	16.99	0.712
5.87	17.06	0.712
5.88	17.12	0.712
5.89	17.19	0.712
5.89	17.26	0.712
5.90	17.32	0.712
5.91	17.39	0.712
5.91	17.46	0.712
5.92	17.52	0.712
5.93	17.59	0.711
5.93	17.66	0.711
5.94	17.72	0.711
5.95	17.79	0.711
5.95	17.86	0.711
5.96	17.92	0.711
5.97	17.99	0.711
5.97	18.06	0.711
5.98	18.13	0.711
5.99	18.19	0.711
5.99	18.26	0.711
6.00	18.33	0.711
6.01	18.39	0.711
6.01	18.46	0.711
6.02	18.53	0.711
6.03	18.59	0.711
6.03	18.66	0.711
6.04	18.73	0.711
6.05	18.79	0.711
6.05	18.86	0.711
6.06	18.93	0.711
6.07	18.99	0.710
6.07	19.06	0.710
6.08	19.13	0.710
6.09	19.19	0.710
6.09	19.26	0.710
6.10	19.33	0.710
6.11	19.39	0.710
6.11	19.46	0.710
6.12	19.53	0.710
6.13	19.59	0.710
6.13	19.66	0.710
6.14	19.73	0.710
6.15	19.79	0.710
6.15	19.86	0.710
6.16	19.93	0.710
6.17	19.99	0.710
6.17	20.06	0.710
6.18	20.13	0.710
6.19	20.19	0.710
6.19	20.26	0.710
6.20	20.33	0.710
6.21	20.40	0.710
6.21	20.46	0.710
6.22	20.53	0.710
6.23	20.59	0.710
6.23	20.66	0.710
6.24	20.73	0.710
6.25	20.79	0.710
6.25	20.86	0.710
6.26	20.93	0.710
6.27	20.99	0.710
6.27	21.06	0.710
6.28	21.13	0.710
6.29	21.20	0.710
6.29	21.26	0.710
6.30	21.33	0.710
6.31	21.40	0.710
6.31	21.46	0.710
6.32	21.53	0.710
6.33	21.59	0.710
6.33	21.66	0.710
6.34	21.73	0.710
6.35	21.79	0.710
6.35	21.86	0.710
6.36	21.93	0.710
6.37	22.00	0.710
6.37	22.06	0.710
6.38	22.13	0.710
6.39	22.20	0.710
6.39	22.26	0.710
6.40	22.33	0.710
6.41	22.40	0.710
6.41	22.46	0.710
6.42	22.53	0.710
6.43	22.60	0.710
6.43	22.66	0.710
6.44	22.73	0.710
6.45	22.80	0.710
6.45	22.86	0.710
6.46	22.93	0.710
6.47	23.00	0.710
6.47	23.06	0.710
6.48	23.13	0.710
6.49	23.20	0.710
6.49	23.26	0.710
6.50	23.33	0.710
6.51	23.40	0.710
6.51	23.46	0.710
6.52	23.53	0.710
6.53	23.60	0.710
6.53	23.66	0.710
6.54	23.73	0.710
6.55	23.80	0.710
6.55	23.86	0.710
6.56	23.93	0.710
6.57	24.00	0.710
6.57	24.06	0.710
6.58	24.13	0.710
6.59	24.20	0.710
6.59	24.26	0.710
6.60	24.33	0.710
6.61	24.40	0.710
6.61	24.47	0.710
6.62	24.53	0.710
6.63	24.60	0.710
6.63	24.67	0.710
6.64	24.73	0.710
6.65	24.80	0.710
6.65	24.86	0.710
6.66	24.93	0.710
6.67	25.00	0.710
6.67	25.07	0.710
6.68	25.13	0.710
6.69	25.20	0.710
6.69	25.27	0.710
6.70	25.33	0.710
6.71	25.40	0.710
6.71	25.47	0.710
6.72	25.53	0.710
6.73	25.60	0.710
6.73	25.67	0.710
6.74	25.73	0.711
6.75	25.80	0.711
6.75	25.87	0.711
6.76	25.93	0.711
6.77	26.00	0.711
6.77	26.07	0.711
6.78	26.13	0.711
6.79	26.20	0.711
6.79	26.27	0.711
6.80	26.33	0.711
6.81	26.40	0.711
6.81	26.47	0.711
6.82	26.53	0.711
6.83	26.60	0.711
6.83	26.67	0.711
6.84	26.73	0.711
6.85	26.80	0.711
6.85	26.87	0.711
6.86	26.93	0.711
6.87	27.00	0.711
6.87	27.07	0.711
6.88	27.13	0.711
6.89	27.20	0.711
6.89	27.27	0.711
6.90	27.34	0.711
6.91	27.40	0.711
6.91	27.47	0.711
6.92	27.54	0.711
6.93	27.60	0.711
6.93	27.67	0.711
6.94	27.74	0.711
6.95	27.80	0.711
6.95	27.87	0.711
6.96	27.93	0.711
6.97	28.00	0.711
6.97	28.07	0.711
6.98	28.14	0.711
6.99	28.20	0.711
6.99	28.27	0.711
7.00	28.34	0.711
7.01	28.40	0.711
7.01	28.47	0.711
7.02	28.54	0.711
7.03	28.60	0.711
7.03	28.67	0.711
7.04	28.74	0.711
7.05	28.80	0.711
7.05	28.87	0.712
7.06	28.94	0.712
7.07	29.00	0.712
7.07	29.07	0.712
7.08	29.14	0.712
7.09	29.20	0.712
7.09	29.27	0.712
7.10	29.34	0.712
7.11	29.40	0.712
7.11	29.47	0.712
7.12	29.54	0.712
7.13	29.61	0.712
7.13	29.67	0.712
7.14	29.74	0.712
7.15	29.80	0.712
7.15	29.87	0.712
7.16	29.94	0.712
7.17	30.00	0.712
7.17	30.07	0.712
7.18	30.14	0.712
7.19	30.21	0.712
7.19	30.27	0.712
7.20	30.34	0.712
7.21	30.41	0.712
7.21	30.47	0.712
7.22	30.54	0.712
7.23	30.61	0.712
7.23	30.67	0.712
7.24	30.74	0.713
7.25	30.81	0.713
7.25	30.87	0.713
7.26	30.94	0.713
7.27	31.01	0.713
7.27	31.07	0.713
7.28	31.14	0.713
7.29	31.21	0.713
7.29	31.27	0.713
7.30	31.34	0.713
7.31	31.41	0.713
7.31	31.47	0.713
7.32	31.54	0.713
7.33	31.61	0.713
7.33	31.67	0.713
7.34	31.74	0.713
7.35	31.81	0.713
7.35	31.87	0.713
7.36	31.94	0.713
7.37	32.01	0.713
7.37	32.07	0.713
7.38	32.14	0.713
7.39	32.21	0.713
7.39	32.27	0.713
7.40	32.34	0.713
7.41	32.41	0.713
7.41	32.47	0.714
7.42	32.54	0.714
7.43	32.61	0.714
7.43	32.67	0.714
7.44	32.74	0.714
7.45	32.81	0.714
7.45	32.87	0.714
7.46	32.94	0.714
7.47	33.01	0.714
7.47	33.07	0.714
7.48	33.14	0.714
7.49	33.21	0.714
7.49	33.27	0.714
7.50	33.34	0.714
7.51	33.41	0.714
7.51	33.47	0.714
7.52	33.54	0.714
7.53	33.61	0.714
7.53	33.68	0.714
7.54	33.74	0.714
7.55	33.81	0.714
7.55	33.88	0.714
7.56	33.94	0.714
7.57	34.01	0.714
7.57	34.08	0.714
7.58	34.14	0.714
7.59	34.21	0.714
7.59	34.27	0.714
7.60	34.34	0.714
7.61	34.41	0.714
7.61	34.48	0.714
7.62	34.54	0.714
7.63	34.61	0.715
7.63	34.68	0.715
7.64	34.74	0.715
7.65	34.81	0.715
7.65	34.88	0.715
7.66	34.94	0.715
7.67	35.01	0.715
7.67	35.08	0.715
7.68	35.14	0.715
7.69	35.21	0.715
7.69	35.28	0.715
7.70	35.34	0.715
7.71	35.41	0.715
7.71	35.48	0.715
7.72	35.54	0.715
7.73	35.61	0.715
7.73	35.68	0.715
7.74	35.74	0.715
7.75	35.81	0.715
7.75	35.88	0.715
7.76	35.94	0.715
7.77	36.01	0.715
7.77	36.08	0.715
7.78	36.15	0.715
7.79	36.21	0.715
7.79	36.28	0.715
7.80	36.35	0.715
7.81	36.41	0.715
7.81	36.48	0.715
7.82	36.55	0.715
7.83	36.61	0.715
7.83	36.68	0.715
7.84	36.74	0.715
7.85	36.81	0.715
7.85	36.88	0.716
7.86	36.95	0.716
7.87	37.01	0.716
7.87	37.08	0.716
7.88	37.15	0.716
7.89	37.21	0.716
7.89	37.28	0.716
7.90	37.35	0.716
7.91	37.41	0.716
7.91	37.48	0.716
7.92	37.55	0.716
7.93	37.61	0.716
7.93	37.68	0.716
7.94	37.75	0.716
7.95	37.81	0.716
7.95	37.88	0.716
7.96	37.95	0.716
7.97	38.01	0.716
7.97	38.08	0.716
7.98	38.15	0.716
7.99	38.21	0.716
7.99	38.28	0.716
8.00	38.30	0.716

[step]
Ramp 10.00 °C/min to -40.00 °C
Time	Temperature	Heat Flow (Normalized)
min	°C	W/g
9.00	40.07	-0.023
9.00	40.07	-0.023
9.01	40.07	-0.023
9.02	40.07	-0.023
9.02	40.06	-0.023
9.03	40.06	-0.024
9.04	40.06	-0.024
9.04	40.06	-0.024
9.05	40.05	-0.024
9.06	40.05	-0.022
9.06	40.04	-0.018
9.07	40.02	-0.013
9.08	40.01	-0.010
9.08	39.99	-0.008
9.09	39.98	-0.009
9.10	39.95	-0.010
9.10	39.93	-0.012
9.11	39.90	-0.029
9.12	39.87	-0.051
9.12	39.84	-0.070
9.13	39.80	-0.089
9.14	39.76	-0.112
9.14	39.73	-0.137
9.15	39.69	-0.164
9.16	39.64	-0.192
9.16	39.60	-0.220
9.17	39.55	-0.246
9.18	39.51	-0.274
9.18	39.46	-0.303
9.19	39.41	-0.330
9.20	39.36	-0.356
9.20	39.31	-0.378
9.21	39.26	-0.402
9.22	39.20	-0.424
9.22	39.15	-0.445
9.23	39.10	-0.464
9.24	39.04	-0.479
9.24	38.99	-0.497
9.25	38.93	-0.511
9.26	38.88	-0.528
9.26	38.82	-0.541
9.27	38.77	-0.552
9.28	38.71	-0.566
9.28	38.65	-0.575
9.29	38.59	-0.586
9.30	38.53	-0.598
9.30	38.48	-0.606
9.31	38.42	-0.614
9.32	38.36	-0.622
9.32	38.30	-0.629
9.33	38.24	-0.639
9.34	38.18	-0.647
9.34	38.11	-0.652
9.35	38.05	-0.659
9.36	37.99	-0.664
9.36	37.93	-0.672
9.37	37.87	-0.679
9.38	37.81	-0.683
9.38	37.75	-0.689
9.39	37.68	-0.695
9.40	37.62	-0.699
9.40	37.56	-0.704
9.41	37.50	-0.707
9.42	37.43	-0.711
9.42	37.37	-0.715
9.43	37.31	-0.718
9.44	37.24	-0.722
9.44	37.18	-0.723
9.45	37.12	-0.726
9.46	37.05	-0.729
9.46	36.99	-0.734
9.47	36.92	-0.735
9.48	36.86	-0.737
9.48	36.80	-0.740
9.49	36.73	-0.742
9.50	36.67	-0.744
9.50	36.60	-0.746
9.51	36.54	-0.749
9.52	36.48	-0.750
9.52	36.41	-0.750
9.53	36.35	-0.752
9.54	36.28	-0.753
9.54	36.22	-0.754
9.55	36.15	-0.755
9.56	36.09	-0.758
9.56	36.02	-0.760
9.57	35.96	-0.762
9.58	35.89	-0.762
9.58	35.83	-0.762
9.59	35.76	-0.763
9.60	35.70	-0.764
9.60	35.63	-0.765
9.61	35.57	-0.766
9.62	35.50	-0.766
9.62	35.44	-0.768
9.63	35.37	-0.768
9.64	35.31	-0.768
9.64	35.24	-0.769
9.65	35.17	-0.770
9.66	35.11	-0.771
9.66	35.04	-0.771
9.67	34.98	-0.771
9.68	34.91	-0.772
9.68	34.85	-0.773
9.69	34.78	-0.774
9.70	34.72	-0.774
9.70	34.65	-0.774
9.71	34.59	-0.774
9.72	34.52	-0.775
9.72	34.46	-0.775
9.73	34.39	-0.775
9.74	34.32	-0.775
9.74	34.26	-0.775
9.75	34.19	-0.775
9.76	34.13	-0.776
9.76	34.06	-0.776
9.77	34.00	-0.776
9.78	33.93	-0.776
9.78	33.86	-0.777
9.79	33.80	-0.777
9.80	33.73	-0.777
9.80	33.67	-0.777
9.81	33.60	-0.777
9.82	33.53	-0.777
9.82	33.47	-0.778
9.83	33.40	-0.778
9.84	33.34	-0.778
9.84	33.27	-0.779
9.85	33.20	-0.779
9.86	33.14	-0.779
9.86	33.07	-0.779
9.87	33.01	-0.779
9.88	32.94	-0.779
9.88	32.87	-0.780
9.89	32.81	-0.780
9.90	32.74	-0.780
9.90	32.68	-0.780
9.91	32.61	-0.780
9.92	32.54	-0.781
9.92	32.48	-0.781
9.93	32.41	-0.781
9.94	32.35	-0.781
9.94	32.28	-0.781
9.95	32.22	-0.781
9.96	32.15	-0.781
9.96	32.08	-0.782
9.97	32.02	-0.782
9.98	31.95	-0.782
9.98	31.88	-0.782
9.99	31.82	-0.782
10.00	31.75	-0.782
10.00	31.69	-0.782
10.01	31.62	-0.782
10.02	31.56	-0.783
10.02	31.49	-0.783
10.03	31.42	-0.783
10.04	31.36	-0.783
10.04	31.29	-0.783
10.05	31.22	-0.783
10.06	31.16	-0.783
10.06	31.09	-0.783
10.07	31.03	-0.784
10.08	30.96	-0.784
10.08	30.89	-0.784
10.09	30.83	-0.784
10.10	30.76	-0.784
10.10	30.69	-0.784
10.11	30.63	-0.784
10.12	30.56	-0.784
10.12	30.49	-0.784
10.13	30.43	-0.784
10.14	30.36	-0.785
10.14	30.30	-0.785
10.15	30.23	-0.785
10.16	30.16	-0.785
10.16	30.10	-0.785
10.17	30.03	-0.785
10.18	29.96	-0.785
10.18	29.90	-0.785
10.19	29.83	-0.785
10.20	29.77	-0.785
10.20	29.70	-0.786
10.21	29.63	-0.786
10.22	29.57	-0.786
10.22	29.50	-0.786
10.23	29.43	-0.786
10.24	29.37	-0.786
10.24	29.30	-0.786
10.25	29.24	-0.786
10.26	29.17	-0.786
10.26	29.10	-0.786
10.27	29.04	-0.786
10.28	28.97	-0.786
10.28	28.90	-0.786
10.29	28.84	-0.786
10.30	28.77	-0.786
10.30	28.70	-0.786
10.31	28.64	-0.786
10.32	28.57	-0.786
10.32	28.51	-0.786
10.33	28.44	-0.786
10.34	28.37	-0.786
10.34	28.31	-0.786
10.35	28.24	-0.786
10.36	28.17	-0.786
10.36	28.11	-0.787
10.37	28.04	-0.787
10.38	27.97	-0.787
10.38	27.91	-0.787
10.39	27.84	-0.787
10.40	27.78	-0.787
10.40	27.71	-0.787
10.41	27.64	-0.787
10.42	27.58	-0.787
10.42	27.51	-0.787
10.43	27.44	-0.787
10.44	27.38	-0.787
10.44	27.31	-0.787
10.45	27.24	-0.787
10.46	27.18	-0.787
10.46	27.11	-0.787
10.47	27.04	-0.787
10.48	26.98	-0.787
10.48	26.91	-0.787
10.49	26.84	-0.787
10.50	26.78	-0.787
10.50	26.71	-0.787
10.51	26.65	-0.787
10.52	26.58	-0.787
10.52	26.51	-0.787
10.53	26.45	-0.787
10.54	26.38	-0.787
10.54	26.31	-0.787
10.55	26.25	-0.787
10.56	26.18	-0.787
10.56	26.11	-0.787
10.57	26.05	-0.786
10.58	25.98	-0.786
10.58	25.91	-0.787
10.59	25.85	-0.787
10.60	25.78	-0.787
10.60	25.72	-0.787
10.61	25.65	-0.787
10.62	25.58	-0.787
10.62	25.52	-0.787
10.63	25.45	-0.787
10.64	25.38	-0.787
10.64	25.32	-0.787
10.65	25.25	-0.787
10.66	25.18	-0.786
10.66	25.12	-0.786
10.67	25.05	-0.786
10.68	24.98	-0.786
10.68	24.92	-0.786
10.69	24.85	-0.786
10.70	24.78	-0.786
10.70	24.72	-0.786
10.71	24.65	-0.786
10.72	24.58	-0.786
10.72	24.52	-0.786
10.73	24.45	-0.786
10.74	24.38	-0.786
10.74	24.32	-0.786
10.75	24.25	-0.786
10.76	24.19	-0.786
10.76	24.12	-0.786
10.77	24.05	-0.786
10.78	23.98	-0.786
10.78	23.92	-0.786
10.79	23.85	-0.786
10.80	23.79	-0.786
10.80	23.72	-0.786
10.81	23.65	-0.786
10.82	23.59	-0.786
10.82	23.52	-0.786
10.83	23.45	-0.786
10.84	23.39	-0.786
10.84	23.32	-0.786
10.85	23.25	-0.786
10.86	23.19	-0.786
10.86	23.12	-0.786
10.87	23.06	-0.786
10.88	22.99	-0.786
10.88	22.92	-0.786
10.89	22.86	-0.785
10.90	22.79	-0.785
10.90	22.72	-0.785
10.91	22.66	-0.785
10.92	22.59	-0.785
10.92	22.52	-0.785
10.93	22.46	-0.785
10.94	22.39	-0.785
10.94	22.32	-0.785
10.95	22.26	-0.785
10.96	22.19	-0.785
10.96	22.12	-0.785
10.97	22.06	-0.785
10.98	21.99	-0.785
10.98	21.92	-0.784
10.99	21.86	-0.784
11.00	21.79	-0.784
11.00	21.72	-0.784
11.01	21.66	-0.784
11.02	21.59	-0.784
11.02	21.52	-0.784
11.03	21.46	-0.784
11.04	21.39	-0.784
11.04	21.32	-0.784
11.05	21.26	-0.784
11.06	21.19	-0.784
11.06	21.13	-0.784
11.07	21.06	-0.784
11.08	20.99	-0.784
11.08	20.93	-0.783
11.09	20.86	-0.783
11.10	20.79	-0.783
11.10	20.73	-0.783
11.11	20.66	-0.783
11.12	20.59	-0.783
11.12	20.53	-0.783
11.13	20.46	-0.783
11.14	20.39	-0.783
11.14	20.33	-0.783
11.15	20.26	-0.783
11.16	20.19	-0.783
11.16	20.13	-0.783
11.17	20.06	-0.783
11.18	19.99	-0.783
11.18	19.93	-0.783
11.19	19.86	-0.782
11.20	19.79	-0.782
11.20	19.73	-0.782
11.21	19.66	-0.782
11.22	19.59	-0.782
11.22	19.53	-0.782
11.23	19.46	-0.782
11.24	19.39	-0.782
11.24	19.33	-0.782
11.25	19.26	-0.782
11.26	19.20	-0.782
11.26	19.13	-0.782
11.27	19.06	-0.782
11.28	19.00	-0.782
11.28	18.93	-0.781
11.29	18.86	-0.781
11.30	18.79	-0.781
11.30	18.73	-0.781
11.31	18.66	-0.781
11.32	18.60	-0.781
11.32	18.53	-0.781
11.33	18.46	-0.781
11.34	18.40	-0.781
11.34	18.33	-0.781
11.35	18.26	-0.781
11.36	18.20	-0.781
11.36	18.13	-0.780
11.37	18.06	-0.780
11.38	18.00	-0.780
11.38	17.93	-0.780
11.39	17.86	-0.780
11.40	17.80	-0.780
11.40	17.73	-0.780
11.41	17.66	-0.780
11.42	17.60	-0.780
11.42	17.53	-0.780
11.43	17.46	-0.780
11.44	17.40	-0.780
11.44	17.33	-0.780
11.45	17.26	-0.780
11.46	17.20	-0.779
11.46	17.13	-0.779
11.47	17.07	-0.779
11.48	17.00	-0.779
11.48	16.93	-0.779
11.49	16.87	-0.779
11.50	16.80	-0.779
11.50	16.73	-0.779
11.51	16.67	-0.779
11.52	16.60	-0.779
11.52	16.53	-0.779
11.53	16.47	-0.779
11.54	16.40	-0.778
11.54	16.33	-0.778
11.55	16.27	-0.778
11.56	16.20	-0.778
11.56	16.13	-0.778
11.57	16.07	-0.778
11.58	16.00	-0.778
11.58	15.93	-0.778
11.59	15.87	-0.778
11.60	15.80	-0.778
11.60	15.74	-0.778
11.61	15.67	-0.778
11.62	15.60	-0.778
11.62	15.53	-0.778
11.63	15.47	-0.778
11.64	15.40	-0.778
11.64	15.34	-0.777
11.65	15.27	-0.777
11.66	15.20	-0.777
11.66	15.14	-0.777
11.67	15.07	-0.777
11.68	15.00	-0.777
11.68	14.94	-0.777
11.69	14.87	-0.777
11.70	14.80	-0.777
11.70	14.74	-0.777
11.71	14.67	-0.777
11.72	14.60	-0.777
11.72	14.54	-0.777
11.73	14.47	-0.777
11.74	14.40	-0.777
11.74	14.34	-0.777
11.75	14.27	-0.776
11.76	14.20	-0.776
11.76	14.14	-0.776
11.77	14.07	-0.776
11.78	14.00	-0.776
11.78	13.94	-0.776
11.79	13.87	-0.776
11.80	13.80	-0.776
11.80	13.74	-0.776
11.81	13.67	-0.776
11.82	13.61	-0.776
11.82	13.54	-0.776
11.83	13.47	-0.776
11.84	13.40	-0.776
11.84	13.34	-0.776
11.85	13.27	-0.776
11.86	13.20	-0.776
11.86	13.14	-0.776
11.87	13.07	-0.776
11.88	13.01	-0.776
11.88	12.94	-0.776
11.89	12.87	-0.776
11.90	12.81	-0.776
11.90	12.74	-0.776
11.91	12.67	-0.776
11.92	12.61	-0.776
11.92	12.54	-0.775
11.93	12.47	-0.775
11.94	12.41	-0.775
11.94	12.34	-0.775
11.95	12.27	-0.775
11.96	12.21	-0.775
11.96	12.14	-0.775
11.97	12.07	-0.775
11.98	12.01	-0.775
11.98	11.94	-0.775
11.99	11.87	-0.775
12.00	11.81	-0.775
12.00	11.74	-0.775
12.01	11.67	-0.775
12.02	11.61	-0.775
12.02	11.54	-0.775
12.03	11.47	-0.775
12.04	11.41	-0.775
12.04	11.34	-0.775
12.05	11.27	-0.775
12.06	11.21	-0.775
12.06	11.14	-0.775
12.07	11.07	-0.775
12.08	11.01	-0.775
12.08	10.94	-0.775
12.09	10.87	-0.775
12.10	10.81	-0.775
12.10	10.74	-0.775
12.11	10.68	-0.775
12.12	10.61	-0.775
12.12	10.54	-0.774
12.13	10.48	-0.774
12.14	10.41	-0.774
12.14	10.34	-0.774
12.15	10.28	-0.774
12.16	10.21	-0.774
12.16	10.14	-0.774
12.17	10.08	-0.774
12.18	10.01	-0.774
12.18	9.94	-0.774
12.19	9.88	-0.774
12.20	9.81	-0.774
12.20	9.74	-0.774
12.21	9.68	-0.774
12.22	9.61	-0.774
12.22	9.54	-0.774
12.23	9.48	-0.774
12.24	9.41	-0.774
12.24	9.35	-0.773
12.25	9.28	-0.773
12.26	9.21	-0.773
12.26	9.15	-0.773
12.27	9.08	-0.773
12.28	9.01	-0.773
12.28	8.95	-0.773
12.29	8.88	-0.773
12.30	8.81	-0.773
12.30	8.75	-0.773
12.31	8.68	-0.773
12.32	8.61	-0.773
12.32	8.55	-0.773
12.33	8.48	-0.773
12.34	8.41	-0.773
12.34	8.35	-0.773
12.35	8.28	-0.773
12.36	8.21	-0.773
12.36	8.15	-0.773
12.37	8.08	-0.773
12.38	8.02	-0.773
12.38	7.95	-0.773
12.39	7.88	-0.773
12.40	7.81	-0.773
12.40	7.75	-0.773
12.41	7.68	-0.773
12.42	7.62	-0.773
12.42	7.55	-0.772
12.43	7.48	-0.772
12.44	7.42	-0.772
12.44	7.35	-0.772
12.45	7.28	-0.772
12.46	7.22	-0.772
12.46	7.15	-0.772
12.47	7.08	-0.772
12.48	7.02	-0.772
12.48	6.95	-0.772
12.49	6.88	-0.772
12.50	6.82	-0.772
12.50	6.75	-0.772
12.51	6.68	-0.772
12.52	6.62	-0.772
12.52	6.55	-0.772
12.53	6.48	-0.772
12.54	6.42	-0.772
12.54	6.35	-0.772
12.55	6.29	-0.772
12.56	6.22	-0.772
12.56	6.15	-0.772
12.57	6.09	-0.772
12.58	6.02	-0.772
12.58	5.95	-0.772
12.59	5.89	-0.772
12.60	5.82	-0.772
12.60	5.75	-0.772
12.61	5.68	-0.772
12.62	5.62	-0.772
12.62	5.55	-0.772
12.63	5.49	-0.772
12.64	5.42	-0.772
12.64	5.35	-0.772
12.65	5.29	-0.772
12.66	5.22	-0.772
12.66	5.15	-0.772
12.67	5.09	-0.772
12.68	5.02	-0.772
12.68	4.95	-0.772
12.69	4.89	-0.772
12.70	4.82	-0.772
12.70	4.75	-0.772
12.71	4.69	-0.771
12.72	4.62	-0.771
12.72	4.55	-0.771
12.73	4.49	-0.771
12.74	4.42	-0.771
12.74	4.35	-0.771
12.75	4.29	-0.771
12.76	4.22	-0.771
12.76	4.15	-0.771
12.77	4.09	-0.771
12.78	4.02	-0.771
12.78	3.95	-0.771
12.79	3.89	-0.771
12.80	3.82	-0.771
12.80	3.75	-0.771
12.81	3.69	-0.771
12.82	3.62	-0.771
12.82	3.55	-0.771
12.83	3.49	-0.771
12.84	3.42	-0.771
12.84	3.36	-0.771
12.85	3.29	-0.771
12.86	3.22	-0.771
12.86	3.15	-0.771
12.87	3.09	-0.771
12.88	3.02	-0.771
12.88	2.96	-0.771
12.89	2.89	-0.771
12.90	2.82	-0.771
12.90	2.76	-0.771
12.91	2.69	-0.771
12.92	2.62	-0.771
12.92	2.55	-0.771
12.93	2.49	-0.771
12.94	2.42	-0.771
12.94	2.36	-0.771
12.95	2.29	-0.771
12.96	2.22	-0.771
12.96	2.16	-0.771
12.97	2.09	-0.771
12.98	2.02	-0.771
12.98	1.96	-0.771
12.99	1.89	-0.771
13.00	1.82	-0.771
13.00	1.76	-0.771
13.01	1.69	-0.771
13.02	1.62	-0.771
13.02	1.56	-0.771
13.03	1.49	-0.771
13.04	1.42	-0.771
13.04	1.36	-0.771
13.05	1.29	-0.771
13.06	1.22	-0.771
13.06	1.16	-0.771
13.07	1.09	-0.771
13.08	1.02	-0.771
13.08	0.96	-0.771
13.09	0.89	-0.771
13.10	0.82	-0.771
13.10	0.76	-0.771
13.11	0.69	-0.771
13.12	0.62	-0.771
13.12	0.56	-0.771
13.13	0.49	-0.771
13.14	0.42	-0.771
13.14	0.36	-0.771
13.15	0.29	-0.771
13.16	0.22	-0.771
13.16	0.16	-0.771
13.17	0.09	-0.771
13.18	0.02	-0.771
13.18	-0.04	-0.771
13.19	-0.11	-0.771
13.20	-0.18	-0.771
13.20	-0.24	-0.772
13.21	-0.31	-0.772
13.22	-0.38	-0.772
13.22	-0.44	-0.772
13.23	-0.51	-0.772
13.24	-0.58	-0.772
13.24	-0.64	-0.772
13.25	-0.71	-0.772
13.26	-0.78	-0.772
13.26	-0.84	-0.772
13.27	-0.91	-0.772
13.28	-0.98	-0.772
13.28	-1.04	-0.772
13.29	-1.11	-0.772
13.30	-1.18	-0.772
13.30	-1.24	-0.772
13.31	-1.31	-0.772
13.32	-1.38	-0.772
13.32	-1.44	-0.772
13.33	-1.51	-0.772
13.34	-1.58	-0.772
13.34	-1.64	-0.772
13.35	-1.71	-0.772
13.36	-1.78	-0.772
13.36	-1.84	-0.772
13.37	-1.91	-0.772
13.38	-1.98	-0.772
13.38	-2.04	-0.772
13.39	-2.11	-0.772
13.40	-2.18	-0.772
13.40	-2.24	-0.772
13.41	-2.31	-0.772
13.42	-2.38	-0.772
13.42	-2.44	-0.772
13.43	-2.51	-0.772
13.44	-2.58	-0.772
13.44	-2.64	-0.772
13.45	-2.71	-0.773
13.46	-2.78	-0.773
13.46	-2.84	-0.773
13.47	-2.91	-0.773
13.48	-2.98	-0.773
13.48	-3.05	-0.773
13.49	-3.11	-0.773
13.50	-3.18	-0.773
13.50	-3.24	-0.773
13.51	-3.31	-0.773
13.52	-3.38	-0.773
13.52	-3.44	-0.773
13.53	-3.51	-0.773
13.54	-3.58	-0.773
13.54	-3.64	-0.773
13.55	-3.71	-0.773
13.56	-3.78	-0.773
13.56	-3.85	-0.773
13.57	-3.91	-0.773
13.58	-3.98	-0.773
13.58	-4.05	-0.773
13.59	-4.11	-0.773
13.60	-4.18	-0.773
13.60	-4.25	-0.773
13.61	-4.31	-0.773
13.62	-4.38	-0.773
13.62	-4.45	-0.773
13.63	-4.51	-0.773
13.64	-4.58	-0.773
13.64	-4.65	-0.773
13.65	-4.71	-0.773
13.66	-4.78	-0.773
13.66	-4.85	-0.773
13.67	-4.91	-0.773
13.68	-4.98	-0.773
13.68	-5.05	-0.773
13.69	-5.11	-0.774
13.70	-5.18	-0.774
13.70	-5.25	-0.774
13.71	-5.31	-0.774
13.72	-5.38	-0.774
13.72	-5.45	-0.774
13.73	-5.51	-0.774
13.74	-5.58	-0.774
13.74	-5.65	-0.774
13.75	-5.71	-0.774
13.76	-5.78	-0.774
13.76	-5.84	-0.774
13.77	-5.91	-0.774
13.78	-5.98	-0.774
13.78	-6.04	-0.774
13.79	-6.11	-0.774
13.80	-6.18	-0.774
13.80	-6.25	-0.774
13.81	-6.31	-0.774
13.82	-6.38	-0.774
13.82	-6.45	-0.774
13.83	-6.51	-0.774
13.84	-6.58	-0.774
13.84	-6.65	-0.774
13.85	-6.71	-0.774
13.86	-6.78	-0.774
13.86	-6.85	-0.774
13.87	-6.91	-0.774
13.88	-6.98	-0.774
13.88	-7.05	-0.774
13.89	-7.11	-0.774
13.90	-7.18	-0.774
13.90	-7.25	-0.774
13.91	-7.31	-0.774
13.92	-7.38	-0.774
13.92	-7.45	-0.774
13.93	-7.51	-0.775
13.94	-7.58	-0.775
13.94	-7.65	-0.775
13.95	-7.71	-0.775
13.96	-7.78	-0.775
13.96	-7.85	-0.775
13.97	-7.91	-0.775
13.98	-7.98	-0.775
13.98	-8.05	-0.775
13.99	-8.11	-0.775
14.00	-8.18	-0.775
14.00	-8.25	-0.775
14.01	-8.31	-0.775
14.02	-8.38	-0.775
14.02	-8.45	-0.775
14.03	-8.51	-0.775
14.04	-8.58	-0.775
14.04	-8.65	-0.775
14.05	-8.71	-0.775
14.06	-8.78	-0.775
14.06	-8.85	-0.775
14.07	-8.91	-0.775
14.08	-8.98	-0.775
14.08	-9.05	-0.775
14.09	-9.11	-0.775
[...]
18.68	-34.81	0.327
18.68	-34.74	0.327
18.69	-34.68	0.328
18.69	-34.61	0.328
18.70	-34.55	0.329
18.71	-34.48	0.329
18.72	-34.42	0.329
18.72	-34.35	0.329
18.73	-34.29	0.330
18.73	-34.22	0.330
18.74	-34.16	0.330
18.75	-34.09	0.331
18.76	-34.02	0.331
18.76	-33.96	0.331
18.77	-33.89	0.331
18.78	-33.83	0.331
18.78	-33.76	0.331
18.79	-33.70	0.332
18.79	-33.63	0.332
18.80	-33.56	0.332
18.81	-33.50	0.333
18.82	-33.43	0.333
18.82	-33.37	0.333
18.83	-33.30	0.333
18.83	-33.23	0.333
18.84	-33.17	0.334
18.85	-33.10	0.334
18.86	-33.04	0.334
18.86	-32.97	0.334
18.87	-32.91	0.335
18.88	-32.84	0.335
18.88	-32.77	0.335
18.89	-32.71	0.335
18.89	-32.64	0.335
18.90	-32.58	0.335
18.91	-32.51	0.336
18.92	-32.44	0.336
18.92	-32.38	0.336
18.93	-32.31	0.336
18.93	-32.25	0.336
18.94	-32.18	0.336
18.95	-32.11	0.337
18.96	-32.05	0.337
18.96	-31.98	0.337
18.97	-31.92	0.337
18.98	-31.85	0.337
18.98	-31.78	0.337
18.99	-31.72	0.337
18.99	-31.65	0.338
19.00	-31.59	0.338
19.01	-31.52	0.338
19.02	-31.45	0.338
19.02	-31.39	0.338
19.03	-31.32	0.339
19.03	-31.25	0.339
19.04	-31.19	0.339
19.05	-31.12	0.339
19.06	-31.06	0.339
19.06	-30.99	0.339
19.07	-30.92	0.340
19.08	-30.86	0.340
19.08	-30.79	0.340
19.09	-30.73	0.340
19.09	-30.66	0.340
19.10	-30.59	0.341
19.11	-30.53	0.341
19.12	-30.46	0.341
19.12	-30.39	0.341
19.13	-30.33	0.341
19.13	-30.26	0.341
19.14	-30.20	0.341
19.15	-30.13	0.341
19.16	-30.06	0.342
19.16	-30.00	0.342
19.17	-29.93	0.342
19.18	-29.86	0.342
19.18	-29.80	0.342
19.19	-29.73	0.342
19.19	-29.66	0.342
19.20	-29.60	0.342
19.21	-29.53	0.343
19.22	-29.47	0.343
19.22	-29.40	0.343
19.23	-29.33	0.343
19.23	-29.27	0.343
19.24	-29.20	0.343
19.25	-29.13	0.343
19.26	-29.07	0.344
19.26	-29.00	0.344
19.27	-28.93	0.344
19.28	-28.87	0.344
19.28	-28.80	0.344
19.29	-28.73	0.344
19.29	-28.67	0.344
19.30	-28.60	0.344
19.31	-28.54	0.344
19.32	-28.47	0.345
19.32	-28.40	0.345
19.33	-28.34	0.345
19.33	-28.27	0.345
19.34	-28.20	0.345
19.35	-28.14	0.345
19.36	-28.07	0.345
19.36	-28.01	0.345
19.37	-27.94	0.345
19.38	-27.87	0.345
19.38	-27.81	0.346
19.39	-27.74	0.346
19.39	-27.67	0.346
19.40	-27.61	0.346
19.41	-27.54	0.346
19.42	-27.47	0.346
19.42	-27.41	0.346
19.43	-27.34	0.346
19.43	-27.27	0.346
19.44	-27.21	0.346
19.45	-27.14	0.346
19.46	-27.07	0.347
19.46	-27.01	0.347
19.47	-26.94	0.347
19.48	-26.87	0.347
19.48	-26.81	0.347
19.49	-26.74	0.347
19.49	-26.68	0.347
19.50	-26.61	0.347
19.51	-26.54	0.347
19.52	-26.48	0.347
19.52	-26.41	0.347
19.53	-26.34	0.348
19.53	-26.28	0.348
19.54	-26.21	0.348
19.55	-26.14	0.348
19.56	-26.08	0.348
19.56	-26.01	0.348
19.57	-25.94	0.348
19.58	-25.88	0.348
19.58	-25.81	0.348
19.59	-25.74	0.349
19.59	-25.68	0.349
19.60	-25.61	0.349
19.61	-25.54	0.349
19.62	-25.48	0.349
19.62	-25.41	0.349
19.63	-25.34	0.349
19.63	-25.28	0.349
19.64	-25.21	0.349
19.65	-25.14	0.349
19.66	-25.08	0.350
19.66	-25.01	0.350
19.67	-24.94	0.350
19.68	-24.88	0.350
19.68	-24.81	0.350
19.69	-24.74	0.350
19.69	-24.68	0.350
19.70	-24.61	0.350
19.71	-24.54	0.350
19.72	-24.48	0.350
19.72	-24.41	0.350
19.73	-24.34	0.350
19.73	-24.28	0.350
19.74	-24.21	0.350
19.75	-24.14	0.351
19.76	-24.08	0.351
19.76	-24.01	0.351
19.77	-23.94	0.351
19.78	-23.88	0.351
19.78	-23.81	0.351
19.79	-23.75	0.351
19.79	-23.68	0.351
19.80	-23.61	0.351
19.81	-23.54	0.351
19.82	-23.48	0.351
19.82	-23.41	0.351
19.83	-23.34	0.351
19.83	-23.28	0.351
19.84	-23.21	0.351
19.85	-23.14	0.352
19.86	-23.08	0.352
19.86	-23.01	0.352
19.87	-22.94	0.352
19.88	-22.88	0.352
19.88	-22.81	0.352
19.89	-22.75	0.352
19.89	-22.68	0.352
19.90	-22.61	0.352
19.91	-22.54	0.352
19.92	-22.48	0.352
19.92	-22.41	0.352
19.93	-22.34	0.352
19.93	-22.28	0.353
19.94	-22.21	0.353
19.95	-22.14	0.353
19.96	-22.08	0.353
19.96	-22.01	0.353
19.97	-21.94	0.353
19.98	-21.88	0.353
19.98	-21.81	0.353
19.99	-21.74	0.353
19.99	-21.68	0.353
20.00	-21.61	0.353
20.01	-21.54	0.353
20.02	-21.48	0.354
20.02	-21.41	0.354
20.03	-21.34	0.354
20.03	-21.28	0.354
20.04	-21.21	0.354
20.05	-21.14	0.354
20.06	-21.08	0.354
20.06	-21.01	0.354
20.07	-20.94	0.354
20.08	-20.88	0.354
20.08	-20.81	0.354
20.09	-20.74	0.354
20.09	-20.68	0.354
20.10	-20.61	0.354
20.11	-20.55	0.354
20.12	-20.48	0.354
20.12	-20.41	0.354
20.13	-20.35	0.354
20.13	-20.28	0.354
20.14	-20.21	0.355
20.15	-20.15	0.355
20.16	-20.08	0.355
20.16	-20.01	0.355
20.17	-19.94	0.355
20.18	-19.88	0.355
20.18	-19.81	0.355
20.19	-19.74	0.355
20.19	-19.68	0.355
20.20	-19.61	0.355
20.21	-19.54	0.355
20.22	-19.48	0.355
20.22	-19.41	0.355
20.23	-19.34	0.355
20.23	-19.28	0.355
20.24	-19.21	0.355
20.25	-19.14	0.355
20.26	-19.08	0.356
20.26	-19.01	0.356
20.27	-18.94	0.356
20.28	-18.88	0.356
20.28	-18.81	0.356
20.29	-18.74	0.356
20.29	-18.68	0.356
20.30	-18.61	0.356
20.31	-18.55	0.356
20.32	-18.48	0.356
20.32	-18.41	0.356
20.33	-18.34	0.356
20.33	-18.28	0.356
20.34	-18.21	0.357
20.35	-18.15	0.357
20.36	-18.08	0.357
20.36	-18.01	0.357
20.37	-17.94	0.357
20.38	-17.88	0.357
20.38	-17.81	0.357
20.39	-17.74	0.357
20.39	-17.68	0.357
20.40	-17.61	0.357
20.41	-17.54	0.357
20.42	-17.48	0.357
20.42	-17.41	0.357
20.43	-17.34	0.357
20.43	-17.28	0.357
20.44	-17.21	0.357
20.45	-17.14	0.357
20.46	-17.08	0.358
20.46	-17.01	0.358
20.47	-16.94	0.358
20.48	-16.88	0.358
20.48	-16.81	0.358
20.49	-16.74	0.358
20.49	-16.68	0.358
20.50	-16.61	0.358
20.51	-16.54	0.358
20.52	-16.48	0.358
20.52	-16.41	0.358
20.53	-16.34	0.358
20.53	-16.28	0.358
20.54	-16.21	0.358
20.55	-16.14	0.359
20.56	-16.08	0.359
20.56	-16.01	0.359
20.57	-15.94	0.359
20.58	-15.88	0.359
20.58	-15.81	0.359
20.59	-15.74	0.359
20.59	-15.68	0.359
20.60	-15.61	0.359
20.61	-15.54	0.359
20.62	-15.48	0.359
20.62	-15.41	0.359
20.63	-15.34	0.359
20.63	-15.28	0.359
20.64	-15.21	0.359
20.65	-15.14	0.360
20.66	-15.08	0.360
20.66	-15.01	0.360
20.67	-14.94	0.360
20.68	-14.88	0.360
20.68	-14.81	0.360
20.69	-14.74	0.360
20.69	-14.68	0.360
20.70	-14.61	0.360
20.71	-14.54	0.360
20.72	-14.48	0.360
20.72	-14.41	0.360
20.73	-14.34	0.360
20.73	-14.28	0.360
20.74	-14.21	0.360
20.75	-14.14	0.361
20.76	-14.08	0.361
20.76	-14.01	0.361
20.77	-13.94	0.361
20.78	-13.88	0.361
20.78	-13.81	0.361
20.79	-13.74	0.361
20.79	-13.68	0.361
20.80	-13.61	0.361
20.81	-13.54	0.361
20.82	-13.48	0.362
20.82	-13.41	0.362
20.83	-13.34	0.362
20.83	-13.27	0.362
20.84	-13.21	0.362
20.85	-13.14	0.362
20.86	-13.08	0.362
20.86	-13.01	0.362
20.87	-12.94	0.362
20.88	-12.88	0.362
20.88	-12.81	0.362
20.89	-12.74	0.362
20.89	-12.68	0.362
20.90	-12.61	0.362
20.91	-12.54	0.363
20.92	-12.47	0.363
20.92	-12.41	0.363
20.93	-12.34	0.363
20.93	-12.27	0.363
20.94	-12.21	0.363
20.95	-12.14	0.363
20.96	-12.08	0.363
20.96	-12.01	0.363
20.97	-11.94	0.363
20.98	-11.87	0.363
20.98	-11.81	0.363
20.99	-11.74	0.364
20.99	-11.67	0.364
21.00	-11.61	0.364
21.01	-11.54	0.364
21.02	-11.47	0.364
21.02	-11.41	0.364
21.03	-11.34	0.364
21.03	-11.27	0.364
21.04	-11.21	0.364
21.05	-11.14	0.364
21.06	-11.07	0.364
21.06	-11.01	0.364
21.07	-10.94	0.364
21.08	-10.87	0.364
21.08	-10.81	0.365
21.09	-10.74	0.365
21.09	-10.67	0.365
21.10	-10.61	0.365
21.11	-10.54	0.365
21.12	-10.47	0.365
21.12	-10.41	0.365
21.13	-10.34	0.365
21.13	-10.27	0.365
21.14	-10.21	0.365
21.15	-10.14	0.365
21.16	-10.07	0.365
21.16	-10.01	0.366
21.17	-9.94	0.366
21.18	-9.87	0.366
21.18	-9.81	0.366
21.19	-9.74	0.366
21.19	-9.67	0.366
21.20	-9.61	0.366
21.21	-9.54	0.366
21.22	-9.47	0.366
21.22	-9.41	0.366
21.23	-9.34	0.366
21.23	-9.27	0.366
21.24	-9.21	0.367
21.25	-9.14	0.367
21.26	-9.07	0.367
21.26	-9.01	0.367
21.27	-8.94	0.367
21.28	-8.87	0.367
21.28	-8.81	0.367
21.29	-8.74	0.367
21.29	-8.67	0.367
21.30	-8.61	0.367
21.31	-8.54	0.368
21.32	-8.47	0.368
21.32	-8.41	0.368
21.33	-8.34	0.368
21.33	-8.27	0.368
21.34	-8.21	0.368
21.35	-8.14	0.368
21.36	-8.07	0.368
21.36	-8.01	0.369
21.37	-7.94	0.369
21.38	-7.87	0.369
21.38	-7.80	0.369
21.39	-7.74	0.369
21.39	-7.67	0.369
21.40	-7.60	0.369
21.41	-7.54	0.369
21.42	-7.47	0.369
21.42	-7.41	0.369
21.43	-7.34	0.370
21.43	-7.27	0.370
21.44	-7.21	0.370
21.45	-7.14	0.370
21.46	-7.07	0.370
21.46	-7.01	0.370
21.47	-6.94	0.370
21.48	-6.87	0.370
21.48	-6.81	0.370
21.49	-6.74	0.371
21.49	-6.67	0.371
21.50	-6.60	0.371
21.51	-6.54	0.371
21.52	-6.47	0.371
21.52	-6.41	0.371
21.53	-6.34	0.371
21.53	-6.27	0.371
21.54	-6.20	0.372
21.55	-6.14	0.372
21.56	-6.07	0.372
21.56	-6.00	0.372
21.57	-5.94	0.372
21.58	-5.87	0.372
21.58	-5.80	0.372
21.59	-5.74	0.373
21.59	-5.67	0.373
21.60	-5.61	0.373
21.61	-5.54	0.373
21.62	-5.47	0.373
21.62	-5.40	0.373
21.63	-5.34	0.374
21.63	-5.27	0.374
21.64	-5.20	0.374
21.65	-5.14	0.374
21.66	-5.07	0.374
21.66	-5.00	0.375
21.67	-4.94	0.375
21.68	-4.87	0.375
21.68	-4.80	0.375
21.69	-4.74	0.376
21.69	-4.67	0.376
21.70	-4.61	0.376
21.71	-4.54	0.376
21.72	-4.47	0.377
21.72	-4.40	0.377
21.73	-4.34	0.377
21.73	-4.27	0.377
21.74	-4.21	0.378
21.75	-4.14	0.378
21.76	-4.07	0.379
21.76	-4.01	0.379
21.77	-3.94	0.380
21.78	-3.87	0.380
21.78	-3.81	0.381
21.79	-3.74	0.382
21.79	-3.67	0.384
21.80	-3.61	0.384
21.81	-3.54	0.385
21.82	-3.47	0.388
21.82	-3.41	0.389
21.83	-3.34	0.390
21.83	-3.27	0.392
21.84	-3.21	0.395
21.85	-3.14	0.396
21.86	-3.07	0.401
21.86	-3.01	0.405
21.87	-2.94	0.408
21.88	-2.88	0.412
21.88	-2.81	0.415
21.89	-2.74	0.419
21.89	-2.68	0.423
21.90	-2.61	0.426
21.91	-2.54	0.433
21.92	-2.48	0.441
21.92	-2.41	0.449
21.93	-2.35	0.457
21.93	-2.28	0.466
21.94	-2.22	0.480
21.95	-2.15	0.497
21.96	-2.09	0.514
21.96	-2.02	0.534
21.97	-1.96	0.560
21.98	-1.89	0.592
21.98	-1.83	0.637
21.99	-1.77	0.692
21.99	-1.71	0.761
22.00	-1.65	0.849
22.01	-1.59	0.961
22.02	-1.54	1.097
22.02	-1.49	1.260
22.03	-1.44	1.448
22.03	-1.39	1.651
22.04	-1.35	1.856
22.05	-1.31	2.064
22.06	-1.28	2.266
22.06	-1.24	2.463
22.07	-1.21	2.658
22.08	-1.18	2.848
22.08	-1.15	3.033
22.09	-1.12	3.227
22.09	-1.10	3.421
22.10	-1.07	3.603
22.11	-1.05	3.785
22.12	-1.02	3.952
22.12	-1.00	4.113
22.13	-0.97	4.266
22.13	-0.94	4.418
22.14	-0.92	4.568
22.15	-0.89	4.708
22.16	-0.86	4.846
22.16	-0.84	4.986
22.17	-0.81	5.121
22.18	-0.78	5.251
22.18	-0.75	5.383
22.19	-0.72	5.512
22.19	-0.69	5.636
22.20	-0.66	5.760
22.21	-0.63	5.883
22.22	-0.60	5.999
22.22	-0.57	6.114
22.23	-0.54	6.232
22.23	-0.50	6.345
22.24	-0.47	6.457
22.25	-0.44	6.565
22.26	-0.40	6.666
22.26	-0.36	6.763
22.27	-0.33	6.861
22.28	-0.29	6.955
22.28	-0.25	7.046
22.29	-0.22	7.139
22.29	-0.18	7.226
22.30	-0.14	7.310
22.31	-0.10	7.391
22.32	-0.06	7.469
22.32	-0.02	7.547
22.33	0.02	7.625
22.33	0.07	7.697
22.34	0.11	7.766
22.35	0.16	7.831
22.36	0.20	7.893
22.36	0.24	7.954
22.37	0.29	8.014
22.38	0.34	8.068
22.38	0.38	8.122
22.39	0.43	8.177
22.39	0.48	8.231
22.40	0.53	8.293
22.41	0.58	8.369
22.42	0.63	8.468
22.42	0.67	8.600
22.43	0.72	8.927
22.43	0.74	9.978
22.44	0.73	11.462
22.45	0.69	12.226
22.46	0.66	12.333
22.46	0.65	12.165
22.47	0.65	11.790
22.48	0.68	11.370
22.48	0.72	11.064
22.49	0.76	10.886
22.49	0.81	10.801
22.50	0.86	10.773
22.51	0.92	10.774
22.52	0.97	10.790
22.52	1.03	10.812
22.53	1.08	10.831
22.53	1.14	10.840
22.54	1.20	10.838
22.55	1.26	10.817
22.56	1.32	10.789
22.56	1.38	10.765
22.57	1.44	10.736
22.58	1.51	10.700
22.58	1.57	10.662
22.59	1.64	10.621
22.59	1.71	10.579
22.60	1.78	10.532
22.61	1.85	10.468
22.62	1.92	10.392
22.62	1.99	10.307
22.63	2.07	10.165
22.63	2.15	9.923
22.64	2.24	9.640
22.65	2.33	9.391
22.66	2.43	9.161
22.66	2.53	8.928
22.67	2.63	8.694
22.68	2.73	8.443
22.68	2.84	8.174
22.69	2.95	7.892
22.69	3.07	7.594
22.70	3.18	7.274
22.71	3.30	6.925
22.72	3.43	6.553
22.72	3.56	6.155
22.73	3.69	5.727
22.73	3.83	5.276
22.74	3.98	4.814
22.75	4.12	4.381
22.76	4.27	4.036
22.76	4.42	3.771
22.77	4.57	3.557
22.78	4.71	3.373
22.78	4.85	3.211
22.79	4.98	3.065
22.79	5.11	2.931
22.80	5.24	2.808
22.81	5.37	2.692
22.82	5.49	2.585
22.82	5.61	2.484
22.83	5.72	2.389
22.83	5.84	2.299
22.84	5.95	2.210
22.85	6.06	2.130
22.86	6.16	2.057
22.86	6.27	1.981
22.87	6.37	1.914
22.88	6.47	1.850
22.88	6.57	1.788
22.89	6.67	1.731
22.89	6.76	1.675
22.90	6.86	1.621
22.91	6.95	1.574
22.92	7.04	1.527
22.92	7.13	1.482
22.93	7.22	1.442
22.93	7.30	1.401
22.94	7.39	1.364
22.95	7.47	1.333
22.96	7.56	1.302
22.96	7.64	1.261
22.97	7.72	1.225
22.98	7.81	1.206
22.98	7.89	1.186
22.99	7.97	1.158
22.99	8.04	1.130
23.00	8.12	1.105
23.01	8.20	1.085
23.02	8.28	1.067
23.02	8.36	1.048
23.03	8.43	1.028
23.03	8.51	1.009
23.04	8.58	0.995
23.05	8.66	0.980
23.06	8.73	0.965
23.06	8.80	0.952
23.07	8.88	0.938
23.08	8.95	0.925
23.08	9.02	0.913
23.09	9.10	0.904
23.09	9.17	0.894
23.10	9.24	0.881
23.11	9.31	0.873
23.12	9.38	0.863
23.12	9.45	0.855
23.13	9.52	0.849
23.13	9.60	0.841
23.14	9.66	0.832
23.15	9.73	0.828
23.16	9.81	0.822
23.16	9.88	0.814
23.17	9.95	0.809
23.18	10.01	0.804
23.18	10.08	0.798
23.19	10.15	0.793
23.19	10.22	0.790
23.20	10.29	0.786
23.21	10.36	0.781
23.22	10.43	0.777
23.22	10.50	0.774
23.23	10.57	0.770
23.23	10.63	0.766
23.24	10.70	0.763
23.25	10.77	0.761
23.26	10.84	0.758
23.26	10.91	0.757
23.27	10.97	0.756
23.28	11.04	0.752
23.28	11.11	0.748
23.29	11.18	0.746
23.29	11.25	0.746
23.30	11.31	0.744
23.31	11.38	0.743
23.32	11.45	0.742
23.32	11.52	0.741
23.33	11.58	0.738
23.33	11.65	0.737
23.34	11.72	0.736
23.35	11.79	0.734
23.36	11.85	0.733
23.36	11.92	0.733
23.37	11.99	0.732
23.38	12.06	0.731
23.38	12.12	0.730
23.39	12.19	0.729
23.39	12.26	0.729
23.40	12.32	0.728
23.41	12.39	0.727
23.42	12.46	0.727
23.42	12.53	0.726
23.43	12.59	0.726
23.43	12.66	0.725
23.44	12.73	0.725
23.45	12.79	0.725
23.46	12.86	0.724
23.46	12.93	0.724
23.47	12.99	0.724
23.48	13.06	0.723
23.48	13.13	0.723
23.49	13.20	0.722
23.49	13.26	0.722
23.50	13.33	0.722
23.51	13.40	0.722
23.52	13.46	0.721
23.52	13.53	0.721
23.53	13.60	0.721
23.53	13.67	0.720
23.54	13.73	0.720
23.55	13.80	0.720
23.56	13.87	0.720
23.56	13.93	0.720
23.57	14.00	0.719
23.58	14.07	0.719
23.58	14.13	0.719
23.59	14.20	0.719
23.59	14.27	0.719
23.60	14.33	0.719
23.61	14.40	0.718
23.62	14.47	0.718
23.62	14.53	0.718
23.63	14.60	0.718
23.63	14.67	0.718
23.64	14.73	0.717
23.65	14.80	0.717
23.66	14.87	0.717
23.66	14.93	0.717
23.67	15.00	0.717
23.68	15.07	0.717
23.68	15.13	0.717
23.69	15.20	0.716
23.69	15.27	0.716
23.70	15.33	0.716
23.71	15.40	0.716
23.72	15.47	0.716
23.72	15.53	0.716
23.73	15.60	0.716
23.73	15.67	0.715
23.74	15.74	0.715
23.75	15.80	0.715
23.76	15.87	0.715
23.76	15.94	0.715
23.77	16.00	0.715
23.78	16.07	0.715
23.78	16.14	0.715
23.79	16.20	0.714
23.79	16.27	0.714
23.80	16.34	0.714
23.81	16.40	0.714
23.82	16.47	0.714
23.82	16.54	0.714
23.83	16.60	0.714
23.83	16.67	0.714
23.84	16.74	0.714
23.85	16.80	0.714
23.86	16.87	0.714
23.86	16.94	0.714
23.87	17.00	0.713
23.88	17.07	0.713
23.88	17.14	0.713
23.89	17.21	0.713
23.89	17.27	0.713
23.90	17.34	0.713
23.91	17.40	0.713
23.92	17.47	0.713
23.92	17.54	0.713
23.93	17.60	0.713
23.93	17.67	0.713
23.94	17.74	0.713
23.95	17.81	0.713
23.96	17.87	0.712
23.96	17.94	0.712
23.97	18.01	0.712
23.98	18.07	0.712
23.98	18.14	0.712
23.99	18.21	0.712
23.99	18.27	0.712
24.00	18.34	0.712
24.01	18.41	0.712
24.02	18.47	0.712
24.02	18.54	0.712
24.03	18.61	0.712
24.03	18.67	0.712
24.04	18.74	0.712
24.05	18.81	0.712
24.06	18.87	0.712
24.06	18.94	0.712
24.07	19.01	0.712
24.08	19.07	0.712
24.08	19.14	0.712
24.09	19.21	0.712
24.09	19.27	0.712
24.10	19.34	0.712
24.11	19.41	0.711
24.12	19.47	0.711
24.12	19.54	0.711
24.13	19.61	0.711
24.13	19.67	0.711
24.14	19.74	0.711
24.15	19.81	0.711
24.16	19.87	0.711
24.16	19.94	0.711
24.17	20.01	0.711
24.18	20.07	0.711
24.18	20.14	0.711
24.19	20.21	0.711
24.19	20.27	0.711
24.20	20.34	0.711
24.21	20.41	0.711
24.22	20.48	0.711
24.22	20.54	0.711
24.23	20.61	0.711
24.23	20.68	0.711
24.24	20.74	0.711
24.25	20.81	0.711
24.26	20.88	0.711
24.26	20.94	0.711
24.27	21.01	0.711
24.28	21.07	0.711
24.28	21.14	0.711
24.29	21.21	0.711
24.29	21.28	0.711
24.30	21.34	0.711
24.31	21.41	0.711
24.32	21.48	0.711
24.32	21.54	0.711
24.33	21.61	0.711
24.33	21.68	0.711
24.34	21.74	0.711
24.35	21.81	0.711
24.36	21.88	0.711
24.36	21.94	0.711
24.37	22.01	0.711
24.38	22.08	0.711
24.38	22.14	0.711
24.39	22.21	0.711
24.39	22.28	0.711
24.40	22.34	0.711
24.41	22.41	0.711
24.42	22.48	0.711
24.42	22.54	0.711
24.43	22.61	0.711
24.43	22.68	0.711
24.44	22.74	0.712
24.45	22.81	0.712
24.46	22.88	0.711
24.46	22.94	0.711
24.47	23.01	0.711
24.48	23.08	0.711
24.48	23.15	0.711
24.49	23.21	0.712
24.49	23.28	0.711
24.50	23.34	0.711
24.51	23.41	0.711
24.52	23.48	0.711
24.52	23.55	0.711
24.53	23.61	0.711
24.53	23.68	0.712
24.54	23.75	0.712
24.55	23.81	0.712
24.56	23.88	0.712
24.56	23.95	0.712
24.57	24.01	0.712
24.58	24.08	0.712
24.58	24.15	0.712
24.59	24.21	0.712
24.59	24.28	0.712
24.60	24.35	0.712
24.61	24.41	0.712
24.62	24.48	0.712
24.62	24.55	0.712
24.63	24.61	0.712
24.63	24.68	0.712
24.64	24.75	0.712
24.65	24.81	0.712
24.66	24.88	0.712
24.66	24.95	0.712
24.67	25.01	0.712
24.68	25.08	0.712
24.68	25.15	0.712
24.69	25.21	0.712
24.69	25.28	0.712
24.70	25.35	0.712
24.71	25.41	0.712
24.72	25.48	0.712
24.72	25.55	0.712
24.73	25.61	0.712
24.73	25.68	0.712
24.74	25.75	0.712
24.75	25.81	0.712
24.76	25.88	0.712
24.76	25.95	0.712
24.77	26.02	0.712
24.78	26.08	0.712
24.78	26.15	0.712
24.79	26.22	0.712
24.79	26.28	0.712
24.80	26.35	0.712
24.81	26.41	0.712
24.82	26.48	0.712
24.82	26.55	0.712
24.83	26.62	0.712
24.83	26.68	0.712
24.84	26.75	0.712
24.85	26.82	0.712
24.86	26.88	0.712
24.86	26.95	0.712
24.87	27.02	0.712
24.88	27.08	0.712
24.88	27.15	0.712
24.89	27.22	0.712
24.89	27.28	0.712
24.90	27.35	0.712
24.91	27.42	0.712
24.92	27.48	0.712
24.92	27.55	0.712
24.93	27.62	0.712
24.93	27.68	0.712
24.94	27.75	0.712
24.95	27.82	0.712
24.96	27.88	0.712
24.96	27.95	0.712
24.97	28.02	0.712
24.98	28.08	0.712
24.98	28.15	0.712
24.99	28.22	0.712
24.99	28.28	0.712
25.00	28.35	0.712
25.01	28.42	0.712
25.02	28.48	0.712
25.02	28.55	0.712
25.03	28.62	0.712
25.03	28.68	0.713
25.04	28.75	0.713
25.05	28.82	0.713
25.06	28.88	0.713
25.06	28.95	0.713
25.07	29.02	0.713
25.08	29.09	0.713
25.08	29.15	0.713
25.09	29.22	0.713
25.09	29.29	0.713
25.10	29.35	0.713
25.11	29.42	0.713
25.12	29.48	0.713
25.12	29.55	0.713
25.13	29.62	0.713
25.13	29.69	0.713
25.14	29.75	0.713
25.15	29.82	0.713
25.16	29.89	0.713
25.16	29.95	0.713
25.17	30.02	0.713
25.18	30.09	0.713
25.18	30.15	0.713
25.19	30.22	0.713
25.19	30.29	0.713
25.20	30.35	0.713
25.21	30.42	0.713
25.22	30.49	0.713
25.22	30.55	0.713
25.23	30.62	0.713
25.23	30.69	0.714
25.24	30.75	0.714
25.25	30.82	0.714
25.26	30.89	0.714
25.26	30.95	0.714
25.27	31.02	0.714
25.28	31.09	0.714
25.28	31.15	0.714
25.29	31.22	0.714
25.29	31.29	0.714
25.30	31.35	0.714
25.31	31.42	0.714
25.32	31.49	0.714
25.32	31.55	0.714
25.33	31.62	0.714
25.33	31.69	0.714
25.34	31.76	0.714
25.35	31.82	0.714
25.36	31.89	0.714
25.36	31.96	0.714
25.37	32.02	0.714
25.38	32.09	0.714
25.38	32.16	0.714
25.39	32.22	0.714
25.39	32.29	0.714
25.40	32.36	0.714
25.41	32.42	0.714
25.42	32.49	0.714
25.42	32.56	0.714
25.43	32.62	0.714
25.43	32.69	0.714
25.44	32.76	0.714
25.45	32.82	0.714
25.46	32.89	0.714
25.46	32.96	0.714
25.47	33.02	0.715
25.48	33.09	0.715
25.48	33.16	0.715
25.49	33.22	0.715
25.49	33.29	0.715
25.50	33.36	0.715
25.51	33.42	0.715
25.52	33.49	0.715
25.52	33.56	0.715
25.53	33.62	0.715
25.53	33.69	0.715
25.54	33.76	0.715
25.55	33.82	0.715
25.56	33.89	0.715
25.56	33.96	0.715
25.57	34.03	0.715
25.58	34.09	0.715
25.58	34.16	0.715
25.59	34.22	0.715
25.59	34.29	0.715
25.60	34.36	0.715
25.61	34.42	0.715
25.62	34.49	0.715
25.62	34.56	0.715
25.63	34.62	0.715
25.63	34.69	0.715
25.64	34.76	0.715
25.65	34.82	0.715
25.66	34.89	0.715
25.66	34.96	0.715
25.67	35.02	0.715
25.68	35.09	0.715
25.68	35.16	0.715
25.69	35.23	0.715
25.69	35.29	0.715
25.70	35.36	0.715
25.71	35.42	0.715
25.72	35.49	0.715
25.72	35.56	0.715
25.73	35.63	0.716
25.73	35.69	0.716
25.74	35.76	0.716
25.75	35.83	0.716
25.76	35.89	0.716
25.76	35.96	0.716
25.77	36.03	0.716
25.78	36.09	0.716
25.78	36.16	0.716
25.79	36.23	0.716
25.79	36.29	0.716
25.80	36.36	0.716
25.81	36.43	0.716
25.82	36.49	0.716
25.82	36.56	0.716
25.83	36.63	0.716
25.83	36.69	0.716
25.84	36.76	0.716
25.85	36.83	0.716
25.86	36.89	0.716
25.86	36.96	0.716
25.87	37.03	0.716
25.88	37.09	0.716
25.88	37.16	0.716
25.89	37.23	0.716
25.89	37.29	0.716
25.90	37.36	0.716
25.91	37.43	0.716
25.92	37.49	0.716
25.92	37.56	0.716
25.93	37.63	0.716
25.93	37.69	0.716
25.94	37.76
25.95	37.83
25.96	37.89
25.96	37.96
25.97	38.03
25.98	38.10
25.98	38.16
25.99
25.99