File: Data/2024_09_17_Benzoic_Acid_CHM343_DSC.csv
Filename,2024_09_17_Benzoic_Acid_CHM343_DSC
Instrument name,DSC2A-00468 (192.168.1.100)
Operator,CHM343
rundate,9/17/2024
Sample name,2024_09_17_Benzoic_Acid_CHM343_DSC
proceduresegments,Equilibrate 50.00 °C; Ramp 10.00 °C/min to 150.00 °C; Isothermal 1.0 min; Ramp 10.00 °C/min to 50.00 °C; Isothermal 1.0 min; Ramp 10.00 °C/min to 150.00 °C
[File Parameters]
Run date,9/17/2024 2:23:31 PM
Trios version,5.1.1.46572
Original File Name,
Current File Name,C:\ProgramData\TA Instruments\TRIOS\Data\2024_09_17_Benzoic_Acid_CHM343_DSC.tri
[Procedure]
Procedure Name,CHM343_Fall2024_Benzoic_Acid
Sample Name,2024_09_17_Benzoic_Acid_CHM343_DSC
Sample Mass,2.94 mg
Reference Sample Mass,0 mg
Pan Mass,54.47 mg
Pan Number,20
Reference Pan Mass,54 mg
Reference Pan Number,19
Pan Type,Aluminum
Comments,"Benzoic Acid in Al Hermetic Sealed Pan, with ref Al pan."
Project Name,Lab 4 - Fall 2024
Operator,CHM343
Test,Custom
Unload Max Temperature,30
Unload Min Temperature,30
Load Max Temperature,30
Load Min Temperature,30
Stop on Gas Flow Error,Yes
[Signal List]
Signal #1,Time (min)
Signal #2,Temperature (°C)
Signal #3,Heat Flow (mW)
Signal #4,Delta T (µV)
Signal #5,Delta Tzero (µV)
Signal #6,Tzero Temperature (°C)
Signal #7,Cell Purge (mL/min)
Signal #8,Heater Temp (°C)
Signal #9,Power Delivered (W)
Signal #10,Reference Junction Temperature (°C)
Signal #11,Flange Temperature (°C)
Signal #12,Heat Flow Phase (rad)
Signal #13,Total Heat Capacity (J/°C)
Signal #14,Heat Capacity (J/°C)
[Configuration]
Company Name,ASU
Instrument Name,DSC2A-00468
Instrument Type,DSC2500
Serial Number,DSC2A-00468
IP,192.168.1.100
Location of Instrument,MRRC
DisplayType,Unknown
Sample Interval ,0.1 s/pt
Selected Heat Flow,T4P
Exotherm Direction,Down
Cell Serial,DRC2-00792
Lid Type,Standard
Cooler,RCS 90
Leave Cooler on at End of Sequence,On
Gas 2,Nitrogen
Gas Selected,Channel 1
Flow Rate,50 mL/min
Secondary Purge,On
Licensed Heat Flow,Heat Flow T4P
Modulation Licensed,Yes
[Versions]
Common IDD Version,1
Cortex Version,VER 2.10.2.31
Driver,5.0.0.6
GDM Version,1.0.3.3
TouchscreenVersion,1.0.0.16145
FEP Version,1.2.1.21
FEP Bootloader,2.0.0.5
AutoSampler Version,2.1.1.26
Auto Sampler Bootloader,2.0.0.5
FCM Version,1.1.0.3
FCM Bootloader,2.0.0.5
[Experiment Logs]
Experiment Log Entry # 1,Equilibrate Segment 50 (C) Started
Experiment Log Entry # 3,Air Cool is off.
Experiment Log Entry # 5,Ramp Segment 10 C/min to 150 Started
Experiment Log Entry # 7,Isothermal Segment 1 min started
Experiment Log Entry # 9,Ramp Segment 10 C/min to 50 Started
Experiment Log Entry # 11,Isothermal Segment 1 min started
Experiment Log Entry # 13,Ramp Segment 10 C/min to 150 Started
[Method Log]
Method Log Entry # 1,Equilibrate 50 °C
Method Log Entry # 2,(Ramp 6392) Ramp 10 °C/minute to 150 °C
Method Log Entry # 3,Isothermal 1 minutes
Method Log Entry # 4,(Ramp 6394) Ramp 10 °C/minute to 50 °C
Method Log Entry # 5,Isothermal 1 minutes
Method Log Entry # 6,(Ramp 6396) Ramp 10 °C/minute to 150 °C
Cell Serial,DRC2-00792
[T1 Calibration]
Slope,-0.008529666
Offset,9.636258
Initial Temperature,98.23
GUID,f8bfdadc-4977-4fdf-ba6d-0ba9134940c3
[TZero Calibration]
Date Applied,11/29/2022 4:06:13 PM
Description,From -89.059 °C to 396.009 °C at 20.000°C/min
Gas Type,Nitrogen
Pan Type,None
Source Files 1,C:\Users\yargerlab\Desktop\DSC Data\General\TZero_calibration_11_29_22_2nd(2).tri
Source Files 2,C:\Users\yargerlab\Desktop\DSC Data\General\TZero_calibration_11_29_22_2nd(3).tri
Delta T Offset,13.05235
Delta T Slope,-0.007271007
Delta T0 Offset,-13.69128
Delta T0 Slope,0.06063341
[Temperature Calibration]
Date Applied,11/29/2022 7:12:28 PM
Description,From 106.590 °C to 186.590 °C at 10.000°C/min
Gas Type,Nitrogen
Pan Type,Tzero Aluminum Hermetic
Source Files 1,C:\Users\yargerlab\Desktop\DSC Data\General\Indium(6).tri
Measured 1,157.391
Known 1,156.598
[Cell Constant Calibration]
Date Applied,11/29/2022 7:12:29 PM
Description,From 106.590 °C to 186.590 °C at 10.000°C/min
Gas Type,Nitrogen
Pan Type,Tzero Aluminum Hermetic
Source Files 1,C:\Users\yargerlab\Desktop\DSC Data\General\Indium(6).tri
T4P KCell,1.006051
Onset Slope,63.26126 mW/°C
[Direct Cp Calibration]
Date Applied,11/30/2022 11:04:51 AM
Description,From -79.983 °C to 298.409 °C at 10.000°C/min
Gas Type,Nitrogen
Pan Type,Tzero Aluminum Hermetic
Source Files 1,C:\Users\yargerlab\Desktop\DSC Data\General\Sapphire_Heat_Capacity_11_30_22.tri
[Rev Cp Calibration]
Date Applied,11/30/2022 1:58:51 PM
Description,From -79.996 °C to 292.812 °C at 3.000°C/min
Gas Type,Nitrogen
Pan Type,Tzero Aluminum Hermetic
Source Files 1,C:\Users\yargerlab\Desktop\DSC Data\General\Sapphire_MDSC_Calibration_11_30_22.tri
[step]
Ramp 10.00 °C/min to 150.00 °C
Time,Temperature,Heat Flow (Normalized)
min,°C,W/g
0.00,50.12,-0.015
0.01,50.12,-0.016
0.01,50.12,-0.017
0.02,50.12,-0.018
0.03,50.13,-0.019
0.03,50.13,-0.021
0.04,50.13,-0.023
0.05,50.14,-0.028
0.05,50.15,-0.036
0.06,50.15,-0.045
0.07,50.17,-0.054
0.07,50.18,-0.065
0.08,50.20,-0.075
0.09,50.22,-0.081
0.09,50.25,-0.085
0.10,50.27,-0.089
0.11,50.31,-0.091
0.11,50.34,-0.090
0.12,50.37,-0.088
0.13,50.41,-0.083
0.13,50.45,-0.080
0.14,50.50,-0.073
0.15,50.54,-0.058
0.15,50.59,-0.040
0.16,50.64,-0.027
0.17,50.69,-0.016
0.17,50.74,-0.001
0.18,50.79,0.011
0.19,50.84,0.023
0.19,50.90,0.035
0.20,50.95,0.045
0.21,51.00,0.056
0.21,51.06,0.068
0.22,51.12,0.073
0.23,51.17,0.078
0.23,51.23,0.089
0.24,51.29,0.099
0.25,51.34,0.104
0.25,51.40,0.110
0.26,51.46,0.114
0.27,51.52,0.118
0.27,51.58,0.125
0.28,51.64,0.130
0.29,51.70,0.134
0.29,51.76,0.140
0.30,51.83,0.143
0.31,51.89,0.147
0.31,51.95,0.153
0.32,52.01,0.155
0.33,52.07,0.158
0.33,52.14,0.161
0.34,52.20,0.166
0.35,52.26,0.172
0.35,52.33,0.172
0.36,52.39,0.173
0.37,52.45,0.176
0.37,52.52,0.177
0.38,52.58,0.180
0.39,52.64,0.183
0.39,52.71,0.184
0.40,52.77,0.185
0.41,52.84,0.188
0.41,52.90,0.192
0.42,52.97,0.193
0.43,53.03,0.193
0.43,53.10,0.194
0.44,53.16,0.195
0.45,53.23,0.196
0.45,53.29,0.197
0.46,53.35,0.198
0.47,53.42,0.200
0.47,53.49,0.201
0.48,53.55,0.201
0.49,53.61,0.202
0.49,53.68,0.202
0.50,53.75,0.202
0.51,53.81,0.203
0.51,53.88,0.204
0.52,53.94,0.204
0.53,54.01,0.205
0.53,54.07,0.205
0.54,54.14,0.206
0.55,54.21,0.207
0.55,54.27,0.207
0.56,54.34,0.207
0.57,54.40,0.207
0.57,54.47,0.207
0.58,54.53,0.208
0.59,54.60,0.208
0.59,54.66,0.208
0.60,54.73,0.209
0.61,54.79,0.209
0.61,54.86,0.209
0.62,54.93,0.209
0.63,54.99,0.209
0.63,55.06,0.210
0.64,55.12,0.210
0.65,55.19,0.210
0.65,55.26,0.210
0.66,55.32,0.211
0.67,55.39,0.211
0.67,55.45,0.211
0.68,55.52,0.211
0.69,55.59,0.212
0.69,55.65,0.212
0.70,55.72,0.212
0.71,55.79,0.213
0.71,55.85,0.213
0.72,55.92,0.213
0.73,55.98,0.213
0.73,56.05,0.213
0.74,56.12,0.213
0.75,56.18,0.214
0.75,56.25,0.214
0.76,56.31,0.214
0.77,56.38,0.214
0.77,56.45,0.214
0.78,56.51,0.215
0.79,56.58,0.215
0.79,56.65,0.215
0.80,56.71,0.215
0.81,56.78,0.215
0.81,56.84,0.216
0.82,56.91,0.216
0.83,56.98,0.216
0.83,57.04,0.216
0.84,57.11,0.216
0.85,57.17,0.216
0.85,57.24,0.217
0.86,57.31,0.217
0.87,57.37,0.217
0.87,57.44,0.217
0.88,57.51,0.217
0.89,57.57,0.217
0.89,57.64,0.218
0.90,57.71,0.218
0.91,57.77,0.218
0.91,57.84,0.218
0.92,57.90,0.218
0.93,57.97,0.218
0.93,58.04,0.218
0.94,58.10,0.219
0.95,58.17,0.219
0.95,58.24,0.219
0.96,58.30,0.219
0.97,58.37,0.219
0.97,58.44,0.219
0.98,58.50,0.219
0.99,58.57,0.219
0.99,58.63,0.220
1.00,58.70,0.220
1.01,58.77,0.220
1.01,58.83,0.220
1.02,58.90,0.220
1.03,58.97,0.220
1.03,59.03,0.220
1.04,59.10,0.220
1.05,59.17,0.221
1.05,59.23,0.221
1.06,59.30,0.221
1.07,59.37,0.221
1.07,59.43,0.221
1.08,59.50,0.221
1.09,59.56,0.221
1.09,59.63,0.221
1.10,59.70,0.221
1.11,59.76,0.221
1.11,59.83,0.222
1.12,59.90,0.222
1.13,59.96,0.222
1.13,60.03,0.222
1.14,60.10,0.222
1.15,60.16,0.222
1.15,60.23,0.222
1.16,60.30,0.222
1.17,60.36,0.222
1.17,60.43,0.222
1.18,60.50,0.222
1.19,60.56,0.223
1.19,60.63,0.223
1.20,60.70,0.223
1.21,60.76,0.223
1.21,60.83,0.223
1.22,60.90,0.223
1.23,60.96,0.223
1.23,61.03,0.223
1.24,61.09,0.223
1.25,61.16,0.224
1.25,61.23,0.224
1.26,61.29,0.224
1.27,61.36,0.224
1.27,61.43,0.224
1.28,61.49,0.224
1.29,61.56,0.224
1.29,61.63,0.224
1.30,61.69,0.224
1.31,61.76,0.224
1.31,61.83,0.224
1.32,61.89,0.224
1.33,61.96,0.225
1.33,62.03,0.225
1.34,62.09,0.225
1.35,62.16,0.225
1.35,62.23,0.225
1.36,62.29,0.225
1.37,62.36,0.225
1.37,62.43,0.225
1.38,62.49,0.225
1.39,62.56,0.225
1.39,62.63,0.225
1.40,62.69,0.225
1.41,62.76,0.225
1.41,62.82,0.225
1.42,62.89,0.225
1.43,62.96,0.225
1.43,63.02,0.225
1.44,63.09,0.225
1.45,63.16,0.225
1.45,63.22,0.225
1.46,63.29,0.225
1.47,63.36,0.225
1.47,63.43,0.226
1.48,63.49,0.226
1.49,63.56,0.226
1.49,63.62,0.226
1.50,63.69,0.226
1.51,63.76,0.226
1.51,63.82,0.226
1.52,63.89,0.226
1.53,63.96,0.226
1.53,64.02,0.226
1.54,64.09,0.226
1.55,64.16,0.226
1.55,64.22,0.226
1.56,64.29,0.226
1.57,64.36,0.226
1.57,64.42,0.226
1.58,64.49,0.226
1.59,64.56,0.227
1.59,64.62,0.227
1.60,64.69,0.227
1.61,64.76,0.227
1.61,64.82,0.227
1.62,64.89,0.227
1.63,64.96,0.227
1.63,65.02,0.227
1.64,65.09,0.227
1.65,65.16,0.227
1.65,65.22,0.227
1.66,65.29,0.227
1.67,65.36,0.227
1.67,65.42,0.227
1.68,65.49,0.227
1.69,65.56,0.227
1.69,65.62,0.227
1.70,65.69,0.227
1.71,65.76,0.227
1.71,65.83,0.227
1.72,65.89,0.227
1.73,65.96,0.228
1.73,66.02,0.228
1.74,66.09,0.228
1.75,66.16,0.228
1.75,66.23,0.228
1.76,66.29,0.228
1.77,66.36,0.228
1.77,66.43,0.228
1.78,66.49,0.228
1.79,66.56,0.228
1.79,66.63,0.228
1.80,66.69,0.228
1.81,66.76,0.228
1.81,66.82,0.228
1.82,66.89,0.228
1.83,66.96,0.228
1.83,67.03,0.228
1.84,67.09,0.228
1.85,67.16,0.228
1.85,67.23,0.228
1.86,67.29,0.228
1.87,67.36,0.228
1.87,67.43,0.228
1.88,67.49,0.228
1.89,67.56,0.228
1.89,67.62,0.228
1.90,67.69,0.228
1.91,67.76,0.228
1.91,67.83,0.229
1.92,67.89,0.229
1.93,67.96,0.229
1.93,68.03,0.229
1.94,68.09,0.229
1.95,68.16,0.229
1.95,68.23,0.229
1.96,68.29,0.229
1.97,68.36,0.229
1.97,68.43,0.229
1.98,68.49,0.229
1.99,68.56,0.229
1.99,68.63,0.229
2.00,68.69,0.229
2.01,68.76,0.229
2.01,68.83,0.229
2.02,68.89,0.229
2.03,68.96,0.229
2.03,69.03,0.229
2.04,69.09,0.229
2.05,69.16,0.229
2.05,69.23,0.229
2.06,69.29,0.229
2.07,69.36,0.229
2.07,69.42,0.229
2.08,69.49,0.229
2.09,69.56,0.229
2.09,69.63,0.229
2.10,69.69,0.229
2.11,69.76,0.229
2.11,69.83,0.229
2.12,69.89,0.230
2.13,69.96,0.230
2.13,70.03,0.230
2.14,70.09,0.230
2.15,70.16,0.230
2.15,70.22,0.231
2.16,70.29,0.231
2.17,70.36,0.231
2.17,70.43,0.231
2.18,70.49,0.231
2.19,70.56,0.231
2.19,70.62,0.231
2.20,70.69,0.231
2.21,70.76,0.231
2.21,70.83,0.231
2.22,70.89,0.231
2.23,70.96,0.231
2.23,71.03,0.231
2.24,71.09,0.231
2.25,71.16,0.231
2.25,71.23,0.231
2.26,71.29,0.231
2.27,71.36,0.231
2.27,71.43,0.232
2.28,71.49,0.232
2.29,71.56,0.232
2.29,71.62,0.232
2.30,71.69,0.232
2.31,71.76,0.232
2.31,71.83,0.232
2.32,71.89,0.232
2.33,71.96,0.232
2.33,72.03,0.232
2.34,72.09,0.232
2.35,72.16,0.232
2.35,72.23,0.232
2.36,72.29,0.232
2.37,72.36,0.232
2.37,72.43,0.232
2.38,72.49,0.232
2.39,72.56,0.232
2.39,72.63,0.232
2.40,72.69,0.232
2.41,72.76,0.232
2.41,72.83,0.232
2.42,72.89,0.232
2.43,72.96,0.232
2.43,73.03,0.232
2.44,73.09,0.232
2.45,73.16,0.232
2.45,73.23,0.232
2.46,73.29,0.232
2.47,73.36,0.232
2.47,73.43,0.232
2.48,73.49,0.233
2.49,73.56,0.233
2.49,73.63,0.233
2.50,73.69,0.233
2.51,73.76,0.233
2.51,73.83,0.233
2.52,73.89,0.233
2.53,73.96,0.233
2.53,74.03,0.233
2.54,74.09,0.233
2.55,74.16,0.233
2.55,74.23,0.233
2.56,74.29,0.233
2.57,74.36,0.233
2.57,74.43,0.233
2.58,74.49,0.233
2.59,74.56,0.233
2.59,74.63,0.233
2.60,74.70,0.233
2.61,74.76,0.233
2.61,74.83,0.233
2.62,74.89,0.233
2.63,74.96,0.233
2.63,75.03,0.233
2.64,75.10,0.233
2.65,75.16,0.233
2.65,75.23,0.233
2.66,75.30,0.233
2.67,75.36,0.234
2.67,75.43,0.234
2.68,75.50,0.234
2.69,75.56,0.234
2.69,75.63,0.234
2.70,75.70,0.234
2.71,75.76,0.234
2.71,75.83,0.234
2.72,75.90,0.234
2.73,75.96,0.234
2.73,76.03,0.234
2.74,76.10,0.234
2.75,76.16,0.234
2.75,76.23,0.234
2.76,76.30,0.234
2.77,76.36,0.234
2.77,76.43,0.234
2.78,76.50,0.234
2.79,76.56,0.234
2.79,76.63,0.234
2.80,76.70,0.234
2.81,76.76,0.234
2.81,76.83,0.234
2.82,76.90,0.234
2.83,76.96,0.234
2.83,77.03,0.234
2.84,77.10,0.234
2.85,77.16,0.234
2.85,77.23,0.235
2.86,77.30,0.234
2.87,77.36,0.234
2.87,77.43,0.234
2.88,77.50,0.234
2.89,77.56,0.234
2.89,77.63,0.235
2.90,77.70,0.235
2.91,77.76,0.235
2.91,77.83,0.235
2.92,77.90,0.235
2.93,77.96,0.235
2.93,78.03,0.235
2.94,78.10,0.235
2.95,78.16,0.235
2.95,78.23,0.235
2.96,78.30,0.235
2.97,78.36,0.235
2.97,78.43,0.235
2.98,78.50,0.235
2.99,78.56,0.235
2.99,78.63,0.235
3.00,78.70,0.235
3.01,78.76,0.235
3.01,78.83,0.235
3.02,78.90,0.235
3.03,78.96,0.235
3.03,79.03,0.235
3.04,79.10,0.235
3.05,79.17,0.235
3.05,79.23,0.235
3.06,79.30,0.235
3.07,79.36,0.235
3.07,79.43,0.235
3.08,79.50,0.235
3.09,79.57,0.235
3.09,79.63,0.235
3.10,79.70,0.236
3.11,79.77,0.236
3.11,79.83,0.236
3.12,79.90,0.236
3.13,79.96,0.236
3.13,80.03,0.236
3.14,80.10,0.236
3.15,80.16,0.236
3.15,80.23,0.236
3.16,80.30,0.236
3.17,80.37,0.236
3.17,80.43,0.236
3.18,80.50,0.236
3.19,80.57,0.236
3.19,80.63,0.236
3.20,80.70,0.236
3.21,80.77,0.236
3.21,80.83,0.236
3.22,80.90,0.236
3.23,80.97,0.236
3.23,81.03,0.236
3.24,81.10,0.236
3.25,81.17,0.236
3.25,81.23,0.236
3.26,81.30,0.236
3.27,81.37,0.236
3.27,81.43,0.236
3.28,81.50,0.236
3.29,81.57,0.236
3.29,81.63,0.236
3.30,81.70,0.236
3.31,81.77,0.236
3.31,81.83,0.236
3.32,81.90,0.236
3.33,81.97,0.236
3.33,82.03,0.236
3.34,82.10,0.236
3.35,82.17,0.236
3.35,82.23,0.236
3.36,82.30,0.236
3.37,82.37,0.237
3.37,82.43,0.237
3.38,82.50,0.237
3.39,82.57,0.237
3.39,82.64,0.237
3.40,82.70,0.237
3.41,82.77,0.237
3.41,82.83,0.237
3.42,82.90,0.237
3.43,82.97,0.237
3.43,83.03,0.237
3.44,83.10,0.237
3.45,83.17,0.237
3.45,83.23,0.237
3.46,83.30,0.237
3.47,83.37,0.237
3.47,83.43,0.237
3.48,83.50,0.237
3.49,83.57,0.237
3.49,83.63,0.237
3.50,83.70,0.237
3.51,83.77,0.237
3.51,83.83,0.237
3.52,83.90,0.237
3.53,83.97,0.237
3.53,84.04,0.237
3.54,84.10,0.237
3.55,84.17,0.237
3.55,84.23,0.237
3.56,84.30,0.237
3.57,84.37,0.237
3.57,84.44,0.237
3.58,84.50,0.237
3.59,84.57,0.237
3.59,84.63,0.237
3.60,84.70,0.237
3.61,84.77,0.237
3.61,84.84,0.237
3.62,84.90,0.237
3.63,84.97,0.237
3.63,85.04,0.237
3.64,85.10,0.237
3.65,85.17,0.237
3.65,85.24,0.237
3.66,85.30,0.237
3.67,85.37,0.237
3.67,85.44,0.237
3.68,85.50,0.237
3.69,85.57,0.237
3.69,85.64,0.237
3.70,85.70,0.237
3.71,85.77,0.237
3.71,85.84,0.237
3.72,85.90,0.237
3.73,85.97,0.237
3.73,86.04,0.237
3.74,86.10,0.237
3.75,86.17,0.237
3.75,86.24,0.237
3.76,86.30,0.237
3.77,86.37,0.237
3.77,86.44,0.237
3.78,86.50,0.237
3.79,86.57,0.238
3.79,86.64,0.238
3.80,86.70,0.238
3.81,86.77,0.238
3.81,86.84,0.238
3.82,86.90,0.238
3.83,86.97,0.238
3.83,87.04,0.238
3.84,87.10,0.238
3.85,87.17,0.238
3.85,87.24,0.238
3.86,87.30,0.238
3.87,87.37,0.238
3.87,87.44,0.238
3.88,87.50,0.238
3.89,87.57,0.238
3.89,87.64,0.238
3.90,87.70,0.238
3.91,87.77,0.238
3.91,87.84,0.238
3.92,87.91,0.238
3.93,87.97,0.238
3.93,88.04,0.238
3.94,88.10,0.238
3.95,88.17,0.238
3.95,88.24,0.238
3.96,88.30,0.238
3.97,88.37,0.238
3.97,88.44,0.238
3.98,88.50,0.238
3.99,88.57,0.238
3.99,88.64,0.238
4.00,88.71,0.238
4.01,88.77,0.238
4.01,88.84,0.238
4.02,88.90,0.238
4.03,88.97,0.239
4.03,89.04,0.239
4.04,89.10,0.239
4.05,89.17,0.239
4.05,89.24,0.239
4.06,89.30,0.239
4.07,89.37,0.239
4.07,89.44,0.239
4.08,89.50,0.239
4.09,89.57,0.239
4.09,89.64,0.239
4.10,89.71,0.239
4.11,89.77,0.239
4.11,89.84,0.239
4.12,89.90,0.239
4.13,89.97,0.239
4.13,90.04,0.239
4.14,90.11,0.239
4.15,90.17,0.239
4.15,90.24,0.239
4.16,90.30,0.239
4.17,90.37,0.239
4.17,90.44,0.240
4.18,90.51,0.240
4.19,90.57,0.240
4.19,90.64,0.240
4.20,90.71,0.240
4.21,90.77,0.240
4.21,90.84,0.240
4.22,90.91,0.240
4.23,90.97,0.240
4.23,91.04,0.240
4.24,91.11,0.240
4.25,91.17,0.240
4.25,91.24,0.240
4.26,91.31,0.240
4.27,91.37,0.240
4.27,91.44,0.240
4.28,91.51,0.240
4.29,91.57,0.241
4.29,91.64,0.241
4.30,91.71,0.241
4.31,91.77,0.241
4.31,91.84,0.241
4.32,91.91,0.241
4.33,91.97,0.241
4.33,92.04,0.241
4.34,92.11,0.241
4.35,92.17,0.241
4.35,92.24,0.241
4.36,92.31,0.241
4.37,92.37,0.241
4.37,92.44,0.241
4.38,92.51,0.241
4.39,92.57,0.241
4.39,92.64,0.241
4.40,92.71,0.241
4.41,92.77,0.241
4.41,92.84,0.242
4.42,92.91,0.242
4.43,92.97,0.242
4.43,93.04,0.242
4.44,93.11,0.242
4.45,93.17,0.242
4.45,93.24,0.242
4.46,93.31,0.242
4.47,93.37,0.242
4.47,93.44,0.242
4.48,93.51,0.242
4.49,93.57,0.242
4.49,93.64,0.242
4.50,93.71,0.242
4.51,93.78,0.242
4.51,93.84,0.242
4.52,93.91,0.242
4.53,93.97,0.242
4.53,94.04,0.243
4.54,94.11,0.243
4.55,94.17,0.243
4.55,94.24,0.243
4.56,94.31,0.243
4.57,94.37,0.243
4.57,94.44,0.243
4.58,94.51,0.243
4.59,94.57,0.243
4.59,94.64,0.243
4.60,94.71,0.243
4.61,94.77,0.243
4.61,94.84,0.243
4.62,94.91,0.243
4.63,94.97,0.243
4.63,95.04,0.243
4.64,95.11,0.243
4.65,95.17,0.243
4.65,95.24,0.243
4.66,95.31,0.243
4.67,95.37,0.243
4.67,95.44,0.243
4.68,95.51,0.244
4.69,95.58,0.244
4.69,95.64,0.244
4.70,95.71,0.244
4.71,95.78,0.244
4.71,95.84,0.244
4.72,95.91,0.244
4.73,95.98,0.244
4.73,96.04,0.244
4.74,96.11,0.244
4.75,96.18,0.244
4.75,96.24,0.244
4.76,96.31,0.244
4.77,96.38,0.244
4.77,96.44,0.244
4.78,96.51,0.244
4.79,96.58,0.244
4.79,96.64,0.244
4.80,96.71,0.245
4.81,96.78,0.245
4.81,96.84,0.245
4.82,96.91,0.245
4.83,96.98,0.245
4.83,97.04,0.245
4.84,97.11,0.245
4.85,97.18,0.245
4.85,97.24,0.245
4.86,97.31,0.245
4.87,97.38,0.245
4.87,97.44,0.245
4.88,97.51,0.245
4.89,97.58,0.245
4.89,97.64,0.245
4.90,97.71,0.245
4.91,97.78,0.245
4.91,97.84,0.245
4.92,97.91,0.245
4.93,97.98,0.245
4.93,98.04,0.245
4.94,98.11,0.245
4.95,98.18,0.246
4.95,98.24,0.246
4.96,98.31,0.246
4.97,98.38,0.246
4.97,98.44,0.246
4.98,98.51,0.246
4.99,98.58,0.246
4.99,98.64,0.246
5.00,98.71,0.246
5.01,98.78,0.246
5.01,98.84,0.246
5.02,98.91,0.246
5.03,98.98,0.246
5.03,99.04,0.246
5.04,99.11,0.246
5.05,99.18,0.246
5.05,99.24,0.246
5.06,99.31,0.246
5.07,99.38,0.246
5.07,99.44,0.246
5.08,99.51,0.246
5.09,99.58,0.246
5.09,99.64,0.246
5.10,99.71,0.247
5.11,99.78,0.247
5.11,99.85,0.247
5.12,99.91,0.247
5.13,99.98,0.247
5.13,100.05,0.247
5.14,100.11,0.247
5.15,100.18,0.247
5.15,100.25,0.247
5.16,100.31,0.247
5.17,100.38,0.247
5.17,100.44,0.247
5.18,100.51,0.247
5.19,100.58,0.247
5.19,100.65,0.247
5.20,100.71,0.247
5.21,100.78,0.247
5.21,100.84,0.247
5.22,100.91,0.247
5.23,100.98,0.247
5.23,101.04,0.247
5.24,101.11,0.247
5.25,101.18,0.247
5.25,101.24,0.247
5.26,101.31,0.248
5.27,101.38,0.248
5.27,101.45,0.248
5.28,101.51,0.248
5.29,101.58,0.248
5.29,101.65,0.248
5.30,101.71,0.248
5.31,101.78,0.248
5.31,101.85,0.248
5.32,101.91,0.248
5.33,101.98,0.248
5.33,102.05,0.248
5.34,102.11,0.248
5.35,102.18,0.248
5.35,102.25,0.248
5.36,102.31,0.248
5.37,102.38,0.248
5.37,102.45,0.248
5.38,102.51,0.248
5.39,102.58,0.248
5.39,102.65,0.248
5.40,102.71,0.248
5.41,102.78,0.248
5.41,102.85,0.248
5.42,102.91,0.248
5.43,102.98,0.248
5.43,103.05,0.249
5.44,103.11,0.249
5.45,103.18,0.249
5.45,103.25,0.249
5.46,103.31,0.249
5.47,103.38,0.249
5.47,103.45,0.249
5.48,103.51,0.249
5.49,103.58,0.249
5.49,103.65,0.249
5.50,103.71,0.249
5.51,103.78,0.249
5.51,103.85,0.249
5.52,103.91,0.249
5.53,103.98,0.249
5.53,104.05,0.249
5.54,104.11,0.249
5.55,104.18,0.249
5.55,104.25,0.249
5.56,104.31,0.249
5.57,104.38,0.250
5.57,104.45,0.250
5.58,104.51,0.250
5.59,104.58,0.250
5.59,104.65,0.250
5.60,104.71,0.250
5.61,104.78,0.250
5.61,104.85,0.250
5.62,104.91,0.250
5.63,104.98,0.250
5.63,105.05,0.250
5.64,105.11,0.250
5.65,105.18,0.250
5.65,105.25,0.250
5.66,105.31,0.250
5.67,105.38,0.250
5.67,105.45,0.250
5.68,105.52,0.250
5.69,105.58,0.250
5.69,105.65,0.251
5.70,105.72,0.251
5.71,105.78,0.251
5.71,105.85,0.251
5.72,105.92,0.251
5.73,105.98,0.251
5.73,106.05,0.251
5.74,106.12,0.251
5.75,106.18,0.251
5.75,106.25,0.251
5.76,106.31,0.251
5.77,106.38,0.251
5.77,106.45,0.251
5.78,106.52,0.251
5.79,106.58,0.251
5.79,106.65,0.251
5.80,106.71,0.251
5.81,106.78,0.251
5.81,106.85,0.251
5.82,106.91,0.251
5.83,106.98,0.251
5.83,107.05,0.252
5.84,107.11,0.251
5.85,107.18,0.252
5.85,107.25,0.252
5.86,107.32,0.252
5.87,107.38,0.252
5.87,107.45,0.252
5.88,107.52,0.252
5.89,107.58,0.252
5.89,107.65,0.252
5.90,107.72,0.252
5.91,107.78,0.252
5.91,107.85,0.252
5.92,107.92,0.252
5.93,107.98,0.252
5.93,108.05,0.252
5.94,108.12,0.252
5.95,108.18,0.252
5.95,108.25,0.252
5.96,108.32,0.252
5.97,108.38,0.252
5.97,108.45,0.252
5.98,108.52,0.253
5.99,108.58,0.253
5.99,108.65,0.253
6.00,108.72,0.253
6.01,108.78,0.253
6.01,108.85,0.253
6.02,108.92,0.253
6.03,108.98,0.253
6.03,109.05,0.253
6.04,109.12,0.253
6.05,109.18,0.253
6.05,109.25,0.253
6.06,109.32,0.253
6.07,109.38,0.253
6.07,109.45,0.253
6.08,109.52,0.253
6.09,109.58,0.253
6.09,109.65,0.253
6.10,109.72,0.253
6.11,109.78,0.254
6.11,109.85,0.254
6.12,109.92,0.254
6.13,109.98,0.254
6.13,110.05,0.254
6.14,110.12,0.254
6.15,110.18,0.254
6.15,110.25,0.254
6.16,110.32,0.254
6.17,110.38,0.254
6.17,110.45,0.254
6.18,110.52,0.254
6.19,110.58,0.254
6.19,110.65,0.254
6.20,110.72,0.254
6.21,110.78,0.254
6.21,110.85,0.254
6.22,110.92,0.254
6.23,110.98,0.254
6.23,111.05,0.254
6.24,111.12,0.254
6.25,111.18,0.255
6.25,111.25,0.255
6.26,111.32,0.255
6.27,111.39,0.255
6.27,111.45,0.255
6.28,111.52,0.255
6.29,111.58,0.255
6.29,111.65,0.255
6.30,111.72,0.255
6.31,111.78,0.255
6.31,111.85,0.255
6.32,111.92,0.255
6.33,111.98,0.255
6.33,112.05,0.255
6.34,112.12,0.255
6.35,112.19,0.255
6.35,112.25,0.255
6.36,112.32,0.255
6.37,112.39,0.255
6.37,112.45,0.256
6.38,112.52,0.256
6.39,112.59,0.256
6.39,112.65,0.256
6.40,112.72,0.256
6.41,112.79,0.256
6.41,112.85,0.256
6.42,112.92,0.256
6.43,112.99,0.256
6.43,113.05,0.256
6.44,113.12,0.256
6.45,113.19,0.256
6.45,113.25,0.256
6.46,113.32,0.256
6.47,113.39,0.256
6.47,113.45,0.256
6.48,113.52,0.256
6.49,113.59,0.256
6.49,113.65,0.257
6.50,113.72,0.257
6.51,113.79,0.257
6.51,113.85,0.257
6.52,113.92,0.257
6.53,113.99,0.257
6.53,114.05,0.257
6.54,114.12,0.257
6.55,114.19,0.257
6.55,114.25,0.257
6.56,114.32,0.257
6.57,114.39,0.257
6.57,114.45,0.257
6.58,114.52,0.257
6.59,114.59,0.257
6.59,114.65,0.257
6.60,114.72,0.257
6.61,114.79,0.257
6.61,114.85,0.257
6.62,114.92,0.257
6.63,114.99,0.258
6.63,115.05,0.258
6.64,115.12,0.258
6.65,115.19,0.258
6.65,115.25,0.258
6.66,115.32,0.258
6.67,115.39,0.258
6.67,115.45,0.258
6.68,115.52,0.258
6.69,115.59,0.258
6.69,115.65,0.258
6.70,115.72,0.258
6.71,115.79,0.258
6.71,115.85,0.258
6.72,115.92,0.258
6.73,115.99,0.259
6.73,116.05,0.259
6.74,116.12,0.259
6.75,116.19,0.259
6.75,116.25,0.259
6.76,116.32,0.259
6.77,116.39,0.259
6.77,116.45,0.259
6.78,116.52,0.259
6.79,116.59,0.259
6.79,116.65,0.259
6.80,116.72,0.259
6.81,116.79,0.259
6.81,116.85,0.259
6.82,116.92,0.259
6.83,116.99,0.259
6.83,117.05,0.259
6.84,117.12,0.260
6.85,117.19,0.260
6.85,117.25,0.260
6.86,117.32,0.260
6.87,117.39,0.260
6.87,117.45,0.260
6.88,117.52,0.260
6.89,117.59,0.260
6.89,117.65,0.260
6.90,117.72,0.260
6.91,117.79,0.260
6.91,117.85,0.260
6.92,117.92,0.260
6.93,117.99,0.260
6.93,118.05,0.261
6.94,118.12,0.261
6.95,118.19,0.261
6.95,118.25,0.261
6.96,118.32,0.261
6.97,118.39,0.261
6.97,118.46,0.261
6.98,118.52,0.261
6.99,118.59,0.261
6.99,118.65,0.261
7.00,118.72,0.261
7.01,118.79,0.261
7.01,118.85,0.261
7.02,118.92,0.262
7.03,118.99,0.262
7.03,119.06,0.262
7.04,119.12,0.262
7.05,119.19,0.262
7.05,119.25,0.262
7.06,119.32,0.262
7.07,119.39,0.262
7.07,119.46,0.262
7.08,119.52,0.262
7.09,119.59,0.262
7.09,119.66,0.263
7.10,119.72,0.263
7.11,119.79,0.263
7.11,119.86,0.263
7.12,119.92,0.263
7.13,119.99,0.263
7.13,120.05,0.263
7.14,120.12,0.263
7.15,120.19,0.263
7.15,120.25,0.264
7.16,120.32,0.264
7.17,120.39,0.264
7.17,120.46,0.264
7.18,120.52,0.264
7.19,120.59,0.264
7.19,120.66,0.264
7.20,120.72,0.265
7.21,120.79,0.265
7.21,120.86,0.265
7.22,120.92,0.265
7.23,120.99,0.266
7.23,121.06,0.266
7.24,121.12,0.266
7.25,121.19,0.266
7.25,121.25,0.267
7.26,121.32,0.267
7.27,121.39,0.267
7.27,121.46,0.268
7.28,121.52,0.270
7.29,121.59,0.272
7.29,121.65,0.273
7.30,121.72,0.277
7.31,121.79,0.282
7.31,121.85,0.289
7.32,121.92,0.302
7.33,121.99,0.319
7.33,122.05,0.344
7.34,122.12,0.399
7.35,122.18,0.530
7.35,122.24,0.799
7.36,122.29,1.258
7.37,122.33,1.866
7.37,122.36,2.403
7.38,122.39,2.747
7.39,122.42,2.940
7.39,122.44,3.142
7.40,122.47,3.415
7.41,122.50,3.635
7.41,122.53,3.817
7.42,122.55,4.025
7.43,122.58,4.247
7.43,122.61,4.485
7.44,122.64,4.707
7.45,122.67,4.966
7.45,122.69,5.325
7.46,122.71,5.702
7.47,122.73,6.026
7.47,122.75,6.247
7.48,122.77,6.359
7.49,122.80,6.430
7.49,122.83,6.545
7.50,122.86,6.720
7.51,122.89,6.854
7.51,122.92,6.890
7.52,122.96,6.855
7.53,123.00,6.789
7.53,123.05,6.713
7.54,123.10,6.633
7.55,123.15,6.609
7.55,123.21,6.670
7.56,123.26,6.813
7.57,123.31,7.128
7.57,123.36,7.390
7.58,123.40,7.429
7.59,123.45,7.534
7.59,123.50,7.648
7.60,123.55,7.626
7.61,123.60,7.663
7.61,123.65,7.935
7.62,123.69,8.242
7.63,123.73,8.300
7.63,123.78,8.194
7.64,123.83,8.167
7.65,123.88,8.213
7.65,123.94,8.225
7.66,123.99,8.293
7.67,124.04,8.468
7.67,124.10,8.346
7.68,124.16,7.863
7.69,124.24,7.353
7.69,124.32,6.872
7.70,124.42,6.320
7.71,124.52,5.652
7.71,124.63,5.073
7.72,124.75,4.721
7.73,124.86,4.455
7.73,124.98,4.298
7.74,125.09,4.209
7.75,125.19,3.885
7.75,125.31,3.186
7.76,125.44,2.535
7.77,125.57,2.194
7.77,125.70,1.993
7.78,125.82,1.842
7.79,125.93,1.721
7.79,126.05,1.614
7.80,126.16,1.521
7.81,126.27,1.433
7.81,126.37,1.350
7.82,126.47,1.276
7.83,126.57,1.209
7.83,126.67,1.145
7.84,126.77,1.089
7.85,126.86,1.030
7.85,126.95,0.974
7.86,127.04,0.942
7.87,127.12,0.893
7.87,127.21,0.849
7.88,127.29,0.814
7.89,127.38,0.780
7.89,127.46,0.749
7.90,127.54,0.716
7.91,127.62,0.689
7.91,127.70,0.667
7.92,127.77,0.643
7.93,127.85,0.619
7.93,127.93,0.601
7.94,128.00,0.581
7.95,128.08,0.563
7.95,128.15,0.549
7.96,128.23,0.532
7.97,128.30,0.518
7.97,128.37,0.508
7.98,128.44,0.495
7.99,128.51,0.482
7.99,128.59,0.473
8.00,128.66,0.465
8.01,128.73,0.456
8.01,128.80,0.448
8.02,128.87,0.440
8.03,128.94,0.432
8.03,129.01,0.428
8.04,129.08,0.423
8.05,129.15,0.415
8.05,129.22,0.409
8.06,129.29,0.405
8.07,129.35,0.402
8.07,129.42,0.400
8.08,129.49,0.393
8.09,129.56,0.390
8.09,129.63,0.388
8.10,129.70,0.386
8.11,129.76,0.383
8.11,129.83,0.381
8.12,129.90,0.379
8.13,129.97,0.376
8.13,130.04,0.373
8.14,130.10,0.371
8.15,130.17,0.370
8.15,130.24,0.370
8.16,130.30,0.369
8.17,130.37,0.367
8.17,130.44,0.367
8.18,130.51,0.366
8.19,130.57,0.365
8.19,130.64,0.365
8.20,130.71,0.364
8.21,130.78,0.364
8.21,130.84,0.363
8.22,130.91,0.363
8.23,130.98,0.362
8.23,131.04,0.362
8.24,131.11,0.361
8.25,131.18,0.360
8.25,131.24,0.359
8.26,131.31,0.359
8.27,131.38,0.358
8.27,131.44,0.358
8.28,131.51,0.357
8.29,131.58,0.357
8.29,131.64,0.357
8.30,131.71,0.357
8.31,131.78,0.356
8.31,131.85,0.356
8.32,131.91,0.356
8.33,131.98,0.356
8.33,132.05,0.356
8.34,132.11,0.356
8.35,132.18,0.356
8.35,132.25,0.356
8.36,132.31,0.356
8.37,132.38,0.356
8.37,132.45,0.355
8.38,132.51,0.355
8.39,132.58,0.355
8.39,132.65,0.355
8.40,132.71,0.355
8.41,132.78,0.355
8.41,132.85,0.355
8.42,132.91,0.355
8.43,132.98,0.355
8.43,133.05,0.355
8.44,133.11,0.355
8.45,133.18,0.355
8.45,133.25,0.355
8.46,133.31,0.355
8.47,133.38,0.355
8.47,133.45,0.354
8.48,133.51,0.354
8.49,133.58,0.354
8.49,133.65,0.354
8.50,133.72,0.354
8.51,133.78,0.354
8.51,133.85,0.354
8.52,133.91,0.354
8.53,133.98,0.354
8.53,134.05,0.354
8.54,134.12,0.354
8.55,134.18,0.354
8.55,134.25,0.354
8.56,134.32,0.354
8.57,134.38,0.354
8.57,134.45,0.354
8.58,134.52,0.354
8.59,134.58,0.354
8.59,134.65,0.354
8.60,134.72,0.354
8.61,134.78,0.354
8.61,134.85,0.354
8.62,134.92,0.354
8.63,134.98,0.354
8.63,135.05,0.354
8.64,135.12,0.354
8.65,135.18,0.354
8.65,135.25,0.354
8.66,135.32,0.354
8.67,135.38,0.354
8.67,135.45,0.354
8.68,135.52,0.354
8.69,135.58,0.354
8.69,135.65,0.354
8.70,135.72,0.354
8.71,135.78,0.354
8.71,135.85,0.354
8.72,135.92,0.354
8.73,135.98,0.354
8.73,136.05,0.354
8.74,136.12,0.354
8.75,136.18,0.354
8.75,136.25,0.354
8.76,136.32,0.354
8.77,136.38,0.354
8.77,136.45,0.354
8.78,136.52,0.354
8.79,136.58,0.354
8.79,136.65,0.354
8.80,136.72,0.354
8.81,136.78,0.354
8.81,136.85,0.354
8.82,136.92,0.354
8.83,136.98,0.354
8.83,137.05,0.354
8.84,137.12,0.354
8.85,137.18,0.354
8.85,137.25,0.354
8.86,137.32,0.354
8.87,137.38,0.354
8.87,137.45,0.354
8.88,137.52,0.354
8.89,137.58,0.354
8.89,137.65,0.354
8.90,137.72,0.354
8.91,137.78,0.354
8.91,137.85,0.354
8.92,137.92,0.354
8.93,137.98,0.354
8.93,138.05,0.354
8.94,138.12,0.355
8.95,138.18,0.355
8.95,138.25,0.355
8.96,138.32,0.355
8.97,138.38,0.355
8.97,138.45,0.355
8.98,138.52,0.355
8.99,138.58,0.355
8.99,138.65,0.355
9.00,138.72,0.355
9.01,138.78,0.355
9.01,138.85,0.355
9.02,138.92,0.355
9.03,138.98,0.355
9.03,139.05,0.355
9.04,139.12,0.355
9.05,139.18,0.355
9.05,139.25,0.355
9.06,139.32,0.355
9.07,139.38,0.356
9.07,139.45,0.356
9.08,139.52,0.356
9.09,139.59,0.356
9.09,139.65,0.356
9.10,139.72,0.356
9.11,139.78,0.356
9.11,139.85,0.356
9.12,139.92,0.356
9.13,139.98,0.356
9.13,140.05,0.356
9.14,140.12,0.356
9.15,140.18,0.356
9.15,140.25,0.356
9.16,140.32,0.356
9.17,140.38,0.356
9.17,140.45,0.356
9.18,140.52,0.356
9.19,140.58,0.356
9.19,140.65,0.357
9.20,140.72,0.357
9.21,140.78,0.357
9.21,140.85,0.357
9.22,140.92,0.357
9.23,140.99,0.357
9.23,141.05,0.357
9.24,141.12,0.357
9.25,141.19,0.357
9.25,141.25,0.357
9.26,141.32,0.357
9.27,141.39,0.357
9.27,141.45,0.357
9.28,141.52,0.357
9.29,141.59,0.357
9.29,141.65,0.357
9.30,141.72,0.358
9.31,141.78,0.358
9.31,141.85,0.358
9.32,141.92,0.358
9.33,141.98,0.358
9.33,142.05,0.358
9.34,142.12,0.358
9.35,142.18,0.358
9.35,142.25,0.358
9.36,142.32,0.358
9.37,142.38,0.358
9.37,142.45,0.358
9.38,142.52,0.358
9.39,142.58,0.358
9.39,142.65,0.358
9.40,142.72,0.358
9.41,142.79,0.358
9.41,142.85,0.359
9.42,142.92,0.359
9.43,142.99,0.359
9.43,143.05,0.359
9.44,143.12,0.359
9.45,143.18,0.359
9.45,143.25,0.359
9.46,143.32,0.359
9.47,143.39,0.359
9.47,143.45,0.359
9.48,143.52,0.359
9.49,143.59,0.359
9.49,143.65,0.359
9.50,143.72,0.359
9.51,143.79,0.359
9.51,143.85,0.360
9.52,143.92,0.360
9.53,143.99,0.360
9.53,144.05,0.360
9.54,144.12,0.360
9.55,144.19,0.360
9.55,144.25,0.360
9.56,144.32,0.360
9.57,144.39,0.360
9.57,144.45,0.360
9.58,144.52,0.360
9.59,144.58,0.360
9.59,144.65,0.360
9.60,144.72,0.360
9.61,144.79,0.360
9.61,144.85,0.360
9.62,144.92,0.360
9.63,144.99,0.360
9.63,145.05,0.361
9.64,145.12,0.361
9.65,145.19,0.361
9.65,145.25,0.361
9.66,145.32,0.361
9.67,145.39,0.361
9.67,145.45,0.361
9.68,145.52,0.361
9.69,145.59,0.361
9.69,145.65,0.361
9.70,145.72,0.361
9.71,145.79,0.361
9.71,145.85,0.361
9.72,145.92,0.361
9.73,145.99,0.362
9.73,146.05,0.362
9.74,146.12,0.362
9.75,146.19,0.362
9.75,146.25,0.362
9.76,146.32,0.362
9.77,146.39,0.362
9.77,146.45,0.362
9.78,146.52,0.362
9.79,146.59,0.362
9.79,146.65,0.362
9.80,146.72,0.362
9.81,146.79,0.362
9.81,146.85,0.362
9.82,146.92,0.362
9.83,146.99,0.362
9.83,147.05,0.362
9.84,147.12,0.363
9.85,147.19,0.363
9.85,147.25,0.363
9.86,147.32,0.363
9.87,147.39,0.363
9.87,147.45,0.363
9.88,147.52,0.363
9.89,147.59,0.363
9.89,147.65,0.363
9.90,147.72,0.363
9.91,147.79,0.363
9.91,147.85,0.363
9.92,147.92,0.363
9.93,147.99,0.363
9.93,148.05,0.364
9.94,148.12,0.364
9.95,148.19,0.364
9.95,148.25,0.364
9.96,148.32,0.364
9.97,148.39,0.364
9.97,148.45,0.364
9.98,148.52,0.364
9.99,148.59,0.364
9.99,148.65,0.364

[step]
Ramp 10.00 °C/min to 50.00 °C
Time,Temperature,Heat Flow (Normalized)
min,°C,W/g
11.00,150.09,-0.059
11.00,150.09,-0.060
11.01,150.09,-0.060
11.02,150.09,-0.060
11.02,150.09,-0.060
11.03,150.08,-0.060
11.03,150.08,-0.060
11.04,150.08,-0.060
11.05,150.07,-0.059
11.05,150.07,-0.058
11.06,150.06,-0.055
11.07,150.05,-0.049
11.08,150.03,-0.045
11.08,150.01,-0.043
11.09,149.99,-0.042
11.10,149.97,-0.042
11.10,149.95,-0.043
11.11,149.92,-0.048
11.12,149.88,-0.072
11.12,149.85,-0.091
11.13,149.81,-0.106
11.13,149.77,-0.126
11.14,149.73,-0.145
11.15,149.69,-0.168
11.15,149.64,-0.187
11.16,149.59,-0.208
11.17,149.54,-0.227
11.18,149.49,-0.245
11.18,149.44,-0.262
11.19,149.39,-0.278
11.20,149.34,-0.294
11.20,149.28,-0.308
11.21,149.23,-0.320
11.22,149.17,-0.331
11.22,149.12,-0.342
11.23,149.06,-0.350
11.23,149.00,-0.360
11.24,148.95,-0.369
11.25,148.89,-0.375
11.25,148.83,-0.380
11.26,148.77,-0.387
11.27,148.71,-0.395
11.28,148.65,-0.401
11.28,148.59,-0.405
11.29,148.52,-0.410
11.30,148.46,-0.416
11.30,148.40,-0.421
11.31,148.34,-0.423
11.32,148.28,-0.428
11.32,148.22,-0.432
11.33,148.15,-0.432
11.33,148.09,-0.435
11.34,148.03,-0.440
11.35,147.96,-0.442
11.35,147.90,-0.446
11.36,147.84,-0.448
11.37,147.77,-0.449
11.38,147.71,-0.452
11.38,147.64,-0.452
11.39,147.58,-0.453
11.40,147.52,-0.457
11.40,147.45,-0.459
11.41,147.39,-0.459
11.42,147.32,-0.460
11.42,147.26,-0.462
11.43,147.19,-0.462
11.43,147.13,-0.463
11.44,147.06,-0.464
11.45,147.00,-0.466
11.45,146.93,-0.467
11.46,146.87,-0.467
11.47,146.80,-0.467
11.48,146.74,-0.467
11.48,146.67,-0.468
11.49,146.61,-0.469
11.50,146.54,-0.470
11.50,146.48,-0.470
11.51,146.41,-0.470
11.52,146.35,-0.471
11.52,146.28,-0.471
11.53,146.22,-0.471
11.53,146.15,-0.472
11.54,146.09,-0.472
11.55,146.02,-0.472
11.55,145.96,-0.472
11.56,145.89,-0.473
11.57,145.82,-0.473
11.58,145.76,-0.473
11.58,145.69,-0.473
11.59,145.63,-0.473
11.60,145.56,-0.473
11.60,145.50,-0.474
11.61,145.43,-0.474
11.62,145.37,-0.474
11.62,145.30,-0.474
11.63,145.23,-0.474
11.63,145.17,-0.475
11.64,145.10,-0.475
11.65,145.04,-0.475
11.65,144.97,-0.475
11.66,144.91,-0.475
11.67,144.84,-0.475
11.68,144.77,-0.475
11.68,144.71,-0.475
11.69,144.64,-0.475
11.70,144.58,-0.476
11.70,144.51,-0.476
11.71,144.44,-0.476
11.72,144.38,-0.476
11.72,144.31,-0.476
11.73,144.25,-0.476
11.73,144.18,-0.476
11.74,144.11,-0.476
11.75,144.05,-0.477
11.75,143.98,-0.477
11.76,143.92,-0.477
11.77,143.85,-0.477
11.78,143.78,-0.477
11.78,143.72,-0.477
11.79,143.65,-0.477
11.80,143.59,-0.477
11.80,143.52,-0.477
11.81,143.45,-0.477
11.82,143.39,-0.477
11.82,143.32,-0.477
11.83,143.26,-0.478
11.83,143.19,-0.478
11.84,143.12,-0.478
11.85,143.06,-0.478
11.85,142.99,-0.478
11.86,142.93,-0.478
11.87,142.86,-0.478
11.88,142.79,-0.478
11.88,142.73,-0.478
11.89,142.66,-0.478
11.90,142.60,-0.478
11.90,142.53,-0.478
11.91,142.46,-0.478
11.92,142.40,-0.478
11.92,142.33,-0.478
11.93,142.26,-0.478
11.93,142.20,-0.478
11.94,142.13,-0.478
11.95,142.07,-0.478
11.95,142.00,-0.478
11.96,141.93,-0.478
11.97,141.87,-0.478
11.98,141.80,-0.478
11.98,141.73,-0.478
11.99,141.67,-0.478
12.00,141.60,-0.479
12.00,141.54,-0.479
12.01,141.47,-0.479
12.02,141.40,-0.478
12.02,141.34,-0.478
12.03,141.27,-0.479
12.03,141.20,-0.479
12.04,141.14,-0.479
12.05,141.07,-0.479
12.05,141.01,-0.479
12.06,140.94,-0.479
12.07,140.87,-0.478
12.08,140.81,-0.478
12.08,140.74,-0.478
12.09,140.67,-0.478
12.10,140.61,-0.478
12.10,140.54,-0.478
12.11,140.47,-0.478
12.12,140.41,-0.478
12.12,140.34,-0.478
12.13,140.28,-0.478
12.13,140.21,-0.478
12.14,140.14,-0.478
12.15,140.08,-0.478
12.15,140.01,-0.478
12.16,139.94,-0.478
12.17,139.88,-0.478
12.18,139.81,-0.478
12.18,139.74,-0.478
12.19,139.68,-0.478
12.20,139.61,-0.478
12.20,139.54,-0.478
12.21,139.48,-0.478
12.22,139.41,-0.478
12.22,139.35,-0.478
12.23,139.28,-0.478
12.23,139.21,-0.478
12.24,139.15,-0.478
12.25,139.08,-0.478
12.25,139.01,-0.478
12.26,138.95,-0.478
12.27,138.88,-0.478
12.28,138.81,-0.478
12.28,138.75,-0.477
12.29,138.68,-0.477
12.30,138.62,-0.477
12.30,138.55,-0.477
12.31,138.48,-0.477
12.32,138.42,-0.477
12.32,138.35,-0.477
12.33,138.28,-0.477
12.33,138.22,-0.477
12.34,138.15,-0.477
12.35,138.08,-0.476
12.35,138.02,-0.476
12.36,137.95,-0.476
12.37,137.88,-0.476
12.38,137.82,-0.476
12.38,137.75,-0.476
12.39,137.68,-0.476
12.40,137.62,-0.476
12.40,137.55,-0.476
12.41,137.48,-0.476
12.42,137.42,-0.476
12.42,137.35,-0.476
12.43,137.28,-0.476
12.43,137.22,-0.476
12.44,137.15,-0.476
12.45,137.09,-0.476
12.45,137.02,-0.476
12.46,136.95,-0.476
12.47,136.89,-0.475
12.48,136.82,-0.475
12.48,136.75,-0.475
12.49,136.69,-0.475
12.50,136.62,-0.475
12.50,136.55,-0.475
12.51,136.49,-0.475
12.52,136.42,-0.475
12.52,136.35,-0.475
12.53,136.29,-0.475
12.53,136.22,-0.475
12.54,136.16,-0.475
12.55,136.09,-0.475
12.55,136.02,-0.474
12.56,135.96,-0.474
12.57,135.89,-0.474
12.58,135.82,-0.474
12.58,135.76,-0.474
12.59,135.69,-0.474
12.60,135.62,-0.474
12.60,135.56,-0.474
12.61,135.49,-0.474
12.62,135.42,-0.474
12.62,135.36,-0.474
12.63,135.29,-0.474
12.63,135.22,-0.474
12.64,135.16,-0.473
12.65,135.09,-0.473
12.65,135.02,-0.473
12.66,134.96,-0.473
12.67,134.89,-0.473
12.68,134.82,-0.473
12.68,134.76,-0.473
12.69,134.69,-0.473
12.70,134.62,-0.473
12.70,134.56,-0.473
12.71,134.49,-0.473
12.72,134.42,-0.472
12.72,134.36,-0.472
12.73,134.29,-0.472
12.73,134.22,-0.472
12.74,134.16,-0.472
12.75,134.09,-0.472
12.75,134.03,-0.472
12.76,133.96,-0.472
12.77,133.89,-0.472
12.78,133.83,-0.472
12.78,133.76,-0.472
12.79,133.69,-0.472
12.80,133.62,-0.471
12.80,133.56,-0.471
12.81,133.49,-0.471
12.82,133.43,-0.471
12.82,133.36,-0.471
12.83,133.29,-0.471
12.83,133.23,-0.471
12.84,133.16,-0.471
12.85,133.09,-0.471
12.85,133.03,-0.470
12.86,132.96,-0.470
12.87,132.89,-0.470
12.88,132.83,-0.470
12.88,132.76,-0.470
12.89,132.69,-0.470
12.90,132.63,-0.470
12.90,132.56,-0.470
12.91,132.49,-0.470
12.92,132.43,-0.470
12.92,132.36,-0.470
12.93,132.29,-0.470
12.93,132.23,-0.469
12.94,132.16,-0.469
12.95,132.10,-0.469
12.95,132.03,-0.469
12.96,131.96,-0.469
12.97,131.90,-0.469
12.98,131.83,-0.469
12.98,131.76,-0.469
12.99,131.70,-0.469
13.00,131.63,-0.469
13.00,131.56,-0.469
13.01,131.50,-0.468
13.02,131.43,-0.468
13.02,131.36,-0.468
13.03,131.30,-0.468
13.03,131.23,-0.468
13.04,131.16,-0.468
13.05,131.10,-0.468
13.05,131.03,-0.468
13.06,130.96,-0.468
13.07,130.90,-0.468
13.08,130.83,-0.468
13.08,130.76,-0.467
13.09,130.70,-0.467
13.10,130.63,-0.467
13.10,130.56,-0.467
13.11,130.50,-0.467
13.12,130.43,-0.467
13.12,130.36,-0.467
13.13,130.30,-0.467
13.13,130.23,-0.467
13.14,130.16,-0.466
13.15,130.10,-0.466
13.15,130.03,-0.466
13.16,129.96,-0.466
13.17,129.90,-0.466
13.18,129.83,-0.466
13.18,129.76,-0.466
13.19,129.70,-0.466
13.20,129.63,-0.466
13.20,129.56,-0.466
13.21,129.50,-0.466
13.22,129.43,-0.465
13.22,129.37,-0.465
13.23,129.30,-0.465
13.23,129.23,-0.465
13.24,129.16,-0.465
13.25,129.10,-0.465
13.25,129.03,-0.465
13.26,128.97,-0.465
13.27,128.90,-0.465
13.28,128.83,-0.465
13.28,128.77,-0.465
13.29,128.70,-0.465
13.30,128.63,-0.464
13.30,128.57,-0.464
13.31,128.50,-0.464
13.32,128.43,-0.464
13.32,128.37,-0.464
13.33,128.30,-0.464
13.33,128.23,-0.464
13.34,128.17,-0.464
13.35,128.10,-0.464
13.35,128.03,-0.464
13.36,127.97,-0.464
13.37,127.90,-0.463
13.38,127.83,-0.463
13.38,127.77,-0.463
13.39,127.70,-0.463
13.40,127.63,-0.463
13.40,127.57,-0.463
13.41,127.50,-0.463
13.42,127.43,-0.463
13.42,127.37,-0.463
13.43,127.30,-0.463
13.43,127.23,-0.463
13.44,127.17,-0.463
13.45,127.10,-0.463
13.45,127.03,-0.462
13.46,126.97,-0.462
13.47,126.90,-0.462
13.48,126.83,-0.462
13.48,126.77,-0.462
13.49,126.70,-0.462
13.50,126.63,-0.462
13.50,126.57,-0.462
13.51,126.50,-0.461
13.52,126.43,-0.461
13.52,126.37,-0.461
13.53,126.30,-0.461
13.53,126.23,-0.461
13.54,126.17,-0.461
13.55,126.10,-0.461
13.55,126.04,-0.461
13.56,125.97,-0.461
13.57,125.90,-0.461
13.58,125.84,-0.460
13.58,125.77,-0.460
13.59,125.70,-0.460
13.60,125.64,-0.460
13.60,125.57,-0.460
13.61,125.50,-0.460
13.62,125.43,-0.460
13.62,125.37,-0.460
13.63,125.30,-0.460
13.63,125.24,-0.460
13.64,125.17,-0.459
13.65,125.10,-0.459
13.65,125.04,-0.459
13.66,124.97,-0.459
13.67,124.90,-0.459
13.68,124.84,-0.459
13.68,124.77,-0.459
13.69,124.70,-0.459
13.70,124.64,-0.459
13.70,124.57,-0.458
13.71,124.50,-0.458
13.72,124.44,-0.458
13.72,124.37,-0.458
13.73,124.30,-0.458
13.73,124.24,-0.458
13.74,124.17,-0.458
13.75,124.10,-0.458
13.75,124.04,-0.458
13.76,123.97,-0.458
13.77,123.90,-0.458
13.78,123.84,-0.457
13.78,123.77,-0.457
13.79,123.70,-0.457
13.80,123.64,-0.457
13.80,123.57,-0.457
13.81,123.50,-0.457
13.82,123.44,-0.457
13.82,123.37,-0.457
13.83,123.30,-0.457
13.83,123.24,-0.457
13.84,123.17,-0.457
13.85,123.11,-0.457
13.85,123.04,-0.456
13.86,122.97,-0.456
13.87,122.90,-0.456
13.88,122.84,-0.456
13.88,122.77,-0.456
13.89,122.70,-0.456
13.90,122.64,-0.456
13.90,122.57,-0.456
13.91,122.51,-0.456
13.92,122.44,-0.456
13.92,122.37,-0.456
13.93,122.31,-0.456
13.93,122.24,-0.455
13.94,122.17,-0.455
13.95,122.11,-0.455
13.95,122.04,-0.455
[...]
26.63,94.95,0.249,1.327
26.63,95.01,0.249,1.327
26.64,95.08,0.249,1.328
26.65,95.14,0.249,1.328
26.66,95.21,0.249,1.328
26.66,95.28,0.249,1.328
26.67,95.34,0.249,1.328
26.68,95.41,0.249,1.328
26.68,95.48,0.249,1.329
26.69,95.54,0.249,1.329
26.69,95.61,0.249,1.329
26.70,95.68,0.249,1.330
26.71,95.74,0.250,1.330
26.72,95.81,0.250,1.330
26.72,95.88,0.250,1.330
26.73,95.94,0.250,1.331
26.73,96.01,0.250,1.331
26.74,96.08,0.250,1.331
26.75,96.14,0.250,1.331
26.76,96.21,0.250,1.331
26.76,96.28,0.250,1.331
26.77,96.34,0.250,1.332
26.78,96.41,0.250,1.332
26.78,96.48,0.250,1.332
26.79,96.55,0.250,1.332
26.79,96.61,0.250,1.333
26.80,96.68,0.250,1.333
26.81,96.75,0.250,1.334
26.82,96.81,0.250,1.334
26.82,96.88,0.250,1.334
26.83,96.95,0.250,1.334
26.83,97.01,0.250,1.335
26.84,97.08,0.251,1.335
26.85,97.14,0.251,1.335
26.86,97.21,0.251,1.335
26.86,97.28,0.251,1.336
26.87,97.35,0.251,1.336
26.88,97.41,0.251,1.337
26.88,97.48,0.251,1.337
26.89,97.55,0.251,1.337
26.89,97.61,0.251,1.337
26.90,97.68,0.251,1.338
26.91,97.75,0.251,1.338
26.92,97.81,0.251,1.338
26.92,97.88,0.251,1.339
26.93,97.95,0.251,1.338
26.93,98.01,0.251,1.339
26.94,98.08,0.251,1.339
26.95,98.15,0.251,1.338
26.96,98.21,0.251,1.339
26.96,98.28,0.251,1.340
26.97,98.35,0.251,1.340
26.98,98.41,0.251,1.340
26.98,98.48,0.251,1.340
26.99,98.55,0.252,1.340
26.99,98.61,0.252,1.340
27.00,98.68,0.252,1.340
27.01,98.75,0.252,1.340
27.02,98.81,0.252,1.340
27.02,98.88,0.252,1.341
27.03,98.95,0.252,1.341
27.03,99.01,0.252,1.341
27.04,99.08,0.252,1.342
27.05,99.15,0.252,1.342
27.06,99.21,0.252,1.342
27.06,99.28,0.252,1.342
27.07,99.35,0.252,1.342
27.08,99.41,0.252,1.343
27.08,99.48,0.252,1.343
27.09,99.55,0.252,1.342
27.09,99.61,0.252,1.343
27.10,99.68,0.252,1.343
27.11,99.75,0.252,1.343
27.12,99.81,0.252,1.343
27.12,99.88,0.252,1.343
27.13,99.95,0.252,1.344
27.13,100.01,0.252,1.344
27.14,100.08,0.253,1.345
27.15,100.15,0.253,1.345
27.16,100.21,0.253,1.346
27.16,100.28,0.253,1.346
27.17,100.35,0.253,1.346
27.18,100.41,0.253,1.346
27.18,100.48,0.253,1.346
27.19,100.55,0.253,1.347
27.19,100.61,0.253,1.348
27.20,100.68,0.253,1.348
27.21,100.75,0.253,1.348
27.22,100.82,0.253,1.348
27.22,100.88,0.253,1.348
27.23,100.95,0.253,1.348
27.23,101.01,0.253,1.349
27.24,101.08,0.253,1.349
27.25,101.15,0.253,1.349
27.26,101.21,0.253,1.349
27.26,101.28,0.253,1.349
27.27,101.35,0.254,1.350
27.28,101.42,0.254,1.350
27.28,101.48,0.254,1.350
27.29,101.55,0.254,1.351
27.29,101.62,0.254,1.351
27.30,101.68,0.254,1.351
27.31,101.75,0.254,1.351
27.32,101.82,0.254,1.352
27.32,101.88,0.254,1.352
27.33,101.95,0.254,1.352
27.33,102.01,0.254,1.352
27.34,102.08,0.254,1.352
27.35,102.15,0.254,1.352
27.36,102.22,0.254,1.352
27.36,102.28,0.254,1.352
27.37,102.35,0.254,1.352
27.38,102.42,0.254,1.352
27.38,102.48,0.254,1.353
27.39,102.55,0.254,1.353
27.39,102.62,0.254,1.354
27.40,102.68,0.254,1.354
27.41,102.75,0.254,1.354
27.42,102.81,0.254,1.354
27.42,102.88,0.254,1.354
27.43,102.95,0.254,1.355
27.43,103.02,0.254,1.355
27.44,103.08,0.254,1.355
27.45,103.15,0.255,1.355
27.46,103.22,0.255,1.355
27.46,103.28,0.255,1.356
27.47,103.35,0.255,1.357
27.48,103.42,0.255,1.357
27.48,103.48,0.255,1.357
27.49,103.55,0.255,1.357
27.49,103.62,0.255,1.357
27.50,103.68,0.255,1.357
27.51,103.75,0.255,1.358
27.52,103.82,0.255,1.358
27.52,103.88,0.255,1.358
27.53,103.95,0.255,1.359
27.53,104.02,0.255,1.359
27.54,104.08,0.255,1.359
27.55,104.15,0.255,1.359
27.56,104.22,0.255,1.359
27.56,104.28,0.255,1.360
27.57,104.35,0.255,1.360
27.58,104.42,0.255,1.361
27.58,104.48,0.255,1.360
27.59,104.55,0.256,1.360
27.59,104.62,0.256,1.361
27.60,104.68,0.256,1.361
27.61,104.75,0.256,1.361
27.62,104.82,0.256,1.361
27.62,104.88,0.256,1.361
27.63,104.95,0.256,1.362
27.63,105.02,0.256,1.362
27.64,105.08,0.256,1.362
27.65,105.15,0.256,1.362
27.66,105.22,0.256,1.362
27.66,105.28,0.256,1.362
27.67,105.35,0.256,1.362
27.68,105.42,0.256,1.363
27.68,105.48,0.256,1.363
27.69,105.55,0.256,1.363
27.69,105.62,0.256,1.364
27.70,105.68,0.256,1.364
27.71,105.75,0.256,1.364
27.72,105.82,0.256,1.365
27.72,105.88,0.256,1.364
27.73,105.95,0.256,1.364
27.73,106.02,0.257,1.365
27.74,106.08,0.257,1.366
27.75,106.15,0.257,1.366
27.76,106.22,0.257,1.366
27.76,106.28,0.257,1.367
27.77,106.35,0.257,1.367
27.78,106.42,0.257,1.367
27.78,106.48,0.257,1.367
27.79,106.55,0.257,1.367
27.79,106.62,0.257,1.367
27.80,106.68,0.257,1.368
27.81,106.75,0.257,1.368
27.82,106.82,0.257,1.369
27.82,106.88,0.257,1.369
27.83,106.95,0.257,1.368
27.83,107.02,0.257,1.369
27.84,107.08,0.257,1.369
27.85,107.15,0.257,1.370
27.86,107.22,0.258,1.370
27.86,107.28,0.258,1.370
27.87,107.35,0.258,1.370
27.88,107.42,0.258,1.370
27.88,107.48,0.258,1.370
27.89,107.55,0.258,1.371
27.89,107.62,0.258,1.371
27.90,107.68,0.258,1.371
27.91,107.75,0.258,1.371
27.92,107.82,0.258,1.371
27.92,107.88,0.258,1.372
27.93,107.95,0.258,1.373
27.93,108.02,0.258,1.373
27.94,108.08,0.258,1.373
27.95,108.15,0.258,1.373
27.96,108.22,0.258,1.373
27.96,108.29,0.258,1.373
27.97,108.35,0.258,1.373
27.98,108.42,0.258,1.373
27.98,108.49,0.258,1.374
27.99,108.55,0.259,1.375
27.99,108.62,0.259,1.375
28.00,108.69,0.259,1.375
28.01,108.75,0.259,1.375
28.02,108.82,0.259,1.375
28.02,108.88,0.259,1.375
28.03,108.95,0.259,1.376
28.03,109.02,0.259,1.376
28.04,109.09,0.259,1.377
28.05,109.15,0.259,1.377
28.06,109.22,0.259,1.378
28.06,109.29,0.259,1.379
28.07,109.35,0.259,1.379
28.08,109.42,0.259,1.379
28.08,109.49,0.259,1.379
28.09,109.55,0.259,1.379
28.09,109.62,0.259,1.380
28.10,109.69,0.260,1.381
28.11,109.75,0.260,1.381
28.12,109.82,0.260,1.381
28.12,109.89,0.260,1.381
28.13,109.95,0.260,1.381
28.13,110.02,0.260,1.382
28.14,110.09,0.260,1.382
28.15,110.15,0.260,1.383
28.16,110.22,0.260,1.383
28.16,110.29,0.260,1.383
28.17,110.35,0.260,1.384
28.18,110.42,0.260,1.384
28.18,110.49,0.260,1.384
28.19,110.55,0.260,1.384
28.19,110.62,0.260,1.385
28.20,110.69,0.260,1.385
28.21,110.75,0.260,1.386
28.22,110.82,0.261,1.386
28.22,110.89,0.261,1.386
28.23,110.95,0.261,1.386
28.23,111.02,0.261,1.387
28.24,111.09,0.261,1.387
28.25,111.15,0.261,1.387
28.26,111.22,0.261,1.387
28.26,111.29,0.261,1.387
28.27,111.35,0.261,1.388
28.28,111.42,0.261,1.388
28.28,111.49,0.261,1.388
28.29,111.55,0.261,1.389
28.29,111.62,0.261,1.389
28.30,111.69,0.261,1.390
28.31,111.75,0.261,1.390
28.32,111.82,0.261,1.390
28.32,111.89,0.262,1.390
28.33,111.95,0.262,1.392
28.33,112.02,0.262,1.394
28.34,112.09,0.262,1.394
28.35,112.15,0.262,1.393
28.36,112.22,0.262,1.394
28.36,112.29,0.262,1.395
28.37,112.35,0.262,1.395
28.38,112.42,0.262,1.395
28.38,112.49,0.263,1.396
28.39,112.55,0.263,1.396
28.39,112.62,0.263,1.396
28.40,112.69,0.263,1.397
28.41,112.75,0.263,1.397
28.42,112.82,0.263,1.398
28.42,112.89,0.263,1.398
28.43,112.95,0.263,1.398
28.43,113.02,0.263,1.399
28.44,113.09,0.263,1.399
28.45,113.15,0.263,1.400
28.46,113.22,0.263,1.400
28.46,113.29,0.263,1.400
28.47,113.35,0.264,1.401
28.48,113.42,0.264,1.402
28.48,113.49,0.264,1.402
28.49,113.56,0.264,1.402
28.49,113.62,0.264,1.403
28.50,113.69,0.264,1.403
28.51,113.75,0.264,1.403
28.52,113.82,0.264,1.404
28.52,113.89,0.264,1.405
28.53,113.95,0.264,1.405
28.53,114.02,0.264,1.406
28.54,114.09,0.265,1.407
28.55,114.16,0.265,1.407
28.56,114.22,0.265,1.407
28.56,114.29,0.265,1.408
28.57,114.35,0.265,1.409
28.58,114.42,0.265,1.409
28.58,114.49,0.265,1.410
28.59,114.55,0.265,1.410
28.59,114.62,0.265,1.411
28.60,114.69,0.266,1.412
28.61,114.75,0.266,1.412
28.62,114.82,0.266,1.413
28.62,114.89,0.266,1.413
28.63,114.96,0.266,1.414
28.63,115.02,0.266,1.415
28.64,115.09,0.266,1.415
28.65,115.16,0.266,1.416
28.66,115.22,0.266,1.416
28.66,115.29,0.266,1.417
28.67,115.35,0.267,1.417
28.68,115.42,0.267,1.417
28.68,115.49,0.267,1.418
28.69,115.55,0.267,1.419
28.69,115.62,0.267,1.419
28.70,115.69,0.267,1.420
28.71,115.75,0.268,1.423
28.72,115.82,0.268,1.424
28.72,115.89,0.268,1.425
28.73,115.95,0.268,1.426
28.73,116.02,0.268,1.426
28.74,116.09,0.268,1.427
28.75,116.15,0.269,1.428
28.76,116.22,0.269,1.430
28.76,116.29,0.269,1.431
28.77,116.35,0.269,1.432
28.78,116.42,0.270,1.433
28.78,116.49,0.270,1.434
28.79,116.56,0.270,1.435
28.79,116.62,0.270,1.436
28.80,116.69,0.270,1.437
28.81,116.75,0.270,1.438
28.82,116.82,0.271,1.439
28.82,116.89,0.271,1.440
28.83,116.95,0.271,1.442
28.83,117.02,0.271,1.443
28.84,117.09,0.272,1.444
28.85,117.15,0.272,1.445
28.86,117.22,0.272,1.447
28.86,117.29,0.272,1.448
28.87,117.35,0.273,1.450
28.88,117.42,0.273,1.452
28.88,117.49,0.273,1.453
28.89,117.55,0.273,1.455
28.89,117.62,0.274,1.459
28.90,117.69,0.274,1.460
28.91,117.75,0.275,1.462
28.92,117.82,0.275,1.464
28.92,117.89,0.276,1.467
28.93,117.95,0.276,1.471
28.93,118.02,0.277,1.472
28.94,118.09,0.277,1.475
28.95,118.15,0.279,1.487
28.96,118.22,0.280,1.490
28.96,118.29,0.280,1.493
28.97,118.35,0.281,1.498
28.98,118.42,0.282,1.501
28.98,118.49,0.284,1.510
28.99,118.55,0.285,1.518
28.99,118.62,0.286,1.523
29.00,118.69,0.287,1.530
29.01,118.75,0.289,1.541
29.02,118.82,0.291,1.551
29.02,118.89,0.293,1.560
29.03,118.95,0.294,1.569
29.03,119.02,0.297,1.581
29.04,119.09,0.299,1.594
29.05,119.15,0.303,1.614
29.06,119.22,0.306,1.631
29.06,119.28,0.308,1.643
29.07,119.35,0.311,1.662
29.08,119.42,0.315,1.681
29.08,119.48,0.317,1.695
29.09,119.55,0.322,1.719
29.09,119.62,0.325,1.739
29.10,119.68,0.329,1.760
29.11,119.75,0.333,1.784
29.12,119.82,0.339,1.819
29.12,119.88,0.344,1.844
29.13,119.95,0.348,1.866
29.13,120.01,0.355,1.906
29.14,120.08,0.361,1.946
29.15,120.15,0.367,1.981
29.16,120.21,0.374,2.019
29.16,120.28,0.380,2.058
29.17,120.34,0.390,2.114
29.18,120.41,0.399,2.169
29.18,120.48,0.410,2.232
29.19,120.54,0.422,2.303
29.19,120.61,0.432,2.369
29.20,120.67,0.446,2.454
29.21,120.74,0.464,2.566
29.22,120.80,0.481,2.672
29.22,120.87,0.499,2.784
29.23,120.93,0.521,2.930
29.23,121.00,0.545,3.090
29.24,121.06,0.573,3.280
29.25,121.12,0.607,3.512
29.26,121.19,0.641,3.754
29.26,121.25,0.681,4.046
29.27,121.31,0.726,4.382
29.28,121.37,0.774,4.757
29.28,121.43,0.830,5.203
29.29,121.50,0.893,5.715
29.29,121.56,0.964,6.304
29.30,121.61,1.047,7.003
29.31,121.67,1.145,7.839
29.32,121.73,1.265,8.875
29.32,121.78,1.405,10.099
29.33,121.84,1.563,11.515
29.33,121.89,1.739,13.135
29.34,121.94,1.941,15.020
29.35,121.98,2.173,17.219
29.36,122.03,2.440,19.793
29.36,122.07,2.730,22.678
29.37,122.10,3.023,25.697
29.38,122.14,3.308,28.743
29.38,122.17,3.579,31.769
29.39,122.20,3.847,34.836
29.39,122.23,4.105,37.857
29.40,122.26,4.359,40.882
29.41,122.29,4.600,43.797
29.42,122.32,4.823,46.527
29.42,122.34,5.037,49.134
29.43,122.37,5.227,51.376
29.43,122.40,5.398,53.236
29.44,122.43,5.570,54.915
29.45,122.46,5.741,56.381
29.46,122.49,5.903,57.564
29.46,122.53,6.056,58.421
29.47,122.56,6.198,58.886
29.48,122.59,6.331,59.046
29.48,122.63,6.453,58.945
29.49,122.67,6.559,58.578
29.49,122.70,6.647,57.974
29.50,122.74,6.742,57.346
29.51,122.78,6.842,56.713
29.52,122.83,6.931,55.917
29.52,122.87,6.990,54.902
29.53,122.91,7.030,53.789
29.53,122.96,7.054,52.582
29.54,123.01,7.074,51.415
29.55,123.06,7.111,50.456
29.56,123.11,7.163,49.638
29.56,123.17,7.197,48.737
29.57,123.22,7.188,47.573
29.58,123.28,7.178,46.439
29.58,123.33,7.191,45.452
29.59,123.39,7.206,44.437
29.59,123.45,7.206,43.256
29.60,123.51,7.195,41.901
29.61,123.57,7.176,40.387
29.62,123.63,7.155,38.756
29.62,123.70,7.117,37.000
29.63,123.76,7.071,35.293
29.63,123.83,7.042,33.834
29.64,123.89,7.022,32.585
29.65,123.96,6.998,31.466
29.66,124.03,6.959,30.412
29.66,124.09,6.916,29.453
29.67,124.16,6.862,28.564
29.68,124.23,6.757,27.552
29.68,124.31,6.570,26.291
29.69,124.39,6.286,24.733
29.69,124.47,5.884,22.803
29.70,124.56,5.343,20.422
29.71,124.67,4.651,17.559
29.72,124.78,3.886,14.512
29.72,124.91,3.174,11.740
29.73,125.04,2.629,9.638
29.73,125.17,2.287,8.321
29.74,125.30,2.073,7.490
29.75,125.42,1.915,6.878
29.76,125.54,1.785,6.375
29.76,125.66,1.671,5.940
29.77,125.77,1.573,5.571
29.78,125.88,1.481,5.227
29.78,125.99,1.395,4.916
29.79,126.09,1.319,4.649
29.79,126.19,1.248,4.405
29.80,126.29,1.181,4.191
29.81,126.39,1.121,4.014
29.82,126.48,1.067,3.868
29.82,126.57,1.004,3.701
29.83,126.66,0.961,3.612
29.83,126.75,0.924,3.547
29.84,126.84,0.870,3.405
29.85,126.92,0.833,3.327
29.86,127.01,0.802,3.260
29.86,127.09,0.766,3.169
29.87,127.17,0.734,3.089
29.88,127.25,0.706,3.016
29.88,127.33,0.681,2.953
29.89,127.41,0.656,2.882
29.89,127.48,0.632,2.816
29.90,127.56,0.611,2.756
29.91,127.64,0.591,2.694
29.92,127.71,0.574,2.643
29.92,127.78,0.557,2.590
29.93,127.86,0.541,2.538
29.93,127.93,0.529,2.505
29.94,128.01,0.516,2.464
29.95,128.08,0.502,2.414
29.96,128.15,0.489,2.371
29.96,128.22,0.480,2.338
29.97,128.29,0.472,2.313
29.98,128.36,0.463,2.285
29.98,128.43,0.452,2.239
29.99,128.50,0.446,2.221
29.99,128.57,0.440,2.200
30.00,128.64,0.433,2.174
30.01,128.71,0.426,2.150
30.02,128.78,0.418,2.119
30.02,128.85,0.414,2.103
30.03,128.92,0.411,2.093
30.03,128.99,0.405,2.069
30.04,129.06,0.400,2.051
30.05,129.13,0.398,2.047
30.06,129.19,0.395,2.033
30.06,129.26,0.390,2.015
30.07,129.33,0.388,2.007
30.08,129.40,0.385,1.997
30.08,129.47,0.383,1.987
30.09,129.53,0.382,1.984
30.09,129.60,0.379,1.972
30.10,129.67,0.377,1.964
30.11,129.74,0.376,1.961
30.12,129.80,0.374,1.956
30.12,129.87,0.373,1.952
30.13,129.94,0.371,1.940
30.13,130.01,0.369,1.935
30.14,130.08,0.369,1.937
30.15,130.14,0.369,1.935
30.16,130.21,0.368,1.931
30.16,130.28,0.367,1.928
30.17,130.34,0.366,1.923
30.18,130.41,0.365,1.920
30.18,130.48,0.364,1.919
30.19,130.55,0.364,1.918
30.19,130.61,0.364,1.917
30.20,130.68,0.363,1.917
30.21,130.75,0.363,1.916
30.22,130.81,0.363,1.915
30.22,130.88,0.362,1.912
30.23,130.95,0.362,1.911
30.23,131.01,0.362,1.911
30.24,131.08,0.361,1.910
30.25,131.15,0.361,1.910
30.26,131.21,0.361,1.909
30.26,131.28,0.361,1.907
30.27,131.35,0.361,1.907
30.28,131.41,0.360,1.906
30.28,131.48,0.360,1.905
30.29,131.55,0.360,1.904
30.29,131.62,0.360,1.904
30.30,131.68,0.359,1.902
30.31,131.75,0.359,1.901
30.32,131.82,0.359,1.901
30.32,131.88,0.359,1.900
30.33,131.95,0.359,1.899
30.33,132.02,0.359,1.899
30.34,132.08,0.358,1.898
30.35,132.15,0.358,1.897
30.36,132.22,0.358,1.897
30.36,132.28,0.358,1.897
30.37,132.35,0.358,1.896
30.38,132.42,0.358,1.895
30.38,132.48,0.358,1.895
30.39,132.55,0.358,1.894
30.39,132.62,0.357,1.894
30.40,132.68,0.357,1.893
30.41,132.75,0.357,1.893
30.42,132.82,0.357,1.892
30.42,132.88,0.357,1.892
30.43,132.95,0.357,1.891
30.43,133.02,0.357,1.891
30.44,133.08,0.357,1.890
30.45,133.15,0.357,1.889
30.46,133.22,0.357,1.889
30.46,133.28,0.357,1.888
30.47,133.35,0.357,1.888
30.48,133.42,0.356,1.888
30.48,133.48,0.356,1.887
30.49,133.55,0.356,1.887
30.49,133.62,0.356,1.887
30.50,133.68,0.356,1.886
30.51,133.75,0.356,1.886
30.52,133.82,0.356,1.886
30.52,133.88,0.356,1.885
30.53,133.95,0.356,1.885
30.53,134.02,0.356,1.885
30.54,134.08,0.356,1.885
30.55,134.15,0.356,1.885
30.56,134.22,0.356,1.884
30.56,134.28,0.356,1.884
30.57,134.35,0.356,1.884
30.58,134.42,0.356,1.883
30.58,134.48,0.356,1.883
30.59,134.55,0.356,1.883
30.59,134.62,0.355,1.883
30.60,134.68,0.356,1.883
30.61,134.75,0.356,1.883
30.62,134.82,0.356,1.883
30.62,134.88,0.355,1.883
30.63,134.95,0.355,1.883
30.63,135.02,0.355,1.883
30.64,135.08,0.355,1.883
30.65,135.15,0.355,1.884
30.66,135.22,0.355,1.883
30.66,135.28,0.355,1.883
30.67,135.35,0.355,1.883
30.68,135.42,0.355,1.883
30.68,135.48,0.355,1.883
30.69,135.55,0.355,1.883
30.69,135.62,0.355,1.882
30.70,135.69,0.355,1.883
30.71,135.75,0.355,1.883
30.72,135.82,0.355,1.883
30.72,135.88,0.355,1.883
30.73,135.95,0.355,1.883
30.73,136.02,0.355,1.883
30.74,136.09,0.356,1.883
30.75,136.15,0.356,1.884
30.76,136.22,0.356,1.884
30.76,136.29,0.356,1.884
30.77,136.35,0.356,1.884
30.78,136.42,0.356,1.884
30.78,136.49,0.356,1.885
30.79,136.55,0.356,1.885
30.79,136.62,0.356,1.885
30.80,136.69,0.356,1.885
30.81,136.75,0.356,1.886
30.82,136.82,0.356,1.886
30.82,136.89,0.356,1.886
30.83,136.95,0.356,1.886
30.83,137.02,0.356,1.885
30.84,137.09,0.356,1.886
30.85,137.15,0.356,1.887
30.86,137.22,0.356,1.887
30.86,137.28,0.356,1.887
30.87,137.35,0.356,1.887
30.88,137.42,0.356,1.886
30.88,137.49,0.356,1.887
30.89,137.55,0.356,1.887
30.89,137.62,0.356,1.887
30.90,137.69,0.356,1.887
30.91,137.75,0.356,1.887
30.92,137.82,0.356,1.888
30.92,137.88,0.356,1.887
30.93,137.95,0.357,1.889
30.93,138.02,0.357,1.890
30.94,138.09,0.357,1.890
30.95,138.15,0.357,1.889
30.96,138.22,0.357,1.889
30.96,138.29,0.357,1.889
30.97,138.35,0.357,1.889
30.98,138.42,0.357,1.889
30.98,138.49,0.357,1.889
30.99,138.55,0.357,1.889
30.99,138.62,0.357,1.889
31.00,138.69,0.357,1.890
31.01,138.75,0.357,1.891
31.02,138.82,0.357,1.890
31.02,138.89,0.357,1.890
31.03,138.95,0.357,1.891
31.03,139.02,0.357,1.891
31.04,139.09,0.357,1.891
31.05,139.15,0.357,1.891
31.06,139.22,0.357,1.891
31.06,139.29,0.357,1.891
31.07,139.35,0.357,1.891
31.08,139.42,0.358,1.892
31.08,139.49,0.358,1.893
31.09,139.55,0.358,1.893
31.09,139.62,0.358,1.893
31.10,139.69,0.358,1.894
31.11,139.75,0.358,1.896
31.12,139.82,0.358,1.896
31.12,139.89,0.358,1.896
31.13,139.95,0.358,1.896
31.13,140.02,0.358,1.896
31.14,140.09,0.358,1.897
31.15,140.15,0.358,1.897
31.16,140.22,0.359,1.898
31.16,140.29,0.359,1.898
31.17,140.35,0.359,1.899
31.18,140.42,0.359,1.899
31.18,140.49,0.359,1.899
31.19,140.55,0.359,1.900
31.19,140.62,0.359,1.900
31.20,140.69,0.359,1.900
31.21,140.75,0.359,1.900
31.22,140.82,0.359,1.901
31.22,140.89,0.359,1.901
31.23,140.95,0.359,1.901
31.23,141.02,0.359,1.901
31.24,141.09,0.359,1.901
31.25,141.15,0.359,1.901
31.26,141.22,0.359,1.902
31.26,141.29,0.359,1.902
31.27,141.35,0.359,1.903
31.28,141.42,0.359,1.903
31.28,141.49,0.359,1.903
31.29,141.55,0.359,1.903
31.29,141.62,0.360,1.903
31.30,141.69,0.360,1.903
31.31,141.75,0.360,1.903
31.32,141.82,0.360,1.903
31.32,141.89,0.360,1.904
31.33,141.95,0.360,1.904
31.33,142.02,0.360,1.905
31.34,142.09,0.360,1.905
31.35,142.15,0.360,1.905
31.36,142.22,0.360,1.905
31.36,142.29,0.360,1.905
31.37,142.35,0.360,1.904
31.38,142.42,0.360,1.905
31.38,142.49,0.360,1.905
31.39,142.55,0.360,1.906
31.39,142.62,0.360,1.907
31.40,142.69,0.360,1.907
31.41,142.75,0.360,1.907
31.42,142.82,0.361,1.908
31.42,142.89,0.361,1.908
31.43,142.95,0.361,1.908
31.43,143.02,0.361,1.908
31.44,143.09,0.361,1.909
31.45,143.15,0.361,1.909
31.46,143.22,0.361,1.909
31.46,143.29,0.361,1.909
31.47,143.35,0.361,1.910
31.48,143.42,0.361,1.910
31.48,143.49,0.361,1.911
31.49,143.55,0.361,1.911
31.49,143.62,0.361,1.911
31.50,143.69,0.361,1.911
31.51,143.75,0.361,1.911
31.52,143.82,0.361,1.912
31.52,143.89,0.362,1.912
31.53,143.95,0.362,1.912
31.53,144.02,0.362,1.912
31.54,144.09,0.362,1.913
31.55,144.15,0.362,1.913
31.56,144.22,0.362,1.914
31.56,144.29,0.362,1.914
31.57,144.35,0.362,1.914
31.58,144.42,0.362,1.915
31.58,144.49,0.362,1.915
31.59,144.55,0.362,1.915
31.59,144.62,0.362,1.915
31.60,144.69,0.362,1.916
31.61,144.75,0.362,1.916
31.62,144.82,0.362,1.916
31.62,144.89,0.363,1.916
31.63,144.95,0.363,1.917
31.63,145.02,0.363,1.918
31.64,145.09,0.363,1.918
31.65,145.15,0.363,1.919
31.66,145.22,0.363,1.919
31.66,145.29,0.363,1.919
31.67,145.36,0.363,1.919
31.68,145.42,0.363,1.920
31.68,145.49,0.363,1.920
31.69,145.56,0.363,1.920
31.69,145.62,0.363,1.920
31.70,145.69,0.363,1.921
31.71,145.76,0.363,1.921
31.72,145.82,0.363,1.921
31.72,145.89,0.363,1.922
31.73,145.96,0.364,1.922
31.73,146.02,0.364,1.922
31.74,146.09,0.364,1.923
31.75,146.16,0.364,1.923
31.76,146.22,0.364,1.923
31.76,146.29,0.364,1.923
31.77,146.36,0.364,1.924
31.78,146.42,0.364,1.924
31.78,146.49,0.364,1.924
31.79,146.56,0.364,1.925
31.79,146.62,0.364,1.925
31.80,146.69,0.364,1.926
31.81,146.76,0.364,1.926
31.82,146.82,0.364,1.926
31.82,146.89,0.364,1.927
31.83,146.96,0.364,1.927
31.83,147.02,0.365,1.927
31.84,147.09,0.365,1.927
31.85,147.16,0.365,1.928
31.86,147.22,0.365,1.928
31.86,147.29,0.365,1.929
31.87,147.36,0.365,1.929
31.88,147.42,0.365,1.930
31.88,147.49,0.365,
31.89,147.56,0.365,
31.89,147.62,0.365,
31.90,147.69,0.365,
31.91,147.76,0.365,
31.92,147.82,0.365,
31.92,147.89,0.366,
31.93,147.96,0.366,
31.93,148.02,0.366,
31.94,148.09,,
31.95,148.16,,
31.96,148.22,,
31.96,148.29,,
31.97,148.36,,
31.98,148.42,,
31.98,148.49,,
31.99,,,
31.99,,,