File: Data/2024_09_19_Benzoic_Acid_CHM343_DSC.txt
Filename	2024_09_19_Benzoic_Acid_CHM343_DSC
Instrument name	DSC2A-00468 (192.168.1.100)
Operator	CHM343
rundate	9/19/2024
Sample name	2024_09_19_Benzoic_Acid_CHM343_DSC
proceduresegments	Equilibrate 30.00 °C; Ramp 10.00 °C/min to 160.00 °C; Isothermal 1.0 min; Ramp 10.00 °C/min to 30.00 °C
[File Parameters]
Run date	9/19/2024 5:14:00 PM
Trios version	5.1.1.46572
Original File Name	C:\ProgramData\TA Instruments\TRIOS\Data\2024_09_19_Benzoic_Acid_CHM343_DSC.tri
Current File Name	D:\DSC2500\CHM343\2024_09_19_Benzoic_Acid_CHM343_DSC.tri
[Procedure]
Procedure Name	CHM343_Fall2024_BA
Sample Name	2024_09_19_Benzoic_Acid_CHM343_DSC
Sample Mass	2.94 mg
Reference Sample Mass	0 mg
Pan Mass	54.23 mg
Pan Number	20
Reference Pan Mass	54 mg
Reference Pan Number	19
Pan Type	Aluminum
Comments	Benzoic Acid - Al Hermetic Sealed Pan, with ref Al pan.  ASU Online CHM343, Remote DSC experimental lab. Fall 2024.  Group Zoom Data Collection, Sept 19, 2024 from 5-7 pm.  TA Instruments DSC2500.
Project Name	Lab 4 - Fall 2024
Operator	CHM343
Test	Custom
Unload Max Temperature	30
Unload Min Temperature	30
Load Max Temperature	30
Load Min Temperature	30
Stop on Gas Flow Error	Yes
[Signal List]
Signal #1	Time (min)
Signal #2	Temperature (°C)
Signal #3	Heat Flow (mW)
Signal #4	Delta T (µV)
Signal #5	Delta Tzero (µV)
Signal #6	Tzero Temperature (°C)
Signal #7	Cell Purge (mL/min)
Signal #8	Heater Temp (°C)
Signal #9	Power Delivered (W)
Signal #10	Reference Junction Temperature (°C)
Signal #11	Flange Temperature (°C)
Signal #12	Heat Flow Phase (rad)
Signal #13	Total Heat Capacity (J/°C)
Signal #14	Heat Capacity (J/°C)
[Configuration]
Company Name	ASU
Instrument Name	DSC2A-00468
Instrument Type	DSC2500
Serial Number	DSC2A-00468
IP	192.168.1.100
Location of Instrument	MRRC
DisplayType	Unknown
Sample Interval 	0.1 s/pt
Selected Heat Flow	T4P
Exotherm Direction	Down
Cell Serial	DRC2-00792
Lid Type	Standard
Cooler	RCS 90
Leave Cooler on at End of Sequence	On
Gas 2	Nitrogen
Gas Selected	Channel 1
Flow Rate	50 mL/min
Secondary Purge	On
Licensed Heat Flow	Heat Flow T4P
Modulation Licensed	Yes
[Versions]
Common IDD Version	1
Cortex Version	VER 2.10.2.31
Driver	5.0.0.6
GDM Version	1.0.3.3
TouchscreenVersion	1.0.0.16145
FEP Version	1.2.1.21
FEP Bootloader	2.0.0.5
AutoSampler Version	2.1.1.26
Auto Sampler Bootloader	2.0.0.5
FCM Version	1.1.0.3
FCM Bootloader	2.0.0.5
[Experiment Logs]
Experiment Log Entry # 1	Air Cool is off.
Experiment Log Entry # 3	Equilibrate Segment 30 (C) Started
Experiment Log Entry # 5	Ramp Segment 10 C/min to 160 Started
Experiment Log Entry # 7	Isothermal Segment 1 min started
Experiment Log Entry # 9	Ramp Segment 10 C/min to 30 Started
[Method Log]
Method Log Entry # 1	Equilibrate 30 °C
Method Log Entry # 2	(Ramp 719) Ramp 10 °C/minute to 160 °C
Method Log Entry # 3	Isothermal 1 minutes
Method Log Entry # 4	(Ramp 721) Ramp 10 °C/minute to 30 °C
Cell Serial	DRC2-00792
[T1 Calibration]
Slope	-0.008529666
Offset	9.636258
Initial Temperature	98.23
GUID	f8bfdadc-4977-4fdf-ba6d-0ba9134940c3
[TZero Calibration]
Date Applied	11/29/2022 4:06:13 PM
Description	From -89.059 °C to 396.009 °C at 20.000°C/min
Gas Type	Nitrogen
Pan Type	None
Source Files 1	C:\Users\yargerlab\Desktop\DSC Data\General\TZero_calibration_11_29_22_2nd(2).tri
Source Files 2	C:\Users\yargerlab\Desktop\DSC Data\General\TZero_calibration_11_29_22_2nd(3).tri
Delta T Offset	13.05235
Delta T Slope	-0.007271007
Delta T0 Offset	-13.69128
Delta T0 Slope	0.06063341
[Temperature Calibration]
Date Applied	11/29/2022 7:12:28 PM
Description	From 106.590 °C to 186.590 °C at 10.000°C/min
Gas Type	Nitrogen
Pan Type	Tzero Aluminum Hermetic
Source Files 1	C:\Users\yargerlab\Desktop\DSC Data\General\Indium(6).tri
Measured 1	157.391
Known 1	156.598
[Cell Constant Calibration]
Date Applied	11/29/2022 7:12:29 PM
Description	From 106.590 °C to 186.590 °C at 10.000°C/min
Gas Type	Nitrogen
Pan Type	Tzero Aluminum Hermetic
Source Files 1	C:\Users\yargerlab\Desktop\DSC Data\General\Indium(6).tri
T4P KCell	1.006051
Onset Slope	63.26126 mW/°C
[Direct Cp Calibration]
Date Applied	11/30/2022 11:04:51 AM
Description	From -79.983 °C to 298.409 °C at 10.000°C/min
Gas Type	Nitrogen
Pan Type	Tzero Aluminum Hermetic
Source Files 1	C:\Users\yargerlab\Desktop\DSC Data\General\Sapphire_Heat_Capacity_11_30_22.tri
[Rev Cp Calibration]
Date Applied	11/30/2022 1:58:51 PM
Description	From -79.996 °C to 292.812 °C at 3.000°C/min
Gas Type	Nitrogen
Pan Type	Tzero Aluminum Hermetic
Source Files 1	C:\Users\yargerlab\Desktop\DSC Data\General\Sapphire_MDSC_Calibration_11_30_22.tri
[step]
Ramp 10.00 °C/min to 160.00 °C
Time	Temperature	Heat Flow (Normalized)
min	°C	W/g
0.00	29.96	0.003
0.01	29.96	0.001
0.02	29.97	-0.001
0.03	29.98	-0.002
0.04	29.99	-0.003
0.05	30.00	-0.004
0.06	30.01	-0.007
0.07	30.03	-0.011
0.08	30.06	-0.015
0.09	30.09	-0.016
0.10	30.13	-0.017
0.11	30.18	-0.017
0.12	30.24	-0.013
0.13	30.29	0.003
0.14	30.36	0.021
0.15	30.43	0.040
0.16	30.50	0.056
0.17	30.57	0.070
0.18	30.65	0.087
0.19	30.73	0.102
0.20	30.81	0.113
0.21	30.90	0.125
0.22	30.98	0.135
0.23	31.07	0.144
0.24	31.16	0.151
0.25	31.25	0.157
0.26	31.34	0.164
0.27	31.43	0.169
0.28	31.52	0.173
0.29	31.61	0.180
0.30	31.71	0.185
0.31	31.80	0.189
0.32	31.90	0.192
0.33	31.99	0.195
0.34	32.09	0.198
0.35	32.18	0.201
0.36	32.28	0.205
0.37	32.38	0.207
0.38	32.47	0.208
0.39	32.57	0.209
0.40	32.67	0.212
0.41	32.77	0.214
0.42	32.86	0.215
0.43	32.96	0.216
0.44	33.06	0.217
0.45	33.16	0.218
0.46	33.26	0.220
0.47	33.36	0.221
0.48	33.46	0.221
0.49	33.55	0.222
0.50	33.65	0.222
0.51	33.75	0.222
0.52	33.85	0.223
0.53	33.95	0.224
0.54	34.05	0.224
0.55	34.15	0.224
0.56	34.25	0.225
0.57	34.35	0.225
0.58	34.45	0.225
0.59	34.55	0.225
0.60	34.65	0.226
0.61	34.75	0.226
0.62	34.85	0.226
0.63	34.94	0.226
0.64	35.04	0.227
0.65	35.14	0.227
0.66	35.24	0.227
0.67	35.34	0.227
0.68	35.44	0.227
0.69	35.54	0.228
0.70	35.64	0.228
0.71	35.74	0.228
0.72	35.84	0.228
0.73	35.94	0.228
0.74	36.04	0.228
0.75	36.14	0.229
0.76	36.24	0.229
0.77	36.34	0.229
0.78	36.44	0.229
0.79	36.54	0.229
0.80	36.64	0.229
0.81	36.74	0.230
0.82	36.84	0.230
0.83	36.94	0.230
0.84	37.04	0.230
0.85	37.14	0.230
0.86	37.23	0.230
0.87	37.33	0.230
0.88	37.43	0.230
0.89	37.53	0.231
0.90	37.63	0.231
0.91	37.73	0.231
0.92	37.83	0.231
0.93	37.93	0.231
0.94	38.03	0.231
0.95	38.13	0.231
0.96	38.23	0.231
0.97	38.33	0.231
0.98	38.43	0.232
0.99	38.53	0.232
1.00	38.63	0.232
1.01	38.73	0.232
1.02	38.83	0.232
1.03	38.93	0.232
1.04	39.03	0.232
1.05	39.13	0.232
1.06	39.23	0.232
1.07	39.33	0.232
1.08	39.43	0.232
1.09	39.53	0.233
1.10	39.63	0.233
1.11	39.73	0.233
1.12	39.83	0.233
1.13	39.93	0.233
1.14	40.03	0.233
1.15	40.13	0.233
1.16	40.23	0.233
1.17	40.33	0.233
1.18	40.43	0.233
1.19	40.53	0.233
1.20	40.63	0.233
1.21	40.73	0.233
1.22	40.83	0.233
1.23	40.93	0.233
1.24	41.03	0.233
1.25	41.13	0.233
1.26	41.23	0.233
1.27	41.33	0.233
1.28	41.43	0.234
1.29	41.53	0.234
1.30	41.63	0.234
1.31	41.73	0.234
1.32	41.83	0.234
1.33	41.93	0.234
1.34	42.02	0.234
1.35	42.13	0.234
1.36	42.22	0.234
1.37	42.33	0.234
1.38	42.43	0.234
1.39	42.53	0.234
1.40	42.63	0.234
1.41	42.73	0.234
1.42	42.82	0.234
1.43	42.92	0.234
1.44	43.02	0.234
1.45	43.12	0.234
1.46	43.22	0.234
1.47	43.32	0.234
1.48	43.42	0.234
1.49	43.52	0.234
1.50	43.62	0.234
1.51	43.72	0.235
1.52	43.83	0.235
1.53	43.92	0.235
1.54	44.02	0.235
1.55	44.12	0.235
1.56	44.22	0.235
1.57	44.32	0.235
1.58	44.42	0.235
1.59	44.52	0.235
1.60	44.62	0.235
1.61	44.72	0.235
1.62	44.82	0.235
1.63	44.92	0.235
1.64	45.02	0.235
1.65	45.12	0.235
1.66	45.22	0.235
1.67	45.32	0.235
1.68	45.42	0.235
1.69	45.52	0.235
1.70	45.62	0.235
1.71	45.72	0.235
1.72	45.82	0.236
1.73	45.92	0.236
1.74	46.02	0.236
1.75	46.12	0.236
1.76	46.22	0.236
1.77	46.32	0.236
1.78	46.42	0.236
1.79	46.52	0.236
1.80	46.62	0.236
1.81	46.72	0.236
1.82	46.82	0.236
1.83	46.92	0.236
1.84	47.02	0.236
1.85	47.12	0.236
1.86	47.22	0.236
1.87	47.32	0.236
1.88	47.42	0.236
1.89	47.52	0.236
1.90	47.63	0.236
1.91	47.72	0.236
1.92	47.82	0.237
1.93	47.93	0.237
1.94	48.02	0.237
1.95	48.13	0.237
1.96	48.23	0.237
1.97	48.32	0.237
1.98	48.42	0.237
1.99	48.52	0.237
2.00	48.63	0.237
2.01	48.72	0.237
2.02	48.82	0.237
2.03	48.92	0.237
2.04	49.02	0.237
2.05	49.12	0.237
2.06	49.22	0.237
2.07	49.32	0.237
2.08	49.42	0.237
2.09	49.52	0.237
2.10	49.63	0.237
2.11	49.72	0.237
2.12	49.83	0.237
2.13	49.93	0.237
2.14	50.03	0.237
2.15	50.13	0.237
2.16	50.23	0.237
2.17	50.33	0.237
2.18	50.43	0.237
2.19	50.53	0.238
2.20	50.63	0.238
2.21	50.73	0.238
2.22	50.83	0.238
2.23	50.93	0.238
2.24	51.03	0.238
2.25	51.13	0.238
2.26	51.23	0.238
2.27	51.33	0.238
2.28	51.43	0.238
2.29	51.53	0.238
2.30	51.63	0.238
2.31	51.73	0.238
2.32	51.83	0.238
2.33	51.93	0.238
2.34	52.03	0.238
2.35	52.13	0.238
2.36	52.23	0.238
2.37	52.33	0.238
2.38	52.43	0.238
2.39	52.53	0.238
2.40	52.63	0.239
2.41	52.73	0.239
2.42	52.83	0.239
2.43	52.93	0.239
2.44	53.03	0.239
2.45	53.13	0.239
2.46	53.23	0.239
2.47	53.33	0.239
2.48	53.43	0.239
2.49	53.53	0.239
2.50	53.63	0.239
2.51	53.73	0.239
2.52	53.83	0.239
2.53	53.93	0.239
2.54	54.03	0.239
2.55	54.13	0.239
2.56	54.23	0.239
2.57	54.33	0.239
2.58	54.43	0.239
2.59	54.53	0.239
2.60	54.63	0.239
2.61	54.73	0.239
2.62	54.83	0.239
2.63	54.93	0.239
2.64	55.03	0.239
2.65	55.13	0.239
2.66	55.23	0.239
2.67	55.33	0.239
2.68	55.43	0.240
2.69	55.53	0.240
2.70	55.63	0.240
2.71	55.73	0.240
2.72	55.83	0.240
2.73	55.93	0.240
2.74	56.03	0.240
2.75	56.13	0.240
2.76	56.23	0.240
2.77	56.33	0.240
2.78	56.43	0.240
2.79	56.53	0.240
2.80	56.63	0.240
2.81	56.73	0.240
2.82	56.83	0.240
2.83	56.93	0.240
2.84	57.03	0.240
2.85	57.13	0.240
2.86	57.23	0.241
2.87	57.33	0.241
2.88	57.43	0.241
2.89	57.53	0.241
2.90	57.63	0.241
2.91	57.73	0.241
2.92	57.83	0.241
2.93	57.93	0.241
2.94	58.03	0.241
2.95	58.13	0.241
2.96	58.23	0.241
2.97	58.33	0.241
2.98	58.43	0.241
2.99	58.53	0.241
3.00	58.63	0.241
3.01	58.73	0.241
3.02	58.83	0.241
3.03	58.93	0.241
3.04	59.03	0.241
3.05	59.13	0.241
3.06	59.23	0.242
3.07	59.33	0.242
3.08	59.43	0.242
3.09	59.53	0.242
3.10	59.63	0.242
3.11	59.73	0.242
3.12	59.83	0.242
3.13	59.93	0.242
3.14	60.03	0.242
3.15	60.13	0.242
3.16	60.23	0.242
3.17	60.33	0.242
3.18	60.43	0.242
3.19	60.53	0.242
3.20	60.63	0.242
3.21	60.73	0.242
3.22	60.83	0.242
3.23	60.93	0.242
3.24	61.03	0.242
3.25	61.13	0.242
3.26	61.23	0.242
3.27	61.33	0.243
3.28	61.43	0.243
3.29	61.53	0.243
3.30	61.63	0.243
3.31	61.73	0.243
3.32	61.83	0.243
3.33	61.93	0.243
3.34	62.03	0.243
3.35	62.13	0.243
3.36	62.23	0.243
3.37	62.33	0.243
3.38	62.43	0.243
3.39	62.53	0.243
3.40	62.64	0.243
3.41	62.73	0.243
3.42	62.83	0.243
3.43	62.93	0.243
3.44	63.03	0.244
3.45	63.13	0.244
3.46	63.23	0.244
3.47	63.34	0.244
3.48	63.44	0.244
3.49	63.53	0.244
3.50	63.63	0.244
3.51	63.74	0.244
3.52	63.84	0.244
3.53	63.93	0.244
3.54	64.04	0.244
3.55	64.14	0.244
3.56	64.24	0.244
3.57	64.34	0.244
3.58	64.44	0.244
3.59	64.54	0.244
3.60	64.64	0.244
3.61	64.74	0.245
3.62	64.84	0.245
3.63	64.94	0.245
3.64	65.04	0.245
3.65	65.14	0.245
3.66	65.24	0.245
3.67	65.34	0.245
3.68	65.44	0.245
3.69	65.54	0.245
3.70	65.64	0.245
3.71	65.74	0.245
3.72	65.84	0.245
3.73	65.94	0.245
3.74	66.04	0.245
3.75	66.14	0.245
3.76	66.24	0.245
3.77	66.34	0.246
3.78	66.44	0.246
3.79	66.54	0.246
3.80	66.64	0.246
3.81	66.74	0.246
3.82	66.84	0.246
3.83	66.94	0.246
3.84	67.04	0.246
3.85	67.14	0.246
3.86	67.24	0.246
3.87	67.34	0.246
3.88	67.44	0.246
3.89	67.54	0.246
3.90	67.64	0.246
3.91	67.74	0.246
3.92	67.84	0.246
3.93	67.94	0.246
3.94	68.04	0.247
3.95	68.14	0.247
3.96	68.24	0.247
3.97	68.34	0.247
3.98	68.44	0.247
3.99	68.54	0.247
4.00	68.64	0.247
4.01	68.74	0.247
4.02	68.84	0.247
4.03	68.94	0.247
4.04	69.04	0.247
4.05	69.14	0.247
4.06	69.24	0.247
4.07	69.34	0.247
4.08	69.44	0.247
4.09	69.54	0.247
4.10	69.64	0.247
4.11	69.74	0.247
4.12	69.84	0.248
4.13	69.94	0.248
4.14	70.04	0.248
4.15	70.14	0.248
4.16	70.24	0.248
4.17	70.34	0.248
4.18	70.44	0.248
4.19	70.54	0.248
4.20	70.64	0.248
4.21	70.74	0.248
4.22	70.84	0.248
4.23	70.94	0.248
4.24	71.04	0.249
4.25	71.14	0.249
4.26	71.24	0.249
4.27	71.34	0.249
4.28	71.44	0.249
4.29	71.54	0.249
4.30	71.64	0.249
4.31	71.74	0.249
4.32	71.84	0.249
4.33	71.94	0.249
4.34	72.04	0.249
4.35	72.14	0.249
4.36	72.24	0.249
4.37	72.34	0.249
4.38	72.44	0.249
4.39	72.54	0.249
4.40	72.64	0.250
4.41	72.74	0.250
4.42	72.84	0.250
4.43	72.94	0.250
4.44	73.04	0.250
4.45	73.14	0.250
4.46	73.24	0.250
4.47	73.34	0.250
4.48	73.44	0.250
4.49	73.54	0.250
4.50	73.64	0.250
4.51	73.74	0.250
4.52	73.84	0.250
4.53	73.94	0.250
4.54	74.04	0.250
4.55	74.14	0.250
4.56	74.24	0.250
4.57	74.34	0.250
4.58	74.44	0.251
4.59	74.54	0.251
4.60	74.64	0.251
4.61	74.74	0.251
4.62	74.84	0.251
4.63	74.94	0.251
4.64	75.04	0.251
4.65	75.14	0.251
4.66	75.24	0.251
4.67	75.35	0.251
4.68	75.44	0.251
4.69	75.54	0.251
4.70	75.65	0.251
4.71	75.74	0.251
4.72	75.84	0.252
4.73	75.94	0.252
4.74	76.05	0.252
4.75	76.14	0.252
4.76	76.24	0.252
4.77	76.34	0.252
4.78	76.44	0.252
4.79	76.54	0.252
4.80	76.64	0.252
4.81	76.75	0.252
4.82	76.85	0.252
4.83	76.94	0.252
4.84	77.05	0.252
4.85	77.15	0.252
4.86	77.24	0.252
4.87	77.34	0.252
4.88	77.45	0.253
4.89	77.55	0.253
4.90	77.65	0.253
4.91	77.75	0.253
4.92	77.85	0.253
4.93	77.95	0.253
4.94	78.05	0.253
4.95	78.15	0.253
4.96	78.25	0.253
4.97	78.35	0.253
4.98	78.45	0.253
4.99	78.55	0.253
5.00	78.65	0.253
5.01	78.75	0.254
5.02	78.85	0.254
5.03	78.95	0.254
5.04	79.05	0.254
5.05	79.15	0.254
5.06	79.25	0.254
5.07	79.35	0.254
5.08	79.45	0.254
5.09	79.55	0.254
5.10	79.65	0.254
5.11	79.75	0.254
5.12	79.85	0.254
5.13	79.95	0.254
5.14	80.05	0.254
5.15	80.15	0.254
5.16	80.25	0.254
5.17	80.35	0.255
5.18	80.45	0.255
5.19	80.55	0.255
5.20	80.65	0.255
5.21	80.75	0.255
5.22	80.85	0.255
5.23	80.95	0.255
5.24	81.05	0.255
5.25	81.15	0.255
5.26	81.25	0.255
5.27	81.35	0.255
5.28	81.45	0.255
5.29	81.55	0.255
5.30	81.65	0.255
5.31	81.75	0.255
5.32	81.85	0.255
5.33	81.95	0.256
5.34	82.05	0.256
5.35	82.15	0.256
5.36	82.25	0.256
5.37	82.35	0.256
5.38	82.45	0.256
5.39	82.55	0.256
5.40	82.65	0.256
5.41	82.75	0.256
5.42	82.85	0.256
5.43	82.95	0.256
5.44	83.05	0.256
5.45	83.15	0.256
5.46	83.25	0.256
5.47	83.35	0.256
5.48	83.45	0.256
5.49	83.55	0.256
5.50	83.65	0.256
5.51	83.75	0.256
5.52	83.85	0.257
5.53	83.95	0.257
5.54	84.05	0.257
5.55	84.15	0.257
5.56	84.25	0.257
5.57	84.35	0.257
5.58	84.45	0.257
5.59	84.55	0.257
5.60	84.65	0.257
5.61	84.75	0.257
5.62	84.85	0.257
5.63	84.95	0.257
5.64	85.05	0.257
5.65	85.15	0.257
5.66	85.25	0.257
5.67	85.35	0.257
5.68	85.45	0.257
5.69	85.55	0.257
5.70	85.65	0.257
5.71	85.75	0.257
5.72	85.85	0.257
5.73	85.95	0.258
5.74	86.05	0.258
5.75	86.15	0.258
5.76	86.25	0.258
5.77	86.35	0.258
5.78	86.45	0.258
5.79	86.55	0.258
5.80	86.65	0.258
5.81	86.75	0.258
5.82	86.85	0.258
5.83	86.95	0.258
5.84	87.05	0.258
5.85	87.15	0.258
5.86	87.25	0.258
5.87	87.35	0.258
5.88	87.45	0.258
5.89	87.55	0.258
5.90	87.65	0.258
5.91	87.75	0.258
5.92	87.85	0.258
5.93	87.95	0.259
5.94	88.05	0.259
5.95	88.15	0.259
5.96	88.25	0.259
5.97	88.35	0.259
5.98	88.45	0.259
5.99	88.55	0.259
6.00	88.65	0.259
6.01	88.75	0.259
6.02	88.85	0.259
6.03	88.95	0.259
6.04	89.05	0.259
6.05	89.15	0.259
6.06	89.25	0.260
6.07	89.35	0.260
6.08	89.45	0.260
6.09	89.55	0.260
6.10	89.65	0.260
6.11	89.75	0.260
6.12	89.85	0.260
6.13	89.95	0.260
6.14	90.05	0.260
6.15	90.15	0.260
6.16	90.26	0.260
6.17	90.35	0.260
6.18	90.45	0.260
6.19	90.55	0.261
6.20	90.65	0.261
6.21	90.75	0.261
6.22	90.86	0.261
6.23	90.95	0.261
6.24	91.06	0.261
6.25	91.16	0.261
6.26	91.25	0.261
6.27	91.36	0.261
6.28	91.45	0.261
6.29	91.56	0.262
6.30	91.66	0.262
6.31	91.76	0.262
6.32	91.86	0.262
6.33	91.96	0.262
6.34	92.06	0.262
6.35	92.16	0.262
6.36	92.26	0.262
6.37	92.36	0.262
6.38	92.46	0.263
6.39	92.56	0.263
6.40	92.66	0.263
6.41	92.76	0.263
6.42	92.86	0.263
6.43	92.96	0.263
6.44	93.06	0.263
6.45	93.16	0.263
6.46	93.26	0.263
6.47	93.36	0.264
6.48	93.46	0.264
6.49	93.56	0.264
6.50	93.66	0.264
6.51	93.76	0.264
6.52	93.86	0.264
6.53	93.96	0.264
6.54	94.06	0.264
6.55	94.16	0.264
6.56	94.26	0.264
6.57	94.36	0.264
6.58	94.46	0.265
6.59	94.56	0.265
6.60	94.66	0.265
6.61	94.76	0.265
6.62	94.86	0.265
6.63	94.96	0.265
6.64	95.06	0.265
6.65	95.16	0.265
6.66	95.26	0.265
6.67	95.36	0.266
6.68	95.46	0.266
6.69	95.56	0.266
6.70	95.66	0.266
6.71	95.76	0.266
6.72	95.86	0.266
6.73	95.96	0.266
6.74	96.06	0.266
6.75	96.16	0.266
6.76	96.26	0.266
6.77	96.36	0.267
6.78	96.46	0.267
6.79	96.56	0.267
6.80	96.66	0.267
6.81	96.76	0.267
6.82	96.86	0.267
6.83	96.96	0.267
6.84	97.06	0.267
6.85	97.16	0.267
6.86	97.26	0.267
6.87	97.36	0.267
6.88	97.46	0.268
6.89	97.56	0.268
6.90	97.66	0.268
6.91	97.76	0.268
6.92	97.86	0.268
6.93	97.96	0.268
6.94	98.06	0.268
6.95	98.16	0.268
6.96	98.26	0.268
6.97	98.36	0.268
6.98	98.46	0.269
6.99	98.56	0.269
7.00	98.66	0.269
7.01	98.76	0.269
7.02	98.86	0.269
7.03	98.96	0.269
7.04	99.06	0.269
7.05	99.16	0.269
7.06	99.26	0.269
7.07	99.36	0.269
7.08	99.46	0.269
7.09	99.56	0.270
7.10	99.66	0.270
7.11	99.76	0.270
7.12	99.86	0.270
7.13	99.96	0.270
7.14	100.06	0.270
7.15	100.16	0.270
7.16	100.26	0.270
7.17	100.36	0.270
7.18	100.46	0.270
7.19	100.56	0.270
7.20	100.66	0.271
7.21	100.76	0.271
7.22	100.86	0.271
7.23	100.96	0.271
7.24	101.06	0.271
7.25	101.16	0.271
7.26	101.26	0.271
7.27	101.36	0.271
7.28	101.46	0.271
7.29	101.56	0.271
7.30	101.66	0.271
7.31	101.76	0.272
7.32	101.86	0.272
7.33	101.96	0.272
7.34	102.06	0.272
7.35	102.16	0.272
7.36	102.26	0.272
7.37	102.36	0.272
7.38	102.46	0.272
7.39	102.56	0.272
7.40	102.66	0.272
7.41	102.76	0.273
7.42	102.86	0.273
7.43	102.96	0.273
7.44	103.06	0.273
7.45	103.16	0.273
7.46	103.26	0.273
7.47	103.36	0.273
7.48	103.46	0.273
7.49	103.56	0.273
7.50	103.66	0.273
7.51	103.76	0.274
7.52	103.86	0.274
7.53	103.96	0.274
7.54	104.06	0.274
7.55	104.16	0.274
7.56	104.26	0.274
7.57	104.36	0.274
7.58	104.46	0.274
7.59	104.56	0.274
7.60	104.66	0.274
7.61	104.76	0.275
7.62	104.86	0.275
7.63	104.96	0.275
7.64	105.06	0.275
7.65	105.16	0.275
7.66	105.26	0.275
7.67	105.36	0.275
7.68	105.46	0.275
7.69	105.56	0.275
7.70	105.66	0.275
7.71	105.76	0.276
7.72	105.86	0.276
7.73	105.96	0.276
7.74	106.06	0.276
7.75	106.16	0.276
7.76	106.26	0.276
7.77	106.36	0.276
7.78	106.46	0.276
7.79	106.56	0.276
7.80	106.66	0.277
7.81	106.76	0.277
7.82	106.86	0.277
7.83	106.97	0.277
7.84	107.06	0.277
7.85	107.16	0.277
7.86	107.26	0.277
7.87	107.36	0.277
7.88	107.46	0.277
7.89	107.56	0.278
7.90	107.66	0.278
7.91	107.76	0.278
7.92	107.86	0.278
7.93	107.97	0.278
7.94	108.06	0.278
7.95	108.16	0.278
7.96	108.27	0.278
7.97	108.37	0.279
7.98	108.47	0.279
7.99	108.56	0.279
8.00	108.67	0.279
8.01	108.76	0.279
8.02	108.86	0.279
8.03	108.97	0.280
8.04	109.07	0.280
8.05	109.16	0.280
8.06	109.26	0.280
8.07	109.37	0.280
8.08	109.47	0.280
8.09	109.56	0.281
8.10	109.66	0.281
8.11	109.77	0.281
8.12	109.87	0.281
8.13	109.96	0.281
8.14	110.07	0.281
8.15	110.17	0.281
8.16	110.27	0.282
8.17	110.37	0.282
8.18	110.46	0.282
8.19	110.56	0.282
8.20	110.67	0.282
8.21	110.77	0.282
8.22	110.87	0.282
8.23	110.96	0.283
8.24	111.07	0.283
8.25	111.16	0.283
8.26	111.27	0.283
8.27	111.37	0.283
8.28	111.46	0.283
8.29	111.57	0.284
8.30	111.67	0.284
8.31	111.77	0.284
8.32	111.87	0.284
8.33	111.97	0.284
8.34	112.07	0.284
8.35	112.17	0.285
8.36	112.27	0.285
8.37	112.37	0.285
8.38	112.47	0.285
8.39	112.57	0.285
8.40	112.67	0.286
8.41	112.77	0.286
8.42	112.87	0.286
8.43	112.97	0.286
8.44	113.07	0.286
8.45	113.17	0.287
8.46	113.27	0.287
8.47	113.37	0.287
8.48	113.47	0.287
8.49	113.57	0.287
8.50	113.67	0.287
8.51	113.77	0.288
8.52	113.87	0.288
8.53	113.97	0.288
8.54	114.07	0.289
8.55	114.17	0.289
8.56	114.27	0.289
8.57	114.37	0.289
8.58	114.47	0.290
8.59	114.57	0.290
8.60	114.67	0.290
8.61	114.77	0.290
8.62	114.87	0.290
8.63	114.97	0.291
8.64	115.07	0.291
8.65	115.17	0.291
8.66	115.27	0.291
8.67	115.37	0.291
8.68	115.47	0.292
8.69	115.57	0.292
8.70	115.67	0.292
8.71	115.77	0.292
8.72	115.87	0.293
8.73	115.97	0.293
8.74	116.07	0.293
8.75	116.17	0.293
8.76	116.27	0.294
8.77	116.37	0.294
8.78	116.47	0.294
8.79	116.57	0.294
8.80	116.67	0.295
8.81	116.77	0.295
8.82	116.87	0.295
8.83	116.97	0.296
8.84	117.07	0.296
8.85	117.17	0.296
8.86	117.27	0.297
8.87	117.37	0.297
8.88	117.47	0.297
8.89	117.57	0.297
8.90	117.67	0.298
8.91	117.77	0.298
8.92	117.87	0.299
8.93	117.97	0.299
8.94	118.07	0.300
8.95	118.17	0.300
8.96	118.27	0.301
8.97	118.37	0.301
8.98	118.47	0.302
8.99	118.57	0.303
9.00	118.67	0.304
9.01	118.77	0.304
9.02	118.87	0.305
9.03	118.97	0.307
9.04	119.07	0.308
9.05	119.17	0.310
9.06	119.27	0.314
9.07	119.37	0.317
9.08	119.47	0.322
9.09	119.57	0.324
9.10	119.67	0.330
9.11	119.77	0.333
9.12	119.86	0.336
9.13	119.96	0.345
9.14	120.06	0.349
9.15	120.16	0.358
9.16	120.26	0.364
9.17	120.36	0.370
9.18	120.46	0.387
9.19	120.56	0.397
9.20	120.66	0.412
9.21	120.76	0.428
9.22	120.85	0.452
9.23	120.95	0.477
9.24	121.05	0.512
9.25	121.15	0.551
9.26	121.24	0.607
9.27	121.34	0.674
9.28	121.43	0.767
9.29	121.52	0.878
9.30	121.61	1.013
9.31	121.69	1.172
9.32	121.78	1.353
9.33	121.86	1.580
9.34	121.93	1.836
9.35	122.00	2.177
9.36	122.07	2.630
9.37	122.12	3.099
9.38	122.17	3.554
9.39	122.21	3.994
9.40	122.25	4.397
9.41	122.29	4.776
9.42	122.33	5.127
9.43	122.37	5.427
9.44	122.41	5.711
9.45	122.45	5.966
9.46	122.49	6.184
9.47	122.54	6.375
9.48	122.59	6.552
9.49	122.65	6.692
9.50	122.71	6.828
9.51	122.77	6.967
9.52	122.84	7.035
9.53	122.91	7.117
9.54	122.98	7.190
9.55	123.06	7.216
9.56	123.13	7.224
9.57	123.22	7.200
9.58	123.31	7.203
9.59	123.39	7.230
9.60	123.48	7.243
9.61	123.57	7.264
9.62	123.67	7.171
9.63	123.77	7.076
9.64	123.87	7.024
9.65	123.97	7.010
9.66	124.07	7.096
9.67	124.16	7.142
9.68	124.27	6.756
9.69	124.39	6.347
9.70	124.52	5.602
9.71	124.68	4.412
9.72	124.86	3.288
9.73	125.06	2.562
9.74	125.26	2.136
9.75	125.45	1.895
9.76	125.63	1.716
9.77	125.80	1.563
9.78	125.96	1.432
9.79	126.11	1.315
9.80	126.26	1.213
9.81	126.41	1.121
9.82	126.55	1.038
9.83	126.68	0.969
9.84	126.81	0.899
9.85	126.94	0.843
9.86	127.07	0.793
9.87	127.19	0.746
9.88	127.31	0.706
9.89	127.42	0.669
9.90	127.54	0.636
9.91	127.65	0.609
9.92	127.77	0.582
9.93	127.88	0.560
9.94	127.99	0.540
9.95	128.09	0.522
9.96	128.20	0.507
9.97	128.31	0.492
9.98	128.41	0.480
9.99	128.52	0.469
10.00	128.62	0.458
10.01	128.73	0.451
10.02	128.83	0.440
10.03	128.94	0.435
10.04	129.04	0.430
10.05	129.14	0.421
10.06	129.24	0.419
10.07	129.35	0.414
10.08	129.45	0.410
10.09	129.55	0.408
10.10	129.65	0.407
10.11	129.75	0.404
10.12	129.85	0.400
10.13	129.95	0.399
10.14	130.06	0.398
10.15	130.16	0.397
10.16	130.26	0.395
10.17	130.36	0.394
10.18	130.46	0.393
10.19	130.56	0.392
10.20	130.66	0.392
10.21	130.76	0.391
10.22	130.86	0.391
10.23	130.96	0.390
10.24	131.06	0.390
10.25	131.16	0.389
10.26	131.26	0.389
10.27	131.36	0.389
10.28	131.46	0.388
10.29	131.56	0.388
10.30	131.66	0.388
10.31	131.76	0.387
10.32	131.86	0.387
10.33	131.96	0.387
10.34	132.06	0.387
10.35	132.16	0.387
10.36	132.26	0.387
10.37	132.36	0.386
10.38	132.46	0.386
10.39	132.56	0.386
10.40	132.66	0.386
10.41	132.76	0.386
10.42	132.86	0.386
10.43	132.96	0.386
10.44	133.06	0.385
10.45	133.16	0.385
10.46	133.26	0.385
10.47	133.36	0.385
10.48	133.46	0.385
10.49	133.56	0.385
10.50	133.66	0.385
10.51	133.76	0.385
10.52	133.86	0.385
10.53	133.96	0.385
10.54	134.07	0.385
10.55	134.16	0.385
10.56	134.26	0.384
10.57	134.36	0.384
10.58	134.46	0.384
10.59	134.56	0.384
10.60	134.66	0.384
10.61	134.76	0.384
10.62	134.87	0.384
10.63	134.96	0.384
10.64	135.06	0.384
10.65	135.16	0.384
10.66	135.27	0.384
10.67	135.36	0.384
10.68	135.46	0.384
10.69	135.56	0.384
10.70	135.66	0.384
10.71	135.77	0.385
10.72	135.87	0.385
10.73	135.97	0.385
10.74	136.07	0.385
10.75	136.17	0.385
10.76	136.26	0.385
10.77	136.37	0.385
10.78	136.46	0.385
10.79	136.57	0.385
10.80	136.67	0.385
10.81	136.77	0.385
10.82	136.87	0.385
10.83	136.97	0.385
10.84	137.07	0.385
10.85	137.17	0.385
10.86	137.27	0.385
10.87	137.37	0.385
10.88	137.46	0.385
10.89	137.56	0.385
10.90	137.66	0.385
10.91	137.76	0.385
10.92	137.87	0.386
10.93	137.97	0.386
10.94	138.07	0.386
10.95	138.17	0.386
10.96	138.27	0.386
10.97	138.37	0.386
10.98	138.47	0.386
10.99	138.57	0.386
11.00	138.67	0.386
11.01	138.77	0.386
11.02	138.87	0.386
11.03	138.97	0.386
11.04	139.07	0.387
11.05	139.17	0.387
11.06	139.27	0.387
11.07	139.37	0.387
11.08	139.47	0.387
11.09	139.57	0.387
11.10	139.67	0.387
11.11	139.77	0.387
11.12	139.87	0.387
11.13	139.97	0.387
11.14	140.07	0.387
11.15	140.17	0.387
11.16	140.27	0.387
11.17	140.37	0.388
11.18	140.47	0.388
11.19	140.57	0.388
11.20	140.67	0.388
11.21	140.77	0.388
11.22	140.87	0.388
11.23	140.97	0.388
11.24	141.07	0.388
11.25	141.17	0.388
11.26	141.27	0.388
11.27	141.37	0.388
11.28	141.47	0.389
11.29	141.57	0.389
11.30	141.67	0.389
11.31	141.77	0.389
11.32	141.87	0.389
11.33	141.97	0.389
11.34	142.07	0.389
11.35	142.17	0.389
11.36	142.27	0.389
11.37	142.37	0.389
11.38	142.47	0.390
11.39	142.57	0.390
11.40	142.67	0.390
11.41	142.77	0.390
11.42	142.87	0.390
11.43	142.97	0.390
11.44	143.07	0.390
11.45	143.17	0.390
11.46	143.27	0.391
11.47	143.37	0.391
11.48	143.47	0.391
11.49	143.57	0.391
11.50	143.67	0.391
11.51	143.77	0.391
11.52	143.87	0.391
11.53	143.97	0.391
11.54	144.07	0.391
11.55	144.17	0.391
11.56	144.27	0.392
11.57	144.37	0.392
11.58	144.47	0.392
11.59	144.57	0.392
11.60	144.67	0.392
11.61	144.77	0.392
11.62	144.87	0.392
11.63	144.97	0.392
11.64	145.07	0.392
11.65	145.17	0.393
11.66	145.27	0.393
11.67	145.37	0.393
11.68	145.47	0.393
11.69	145.57	0.393
11.70	145.67	0.393
11.71	145.77	0.393
11.72	145.87	0.393
11.73	145.97	0.393
11.74	146.07	0.393
11.75	146.17	0.394
11.76	146.27	0.394
11.77	146.37	0.394
11.78	146.47	0.394
11.79	146.57	0.394
11.80	146.67	0.394
11.81	146.77	0.394
11.82	146.87	0.394
11.83	146.97	0.394
11.84	147.07	0.394
11.85	147.17	0.395
11.86	147.27	0.395
11.87	147.37	0.395
11.88	147.47	0.395
11.89	147.57	0.395
11.90	147.67	0.395
11.91	147.77	0.395
11.92	147.87	0.395
11.93	147.97	0.395
11.94	148.07	0.396
11.95	148.17	0.396
11.96	148.27	0.396
11.97	148.37	0.396
11.98	148.47	0.396
11.99	148.57	0.396
12.00	148.67	0.396
12.01	148.77	0.396
12.02	148.87	0.396
12.03	148.97	0.396
12.04	149.07	0.397
12.05	149.17	0.397
12.06	149.27	0.397
12.07	149.37	0.397
12.08	149.47	0.397
12.09	149.57	0.397
12.10	149.67	0.397
12.11	149.77	0.397
12.12	149.87	0.397
12.13	149.97	0.397
12.14	150.07	0.398
12.15	150.17	0.398
12.16	150.27	0.398
12.17	150.37	0.398
12.18	150.47	0.398
12.19	150.57	0.398
12.20	150.67	0.398
12.21	150.77	0.398
12.22	150.87	0.398
12.23	150.97	0.399
12.24	151.07	0.399
12.25	151.17	0.399
12.26	151.27	0.399
12.27	151.37	0.399
12.28	151.47	0.399
12.29	151.57	0.399
12.30	151.67	0.399
12.31	151.77	0.399
12.32	151.87	0.399
12.33	151.97	0.400
12.34	152.07	0.400
12.35	152.17	0.400
12.36	152.27	0.400
12.37	152.37	0.400
12.38	152.47	0.400
12.39	152.57	0.400
12.40	152.67	0.400
12.41	152.77	0.400
12.42	152.87	0.401
12.43	152.97	0.401
12.44	153.07	0.401
12.45	153.17	0.401
12.46	153.27	0.401
12.47	153.37	0.401
12.48	153.47	0.401
12.49	153.57	0.401
12.50	153.67	0.401
12.51	153.77	0.402
12.52	153.87	0.402
12.53	153.97	0.402
12.54	154.07	0.402
12.55	154.17	0.402
12.56	154.27	0.402
12.57	154.37	0.402
12.58	154.47	0.402
12.59	154.57	0.402
12.60	154.67	0.403
12.61	154.77	0.403
12.62	154.87	0.403
12.63	154.97	0.403
12.64	155.07	0.403
12.65	155.17	0.403
12.66	155.27	0.403
12.67	155.37	0.403
12.68	155.47	0.404
12.69	155.57	0.404
12.70	155.67	0.405
12.71	155.77	0.407
12.72	155.87	0.408
12.73	155.97	0.408
12.74	156.07	0.408
12.75	156.17	0.408
12.76	156.27	0.408
12.77	156.37	0.408
12.78	156.47	0.408
12.79	156.57	0.408
12.80	156.67	0.408
12.81	156.77	0.408
12.82	156.87	0.408
12.83	156.97	0.408
12.84	157.07	0.408
12.85	157.17	0.408
12.86	157.27	0.408
12.87	157.37	0.408
12.88	157.47	0.408
12.89	157.57	0.408
12.90	157.67	0.408
12.91	157.77	0.408
12.92	157.87	0.408
12.93	157.97	0.408
12.94	158.07	0.408
12.95	158.17	0.408
12.96	158.27	0.408
12.97	158.37	0.408
12.98	158.47	0.408
12.99	158.57	0.409
13.00	158.66	0.409

[step]
Ramp 10.00 °C/min to 30.00 °C
Time	Temperature	Heat Flow (Normalized)
min	°C	W/g
14.00	160.09	-0.061
14.01	160.09	-0.062
14.02	160.09	-0.062
14.03	160.09	-0.062
14.04	160.08	-0.062
14.05	160.08	-0.062
14.06	160.07	-0.062
14.07	160.06	-0.064
14.08	160.04	-0.070
14.09	160.01	-0.085
14.10	159.98	-0.108
14.11	159.94	-0.130
14.12	159.89	-0.154
14.13	159.84	-0.182
14.14	159.78	-0.213
14.15	159.72	-0.241
14.16	159.65	-0.270
14.17	159.58	-0.298
14.18	159.51	-0.323
14.19	159.43	-0.347
14.20	159.35	-0.364
14.21	159.27	-0.381
14.22	159.19	-0.399
14.23	159.10	-0.411
14.24	159.01	-0.422
14.25	158.93	-0.435
14.26	158.84	-0.440
14.27	158.75	-0.452
14.28	158.66	-0.458
14.29	158.57	-0.466
14.30	158.47	-0.472
14.31	158.38	-0.478
14.32	158.29	-0.484
14.33	158.19	-0.485
14.34	158.10	-0.492
14.35	158.00	-0.492
14.36	157.91	-0.498
14.37	157.81	-0.501
14.38	157.72	-0.501
14.39	157.62	-0.504
14.40	157.53	-0.507
14.41	157.43	-0.509
14.42	157.33	-0.509
14.43	157.23	-0.510
14.44	157.14	-0.512
14.45	157.04	-0.513
14.46	156.94	-0.513
14.47	156.85	-0.514
14.48	156.75	-0.515
14.49	156.65	-0.515
14.50	156.55	-0.516
14.51	156.45	-0.517
14.52	156.36	-0.517
14.53	156.26	-0.518
14.54	156.16	-0.519
14.55	156.06	-0.519
14.56	155.96	-0.519
14.57	155.86	-0.520
14.58	155.77	-0.520
14.59	155.67	-0.520
14.60	155.57	-0.521
14.61	155.47	-0.521
14.62	155.37	-0.521
14.63	155.27	-0.521
14.64	155.17	-0.521
14.65	155.08	-0.521
14.66	154.98	-0.522
14.67	154.88	-0.522
14.68	154.78	-0.522
14.69	154.68	-0.522
14.70	154.58	-0.522
14.71	154.48	-0.523
14.72	154.38	-0.523
14.73	154.28	-0.523
14.74	154.18	-0.523
14.75	154.09	-0.523
14.76	153.99	-0.523
14.77	153.89	-0.524
14.78	153.79	-0.524
14.79	153.69	-0.524
14.80	153.59	-0.524
14.81	153.49	-0.524
14.82	153.39	-0.524
14.83	153.29	-0.524
14.84	153.19	-0.524
14.85	153.09	-0.524
14.86	153.00	-0.524
14.87	152.90	-0.524
14.88	152.80	-0.524
14.89	152.70	-0.524
14.90	152.60	-0.525
14.91	152.50	-0.525
14.92	152.40	-0.525
14.93	152.30	-0.525
14.94	152.20	-0.525
14.95	152.10	-0.525
14.96	152.00	-0.525
14.97	151.90	-0.525
14.98	151.80	-0.525
14.99	151.70	-0.525
15.00	151.60	-0.525
15.01	151.51	-0.525
15.02	151.41	-0.525
15.03	151.31	-0.525
15.04	151.21	-0.525
15.05	151.11	-0.525
15.06	151.01	-0.525
15.07	150.91	-0.525
15.08	150.81	-0.525
15.09	150.71	-0.524
15.10	150.61	-0.524
15.11	150.51	-0.524
15.12	150.41	-0.524
15.13	150.31	-0.524
15.14	150.21	-0.524
15.15	150.11	-0.524
15.16	150.01	-0.524
15.17	149.91	-0.524
15.18	149.81	-0.524
15.19	149.71	-0.524
15.20	149.62	-0.524
15.21	149.51	-0.524
15.22	149.42	-0.524
15.23	149.32	-0.524
15.24	149.22	-0.523
15.25	149.12	-0.523
15.26	149.02	-0.523
15.27	148.92	-0.523
15.28	148.82	-0.523
15.29	148.72	-0.523
15.30	148.62	-0.523
15.31	148.52	-0.523
15.32	148.42	-0.523
15.33	148.32	-0.523
15.34	148.22	-0.522
15.35	148.12	-0.522
15.36	148.02	-0.522
15.37	147.92	-0.522
15.38	147.82	-0.522
15.39	147.72	-0.522
15.40	147.62	-0.522
15.41	147.52	-0.522
15.42	147.42	-0.522
15.43	147.32	-0.521
15.44	147.22	-0.521
15.45	147.12	-0.521
15.46	147.02	-0.521
15.47	146.92	-0.521
15.48	146.82	-0.521
15.49	146.72	-0.521
15.50	146.62	-0.520
15.51	146.52	-0.520
15.52	146.42	-0.520
15.53	146.32	-0.520
15.54	146.22	-0.520
15.55	146.12	-0.520
15.56	146.03	-0.520
15.57	145.93	-0.520
15.58	145.82	-0.519
15.59	145.72	-0.519
15.60	145.63	-0.519
15.61	145.53	-0.519
15.62	145.43	-0.519
15.63	145.33	-0.519
15.64	145.23	-0.519
15.65	145.13	-0.519
15.66	145.03	-0.518
15.67	144.93	-0.518
15.68	144.83	-0.518
15.69	144.73	-0.518
15.70	144.63	-0.518
15.71	144.53	-0.518
15.72	144.43	-0.517
15.73	144.33	-0.517
15.74	144.23	-0.517
15.75	144.13	-0.517
15.76	144.03	-0.517
15.77	143.93	-0.517
15.78	143.83	-0.517
15.79	143.73	-0.516
15.80	143.63	-0.516
15.81	143.53	-0.516
15.82	143.43	-0.516
15.83	143.33	-0.516
15.84	143.23	-0.516
15.85	143.13	-0.516
15.86	143.03	-0.515
15.87	142.93	-0.515
15.88	142.83	-0.515
15.89	142.73	-0.515
15.90	142.63	-0.515
15.91	142.53	-0.515
15.92	142.43	-0.515
15.93	142.33	-0.514
15.94	142.23	-0.514
15.95	142.13	-0.514
15.96	142.03	-0.514
15.97	141.93	-0.514
15.98	141.83	-0.514
15.99	141.73	-0.514
16.00	141.63	-0.513
16.01	141.53	-0.513
16.02	141.43	-0.513
16.03	141.33	-0.513
16.04	141.23	-0.513
16.05	141.13	-0.513
16.06	141.03	-0.512
16.07	140.93	-0.512
16.08	140.83	-0.512
16.09	140.73	-0.512
16.10	140.63	-0.512
16.11	140.53	-0.512
16.12	140.43	-0.512
16.13	140.33	-0.512
16.14	140.23	-0.511
16.15	140.13	-0.511
16.16	140.04	-0.511
16.17	139.93	-0.511
16.18	139.83	-0.511
16.19	139.74	-0.511
16.20	139.63	-0.510
16.21	139.53	-0.510
16.22	139.43	-0.510
16.23	139.33	-0.510
16.24	139.24	-0.510
16.25	139.14	-0.510
16.26	139.04	-0.510
16.27	138.94	-0.509
16.28	138.84	-0.509
16.29	138.74	-0.509
16.30	138.64	-0.509
16.31	138.54	-0.509
16.32	138.44	-0.509
16.33	138.34	-0.509
16.34	138.24	-0.509
16.35	138.14	-0.509
16.36	138.04	-0.508
16.37	137.94	-0.508
16.38	137.84	-0.508
16.39	137.74	-0.508
16.40	137.64	-0.508
16.41	137.54	-0.508
16.42	137.44	-0.508
16.43	137.34	-0.508
16.44	137.24	-0.507
16.45	137.14	-0.507
16.46	137.04	-0.507
16.47	136.94	-0.507
16.48	136.84	-0.507
16.49	136.74	-0.507
16.50	136.64	-0.507
16.51	136.54	-0.506
16.52	136.44	-0.506
16.53	136.34	-0.506
16.54	136.24	-0.506
16.55	136.14	-0.506
16.56	136.04	-0.506
16.57	135.94	-0.506
16.58	135.84	-0.506
16.59	135.74	-0.505
16.60	135.64	-0.505
16.61	135.54	-0.505
16.62	135.44	-0.505
16.63	135.34	-0.505
16.64	135.24	-0.505
16.65	135.14	-0.505
16.66	135.04	-0.505
16.67	134.94	-0.504
16.68	134.84	-0.504
16.69	134.74	-0.504
16.70	134.64	-0.504
16.71	134.54	-0.504
16.72	134.44	-0.504
16.73	134.34	-0.504
16.74	134.24	-0.504
16.75	134.14	-0.503
16.76	134.04	-0.503
16.77	133.94	-0.503
16.78	133.84	-0.503
16.79	133.74	-0.502
16.80	133.64	-0.502
16.81	133.54	-0.502
16.82	133.44	-0.502
16.83	133.34	-0.502
16.84	133.24	-0.502
16.85	133.14	-0.502
16.86	133.04	-0.502
16.87	132.94	-0.501
16.88	132.84	-0.501
16.89	132.74	-0.501
16.90	132.64	-0.501
16.91	132.54	-0.501
16.92	132.44	-0.501
16.93	132.34	-0.501
16.94	132.24	-0.500
16.95	132.14	-0.500
16.96	132.04	-0.500
16.97	131.94	-0.500
16.98	131.84	-0.500
16.99	131.74	-0.500
17.00	131.64	-0.500
17.01	131.54	-0.499
17.02	131.44	-0.499
17.03	131.34	-0.499
17.04	131.24	-0.499
17.05	131.14	-0.499
17.06	131.04	-0.499
17.07	130.94	-0.499
17.08	130.84	-0.499
17.09	130.74	-0.499
17.10	130.64	-0.498
17.11	130.54	-0.498
17.12	130.44	-0.498
17.13	130.34	-0.498
17.14	130.24	-0.498
17.15	130.14	-0.498
17.16	130.05	-0.498
17.17	129.95	-0.497
17.18	129.84	-0.497
17.19	129.74	-0.497
17.20	129.64	-0.497
17.21	129.55	-0.497
17.22	129.44	-0.497
17.23	129.34	-0.497
17.24	129.24	-0.497
17.25	129.14	-0.496
17.26	129.05	-0.496
17.27	128.95	-0.496
17.28	128.84	-0.496
17.29	128.75	-0.496
17.30	128.65	-0.496
17.31	128.55	-0.496
17.32	128.45	-0.496
17.33	128.35	-0.495
17.34	128.25	-0.495
17.35	128.15	-0.495
17.36	128.05	-0.495
17.37	127.95	-0.495
17.38	127.85	-0.495
17.39	127.75	-0.495
17.40	127.65	-0.495
17.41	127.55	-0.494
17.42	127.45	-0.494
17.43	127.35	-0.494
17.44	127.25	-0.494
17.45	127.15	-0.494
17.46	127.05	-0.494
17.47	126.95	-0.494
17.48	126.85	-0.494
17.49	126.75	-0.493
17.50	126.65	-0.493
17.51	126.55	-0.493
17.52	126.45	-0.493
17.53	126.35	-0.493
17.54	126.25	-0.493
17.55	126.15	-0.493
17.56	126.05	-0.492
17.57	125.95	-0.492
17.58	125.85	-0.492
17.59	125.75	-0.492
17.60	125.65	-0.492
17.61	125.55	-0.492
17.62	125.45	-0.492
17.63	125.35	-0.492
17.64	125.25	-0.492
17.65	125.15	-0.491
17.66	125.05	-0.491
17.67	124.95	-0.491
17.68	124.85	-0.491
17.69	124.75	-0.491
17.70	124.65	-0.491
17.71	124.55	-0.491
17.72	124.45	-0.491
17.73	124.35	-0.490
17.74	124.25	-0.490
17.75	124.15	-0.490
17.76	124.05	-0.490
17.77	123.95	-0.490
17.78	123.85	-0.490
17.79	123.75	-0.490
17.80	123.65	-0.489
17.81	123.55	-0.489
17.82	123.45	-0.489
17.83	123.35	-0.489
17.84	123.25	-0.489
17.85	123.15	-0.489
17.86	123.05	-0.489
17.87	122.95	-0.489
17.88	122.85	-0.489
17.89	122.75	-0.488
17.90	122.65	-0.488
17.91	122.55	-0.488
17.92	122.45	-0.488
17.93	122.35	-0.488
17.94	122.25	-0.488
17.95	122.15	-0.488
17.96	122.05	-0.487
17.97	121.95	-0.487
17.98	121.85	-0.487
17.99	121.75	-0.487
18.00	121.65	-0.487
18.01	121.55	-0.487
18.02	121.45	-0.487
18.03	121.35	-0.487
18.04	121.25	-0.486
18.05	121.15	-0.486
18.06	121.05	-0.486
18.07	120.95	-0.486
18.08	120.85	-0.486
18.09	120.75	-0.486
18.10	120.65	-0.486
18.11	120.55	-0.486
18.12	120.45	-0.486
18.13	120.35	-0.485
18.14	120.25	-0.485
18.15	120.15	-0.485
18.16	120.05	-0.485
18.17	119.95	-0.485
18.18	119.85	-0.485
18.19	119.75	-0.485
18.20	119.65	-0.485
18.21	119.55	-0.484
18.22	119.45	-0.484
18.23	119.35	-0.484
18.24	119.25	-0.484
18.25	119.15	-0.484
18.26	119.05	-0.484
18.27	118.95	-0.484
18.28	118.85	-0.484
18.29	118.75	-0.484
18.30	118.65	-0.483
18.31	118.55	-0.483
18.32	118.46	-0.483
18.33	118.36	-0.483
18.34	118.25	-0.483
18.35	118.16	-0.483
18.36	118.06	-0.483
18.37	117.96	-0.483
18.38	117.85	-0.482
18.39	117.76	-0.482
18.40	117.66	-0.482
18.41	117.56	-0.482
18.42	117.46	-0.482
18.43	117.36	-0.482
18.44	117.26	-0.482
18.45	117.16	-0.482
18.46	117.06	-0.481
18.47	116.96	-0.481
18.48	116.86	-0.481
18.49	116.76	-0.481
18.50	116.66	-0.481
18.51	116.56	-0.481
18.52	116.46	-0.481
18.53	116.36	-0.480
18.54	116.26	-0.480
18.55	116.16	-0.480
18.56	116.06	-0.480
18.57	115.96	-0.480
18.58	115.86	-0.480
18.59	115.76	-0.480
18.60	115.66	-0.480
18.61	115.56	-0.479
18.62	115.46	-0.479
18.63	115.36	-0.479
18.64	115.26	-0.479
18.65	115.16	-0.479
18.66	115.06	-0.479
18.67	114.96	-0.479
18.68	114.86	-0.479
18.69	114.76	-0.479
18.70	114.66	-0.478
18.71	114.56	-0.478
18.72	114.46	-0.478
18.73	114.36	-0.478
18.74	114.26	-0.478
18.75	114.16	-0.478
18.76	114.06	-0.478
18.77	113.96	-0.478
18.78	113.86	-0.478
18.79	113.76	-0.477
18.80	113.66	-0.477
18.81	113.56	-0.477
18.82	113.46	-0.477
18.83	113.36	-0.477
18.84	113.26	-0.477
18.85	113.16	-0.477
18.86	113.06	-0.477
18.87	112.96	-0.476
18.88	112.86	-0.476
18.89	112.76	-0.476
18.90	112.66	-0.476
18.91	112.56	-0.476
18.92	112.46	-0.476
18.93	112.36	-0.476
18.94	112.26	-0.476
18.95	112.16	-0.476
18.96	112.06	-0.476
18.97	111.96	-0.475
18.98	111.86	-0.475
18.99	111.76	-0.475
19.00	111.66	-0.475
19.01	111.56	-0.475
19.02	111.46	-0.475
19.03	111.36	-0.475
19.04	111.26	-0.475
19.05	111.16	-0.475
19.06	111.06	-0.474
19.07	110.96	-0.474
19.08	110.86	-0.474
19.09	110.76	-0.474
19.10	110.66	-0.474
19.11	110.56	-0.474
19.12	110.46	-0.474
19.13	110.36	-0.474
19.14	110.26	-0.474
19.15	110.16	-0.473
19.16	110.06	-0.473
19.17	109.96	-0.473
19.18	109.86	-0.473
19.19	109.76	-0.473
19.20	109.66	-0.473
19.21	109.56	-0.473
19.22	109.46	-0.473
19.23	109.36	-0.472
19.24	109.26	-0.472
19.25	109.16	-0.472
19.26	109.06	-0.472
19.27	108.96	-0.472
19.28	108.86	-0.472
19.29	108.76	-0.472
19.30	108.66	-0.471
19.31	108.56	-0.471
19.32	108.46	-0.471
19.33	108.36	-0.471
19.34	108.26	-0.471
19.35	108.16	-0.471
19.36	108.06	-0.471
19.37	107.96	-0.471
19.38	107.86	-0.471
19.39	107.76	-0.471
19.40	107.66	-0.471
19.41	107.56	-0.471
19.42	107.46	-0.470
19.43	107.36	-0.470
19.44	107.26	-0.470
19.45	107.16	-0.470
19.46	107.06	-0.470
19.47	106.96	-0.470
19.48	106.86	-0.470
19.49	106.76	-0.470
19.50	106.66	-0.470
19.51	106.56	-0.469
19.52	106.46	-0.469
19.53	106.36	-0.469
19.54	106.26	-0.469
19.55	106.17	-0.469
19.56	106.06	-0.469
19.57	105.97	-0.469
19.58	105.87	-0.469
19.59	105.76	-0.468
19.60	105.67	-0.468
19.61	105.57	-0.468
19.62	105.47	-0.468
19.63	105.37	-0.468
19.64	105.27	-0.468
19.65	105.17	-0.468
19.66	105.07	-0.467
19.67	104.97	-0.467
19.68	104.87	-0.467
19.69	104.77	-0.467
19.70	104.67	-0.467
19.71	104.57	-0.467
19.72	104.47	-0.467
19.73	104.37	-0.467
19.74	104.27	-0.467
19.75	104.17	-0.467
19.76	104.07	-0.466
19.77	103.97	-0.466
19.78	103.87	-0.466
19.79	103.77	-0.466
19.80	103.67	-0.466
19.81	103.57	-0.466
19.82	103.47	-0.466
19.83	103.37	-0.466
19.84	103.27	-0.465
19.85	103.17	-0.465
19.86	103.07	-0.465
19.87	102.97	-0.465
19.88	102.87	-0.465
19.89	102.77	-0.465
19.90	102.67	-0.465
19.91	102.57	-0.465
19.92	102.47	-0.465
19.93	102.37	-0.464
19.94	102.27	-0.464
19.95	102.17	-0.464
19.96	102.07	-0.464
19.97	101.97	-0.464
19.98	101.87	-0.464
19.99	101.77	-0.464
20.00	101.67	-0.464
20.01	101.57	-0.464
20.02	101.47	-0.464
20.03	101.37	-0.464
20.04	101.27	-0.463
20.05	101.17	-0.463
20.06	101.07	-0.463
20.07	100.97	-0.463
20.08	100.87	-0.463
20.09	100.77	-0.463
20.10	100.67	-0.463
20.11	100.57	-0.462
20.12	100.47	-3.919
20.13	100.91	-60.836
20.14	103.74	-91.937
20.15	104.20	-28.008
20.16	103.79	-9.944
20.17	103.31	-5.777
20.18	102.85	-4.361
20.19	102.42	-3.530
20.20	102.02	-3.029
20.21	101.66	-2.730
20.22	101.33	-2.467
20.23	101.02	-2.233
20.24	100.73	-2.023
20.25	100.47	-1.846
20.26	100.22	-1.687
20.27	99.99	-1.551
20.28	99.78	-1.422
20.29	99.58	-1.314
20.30	99.39	-1.214
20.31	99.21	-1.124
20.32	99.03	-1.042
20.33	98.87	-0.972
20.34	98.71	-0.908
20.35	98.56	-0.847
20.36	98.42	-0.801
20.37	98.28	-0.751
20.38	98.15	-0.711
20.39	98.01	-0.678
20.40	97.88	-0.644
20.41	97.76	-0.616
20.42	97.64	-0.591
20.43	97.52	-0.568
20.44	97.40	-0.549
20.45	97.29	-0.529
20.46	97.17	-0.515
20.47	97.06	-0.499
20.48	96.95	-0.486
20.49	96.84	-0.472
20.50	96.73	-0.465
20.51	96.62	-0.457
20.52	96.52	-0.447
20.53	96.41	-0.441
20.54	96.30	-0.433
20.55	96.20	-0.431
20.56	96.10	-0.422
20.57	95.99	-0.417
20.58	95.89	-0.415
20.59	95.79	-0.414
20.60	95.68	-0.411
20.61	95.58	-0.406
20.62	95.48	-0.404
20.63	95.38	-0.399
20.64	95.28	-0.399
20.65	95.17	-0.399
20.66	95.07	-0.397
20.67	94.97	-0.396
20.68	94.87	-0.395
20.69	94.77	-0.394
20.70	94.67	-0.393
20.71	94.57	-0.393
20.72	94.47	-0.391
20.73	94.37	-0.390
20.74	94.27	-0.390
20.75	94.17	-0.389
20.76	94.07	-0.389
20.77	93.96	-0.388
20.78	93.86	-0.388
20.79	93.76	-0.388
20.80	93.66	-0.387
20.81	93.56	-0.387
20.82	93.46	-0.386
20.83	93.36	-0.386
20.84	93.26	-0.386
20.85	93.16	-0.386
20.86	93.06	-0.386
20.87	92.96	-0.385
20.88	92.86	-0.385
20.89	92.76	-0.385
20.90	92.66	-0.385
20.91	92.56	-0.384
20.92	92.46	-0.384
20.93	92.36	-0.384
20.94	92.26	-0.384
20.95	92.16	-0.384
20.96	92.06	-0.383
20.97	91.96	-0.383
20.98	91.87	-0.383
20.99	91.76	-0.383
21.00	91.66	-0.383
21.01	91.56	-0.382
21.02	91.47	-0.382
21.03	91.36	-0.382
21.04	91.27	-0.382
21.05	91.17	-0.382
21.06	91.06	-0.381
21.07	90.97	-0.381
21.08	90.86	-0.381
21.09	90.77	-0.381
21.10	90.67	-0.381
21.11	90.57	-0.380
21.12	90.47	-0.380
21.13	90.37	-0.380
21.14	90.27	-0.380
21.15	90.17	-0.380
21.16	90.07	-0.380
21.17	89.97	-0.379
21.18	89.87	-0.379
21.19	89.77	-0.379
21.20	89.67	-0.379
21.21	89.57	-0.379
21.22	89.47	-0.379
21.23	89.37	-0.378
21.24	89.27	-0.378
21.25	89.17	-0.378
21.26	89.07	-0.378
21.27	88.97	-0.378
21.28	88.87	-0.378
21.29	88.77	-0.378
21.30	88.67	-0.378
21.31	88.57	-0.377
21.32	88.47	-0.377
21.33	88.37	-0.377
21.34	88.27	-0.377
21.35	88.17	-0.377
21.36	88.07	-0.377
21.37	87.97	-0.376
21.38	87.87	-0.376
21.39	87.77	-0.376
21.40	87.67	-0.376
21.41	87.57	-0.376
21.42	87.47	-0.376
21.43	87.37	-0.376
21.44	87.27	-0.376
21.45	87.17	-0.375
21.46	87.07	-0.375
21.47	86.97	-0.375
21.48	86.87	-0.375
21.49	86.77	-0.375
21.50	86.67	-0.375
21.51	86.57	-0.375
21.52	86.47	-0.375
21.53	86.37	-0.375
21.54	86.27	-0.374
21.55	86.17	-0.374
21.56	86.07	-0.374
21.57	85.97	-0.374
21.58	85.87	-0.374
21.59	85.77	-0.374
21.60	85.67	-0.374
21.61	85.57	-0.374
21.62	85.47	-0.373
21.63	85.37	-0.373
21.64	85.27	-0.373
21.65	85.17	-0.373
21.66	85.07	-0.373
21.67	84.97	-0.373
21.68	84.87	-0.373
21.69	84.77	-0.373
21.70	84.67	-0.373
21.71	84.57	-0.373
21.72	84.47	-0.373
21.73	84.37	-0.373
21.74	84.27	-0.373
21.75	84.17	-0.372
21.76	84.07	-0.372
21.77	83.97	-0.372
21.78	83.87	-0.372
21.79	83.77	-0.372
21.80	83.67	-0.372
21.81	83.57	-0.372
21.82	83.47	-0.372
21.83	83.37	-0.372
21.84	83.27	-0.372
21.85	83.17	-0.372
21.86	83.07	-0.372
21.87	82.97	-0.372
21.88	82.87	-0.372
21.89	82.77	-0.372
21.90	82.67	-0.372
21.91	82.57	-0.371
21.92	82.47	-0.371
21.93	82.37	-0.371
21.94	82.27	-0.371
21.95	82.17	-0.371
21.96	82.07	-0.371
21.97	81.97	-0.371
21.98	81.87	-0.371
21.99	81.77	-0.371
22.00	81.67	-0.371
22.01	81.57	-0.371
22.02	81.47	-0.371
22.03	81.37	-0.371
22.04	81.27	-0.371
22.05	81.17	-0.371
22.06	81.07	-0.371
22.07	80.97	-0.371
22.08	80.87	-0.371
22.09	80.77	-0.371
22.10	80.67	-0.370
22.11	80.57	-0.370
22.12	80.47	-0.370
22.13	80.37	-0.370
22.14	80.28	-0.370
22.15	80.17	-0.370
22.16	80.08	-0.370
22.17	79.97	-0.370
22.18	79.87	-0.370
22.19	79.77	-0.370
22.20	79.67	-0.370
22.21	79.57	-0.370
22.22	79.47	-0.370
22.23	79.37	-0.370
22.24	79.28	-0.370
22.25	79.18	-0.370
22.26	79.07	-0.369
22.27	78.98	-0.370
22.28	78.88	-0.370
22.29	78.78	-0.369
22.30	78.68	-0.369
22.31	78.58	-0.369
22.32	78.48	-0.369
22.33	78.38	-0.369
22.34	78.28	-0.369
22.35	78.18	-0.369
22.36	78.08	-0.369
22.37	77.98	-0.369
22.38	77.88	-0.368
22.39	77.78	-0.368
22.40	77.68	-0.368
22.41	77.58	-0.368
22.42	77.48	-0.368
22.43	77.38	-0.368
22.44	77.28	-0.368
22.45	77.18	-0.368
22.46	77.08	-0.368
22.47	76.98	-0.368
22.48	76.88	-0.368
22.49	76.78	-0.368
22.50	76.68	-0.368
22.51	76.58	-0.368
22.52	76.48	-0.367
22.53	76.38	-0.367
22.54	76.28	-0.367
22.55	76.18	-0.367
22.56	76.08	-0.367
22.57	75.98	-0.367
22.58	75.88	-0.367
22.59	75.78	-0.367
22.60	75.68	-0.367
22.61	75.58	-0.367
22.62	75.48	-0.367
22.63	75.38	-0.367
22.64	75.28	-0.367
22.65	75.18	-0.366
22.66	75.08	-0.366
22.67	74.98	-0.366
22.68	74.88	-0.366
22.69	74.78	-0.366
22.70	74.68	-0.366
22.71	74.58	-0.366
22.72	74.48	-0.366
22.73	74.38	-0.366
22.74	74.28	-0.365
22.75	74.18	-0.365
22.76	74.08	-0.365
22.77	73.98	-0.365
22.78	73.88	-0.365
22.79	73.78	-0.365
22.80	73.68	-0.365
22.81	73.58	-0.365
22.82	73.48	-0.365
22.83	73.38	-0.364
22.84	73.28	-0.364
22.85	73.18	-0.364
22.86	73.08	-0.364
22.87	72.98	-0.364
22.88	72.88	-0.364
22.89	72.78	-0.364
22.90	72.68	-0.363
22.91	72.58	-0.363
22.92	72.48	-0.363
22.93	72.38	-0.363
22.94	72.28	-0.363
22.95	72.18	-0.363
22.96	72.08	-0.363
22.97	71.98	-0.363
22.98	71.88	-0.362
22.99	71.78	-0.362
23.00	71.68	-0.362
23.01	71.58	-0.362
23.02	71.48	-0.362
23.03	71.38	-0.362
23.04	71.28	-0.362
23.05	71.18	-0.362
23.06	71.08	-0.361
23.07	70.98	-0.361
23.08	70.88	-0.361
23.09	70.78	-0.361
23.10	70.68	-0.361
23.11	70.58	-0.361
23.12	70.48	-0.361
23.13	70.38	-0.361
23.14	70.28	-0.361
23.15	70.18	-0.360
23.16	70.08	-0.360
23.17	69.98	-0.360
23.18	69.88	-0.360
23.19	69.78	-0.360
23.20	69.68	-0.360
23.21	69.58	-0.360
23.22	69.48	-0.360
23.23	69.38	-0.360
23.24	69.28	-0.359
23.25	69.18	-0.359
23.26	69.08	-0.359
23.27	68.98	-0.359
23.28	68.88	-0.359
23.29	68.78	-0.359
23.30	68.68	-0.359
23.31	68.58	-0.359
23.32	68.48	-0.359
23.33	68.38	-0.358
23.34	68.28	-0.358
23.35	68.18	-0.358
23.36	68.08	-0.358
23.37	67.98	-0.358
23.38	67.88	-0.358
23.39	67.78	-0.358
23.40	67.68	-0.358
23.41	67.58	-0.358
23.42	67.49	-0.358
23.43	67.38	-0.357
23.44	67.28	-0.357
23.45	67.18	-0.357
23.46	67.08	-0.357
23.47	66.98	-0.357
23.48	66.89	-0.357
23.49	66.79	-0.357
23.50	66.69	-0.357
23.51	66.59	-0.357
23.52	66.48	-0.357
23.53	66.39	-0.356
23.54	66.29	-0.356
23.55	66.19	-0.356
23.56	66.09	-0.356
23.57	65.99	-0.356
23.58	65.89	-0.356
23.59	65.79	-0.356
23.60	65.69	-0.356
23.61	65.59	-0.355
23.62	65.49	-0.355
23.63	65.39	-0.355
23.64	65.29	-0.355
23.65	65.19	-0.355
23.66	65.09	-0.355
23.67	64.99	-0.355
23.68	64.89	-0.355
23.69	64.79	-0.355
23.70	64.69	-0.355
23.71	64.59	-0.355
23.72	64.49	-0.355
23.73	64.39	-0.354
23.74	64.29	-0.354
23.75	64.19	-0.354
23.76	64.09	-0.354
23.77	63.99	-0.354
23.78	63.89	-0.354
23.79	63.79	-0.354
23.80	63.69	-0.354
23.81	63.59	-0.354
23.82	63.49	-0.354
23.83	63.39	-0.354
23.84	63.29	-0.353
23.85	63.19	-0.353
23.86	63.09	-0.353
23.87	62.99	-0.353
23.88	62.89	-0.353
23.89	62.79	-0.353
23.90	62.69	-0.353
23.91	62.59	-0.353
23.92	62.49	-0.353
23.93	62.39	-0.352
23.94	62.29	-0.352
23.95	62.19	-0.352
23.96	62.09	-0.352
23.97	61.99	-0.352
23.98	61.89	-0.352
23.99	61.79	-0.352
24.00	61.69	-0.352
24.01	61.59	-0.352
24.02	61.49	-0.352
24.03	61.39	-0.351
24.04	61.29	-0.351
24.05	61.19	-0.351
24.06	61.09	-0.351
24.07	60.99	-0.351
24.08	60.89	-0.351
24.09	60.79	-0.351
24.10	60.69	-0.351
24.11	60.59	-0.351
24.12	60.49	-0.350
24.13	60.39	-0.350
24.14	60.29	-0.350
24.15	60.19	-0.350
24.16	60.09	-0.350
24.17	59.99	-0.350
24.18	59.89	-0.350
24.19	59.79	-0.350
24.20	59.69	-0.350
24.21	59.59	-0.350
24.22	59.49	-0.350
24.23	59.39	-0.349
24.24	59.29	-0.349
24.25	59.19	-0.349
24.26	59.09	-0.349
24.27	58.99	-0.349
24.28	58.89	-0.349
24.29	58.79	-0.349
24.30	58.69	-0.349
24.31	58.59	-0.349
24.32	58.49	-0.349
24.33	58.39	-0.348
24.34	58.29	-0.348
24.35	58.19	-0.348
24.36	58.09	-0.348
24.37	57.99	-0.348
24.38	57.89	-0.348
24.39	57.79	-0.348
24.40	57.69	-0.348
24.41	57.59	-0.348
24.42	57.49	-0.348
24.43	57.39	-0.348
24.44	57.29	-0.348
24.45	57.19	-0.347
24.46	57.09	-0.347
24.47	56.99	-0.347
24.48	56.89	-0.347
24.49	56.79	-0.347
24.50	56.69	-0.347
24.51	56.59	-0.347
24.52	56.49	-0.347
24.53	56.39	-0.347
24.54	56.29	-0.346
24.55	56.19	-0.346
24.56	56.10	-0.346
24.57	55.99	-0.346
24.58	55.89	-0.346
24.59	55.80	-0.346
24.60	55.69	-0.346
24.61	55.59	-0.346
24.62	55.49	-0.346
24.63	55.40	-0.346
24.64	55.29	-0.346
24.65	55.19	-0.346
24.66	55.09	-0.346
24.67	55.00	-0.345
24.68	54.90	-0.345
24.69	54.80	-0.345
24.70	54.69	-0.345
24.71	54.60	-0.345
24.72	54.49	-0.345
24.73	54.40	-0.345
24.74	54.30	-0.345
24.75	54.20	-0.345
24.76	54.10	-0.345
24.77	54.00	-0.345
24.78	53.90	-0.344
24.79	53.80	-0.344
24.80	53.70	-0.344
24.81	53.60	-0.344
24.82	53.50	-0.344
24.83	53.40	-0.344
24.84	53.30	-0.343
24.85	53.20	-0.343
24.86	53.10	-0.343
24.87	53.00	-0.343
24.88	52.90	-0.343
24.89	52.80	-0.343
24.90	52.70	-0.343
24.91	52.60	-0.343
24.92	52.50	-0.343
24.93	52.40	-0.343
24.94	52.30	-0.342
24.95	52.20	-0.342
24.96	52.10	-0.342
24.97	52.00	-0.342
24.98	51.90	-0.342
24.99	51.80	-0.342
25.00	51.70	-0.342
25.01	51.60	-0.342
25.02	51.50	-0.342
25.03	51.40	-0.341
25.04	51.30	-0.341
25.05	51.20	-0.341
25.06	51.10	-0.341
25.07	51.00	-0.341
25.08	50.90	-0.341
25.09	50.80	-0.341
25.10	50.70	-0.341
25.11	50.60	-0.341
25.12	50.50	-0.341
25.13	50.40	-0.341
25.14	50.30	-0.340
25.15	50.20	-0.340
25.16	50.10	-0.340
25.17	50.00	-0.340
25.18	49.90	-0.340
25.19	49.80	-0.340
25.20	49.70	-0.340
25.21	49.60	-0.340
25.22	49.50	-0.340
25.23	49.40	-0.340
25.24	49.30	-0.340
25.25	49.20	-0.340
25.26	49.10	-0.339
25.27	49.00	-0.339
25.28	48.90	-0.339
25.29	48.80	-0.339
25.30	48.70	-0.339
25.31	48.60	-0.339
25.32	48.50	-0.339
25.33	48.40	-0.339
25.34	48.30	-0.339
25.35	48.20	-0.338
25.36	48.10	-0.338
25.37	48.00	-0.338
25.38	47.90	-0.338
25.39	47.80	-0.338
25.40	47.70	-0.338
25.41	47.60	-0.338
25.42	47.50	-0.337
25.43	47.40	-0.337
25.44	47.30	-0.337
25.45	47.20	-0.337
25.46	47.10	-0.337
25.47	47.00	-0.337
25.48	46.90	-0.337
25.49	46.80	-0.337
25.50	46.70	-0.337
25.51	46.60	-0.336
25.52	46.50	-0.336
25.53	46.40	-0.336
25.54	46.30	-0.336
25.55	46.20	-0.336
25.56	46.10	-0.336
25.57	46.00	-0.336
25.58	45.90	-0.336
25.59	45.80	-0.336
25.60	45.70	-0.336
25.61	45.60	-0.335
25.62	45.50	-0.335
25.63	45.40	-0.335
25.64	45.30	-0.335
25.65	45.20	-0.335
25.66	45.10	-0.335
25.67	45.00	-0.335
25.68	44.90	-0.335
25.69	44.80	-0.335
25.70	44.70	-0.335
25.71	44.60	-0.335
25.72	44.50	-0.334
25.73	44.40	-0.334
25.74	44.30	-0.334
25.75	44.20	-0.334
25.76	44.10	-0.334
25.77	44.00	-0.334
25.78	43.90	-0.334
25.79	43.80	-0.334
25.80	43.70	-0.334
25.81	43.60	-0.334
25.82	43.50	-0.334
25.83	43.40	-0.333
25.84	43.30	-0.333
25.85	43.20	-0.333
25.86	43.10	-0.333
25.87	43.01	-0.333
25.88	42.91	-0.333
25.89	42.80	-0.333
25.90	42.70	-0.333
25.91	42.60	-0.333
25.92	42.51	-0.333
25.93	42.41	-0.333
25.94	42.31	-0.333
25.95	42.20	-0.333
25.96	42.11	-0.333
25.97	42.01	-0.333
25.98	41.91	-0.332
25.99	41.81	-0.332
26.00	41.71	-0.332
26.01	41.61	-0.332
26.02	41.51	-0.332
26.03	41.41	-0.332
26.04	41.31	-0.332
26.05	41.21	-0.332
26.06	41.11	-0.332
26.07	41.01	-0.332
26.08	40.91	-0.332
26.09	40.81	-0.331
26.10	40.71	-0.331
26.11	40.61	-0.331
26.12	40.51	-0.331
26.13	40.41	-0.331
26.14	40.31	-0.331
26.15	40.21	-0.331
26.16	40.11	-0.330
26.17	40.01	-0.330
26.18	39.91	-0.330
26.19	39.81	-0.330
26.20	39.71	-0.330
26.21	39.61	-0.330
26.22	39.51	-0.330
26.23	39.41	-0.329
26.24	39.31	-0.329
26.25	39.21	-0.329
26.26	39.11	-0.329
26.27	39.01	-0.329
26.28	38.91	-0.329
26.29	38.81	-0.328
26.30	38.71	-0.328
26.31	38.61	-0.328
26.32	38.51	-0.328
26.33	38.41	-0.328
26.34	38.31	-0.328
26.35	38.21	-0.328
26.36	38.11	-0.328
26.37	38.01	-0.328
26.38	37.91	-0.328
26.39	37.81	-0.328
26.40	37.71	-0.328
26.41	37.61	-0.328
26.42	37.51	-0.327
26.43	37.41	-0.327
26.44	37.31	-0.327
26.45	37.21	-0.327
26.46	37.11	-0.327
26.47	37.01	-0.327
26.48	36.91	-0.327
26.49	36.81	-0.327
26.50	36.71	-0.327
26.51	36.61	-0.327
26.52	36.51	-0.327
26.53	36.41	-0.326
26.54	36.31	-0.326
26.55	36.21	-0.326
26.56	36.11	-0.326
26.57	36.01	-0.326
26.58	35.91	-0.326
26.59	35.81	-0.326
26.60	35.71	-0.326
26.61	35.61	-0.326
26.62	35.51	-0.326
26.63	35.41	-0.326
26.64	35.31	-0.326
26.65	35.21	-0.325
26.66	35.11	-0.325
26.67	35.01	-0.325
26.68	34.91	-0.325
26.69	34.81	-0.325
26.70	34.71	-0.325
26.71	34.61	-0.325
26.72	34.51	-0.325
26.73	34.41	-0.325
26.74	34.31	-0.325
26.75	34.21	-0.325
26.76	34.11	-0.325
26.77	34.01	-0.325
26.78	33.91	-0.325
26.79	33.81	-0.325
26.80	33.71	-0.325
26.81	33.61	-0.325
26.82	33.51	-0.325
26.83	33.41	-0.325
26.84	33.31	-0.325
26.85	33.21	-0.325
26.86	33.11	-0.325
26.87	33.01	-0.325
26.88	32.91	-0.324
26.89	32.81	-0.324
26.90	32.71	-0.324
26.91	32.61	-0.324
26.92	32.51	-0.325
26.93	32.41	-0.325
26.94	32.31	-0.325
26.95	32.21
26.96	32.11
26.97	32.01
26.98	31.91
26.99	31.81
27.00