File: Data/2024_09_17_Indium_DSC.txt
Filename	2024_09_17_Indium_DSC
Instrument name	DSC2A-00468 (192.168.1.100)
Operator	CHM343
rundate	9/18/2024
Sample name	2024_09_17_Indium_DSC
proceduresegments	Equilibrate 30.00 °C; Ramp 10.00 °C/min to 210.00 °C; Isothermal 1.0 min; Ramp 10.00 °C/min to 30.00 °C; Isothermal 1.0 min; Ramp 10.00 °C/min to 210.00 °C
[File Parameters]
Run date	9/18/2024 12:44:11 AM
Trios version	5.1.1.46572
Original File Name	C:\ProgramData\TA Instruments\TRIOS\Data\2024_09_17_Indium_DSC.tri
Current File Name	D:\DSC2500\CHM343\2024_09_17_Indium_DSC.tri
[Procedure]
Procedure Name	CHM343_Fall2024_Indium
Sample Name	2024_09_17_Indium_DSC
Sample Mass	2.26 mg
Reference Sample Mass	0 mg
Pan Mass	54.24 mg
Pan Number	25
Reference Pan Mass	54 mg
Reference Pan Number	19
Pan Type	Aluminum
Comments	Indium - Al Hermetic Sealed Pan, with ref Al pan.  ASU Online CHM343, Remote DSC experimental lab. Fall 2024.  Group Zoom Data Collection, Sept 17, 2024 from 9-11 pm.  TA Instruments DSC2500.
Project Name	Lab 4 - Fall 2024
Operator	CHM343
Test	Custom
Unload Max Temperature	30
Unload Min Temperature	30
Load Max Temperature	30
Load Min Temperature	30
Stop on Gas Flow Error	Yes
[Signal List]
Signal #1	Time (min)
Signal #2	Temperature (°C)
Signal #3	Heat Flow (mW)
Signal #4	Delta T (µV)
Signal #5	Delta Tzero (µV)
Signal #6	Tzero Temperature (°C)
Signal #7	Cell Purge (mL/min)
Signal #8	Heater Temp (°C)
Signal #9	Power Delivered (W)
Signal #10	Reference Junction Temperature (°C)
Signal #11	Flange Temperature (°C)
Signal #12	Heat Flow Phase (rad)
Signal #13	Total Heat Capacity (J/°C)
Signal #14	Heat Capacity (J/°C)
[Configuration]
Company Name	ASU
Instrument Name	DSC2A-00468
Instrument Type	DSC2500
Serial Number	DSC2A-00468
IP	192.168.1.100
Location of Instrument	MRRC
DisplayType	Unknown
Sample Interval 	0.1 s/pt
Selected Heat Flow	T4P
Exotherm Direction	Down
Cell Serial	DRC2-00792
Lid Type	Standard
Cooler	RCS 90
Leave Cooler on at End of Sequence	On
Gas 2	Nitrogen
Gas Selected	Channel 1
Flow Rate	50 mL/min
Secondary Purge	On
Licensed Heat Flow	Heat Flow T4P
Modulation Licensed	Yes
[Versions]
Common IDD Version	1
Cortex Version	VER 2.10.2.31
Driver	5.0.0.6
GDM Version	1.0.3.3
TouchscreenVersion	1.0.0.16145
FEP Version	1.2.1.21
FEP Bootloader	2.0.0.5
AutoSampler Version	2.1.1.26
Auto Sampler Bootloader	2.0.0.5
FCM Version	1.1.0.3
FCM Bootloader	2.0.0.5
[Experiment Logs]
Experiment Log Entry # 1	Equilibrate Segment 30 (C) Started
Experiment Log Entry # 3	Air Cool is off.
Experiment Log Entry # 5	Ramp Segment 10 C/min to 210 Started
Experiment Log Entry # 7	Isothermal Segment 1 min started
Experiment Log Entry # 9	Ramp Segment 10 C/min to 30 Started
Experiment Log Entry # 11	Isothermal Segment 1 min started
Experiment Log Entry # 13	Ramp Segment 10 C/min to 210 Started
[Method Log]
Method Log Entry # 1	Equilibrate 30 °C
Method Log Entry # 2	(Ramp 99349) Ramp 10 °C/minute to 210 °C
Method Log Entry # 3	Isothermal 1 minutes
Method Log Entry # 4	(Ramp 99351) Ramp 10 °C/minute to 30 °C
Method Log Entry # 5	Isothermal 1 minutes
Method Log Entry # 6	(Ramp 99353) Ramp 10 °C/minute to 210 °C
Cell Serial	DRC2-00792
[T1 Calibration]
Slope	-0.008529666
Offset	9.636258
Initial Temperature	98.23
GUID	f8bfdadc-4977-4fdf-ba6d-0ba9134940c3
[TZero Calibration]
Date Applied	11/29/2022 4:06:13 PM
Description	From -89.059 °C to 396.009 °C at 20.000°C/min
Gas Type	Nitrogen
Pan Type	None
Source Files 1	C:\Users\yargerlab\Desktop\DSC Data\General\TZero_calibration_11_29_22_2nd(2).tri
Source Files 2	C:\Users\yargerlab\Desktop\DSC Data\General\TZero_calibration_11_29_22_2nd(3).tri
Delta T Offset	13.05235
Delta T Slope	-0.007271007
Delta T0 Offset	-13.69128
Delta T0 Slope	0.06063341
[Temperature Calibration]
Date Applied	11/29/2022 7:12:28 PM
Description	From 106.590 °C to 186.590 °C at 10.000°C/min
Gas Type	Nitrogen
Pan Type	Tzero Aluminum Hermetic
Source Files 1	C:\Users\yargerlab\Desktop\DSC Data\General\Indium(6).tri
Measured 1	157.391
Known 1	156.598
[Cell Constant Calibration]
Date Applied	11/29/2022 7:12:29 PM
Description	From 106.590 °C to 186.590 °C at 10.000°C/min
Gas Type	Nitrogen
Pan Type	Tzero Aluminum Hermetic
Source Files 1	C:\Users\yargerlab\Desktop\DSC Data\General\Indium(6).tri
T4P KCell	1.006051
Onset Slope	63.26126 mW/°C
[Direct Cp Calibration]
Date Applied	11/30/2022 11:04:51 AM
Description	From -79.983 °C to 298.409 °C at 10.000°C/min
Gas Type	Nitrogen
Pan Type	Tzero Aluminum Hermetic
Source Files 1	C:\Users\yargerlab\Desktop\DSC Data\General\Sapphire_Heat_Capacity_11_30_22.tri
[Rev Cp Calibration]
Date Applied	11/30/2022 1:58:51 PM
Description	From -79.996 °C to 292.812 °C at 3.000°C/min
Gas Type	Nitrogen
Pan Type	Tzero Aluminum Hermetic
Source Files 1	C:\Users\yargerlab\Desktop\DSC Data\General\Sapphire_MDSC_Calibration_11_30_22.tri
[step]
Ramp 10.00 °C/min to 210.00 °C
Time	Temperature	Heat Flow (Normalized)
min	°C	W/g
0.00	30.06	-0.056
0.01	30.06	-0.055
0.03	30.06	-0.054
0.04	30.07	-0.054
0.05	30.08	-0.055
0.07	30.10	-0.085
0.08	30.13	-0.129
0.09	30.17	-0.170
0.11	30.23	-0.206
0.12	30.30	-0.230
0.13	30.38	-0.235
0.15	30.46	-0.229
0.16	30.56	-0.211
0.17	30.66	-0.185
0.19	30.76	-0.149
0.20	30.86	-0.119
0.21	30.97	-0.097
0.23	31.09	-0.077
0.24	31.20	-0.061
0.25	31.32	-0.047
0.27	31.43	-0.035
0.28	31.55	-0.024
0.29	31.68	-0.015
0.31	31.80	-0.006
0.32	31.92	0.004
0.33	32.05	0.010
0.35	32.17	0.022
0.36	32.30	0.026
0.37	32.43	0.033
0.39	32.55	0.037
0.40	32.68	0.041
0.41	32.81	0.045
0.43	32.94	0.049
0.44	33.07	0.050
0.45	33.20	0.053
0.47	33.33	0.055
0.48	33.46	0.056
0.49	33.59	0.058
0.51	33.72	0.060
0.52	33.85	0.061
0.53	33.98	0.061
0.55	34.11	0.062
0.56	34.25	0.063
0.57	34.38	0.064
0.59	34.51	0.065
0.60	34.64	0.065
0.61	34.77	0.066
0.63	34.90	0.066
0.64	35.03	0.067
0.65	35.17	0.067
0.67	35.30	0.068
0.68	35.43	0.068
0.69	35.56	0.069
0.71	35.70	0.069
0.72	35.83	0.070
0.73	35.96	0.070
0.75	36.09	0.071
0.76	36.22	0.071
0.77	36.36	0.071
0.79	36.49	0.072
0.80	36.62	0.072
0.81	36.75	0.072
0.83	36.89	0.073
0.84	37.02	0.073
0.85	37.15	0.073
0.87	37.28	0.074
0.88	37.42	0.074
0.89	37.55	0.074
0.91	37.68	0.074
0.92	37.81	0.074
0.93	37.95	0.074
0.95	38.08	0.075
0.96	38.21	0.075
0.97	38.35	0.075
0.99	38.48	0.075
1.00	38.61	0.075
1.01	38.74	0.075
1.03	38.88	0.075
1.04	39.01	0.075
1.05	39.14	0.076
1.07	39.27	0.076
1.08	39.41	0.076
1.09	39.54	0.076
1.11	39.67	0.076
1.12	39.81	0.076
1.13	39.94	0.076
1.15	40.07	0.076
1.16	40.21	0.076
1.17	40.34	0.076
1.19	40.47	0.076
1.20	40.61	0.076
1.21	40.74	0.076
1.23	40.87	0.076
1.24	41.00	0.076
1.25	41.14	0.075
1.27	41.27	0.075
1.28	41.40	0.075
1.29	41.54	0.075
1.31	41.67	0.075
1.32	41.80	0.075
1.33	41.94	0.075
1.35	42.07	0.075
1.36	42.20	0.075
1.37	42.33	0.075
1.39	42.47	0.075
1.40	42.60	0.075
1.41	42.73	0.075
1.43	42.87	0.075
1.44	43.00	0.075
1.45	43.13	0.075
1.47	43.27	0.075
1.48	43.40	0.075
1.49	43.53	0.074
1.51	43.67	0.074
1.52	43.80	0.074
1.53	43.93	0.074
1.55	44.07	0.074
1.56	44.20	0.074
1.57	44.33	0.074
1.59	44.47	0.074
1.60	44.60	0.074
1.61	44.73	0.074
1.63	44.87	0.074
1.64	45.00	0.074
1.65	45.13	0.073
1.67	45.27	0.073
1.68	45.40	0.073
1.69	45.53	0.073
1.71	45.67	0.073
1.72	45.80	0.073
1.73	45.93	0.073
1.75	46.07	0.073
1.76	46.20	0.073
1.77	46.33	0.072
1.79	46.47	0.072
1.80	46.60	0.072
1.81	46.73	0.072
1.83	46.87	0.072
1.84	47.00	0.072
1.85	47.13	0.072
1.87	47.27	0.072
1.88	47.40	0.072
1.89	47.53	0.071
1.91	47.67	0.071
1.92	47.80	0.071
1.93	47.93	0.071
1.95	48.07	0.071
1.96	48.20	0.071
1.97	48.33	0.071
1.99	48.47	0.071
2.00	48.60	0.071
2.01	48.73	0.071
2.03	48.87	0.070
2.04	49.00	0.070
2.05	49.13	0.070
2.07	49.27	0.070
2.08	49.40	0.070
2.09	49.53	0.070
2.11	49.67	0.070
2.12	49.80	0.070
2.13	49.93	0.070
2.15	50.07	0.070
2.16	50.20	0.070
2.17	50.34	0.069
2.19	50.47	0.069
2.20	50.60	0.069
2.21	50.73	0.069
2.23	50.87	0.069
2.24	51.00	0.069
2.25	51.14	0.069
2.27	51.27	0.069
2.28	51.40	0.069
2.29	51.53	0.069
2.31	51.67	0.068
2.32	51.80	0.068
2.33	51.94	0.068
2.35	52.07	0.068
2.36	52.20	0.068
2.37	52.34	0.068
2.39	52.47	0.068
2.40	52.60	0.068
2.41	52.74	0.068
2.43	52.87	0.068
2.44	53.00	0.068
2.45	53.14	0.068
2.47	53.27	0.068
2.48	53.40	0.067
2.49	53.54	0.067
2.51	53.67	0.067
2.52	53.80	0.067
2.53	53.94	0.067
2.55	54.07	0.067
2.56	54.20	0.066
2.57	54.34	0.066
2.59	54.47	0.066
2.60	54.60	0.066
2.61	54.74	0.066
2.63	54.87	0.066
2.64	55.00	0.066
2.65	55.14	0.066
2.67	55.27	0.066
2.68	55.40	0.066
2.69	55.54	0.066
2.71	55.67	0.066
2.72	55.80	0.066
2.73	55.94	0.065
2.75	56.07	0.065
2.76	56.20	0.065
2.77	56.34	0.065
2.79	56.47	0.065
2.80	56.61	0.065
2.81	56.74	0.065
2.83	56.87	0.065
2.84	57.01	0.065
2.85	57.14	0.065
2.87	57.27	0.065
2.88	57.41	0.065
2.89	57.54	0.065
2.91	57.67	0.064
2.92	57.81	0.064
2.93	57.94	0.064
2.95	58.07	0.064
2.96	58.21	0.064
2.97	58.34	0.064
2.99	58.47	0.064
3.00	58.61	0.064
3.01	58.74	0.064
3.03	58.87	0.064
3.04	59.01	0.064
3.05	59.14	0.064
3.07	59.27	0.064
3.08	59.41	0.064
3.09	59.54	0.063
3.11	59.67	0.063
3.12	59.81	0.063
3.13	59.94	0.063
3.15	60.08	0.063
3.16	60.21	0.063
3.17	60.34	0.063
3.19	60.48	0.063
3.20	60.61	0.063
3.21	60.74	0.063
3.23	60.88	0.063
3.24	61.01	0.063
3.25	61.14	0.063
3.27	61.28	0.063
3.28	61.41	0.063
3.29	61.54	0.063
3.31	61.68	0.063
3.32	61.81	0.062
3.33	61.94	0.062
3.35	62.08	0.062
3.36	62.21	0.062
3.37	62.34	0.062
3.39	62.48	0.062
3.40	62.61	0.062
3.41	62.74	0.062
3.43	62.88	0.062
3.44	63.01	0.062
3.45	63.14	0.062
3.47	63.28	0.062
3.48	63.41	0.062
3.49	63.54	0.062
3.51	63.68	0.062
3.52	63.81	0.061
3.53	63.95	0.061
3.55	64.08	0.061
3.56	64.21	0.061
3.57	64.35	0.061
3.59	64.48	0.061
3.60	64.61	0.061
3.61	64.75	0.061
3.63	64.88	0.061
3.64	65.01	0.061
3.65	65.15	0.061
3.67	65.28	0.061
3.68	65.41	0.061
3.69	65.55	0.061
3.71	65.68	0.061
3.72	65.81	0.061
3.73	65.95	0.061
3.75	66.08	0.061
3.76	66.21	0.061
3.77	66.35	0.061
3.79	66.48	0.061
3.80	66.61	0.061
3.81	66.75	0.060
3.83	66.88	0.060
3.84	67.01	0.060
3.85	67.15	0.060
3.87	67.28	0.060
3.88	67.41	0.060
3.89	67.55	0.060
3.91	67.68	0.060
3.92	67.82	0.060
3.93	67.95	0.060
3.95	68.08	0.060
3.96	68.22	0.060
3.97	68.35	0.060
3.99	68.48	0.060
4.00	68.62	0.060
4.01	68.75	0.059
4.03	68.88	0.060
4.04	69.02	0.059
4.05	69.15	0.059
4.07	69.28	0.059
4.08	69.42	0.059
4.09	69.55	0.059
4.11	69.68	0.059
4.12	69.82	0.059
4.13	69.95	0.059
4.15	70.08	0.059
4.16	70.22	0.059
4.17	70.35	0.059
4.19	70.48	0.059
4.20	70.62	0.059
4.21	70.75	0.059
4.23	70.88	0.059
4.24	71.02	0.059
4.25	71.15	0.058
4.27	71.28	0.058
4.28	71.42	0.058
4.29	71.55	0.058
4.31	71.68	0.058
4.32	71.82	0.058
4.33	71.95	0.058
4.35	72.09	0.058
4.36	72.22	0.058
4.37	72.35	0.058
4.39	72.49	0.059
4.40	72.62	0.058
4.41	72.75	0.058
4.43	72.89	0.058
4.44	73.02	0.058
4.45	73.15	0.058
4.47	73.29	0.058
4.48	73.42	0.058
4.49	73.55	0.058
4.51	73.69	0.058
4.52	73.82	0.058
4.53	73.95	0.058
4.55	74.09	0.058
4.56	74.22	0.058
4.57	74.35	0.058
4.59	74.49	0.057
4.60	74.62	0.057
4.61	74.75	0.057
4.63	74.89	0.057
4.64	75.02	0.057
4.65	75.15	0.057
4.67	75.29	0.057
4.68	75.42	0.057
4.69	75.56	0.057
4.71	75.69	0.057
4.72	75.82	0.057
4.73	75.96	0.057
4.75	76.09	0.057
4.76	76.22	0.057
4.77	76.36	0.057
4.79	76.49	0.057
4.80	76.62	0.057
4.81	76.76	0.057
4.83	76.89	0.057
4.84	77.02	0.057
4.85	77.16	0.057
4.87	77.29	0.056
4.88	77.42	0.056
4.89	77.56	0.056
4.91	77.69	0.056
4.92	77.82	0.056
4.93	77.96	0.056
4.95	78.09	0.056
4.96	78.22	0.056
4.97	78.36	0.056
4.99	78.49	0.056
5.00	78.63	0.056
5.01	78.76	0.056
5.03	78.89	0.056
5.04	79.02	0.056
5.05	79.16	0.056
5.07	79.29	0.056
5.08	79.42	0.056
5.09	79.56	0.056
5.11	79.69	0.056
5.12	79.82	0.056
5.13	79.96	0.056
5.15	80.09	0.056
5.16	80.23	0.056
5.17	80.36	0.056
5.19	80.49	0.055
5.20	80.63	0.055
5.21	80.76	0.055
5.23	80.89	0.055
5.24	81.03	0.055
5.25	81.16	0.055
5.27	81.29	0.055
5.28	81.43	0.055
5.29	81.56	0.055
5.31	81.69	0.055
5.32	81.83	0.055
5.33	81.96	0.055
5.35	82.09	0.055
5.36	82.23	0.055
5.37	82.36	0.055
5.39	82.49	0.055
5.40	82.63	0.054
5.41	82.76	0.054
5.43	82.89	0.054
5.44	83.03	0.054
5.45	83.16	0.054
5.47	83.29	0.054
5.48	83.43	0.054
5.49	83.56	0.054
5.51	83.69	0.054
5.52	83.83	0.054
5.53	83.96	0.054
5.55	84.09	0.054
5.56	84.23	0.054
5.57	84.36	0.053
5.59	84.49	0.053
5.60	84.63	0.053
5.61	84.76	0.053
5.63	84.90	0.053
5.64	85.03	0.053
5.65	85.16	0.053
5.67	85.30	0.053
5.68	85.43	0.053
5.69	85.56	0.053
5.71	85.70	0.053
5.72	85.83	0.053
5.73	85.96	0.053
5.75	86.10	0.053
5.76	86.23	0.052
5.77	86.36	0.052
5.79	86.50	0.052
5.80	86.63	0.052
5.81	86.76	0.052
5.83	86.90	0.052
5.84	87.03	0.052
5.85	87.16	0.052
5.87	87.30	0.052
5.88	87.43	0.052
5.89	87.56	0.052
5.91	87.70	0.052
5.92	87.83	0.052
5.93	87.96	0.052
5.95	88.10	0.052
5.96	88.23	0.052
5.97	88.36	0.052
5.99	88.50	0.052
6.00	88.63	0.051
6.01	88.76	0.051
6.03	88.90	0.051
6.04	89.03	0.051
6.05	89.16	0.051
6.07	89.30	0.051
6.08	89.43	0.051
6.09	89.56	0.051
6.11	89.70	0.051
6.12	89.83	0.051
6.13	89.96	0.050
6.15	90.10	0.050
6.16	90.23	0.050
6.17	90.37	0.050
6.19	90.50	0.050
6.20	90.63	0.050
6.21	90.77	0.050
6.23	90.90	0.050
6.24	91.03	0.050
6.25	91.17	0.051
6.27	91.30	0.051
6.28	91.43	0.051
6.29	91.57	0.051
6.31	91.70	0.051
6.32	91.83	0.051
6.33	91.97	0.051
6.35	92.10	0.051
6.36	92.23	0.051
6.37	92.37	0.051
6.39	92.50	0.051
6.40	92.63	0.051
6.41	92.77	0.051
6.43	92.90	0.051
6.44	93.03	0.051
6.45	93.17	0.051
6.47	93.30	0.051
6.48	93.43	0.051
6.49	93.57	0.051
6.51	93.70	0.051
6.52	93.83	0.051
6.53	93.97	0.051
6.55	94.10	0.051
6.56	94.23	0.051
6.57	94.37	0.051
6.59	94.50	0.051
6.60	94.63	0.051
6.61	94.77	0.050
6.63	94.90	0.050
6.64	95.03	0.050
6.65	95.17	0.051
6.67	95.30	0.051
6.68	95.43	0.051
6.69	95.57	0.051
6.71	95.70	0.051
6.72	95.84	0.051
6.73	95.97	0.051
6.75	96.10	0.051
6.76	96.24	0.051
6.77	96.37	0.051
6.79	96.50	0.051
6.80	96.64	0.051
6.81	96.77	0.051
6.83	96.90	0.051
6.84	97.04	0.051
6.85	97.17	0.051
6.87	97.30	0.051
6.88	97.44	0.051
6.89	97.57	0.051
6.91	97.71	0.051
6.92	97.84	0.051
6.93	97.97	0.051
6.95	98.11	0.051
6.96	98.24	0.051
6.97	98.37	0.051
6.99	98.51	0.051
7.00	98.64	0.051
7.01	98.77	0.051
7.03	98.90	0.051
7.04	99.04	0.050
7.05	99.17	0.051
7.07	99.30	0.051
7.08	99.44	0.050
7.09	99.57	0.050
7.11	99.71	0.050
7.12	99.84	0.050
7.13	99.97	0.050
7.15	100.11	0.050
7.16	100.24	0.051
7.17	100.37	0.051
7.19	100.51	0.050
7.20	100.64	0.050
7.21	100.77	0.050
7.23	100.91	0.050
7.24	101.04	0.050
7.25	101.17	0.050
7.27	101.31	0.050
7.28	101.44	0.050
7.29	101.57	0.050
7.31	101.71	0.050
7.32	101.84	0.050
7.33	101.97	0.050
7.35	102.11	0.050
7.36	102.24	0.050
7.37	102.37	0.050
7.39	102.51	0.050
7.40	102.64	0.050
7.41	102.78	0.050
7.43	102.91	0.050
7.44	103.04	0.050
7.45	103.18	0.050
7.47	103.31	0.050
7.48	103.44	0.050
7.49	103.57	0.050
7.51	103.71	0.050
7.52	103.84	0.050
7.53	103.98	0.050
7.55	104.11	0.050
7.56	104.24	0.050
7.57	104.38	0.050
7.59	104.51	0.050
7.60	104.64	0.050
7.61	104.78	0.050
7.63	104.91	0.050
7.64	105.04	0.050
7.65	105.17	0.050
7.67	105.31	0.050
7.68	105.44	0.050
7.69	105.57	0.050
7.71	105.71	0.050
7.72	105.84	0.050
7.73	105.98	0.050
7.75	106.11	0.050
7.76	106.24	0.050
7.77	106.38	0.050
7.79	106.51	0.050
7.80	106.64	0.050
7.81	106.78	0.050
7.83	106.91	0.050
7.84	107.04	0.050
7.85	107.18	0.050
7.87	107.31	0.050
7.88	107.44	0.050
7.89	107.58	0.050
7.91	107.71	0.050
7.92	107.84	0.050
7.93	107.98	0.050
7.95	108.11	0.050
7.96	108.24	0.050
7.97	108.38	0.050
7.99	108.51	0.050
8.00	108.65	0.050
8.01	108.78	0.050
8.03	108.91	0.050
8.04	109.05	0.050
8.05	109.18	0.050
8.07	109.31	0.050
8.08	109.45	0.050
8.09	109.58	0.050
8.11	109.71	0.050
8.12	109.85	0.050
8.13	109.98	0.050
8.15	110.11	0.050
8.16	110.25	0.050
8.17	110.38	0.050
8.19	110.51	0.050
8.20	110.65	0.050
8.21	110.78	0.050
8.23	110.91	0.050
8.24	111.05	0.050
8.25	111.18	0.050
8.27	111.31	0.050
8.28	111.45	0.050
8.29	111.58	0.050
8.31	111.71	0.050
8.32	111.85	0.050
8.33	111.98	0.050
8.35	112.11	0.050
8.36	112.25	0.050
8.37	112.38	0.050
8.39	112.51	0.050
8.40	112.65	0.050
8.41	112.78	0.050
8.43	112.91	0.050
8.44	113.05	0.050
8.45	113.18	0.050
8.47	113.32	0.050
8.48	113.45	0.049
8.49	113.58	0.049
8.51	113.72	0.050
8.52	113.85	0.050
8.53	113.98	0.050
8.55	114.12	0.049
8.56	114.25	0.050
8.57	114.38	0.050
8.59	114.52	0.050
8.60	114.65	0.050
8.61	114.78	0.050
8.63	114.92	0.050
8.64	115.05	0.050
8.65	115.18	0.050
8.67	115.32	0.050
8.68	115.45	0.050
8.69	115.58	0.050
8.71	115.72	0.050
8.72	115.85	0.050
8.73	115.98	0.050
8.75	116.12	0.050
8.76	116.25	0.050
8.77	116.38	0.049
8.79	116.52	0.049
8.80	116.65	0.049
8.81	116.78	0.049
8.83	116.92	0.049
8.84	117.05	0.049
8.85	117.18	0.049
8.87	117.32	0.049
8.88	117.45	0.049
8.89	117.58	0.049
8.91	117.72	0.049
8.92	117.85	0.049
8.93	117.98	0.049
8.95	118.12	0.049
8.96	118.25	0.049
8.97	118.38	0.049
8.99	118.52	0.049
9.00	118.65	0.049
9.01	118.78	0.049
9.03	118.92	0.049
9.04	119.05	0.049
9.05	119.18	0.049
9.07	119.32	0.049
9.08	119.45	0.049
9.09	119.58	0.049
9.11	119.72	0.049
9.12	119.85	0.049
9.13	119.99	0.049
9.15	120.12	0.049
9.16	120.25	0.049
9.17	120.38	0.049
9.19	120.52	0.049
9.20	120.65	0.049
9.21	120.79	0.049
9.23	120.92	0.049
9.24	121.05	0.049
9.25	121.19	0.049
9.27	121.32	0.049
9.28	121.45	0.049
9.29	121.59	0.049
9.31	121.72	0.049
9.32	121.85	0.049
9.33	121.99	0.049
9.35	122.12	0.049
9.36	122.25	0.049
9.37	122.39	0.049
9.39	122.52	0.049
9.40	122.65	0.049
9.41	122.79	0.049
9.43	122.92	0.049
9.44	123.05	0.049
9.45	123.19	0.049
9.47	123.32	0.049
9.48	123.45	0.049
9.49	123.59	0.049
9.51	123.72	0.049
9.52	123.85	0.049
9.53	123.99	0.049
9.55	124.12	0.049
9.56	124.25	0.049
9.57	124.39	0.049
9.59	124.52	0.049
9.60	124.65	0.049
9.61	124.79	0.049
9.63	124.92	0.049
9.64	125.05	0.049
9.65	125.19	0.049
9.67	125.32	0.049
9.68	125.45	0.049
9.69	125.59	0.049
9.71	125.72	0.049
9.72	125.86	0.049
9.73	125.99	0.049
9.75	126.12	0.049
9.76	126.26	0.049
9.77	126.39	0.049
9.79	126.52	0.049
9.80	126.65	0.049
9.81	126.79	0.049
9.83	126.92	0.049
9.84	127.06	0.049
9.85	127.19	0.049
9.87	127.32	0.049
9.88	127.46	0.049
9.89	127.59	0.049
9.91	127.72	0.049
9.92	127.86	0.049
9.93	127.99	0.049
9.95	128.12	0.049
9.96	128.26	0.049
9.97	128.39	0.049
9.99	128.52	0.049
10.00	128.66	0.049
10.01	128.79	0.049
10.03	128.92	0.049
10.04	129.06	0.049
10.05	129.19	0.049
10.07	129.32	0.049
10.08	129.46	0.049
10.09	129.59	0.049
10.11	129.72	0.049
10.12	129.86	0.049
10.13	129.99	0.049
10.15	130.12	0.049
10.16	130.26	0.049
10.17	130.39	0.049
10.19	130.52	0.049
10.20	130.66	0.049
10.21	130.79	0.049
10.23	130.92	0.049
10.24	131.06	0.049
10.25	131.19	0.049
10.27	131.32	0.049
10.28	131.46	0.049
10.29	131.59	0.049
10.31	131.73	0.049
10.32	131.86	0.049
10.33	131.99	0.049
10.35	132.12	0.049
10.36	132.26	0.049
10.37	132.39	0.049
10.39	132.53	0.049
10.40	132.66	0.049
10.41	132.79	0.049
10.43	132.92	0.049
10.44	133.06	0.049
10.45	133.19	0.049
10.47	133.33	0.049
10.48	133.46	0.049
10.49	133.59	0.049
10.51	133.73	0.049
10.52	133.86	0.049
10.53	133.99	0.049
10.55	134.13	0.049
10.56	134.26	0.049
10.57	134.39	0.049
10.59	134.53	0.049
10.60	134.66	0.049
10.61	134.79	0.049
10.63	134.93	0.049
10.64	135.06	0.049
10.65	135.19	0.049
10.67	135.33	0.049
10.68	135.46	0.049
10.69	135.59	0.049
10.71	135.73	0.049
10.72	135.86	0.049
10.73	135.99	0.049
10.75	136.13	0.049
10.76	136.26	0.049
10.77	136.39	0.049
10.79	136.53	0.049
10.80	136.66	0.049
10.81	136.80	0.049
10.83	136.93	0.049
10.84	137.06	0.049
10.85	137.19	0.049
10.87	137.33	0.049
10.88	137.46	0.049
10.89	137.59	0.049
10.91	137.73	0.049
10.92	137.86	0.049
10.93	137.99	0.049
10.95	138.13	0.049
10.96	138.26	0.049
10.97	138.39	0.049
10.99	138.53	0.049
11.00	138.66	0.049
11.01	138.80	0.049
11.03	138.93	0.049
11.04	139.06	0.049
11.05	139.20	0.049
11.07	139.33	0.049
11.08	139.46	0.049
11.09	139.60	0.049
11.11	139.73	0.049
11.12	139.86	0.049
11.13	140.00	0.049
11.15	140.13	0.049
11.16	140.26	0.049
11.17	140.40	0.049
11.19	140.53	0.049
11.20	140.66	0.049
11.21	140.80	0.049
11.23	140.93	0.049
11.24	141.06	0.049
11.25	141.20	0.049
11.27	141.33	0.049
11.28	141.46	0.049
11.29	141.60	0.049
11.31	141.73	0.049
11.32	141.86	0.049
11.33	142.00	0.049
11.35	142.13	0.049
11.36	142.26	0.049
11.37	142.40	0.049
11.39	142.53	0.049
11.40	142.66	0.049
11.41	142.80	0.049
11.43	142.93	0.049
11.44	143.06	0.049
11.45	143.20	0.049
11.47	143.33	0.049
11.48	143.46	0.049
11.49	143.60	0.049
11.51	143.73	0.049
11.52	143.86	0.049
11.53	144.00	0.049
11.55	144.13	0.050
11.56	144.26	0.049
11.57	144.40	0.049
11.59	144.53	0.049
11.60	144.66	0.050
11.61	144.80	0.050
11.63	144.93	0.050
11.64	145.06	0.050
11.65	145.20	0.050
11.67	145.33	0.050
11.68	145.47	0.050
11.69	145.60	0.050
11.71	145.73	0.050
11.72	145.87	0.050
11.73	146.00	0.050
11.75	146.13	0.050
11.76	146.27	0.050
11.77	146.40	0.050
11.79	146.53	0.050
11.80	146.67	0.050
11.81	146.80	0.050
11.83	146.93	0.050
11.84	147.07	0.050
11.85	147.20	0.050
11.87	147.33	0.050
11.88	147.47	0.050
11.89	147.60	0.050
11.91	147.73	0.050
11.92	147.87	0.050
11.93	148.00	0.050
11.95	148.13	0.050
11.96	148.27	0.051
11.97	148.40	0.051
11.99	148.53	0.051
12.00	148.67	0.051
12.01	148.80	0.051
12.03	148.93	0.051
12.04	149.07	0.051
12.05	149.20	0.051
12.07	149.33	0.051
12.08	149.47	0.051
12.09	149.60	0.051
12.11	149.73	0.051
12.12	149.87	0.051
12.13	150.00	0.051
12.15	150.13	0.051
12.16	150.27	0.051
12.17	150.40	0.052
12.19	150.53	0.052
12.20	150.67	0.052
12.21	150.80	0.052
12.23	150.93	0.052
12.24	151.07	0.052
12.25	151.20	0.052
12.27	151.33	0.052
12.28	151.47	0.052
12.29	151.60	0.052
12.31	151.73	0.052
12.32	151.87	0.052
12.33	152.00	0.052
12.35	152.14	0.052
12.36	152.27	0.052
12.37	152.40	0.052
12.39	152.53	0.052
12.40	152.67	0.052
12.41	152.80	0.052
12.43	152.94	0.052
12.44	153.07	0.052
12.45	153.20	0.052
12.47	153.34	0.052
12.48	153.47	0.053
12.49	153.60	0.053
12.51	153.74	0.053
12.52	153.87	0.053
12.53	154.00	0.053
12.55	154.14	0.053
12.56	154.27	0.053
12.57	154.40	0.053
12.59	154.54	0.053
12.60	154.67	0.053
12.61	154.80	0.053
12.63	154.94	0.053
12.64	155.07	0.053
12.65	155.20	0.053
12.67	155.33	0.053
12.68	155.47	0.053
12.69	155.60	0.053
12.71	155.74	0.053
12.72	155.87	0.053
12.73	156.00	0.053
12.75	156.14	0.053
12.76	156.27	0.054
12.77	156.40	0.054
12.79	156.54	0.054
12.80	156.67	0.054
12.81	156.80	0.056
12.83	156.94	0.111
12.84	157.07	0.206
12.85	157.19	0.348
12.87	157.32	0.517
12.88	157.44	0.753
12.89	157.55	1.037
12.91	157.66	1.254
12.92	157.77	1.451
12.93	157.88	1.643
12.95	157.99	1.841
12.96	158.10	2.036
12.97	158.21	2.225
12.99	158.32	2.413
13.00	158.43	2.597
13.01	158.54	2.777
13.03	158.65	2.932
13.04	158.76	2.917
13.05	158.89	2.577
13.07	159.04	1.476
13.08	159.21	0.901
13.09	159.38	0.708
13.11	159.55	0.598
13.12	159.71	0.513
13.13	159.87	0.442
13.15	160.02	0.385
13.16	160.17	0.335
13.17	160.32	0.294
13.19	160.47	0.259
13.20	160.61	0.228
13.21	160.76	0.199
13.23	160.90	0.180
13.24	161.04	0.161
13.25	161.17	0.144
13.27	161.31	0.130
13.28	161.45	0.118
13.29	161.59	0.108
13.31	161.72	0.101
13.32	161.86	0.095
13.33	161.99	0.090
13.35	162.13	0.087
13.36	162.26	0.084
13.37	162.40	0.078
13.39	162.53	0.076
13.40	162.67	0.072
13.41	162.80	0.072
13.43	162.94	0.071
13.44	163.07	0.069
13.45	163.20	0.068
13.47	163.34	0.067
13.48	163.47	0.066
13.49	163.60	0.066
13.51	163.74	0.065
13.52	163.87	0.065
13.53	164.01	0.064
13.55	164.14	0.063
13.56	164.27	0.063
13.57	164.41	0.063
13.59	164.54	0.063
13.60	164.67	0.063
13.61	164.81	0.062
13.63	164.94	0.062
13.64	165.07	0.062
13.65	165.21	0.062
13.67	165.34	0.062
13.68	165.47	0.061
13.69	165.61	0.061
13.71	165.74	0.061
13.72	165.87	0.061
13.73	166.01	0.060
13.75	166.14	0.060
13.76	166.27	0.060
13.77	166.41	0.060
13.79	166.54	0.060
13.80	166.68	0.060
13.81	166.81	0.060
13.83	166.94	0.060
13.84	167.08	0.060
13.85	167.21	0.060
13.87	167.34	0.060
13.88	167.47	0.060
13.89	167.61	0.060
13.91	167.74	0.059
13.92	167.88	0.059
13.93	168.01	0.060
13.95	168.14	0.059
13.96	168.28	0.059
13.97	168.41	0.059
13.99	168.54	0.059
14.00	168.67	0.059
14.01	168.81	0.059
14.03	168.94	0.059
14.04	169.08	0.059
14.05	169.21	0.059
14.07	169.34	0.059
14.08	169.47	0.060
14.09	169.61	0.059
14.11	169.74	0.060
14.12	169.87	0.059
14.13	170.01	0.059
14.15	170.14	0.060
14.16	170.28	0.060
14.17	170.41	0.060
14.19	170.54	0.060
14.20	170.68	0.060
14.21	170.81	0.060
14.23	170.94	0.060
14.24	171.08	0.060
14.25	171.21	0.060
14.27	171.34	0.060
14.28	171.48	0.060
14.29	171.61	0.060
14.31	171.74	0.060
14.32	171.88	0.060
14.33	172.01	0.060
14.35	172.14	0.060
14.36	172.28	0.060
14.37	172.41	0.060
14.39	172.54	0.060
14.40	172.67	0.060
14.41	172.81	0.060
14.43	172.94	0.060
14.44	173.08	0.060
14.45	173.21	0.060
14.47	173.34	0.061
14.48	173.48	0.061
14.49	173.61	0.061
14.51	173.74	0.061
14.52	173.88	0.061
14.53	174.01	0.061
14.55	174.14	0.061
14.56	174.28	0.061
14.57	174.41	0.061
14.59	174.54	0.062
14.60	174.68	0.062
14.61	174.81	0.062
14.63	174.94	0.062
14.64	175.08	0.062
14.65	175.21	0.062
14.67	175.34	0.062
14.68	175.48	0.062
14.69	175.61	0.062
14.71	175.75	0.062
14.72	175.88	0.062
14.73	176.01	0.062
14.75	176.15	0.062
14.76	176.28	0.062
14.77	176.41	0.062
14.79	176.54	0.063
14.80	176.68	0.063
14.81	176.81	0.063
14.83	176.95	0.063
14.84	177.08	0.063
14.85	177.21	0.063
14.87	177.35	0.063
14.88	177.48	0.063
14.89	177.61	0.063
14.91	177.75	0.063
14.92	177.88	0.063
14.93	178.01	0.063
14.95	178.15	0.063
14.96	178.28	0.063
14.97	178.41	0.063
14.99	178.55	0.063
15.00	178.68	0.063
15.01	178.81	0.063
15.03	178.95	0.063
15.04	179.08	0.063
15.05	179.21	0.063
15.07	179.34	0.064
15.08	179.48	0.064
15.09	179.61	0.064
15.11	179.75	0.064
15.12	179.88	0.064
15.13	180.01	0.064
15.15	180.14	0.064
15.16	180.28	0.064
15.17	180.41	0.064
15.19	180.54	0.064
15.20	180.68	0.064
15.21	180.81	0.064
15.23	180.95	0.064
15.24	181.08	0.064
15.25	181.21	0.064
15.27	181.35	0.064
15.28	181.48	0.064
15.29	181.61	0.064
15.31	181.75	0.064
15.32	181.88	0.064
15.33	182.01	0.064
15.35	182.15	0.064
15.36	182.28	0.065
15.37	182.41	0.065
15.39	182.55	0.065
15.40	182.68	0.065
15.41	182.81	0.065
15.43	182.95	0.065
15.44	183.08	0.065
15.45	183.21	0.065
15.47	183.35	0.064
15.48	183.48	0.064
15.49	183.61	0.064
15.51	183.75	0.064
15.52	183.88	0.064
15.53	184.01	0.064
15.55	184.15	0.064
15.56	184.28	0.064
15.57	184.41	0.064
15.59	184.55	0.064
15.60	184.68	0.064
15.61	184.82	0.064
15.63	184.95	0.064
15.64	185.08	0.064
15.65	185.22	0.064
15.67	185.35	0.064
15.68	185.48	0.064
15.69	185.62	0.064
15.71	185.75	0.064
15.72	185.88	0.064
15.73	186.02	0.064
15.75	186.15	0.064
15.76	186.28	0.064
15.77	186.42	0.064
15.79	186.55	0.064
15.80	186.68	0.064
15.81	186.82	0.064
15.83	186.95	0.064
15.84	187.08	0.064
15.85	187.22	0.064
15.87	187.35	0.064
15.88	187.48	0.064
15.89	187.62	0.064
15.91	187.75	0.064
15.92	187.88	0.064
15.93	188.02	0.064
15.95	188.15	0.064
15.96	188.28	0.064
15.97	188.42	0.064
15.99	188.55	0.064
16.00	188.68	0.064
16.01	188.82	0.064
16.03	188.95	0.064
16.04	189.08	0.064
16.05	189.22	0.064
16.07	189.35	0.064
16.08	189.48	0.064
16.09	189.62	0.064
16.11	189.75	0.064
16.12	189.88	0.064
16.13	190.02	0.064
16.15	190.15	0.064
16.16	190.28	0.064
16.17	190.42	0.064
16.19	190.55	0.064
16.20	190.68	0.064
16.21	190.82	0.064
16.23	190.95	0.064
16.24	191.08	0.063
16.25	191.22	0.063
16.27	191.35	0.063
16.28	191.48	0.063
16.29	191.62	0.063
16.31	191.75	0.063
16.32	191.88	0.063
16.33	192.02	0.063
16.35	192.15	0.063
16.36	192.28	0.063
16.37	192.42	0.063
16.39	192.55	0.063
16.40	192.68	0.063
16.41	192.82	0.063
16.43	192.95	0.063
16.44	193.08	0.063
16.45	193.22	0.063
16.47	193.35	0.063
16.48	193.48	0.063
16.49	193.62	0.063
16.51	193.75	0.063
16.52	193.88	0.063
16.53	194.02	0.063
16.55	194.15	0.063
16.56	194.28	0.063
16.57	194.42	0.063
16.59	194.55	0.063
16.60	194.69	0.063
16.61	194.82	0.063
16.63	194.95	0.063
16.64	195.08	0.063
16.65	195.22	0.063
16.67	195.35	0.063
16.68	195.48	0.063
16.69	195.62	0.063
16.71	195.75	0.063
16.72	195.89	0.063
16.73	196.02	0.063
16.75	196.15	0.063
16.76	196.29	0.063
16.77	196.42	0.063
16.79	196.55	0.063
16.80	196.69	0.063
16.81	196.82	0.063
16.83	196.95	0.063
16.84	197.09	0.063
16.85	197.22	0.063
16.87	197.35	0.063
16.88	197.49	0.063
16.89	197.62	0.063
16.91	197.75	0.063
16.92	197.89	0.063
16.93	198.02	0.063
16.95	198.15	0.063
16.96	198.29	0.063
16.97	198.42	0.063
16.99	198.55	0.063
17.00	198.69	0.063
17.01	198.82	0.063
17.03	198.95	0.062
17.04	199.09	0.062
17.05	199.22	0.062
17.07	199.35	0.062
17.08	199.49	0.062
17.09	199.62	0.062
17.11	199.75	0.062
17.12	199.89	0.062
17.13	200.02	0.062
17.15	200.15	0.062
17.16	200.29	0.062
17.17	200.42	0.062
17.19	200.55	0.062
17.20	200.69	0.062
17.21	200.82	0.062
17.23	200.95	0.062
17.24	201.09	0.062
17.25	201.22	0.062
17.27	201.35	0.062
17.28	201.49	0.062
17.29	201.62	0.062
17.31	201.75	0.062
17.32	201.89	0.062
17.33	202.02	0.062
17.35	202.15	0.062
17.36	202.29	0.062
17.37	202.42	0.062
17.39	202.55	0.062
17.40	202.69	0.062
17.41	202.82	0.062
17.43	202.95	0.062
17.44	203.09	0.062
17.45	203.22	0.062
17.47	203.36	0.062
17.48	203.49	0.062
17.49	203.62	0.062
17.51	203.76	0.062
17.52	203.89	0.062
17.53	204.02	0.062
17.55	204.15	0.062
17.56	204.29	0.062
17.57	204.42	0.062
17.59	204.55	0.062
17.60	204.69	0.062
17.61	204.82	0.062
17.63	204.95	0.062
17.64	205.09	0.062
17.65	205.22	0.062
17.67	205.35	0.062
17.68	205.49	0.061
17.69	205.62	0.061
17.71	205.75	0.061
17.72	205.89	0.061
17.73	206.02	0.061
17.75	206.16	0.062
17.76	206.29	0.061
17.77	206.42	0.061
17.79	206.56	0.061
17.80	206.69	0.062
17.81	206.82	0.062
17.83	206.96	0.061
17.84	207.09	0.062
17.85	207.22	0.061
17.87	207.36	0.061
17.88	207.49	0.061
17.89	207.62	0.061
17.91	207.76	0.061
17.92	207.89	0.061
17.93	208.02	0.061
17.95	208.16	0.061
17.96	208.29	0.061
17.97	208.42	0.061
17.99	208.56	0.061
18.00	208.69	0.061

[step]
Ramp 10.00 °C/min to 30.00 °C
Time	Temperature	Heat Flow (Normalized)
min	°C	W/g
19.00	210.07	-0.106
19.02	210.07	-0.106
19.03	210.07	-0.106
19.04	210.07	-0.106
19.06	210.06	-0.099
19.07	210.04	-0.068
19.08	210.02	-0.033
19.09	209.98	-0.006
19.11	209.94	0.014
19.12	209.87	0.022
19.13	209.80	0.022
19.15	209.72	0.009
19.16	209.63	-0.005
19.18	209.53	-0.047
19.19	209.42	-0.074
19.20	209.31	-0.106
19.22	209.20	-0.129
19.23	209.09	-0.151
19.24	208.97	-0.172
19.26	208.85	-0.184
19.27	208.72	-0.199
19.28	208.60	-0.209
19.29	208.48	-0.218
19.31	208.35	-0.225
19.32	208.22	-0.232
19.33	208.10	-0.236
19.35	207.97	-0.239
19.36	207.84	-0.246
19.38	207.71	-0.248
19.39	207.58	-0.248
19.40	207.45	-0.252
19.42	207.32	-0.253
19.43	207.19	-0.253
19.44	207.06	-0.255
19.46	206.93	-0.257
19.47	206.80	-0.257
19.48	206.67	-0.258
19.49	206.54	-0.259
19.51	206.41	-0.259
19.52	206.28	-0.260
19.53	206.15	-0.261
19.55	206.02	-0.261
19.56	205.89	-0.261
19.58	205.75	-0.262
19.59	205.62	-0.262
19.60	205.49	-0.263
19.62	205.36	-0.263
19.63	205.23	-0.263
19.64	205.10	-0.264
19.66	204.97	-0.264
19.67	204.83	-0.264
19.68	204.70	-0.264
19.69	204.57	-0.265
19.71	204.44	-0.265
19.72	204.31	-0.265
19.73	204.17	-0.265
19.75	204.04	-0.266
19.76	203.91	-0.266
19.78	203.78	-0.266
19.79	203.65	-0.266
19.80	203.51	-0.266
19.82	203.38	-0.267
19.83	203.25	-0.267
19.84	203.12	-0.267
19.86	202.98	-0.267
19.87	202.85	-0.267
19.88	202.72	-0.267
19.89	202.59	-0.267
19.91	202.46	-0.268
19.92	202.32	-0.268
19.93	202.19	-0.268
19.95	202.06	-0.268
19.96	201.93	-0.268
19.98	201.79	-0.268
19.99	201.66	-0.268
20.00	201.53	-0.268
20.02	201.39	-0.268
20.03	201.26	-0.268
20.04	201.13	-0.268
20.06	201.00	-0.268
20.07	200.87	-0.268
20.08	200.73	-0.268
20.09	200.60	-0.268
20.11	200.47	-0.268
20.12	200.34	-0.268
20.13	200.20	-0.268
20.15	200.07	-0.268
20.16	199.94	-0.268
20.18	199.80	-0.268
20.19	199.67	-0.268
20.20	199.54	-0.268
20.22	199.41	-0.268
20.23	199.27	-0.268
20.24	199.14	-0.268
20.26	199.01	-0.268
20.27	198.87	-0.268
20.28	198.74	-0.267
20.29	198.61	-0.267
20.31	198.48	-0.267
20.32	198.34	-0.267
20.33	198.21	-0.267
20.35	198.08	-0.267
20.36	197.94	-0.267
20.38	197.81	-0.267
20.39	197.68	-0.267
20.40	197.55	-0.267
20.42	197.41	-0.267
20.43	197.28	-0.266
20.44	197.15	-0.266
20.46	197.01	-0.266
20.47	196.88	-0.266
20.48	196.75	-0.266
20.49	196.62	-0.266
20.51	196.48	-0.266
20.52	196.35	-0.266
20.53	196.22	-0.266
20.55	196.08	-0.266
20.56	195.95	-0.266
20.58	195.82	-0.266
20.59	195.68	-0.266
20.60	195.55	-0.265
20.62	195.42	-0.265
20.63	195.29	-0.265
20.64	195.15	-0.265
20.66	195.02	-0.265
20.67	194.89	-0.265
20.68	194.75	-0.265
20.69	194.62	-0.265
20.71	194.49	-0.264
20.72	194.35	-0.264
20.73	194.22	-0.264
20.75	194.09	-0.264
20.76	193.95	-0.264
20.78	193.82	-0.264
20.79	193.69	-0.264
20.80	193.55	-0.264
20.82	193.42	-0.264
20.83	193.29	-0.264
20.84	193.16	-0.264
20.86	193.02	-0.263
20.87	192.89	-0.263
20.88	192.76	-0.263
20.89	192.62	-0.263
20.91	192.49	-0.263
20.92	192.36	-0.263
20.93	192.22	-0.263
20.95	192.09	-0.263
20.96	191.96	-0.263
20.98	191.82	-0.262
20.99	191.69	-0.262
21.00	191.56	-0.262
21.02	191.43	-0.262
21.03	191.29	-0.262
21.04	191.16	-0.262
21.06	191.02	-0.262
21.07	190.89	-0.262
21.08	190.76	-0.262
21.09	190.63	-0.262
21.11	190.49	-0.262
21.12	190.36	-0.261
21.13	190.23	-0.261
21.15	190.09	-0.261
21.16	189.96	-0.261
21.18	189.83	-0.261
21.19	189.69	-0.261
21.20	189.56	-0.261
21.22	189.43	-0.261
21.23	189.30	-0.260
21.24	189.16	-0.260
21.26	189.03	-0.260
21.27	188.90	-0.260
21.28	188.76	-0.260
21.29	188.63	-0.260
21.31	188.50	-0.260
21.32	188.36	-0.260
21.33	188.23	-0.260
21.35	188.10	-0.260
21.36	187.96	-0.260
21.38	187.83	-0.259
21.39	187.70	-0.259
21.40	187.56	-0.259
21.42	187.43	-0.259
21.43	187.30	-0.259
21.44	187.16	-0.259
21.46	187.03	-0.259
21.47	186.90	-0.258
21.48	186.77	-0.259
21.49	186.63	-0.259
21.51	186.50	-0.258
21.52	186.36	-0.258
21.53	186.23	-0.258
21.55	186.10	-0.258
21.56	185.97	-0.258
21.58	185.83	-0.258
21.59	185.70	-0.258
21.60	185.57	-0.258
21.62	185.43	-0.258
21.63	185.30	-0.257
21.64	185.17	-0.257
21.66	185.03	-0.257
21.67	184.90	-0.257
21.68	184.77	-0.257
21.69	184.63	-0.257
21.71	184.50	-0.257
21.72	184.37	-0.257
21.73	184.23	-0.257
21.75	184.10	-0.257
21.76	183.97	-0.257
21.78	183.83	-0.257
21.79	183.70	-0.257
21.80	183.57	-0.256
21.82	183.43	-0.256
21.83	183.30	-0.256
21.84	183.17	-0.256
21.86	183.04	-0.256
21.87	182.90	-0.256
21.88	182.77	-0.256
21.89	182.63	-0.256
21.91	182.50	-0.256
21.92	182.37	-0.256
21.93	182.24	-0.256
21.95	182.10	-0.256
21.96	181.97	-0.256
21.98	181.84	-0.256
21.99	181.70	-0.255
22.00	181.57	-0.255
22.02	181.44	-0.255
22.03	181.30	-0.255
22.04	181.17	-0.255
22.06	181.04	-0.255
22.07	180.90	-0.255
22.08	180.77	-0.255
22.09	180.64	-0.255
22.11	180.50	-0.255
22.12	180.37	-0.255
22.13	180.24	-0.255
22.15	180.10	-0.255
22.16	179.97	-0.254
22.18	179.84	-0.254
22.19	179.71	-0.254
22.20	179.57	-0.254
22.22	179.44	-0.254
22.23	179.31	-0.254
22.24	179.17	-0.254
22.26	179.04	-0.254
22.27	178.91	-0.254
22.28	178.77	-0.254
22.29	178.64	-0.254
22.31	178.51	-0.254
22.32	178.37	-0.254
22.33	178.24	-0.254
22.35	178.11	-0.254
22.36	177.97	-0.254
22.38	177.84	-0.254
22.39	177.71	-0.254
22.40	177.57	-0.253
22.42	177.44	-0.254
22.43	177.31	-0.253
22.44	177.18	-0.253
22.46	177.04	-0.253
22.47	176.91	-0.253
22.48	176.78	-0.253
22.49	176.64	-0.253
22.51	176.51	-0.253
22.52	176.38	-0.253
22.53	176.24	-0.253
22.55	176.11	-0.253
22.56	175.98	-0.253
22.58	175.84	-0.253
22.59	175.71	-0.253
22.60	175.58	-0.253
22.62	175.44	-0.253
22.63	175.31	-0.253
22.64	175.18	-0.252
22.66	175.04	-0.252
22.67	174.91	-0.252
22.68	174.78	-0.252
22.69	174.64	-0.252
22.71	174.51	-0.252
22.72	174.38	-0.252
22.73	174.25	-0.252
22.75	174.11	-0.252
22.76	173.98	-0.252
22.78	173.85	-0.252
22.79	173.71	-0.251
22.80	173.58	-0.251
22.82	173.45	-0.252
22.83	173.31	-0.251
22.84	173.18	-0.251
22.86	173.05	-0.251
22.87	172.91	-0.251
22.88	172.78	-0.251
22.89	172.65	-0.251
22.91	172.51	-0.251
22.92	172.38	-0.251
22.93	172.25	-0.251
22.95	172.11	-0.251
22.96	171.98	-0.251
22.98	171.85	-0.251
22.99	171.71	-0.251
23.00	171.58	-0.251
23.02	171.45	-0.251
23.03	171.31	-0.251
23.04	171.18	-0.251
23.06	171.05	-0.251
23.07	170.91	-0.251
23.08	170.78	-0.251
23.09	170.65	-0.251
23.11	170.52	-0.251
23.12	170.38	-0.251
23.13	170.25	-0.250
23.15	170.12	-0.250
23.16	169.98	-0.250
23.18	169.85	-0.250
23.19	169.72	-0.250
23.20	169.58	-0.250
23.22	169.45	-0.250
23.23	169.32	-0.250
23.24	169.18	-0.250
23.26	169.05	-0.250
23.27	168.92	-0.250
23.28	168.78	-0.249
23.29	168.65	-0.249
23.31	168.52	-0.250
23.32	168.38	-0.249
23.33	168.25	-0.249
23.35	168.12	-0.249
23.36	167.98	-0.249
23.38	167.85	-0.249
23.39	167.72	-0.249
23.40	167.59	-0.249
23.42	167.45	-0.249
23.43	167.32	-0.249
23.44	167.19	-0.249
23.46	167.05	-0.249
23.47	166.92	-0.249
23.48	166.79	-0.249
23.49	166.65	-0.249
23.51	166.52	-0.249
23.52	166.39	-0.249
23.53	166.25	-0.249
23.55	166.12	-0.249
23.56	165.99	-0.249
23.58	165.85	-0.248
23.59	165.72	-0.249
23.60	165.59	-0.248
23.62	165.45	-0.248
23.63	165.32	-0.248
23.64	165.19	-0.248
23.66	165.05	-0.248
23.67	164.92	-0.248
23.68	164.79	-0.248
23.69	164.65	-0.248
23.71	164.52	-0.248
23.72	164.39	-0.248
23.73	164.26	-0.248
23.75	164.12	-0.248
23.76	163.99	-0.248
23.78	163.86	-0.248
23.79	163.72	-0.248
23.80	163.59	-0.248
23.82	163.46	-0.248
23.83	163.32	-0.248
23.84	163.19	-0.248
23.86	163.06	-0.248
23.87	162.92	-0.248
23.88	162.79	-0.248
23.89	162.66	-0.248
23.91	162.52	-0.248
23.92	162.39	-0.248
23.93	162.26	-0.247
23.95	162.12	-0.248
23.96	161.99	-0.247
23.98	161.86	-0.247
23.99	161.72	-0.247
24.00	161.59	-0.247
24.02	161.46	-0.247
24.03	161.32	-0.247
24.04	161.19	-0.247
24.06	161.06	-0.247
24.07	160.93	-0.247
24.08	160.79	-0.247
24.09	160.66	-0.247
24.11	160.53	-0.247
24.12	160.39	-0.247
24.13	160.26	-0.247
24.15	160.13	-0.247
24.16	159.99	-0.247
24.18	159.86	-0.247
24.19	159.72	-0.247
24.20	159.59	-0.247
24.22	159.46	-0.247
24.23	159.33	-0.247
24.24	159.19	-0.247
24.26	159.06	-0.247
24.27	158.93	-0.247
24.28	158.79	-0.247
24.29	158.66	-0.247
24.31	158.53	-0.247
24.32	158.39	-0.247
24.33	158.26	-0.247
24.35	158.13	-0.246
24.36	157.99	-0.246
24.38	157.86	-0.246
24.39	157.73	-0.246
24.40	157.59	-0.246
24.42	157.46	-0.247
24.43	157.33	-0.246
24.44	157.19	-0.246
24.46	157.06	-0.246
24.47	156.93	-0.246
24.48	156.79	-0.246
24.49	156.66	-0.246
24.51	156.53	-0.246
24.52	156.40	-0.246
24.53	156.26	-0.246
24.55	156.13	-0.246
24.56	156.00	-0.246
24.58	155.86	-0.246
24.59	155.73	-0.246
24.60	155.60	-0.246
24.62	155.46	-0.246
24.63	155.33	-0.246
24.64	155.20	-0.246
24.66	155.06	-0.246
24.67	154.93	-0.246
24.68	154.80	-0.246
24.69	154.66	-0.246
24.71	154.53	-0.245
24.72	154.40	-0.245
24.73	154.26	-0.245
24.75	154.13	-0.245
24.76	154.00	-0.245
24.78	153.86	-0.369
24.79	153.77	-3.061
24.80	153.74	-4.798
24.82	153.70	-5.033
24.83	153.64	-5.048
24.84	153.57	-5.075
24.86	153.49	-5.099
24.87	153.39	-3.800
24.88	153.21	-1.406
24.89	153.02	-0.930
24.91	152.83	-0.766
24.92	152.65	-0.673
24.93	152.48	-0.601
24.95	152.32	-0.553
24.96	152.15	-0.502
24.98	152.00	-0.466
24.99	151.84	-0.434
25.00	151.69	-0.402
25.02	151.55	-0.381
25.03	151.40	-0.357
25.04	151.26	-0.342
25.06	151.12	-0.325
25.07	150.98	-0.313
25.08	150.84	-0.302
25.09	150.70	-0.294
25.11	150.56	-0.286
25.12	150.42	-0.282
25.13	150.29	-0.276
25.15	150.15	-0.274
25.16	150.02	-0.269
25.18	149.88	-0.264
25.19	149.75	-0.262
25.20	149.61	-0.261
25.22	149.48	-0.259
25.23	149.34	-0.258
25.24	149.21	-0.256
25.26	149.07	-0.255
25.27	148.94	-0.254
25.28	148.81	-0.253
25.29	148.67	-0.253
25.31	148.54	-0.252
25.32	148.41	-0.251
25.33	148.27	-0.251
25.35	148.14	-0.251
25.36	148.01	-0.250
25.38	147.87	-0.250
25.39	147.74	-0.250
25.40	147.61	-0.250
25.42	147.47	-0.249
25.43	147.34	-0.249
25.44	147.21	-0.249
25.46	147.07	-0.249
25.47	146.94	-0.248
25.48	146.80	-0.248
25.49	146.67	-0.248
25.51	146.54	-0.248
25.52	146.40	-0.248
25.53	146.27	-0.247
25.55	146.14	-0.247
25.56	146.00	-0.247
25.58	145.87	-0.247
25.59	145.74	-0.246
25.60	145.61	-0.246
25.62	145.47	-0.246
25.63	145.34	-0.246
25.64	145.21	-0.246
25.66	145.07	-0.246
25.67	144.94	-0.246
25.68	144.81	-0.245
25.69	144.67	-0.245
25.71	144.54	-0.245
25.72	144.41	-0.245
25.73	144.28	-0.245
25.75	144.14	-0.245
25.76	144.01	-0.245
25.78	143.88	-0.244
25.79	143.74	-0.244
25.80	143.61	-0.244
25.82	143.48	-0.244
25.83	143.34	-0.244
25.84	143.21	-0.244
25.86	143.08	-0.244
25.87	142.94	-0.244
25.88	142.81	-0.244
25.89	142.68	-0.244
25.91	142.54	-0.244
25.92	142.41	-0.243
25.93	142.28	-0.243
25.95	142.14	-0.243
25.96	142.01	-0.243
25.98	141.88	-0.243
25.99	141.74	-0.243
26.00	141.61	-0.243
26.02	141.48	-0.243
26.03	141.34	-0.243
26.04	141.21	-0.243
26.06	141.08	-0.243
26.07	140.95	-0.243
26.08	140.81	-0.243
[...]
41.79	66.51	0.094
41.80	66.64	0.095
41.81	66.78	0.094
41.83	66.91	0.094
41.84	67.04	0.094
41.86	67.18	0.094
41.87	67.31	0.094
41.88	67.44	0.094
41.89	67.58	0.094
41.91	67.71	0.094
41.92	67.84	0.094
41.94	67.98	0.094
41.95	68.11	0.094
41.96	68.24	0.094
41.98	68.38	0.094
41.99	68.51	0.094
42.00	68.64	0.094
42.01	68.78	0.094
42.03	68.91	0.094
42.04	69.05	0.094
42.06	69.18	0.094
42.07	69.31	0.094
42.08	69.44	0.094
42.09	69.58	0.094
42.11	69.71	0.094
42.12	69.85	0.094
42.14	69.98	0.094
42.15	70.11	0.094
42.16	70.25	0.093
42.18	70.38	0.093
42.19	70.51	0.093
42.20	70.65	0.093
42.21	70.78	0.093
42.23	70.91	0.093
42.24	71.05	0.093
42.26	71.18	0.093
42.27	71.31	0.093
42.28	71.45	0.093
42.29	71.58	0.093
42.31	71.71	0.093
42.32	71.85	0.093
42.34	71.98	0.093
42.35	72.11	0.093
42.36	72.25	0.093
42.38	72.38	0.093
42.39	72.52	0.093
42.40	72.65	0.093
42.41	72.78	0.093
42.43	72.91	0.093
42.44	73.05	0.093
42.46	73.18	0.093
42.47	73.31	0.093
42.48	73.45	0.093
42.49	73.58	0.093
42.51	73.71	0.093
42.52	73.85	0.093
42.54	73.98	0.093
42.55	74.12	0.093
42.56	74.25	0.093
42.58	74.38	0.093
42.59	74.52	0.093
42.60	74.65	0.093
42.61	74.78	0.093
42.63	74.92	0.093
42.64	75.05	0.092
42.66	75.18	0.092
42.67	75.32	0.092
42.68	75.45	0.092
42.69	75.58	0.092
42.71	75.72	0.092
42.72	75.85	0.092
42.74	75.98	0.092
42.75	76.12	0.092
42.76	76.25	0.092
42.78	76.38	0.092
42.79	76.52	0.092
42.80	76.65	0.092
42.81	76.78	0.092
42.83	76.92	0.092
42.84	77.05	0.092
42.86	77.18	0.092
42.87	77.32	0.092
42.88	77.45	0.092
42.89	77.59	0.092
42.91	77.72	0.092
42.92	77.85	0.092
42.94	77.99	0.092
42.95	78.12	0.092
42.96	78.25	0.092
42.98	78.38	0.092
42.99	78.52	0.092
43.00	78.65	0.092
43.01	78.79	0.092
43.03	78.92	0.091
43.04	79.05	0.091
43.06	79.19	0.091
43.07	79.32	0.091
43.08	79.45	0.091
43.09	79.59	0.091
43.11	79.72	0.091
43.12	79.85	0.091
43.14	79.99	0.091
43.15	80.12	0.091
43.16	80.25	0.091
43.18	80.39	0.091
43.19	80.52	0.091
43.20	80.65	0.091
43.21	80.79	0.091
43.23	80.92	0.091
43.24	81.05	0.091
43.26	81.19	0.091
43.27	81.32	0.091
43.28	81.45	0.091
43.29	81.59	0.090
43.31	81.72	0.090
43.32	81.85	0.090
43.34	81.99	0.090
43.35	82.12	0.090
43.36	82.25	0.090
43.38	82.39	0.090
43.39	82.52	0.090
43.40	82.65	0.090
43.41	82.79	0.090
43.43	82.92	0.090
43.44	83.05	0.090
43.46	83.19	0.090
43.47	83.32	0.090
43.48	83.46	0.089
43.49	83.59	0.089
43.51	83.72	0.089
43.52	83.86	0.089
43.54	83.99	0.089
43.55	84.12	0.089
43.56	84.26	0.089
43.58	84.39	0.089
43.59	84.52	0.089
43.60	84.66	0.089
43.61	84.79	0.089
43.63	84.92	0.089
43.64	85.06	0.089
43.66	85.19	0.089
43.67	85.32	0.089
43.68	85.46	0.089
43.69	85.59	0.088
43.71	85.72	0.088
43.72	85.86	0.088
43.74	85.99	0.088
43.75	86.12	0.088
43.76	86.26	0.088
43.78	86.39	0.088
43.79	86.53	0.088
43.80	86.66	0.088
43.81	86.79	0.088
43.83	86.92	0.088
43.84	87.06	0.088
43.86	87.19	0.088
43.87	87.33	0.088
43.88	87.46	0.088
43.89	87.59	0.088
43.91	87.73	0.088
43.92	87.86	0.088
43.94	87.99	0.088
43.95	88.13	0.087
43.96	88.26	0.088
43.98	88.39	0.088
43.99	88.53	0.088
44.00	88.66	0.087
44.01	88.79	0.087
44.03	88.93	0.087
44.04	89.06	0.087
44.06	89.19	0.087
44.07	89.33	0.088
44.08	89.46	0.088
44.09	89.59	0.087
44.11	89.73	0.088
44.12	89.86	0.088
44.14	89.99	0.087
44.15	90.13	0.088
44.16	90.26	0.087
44.18	90.39	0.087
44.19	90.53	0.087
44.20	90.66	0.087
44.21	90.79	0.087
44.23	90.93	0.087
44.24	91.06	0.087
44.26	91.19	0.087
44.27	91.33	0.087
44.28	91.46	0.087
44.29	91.59	0.087
44.31	91.73	0.088
44.32	91.86	0.088
44.34	91.99	0.088
44.35	92.13	0.088
44.36	92.26	0.088
44.38	92.40	0.087
44.39	92.53	0.087
44.40	92.66	0.087
44.41	92.80	0.087
44.43	92.93	0.087
44.44	93.06	0.087
44.46	93.20	0.087
44.47	93.33	0.087
44.48	93.46	0.087
44.49	93.60	0.087
44.51	93.73	0.087
44.52	93.86	0.087
44.54	94.00	0.087
44.55	94.13	0.087
44.56	94.26	0.087
44.58	94.40	0.087
44.59	94.53	0.087
44.60	94.66	0.087
44.61	94.80	0.087
44.63	94.93	0.087
44.64	95.06	0.087
44.66	95.20	0.087
44.67	95.33	0.087
44.68	95.46	0.087
44.69	95.60	0.087
44.71	95.73	0.087
44.72	95.86	0.087
44.74	96.00	0.087
44.75	96.13	0.087
44.76	96.27	0.087
44.78	96.40	0.087
44.79	96.53	0.087
44.80	96.67	0.087
44.81	96.80	0.087
44.83	96.93	0.087
44.84	97.06	0.087
44.86	97.20	0.087
44.87	97.33	0.087
44.88	97.46	0.087
44.89	97.60	0.087
44.91	97.73	0.087
44.92	97.87	0.087
44.94	98.00	0.087
44.95	98.13	0.087
44.96	98.27	0.087
44.98	98.40	0.087
44.99	98.53	0.087
45.00	98.67	0.087
45.01	98.80	0.087
45.03	98.93	0.087
45.04	99.07	0.087
45.06	99.20	0.087
45.07	99.33	0.087
45.08	99.47	0.087
45.09	99.60	0.087
45.11	99.73	0.087
45.12	99.87	0.087
45.14	100.00	0.087
45.15	100.13	0.087
45.16	100.27	0.087
45.18	100.40	0.087
45.19	100.54	0.087
45.20	100.67	0.087
45.21	100.80	0.087
45.23	100.94	0.087
45.24	101.07	0.087
45.26	101.20	0.087
45.27	101.34	0.087
45.28	101.47	0.087
45.29	101.60	0.087
45.31	101.74	0.087
45.32	101.87	0.087
45.34	102.00	0.087
45.35	102.14	0.087
45.36	102.27	0.087
45.38	102.40	0.087
45.39	102.54	0.087
45.40	102.67	0.087
45.41	102.80	0.087
45.43	102.94	0.087
45.44	103.07	0.087
45.46	103.20	0.087
45.47	103.34	0.086
45.48	103.47	0.087
45.49	103.60	0.087
45.51	103.74	0.087
45.52	103.87	0.086
45.54	104.00	0.086
45.55	104.14	0.086
45.56	104.27	0.086
45.58	104.40	0.087
45.59	104.54	0.087
45.60	104.67	0.086
45.61	104.80	0.086
45.63	104.94	0.086
45.64	105.07	0.086
45.66	105.20	0.086
45.67	105.34	0.086
45.68	105.47	0.086
45.69	105.61	0.086
45.71	105.74	0.086
45.72	105.87	0.086
45.74	106.01	0.086
45.75	106.14	0.086
45.76	106.27	0.086
45.78	106.41	0.086
45.79	106.54	0.086
45.80	106.67	0.086
45.81	106.80	0.086
45.83	106.94	0.086
45.84	107.07	0.086
45.86	107.21	0.086
45.87	107.34	0.086
45.88	107.47	0.086
45.89	107.61	0.086
45.91	107.74	0.086
45.92	107.87	0.086
45.94	108.01	0.086
45.95	108.14	0.086
45.96	108.27	0.086
45.98	108.41	0.086
45.99	108.54	0.086
46.00	108.67	0.086
46.01	108.81	0.086
46.03	108.94	0.086
46.04	109.07	0.086
46.06	109.21	0.086
46.07	109.34	0.086
46.08	109.47	0.086
46.09	109.61	0.086
46.11	109.74	0.086
46.12	109.87	0.086
46.14	110.01	0.086
46.15	110.14	0.086
46.16	110.27	0.086
46.18	110.41	0.086
46.19	110.54	0.086
46.20	110.67	0.086
46.21	110.81	0.086
46.23	110.94	0.086
46.24	111.07	0.086
46.26	111.21	0.086
46.27	111.34	0.085
46.28	111.48	0.085
46.29	111.61	0.085
46.31	111.74	0.085
46.32	111.88	0.085
46.34	112.01	0.085
46.35	112.14	0.085
46.36	112.28	0.085
46.38	112.41	0.085
46.39	112.54	0.085
46.40	112.68	0.085
46.41	112.81	0.085
46.43	112.94	0.085
46.44	113.08	0.085
46.46	113.21	0.085
46.47	113.34	0.085
46.48	113.48	0.085
46.49	113.61	0.085
46.51	113.74	0.085
46.52	113.88	0.085
46.54	114.01	0.085
46.55	114.14	0.085
46.56	114.28	0.085
46.58	114.41	0.085
46.59	114.54	0.085
46.60	114.68	0.085
46.61	114.81	0.085
46.63	114.94	0.085
46.64	115.08	0.085
46.66	115.21	0.085
46.67	115.34	0.085
46.68	115.48	0.085
46.69	115.61	0.085
46.71	115.74	0.085
46.72	115.88	0.085
46.74	116.01	0.085
46.75	116.14	0.085
46.76	116.28	0.085
46.78	116.41	0.085
46.79	116.54	0.085
46.80	116.68	0.085
46.81	116.81	0.085
46.83	116.94	0.085
46.84	117.08	0.085
46.86	117.21	0.085
46.87	117.34	0.085
46.88	117.48	0.085
46.89	117.61	0.085
46.91	117.74	0.085
46.92	117.88	0.085
46.94	118.01	0.085
46.95	118.14	0.085
46.96	118.28	0.085
46.98	118.41	0.085
46.99	118.55	0.085
47.00	118.68	0.084
47.01	118.81	0.084
47.03	118.95	0.084
47.04	119.08	0.084
47.06	119.21	0.085
47.07	119.35	0.085
47.08	119.48	0.085
47.09	119.61	0.085
47.11	119.75	0.085
47.12	119.88	0.084
47.14	120.01	0.084
47.15	120.15	0.084
47.16	120.28	0.084
47.18	120.41	0.084
47.19	120.55	0.084
47.20	120.68	0.084
47.21	120.81	0.084
47.23	120.95	0.084
47.24	121.08	0.084
47.26	121.21	0.084
47.27	121.35	0.084
47.28	121.48	0.084
47.29	121.62	0.084
47.31	121.75	0.084
47.32	121.88	0.084
47.34	122.01	0.084
47.35	122.15	0.084
47.36	122.28	0.084
47.38	122.41	0.084
47.39	122.55	0.084
47.40	122.68	0.084
47.41	122.82	0.084
47.43	122.95	0.084
47.44	123.08	0.084
47.46	123.22	0.084
47.47	123.35	0.084
47.48	123.48	0.084
47.49	123.61	0.084
47.51	123.75	0.084
47.52	123.88	0.084
47.54	124.02	0.084
47.55	124.15	0.084
47.56	124.28	0.084
47.58	124.42	0.084
47.59	124.55	0.083
47.60	124.68	0.083
47.61	124.82	0.083
47.63	124.95	0.083
47.64	125.08	0.083
47.66	125.22	0.083
47.67	125.35	0.083
47.68	125.48	0.083
47.69	125.62	0.083
47.71	125.75	0.083
47.72	125.88	0.083
47.74	126.02	0.083
47.75	126.15	0.083
47.76	126.28	0.083
47.78	126.42	0.083
47.79	126.55	0.083
47.80	126.68	0.083
47.81	126.82	0.083
47.83	126.95	0.083
47.84	127.08	0.083
47.86	127.22	0.083
47.87	127.35	0.083
47.88	127.48	0.083
47.89	127.62	0.083
47.91	127.75	0.083
47.92	127.89	0.083
47.94	128.02	0.083
47.95	128.15	0.083
47.96	128.29	0.083
47.98	128.42	0.083
47.99	128.55	0.083
48.00	128.69	0.083
48.01	128.82	0.083
48.03	128.95	0.083
48.04	129.08	0.082
48.06	129.22	0.082
48.07	129.35	0.082
48.08	129.48	0.082
48.09	129.62	0.082
48.11	129.75	0.082
48.12	129.89	0.082
48.14	130.02	0.082
48.15	130.15	0.082
48.16	130.29	0.082
48.18	130.42	0.082
48.19	130.55	0.082
48.20	130.69	0.082
48.21	130.82	0.082
48.23	130.95	0.082
48.24	131.09	0.082
48.26	131.22	0.082
48.27	131.35	0.082
48.28	131.49	0.082
48.29	131.62	0.082
48.31	131.75	0.081
48.32	131.89	0.081
48.34	132.02	0.081
48.35	132.16	0.081
48.36	132.29	0.081
48.38	132.42	0.081
48.39	132.55	0.081
48.40	132.69	0.081
48.41	132.82	0.081
48.43	132.95	0.081
48.44	133.09	0.081
48.46	133.22	0.081
48.47	133.35	0.081
48.48	133.49	0.081
48.49	133.62	0.081
48.51	133.76	0.081
48.52	133.89	0.081
48.54	134.02	0.081
48.55	134.16	0.081
48.56	134.29	0.081
48.58	134.42	0.081
48.59	134.56	0.081
48.60	134.69	0.081
48.61	134.82	0.081
48.63	134.96	0.081
48.64	135.09	0.081
48.66	135.22	0.081
48.67	135.36	0.080
48.68	135.49	0.080
48.69	135.62	0.080
48.71	135.76	0.080
48.72	135.89	0.080
48.74	136.02	0.080
48.75	136.16	0.080
48.76	136.29	0.080
48.78	136.42	0.080
48.79	136.56	0.080
48.80	136.69	0.080
48.81	136.82	0.080
48.83	136.96	0.080
48.84	137.09	0.080
48.86	137.22	0.080
48.87	137.36	0.080
48.88	137.49	0.080
48.89	137.62	0.080
48.91	137.76	0.080
48.92	137.89	0.080
48.94	138.02	0.080
48.95	138.16	0.080
48.96	138.29	0.080
48.98	138.42	0.080
48.99	138.56	0.080
49.00	138.69	0.080
49.01	138.82	0.080
49.03	138.96	0.080
49.04	139.09	0.080
49.06	139.22	0.080
49.07	139.36	0.080
49.08	139.49	0.079
49.09	139.62	0.079
49.11	139.76	0.079
49.12	139.89	0.079
49.14	140.02	0.079
49.15	140.16	0.079
49.16	140.29	0.079
49.18	140.43	0.079
49.19	140.56	0.079
49.20	140.69	0.079
49.21	140.83	0.079
49.23	140.96	0.079
49.24	141.09	0.079
49.26	141.23	0.079
49.27	141.36	0.079
49.28	141.49	0.079
49.29	141.63	0.079
49.31	141.76	0.079
49.32	141.89	0.079
49.34	142.03	0.079
49.35	142.16	0.079
49.36	142.29	0.079
49.38	142.43	0.079
49.39	142.56	0.079
49.40	142.69	0.079
49.41	142.83	0.079
49.43	142.96	0.079
49.44	143.09	0.079
49.46	143.23	0.079
49.47	143.36	0.079
49.48	143.49	0.079
49.49	143.63	0.078
49.51	143.76	0.078
49.52	143.89	0.078
49.54	144.03	0.078
49.55	144.16	0.078
49.56	144.29	0.078
49.58	144.43	0.078
49.59	144.56	0.078
49.60	144.69	0.078
49.61	144.83	0.078
49.63	144.96	0.078
49.64	145.09	0.078
49.66	145.23	0.078
49.67	145.36	0.078
49.68	145.50	0.078
49.69	145.63	0.078
49.71	145.76	0.078
49.72	145.89	0.078
49.74	146.03	0.078
49.75	146.16	0.078
49.76	146.30	0.078
49.78	146.43	0.078
49.79	146.56	0.078
49.80	146.70	0.078
49.81	146.83	0.078
49.83	146.96	0.078
49.84	147.10	0.077
49.86	147.23	0.077
49.87	147.36	0.077
49.88	147.50	0.077
49.89	147.63	0.077
49.91	147.76	0.077
49.92	147.90	0.077
49.94	148.03	0.077
49.95	148.16	0.077
49.96	148.30	0.077
49.98	148.43	0.077
49.99	148.56	0.077
50.00	148.70	0.077
50.01	148.83	0.077
50.03	148.96	0.077
50.04	149.10	0.077
50.06	149.23	0.077
50.07	149.36	0.077
50.08	149.50	0.077
50.09	149.63	0.077
50.11	149.76	0.077
50.12	149.90	0.077
50.14	150.03	0.077
50.15	150.16	0.077
50.16	150.30	0.077
50.18	150.43	0.077
50.19	150.56	0.077
50.20	150.70	0.077
50.21	150.83	0.077
50.23	150.96	0.077
50.24	151.10	0.077
50.26	151.23	0.077
50.27	151.36	0.076
50.28	151.50	0.076
50.29	151.63	0.076
50.31	151.76	0.076
50.32	151.90	0.076
50.34	152.03	0.076
50.35	152.17	0.076
50.36	152.30	0.076
50.38	152.43	0.076
50.39	152.57	0.076
50.40	152.70	0.076
50.41	152.83	0.076
50.43	152.97	0.076
50.44	153.10	0.076
50.46	153.23	0.076
50.47	153.37	0.076
50.48	153.50	0.076
50.49	153.63	0.076
50.51	153.77	0.076
50.52	153.90	0.076
50.54	154.03	0.076
50.55	154.17	0.076
50.56	154.30	0.076
50.58	154.43	0.076
50.59	154.57	0.076
50.60	154.70	0.076
50.61	154.83	0.076
50.63	154.97	0.076
50.64	155.10	0.076
50.66	155.23	0.076
50.67	155.37	0.076
50.68	155.50	0.076
50.69	155.63	0.076
50.71	155.77	0.076
50.72	155.90	0.076
50.74	156.03	0.076
50.75	156.17	0.076
50.76	156.30	0.076
50.78	156.43	0.076
50.79	156.57	0.076
50.80	156.70	0.084
50.81	156.83	0.163
50.83	156.96	0.340
50.84	157.08	0.574
50.86	157.20	0.809
50.87	157.32	1.032
50.88	157.43	1.252
50.89	157.54	1.470
50.91	157.65	1.692
50.92	157.76	1.916
50.94	157.86	2.137
50.95	157.97	2.358
50.96	158.07	2.576
50.98	158.18	2.786
50.99	158.29	2.993
51.00	158.39	3.185
51.01	158.50	3.203
51.03	158.63	2.344
51.04	158.80	1.135
51.06	158.98	0.829
51.07	159.15	0.682
51.08	159.32	0.582
51.09	159.48	0.506
51.11	159.64	0.437
51.12	159.79	0.382
51.14	159.94	0.335
51.15	160.09	0.296
51.16	160.23	0.263
51.18	160.38	0.231
51.19	160.52	0.208
51.20	160.66	0.186
51.21	160.80	0.170
51.23	160.94	0.155
51.24	161.08	0.142
51.26	161.21	0.132
51.27	161.35	0.122
51.28	161.49	0.116
51.29	161.62	0.108
51.31	161.76	0.103
51.32	161.89	0.101
51.34	162.03	0.098
51.35	162.16	0.095
51.36	162.30	0.092
51.38	162.43	0.089
51.39	162.56	0.088
51.40	162.70	0.086
51.41	162.83	0.085
51.43	162.97	0.083
51.44	163.10	0.082
51.46	163.23	0.081
51.47	163.37	0.080
51.48	163.50	0.080
51.49	163.64	0.080
51.51	163.77	0.079
51.52	163.90	0.079
51.54	164.04	0.079
51.55	164.17	0.079
51.56	164.30	0.078
51.58	164.44	0.078
51.59	164.57	0.078
51.60	164.70	0.077
51.61	164.84	0.077
51.63	164.97	0.077
51.64	165.10	0.077
51.66	165.24	0.077
51.67	165.37	0.076
51.68	165.50	0.076
51.69	165.64	0.076
51.71	165.77	0.076
51.72	165.90	0.075
51.74	166.04	0.075
51.75	166.17	0.075
51.76	166.31	0.075
51.78	166.44	0.075
51.79	166.57	0.074
51.80	166.71	0.074
51.81	166.84	0.074
51.83	166.97	0.074
51.84	167.11	0.074
51.86	167.24	0.074
51.87	167.37	0.074
51.88	167.51	0.074
51.89	167.64	0.074
51.91	167.77	0.073
51.92	167.91	0.073
51.94	168.04	0.073
51.95	168.17	0.073
51.96	168.31	0.073
51.98	168.44	0.073
51.99	168.57	0.073
52.00	168.71	0.073
52.01	168.84	0.073
52.03	168.97	0.073
52.04	169.11	0.072
52.06	169.24	0.072
52.07	169.37	0.072
52.08	169.51	0.072
52.09	169.64	0.072
52.11	169.77	0.072
52.12	169.91	0.072
52.14	170.04	0.072
52.15	170.17	0.072
52.16	170.31	0.072
52.18	170.44	0.072
52.19	170.57	0.072
52.20	170.71	0.072
52.21	170.84	0.072
52.23	170.97	0.072
52.24	171.11	0.072
52.26	171.24	0.072
52.27	171.37	0.072
52.28	171.51	0.071
52.29	171.64	0.071
52.31	171.77	0.071
52.32	171.91	0.071
52.34	172.04	0.071
52.35	172.18	0.071
52.36	172.31	0.071
52.38	172.44	0.071
52.39	172.57	0.071
52.40	172.71	0.071
52.41	172.84	0.071
52.43	172.98	0.071
52.44	173.11	0.071
52.46	173.24	0.071
52.47	173.37	0.071
52.48	173.51	0.071
52.49	173.64	0.071
52.51	173.78	0.071
52.52	173.91	0.071
52.54	174.04	0.071
52.55	174.18	0.071
52.56	174.31	0.071
52.58	174.44	0.071
52.59	174.58	0.071
52.60	174.71	0.071
52.61	174.84	0.071
52.63	174.98	0.071
52.64	175.11	0.071
52.66	175.24	0.071
52.67	175.38	0.070
52.68	175.51	0.070
52.69	175.64	0.070
52.71	175.78	0.070
52.72	175.91	0.070
52.74	176.04	0.070
52.75	176.18	0.070
52.76	176.31	0.070
52.78	176.44	0.070
52.79	176.58	0.070
52.80	176.71	0.070
52.81	176.84	0.070
52.83	176.98	0.070
52.84	177.11	0.070
52.86	177.24	0.070
52.87	177.38	0.070
52.88	177.51	0.070
52.89	177.64	0.070
52.91	177.78	0.070
52.92	177.91	0.070
52.94	178.04	0.070
52.95	178.18	0.070
52.96	178.31	0.069
52.98	178.44	0.069
52.99	178.58	0.069
53.00	178.71	0.069
53.01	178.84	0.069
53.03	178.98	0.069
53.04	179.11	0.069
53.06	179.24	0.069
53.07	179.38	0.069
53.08	179.51	0.069
53.09	179.64	0.069
53.11	179.78	0.069
53.12	179.91	0.069
53.14	180.04	0.069
53.15	180.18	0.069
53.16	180.31	0.069
53.18	180.45	0.069
53.19	180.58	0.069
53.20	180.71	0.069
53.21	180.85	0.069
53.23	180.98	0.069
53.24	181.11	0.068
53.26	181.25	0.068
53.27	181.38	0.068
53.28	181.51	0.068
53.29	181.65	0.068
53.31	181.78	0.068
53.32	181.91	0.068
53.34	182.05	0.068
53.35	182.18	0.068
53.36	182.31	0.068
53.38	182.45	0.068
53.39	182.58	0.068
53.40	182.71	0.068
53.41	182.85	0.068
53.43	182.98	0.068
53.44	183.11	0.068
53.46	183.25	0.068
53.47	183.38	0.068
53.48	183.51	0.068
53.49	183.65	0.068
53.51	183.78	0.068
53.52	183.91	0.068
53.54	184.05	0.068
53.55	184.18	0.068
53.56	184.31	0.068
53.58	184.45	0.068
53.59	184.58	0.068
53.60	184.71	0.068
53.61	184.85	0.068
53.63	184.98	0.068
53.64	185.11	0.068
53.66	185.25	0.068
53.67	185.38	0.068
53.68	185.51	0.068
53.69	185.65	0.068
53.71	185.78	0.068
53.72	185.91	0.068
53.74	186.05	0.068
53.75	186.18	0.068
53.76	186.31	0.068
53.78	186.45	0.067
53.79	186.58	0.067
53.80	186.71	0.067
53.81	186.85	0.067
53.83	186.98	0.067
53.84	187.11	0.067
53.86	187.25	0.067
53.87	187.38	0.067
53.88	187.51	0.067
53.89	187.65	0.067
53.91	187.78	0.067
53.92	187.91	0.067
53.94	188.05	0.067
53.95	188.18	0.067
53.96	188.31	0.067
53.98	188.45	0.067
53.99	188.58	0.067
54.00	188.72	0.067
54.01	188.85	0.067
54.03	188.98	0.067
54.04	189.12	0.067
54.06	189.25	0.067
54.07	189.38	0.067
54.08	189.52	0.067
54.09	189.65	0.067
54.11	189.78	0.067
54.12	189.92	0.067
54.14	190.05	0.067
54.15	190.18	0.067
54.16	190.32	0.067
54.18	190.45	0.067
54.19	190.58	0.067
54.20	190.71	0.067
54.21	190.85	0.067
54.23	190.98	0.066
54.24	191.12	0.066
54.26	191.25	0.066
54.27	191.38	0.066
54.28	191.52	0.066
54.29	191.65	0.066
54.31	191.78	0.066
54.32	191.92	0.066
54.34	192.05	0.066
54.35	192.18	0.066
54.36	192.32	0.066
54.38	192.45	0.066
54.39	192.58	0.066
54.40	192.72	0.066
54.41	192.85	0.066
54.43	192.98	0.066
54.44	193.12	0.066
54.46	193.25	0.066
54.47	193.38	0.066
54.48	193.52	0.066
54.49	193.65	0.066
54.51	193.78	0.065
54.52	193.92	0.065
54.54	194.05	0.065
54.55	194.18	0.065
54.56	194.32	0.065
54.58	194.45	0.065
54.59	194.58	0.065
54.60	194.72	0.065
54.61	194.85	0.065
54.63	194.98	0.065
54.64	195.12	0.065
54.66	195.25	0.065
54.67	195.38	0.065
54.68	195.52	0.065
54.69	195.65	0.065
54.71	195.79	0.065
54.72	195.92	0.065
54.74	196.05	0.065
54.75	196.19	0.065
54.76	196.32	0.065
54.78	196.45	0.065
54.79	196.58	0.065
54.80	196.72	0.065
54.81	196.85	0.065
54.83	196.98	0.065
54.84	197.12	0.065
54.86	197.25	0.065
54.87	197.38	0.064
54.88	197.52	0.064
54.89	197.65	0.064
54.91	197.78	0.064
54.92	197.92	0.064
54.94	198.05	0.064
54.95	198.18	0.064
54.96	198.32	0.064
54.98	198.45	0.064
54.99	198.58	0.064
55.00	198.72	0.064
55.01	198.85	0.064
55.03	198.99	0.064
55.04	199.12	0.064
55.06	199.25	0.064
55.07	199.39	0.064
55.08	199.52	0.064
55.09	199.65	0.064
55.11	199.79	0.064
55.12	199.92	0.064
55.14	200.05	0.064
55.15	200.19	0.064
55.16	200.32	0.063
55.18	200.45	0.063
55.19	200.59	0.063
55.20	200.72	0.063
55.21	200.85	0.063
55.23	200.99	0.063
55.24	201.12	0.063
55.26	201.25	0.063
55.27	201.39	0.063
55.28	201.52	0.063
55.29	201.65	0.063
55.31	201.79	0.063
55.32	201.92	0.063
55.34	202.05	0.063
55.35	202.19	0.063
55.36	202.32	0.063
55.38	202.45	0.063
55.39	202.59	0.063
55.40	202.72	0.063
55.41	202.85	0.063
55.43	202.99	0.063
55.44	203.12	0.063
55.46	203.25	0.063
55.47	203.39	0.063
55.48	203.52	0.063
55.49	203.65	0.063
55.51	203.79	0.063
55.52	203.92	0.063
55.54	204.05	0.063
55.55	204.19	0.063
55.56	204.32	0.063
55.58	204.45	0.063
55.59	204.59	0.063
55.60	204.72	0.063
55.61	204.85	0.063
55.63	204.99	0.062
55.64	205.12	0.062
55.66	205.25	0.062
55.67	205.39	0.062
55.68	205.52	0.062
55.69	205.65	0.062
55.71	205.79	0.062
55.72	205.92	0.062
55.74	206.05	0.062
55.75	206.19	0.062
55.76	206.32	0.062
55.78	206.45	0.062
55.79	206.59	0.062
55.80	206.72	0.062
55.81	206.85	0.062
55.83	206.99	0.062
55.84	207.12	0.062
55.86	207.26	0.062
55.87	207.39	0.062
55.88	207.52	0.062
55.89	207.65	0.062
55.91	207.79	0.062
55.92	207.92	0.062
55.94	208.05	0.062
55.95	208.19
55.96	208.32
55.98	208.46
55.99	208.59
56.00