File: Data/2024_09_17_H2O_CHM343_DSC.txt
Filename	2024_09_17_H2O_CHM343_DSC
Instrument name	DSC2A-00468 (192.168.1.100)
Operator	CHM343
rundate	9/17/2024
Sample name	2024_09_17_H2O_CHM343_DSC
proceduresegments	Equilibrate -40.00 °C; Ramp 10.00 °C/min to 40.00 °C; Isothermal 1.0 min; Ramp 10.00 °C/min to -40.00 °C; Isothermal 1.0 min; Ramp 10.00 °C/min to 40.00 °C
[File Parameters]
Run date	9/17/2024 8:12:35 PM
Trios version	5.1.1.46572
Original File Name	C:\ProgramData\TA Instruments\TRIOS\Data\2024_09_17_H2O_CHM343_DSC.tri
Current File Name	D:\DSC2500\CHM343\2024_09_17_H2O_CHM343_DSC.tri
[Procedure]
Procedure Name	CHM343_Fall2024_Water
Sample Name	2024_09_17_H2O_CHM343_DSC
Sample Mass	3.47 mg
Reference Sample Mass	0 mg
Pan Mass	54.2 mg
Pan Number	26
Reference Pan Mass	54 mg
Reference Pan Number	19
Pan Type	Aluminum
Comments	Water - H2O - Al Hermetic Sealed Pan, with ref Al pan.
Project Name	Lab 4 - Fall 2024
Operator	CHM343
Test	Custom
Unload Max Temperature	30
Unload Min Temperature	30
Load Max Temperature	30
Load Min Temperature	30
Stop on Gas Flow Error	Yes
[Signal List]
Signal #1	Time (min)
Signal #2	Temperature (°C)
Signal #3	Heat Flow (mW)
Signal #4	Delta T (µV)
Signal #5	Delta Tzero (µV)
Signal #6	Tzero Temperature (°C)
Signal #7	Cell Purge (mL/min)
Signal #8	Heater Temp (°C)
Signal #9	Power Delivered (W)
Signal #10	Reference Junction Temperature (°C)
Signal #11	Flange Temperature (°C)
Signal #12	Heat Flow Phase (rad)
Signal #13	Total Heat Capacity (J/°C)
Signal #14	Heat Capacity (J/°C)
[Configuration]
Company Name	ASU
Instrument Name	DSC2A-00468
Instrument Type	DSC2500
Serial Number	DSC2A-00468
IP	192.168.1.100
Location of Instrument	MRRC
DisplayType	Unknown
Sample Interval 	0.1 s/pt
Selected Heat Flow	T4P
Exotherm Direction	Down
Cell Serial	DRC2-00792
Lid Type	Standard
Cooler	RCS 90
Leave Cooler on at End of Sequence	On
Gas 2	Nitrogen
Gas Selected	Channel 1
Flow Rate	50 mL/min
Secondary Purge	On
Licensed Heat Flow	Heat Flow T4P
Modulation Licensed	Yes
[Versions]
Common IDD Version	1
Cortex Version	VER 2.10.2.31
Driver	5.0.0.6
GDM Version	1.0.3.3
TouchscreenVersion	1.0.0.16145
FEP Version	1.2.1.21
FEP Bootloader	2.0.0.5
AutoSampler Version	2.1.1.26
Auto Sampler Bootloader	2.0.0.5
FCM Version	1.1.0.3
FCM Bootloader	2.0.0.5
[Experiment Logs]
Experiment Log Entry # 1	Equilibrate Segment -40 (C) Started
Experiment Log Entry # 3	Air Cool is off.
Experiment Log Entry # 5	Ramp Segment 10 C/min to 40 Started
Experiment Log Entry # 7	Isothermal Segment 1 min started
Experiment Log Entry # 9	Ramp Segment 10 C/min to -40 Started
Experiment Log Entry # 11	Isothermal Segment 1 min started
Experiment Log Entry # 13	Ramp Segment 10 C/min to 40 Started
[Method Log]
Method Log Entry # 1	Equilibrate -40 °C
Method Log Entry # 2	(Ramp 59597) Ramp 10 °C/minute to 40 °C
Method Log Entry # 3	Isothermal 1 minutes
Method Log Entry # 4	(Ramp 59599) Ramp 10 °C/minute to -40 °C
Method Log Entry # 5	Isothermal 1 minutes
Method Log Entry # 6	(Ramp 59601) Ramp 10 °C/minute to 40 °C
Cell Serial	DRC2-00792
[T1 Calibration]
Slope	-0.008529666
Offset	9.636258
Initial Temperature	98.23
GUID	f8bfdadc-4977-4fdf-ba6d-0ba9134940c3
[TZero Calibration]
Date Applied	11/29/2022 4:06:13 PM
Description	From -89.059 °C to 396.009 °C at 20.000°C/min
Gas Type	Nitrogen
Pan Type	None
Source Files 1	C:\Users\yargerlab\Desktop\DSC Data\General\TZero_calibration_11_29_22_2nd(2).tri
Source Files 2	C:\Users\yargerlab\Desktop\DSC Data\General\TZero_calibration_11_29_22_2nd(3).tri
Delta T Offset	13.05235
Delta T Slope	-0.007271007
Delta T0 Offset	-13.69128
Delta T0 Slope	0.06063341
[Temperature Calibration]
Date Applied	11/29/2022 7:12:28 PM
Description	From 106.590 °C to 186.590 °C at 10.000°C/min
Gas Type	Nitrogen
Pan Type	Tzero Aluminum Hermetic
Source Files 1	C:\Users\yargerlab\Desktop\DSC Data\General\Indium(6).tri
Measured 1	157.391
Known 1	156.598
[Cell Constant Calibration]
Date Applied	11/29/2022 7:12:29 PM
Description	From 106.590 °C to 186.590 °C at 10.000°C/min
Gas Type	Nitrogen
Pan Type	Tzero Aluminum Hermetic
Source Files 1	C:\Users\yargerlab\Desktop\DSC Data\General\Indium(6).tri
T4P KCell	1.006051
Onset Slope	63.26126 mW/°C
[Direct Cp Calibration]
Date Applied	11/30/2022 11:04:51 AM
Description	From -79.983 °C to 298.409 °C at 10.000°C/min
Gas Type	Nitrogen
Pan Type	Tzero Aluminum Hermetic
Source Files 1	C:\Users\yargerlab\Desktop\DSC Data\General\Sapphire_Heat_Capacity_11_30_22.tri
[Rev Cp Calibration]
Date Applied	11/30/2022 1:58:51 PM
Description	From -79.996 °C to 292.812 °C at 3.000°C/min
Gas Type	Nitrogen
Pan Type	Tzero Aluminum Hermetic
Source Files 1	C:\Users\yargerlab\Desktop\DSC Data\General\Sapphire_MDSC_Calibration_11_30_22.tri
[step]
Ramp 10.00 °C/min to 40.00 °C
Time	Temperature	Heat Flow (Normalized)
min	°C	W/g
0.00	-39.70	-0.129
0.01	-39.71	-0.134
0.01	-39.71	-0.128
0.02	-39.72	-0.122
0.03	-39.72	-0.117
0.03	-39.72	-0.113
0.04	-39.73	-0.109
0.05	-39.73	-0.106
0.05	-39.73	-0.104
0.06	-39.73	-0.104
0.07	-39.72	-0.105
0.07	-39.71	-0.107
0.08	-39.71	-0.110
0.09	-39.70	-0.112
0.09	-39.68	-0.116
0.10	-39.66	-0.122
0.11	-39.65	-0.127
0.11	-39.62	-0.132
0.12	-39.60	-0.134
0.13	-39.57	-0.135
0.13	-39.54	-0.135
0.14	-39.51	-0.135
0.15	-39.47	-0.135
0.15	-39.43	-0.126
0.16	-39.39	-0.110
0.17	-39.35	-0.093
0.17	-39.31	-0.079
0.18	-39.26	-0.064
0.19	-39.22	-0.049
0.19	-39.17	-0.035
0.20	-39.12	-0.019
0.21	-39.08	-0.002
0.21	-39.03	0.013
0.22	-38.98	0.030
0.23	-38.92	0.046
0.23	-38.87	0.059
0.24	-38.82	0.071
0.25	-38.77	0.084
0.25	-38.71	0.098
0.26	-38.66	0.108
0.27	-38.60	0.118
0.27	-38.55	0.129
0.28	-38.49	0.139
0.29	-38.44	0.149
0.29	-38.38	0.157
0.30	-38.32	0.163
0.31	-38.27	0.173
0.31	-38.21	0.182
0.32	-38.15	0.187
0.33	-38.09	0.194
0.33	-38.03	0.200
0.34	-37.97	0.206
0.35	-37.91	0.213
0.35	-37.85	0.218
0.36	-37.79	0.223
0.37	-37.73	0.227
0.37	-37.67	0.232
0.38	-37.61	0.237
0.39	-37.55	0.241
0.39	-37.49	0.245
0.40	-37.42	0.252
0.41	-37.36	0.255
0.41	-37.30	0.258
0.42	-37.24	0.260
0.43	-37.18	0.263
0.43	-37.11	0.269
0.44	-37.05	0.272
0.45	-36.99	0.273
0.45	-36.93	0.275
0.46	-36.86	0.278
0.47	-36.80	0.280
0.47	-36.73	0.284
0.48	-36.67	0.285
0.49	-36.61	0.286
0.49	-36.54	0.287
0.50	-36.48	0.291
0.51	-36.42	0.293
0.51	-36.35	0.294
0.52	-36.29	0.295
0.53	-36.23	0.296
0.53	-36.16	0.298
0.54	-36.10	0.300
0.55	-36.03	0.301
0.55	-35.97	0.302
0.56	-35.91	0.302
0.57	-35.84	0.303
0.57	-35.78	0.305
0.58	-35.71	0.306
0.59	-35.65	0.306
0.59	-35.58	0.307
0.60	-35.52	0.307
0.61	-35.46	0.308
0.61	-35.39	0.309
0.62	-35.32	0.311
0.63	-35.26	0.311
0.63	-35.20	0.311
0.64	-35.13	0.312
0.65	-35.07	0.312
0.65	-35.00	0.313
0.66	-34.94	0.313
0.67	-34.87	0.315
0.67	-34.81	0.317
0.68	-34.74	0.317
0.69	-34.68	0.318
0.69	-34.61	0.318
0.70	-34.54	0.318
0.71	-34.48	0.319
0.71	-34.41	0.319
0.72	-34.35	0.319
0.73	-34.28	0.320
0.73	-34.22	0.320
0.74	-34.15	0.320
0.75	-34.09	0.320
0.75	-34.02	0.320
0.76	-33.96	0.321
0.77	-33.89	0.321
0.77	-33.83	0.321
0.78	-33.76	0.321
0.79	-33.70	0.321
0.79	-33.63	0.321
0.80	-33.57	0.322
0.81	-33.50	0.322
0.81	-33.43	0.322
0.82	-33.37	0.322
0.83	-33.30	0.323
0.83	-33.24	0.323
0.84	-33.17	0.323
0.85	-33.11	0.323
0.85	-33.04	0.323
0.86	-32.97	0.324
0.87	-32.91	0.324
0.87	-32.84	0.324
0.88	-32.78	0.324
0.89	-32.71	0.324
0.89	-32.65	0.325
0.90	-32.58	0.325
0.91	-32.51	0.325
0.91	-32.45	0.325
0.92	-32.38	0.325
0.93	-32.32	0.326
0.93	-32.25	0.326
0.94	-32.19	0.326
0.95	-32.12	0.326
0.95	-32.05	0.326
0.96	-31.99	0.326
0.97	-31.92	0.327
0.97	-31.86	0.327
0.98	-31.79	0.327
0.99	-31.72	0.327
0.99	-31.66	0.328
1.00	-31.59	0.328
1.01	-31.53	0.328
1.01	-31.46	0.328
1.02	-31.39	0.329
1.03	-31.33	0.329
1.03	-31.26	0.329
1.04	-31.20	0.329
1.05	-31.13	0.329
1.05	-31.06	0.330
1.06	-31.00	0.330
1.07	-30.93	0.330
1.07	-30.87	0.330
1.08	-30.80	0.330
1.09	-30.73	0.330
1.09	-30.67	0.331
1.10	-30.60	0.331
1.11	-30.54	0.331
1.11	-30.47	0.331
1.12	-30.40	0.331
1.13	-30.34	0.331
1.13	-30.27	0.332
1.14	-30.21	0.332
1.15	-30.14	0.332
1.15	-30.07	0.332
1.16	-30.01	0.332
1.17	-29.94	0.332
1.17	-29.87	0.333
1.18	-29.81	0.333
1.19	-29.74	0.333
1.19	-29.68	0.333
1.20	-29.61	0.333
1.21	-29.54	0.333
1.21	-29.48	0.333
1.22	-29.41	0.334
1.23	-29.34	0.334
1.23	-29.28	0.334
1.24	-29.21	0.334
1.25	-29.15	0.334
1.25	-29.08	0.334
1.26	-29.01	0.334
1.27	-28.95	0.335
1.27	-28.88	0.335
1.28	-28.81	0.335
1.29	-28.75	0.335
1.29	-28.68	0.335
1.30	-28.62	0.335
1.31	-28.55	0.335
1.31	-28.48	0.335
1.32	-28.42	0.336
1.33	-28.35	0.336
1.33	-28.28	0.336
1.34	-28.22	0.336
1.35	-28.15	0.336
1.35	-28.09	0.336
1.36	-28.02	0.336
1.37	-27.95	0.336
1.37	-27.89	0.337
1.38	-27.82	0.337
1.39	-27.75	0.337
1.39	-27.69	0.337
1.40	-27.62	0.337
1.41	-27.55	0.337
1.41	-27.49	0.337
1.42	-27.42	0.337
1.43	-27.35	0.337
1.43	-27.29	0.338
1.44	-27.22	0.338
1.45	-27.16	0.338
1.45	-27.09	0.338
1.46	-27.02	0.338
1.47	-26.95	0.338
1.47	-26.89	0.338
1.48	-26.82	0.338
1.49	-26.76	0.338
1.49	-26.69	0.339
1.50	-26.62	0.339
1.51	-26.56	0.339
1.51	-26.49	0.339
1.52	-26.42	0.339
1.53	-26.36	0.339
1.53	-26.29	0.339
1.54	-26.22	0.339
1.55	-26.16	0.340
1.55	-26.09	0.340
1.56	-26.02	0.340
1.57	-25.96	0.340
1.57	-25.89	0.340
1.58	-25.83	0.340
1.59	-25.76	0.340
1.59	-25.69	0.340
1.60	-25.63	0.340
1.61	-25.56	0.340
1.61	-25.49	0.340
1.62	-25.43	0.341
1.63	-25.36	0.341
1.63	-25.29	0.341
1.64	-25.23	0.341
1.65	-25.16	0.341
1.65	-25.09	0.341
1.66	-25.03	0.341
1.67	-24.96	0.341
1.67	-24.89	0.341
1.68	-24.83	0.341
1.69	-24.76	0.341
1.69	-24.69	0.341
1.70	-24.63	0.342
1.71	-24.56	0.342
1.71	-24.49	0.342
1.72	-24.43	0.342
1.73	-24.36	0.342
1.73	-24.30	0.342
1.74	-24.23	0.342
1.75	-24.16	0.342
1.75	-24.10	0.342
1.76	-24.03	0.342
1.77	-23.96	0.342
1.77	-23.90	0.343
1.78	-23.83	0.343
1.79	-23.76	0.343
1.79	-23.70	0.343
1.80	-23.63	0.343
1.81	-23.56	0.343
1.81	-23.50	0.343
1.82	-23.43	0.343
1.83	-23.36	0.343
1.83	-23.30	0.343
1.84	-23.23	0.343
1.85	-23.16	0.343
1.85	-23.10	0.344
1.86	-23.03	0.344
1.87	-22.96	0.344
1.87	-22.90	0.344
1.88	-22.83	0.344
1.89	-22.76	0.344
1.89	-22.70	0.344
1.90	-22.63	0.344
1.91	-22.56	0.344
1.91	-22.50	0.344
1.92	-22.43	0.344
1.93	-22.36	0.344
1.93	-22.30	0.344
1.94	-22.23	0.344
1.95	-22.16	0.345
1.95	-22.10	0.345
1.96	-22.03	0.345
1.97	-21.96	0.345
1.97	-21.90	0.345
1.98	-21.83	0.345
1.99	-21.77	0.345
1.99	-21.70	0.345
2.00	-21.63	0.345
2.01	-21.56	0.345
2.01	-21.50	0.345
2.02	-21.43	0.345
2.03	-21.36	0.345
2.03	-21.30	0.346
2.04	-21.23	0.346
2.05	-21.16	0.346
2.05	-21.10	0.346
2.06	-21.03	0.346
2.07	-20.96	0.346
2.07	-20.90	0.346
2.08	-20.83	0.346
2.09	-20.76	0.346
2.09	-20.70	0.346
2.10	-20.63	0.346
2.11	-20.57	0.346
2.11	-20.50	0.346
2.12	-20.43	0.347
2.13	-20.37	0.347
2.13	-20.30	0.347
2.14	-20.23	0.347
2.15	-20.17	0.347
2.15	-20.10	0.347
2.16	-20.03	0.347
2.17	-19.96	0.347
2.17	-19.90	0.347
2.18	-19.83	0.347
2.19	-19.76	0.347
2.19	-19.70	0.347
2.20	-19.63	0.347
2.21	-19.56	0.347
2.21	-19.50	0.347
2.22	-19.43	0.348
2.23	-19.36	0.348
2.23	-19.30	0.348
2.24	-19.23	0.348
2.25	-19.16	0.348
2.25	-19.10	0.348
2.26	-19.03	0.348
2.27	-18.96	0.348
2.27	-18.90	0.348
2.28	-18.83	0.348
2.29	-18.76	0.348
2.29	-18.70	0.348
2.30	-18.63	0.348
2.31	-18.56	0.348
2.31	-18.50	0.348
2.32	-18.43	0.349
2.33	-18.36	0.349
2.33	-18.30	0.349
2.34	-18.23	0.349
2.35	-18.16	0.349
2.35	-18.10	0.349
2.36	-18.03	0.349
2.37	-17.96	0.349
2.37	-17.90	0.349
2.38	-17.83	0.349
2.39	-17.77	0.349
2.39	-17.70	0.349
2.40	-17.63	0.349
2.41	-17.56	0.349
2.41	-17.50	0.349
2.42	-17.43	0.350
2.43	-17.36	0.350
2.43	-17.30	0.350
2.44	-17.23	0.350
2.45	-17.16	0.350
2.45	-17.10	0.350
2.46	-17.03	0.350
2.47	-16.96	0.350
2.47	-16.90	0.350
2.48	-16.83	0.350
2.49	-16.76	0.350
2.49	-16.70	0.350
2.50	-16.63	0.350
2.51	-16.56	0.350
2.51	-16.50	0.350
2.52	-16.43	0.350
2.53	-16.36	0.351
2.53	-16.30	0.351
2.54	-16.23	0.351
2.55	-16.16	0.351
2.55	-16.10	0.351
2.56	-16.03	0.351
2.57	-15.96	0.351
2.57	-15.90	0.351
2.58	-15.83	0.351
2.59	-15.76	0.351
2.59	-15.70	0.351
2.60	-15.63	0.351
2.61	-15.56	0.351
2.61	-15.50	0.351
2.62	-15.43	0.351
2.63	-15.36	0.351
2.63	-15.30	0.352
2.64	-15.23	0.352
2.65	-15.16	0.352
2.65	-15.10	0.352
2.66	-15.03	0.352
2.67	-14.96	0.352
2.67	-14.90	0.352
2.68	-14.83	0.352
2.69	-14.76	0.352
2.69	-14.70	0.352
2.70	-14.63	0.352
2.71	-14.56	0.352
2.71	-14.50	0.352
2.72	-14.43	0.352
2.73	-14.36	0.352
2.73	-14.30	0.353
2.74	-14.23	0.353
2.75	-14.16	0.353
2.75	-14.10	0.353
2.76	-14.03	0.353
2.77	-13.96	0.353
2.77	-13.90	0.353
2.78	-13.83	0.353
2.79	-13.76	0.353
2.79	-13.70	0.353
2.80	-13.63	0.353
2.81	-13.56	0.353
2.81	-13.50	0.353
2.82	-13.43	0.353
2.83	-13.36	0.354
2.83	-13.30	0.354
2.84	-13.23	0.354
2.85	-13.16	0.354
2.85	-13.10	0.354
2.86	-13.03	0.354
2.87	-12.96	0.354
2.87	-12.90	0.354
2.88	-12.83	0.354
2.89	-12.76	0.354
2.89	-12.70	0.354
2.90	-12.63	0.354
2.91	-12.56	0.354
2.91	-12.50	0.354
2.92	-12.43	0.355
2.93	-12.36	0.355
2.93	-12.29	0.355
2.94	-12.23	0.355
2.95	-12.16	0.355
2.95	-12.10	0.355
2.96	-12.03	0.355
2.97	-11.96	0.355
2.97	-11.90	0.355
2.98	-11.83	0.355
2.99	-11.76	0.355
2.99	-11.69	0.355
3.00	-11.63	0.355
3.01	-11.56	0.355
3.01	-11.50	0.355
3.02	-11.43	0.356
3.03	-11.36	0.356
3.03	-11.29	0.356
3.04	-11.23	0.356
3.05	-11.16	0.356
3.05	-11.10	0.356
3.06	-11.03	0.356
3.07	-10.96	0.356
3.07	-10.89	0.356
3.08	-10.83	0.356
3.09	-10.76	0.356
3.09	-10.69	0.356
3.10	-10.63	0.356
3.11	-10.56	0.357
3.11	-10.50	0.357
3.12	-10.43	0.357
3.13	-10.36	0.357
3.13	-10.29	0.357
3.14	-10.23	0.357
3.15	-10.16	0.357
3.15	-10.10	0.357
3.16	-10.03	0.357
3.17	-9.96	0.357
3.17	-9.90	0.357
3.18	-9.83	0.357
3.19	-9.76	0.357
3.19	-9.69	0.357
3.20	-9.63	0.357
3.21	-9.56	0.358
3.21	-9.49	0.358
3.22	-9.43	0.358
3.23	-9.36	0.358
3.23	-9.29	0.358
3.24	-9.23	0.358
3.25	-9.16	0.358
3.25	-9.09	0.358
3.26	-9.03	0.358
3.27	-8.96	0.358
3.27	-8.89	0.358
3.28	-8.83	0.358
3.29	-8.76	0.359
3.29	-8.69	0.359
3.30	-8.63	0.359
3.31	-8.56	0.359
3.31	-8.49	0.359
3.32	-8.43	0.359
3.33	-8.36	0.359
3.33	-8.29	0.359
3.34	-8.23	0.360
3.35	-8.16	0.360
3.35	-8.09	0.360
3.36	-8.03	0.360
3.37	-7.96	0.360
3.37	-7.89	0.360
3.38	-7.83	0.360
3.39	-7.76	0.360
3.39	-7.69	0.360
3.40	-7.63	0.360
3.41	-7.56	0.360
3.41	-7.49	0.361
3.42	-7.43	0.361
3.43	-7.36	0.361
3.43	-7.29	0.361
3.44	-7.23	0.361
3.45	-7.16	0.361
3.45	-7.09	0.361
3.46	-7.03	0.361
3.47	-6.96	0.361
3.47	-6.89	0.361
3.48	-6.83	0.362
3.49	-6.76	0.362
3.49	-6.69	0.362
3.50	-6.63	0.362
3.51	-6.56	0.362
3.51	-6.49	0.362
3.52	-6.43	0.362
3.53	-6.36	0.362
3.53	-6.29	0.362
3.54	-6.23	0.363
3.55	-6.16	0.363
3.55	-6.09	0.363
3.56	-6.03	0.363
3.57	-5.96	0.363
3.57	-5.89	0.363
3.58	-5.83	0.364
3.59	-5.76	0.364
3.59	-5.69	0.364
3.60	-5.63	0.364
3.61	-5.56	0.364
3.61	-5.49	0.364
3.62	-5.43	0.365
3.63	-5.36	0.365
3.63	-5.29	0.365
3.64	-5.23	0.365
3.65	-5.16	0.365
3.65	-5.09	0.366
3.66	-5.03	0.366
3.67	-4.96	0.366
3.67	-4.89	0.366
3.68	-4.83	0.366
3.69	-4.76	0.367
3.69	-4.69	0.367
3.70	-4.63	0.367
3.71	-4.56	0.367
3.71	-4.49	0.367
3.72	-4.43	0.368
3.73	-4.36	0.369
3.73	-4.29	0.369
3.74	-4.23	0.369
3.75	-4.16	0.370
3.75	-4.09	0.370
3.76	-4.03	0.370
3.77	-3.96	0.371
3.77	-3.89	0.371
3.78	-3.83	0.372
3.79	-3.76	0.372
3.79	-3.69	0.372
3.80	-3.63	0.373
3.81	-3.56	0.375
3.81	-3.49	0.377
3.82	-3.43	0.378
3.83	-3.36	0.379
3.83	-3.29	0.380
3.84	-3.23	0.385
3.85	-3.16	0.389
3.85	-3.09	0.390
3.86	-3.03	0.391
3.87	-2.96	0.394
3.87	-2.90	0.398
3.88	-2.83	0.401
3.89	-2.76	0.405
3.89	-2.70	0.410
3.90	-2.63	0.414
3.91	-2.57	0.419
3.91	-2.50	0.425
3.92	-2.43	0.432
3.93	-2.37	0.439
3.93	-2.30	0.448
3.94	-2.23	0.459
3.95	-2.17	0.471
3.95	-2.11	0.484
3.96	-2.04	0.502
3.97	-1.98	0.525
3.97	-1.91	0.553
3.98	-1.85	0.587
3.99	-1.78	0.629
3.99	-1.72	0.685
4.00	-1.66	0.754
4.01	-1.61	0.843
4.01	-1.55	0.958
4.02	-1.49	1.097
4.03	-1.44	1.261
4.03	-1.39	1.445
4.04	-1.35	1.643
4.05	-1.31	1.844
4.05	-1.27	2.046
4.06	-1.23	2.245
4.07	-1.20	2.444
4.07	-1.17	2.644
4.08	-1.14	2.839
4.09	-1.11	3.031
4.09	-1.08	3.230
4.10	-1.05	3.419
4.11	-1.03	3.592
4.11	-1.00	3.765
4.12	-0.97	3.924
4.13	-0.95	4.078
4.13	-0.92	4.229
4.14	-0.89	4.376
4.15	-0.87	4.517
4.15	-0.84	4.658
4.16	-0.81	4.795
4.17	-0.78	4.931
4.17	-0.76	5.066
4.18	-0.73	5.195
4.19	-0.70	5.320
4.19	-0.67	5.447
4.20	-0.64	5.570
4.21	-0.61	5.693
4.21	-0.58	5.812
4.22	-0.54	5.929
4.23	-0.51	6.044
4.23	-0.48	6.156
4.24	-0.44	6.264
4.25	-0.41	6.373
4.25	-0.37	6.481
4.26	-0.34	6.584
4.27	-0.30	6.687
4.27	-0.27	6.790
4.28	-0.23	6.892
4.29	-0.19	6.998
4.29	-0.16	7.093
4.30	-0.12	7.178
4.31	-0.08	7.262
4.31	-0.04	7.346
4.32	0.00	7.426
4.33	0.04	7.497
4.33	0.08	7.567
4.34	0.13	7.636
4.35	0.17	7.700
4.35	0.21	7.770
4.36	0.26	7.854
4.37	0.30	7.947
4.37	0.35	8.041
4.38	0.39	8.134
4.39	0.43	8.217
4.39	0.48	8.357
4.40	0.52	8.866
4.41	0.53	9.898
4.41	0.52	10.720
4.42	0.51	11.016
4.43	0.50	11.179
4.43	0.50	11.186
4.44	0.51	11.076
4.45	0.53	10.968
4.45	0.56	10.838
4.46	0.60	10.664
4.47	0.64	10.500
4.47	0.69	10.395
4.48	0.74	10.360
4.49	0.80	10.373
4.49	0.85	10.407
4.50	0.91	10.449
4.51	0.96	10.493
4.51	1.02	10.532
4.52	1.07	10.563
4.53	1.13	10.586
4.53	1.18	10.607
4.54	1.24	10.619
4.55	1.30	10.624
4.55	1.36	10.629
4.56	1.42	10.626
4.57	1.48	10.615
4.57	1.54	10.597
4.58	1.60	10.562
4.59	1.67	10.512
4.59	1.73	10.452
4.60	1.80	10.379
4.61	1.87	10.291
4.61	1.94	10.178
4.62	2.02	10.050
4.63	2.10	9.921
4.63	2.18	9.787
4.64	2.26	9.633
4.65	2.35	9.454
4.65	2.44	9.253
4.66	2.53	9.052
4.67	2.62	8.866
4.67	2.72	8.683
4.68	2.82	8.489
4.69	2.92	8.271
4.69	3.02	8.028
4.70	3.13	7.768
4.71	3.24	7.484
4.71	3.35	7.171
4.72	3.47	6.835
4.73	3.59	6.477
4.73	3.72	6.090
4.74	3.85	5.677
4.75	3.99	5.241
4.75	4.12	4.786
4.76	4.27	4.365
4.77	4.42	4.029
4.77	4.56	3.771
4.78	4.70	3.559
4.79	4.84	3.381
4.79	4.98	3.222
4.80	5.11	3.080
4.81	5.24	2.947
4.81	5.37	2.825
4.82	5.49	2.712
4.83	5.61	2.604
4.83	5.73	2.504
4.84	5.84	2.410
4.85	5.95	2.317
4.85	6.06	2.234
4.86	6.17	2.153
4.87	6.28	2.076
4.87	6.38	2.003
4.88	6.48	1.935
4.89	6.58	1.873
4.89	6.68	1.810
4.90	6.77	1.749
4.91	6.87	1.696
4.91	6.96	1.646
4.92	7.05	1.595
4.93	7.14	1.546
4.93	7.23	1.502
4.94	7.32	1.462
4.95	7.41	1.418
4.95	7.50	1.380
4.96	7.58	1.350
4.97	7.66	1.318
4.97	7.75	1.280
4.98	7.83	1.241
4.99	7.91	1.216
4.99	7.99	1.199
5.00	8.07	1.177
5.01	8.15	1.146
5.01	8.23	1.117
5.02	8.30	1.094
5.03	8.38	1.074
5.03	8.46	1.057
5.04	8.54	1.039
5.05	8.61	1.021
5.05	8.69	1.003
5.06	8.76	0.988
5.07	8.83	0.975
5.07	8.91	0.958
5.08	8.98	0.945
5.09	9.06	0.932
5.09	9.13	0.920
5.10	9.20	0.910
5.11	9.27	0.898
5.11	9.35	0.886
5.12	9.42	0.878
5.13	9.49	0.869
5.13	9.56	0.859
5.14	9.63	0.852
5.15	9.70	0.844
5.15	9.77	0.837
5.16	9.84	0.830
5.17	9.91	0.824
5.17	9.98	0.817
5.18	10.05	0.811
5.19	10.12	0.806
5.19	10.19	0.801
5.20	10.26	0.793
5.21	10.33	0.789
5.21	10.40	0.786
5.22	10.47	0.781
5.23	10.54	0.777
5.23	10.61	0.773
5.24	10.67	0.768
5.25	10.74	0.767
5.25	10.81	0.762
5.26	10.88	0.757
5.27	10.95	0.756
5.27	11.01	0.756
5.28	11.08	0.752
5.29	11.15	0.748
5.29	11.22	0.748
5.30	11.29	0.747
5.31	11.35	0.743
5.31	11.42	0.741
5.32	11.49	0.740
5.33	11.56	0.738
5.33	11.62	0.736
5.34	11.69	0.735
5.35	11.76	0.732
5.35	11.83	0.731
5.36	11.89	0.731
5.37	11.96	0.729
5.37	12.03	0.728
5.38	12.10	0.728
5.39	12.16	0.726
5.39	12.23	0.724
5.40	12.30	0.723
5.41	12.37	0.722
5.41	12.43	0.722
5.42	12.50	0.722
5.43	12.57	0.721
5.43	12.63	0.721
5.44	12.70	0.720
5.45	12.77	0.719
5.45	12.84	0.719
5.46	12.90	0.718
5.47	12.97	0.718
5.47	13.04	0.717
5.48	13.10	0.717
5.49	13.17	0.717
5.49	13.24	0.716
5.50	13.31	0.716
5.51	13.37	0.715
5.51	13.44	0.715
5.52	13.51	0.715
5.53	13.57	0.715
5.53	13.64	0.715
5.54	13.71	0.714
5.55	13.77	0.714
5.55	13.84	0.714
5.56	13.91	0.714
5.57	13.97	0.714
5.57	14.04	0.714
5.58	14.11	0.713
5.59	14.17	0.713
5.59	14.24	0.713
5.60	14.31	0.713
5.61	14.38	0.712
5.61	14.44	0.712
5.62	14.51	0.712
5.63	14.58	0.712
5.63	14.64	0.712
5.64	14.71	0.712
5.65	14.78	0.711
5.65	14.84	0.711
5.66	14.91	0.711
5.67	14.98	0.711
5.67	15.04	0.711
5.68	15.11	0.710
5.69	15.18	0.710
5.69	15.24	0.710
5.70	15.31	0.710
5.71	15.38	0.710
5.71	15.44	0.710
5.72	15.51	0.710
5.73	15.58	0.709
5.73	15.64	0.709
5.74	15.71	0.709
5.75	15.78	0.709
5.75	15.84	0.709
5.76	15.91	0.709
5.77	15.98	0.709
5.77	16.05	0.708
5.78	16.11	0.708
5.79	16.18	0.708
5.79	16.25	0.708
5.80	16.31	0.708
5.81	16.38	0.708
5.81	16.45	0.708
5.82	16.51	0.708
5.83	16.58	0.708
5.83	16.65	0.707
5.84	16.71	0.707
5.85	16.78	0.707
5.85	16.85	0.707
5.86	16.91	0.707
5.87	16.98	0.707
5.87	17.05	0.707
5.88	17.11	0.707
5.89	17.18	0.707
5.89	17.25	0.707
5.90	17.31	0.707
5.91	17.38	0.707
5.91	17.45	0.707
5.92	17.51	0.706
5.93	17.58	0.706
5.93	17.65	0.706
5.94	17.71	0.706
5.95	17.78	0.706
5.95	17.85	0.706
5.96	17.91	0.706
5.97	17.98	0.706
5.97	18.05	0.706
5.98	18.11	0.706
5.99	18.18	0.706
5.99	18.25	0.706
6.00	18.32	0.706
6.01	18.38	0.706
6.01	18.45	0.706
6.02	18.52	0.706
6.03	18.58	0.706
6.03	18.65	0.706
6.04	18.72	0.706
6.05	18.78	0.706
6.05	18.85	0.705
6.06	18.91	0.705
6.07	18.98	0.705
6.07	19.05	0.705
6.08	19.12	0.705
6.09	19.18	0.705
6.09	19.25	0.705
6.10	19.32	0.705
6.11	19.38	0.705
6.11	19.45	0.705
6.12	19.52	0.705
6.13	19.58	0.705
6.13	19.65	0.705
6.14	19.72	0.705
6.15	19.78	0.705
6.15	19.85	0.705
6.16	19.92	0.705
6.17	19.98	0.705
6.17	20.05	0.705
6.18	20.12	0.705
6.19	20.18	0.705
6.19	20.25	0.705
6.20	20.32	0.705
6.21	20.38	0.705
6.21	20.45	0.705
6.22	20.52	0.705
6.23	20.58	0.705
6.23	20.65	0.705
6.24	20.72	0.705
6.25	20.78	0.705
6.25	20.85	0.705
6.26	20.92	0.705
6.27	20.98	0.705
6.27	21.05	0.705
6.28	21.12	0.705
6.29	21.18	0.705
6.29	21.25	0.705
6.30	21.32	0.705
6.31	21.38	0.705
6.31	21.45	0.705
6.32	21.52	0.705
6.33	21.58	0.705
6.33	21.65	0.705
6.34	21.72	0.705
6.35	21.78	0.705
6.35	21.85	0.705
6.36	21.92	0.705
6.37	21.98	0.705
6.37	22.05	0.705
6.38	22.12	0.705
6.39	22.19	0.705
6.39	22.25	0.705
6.40	22.32	0.705
6.41	22.39	0.705
6.41	22.45	0.705
6.42	22.52	0.705
6.43	22.59	0.705
6.43	22.65	0.705
6.44	22.72	0.705
6.45	22.79	0.705
6.45	22.85	0.705
6.46	22.92	0.705
6.47	22.99	0.705
6.47	23.05	0.705
6.48	23.12	0.705
6.49	23.19	0.705
6.49	23.25	0.705
6.50	23.32	0.705
6.51	23.39	0.705
6.51	23.45	0.705
6.52	23.52	0.705
6.53	23.59	0.705
6.53	23.65	0.705
6.54	23.72	0.705
6.55	23.79	0.705
6.55	23.85	0.705
6.56	23.92	0.706
6.57	23.99	0.706
6.57	24.05	0.706
6.58	24.12	0.706
6.59	24.19	0.706
6.59	24.26	0.706
6.60	24.32	0.706
6.61	24.39	0.706
6.61	24.45	0.706
6.62	24.52	0.706
6.63	24.59	0.706
6.63	24.65	0.706
6.64	24.72	0.706
6.65	24.79	0.706
6.65	24.86	0.706
6.66	24.92	0.706
6.67	24.99	0.706
6.67	25.06	0.706
6.68	25.12	0.706
6.69	25.19	0.706
6.69	25.26	0.706
6.70	25.32	0.706
6.71	25.39	0.706
6.71	25.46	0.706
6.72	25.52	0.706
6.73	25.59	0.706
6.73	25.66	0.706
6.74	25.72	0.706
6.75	25.79	0.706
6.75	25.86	0.706
6.76	25.92	0.706
6.77	25.99	0.706
6.77	26.06	0.706
6.78	26.12	0.706
6.79	26.19	0.706
6.79	26.26	0.706
6.80	26.32	0.706
6.81	26.39	0.706
6.81	26.46	0.706
6.82	26.52	0.706
6.83	26.59	0.706
6.83	26.66	0.706
6.84	26.72	0.706
6.85	26.79	0.706
6.85	26.86	0.706
6.86	26.92	0.706
6.87	26.99	0.706
6.87	27.06	0.706
6.88	27.13	0.706
6.89	27.19	0.706
6.89	27.26	0.706
6.90	27.32	0.706
6.91	27.39	0.706
6.91	27.46	0.706
6.92	27.52	0.706
6.93	27.59	0.706
6.93	27.66	0.707
6.94	27.72	0.707
6.95	27.79	0.707
6.95	27.86	0.707
6.96	27.92	0.707
6.97	27.99	0.707
6.97	28.06	0.707
6.98	28.13	0.707
6.99	28.19	0.707
6.99	28.26	0.707
7.00	28.32	0.707
7.01	28.39	0.707
7.01	28.46	0.707
7.02	28.53	0.707
7.03	28.59	0.707
7.03	28.66	0.707
7.04	28.73	0.707
7.05	28.79	0.707
7.05	28.86	0.707
7.06	28.93	0.707
7.07	28.99	0.707
7.07	29.06	0.707
7.08	29.13	0.707
7.09	29.19	0.707
7.09	29.26	0.707
7.10	29.33	0.707
7.11	29.39	0.707
7.11	29.46	0.707
7.12	29.53	0.707
7.13	29.59	0.707
7.13	29.66	0.707
7.14	29.73	0.707
7.15	29.79	0.707
7.15	29.86	0.707
7.16	29.93	0.707
7.17	29.99	0.708
7.17	30.06	0.708
7.18	30.13	0.708
7.19	30.19	0.708
7.19	30.26	0.708
7.20	30.33	0.708
7.21	30.39	0.708
7.21	30.46	0.708
7.22	30.53	0.708
7.23	30.60	0.708
7.23	30.66	0.708
7.24	30.73	0.708
7.25	30.80	0.708
7.25	30.86	0.708
7.26	30.93	0.708
7.27	31.00	0.708
7.27	31.06	0.708
7.28	31.13	0.708
7.29	31.20	0.708
7.29	31.26	0.708
7.30	31.33	0.708
7.31	31.40	0.708
7.31	31.46	0.708
7.32	31.53	0.708
7.33	31.60	0.709
7.33	31.66	0.709
7.34	31.73	0.709
7.35	31.80	0.709
7.35	31.86	0.709
7.36	31.93	0.709
7.37	32.00	0.709
7.37	32.06	0.709
7.38	32.13	0.709
7.39	32.20	0.709
7.39	32.26	0.709
7.40	32.33	0.709
7.41	32.40	0.709
7.41	32.46	0.709
7.42	32.53	0.709
7.43	32.60	0.709
7.43	32.66	0.709
7.44	32.73	0.709
7.45	32.80	0.709
7.45	32.86	0.709
7.46	32.93	0.709
7.47	33.00	0.709
7.47	33.06	0.709
7.48	33.13	0.709
7.49	33.20	0.709
7.49	33.26	0.709
7.50	33.33	0.709
7.51	33.40	0.709
7.51	33.46	0.709
7.52	33.53	0.709
7.53	33.60	0.709
7.53	33.66	0.709
7.54	33.73	0.710
7.55	33.80	0.710
7.55	33.86	0.710
7.56	33.93	0.710
7.57	34.00	0.710
7.57	34.06	0.710
7.58	34.13	0.710
7.59	34.20	0.710
7.59	34.26	0.710
7.60	34.33	0.710
7.61	34.40	0.710
7.61	34.46	0.710
7.62	34.53	0.710
7.63	34.60	0.710
7.63	34.67	0.710
7.64	34.73	0.710
7.65	34.80	0.710
7.65	34.87	0.710
7.66	34.93	0.710
7.67	35.00	0.710
7.67	35.07	0.710
7.68	35.13	0.710
7.69	35.20	0.710
7.69	35.27	0.710
7.70	35.33	0.710
7.71	35.40	0.710
7.71	35.47	0.710
7.72	35.53	0.710
7.73	35.60	0.710
7.73	35.67	0.710
7.74	35.73	0.710
7.75	35.80	0.710
7.75	35.87	0.710
7.76	35.93	0.710
7.77	36.00	0.710
7.77	36.07	0.710
7.78	36.13	0.710
7.79	36.20	0.711
7.79	36.27	0.711
7.80	36.33	0.711
7.81	36.40	0.711
7.81	36.47	0.711
7.82	36.53	0.711
7.83	36.60	0.711
7.83	36.67	0.711
7.84	36.73	0.711
7.85	36.80	0.711
7.85	36.87	0.711
7.86	36.93	0.711
7.87	37.00	0.711
7.87	37.07	0.711
7.88	37.13	0.711
7.89	37.20	0.711
7.89	37.27	0.711
7.90	37.34	0.711
7.91	37.40	0.711
7.91	37.47	0.711
7.92	37.53	0.711
7.93	37.60	0.711
7.93	37.67	0.711
7.94	37.74	0.711
7.95	37.80	0.711
7.95	37.87	0.711
7.96	37.94	0.711
7.97	38.00	0.711
7.97	38.07	0.711
7.98	38.14	0.711
7.99	38.20	0.711
7.99	38.27	0.711
8.00	38.29	0.711

[step]
Ramp 10.00 °C/min to -40.00 °C
Time	Temperature	Heat Flow (Normalized)
min	°C	W/g
9.00	40.06	-0.021
9.00	40.07	-0.021
9.01	40.07	-0.022
9.02	40.07	-0.022
9.02	40.06	-0.022
9.03	40.06	-0.022
9.04	40.06	-0.023
9.04	40.06	-0.023
9.05	40.05	-0.019
9.06	40.05	-0.009
9.06	40.04	0.002
9.07	40.02	0.011
9.08	40.01	0.018
9.08	39.99	0.024
9.09	39.97	0.025
9.10	39.95	0.025
9.10	39.93	0.023
9.11	39.90	0.018
9.12	39.87	0.013
9.12	39.84	-0.013
9.13	39.80	-0.036
9.14	39.76	-0.056
9.14	39.72	-0.081
9.15	39.68	-0.110
9.16	39.64	-0.138
9.16	39.60	-0.165
9.17	39.55	-0.196
9.18	39.50	-0.225
9.18	39.46	-0.254
9.19	39.41	-0.285
9.20	39.36	-0.312
9.20	39.30	-0.337
9.21	39.25	-0.364
9.22	39.20	-0.387
9.22	39.15	-0.408
9.23	39.10	-0.430
9.24	39.04	-0.449
9.24	38.99	-0.467
9.25	38.93	-0.483
9.26	38.88	-0.498
9.26	38.82	-0.513
9.27	38.76	-0.525
9.28	38.71	-0.539
9.28	38.65	-0.552
9.29	38.59	-0.563
9.30	38.53	-0.574
9.30	38.48	-0.584
9.31	38.42	-0.593
9.32	38.36	-0.602
9.32	38.30	-0.610
9.33	38.24	-0.620
9.34	38.18	-0.628
9.34	38.12	-0.634
9.35	38.06	-0.640
9.36	37.99	-0.648
9.36	37.93	-0.655
9.37	37.87	-0.661
9.38	37.81	-0.666
9.38	37.75	-0.673
9.39	37.69	-0.681
9.40	37.62	-0.683
9.40	37.56	-0.685
9.41	37.50	-0.692
9.42	37.43	-0.697
9.42	37.37	-0.701
9.43	37.31	-0.706
9.44	37.25	-0.708
9.44	37.18	-0.711
9.45	37.12	-0.716
9.46	37.06	-0.717
9.46	36.99	-0.721
9.47	36.93	-0.724
9.48	36.86	-0.725
9.48	36.80	-0.728
9.49	36.74	-0.731
9.50	36.67	-0.733
9.50	36.61	-0.735
9.51	36.55	-0.737
9.52	36.48	-0.739
9.52	36.42	-0.740
9.53	36.35	-0.741
9.54	36.29	-0.744
9.54	36.22	-0.746
9.55	36.16	-0.746
9.56	36.09	-0.747
9.56	36.03	-0.749
9.57	35.96	-0.750
9.58	35.90	-0.751
9.58	35.83	-0.753
9.59	35.77	-0.755
9.60	35.70	-0.755
9.60	35.64	-0.755
9.61	35.57	-0.756
9.62	35.51	-0.758
9.62	35.44	-0.758
9.63	35.38	-0.759
9.64	35.31	-0.760
9.64	35.25	-0.760
9.65	35.18	-0.760
9.66	35.12	-0.761
9.66	35.05	-0.761
9.67	34.99	-0.762
9.68	34.92	-0.762
9.68	34.86	-0.763
9.69	34.79	-0.763
9.70	34.73	-0.764
9.70	34.66	-0.764
9.71	34.59	-0.765
9.72	34.53	-0.767
9.72	34.46	-0.767
9.73	34.40	-0.767
9.74	34.33	-0.768
9.74	34.27	-0.768
9.75	34.20	-0.768
9.76	34.13	-0.769
9.76	34.07	-0.769
9.77	34.00	-0.769
9.78	33.94	-0.769
9.78	33.87	-0.770
9.79	33.81	-0.770
9.80	33.74	-0.770
9.80	33.67	-0.771
9.81	33.61	-0.771
9.82	33.54	-0.771
9.82	33.48	-0.771
9.83	33.41	-0.771
9.84	33.34	-0.772
9.84	33.28	-0.772
9.85	33.21	-0.772
9.86	33.15	-0.772
9.86	33.08	-0.772
9.87	33.02	-0.773
9.88	32.95	-0.773
9.88	32.88	-0.773
9.89	32.82	-0.773
9.90	32.75	-0.773
9.90	32.69	-0.773
9.91	32.62	-0.774
9.92	32.55	-0.774
9.92	32.49	-0.774
9.93	32.42	-0.774
9.94	32.36	-0.774
9.94	32.29	-0.774
9.95	32.22	-0.774
9.96	32.16	-0.775
9.96	32.09	-0.775
9.97	32.03	-0.775
9.98	31.96	-0.775
9.98	31.89	-0.775
9.99	31.83	-0.775
10.00	31.76	-0.776
10.00	31.70	-0.776
10.01	31.63	-0.776
10.02	31.56	-0.776
10.02	31.50	-0.776
10.03	31.43	-0.776
10.04	31.36	-0.776
10.04	31.30	-0.776
10.05	31.23	-0.777
10.06	31.17	-0.777
10.06	31.10	-0.777
10.07	31.03	-0.777
10.08	30.97	-0.777
10.08	30.90	-0.777
10.09	30.84	-0.777
10.10	30.77	-0.777
10.10	30.70	-0.778
10.11	30.64	-0.778
10.12	30.57	-0.778
10.12	30.50	-0.778
10.13	30.44	-0.778
10.14	30.37	-0.778
10.14	30.31	-0.778
10.15	30.24	-0.779
10.16	30.17	-0.779
10.16	30.11	-0.779
10.17	30.04	-0.779
10.18	29.97	-0.779
10.18	29.91	-0.779
10.19	29.84	-0.779
10.20	29.77	-0.779
10.20	29.71	-0.779
10.21	29.64	-0.779
10.22	29.58	-0.779
10.22	29.51	-0.779
10.23	29.44	-0.779
10.24	29.38	-0.779
10.24	29.31	-0.780
10.25	29.24	-0.780
10.26	29.18	-0.780
10.26	29.11	-0.780
10.27	29.05	-0.780
10.28	28.98	-0.780
10.28	28.91	-0.780
10.29	28.85	-0.780
10.30	28.78	-0.780
10.30	28.71	-0.780
10.31	28.65	-0.780
10.32	28.58	-0.780
10.32	28.52	-0.780
10.33	28.45	-0.780
10.34	28.38	-0.780
10.34	28.32	-0.780
10.35	28.25	-0.780
10.36	28.18	-0.780
10.36	28.12	-0.781
10.37	28.05	-0.781
10.38	27.98	-0.781
10.38	27.92	-0.781
10.39	27.85	-0.781
10.40	27.78	-0.781
10.40	27.72	-0.781
10.41	27.65	-0.781
10.42	27.59	-0.781
10.42	27.52	-0.781
10.43	27.45	-0.781
10.44	27.39	-0.781
10.44	27.32	-0.781
10.45	27.25	-0.781
10.46	27.19	-0.781
10.46	27.12	-0.781
10.47	27.05	-0.781
10.48	26.99	-0.781
10.48	26.92	-0.781
10.49	26.85	-0.781
10.50	26.79	-0.781
10.50	26.72	-0.781
10.51	26.66	-0.781
10.52	26.59	-0.781
10.52	26.52	-0.781
10.53	26.46	-0.781
10.54	26.39	-0.781
10.54	26.32	-0.781
10.55	26.26	-0.781
10.56	26.19	-0.781
10.56	26.12	-0.781
10.57	26.06	-0.781
10.58	25.99	-0.781
10.58	25.92	-0.780
10.59	25.86	-0.780
10.60	25.79	-0.780
10.60	25.72	-0.780
10.61	25.66	-0.780
10.62	25.59	-0.780
10.62	25.52	-0.780
10.63	25.46	-0.780
10.64	25.39	-0.780
10.64	25.32	-0.780
10.65	25.26	-0.780
10.66	25.19	-0.780
10.66	25.13	-0.780
10.67	25.06	-0.780
10.68	24.99	-0.780
10.68	24.93	-0.780
10.69	24.86	-0.780
10.70	24.79	-0.780
10.70	24.73	-0.780
10.71	24.66	-0.780
10.72	24.60	-0.780
10.72	24.53	-0.780
10.73	24.46	-0.780
10.74	24.39	-0.780
10.74	24.33	-0.780
10.75	24.26	-0.780
10.76	24.20	-0.780
10.76	24.13	-0.780
10.77	24.06	-0.780
10.78	24.00	-0.779
10.78	23.93	-0.779
10.79	23.86	-0.779
10.80	23.80	-0.779
10.80	23.73	-0.779
10.81	23.66	-0.779
10.82	23.60	-0.779
10.82	23.53	-0.779
10.83	23.46	-0.779
10.84	23.40	-0.779
10.84	23.33	-0.779
10.85	23.26	-0.779
10.86	23.20	-0.779
10.86	23.13	-0.779
10.87	23.07	-0.779
10.88	23.00	-0.779
10.88	22.93	-0.779
10.89	22.87	-0.779
10.90	22.80	-0.779
10.90	22.73	-0.779
10.91	22.67	-0.779
10.92	22.60	-0.779
10.92	22.53	-0.778
10.93	22.47	-0.778
10.94	22.40	-0.778
10.94	22.33	-0.778
10.95	22.27	-0.778
10.96	22.20	-0.778
10.96	22.13	-0.778
10.97	22.07	-0.778
10.98	22.00	-0.778
10.98	21.93	-0.778
10.99	21.87	-0.778
11.00	21.80	-0.778
11.00	21.73	-0.778
11.01	21.67	-0.778
11.02	21.60	-0.778
11.02	21.53	-0.778
11.03	21.47	-0.777
11.04	21.40	-0.777
11.04	21.34	-0.777
11.05	21.27	-0.777
11.06	21.20	-0.777
11.06	21.14	-0.777
11.07	21.07	-0.777
11.08	21.00	-0.777
11.08	20.94	-0.777
11.09	20.87	-0.777
11.10	20.80	-0.777
11.10	20.74	-0.776
11.11	20.67	-0.776
11.12	20.60	-0.776
11.12	20.54	-0.776
11.13	20.47	-0.776
11.14	20.40	-0.776
11.14	20.34	-0.776
11.15	20.27	-0.776
11.16	20.20	-0.776
11.16	20.14	-0.776
11.17	20.07	-0.776
11.18	20.00	-0.776
11.18	19.94	-0.776
11.19	19.87	-0.776
11.20	19.80	-0.775
11.20	19.74	-0.775
11.21	19.67	-0.775
11.22	19.60	-0.775
11.22	19.54	-0.775
11.23	19.47	-0.775
11.24	19.40	-0.775
11.24	19.34	-0.775
11.25	19.27	-0.775
11.26	19.20	-0.775
11.26	19.14	-0.775
11.27	19.07	-0.774
11.28	19.01	-0.774
11.28	18.94	-0.774
11.29	18.87	-0.774
11.30	18.81	-0.774
11.30	18.74	-0.774
11.31	18.67	-0.774
11.32	18.61	-0.774
11.32	18.54	-0.774
11.33	18.47	-0.774
11.34	18.41	-0.774
11.34	18.34	-0.774
11.35	18.27	-0.774
11.36	18.21	-0.774
11.36	18.14	-0.773
11.37	18.07	-0.773
11.38	18.01	-0.773
11.38	17.94	-0.773
11.39	17.87	-0.773
11.40	17.81	-0.773
11.40	17.74	-0.773
11.41	17.67	-0.773
11.42	17.61	-0.773
11.42	17.54	-0.773
11.43	17.47	-0.773
11.44	17.41	-0.773
11.44	17.34	-0.773
11.45	17.27	-0.773
11.46	17.21	-0.772
11.46	17.14	-0.772
11.47	17.07	-0.772
11.48	17.01	-0.772
11.48	16.94	-0.772
11.49	16.87	-0.772
11.50	16.81	-0.772
11.50	16.74	-0.772
11.51	16.68	-0.772
11.52	16.61	-0.772
11.52	16.54	-0.771
11.53	16.48	-0.771
11.54	16.41	-0.771
11.54	16.34	-0.771
11.55	16.28	-0.771
11.56	16.21	-0.771
11.56	16.14	-0.771
11.57	16.08	-0.771
11.58	16.01	-0.771
11.58	15.94	-0.771
11.59	15.88	-0.771
11.60	15.81	-0.771
11.60	15.74	-0.771
11.61	15.68	-0.771
11.62	15.61	-0.771
11.62	15.54	-0.770
11.63	15.48	-0.770
11.64	15.41	-0.770
11.64	15.35	-0.770
11.65	15.28	-0.770
11.66	15.21	-0.770
11.66	15.15	-0.770
11.67	15.08	-0.770
11.68	15.01	-0.770
11.68	14.95	-0.770
11.69	14.88	-0.770
11.70	14.81	-0.770
11.70	14.75	-0.770
11.71	14.68	-0.770
11.72	14.61	-0.770
11.72	14.55	-0.770
11.73	14.48	-0.770
11.74	14.41	-0.769
11.74	14.35	-0.769
11.75	14.28	-0.769
11.76	14.21	-0.769
11.76	14.15	-0.769
11.77	14.08	-0.769
11.78	14.01	-0.769
11.78	13.95	-0.769
11.79	13.88	-0.769
11.80	13.81	-0.769
11.80	13.75	-0.769
11.81	13.68	-0.769
11.82	13.61	-0.769
11.82	13.55	-0.769
11.83	13.48	-0.769
11.84	13.41	-0.769
11.84	13.35	-0.769
11.85	13.28	-0.769
11.86	13.22	-0.769
11.86	13.15	-0.768
11.87	13.08	-0.768
11.88	13.01	-0.768
11.88	12.95	-0.768
11.89	12.88	-0.768
11.90	12.81	-0.768
11.90	12.75	-0.768
11.91	12.68	-0.768
11.92	12.61	-0.768
11.92	12.55	-0.768
11.93	12.48	-0.768
11.94	12.41	-0.768
11.94	12.35	-0.768
11.95	12.28	-0.768
11.96	12.22	-0.768
11.96	12.15	-0.768
11.97	12.08	-0.768
11.98	12.02	-0.768
11.98	11.95	-0.768
11.99	11.88	-0.768
12.00	11.82	-0.768
12.00	11.75	-0.768
12.01	11.68	-0.768
12.02	11.62	-0.768
12.02	11.55	-0.767
12.03	11.48	-0.767
12.04	11.42	-0.767
12.04	11.35	-0.767
12.05	11.29	-0.767
12.06	11.22	-0.767
12.06	11.15	-0.767
12.07	11.09	-0.767
12.08	11.02	-0.767
12.08	10.95	-0.767
12.09	10.89	-0.767
12.10	10.82	-0.767
12.10	10.75	-0.767
12.11	10.69	-0.767
12.12	10.62	-0.767
12.12	10.55	-0.767
12.13	10.49	-0.767
12.14	10.42	-0.767
12.14	10.35	-0.767
12.15	10.29	-0.766
12.16	10.22	-0.766
12.16	10.15	-0.766
12.17	10.09	-0.766
12.18	10.02	-0.766
12.18	9.96	-0.766
12.19	9.89	-0.766
12.20	9.82	-0.766
12.20	9.76	-0.766
12.21	9.69	-0.766
12.22	9.62	-0.766
12.22	9.55	-0.766
12.23	9.49	-0.766
12.24	9.42	-0.766
12.24	9.36	-0.766
12.25	9.29	-0.766
12.26	9.22	-0.766
12.26	9.16	-0.766
12.27	9.09	-0.766
12.28	9.02	-0.766
12.28	8.96	-0.765
12.29	8.89	-0.765
12.30	8.82	-0.765
12.30	8.76	-0.765
12.31	8.69	-0.765
12.32	8.62	-0.765
12.32	8.56	-0.765
12.33	8.49	-0.765
12.34	8.42	-0.765
12.34	8.36	-0.765
12.35	8.29	-0.765
12.36	8.22	-0.765
12.36	8.16	-0.765
12.37	8.09	-0.765
12.38	8.02	-0.765
12.38	7.96	-0.765
12.39	7.89	-0.765
12.40	7.83	-0.765
12.40	7.76	-0.765
12.41	7.69	-0.765
12.42	7.63	-0.765
12.42	7.56	-0.765
12.43	7.49	-0.765
12.44	7.43	-0.765
12.44	7.36	-0.765
12.45	7.29	-0.765
12.46	7.23	-0.765
12.46	7.16	-0.765
12.47	7.09	-0.765
12.48	7.03	-0.764
12.48	6.96	-0.764
12.49	6.89	-0.764
12.50	6.83	-0.764
12.50	6.76	-0.764
12.51	6.70	-0.764
12.52	6.63	-0.764
12.52	6.56	-0.764
12.53	6.50	-0.764
12.54	6.43	-0.764
12.54	6.36	-0.764
12.55	6.30	-0.764
12.56	6.23	-0.764
12.56	6.16	-0.764
12.57	6.10	-0.764
12.58	6.03	-0.764
12.58	5.96	-0.764
12.59	5.90	-0.764
12.60	5.83	-0.764
12.60	5.76	-0.764
12.61	5.70	-0.764
12.62	5.63	-0.764
12.62	5.56	-0.764
12.63	5.50	-0.764
12.64	5.43	-0.764
12.64	5.36	-0.764
12.65	5.30	-0.764
12.66	5.23	-0.764
12.66	5.16	-0.764
12.67	5.10	-0.764
12.68	5.03	-0.764
12.68	4.96	-0.764
12.69	4.90	-0.764
12.70	4.83	-0.764
12.70	4.76	-0.764
12.71	4.70	-0.764
12.72	4.63	-0.764
12.72	4.56	-0.763
12.73	4.50	-0.764
12.74	4.43	-0.764
12.74	4.36	-0.764
12.75	4.30	-0.764
12.76	4.23	-0.763
12.76	4.16	-0.764
12.77	4.10	-0.764
12.78	4.03	-0.764
12.78	3.96	-0.764
12.79	3.90	-0.764
12.80	3.83	-0.764
12.80	3.76	-0.764
12.81	3.70	-0.764
12.82	3.63	-0.763
12.82	3.57	-0.763
12.83	3.50	-0.763
12.84	3.43	-0.763
12.84	3.37	-0.763
12.85	3.30	-0.763
12.86	3.23	-0.763
12.86	3.17	-0.763
12.87	3.10	-0.763
12.88	3.03	-0.763
12.88	2.96	-0.763
12.89	2.90	-0.763
12.90	2.83	-0.763
12.90	2.76	-0.763
12.91	2.70	-0.763
12.92	2.63	-0.763
12.92	2.57	-0.763
12.93	2.50	-0.763
12.94	2.43	-0.763
12.94	2.37	-0.763
12.95	2.30	-0.763
12.96	2.23	-0.763
12.96	2.17	-0.763
12.97	2.10	-0.763
12.98	2.03	-0.763
12.98	1.97	-0.763
12.99	1.90	-0.763
13.00	1.83	-0.763
13.00	1.77	-0.763
13.01	1.70	-0.763
13.02	1.63	-0.763
13.02	1.57	-0.763
13.03	1.50	-0.763
13.04	1.43	-0.763
13.04	1.37	-0.763
13.05	1.30	-0.763
13.06	1.23	-0.763
13.06	1.17	-0.763
13.07	1.10	-0.763
13.08	1.03	-0.763
13.08	0.97	-0.763
13.09	0.90	-0.763
13.10	0.83	-0.763
13.10	0.77	-0.763
13.11	0.70	-0.763
13.12	0.63	-0.763
13.12	0.57	-0.763
13.13	0.50	-0.763
13.14	0.43	-0.763
13.14	0.37	-0.763
13.15	0.30	-0.763
13.16	0.23	-0.763
13.16	0.17	-0.763
13.17	0.10	-0.763
13.18	0.03	-0.763
13.18	-0.03	-0.763
13.19	-0.10	-0.763
13.20	-0.17	-0.763
13.20	-0.23	-0.763
13.21	-0.30	-0.763
13.22	-0.37	-0.763
13.22	-0.43	-0.763
13.23	-0.50	-0.763
13.24	-0.57	-0.763
13.24	-0.63	-0.763
13.25	-0.70	-0.763
13.26	-0.77	-0.763
13.26	-0.83	-0.763
13.27	-0.90	-0.763
13.28	-0.97	-0.763
13.28	-1.03	-0.763
13.29	-1.10	-0.763
13.30	-1.17	-0.763
13.30	-1.23	-0.763
13.31	-1.30	-0.764
13.32	-1.37	-0.764
13.32	-1.43	-0.764
13.33	-1.50	-0.764
13.34	-1.57	-0.764
13.34	-1.63	-0.763
13.35	-1.70	-0.764
13.36	-1.77	-0.764
13.36	-1.83	-0.764
13.37	-1.90	-0.764
13.38	-1.97	-0.764
13.38	-2.03	-0.764
13.39	-2.10	-0.764
13.40	-2.17	-0.764
13.40	-2.24	-0.764
13.41	-2.30	-0.764
13.42	-2.37	-0.764
13.42	-2.43	-0.764
13.43	-2.50	-0.764
13.44	-2.57	-0.764
13.44	-2.63	-0.764
13.45	-2.70	-0.764
13.46	-2.77	-0.764
13.46	-2.83	-0.764
13.47	-2.90	-0.764
13.48	-2.97	-0.764
13.48	-3.04	-0.764
13.49	-3.10	-0.764
13.50	-3.17	-0.764
13.50	-3.23	-0.764
13.51	-3.30	-0.764
13.52	-3.37	-0.764
13.52	-3.44	-0.764
13.53	-3.50	-0.764
13.54	-3.57	-0.764
13.54	-3.64	-0.764
13.55	-3.70	-0.764
13.56	-3.77	-0.764
13.56	-3.84	-0.764
13.57	-3.90	-0.764
13.58	-3.97	-0.764
13.58	-4.03	-0.764
13.59	-4.10	-0.764
13.60	-4.17	-0.765
13.60	-4.24	-0.765
13.61	-4.30	-0.765
13.62	-4.37	-0.765
13.62	-4.44	-0.765
13.63	-4.50	-0.765
13.64	-4.57	-0.765
13.64	-4.64	-0.765
13.65	-4.70	-0.765
13.66	-4.77	-0.765
13.66	-4.84	-0.765
13.67	-4.90	-0.765
13.68	-4.97	-0.765
13.68	-5.04	-0.765
13.69	-5.10	-0.765
13.70	-5.17	-0.765
13.70	-5.24	-0.765
13.71	-5.30	-0.765
13.72	-5.37	-0.765
13.72	-5.44	-0.765
13.73	-5.50	-0.765
13.74	-5.57	-0.765
13.74	-5.64	-0.765
13.75	-5.70	-0.765
13.76	-5.77	-0.765
13.76	-5.84	-0.765
13.77	-5.90	-0.765
13.78	-5.97	-0.765
13.78	-6.04	-0.765
13.79	-6.10	-0.765
13.80	-6.17	-0.765
13.80	-6.24	-0.765
13.81	-6.30	-0.765
13.82	-6.37	-0.766
13.82	-6.44	-0.766
13.83	-6.50	-0.766
13.84	-6.57	-0.766
13.84	-6.64	-0.766
13.85	-6.70	-0.766
13.86	-6.77	-0.766
13.86	-6.84	-0.766
13.87	-6.90	-0.766
13.88	-6.97	-0.766
13.88	-7.04	-0.766
13.89	-7.10	-0.766
13.90	-7.17	-0.766
13.90	-7.24	-0.766
13.91	-7.30	-0.766
13.92	-7.37	-0.766
13.92	-7.44	-0.766
13.93	-7.50	-0.766
13.94	-7.57	-0.766
13.94	-7.64	-0.766
13.95	-7.71	-0.766
13.96	-7.77	-0.766
13.96	-7.84	-0.766
13.97	-7.90	-0.766
13.98	-7.97	-0.766
13.98	-8.04	-0.766
13.99	-8.10	-0.766
14.00	-8.17	-0.766
14.00	-8.24	-0.766
14.01	-8.31	-0.766
14.02	-8.37	-0.766
14.02	-8.44	-0.766
14.03	-8.50	-0.766
14.04	-8.57	-0.767
14.04	-8.64	-0.767
14.05	-8.71	-0.766
14.06	-8.77	-0.767
14.06	-8.84	-0.767
14.07	-8.91	-0.767
14.08	-8.97	-0.767
14.08	-9.04	-0.767
14.09	-9.10	-0.767
14.10	-9.17	-0.767
14.10	-9.24	-0.767
14.11	-9.30	-0.767
14.12	-9.37	-0.767
14.12	-9.44	-0.767
14.13	-9.50	-0.767
[...]
18.68	-34.75	0.315
18.69	-34.68	0.315
18.70	-34.61	0.316
18.70	-34.55	0.316
18.71	-34.48	0.316
18.72	-34.42	0.317
18.72	-34.35	0.317
18.73	-34.29	0.317
18.74	-34.22	0.318
18.74	-34.16	0.318
18.75	-34.09	0.318
18.76	-34.02	0.318
18.76	-33.96	0.318
18.77	-33.89	0.319
18.78	-33.83	0.319
18.78	-33.76	0.319
18.79	-33.70	0.319
18.80	-33.63	0.319
18.80	-33.57	0.320
18.81	-33.50	0.320
18.82	-33.43	0.320
18.82	-33.37	0.321
18.83	-33.30	0.321
18.84	-33.24	0.321
18.84	-33.17	0.321
18.85	-33.11	0.322
18.86	-33.04	0.322
18.86	-32.97	0.322
18.87	-32.91	0.322
18.88	-32.84	0.322
18.88	-32.78	0.323
18.89	-32.71	0.323
18.90	-32.64	0.323
18.90	-32.58	0.323
18.91	-32.51	0.323
18.92	-32.45	0.324
18.92	-32.38	0.324
18.93	-32.31	0.324
18.94	-32.25	0.324
18.94	-32.18	0.324
18.95	-32.12	0.325
18.96	-32.05	0.325
18.96	-31.99	0.325
18.97	-31.92	0.325
18.98	-31.85	0.325
18.98	-31.79	0.325
18.99	-31.72	0.326
19.00	-31.66	0.326
19.00	-31.59	0.326
19.01	-31.52	0.326
19.02	-31.46	0.326
19.02	-31.39	0.326
19.03	-31.32	0.327
19.04	-31.26	0.327
19.04	-31.19	0.327
19.05	-31.13	0.327
19.06	-31.06	0.327
19.06	-30.99	0.328
19.07	-30.93	0.328
19.08	-30.86	0.328
19.08	-30.79	0.328
19.09	-30.73	0.328
19.10	-30.66	0.328
19.10	-30.60	0.329
19.11	-30.53	0.329
19.12	-30.46	0.329
19.12	-30.40	0.329
19.13	-30.33	0.329
19.14	-30.27	0.330
19.14	-30.20	0.330
19.15	-30.13	0.330
19.16	-30.07	0.330
19.16	-30.00	0.330
19.17	-29.93	0.330
19.18	-29.87	0.331
19.18	-29.80	0.331
19.19	-29.73	0.331
19.20	-29.67	0.331
19.20	-29.60	0.331
19.21	-29.53	0.331
19.22	-29.47	0.332
19.22	-29.40	0.332
19.23	-29.34	0.332
19.24	-29.27	0.332
19.24	-29.20	0.332
19.25	-29.14	0.332
19.26	-29.07	0.332
19.26	-29.01	0.333
19.27	-28.94	0.333
19.28	-28.87	0.333
19.28	-28.81	0.333
19.29	-28.74	0.333
19.30	-28.67	0.333
19.30	-28.61	0.333
19.31	-28.54	0.334
19.32	-28.47	0.334
19.32	-28.41	0.334
19.33	-28.34	0.334
19.34	-28.27	0.334
19.34	-28.21	0.334
19.35	-28.14	0.334
19.36	-28.07	0.334
19.36	-28.01	0.334
19.37	-27.94	0.335
19.38	-27.88	0.335
19.38	-27.81	0.335
19.39	-27.74	0.335
19.40	-27.68	0.335
19.40	-27.61	0.335
19.41	-27.54	0.335
19.42	-27.48	0.335
19.42	-27.41	0.335
19.43	-27.34	0.336
19.44	-27.28	0.336
19.44	-27.21	0.336
19.45	-27.14	0.336
19.46	-27.08	0.336
19.46	-27.01	0.336
19.47	-26.94	0.336
19.48	-26.88	0.336
19.48	-26.81	0.336
19.49	-26.75	0.337
19.50	-26.68	0.337
19.50	-26.61	0.337
19.51	-26.55	0.337
19.52	-26.48	0.337
19.52	-26.41	0.337
19.53	-26.35	0.337
19.54	-26.28	0.337
19.54	-26.21	0.337
19.55	-26.15	0.337
19.56	-26.08	0.338
19.56	-26.01	0.338
19.57	-25.95	0.338
19.58	-25.88	0.338
19.58	-25.81	0.338
19.59	-25.75	0.338
19.60	-25.68	0.338
19.60	-25.61	0.338
19.61	-25.55	0.338
19.62	-25.48	0.338
19.62	-25.41	0.339
19.63	-25.35	0.339
19.64	-25.28	0.339
19.64	-25.22	0.339
19.65	-25.15	0.339
19.66	-25.08	0.339
19.66	-25.01	0.339
19.67	-24.95	0.339
19.68	-24.88	0.339
19.68	-24.82	0.339
19.69	-24.75	0.340
19.70	-24.68	0.340
19.70	-24.62	0.340
19.71	-24.55	0.340
19.72	-24.48	0.340
19.72	-24.42	0.340
19.73	-24.35	0.340
19.74	-24.28	0.340
19.74	-24.22	0.340
19.75	-24.15	0.340
19.76	-24.08	0.340
19.76	-24.02	0.340
19.77	-23.95	0.341
19.78	-23.88	0.341
19.78	-23.82	0.341
19.79	-23.75	0.341
19.80	-23.68	0.341
19.80	-23.62	0.341
19.81	-23.55	0.341
19.82	-23.48	0.341
19.82	-23.42	0.341
19.83	-23.35	0.341
19.84	-23.28	0.341
19.84	-23.22	0.341
19.85	-23.15	0.342
19.86	-23.08	0.342
19.86	-23.02	0.342
19.87	-22.95	0.342
19.88	-22.88	0.342
19.88	-22.82	0.342
19.89	-22.75	0.342
19.90	-22.69	0.342
19.90	-22.62	0.342
19.91	-22.55	0.342
19.92	-22.48	0.342
19.92	-22.42	0.342
19.93	-22.35	0.343
19.94	-22.28	0.343
19.94	-22.22	0.343
19.95	-22.15	0.343
19.96	-22.08	0.343
19.96	-22.02	0.343
19.97	-21.95	0.343
19.98	-21.89	0.343
19.98	-21.82	0.343
19.99	-21.75	0.343
20.00	-21.68	0.343
20.00	-21.62	0.344
20.01	-21.55	0.344
20.02	-21.49	0.344
20.02	-21.42	0.344
20.03	-21.35	0.344
20.04	-21.28	0.344
20.04	-21.22	0.344
20.05	-21.15	0.344
20.06	-21.08	0.344
20.06	-21.02	0.344
20.07	-20.95	0.344
20.08	-20.88	0.344
20.08	-20.82	0.345
20.09	-20.75	0.345
20.10	-20.68	0.345
20.10	-20.62	0.345
20.11	-20.55	0.345
20.12	-20.48	0.345
20.12	-20.42	0.345
20.13	-20.35	0.345
20.14	-20.29	0.345
20.14	-20.22	0.345
20.15	-20.15	0.345
20.16	-20.08	0.345
20.16	-20.02	0.346
20.17	-19.95	0.346
20.18	-19.88	0.346
20.18	-19.82	0.346
20.19	-19.75	0.346
20.20	-19.68	0.346
20.20	-19.62	0.346
20.21	-19.55	0.346
20.22	-19.49	0.346
20.22	-19.42	0.346
20.23	-19.35	0.346
20.24	-19.28	0.346
20.24	-19.22	0.346
20.25	-19.15	0.346
20.26	-19.08	0.347
20.26	-19.02	0.347
20.27	-18.95	0.347
20.28	-18.88	0.347
20.28	-18.82	0.347
20.29	-18.75	0.347
20.30	-18.68	0.347
20.30	-18.62	0.347
20.31	-18.55	0.347
20.32	-18.48	0.347
20.32	-18.42	0.347
20.33	-18.35	0.347
20.34	-18.28	0.347
20.34	-18.22	0.348
20.35	-18.15	0.348
20.36	-18.08	0.348
20.36	-18.02	0.348
20.37	-17.95	0.348
20.38	-17.88	0.348
20.38	-17.82	0.348
20.39	-17.75	0.348
20.40	-17.68	0.348
20.40	-17.62	0.348
20.41	-17.55	0.348
20.42	-17.48	0.348
20.42	-17.42	0.349
20.43	-17.35	0.349
20.44	-17.28	0.349
20.44	-17.22	0.349
20.45	-17.15	0.349
20.46	-17.08	0.349
20.46	-17.02	0.349
20.47	-16.95	0.349
20.48	-16.88	0.349
20.48	-16.82	0.349
20.49	-16.75	0.349
20.50	-16.68	0.349
20.50	-16.62	0.349
20.51	-16.55	0.349
20.52	-16.48	0.349
20.52	-16.42	0.349
20.53	-16.35	0.350
20.54	-16.28	0.350
20.54	-16.22	0.350
20.55	-16.15	0.350
20.56	-16.08	0.350
20.56	-16.02	0.350
20.57	-15.95	0.350
20.58	-15.88	0.350
20.58	-15.82	0.350
20.59	-15.75	0.350
20.60	-15.68	0.350
20.60	-15.62	0.350
20.61	-15.55	0.350
20.62	-15.48	0.351
20.62	-15.42	0.351
20.63	-15.35	0.351
20.64	-15.28	0.351
20.64	-15.21	0.351
20.65	-15.15	0.351
20.66	-15.08	0.351
20.66	-15.02	0.351
20.67	-14.95	0.351
20.68	-14.88	0.351
20.68	-14.82	0.351
20.69	-14.75	0.351
20.70	-14.68	0.351
20.70	-14.62	0.352
20.71	-14.55	0.352
20.72	-14.48	0.352
20.72	-14.42	0.352
20.73	-14.35	0.352
20.74	-14.28	0.352
20.74	-14.21	0.352
20.75	-14.15	0.352
20.76	-14.08	0.352
20.76	-14.02	0.352
20.77	-13.95	0.352
20.78	-13.88	0.352
20.78	-13.82	0.352
20.79	-13.75	0.353
20.80	-13.68	0.353
20.80	-13.62	0.353
20.81	-13.55	0.353
20.82	-13.48	0.353
20.82	-13.41	0.353
20.83	-13.35	0.353
20.84	-13.28	0.353
20.84	-13.22	0.353
20.85	-13.15	0.353
20.86	-13.08	0.353
20.86	-13.02	0.353
20.87	-12.95	0.353
20.88	-12.88	0.353
20.88	-12.82	0.353
20.89	-12.75	0.354
20.90	-12.68	0.354
20.90	-12.62	0.354
20.91	-12.55	0.354
20.92	-12.48	0.354
20.92	-12.41	0.354
20.93	-12.35	0.354
20.94	-12.28	0.354
20.94	-12.21	0.354
20.95	-12.15	0.354
20.96	-12.08	0.354
20.96	-12.01	0.354
20.97	-11.95	0.354
20.98	-11.88	0.355
20.98	-11.82	0.355
20.99	-11.75	0.355
21.00	-11.68	0.355
21.00	-11.61	0.355
21.01	-11.55	0.355
21.02	-11.48	0.355
21.02	-11.41	0.355
21.03	-11.35	0.355
21.04	-11.28	0.355
21.04	-11.21	0.355
21.05	-11.15	0.355
21.06	-11.08	0.355
21.06	-11.01	0.355
21.07	-10.95	0.356
21.08	-10.88	0.356
21.08	-10.81	0.356
21.09	-10.75	0.356
21.10	-10.68	0.356
21.10	-10.61	0.356
21.11	-10.55	0.356
21.12	-10.48	0.356
21.12	-10.41	0.356
21.13	-10.35	0.356
21.14	-10.28	0.356
21.14	-10.21	0.357
21.15	-10.15	0.357
21.16	-10.08	0.357
21.16	-10.01	0.357
21.17	-9.95	0.357
21.18	-9.88	0.357
21.18	-9.81	0.357
21.19	-9.75	0.357
21.20	-9.68	0.357
21.20	-9.61	0.357
21.21	-9.55	0.357
21.22	-9.48	0.358
21.22	-9.41	0.358
21.23	-9.35	0.358
21.24	-9.28	0.358
21.24	-9.21	0.358
21.25	-9.15	0.358
21.26	-9.08	0.358
21.26	-9.01	0.358
21.27	-8.95	0.358
21.28	-8.88	0.358
21.28	-8.81	0.358
21.29	-8.75	0.358
21.30	-8.68	0.359
21.30	-8.61	0.359
21.31	-8.55	0.359
21.32	-8.48	0.359
21.32	-8.41	0.359
21.33	-8.35	0.359
21.34	-8.28	0.359
21.34	-8.21	0.359
21.35	-8.15	0.359
21.36	-8.08	0.359
21.36	-8.01	0.360
21.37	-7.94	0.360
21.38	-7.88	0.360
21.38	-7.81	0.360
21.39	-7.74	0.360
21.40	-7.68	0.360
21.40	-7.61	0.360
21.41	-7.55	0.360
21.42	-7.48	0.360
21.42	-7.41	0.361
21.43	-7.35	0.361
21.44	-7.28	0.361
21.44	-7.21	0.361
21.45	-7.15	0.361
21.46	-7.08	0.361
21.46	-7.01	0.362
21.47	-6.95	0.362
21.48	-6.88	0.362
21.48	-6.81	0.362
21.49	-6.74	0.362
21.50	-6.68	0.362
21.50	-6.61	0.362
21.51	-6.54	0.362
21.52	-6.48	0.362
21.52	-6.41	0.362
21.53	-6.35	0.363
21.54	-6.28	0.363
21.54	-6.21	0.363
21.55	-6.15	0.363
21.56	-6.08	0.363
21.56	-6.01	0.363
21.57	-5.94	0.363
21.58	-5.88	0.363
21.58	-5.81	0.364
21.59	-5.74	0.364
21.60	-5.68	0.364
21.60	-5.61	0.364
21.61	-5.54	0.364
21.62	-5.48	0.364
21.62	-5.41	0.364
21.63	-5.35	0.365
21.64	-5.28	0.365
21.64	-5.21	0.365
21.65	-5.15	0.365
21.66	-5.08	0.365
21.66	-5.01	0.366
21.67	-4.95	0.366
21.68	-4.88	0.366
21.68	-4.81	0.366
21.69	-4.75	0.367
21.70	-4.68	0.367
21.70	-4.61	0.367
21.71	-4.54	0.367
21.72	-4.48	0.368
21.72	-4.41	0.369
21.73	-4.35	0.369
21.74	-4.28	0.369
21.74	-4.21	0.370
21.75	-4.14	0.370
21.76	-4.08	0.370
21.76	-4.01	0.371
21.77	-3.94	0.372
21.78	-3.88	0.372
21.78	-3.81	0.373
21.79	-3.74	0.373
21.80	-3.68	0.374
21.80	-3.61	0.375
21.81	-3.55	0.376
21.82	-3.48	0.378
21.82	-3.41	0.379
21.83	-3.35	0.381
21.84	-3.28	0.382
21.84	-3.21	0.384
21.85	-3.15	0.387
21.86	-3.08	0.388
21.86	-3.01	0.390
21.87	-2.95	0.394
21.88	-2.88	0.396
21.88	-2.81	0.401
21.89	-2.75	0.407
21.90	-2.68	0.410
21.90	-2.62	0.413
21.91	-2.55	0.418
21.92	-2.48	0.423
21.92	-2.42	0.431
21.93	-2.35	0.442
21.94	-2.29	0.449
21.94	-2.22	0.459
21.95	-2.15	0.472
21.96	-2.09	0.485
21.96	-2.02	0.504
21.97	-1.96	0.527
21.98	-1.90	0.554
21.98	-1.83	0.589
21.99	-1.77	0.634
22.00	-1.71	0.691
22.00	-1.65	0.765
22.01	-1.59	0.857
22.02	-1.53	0.976
22.02	-1.48	1.121
22.03	-1.43	1.289
22.04	-1.38	1.480
22.04	-1.34	1.682
22.05	-1.30	1.886
22.06	-1.26	2.089
22.06	-1.22	2.295
22.07	-1.19	2.502
22.08	-1.16	2.702
22.08	-1.13	2.895
22.09	-1.10	3.082
22.10	-1.07	3.278
22.10	-1.05	3.462
22.11	-1.02	3.633
22.12	-0.99	3.798
22.12	-0.97	3.957
22.13	-0.94	4.111
22.14	-0.91	4.259
22.14	-0.89	4.405
22.15	-0.86	4.549
22.16	-0.83	4.691
22.16	-0.81	4.828
22.17	-0.78	4.962
22.18	-0.75	5.097
22.18	-0.72	5.230
22.19	-0.69	5.362
22.20	-0.66	5.488
22.20	-0.63	5.612
22.21	-0.60	5.737
22.22	-0.57	5.861
22.22	-0.54	5.982
22.23	-0.51	6.109
22.24	-0.47	6.249
22.24	-0.44	6.431
22.25	-0.41	6.718
22.26	-0.39	7.079
22.26	-0.37	7.359
22.27	-0.35	7.522
22.28	-0.33	7.655
22.28	-0.31	7.794
22.29	-0.29	7.952
22.30	-0.27	8.120
22.30	-0.25	8.279
22.31	-0.22	8.428
22.32	-0.20	8.575
22.32	-0.17	8.736
22.33	-0.15	8.909
22.34	-0.13	9.067
22.34	-0.10	9.187
22.35	-0.07	9.289
22.36	-0.05	9.387
22.36	-0.02	9.481
22.37	0.01	9.578
22.38	0.05	9.670
22.38	0.08	9.758
22.39	0.12	9.836
22.40	0.15	9.903
22.40	0.19	9.960
22.41	0.23	10.004
22.42	0.27	10.033
22.42	0.32	10.042
22.43	0.36	10.038
22.44	0.41	10.026
22.44	0.46	10.017
22.45	0.51	10.021
22.46	0.57	10.039
22.46	0.62	10.070
22.47	0.68	10.109
22.48	0.73	10.151
22.48	0.78	10.199
22.49	0.84	10.249
22.50	0.89	10.293
22.50	0.95	10.335
22.51	1.00	10.377
22.52	1.06	10.415
22.52	1.11	10.448
22.53	1.17	10.480
22.54	1.23	10.507
22.54	1.28	10.525
22.55	1.34	10.531
22.56	1.40	10.528
22.56	1.46	10.517
22.57	1.52	10.493
22.58	1.58	10.453
22.58	1.65	10.401
22.59	1.71	10.342
22.60	1.78	10.285
22.60	1.85	10.219
22.61	1.92	10.138
22.62	1.99	10.041
22.62	2.07	9.925
22.63	2.15	9.784
22.64	2.23	9.630
22.64	2.31	9.469
22.65	2.40	9.288
22.66	2.49	9.012
22.66	2.59	8.668
22.67	2.69	8.362
22.68	2.80	8.083
22.68	2.91	7.812
22.69	3.02	7.538
22.70	3.13	7.249
22.70	3.25	6.942
22.71	3.37	6.619
22.72	3.50	6.279
22.72	3.63	5.923
22.73	3.76	5.552
22.74	3.89	5.173
22.74	4.03	4.789
22.75	4.17	4.406
22.76	4.31	4.058
22.76	4.46	3.779
22.77	4.60	3.554
22.78	4.73	3.368
22.78	4.87	3.204
22.79	5.00	3.058
22.80	5.13	2.926
22.80	5.26	2.803
22.81	5.38	2.687
22.82	5.50	2.583
22.82	5.61	2.484
22.83	5.73	2.386
22.84	5.84	2.298
22.84	5.95	2.213
22.85	6.06	2.136
22.86	6.16	2.062
22.86	6.27	1.988
22.87	6.37	1.919
22.88	6.47	1.857
22.88	6.56	1.796
22.89	6.66	1.737
22.90	6.76	1.683
22.90	6.85	1.631
22.91	6.94	1.583
22.92	7.03	1.536
22.92	7.12	1.491
22.93	7.21	1.451
22.94	7.29	1.410
22.94	7.38	1.373
22.95	7.46	1.342
22.96	7.55	1.311
22.96	7.63	1.271
22.97	7.71	1.233
22.98	7.79	1.211
22.98	7.87	1.195
22.99	7.95	1.168
23.00	8.03	1.139
23.00	8.11	1.113
23.01	8.19	1.091
23.02	8.27	1.072
23.02	8.34	1.055
23.03	8.42	1.035
23.04	8.49	1.017
23.04	8.57	1.000
23.05	8.64	0.985
23.06	8.72	0.971
23.06	8.79	0.957
23.07	8.87	0.942
23.08	8.94	0.929
23.08	9.01	0.919
23.09	9.08	0.909
23.10	9.16	0.896
23.10	9.23	0.885
23.11	9.30	0.878
23.12	9.37	0.867
23.12	9.44	0.858
23.13	9.51	0.851
23.14	9.58	0.844
23.14	9.65	0.835
23.15	9.72	0.827
23.16	9.79	0.820
23.16	9.86	0.815
23.17	9.93	0.810
23.18	10.00	0.803
23.18	10.07	0.800
23.19	10.14	0.795
23.20	10.21	0.788
23.20	10.28	0.783
23.21	10.35	0.780
23.22	10.42	0.776
23.22	10.49	0.772
23.23	10.55	0.770
23.24	10.62	0.765
23.24	10.69	0.763
23.25	10.76	0.762
23.26	10.83	0.757
23.26	10.90	0.754
23.27	10.96	0.751
23.28	11.03	0.749
23.28	11.10	0.747
23.29	11.17	0.746
23.30	11.24	0.744
23.30	11.30	0.742
23.31	11.37	0.739
23.32	11.44	0.737
23.32	11.51	0.737
23.33	11.57	0.735
23.34	11.64	0.734
23.34	11.71	0.733
23.35	11.78	0.732
23.36	11.84	0.730
23.36	11.91	0.727
23.37	11.98	0.727
23.38	12.05	0.726
23.38	12.11	0.726
23.39	12.18	0.724
23.40	12.25	0.724
23.40	12.31	0.723
23.41	12.38	0.723
23.42	12.45	0.723
23.42	12.52	0.722
23.43	12.58	0.722
23.44	12.65	0.722
23.44	12.72	0.721
23.45	12.78	0.720
23.46	12.85	0.719
23.46	12.92	0.719
23.47	12.99	0.718
23.48	13.05	0.718
23.48	13.12	0.718
23.49	13.19	0.718
23.50	13.25	0.717
23.50	13.32	0.717
23.51	13.39	0.717
23.52	13.46	0.716
23.52	13.52	0.716
23.53	13.59	0.716
23.54	13.66	0.716
23.54	13.72	0.715
23.55	13.79	0.715
23.56	13.86	0.715
23.56	13.92	0.715
23.57	13.99	0.714
23.58	14.06	0.714
23.58	14.12	0.714
23.59	14.19	0.714
23.60	14.26	0.714
23.60	14.32	0.714
23.61	14.39	0.713
23.62	14.46	0.713
23.62	14.52	0.713
23.63	14.59	0.713
23.64	14.66	0.713
23.64	14.73	0.713
23.65	14.79	0.712
23.66	14.86	0.712
23.66	14.93	0.712
23.67	14.99	0.712
23.68	15.06	0.712
23.68	15.13	0.712
23.69	15.19	0.711
23.70	15.26	0.711
23.70	15.33	0.711
23.71	15.39	0.711
23.72	15.46	0.711
23.72	15.53	0.711
23.73	15.59	0.711
23.74	15.66	0.710
23.74	15.73	0.710
23.75	15.79	0.710
23.76	15.86	0.710
23.76	15.93	0.710
23.77	15.99	0.710
23.78	16.06	0.709
23.78	16.13	0.709
23.79	16.19	0.709
23.80	16.26	0.709
23.80	16.33	0.709
23.81	16.39	0.709
23.82	16.46	0.709
23.82	16.53	0.709
23.83	16.59	0.708
23.84	16.66	0.708
23.84	16.73	0.708
23.85	16.79	0.708
23.86	16.86	0.708
23.86	16.93	0.708
23.87	17.00	0.708
23.88	17.06	0.708
23.88	17.13	0.708
23.89	17.20	0.708
23.90	17.26	0.708
23.90	17.33	0.708
23.91	17.40	0.707
23.92	17.46	0.707
23.92	17.53	0.707
23.93	17.60	0.707
23.94	17.66	0.707
23.94	17.73	0.707
23.95	17.80	0.707
23.96	17.86	0.707
23.96	17.93	0.707
23.97	18.00	0.707
23.98	18.06	0.707
23.98	18.13	0.707
23.99	18.20	0.707
24.00	18.26	0.707
24.00	18.33	0.707
24.01	18.40	0.707
24.02	18.46	0.707
24.02	18.53	0.707
24.03	18.60	0.706
24.04	18.66	0.706
24.04	18.73	0.706
24.05	18.80	0.706
24.06	18.86	0.706
24.06	18.93	0.706
24.07	19.00	0.706
24.08	19.06	0.706
24.08	19.13	0.706
24.09	19.20	0.706
24.10	19.26	0.706
24.10	19.33	0.706
24.11	19.40	0.706
24.12	19.47	0.706
24.12	19.53	0.706
24.13	19.60	0.706
24.14	19.67	0.706
24.14	19.73	0.706
24.15	19.80	0.706
24.16	19.87	0.706
24.16	19.93	0.706
24.17	20.00	0.706
24.18	20.07	0.706
24.18	20.13	0.706
24.19	20.20	0.706
24.20	20.27	0.706
24.20	20.33	0.706
24.21	20.40	0.706
24.22	20.47	0.706
24.22	20.53	0.706
24.23	20.60	0.706
24.24	20.67	0.706
24.24	20.73	0.706
24.25	20.80	0.706
24.26	20.87	0.706
24.26	20.93	0.706
24.27	21.00	0.706
24.28	21.07	0.706
24.28	21.13	0.706
24.29	21.20	0.706
24.30	21.27	0.706
24.30	21.33	0.706
24.31	21.40	0.706
24.32	21.47	0.706
24.32	21.53	0.706
24.33	21.60	0.706
24.34	21.67	0.706
24.34	21.73	0.706
24.35	21.80	0.706
24.36	21.87	0.706
24.36	21.93	0.706
24.37	22.00	0.706
24.38	22.07	0.706
24.38	22.13	0.706
24.39	22.20	0.706
24.40	22.27	0.706
24.40	22.33	0.706
24.41	22.40	0.706
24.42	22.47	0.706
24.42	22.54	0.706
24.43	22.60	0.706
24.44	22.67	0.706
24.44	22.74	0.706
24.45	22.80	0.706
24.46	22.87	0.706
24.46	22.94	0.706
24.47	23.00	0.706
24.48	23.07	0.706
24.48	23.14	0.706
24.49	23.20	0.706
24.50	23.27	0.706
24.50	23.34	0.706
24.51	23.40	0.706
24.52	23.47	0.706
24.52	23.54	0.706
24.53	23.60	0.706
24.54	23.67	0.706
24.54	23.74	0.706
24.55	23.80	0.706
24.56	23.87	0.706
24.56	23.94	0.706
24.57	24.00	0.706
24.58	24.07	0.706
24.58	24.14	0.706
24.59	24.20	0.706
24.60	24.27	0.706
24.60	24.34	0.706
24.61	24.40	0.706
24.62	24.47	0.706
24.62	24.54	0.706
24.63	24.60	0.706
24.64	24.67	0.706
24.64	24.74	0.706
24.65	24.80	0.706
24.66	24.87	0.706
24.66	24.94	0.706
24.67	25.00	0.706
24.68	25.07	0.706
24.68	25.14	0.706
24.69	25.21	0.706
24.70	25.27	0.706
24.70	25.34	0.706
24.71	25.40	0.706
24.72	25.47	0.706
24.72	25.54	0.707
24.73	25.61	0.707
24.74	25.67	0.707
24.74	25.74	0.707
24.75	25.81	0.707
24.76	25.87	0.707
24.76	25.94	0.707
24.77	26.01	0.707
24.78	26.07	0.707
24.78	26.14	0.707
24.79	26.21	0.707
24.80	26.27	0.707
24.80	26.34	0.707
24.81	26.41	0.707
24.82	26.47	0.707
24.82	26.54	0.707
24.83	26.60	0.707
24.84	26.67	0.707
24.84	26.74	0.707
24.85	26.81	0.707
24.86	26.87	0.707
24.86	26.94	0.707
24.87	27.01	0.707
24.88	27.07	0.707
24.88	27.14	0.707
24.89	27.21	0.707
24.90	27.27	0.707
24.90	27.34	0.707
24.91	27.41	0.707
24.92	27.47	0.707
24.92	27.54	0.707
24.93	27.61	0.707
24.94	27.67	0.707
24.94	27.74	0.707
24.95	27.81	0.707
24.96	27.88	0.707
24.96	27.94	0.707
24.97	28.01	0.707
24.98	28.08	0.707
24.98	28.14	0.707
24.99	28.21	0.707
25.00	28.28	0.707
25.00	28.34	0.707
25.01	28.41	0.707
25.02	28.48	0.707
25.02	28.54	0.707
25.03	28.61	0.707
25.04	28.68	0.707
25.04	28.74	0.707
25.05	28.81	0.707
25.06	28.88	0.707
25.06	28.94	0.707
25.07	29.01	0.707
25.08	29.08	0.707
25.08	29.14	0.707
25.09	29.21	0.707
25.10	29.28	0.707
25.10	29.34	0.707
25.11	29.41	0.708
25.12	29.48	0.708
25.12	29.54	0.708
25.13	29.61	0.708
25.14	29.68	0.708
25.14	29.74	0.708
25.15	29.81	0.708
25.16	29.88	0.708
25.16	29.94	0.708
25.17	30.01	0.708
25.18	30.08	0.708
25.18	30.14	0.708
25.19	30.21	0.708
25.20	30.28	0.708
25.20	30.34	0.708
25.21	30.41	0.708
25.22	30.48	0.708
25.22	30.54	0.708
25.23	30.61	0.708
25.24	30.68	0.708
25.24	30.74	0.708
25.25	30.81	0.709
25.26	30.88	0.709
25.26	30.95	0.709
25.27	31.01	0.709
25.28	31.08	0.709
25.28	31.15	0.709
25.29	31.21	0.709
25.30	31.28	0.709
25.30	31.34	0.709
25.31	31.41	0.709
25.32	31.48	0.709
25.32	31.55	0.709
25.33	31.61	0.709
25.34	31.68	0.709
25.34	31.75	0.709
25.35	31.81	0.709
25.36	31.88	0.709
25.36	31.95	0.709
25.37	32.01	0.709
25.38	32.08	0.709
25.38	32.15	0.709
25.39	32.21	0.709
25.40	32.28	0.709
25.40	32.35	0.709
25.41	32.41	0.709
25.42	32.48	0.709
25.42	32.55	0.709
25.43	32.61	0.710
25.44	32.68	0.710
25.44	32.75	0.710
25.45	32.81	0.710
25.46	32.88	0.710
25.46	32.95	0.710
25.47	33.01	0.710
25.48	33.08	0.710
25.48	33.15	0.710
25.49	33.21	0.710
25.50	33.28	0.710
25.50	33.35	0.710
25.51	33.41	0.710
25.52	33.48	0.710
25.52	33.55	0.710
25.53	33.61	0.710
25.54	33.68	0.710
25.54	33.75	0.710
25.55	33.81	0.710
25.56	33.88	0.710
25.56	33.95	0.710
25.57	34.02	0.710
25.58	34.08	0.710
25.58	34.15	0.710
25.59	34.22	0.710
25.60	34.28	0.710
25.60	34.35	0.710
25.61	34.41	0.710
25.62	34.48	0.710
25.62	34.55	0.710
25.63	34.62	0.710
25.64	34.68	0.710
25.64	34.75	0.710
25.65	34.82	0.710
25.66	34.88	0.710
25.66	34.95	0.710
25.67	35.02	0.711
25.68	35.08	0.711
25.68	35.15	0.711
25.69	35.22	0.710
25.70	35.28	0.711
25.70	35.35	0.711
25.71	35.42	0.711
25.72	35.48	0.711
25.72	35.55	0.711
25.73	35.62	0.711
25.74	35.68	0.711
25.74	35.75	0.711
25.75	35.82	0.711
25.76	35.88	0.711
25.76	35.95	0.711
25.77	36.02	0.711
25.78	36.08	0.711
25.78	36.15	0.711
25.79	36.22	0.711
25.80	36.28	0.711
25.80	36.35	0.711
25.81	36.42	0.711
25.82	36.48	0.711
25.82	36.55	0.711
25.83	36.62	0.711
25.84	36.68	0.711
25.84	36.75	0.711
25.85	36.82	0.711
25.86	36.88	0.711
25.86	36.95	0.711
25.87	37.02	0.711
25.88	37.08	0.711
25.88	37.15	0.711
25.89	37.22	0.711
25.90	37.28	0.711
25.90	37.35	0.711
25.91	37.42	0.711
25.92	37.49	0.711
25.92	37.55	0.711
25.93	37.62	0.711
25.94	37.68	0.711
25.94	37.75
25.95	37.82
25.96	37.89
25.96	37.95
25.97	38.02
25.98	38.09
25.98	38.15
25.99
25.99