File: Data/2025_02_13_Fructose_Again_DSC.txt
Filename	2025_02_13_Fructose_Again_DSC
Instrument name	DSC2A-00468 (192.168.1.100)
Operator	JLY
rundate	2/13/2025
Sample name	2025_02_13_Fructose_Again_DSC
proceduresegments	Data Off ; Equilibrate 30.00 °C; Data On ; Ramp 5.00 °C/min to 150.00 °C
[File Parameters]
Run date	2/13/2025 6:56:39 PM
Trios version	5.1.1.46572
Original File Name
Current File Name	D:\DSC2500\CHM343\2025_02_13_Fructose_Again_DSC.tri
[Procedure]
Procedure Name	Fructose Melting
Sample Name	2025_02_13_Fructose_Again_DSC
Sample Mass	14.02 mg
Reference Sample Mass	0 mg
Pan Mass	53.67 mg
Pan Number	27
Reference Pan Mass	54 mg
Reference Pan Number	19
Pan Type	Tzero Aluminum Hermetic
Comments	Al Hermetic Sealed Pan, with ref Al pan
Project Name
Operator	JLY
Test	Custom
Unload Max Temperature	30
Unload Min Temperature	30
Load Max Temperature	30
Load Min Temperature	30
Stop on Gas Flow Error	Yes
[Signal List]
Signal #1	Time (min)
Signal #2	Temperature (°C)
Signal #3	Heat Flow (mW)
Signal #4	Delta T (µV)
Signal #5	Delta Tzero (µV)
Signal #6	Tzero Temperature (°C)
Signal #7	Cell Purge (mL/min)
Signal #8	Heater Temp (°C)
Signal #9	Power Delivered (W)
Signal #10	Reference Junction Temperature (°C)
Signal #11	Flange Temperature (°C)
Signal #12	Heat Flow Phase (rad)
Signal #13	Total Heat Capacity (J/°C)
Signal #14	Heat Capacity (J/°C)
[Configuration]
Company Name	ASU
Instrument Name	DSC2A-00468
Instrument Type	DSC2500
Serial Number	DSC2A-00468
IP	192.168.1.100
Location of Instrument	MRRC
DisplayType	Unknown
Sample Interval 	0.1 s/pt
Selected Heat Flow	T4P
Exotherm Direction	Down
Cell Serial	DRC2-00792
Lid Type	Standard
Cooler	RCS 90
Leave Cooler on at End of Sequence	On
Gas 2	Nitrogen
Gas Selected	Channel 1
Flow Rate	50 mL/min
Secondary Purge	On
Licensed Heat Flow	Heat Flow T4P
Modulation Licensed	Yes
[Versions]
Common IDD Version	1
Cortex Version	VER 2.10.2.31
Driver	5.0.0.6
GDM Version	1.0.3.3
TouchscreenVersion	1.0.0.16145
FEP Version	1.2.1.21
FEP Bootloader	2.0.0.5
AutoSampler Version	2.1.1.26
Auto Sampler Bootloader	2.0.0.5
FCM Version	1.1.0.3
FCM Bootloader	2.0.0.5
[Experiment Logs]
Experiment Log Entry # 1	Data On set to 0
Experiment Log Entry # 3	Equilibrate Segment 30 (C) Started
Experiment Log Entry # 5	Air Cool is off.
Experiment Log Entry # 7	Data On set to 1
Experiment Log Entry # 9	Ramp Segment 5 C/min to 150 Started
[Method Log]
Method Log Entry # 1	Data Off
Method Log Entry # 2	Equilibrate 30 °C
Method Log Entry # 3	Data On
Method Log Entry # 4	(Ramp 45512) Ramp 5 °C/minute to 150 °C
Cell Serial	DRC2-00792
[T1 Calibration]
Slope	-0.008529666
Offset	9.636258
Initial Temperature	98.23
GUID	f8bfdadc-4977-4fdf-ba6d-0ba9134940c3
[TZero Calibration]
Date Applied	11/29/2022 4:06:13 PM
Description	From -89.059 °C to 396.009 °C at 20.000°C/min
Gas Type	Nitrogen
Pan Type	None
Source Files 1	C:\Users\yargerlab\Desktop\DSC Data\General\TZero_calibration_11_29_22_2nd(2).tri
Source Files 2	C:\Users\yargerlab\Desktop\DSC Data\General\TZero_calibration_11_29_22_2nd(3).tri
Delta T Offset	13.05235
Delta T Slope	-0.007271007
Delta T0 Offset	-13.69128
Delta T0 Slope	0.06063341
[Temperature Calibration]
Date Applied	11/29/2022 7:12:28 PM
Description	From 106.590 °C to 186.590 °C at 10.000°C/min
Gas Type	Nitrogen
Pan Type	Tzero Aluminum Hermetic
Source Files 1	C:\Users\yargerlab\Desktop\DSC Data\General\Indium(6).tri
Measured 1	157.391
Known 1	156.598
[Cell Constant Calibration]
Date Applied	11/29/2022 7:12:29 PM
Description	From 106.590 °C to 186.590 °C at 10.000°C/min
Gas Type	Nitrogen
Pan Type	Tzero Aluminum Hermetic
Source Files 1	C:\Users\yargerlab\Desktop\DSC Data\General\Indium(6).tri
T4P KCell	1.006051
Onset Slope	63.26126 mW/°C
[Direct Cp Calibration]
Date Applied	11/30/2022 11:04:51 AM
Description	From -79.983 °C to 298.409 °C at 10.000°C/min
Gas Type	Nitrogen
Pan Type	Tzero Aluminum Hermetic
Source Files 1	C:\Users\yargerlab\Desktop\DSC Data\General\Sapphire_Heat_Capacity_11_30_22.tri
[Rev Cp Calibration]
Date Applied	11/30/2022 1:58:51 PM
Description	From -79.996 °C to 292.812 °C at 3.000°C/min
Gas Type	Nitrogen
Pan Type	Tzero Aluminum Hermetic
Source Files 1	C:\Users\yargerlab\Desktop\DSC Data\General\Sapphire_MDSC_Calibration_11_30_22.tri
[step]
Ramp 5.00 °C/min to 150.00 °C
Time	Temperature	Heat Flow (Normalized)
min	°C	W/g
0.00	30.08	-0.017
0.02	30.07	-0.017
0.03	30.08	-0.015
0.05	30.08	-0.014
0.07	30.09	-0.011
0.08	30.10	-0.008
0.10	30.13	-0.003
0.12	30.16	0.004
0.13	30.20	0.012
0.15	30.24	0.022
0.17	30.30	0.032
0.18	30.35	0.041
0.20	30.41	0.049
0.22	30.47	0.057
0.23	30.54	0.064
0.25	30.60	0.070
0.27	30.67	0.075
0.28	30.74	0.080
0.30	30.81	0.084
0.32	30.89	0.088
0.33	30.96	0.092
0.35	31.04	0.095
0.37	31.12	0.097
0.38	31.19	0.100
0.40	31.27	0.101
0.42	31.35	0.104
0.43	31.43	0.105
0.45	31.51	0.107
0.47	31.59	0.108
0.48	31.67	0.109
0.50	31.75	0.110
0.52	31.83	0.111
0.53	31.91	0.112
0.55	31.99	0.112
0.57	32.07	0.113
0.58	32.16	0.113
0.60	32.24	0.113
0.62	32.32	0.114
0.63	32.40	0.114
0.65	32.48	0.114
0.67	32.57	0.115
0.68	32.65	0.115
0.70	32.73	0.115
0.72	32.81	0.115
0.73	32.90	0.115
0.75	32.98	0.115
0.77	33.06	0.115
0.78	33.14	0.116
0.80	33.23	0.116
0.82	33.31	0.116
0.83	33.39	0.116
0.85	33.47	0.116
0.87	33.56	0.116
0.88	33.64	0.116
0.90	33.72	0.116
0.92	33.81	0.116
0.93	33.89	0.117
0.95	33.97	0.117
0.97	34.05	0.117
0.98	34.14	0.117
1.00	34.22	0.117
1.02	34.30	0.117
1.03	34.39	0.117
1.05	34.47	0.117
1.07	34.55	0.117
1.08	34.64	0.117
1.10	34.72	0.117
1.12	34.80	0.118
1.13	34.88	0.118
1.15	34.97	0.118
1.17	35.05	0.118
1.18	35.13	0.118
1.20	35.22	0.118
1.22	35.30	0.118
1.23	35.38	0.118
1.25	35.47	0.118
1.27	35.55	0.118
1.28	35.63	0.118
1.30	35.72	0.118
1.32	35.80	0.118
1.33	35.88	0.118
1.35	35.97	0.118
1.37	36.05	0.118
1.38	36.13	0.118
1.40	36.21	0.118
1.42	36.30	0.119
1.43	36.38	0.119
1.45	36.46	0.119
1.47	36.55	0.119
1.48	36.63	0.119
1.50	36.71	0.119
1.52	36.80	0.119
1.53	36.88	0.119
1.55	36.96	0.119
1.57	37.05	0.119
1.58	37.13	0.119
1.60	37.21	0.119
1.62	37.30	0.119
1.63	37.38	0.119
1.65	37.46	0.119
1.67	37.55	0.119
1.68	37.63	0.119
1.70	37.71	0.119
1.72	37.80	0.119
1.73	37.88	0.119
1.75	37.96	0.119
1.77	38.05	0.119
1.78	38.13	0.119
1.80	38.21	0.119
1.82	38.30	0.119
1.83	38.38	0.119
1.85	38.46	0.119
1.87	38.55	0.119
1.88	38.63	0.119
1.90	38.71	0.119
1.92	38.80	0.120
1.93	38.88	0.120
1.95	38.96	0.120
1.97	39.05	0.120
1.98	39.13	0.120
2.00	39.21	0.120
2.02	39.30	0.120
2.03	39.38	0.120
2.05	39.46	0.120
2.07	39.55	0.120
2.08	39.63	0.120
2.10	39.71	0.120
2.12	39.80	0.120
2.13	39.88	0.120
2.15	39.96	0.120
2.17	40.05	0.120
2.18	40.13	0.120
2.20	40.21	0.120
2.22	40.30	0.120
2.23	40.38	0.120
2.25	40.46	0.120
2.27	40.55	0.120
2.28	40.63	0.120
2.30	40.71	0.120
2.32	40.80	0.120
2.33	40.88	0.120
2.35	40.96	0.120
2.37	41.05	0.120
2.38	41.13	0.120
2.40	41.21	0.120
2.42	41.30	0.120
2.43	41.38	0.120
2.45	41.46	0.120
2.47	41.55	0.120
2.48	41.63	0.120
2.50	41.71	0.120
2.52	41.80	0.120
2.53	41.88	0.120
2.55	41.96	0.121
2.57	42.05	0.121
2.58	42.13	0.121
2.60	42.22	0.121
2.62	42.30	0.121
2.63	42.38	0.121
2.65	42.46	0.121
2.67	42.55	0.121
2.68	42.63	0.121
2.70	42.72	0.121
2.72	42.80	0.121
2.73	42.88	0.121
2.75	42.97	0.121
2.77	43.05	0.121
2.78	43.13	0.121
2.80	43.22	0.121
2.82	43.30	0.121
2.83	43.38	0.121
2.85	43.46	0.121
2.87	43.55	0.121
2.88	43.63	0.121
2.90	43.72	0.121
2.92	43.80	0.121
2.93	43.88	0.121
2.95	43.97	0.121
2.97	44.05	0.121
2.98	44.13	0.121
3.00	44.21	0.121
3.02	44.30	0.121
3.03	44.38	0.121
3.05	44.46	0.121
3.07	44.55	0.121
3.08	44.63	0.121
3.10	44.72	0.121
3.12	44.80	0.121
3.13	44.88	0.121
3.15	44.97	0.121
3.17	45.05	0.121
3.18	45.13	0.121
3.20	45.21	0.122
3.22	45.30	0.122
3.23	45.38	0.122
3.25	45.47	0.122
3.27	45.55	0.122
3.28	45.63	0.122
3.30	45.72	0.122
3.32	45.80	0.122
3.33	45.88	0.122
3.35	45.97	0.122
3.37	46.05	0.122
3.38	46.13	0.122
3.40	46.22	0.122
3.42	46.30	0.122
3.43	46.38	0.122
3.45	46.47	0.122
3.47	46.55	0.122
3.48	46.63	0.122
3.50	46.71	0.122
3.52	46.80	0.122
3.53	46.88	0.122
3.55	46.97	0.122
3.57	47.05	0.122
3.58	47.13	0.122
3.60	47.22	0.122
3.62	47.30	0.122
3.63	47.38	0.122
3.65	47.47	0.122
3.67	47.55	0.122
3.68	47.63	0.122
3.70	47.72	0.122
3.72	47.80	0.123
3.73	47.88	0.123
3.75	47.97	0.123
3.77	48.05	0.123
3.78	48.13	0.123
3.80	48.22	0.123
3.82	48.30	0.123
3.83	48.38	0.123
3.85	48.47	0.123
3.87	48.55	0.123
3.88	48.63	0.123
3.90	48.72	0.123
3.92	48.80	0.123
3.93	48.88	0.123
3.95	48.97	0.123
3.97	49.05	0.123
3.98	49.13	0.123
4.00	49.22	0.123
4.02	49.30	0.123
4.03	49.38	0.123
4.05	49.47	0.123
4.07	49.55	0.123
4.08	49.63	0.123
4.10	49.72	0.123
4.12	49.80	0.123
4.13	49.88	0.123
4.15	49.97	0.123
4.17	50.05	0.123
4.18	50.13	0.123
4.20	50.22	0.123
4.22	50.30	0.123
4.23	50.38	0.123
4.25	50.47	0.123
4.27	50.55	0.123
4.28	50.63	0.124
4.30	50.72	0.124
4.32	50.80	0.124
4.33	50.88	0.124
4.35	50.97	0.124
4.37	51.05	0.124
4.38	51.13	0.124
4.40	51.22	0.124
4.42	51.30	0.124
4.43	51.38	0.124
4.45	51.47	0.124
4.47	51.55	0.124
4.48	51.63	0.124
4.50	51.72	0.124
4.52	51.80	0.124
4.53	51.88	0.124
4.55	51.97	0.124
4.57	52.05	0.124
4.58	52.14	0.124
4.60	52.22	0.124
4.62	52.30	0.124
4.63	52.38	0.124
4.65	52.47	0.124
4.67	52.55	0.124
4.68	52.64	0.124
4.70	52.72	0.124
4.72	52.80	0.124
4.73	52.88	0.124
4.75	52.97	0.124
4.77	53.05	0.124
4.78	53.14	0.124
4.80	53.22	0.124
4.82	53.30	0.124
4.83	53.39	0.125
4.85	53.47	0.125
4.87	53.55	0.125
4.88	53.64	0.125
4.90	53.72	0.125
4.92	53.80	0.125
4.93	53.89	0.125
4.95	53.97	0.125
4.97	54.05	0.125
4.98	54.14	0.125
5.00	54.22	0.125
5.02	54.30	0.125
5.03	54.39	0.125
5.05	54.47	0.125
5.07	54.55	0.125
5.08	54.64	0.125
5.10	54.72	0.125
5.12	54.80	0.125
5.13	54.89	0.125
5.15	54.97	0.125
5.17	55.05	0.125
5.18	55.14	0.125
5.20	55.22	0.125
5.22	55.30	0.125
5.23	55.39	0.125
5.25	55.47	0.125
5.27	55.55	0.125
5.28	55.64	0.125
5.30	55.72	0.125
5.32	55.80	0.125
5.33	55.89	0.125
5.35	55.97	0.125
5.37	56.05	0.125
5.38	56.14	0.125
5.40	56.22	0.126
5.42	56.30	0.126
5.43	56.39	0.126
5.45	56.47	0.126
5.47	56.55	0.126
5.48	56.64	0.126
5.50	56.72	0.126
5.52	56.80	0.126
5.53	56.89	0.126
5.55	56.97	0.126
5.57	57.05	0.126
5.58	57.14	0.126
5.60	57.22	0.126
5.62	57.30	0.126
5.63	57.39	0.126
5.65	57.47	0.126
5.67	57.55	0.126
5.68	57.64	0.126
5.70	57.72	0.126
5.72	57.80	0.126
5.73	57.89	0.126
5.75	57.97	0.126
5.77	58.05	0.126
5.78	58.14	0.126
5.80	58.22	0.126
5.82	58.30	0.126
5.83	58.39	0.126
5.85	58.47	0.126
5.87	58.55	0.126
5.88	58.64	0.126
5.90	58.72	0.126
5.92	58.80	0.126
5.93	58.89	0.126
5.95	58.97	0.126
5.97	59.05	0.126
5.98	59.14	0.126
6.00	59.22	0.126
6.02	59.30	0.126
6.03	59.39	0.126
6.05	59.47	0.126
6.07	59.55	0.127
6.08	59.64	0.127
6.10	59.72	0.127
6.12	59.80	0.127
6.13	59.89	0.127
6.15	59.97	0.127
6.17	60.05	0.127
6.18	60.14	0.127
6.20	60.22	0.127
6.22	60.30	0.127
6.23	60.39	0.127
6.25	60.47	0.127
6.27	60.55	0.127
6.28	60.64	0.127
6.30	60.72	0.127
6.32	60.81	0.127
6.33	60.89	0.127
6.35	60.97	0.127
6.37	61.06	0.127
6.38	61.14	0.127
6.40	61.22	0.127
6.42	61.31	0.127
6.43	61.39	0.127
6.45	61.47	0.127
6.47	61.55	0.127
6.48	61.64	0.127
6.50	61.72	0.127
6.52	61.80	0.127
6.53	61.89	0.127
6.55	61.97	0.127
6.57	62.06	0.127
6.58	62.14	0.127
6.60	62.22	0.127
6.62	62.30	0.127
6.63	62.39	0.127
6.65	62.47	0.127
6.67	62.56	0.127
6.68	62.64	0.127
6.70	62.72	0.127
6.72	62.81	0.127
6.73	62.89	0.128
6.75	62.97	0.128
6.77	63.06	0.128
6.78	63.14	0.128
6.80	63.22	0.128
6.82	63.31	0.128
6.83	63.39	0.128
6.85	63.47	0.128
6.87	63.56	0.128
6.88	63.64	0.128
6.90	63.72	0.128
6.92	63.80	0.128
6.93	63.89	0.128
6.95	63.97	0.128
6.97	64.06	0.128
6.98	64.14	0.128
7.00	64.22	0.128
7.02	64.31	0.128
7.03	64.39	0.128
7.05	64.47	0.128
7.07	64.56	0.128
7.08	64.64	0.128
7.10	64.72	0.128
7.12	64.81	0.128
7.13	64.89	0.128
7.15	64.97	0.128
7.17	65.06	0.128
7.18	65.14	0.128
7.20	65.22	0.128
7.22	65.31	0.128
7.23	65.39	0.128
7.25	65.47	0.128
7.27	65.56	0.128
7.28	65.64	0.128
7.30	65.72	0.128
7.32	65.81	0.128
7.33	65.89	0.128
7.35	65.97	0.128
7.37	66.06	0.128
7.38	66.14	0.128
7.40	66.22	0.128
7.42	66.31	0.128
7.43	66.39	0.129
7.45	66.47	0.129
7.47	66.56	0.129
7.48	66.64	0.129
7.50	66.72	0.129
7.52	66.81	0.129
7.53	66.89	0.129
7.55	66.97	0.129
7.57	67.06	0.129
7.58	67.14	0.129
7.60	67.22	0.129
7.62	67.31	0.129
7.63	67.39	0.129
7.65	67.47	0.129
7.67	67.56	0.129
7.68	67.64	0.129
7.70	67.73	0.129
7.72	67.81	0.129
7.73	67.89	0.129
7.75	67.98	0.129
7.77	68.06	0.129
7.78	68.14	0.129
7.80	68.22	0.129
7.82	68.31	0.129
7.83	68.39	0.129
7.85	68.48	0.129
7.87	68.56	0.129
7.88	68.64	0.129
7.90	68.72	0.129
7.92	68.81	0.129
7.93	68.89	0.129
7.95	68.98	0.129
7.97	69.06	0.129
7.98	69.14	0.129
8.00	69.22	0.129
8.02	69.31	0.129
8.03	69.39	0.129
8.05	69.48	0.129
8.07	69.56	0.129
8.08	69.64	0.129
8.10	69.72	0.129
8.12	69.81	0.129
8.13	69.89	0.129
8.15	69.97	0.129
8.17	70.06	0.129
8.18	70.14	0.129
8.20	70.23	0.129
8.22	70.31	0.129
8.23	70.39	0.130
8.25	70.48	0.130
8.27	70.56	0.130
8.28	70.64	0.130
8.30	70.73	0.130
8.32	70.81	0.130
8.33	70.89	0.130
8.35	70.98	0.130
8.37	71.06	0.130
8.38	71.14	0.130
8.40	71.23	0.130
8.42	71.31	0.130
8.43	71.39	0.130
8.45	71.48	0.130
8.47	71.56	0.130
8.48	71.64	0.130
8.50	71.73	0.130
8.52	71.81	0.130
8.53	71.89	0.130
8.55	71.98	0.130
8.57	72.06	0.130
8.58	72.14	0.130
8.60	72.23	0.130
8.62	72.31	0.130
8.63	72.39	0.130
8.65	72.48	0.130
8.67	72.56	0.130
8.68	72.64	0.130
8.70	72.73	0.130
8.72	72.81	0.130
8.73	72.89	0.130
8.75	72.98	0.130
8.77	73.06	0.130
8.78	73.14	0.130
8.80	73.23	0.130
8.82	73.31	0.130
8.83	73.39	0.130
8.85	73.48	0.130
8.87	73.56	0.130
8.88	73.64	0.130
8.90	73.73	0.130
8.92	73.81	0.130
8.93	73.89	0.130
8.95	73.98	0.130
8.97	74.06	0.131
8.98	74.14	0.131
9.00	74.23	0.131
9.02	74.31	0.131
9.03	74.39	0.131
9.05	74.48	0.131
9.07	74.56	0.131
9.08	74.64	0.131
9.10	74.73	0.131
9.12	74.81	0.131
9.13	74.89	0.131
9.15	74.98	0.131
9.17	75.06	0.131
9.18	75.14	0.131
9.20	75.23	0.131
9.22	75.31	0.131
9.23	75.39	0.131
9.25	75.48	0.131
9.27	75.56	0.131
9.28	75.64	0.131
9.30	75.73	0.131
9.32	75.81	0.131
9.33	75.89	0.131
9.35	75.98	0.131
9.37	76.06	0.131
9.38	76.14	0.131
9.40	76.23	0.131
9.42	76.31	0.131
9.43	76.39	0.131
9.45	76.48	0.131
9.47	76.56	0.131
9.48	76.65	0.131
9.50	76.73	0.131
9.52	76.81	0.131
9.53	76.90	0.131
9.55	76.98	0.131
9.57	77.06	0.131
9.58	77.15	0.131
9.60	77.23	0.131
9.62	77.31	0.131
9.63	77.40	0.131
9.65	77.48	0.131
9.67	77.56	0.131
9.68	77.65	0.131
9.70	77.73	0.131
9.72	77.81	0.131
9.73	77.90	0.131
9.75	77.98	0.131
9.77	78.06	0.131
9.78	78.15	0.132
9.80	78.23	0.132
9.82	78.31	0.132
9.83	78.40	0.132
9.85	78.48	0.132
9.87	78.56	0.132
9.88	78.65	0.132
9.90	78.73	0.132
9.92	78.81	0.132
9.93	78.90	0.132
9.95	78.98	0.132
9.97	79.06	0.132
9.98	79.15	0.132
10.00	79.23	0.132
10.02	79.31	0.132
10.03	79.40	0.132
10.05	79.48	0.132
10.07	79.56	0.132
10.08	79.65	0.132
10.10	79.73	0.132
10.12	79.81	0.132
10.13	79.89	0.132
10.15	79.98	0.132
10.17	80.06	0.132
10.18	80.15	0.132
10.20	80.23	0.132
10.22	80.31	0.132
10.23	80.39	0.132
10.25	80.48	0.132
10.27	80.56	0.132
10.28	80.65	0.132
10.30	80.73	0.132
10.32	80.81	0.132
10.33	80.90	0.132
10.35	80.98	0.132
10.37	81.06	0.132
10.38	81.15	0.132
10.40	81.23	0.132
10.42	81.31	0.133
10.43	81.40	0.133
10.45	81.48	0.133
10.47	81.56	0.133
10.48	81.65	0.133
10.50	81.73	0.133
10.52	81.81	0.133
10.53	81.90	0.133
10.55	81.98	0.133
10.57	82.06	0.133
10.58	82.15	0.133
10.60	82.23	0.133
10.62	82.32	0.133
10.63	82.40	0.133
10.65	82.48	0.133
10.67	82.56	0.133
10.68	82.65	0.133
10.70	82.73	0.133
10.72	82.81	0.133
10.73	82.90	0.133
10.75	82.98	0.133
10.77	83.06	0.133
10.78	83.15	0.133
10.80	83.23	0.133
10.82	83.31	0.133
10.83	83.40	0.133
10.85	83.48	0.133
10.87	83.56	0.133
10.88	83.65	0.133
10.90	83.73	0.133
10.92	83.81	0.133
10.93	83.90	0.133
10.95	83.98	0.133
10.97	84.06	0.133
10.98	84.15	0.133
11.00	84.23	0.133
11.02	84.31	0.133
11.03	84.40	0.133
11.05	84.48	0.133
11.07	84.57	0.133
11.08	84.65	0.134
11.10	84.73	0.134
11.12	84.82	0.134
11.13	84.90	0.134
11.15	84.98	0.134
11.17	85.07	0.134
11.18	85.15	0.134
11.20	85.23	0.134
11.22	85.32	0.134
11.23	85.40	0.134
11.25	85.48	0.134
11.27	85.57	0.134
11.28	85.65	0.134
11.30	85.73	0.134
11.32	85.81	0.134
11.33	85.90	0.134
11.35	85.98	0.134
11.37	86.07	0.134
11.38	86.15	0.134
11.40	86.23	0.134
11.42	86.32	0.134
11.43	86.40	0.134
11.45	86.48	0.134
11.47	86.57	0.134
11.48	86.65	0.134
11.50	86.73	0.134
11.52	86.82	0.134
11.53	86.90	0.134
11.55	86.98	0.134
11.57	87.07	0.135
11.58	87.15	0.135
11.60	87.23	0.135
11.62	87.32	0.135
11.63	87.40	0.135
11.65	87.48	0.135
11.67	87.57	0.135
11.68	87.65	0.135
11.70	87.73	0.135
11.72	87.81	0.135
11.73	87.90	0.135
11.75	87.98	0.135
11.77	88.07	0.135
11.78	88.15	0.135
11.80	88.23	0.135
11.82	88.32	0.135
11.83	88.40	0.135
11.85	88.48	0.135
11.87	88.57	0.135
11.88	88.65	0.135
11.90	88.73	0.135
11.92	88.82	0.135
11.93	88.90	0.135
11.95	88.98	0.136
11.97	89.07	0.136
11.98	89.15	0.136
12.00	89.23	0.136
12.02	89.32	0.136
12.03	89.40	0.136
12.05	89.48	0.136
12.07	89.57	0.136
12.08	89.65	0.136
12.10	89.73	0.136
12.12	89.82	0.136
12.13	89.90	0.136
12.15	89.98	0.136
12.17	90.07	0.136
12.18	90.15	0.136
12.20	90.23	0.137
12.22	90.32	0.137
12.23	90.40	0.137
12.25	90.48	0.137
12.27	90.57	0.137
12.28	90.65	0.137
12.30	90.73	0.137
12.32	90.82	0.137
12.33	90.90	0.137
12.35	90.98	0.137
12.37	91.07	0.137
12.38	91.15	0.137
12.40	91.23	0.137
12.42	91.32	0.137
12.43	91.40	0.137
12.45	91.48	0.137
12.47	91.57	0.138
12.48	91.65	0.138
12.50	91.73	0.138
12.52	91.82	0.138
12.53	91.90	0.138
12.55	91.98	0.138
12.57	92.07	0.138
12.58	92.15	0.138
12.60	92.23	0.138
12.62	92.31	0.138
12.63	92.40	0.138
12.65	92.48	0.138
12.67	92.56	0.138
12.68	92.65	0.139
12.70	92.73	0.139
12.72	92.82	0.139
12.73	92.90	0.139
12.75	92.98	0.139
12.77	93.06	0.139
12.78	93.15	0.139
12.80	93.23	0.139
12.82	93.31	0.139
12.83	93.40	0.139
12.85	93.48	0.139
12.87	93.56	0.139
12.88	93.65	0.140
12.90	93.73	0.140
12.92	93.82	0.140
12.93	93.90	0.140
12.95	93.98	0.140
12.97	94.06	0.140
12.98	94.15	0.140
13.00	94.23	0.140
13.02	94.31	0.140
13.03	94.40	0.140
13.05	94.48	0.141
13.07	94.56	0.141
13.08	94.65	0.141
13.10	94.73	0.141
13.12	94.81	0.141
13.13	94.90	0.141
13.15	94.98	0.141
13.17	95.06	0.141
13.18	95.15	0.142
13.20	95.23	0.142
13.22	95.31	0.142
13.23	95.40	0.142
13.25	95.48	0.142
13.27	95.56	0.142
13.28	95.65	0.142
13.30	95.73	0.142
13.32	95.81	0.142
13.33	95.90	0.143
13.35	95.98	0.143
13.37	96.07	0.143
13.38	96.15	0.143
13.40	96.23	0.143
13.42	96.31	0.143
13.43	96.40	0.144
13.45	96.48	0.144
13.47	96.56	0.144
13.48	96.65	0.144
13.50	96.73	0.144
13.52	96.81	0.145
13.53	96.89	0.145
13.55	96.98	0.145
13.57	97.06	0.145
13.58	97.14	0.146
13.60	97.23	0.146
13.62	97.31	0.146
13.63	97.39	0.146
13.65	97.48	0.147
13.67	97.56	0.147
13.68	97.64	0.148
13.70	97.73	0.148
13.72	97.81	0.148
13.73	97.89	0.149
13.75	97.97	0.149
13.77	98.06	0.150
13.78	98.14	0.151
13.80	98.22	0.151
13.82	98.31	0.151
13.83	98.39	0.152
13.85	98.47	0.153
13.87	98.56	0.153
13.88	98.64	0.154
13.90	98.72	0.155
13.92	98.81	0.155
13.93	98.89	0.156
13.95	98.97	0.156
13.97	99.05	0.157
13.98	99.14	0.157
14.00	99.22	0.158
14.02	99.30	0.158
14.03	99.38	0.158
14.05	99.47	0.159
14.07	99.55	0.159
14.08	99.63	0.159
14.10	99.72	0.159
14.12	99.80	0.160
14.13	99.88	0.160
14.15	99.97	0.160
14.17	100.05	0.160
14.18	100.13	0.160
14.20	100.21	0.161
14.22	100.30	0.161
14.23	100.38	0.161
14.25	100.47	0.161
14.27	100.55	0.161
14.28	100.63	0.161
14.30	100.71	0.162
14.32	100.80	0.162
14.33	100.88	0.162
14.35	100.96	0.162
14.37	101.05	0.163
14.38	101.13	0.163
14.40	101.21	0.163
14.42	101.30	0.163
14.43	101.38	0.164
14.45	101.46	0.164
14.47	101.55	0.165
14.48	101.63	0.165
14.50	101.71	0.166
14.52	101.80	0.166
14.53	101.88	0.166
14.55	101.96	0.167
14.57	102.04	0.167
14.58	102.13	0.167
14.60	102.21	0.168
14.62	102.29	0.168
14.63	102.38	0.168
14.65	102.46	0.169
14.67	102.54	0.169
14.68	102.63	0.170
14.70	102.71	0.170
14.72	102.79	0.170
14.73	102.87	0.171
14.75	102.96	0.171
14.77	103.04	0.172
14.78	103.12	0.172
14.80	103.21	0.173
14.82	103.29	0.173
14.83	103.37	0.174
14.85	103.46	0.174
14.87	103.54	0.175
14.88	103.62	0.175
14.90	103.70	0.176
14.92	103.79	0.176
14.93	103.87	0.176
14.95	103.95	0.177
14.97	104.04	0.177
14.98	104.12	0.178
15.00	104.20	0.179
15.02	104.29	0.179
15.03	104.37	0.180
15.05	104.45	0.180
15.07	104.53	0.181
15.08	104.62	0.182
15.10	104.70	0.182
15.12	104.78	0.183
15.13	104.87	0.184
15.15	104.95	0.184
15.17	105.03	0.185
15.18	105.11	0.186
15.20	105.20	0.187
15.22	105.28	0.187
15.23	105.36	0.188
15.25	105.45	0.189
15.27	105.53	0.190
15.28	105.61	0.190
15.30	105.69	0.191
15.32	105.78	0.192
15.33	105.86	0.193
15.35	105.94	0.193
15.37	106.02	0.194
15.38	106.11	0.195
15.40	106.19	0.196
15.42	106.27	0.197
15.43	106.36	0.198
15.45	106.44	0.199
15.47	106.52	0.200
15.48	106.60	0.201
15.50	106.69	0.202
15.52	106.77	0.203
15.53	106.85	0.204
15.55	106.93	0.205
15.57	107.02	0.206
15.58	107.10	0.207
15.60	107.18	0.209
15.62	107.26	0.209
15.63	107.34	0.210
15.65	107.43	0.212
15.67	107.51	0.213
15.68	107.59	0.214
15.70	107.67	0.215
15.72	107.76	0.216
15.73	107.84	0.218
15.75	107.92	0.219
15.77	108.00	0.220
15.78	108.08	0.221
15.80	108.17	0.223
15.82	108.25	0.224
15.83	108.33	0.225
15.85	108.41	0.227
15.87	108.50	0.228
15.88	108.58	0.229
15.90	108.66	0.230
15.92	108.74	0.232
15.93	108.83	0.234
15.95	108.91	0.235
15.97	108.99	0.236
15.98	109.07	0.238
16.00	109.15	0.239
16.02	109.24	0.240
16.03	109.32	0.242
16.05	109.40	0.244
16.07	109.48	0.245
16.08	109.56	0.247
16.10	109.65	0.248
16.12	109.73	0.250
16.13	109.81	0.251
16.15	109.89	0.253
16.17	109.98	0.254
16.18	110.06	0.256
16.20	110.14	0.258
16.22	110.22	0.259
16.23	110.30	0.261
16.25	110.38	0.263
16.27	110.47	0.264
16.28	110.55	0.266
16.30	110.63	0.268
16.32	110.71	0.270
16.33	110.79	0.271
16.35	110.88	0.273
16.37	110.96	0.275
16.38	111.04	0.277
16.40	111.12	0.278
16.42	111.20	0.281
16.43	111.28	0.282
16.45	111.37	0.284
16.47	111.45	0.287
16.48	111.53	0.288
16.50	111.61	0.290
16.52	111.69	0.292
16.53	111.77	0.294
16.55	111.86	0.296
16.57	111.94	0.298
16.58	112.02	0.300
16.60	112.10	0.302
16.62	112.18	0.305
16.63	112.26	0.307
16.65	112.35	0.309
16.67	112.43	0.312
16.68	112.51	0.315
16.70	112.59	0.317
16.72	112.67	0.319
16.73	112.75	0.322
16.75	112.83	0.324
16.77	112.91	0.326
16.78	113.00	0.328
16.80	113.08	0.331
16.82	113.16	0.333
16.83	113.24	0.335
16.85	113.32	0.338
16.87	113.40	0.340
16.88	113.48	0.342
16.90	113.57	0.345
16.92	113.65	0.348
16.93	113.73	0.350
16.95	113.81	0.353
16.97	113.89	0.356
16.98	113.97	0.358
17.00	114.05	0.362
17.02	114.13	0.365
17.03	114.22	0.367
17.05	114.30	0.370
17.07	114.38	0.373
17.08	114.46	0.376
17.10	114.54	0.378
17.12	114.62	0.381
17.13	114.70	0.385
17.15	114.78	0.387
17.17	114.86	0.391
17.18	114.94	0.394
17.20	115.02	0.397
17.22	115.10	0.400
17.23	115.19	0.403
17.25	115.27	0.406
17.27	115.35	0.409
17.28	115.43	0.412
17.30	115.51	0.415
17.32	115.59	0.418
17.33	115.67	0.422
17.35	115.75	0.425
17.37	115.83	0.428
17.38	115.91	0.431
17.40	115.99	0.435
17.42	116.07	0.439
17.43	116.15	0.442
17.45	116.23	0.446
17.47	116.31	0.449
17.48	116.39	0.453
17.50	116.47	0.458
17.52	116.55	0.462
17.53	116.63	0.466
17.55	116.71	0.471
17.57	116.79	0.474
17.58	116.87	0.477
17.60	116.95	0.482
17.62	117.03	0.485
17.63	117.11	0.489
17.65	117.19	0.492
17.67	117.27	0.497
17.68	117.35	0.501
17.70	117.43	0.505
17.72	117.51	0.509
17.73	117.59	0.513
17.75	117.67	0.517
17.77	117.75	0.522
17.78	117.83	0.525
17.80	117.91	0.530
17.82	117.99	0.534
17.83	118.07	0.538
17.85	118.15	0.543
17.87	118.23	0.549
17.88	118.31	0.554
17.90	118.39	0.558
17.92	118.47	0.562
17.93	118.55	0.566
17.95	118.62	0.570
17.97	118.71	0.574
17.98	118.78	0.578
18.00	118.86	0.582
18.02	118.94	0.588
18.03	119.02	0.592
18.05	119.10	0.597
18.07	119.18	0.601
18.08	119.26	0.607
18.10	119.34	0.612
18.12	119.42	0.616
18.13	119.50	0.620
18.15	119.58	0.625
18.17	119.66	0.630
18.18	119.74	0.635
18.20	119.82	0.640
18.22	119.89	0.645
18.23	119.97	0.649
18.25	120.05	0.654
18.27	120.13	0.660
18.28	120.21	0.664
18.30	120.29	0.671
18.32	120.37	0.676
18.33	120.45	0.682
18.35	120.53	0.688
18.37	120.60	0.693
18.38	120.68	0.701
18.40	120.76	0.709
18.42	120.84	0.715
18.43	120.92	0.720
18.45	120.99	0.725
18.47	121.07	0.730
18.48	121.15	0.735
18.50	121.23	0.740
18.52	121.31	0.746
18.53	121.39	0.753
18.55	121.47	0.758
18.57	121.54	0.762
18.58	121.62	0.768
18.60	121.70	0.774
18.62	121.78	0.781
18.63	121.86	0.786
18.65	121.94	0.794
18.67	122.01	0.802
18.68	122.09	0.807
18.70	122.17	0.813
18.72	122.25	0.820
18.73	122.32	0.826
18.75	122.40	0.832
18.77	122.48	0.839
18.78	122.56	0.846
18.80	122.63	0.853
18.82	122.71	0.860
18.83	122.79	0.866
18.85	122.87	0.872
18.87	122.95	0.877
18.88	123.02	0.882
18.90	123.10	0.889
18.92	123.18	0.894
18.93	123.26	0.902
18.95	123.34	0.907
18.97	123.41	0.914
18.98	123.49	0.920
19.00	123.57	0.926
19.02	123.65	0.932
19.03	123.73	0.939
19.05	123.80	0.946
19.07	123.88	0.954
19.08	123.96	0.961
19.10	124.04	0.968
19.12	124.11	0.976
19.13	124.19	0.984
19.15	124.27	0.991
19.17	124.35	0.998
19.18	124.42	1.006
19.20	124.50	1.015
19.22	124.57	1.021
19.23	124.65	1.027
19.25	124.73	1.033
19.27	124.81	1.039
19.28	124.89	1.046
19.30	124.96	1.052
19.32	125.04	1.058
19.33	125.12	1.065
19.35	125.20	1.072
19.37	125.27	1.079
19.38	125.35	1.087
19.40	125.43	1.093
19.42	125.51	1.102
19.43	125.58	1.108
19.45	125.66	1.114
19.47	125.74	1.120
19.48	125.82	1.126
19.50	125.89	1.132
19.52	125.97	1.138
19.53	126.05	1.144
19.55	126.13	1.152
19.57	126.21	1.157
19.58	126.28	1.162
19.60	126.37	1.167
19.62	126.44	1.174
19.63	126.52	1.181
19.65	126.60	1.188
19.67	126.67	1.194
19.68	126.75	1.199
19.70	126.83	1.205
19.72	126.91	1.210
19.73	126.99	1.217
19.75	127.07	1.220
19.77	127.15	1.224
19.78	127.23	1.227
19.80	127.30	1.232
19.82	127.38	1.237
19.83	127.46	1.240
19.85	127.55	1.243
19.87	127.62	1.247
19.88	127.70	1.249
19.90	127.78	1.252
19.92	127.87	1.254
19.93	127.95	1.256
19.95	128.03	1.259
19.97	128.11	1.261
19.98	128.19	1.263
20.00	128.27	1.266
20.02	128.35	1.271
20.03	128.43	1.273
20.05	128.51	1.273
20.07	128.60	1.273
20.08	128.68	1.273
20.10	128.76	1.273
20.12	128.85	1.272
20.13	128.93	1.272
20.15	129.01	1.271
20.17	129.10	1.270
20.18	129.18	1.268
20.20	129.27	1.264
20.22	129.35	1.261
20.23	129.44	1.256
20.25	129.52	1.252
20.27	129.61	1.246
20.28	129.70	1.239
20.30	129.79	1.233
20.32	129.88	1.224
20.33	129.97	1.215
20.35	130.05	1.205
20.37	130.15	1.194
20.38	130.24	1.181
20.40	130.33	1.168
20.42	130.43	1.153
20.43	130.52	1.137
20.45	130.61	1.120
20.47	130.71	1.102
20.48	130.81	1.082
20.50	130.91	1.061
20.52	131.01	1.038
20.53	131.11	1.014
20.55	131.21	0.987
20.57	131.32	0.960
20.58	131.42	0.930
20.60	131.53	0.900
20.62	131.64	0.869
20.63	131.74	0.836
20.65	131.85	0.804
20.67	131.96	0.771
20.68	132.08	0.739
20.70	132.19	0.708
20.72	132.30	0.678
20.73	132.41	0.651
20.75	132.51	0.625
20.77	132.62	0.601
20.78	132.73	0.580
20.80	132.83	0.560
20.82	132.94	0.542
20.83	133.04	0.526
20.85	133.14	0.511
20.87	133.24	0.497
20.88	133.34	0.484
20.90	133.43	0.472
20.92	133.53	0.461
20.93	133.62	0.451
20.95	133.72	0.441
20.97	133.81	0.431
20.98	133.90	0.422
21.00	133.99	0.414
21.02	134.08	0.406
21.03	134.18	0.399
21.05	134.27	0.393
21.07	134.36	0.386
21.08	134.45	0.380
21.10	134.54	0.374
21.12	134.63	0.367
21.13	134.72	0.362
21.15	134.80	0.357
21.17	134.89	0.352
21.18	134.98	0.347
21.20	135.07	0.342
21.22	135.16	0.338
21.23	135.24	0.334
21.25	135.33	0.330
21.27	135.42	0.326
21.28	135.51	0.323
21.30	135.59	0.319
21.32	135.68	0.316
21.33	135.76	0.313
21.35	135.85	0.310
21.37	135.94	0.307
21.38	136.02	0.305
21.40	136.11	0.302
21.42	136.19	0.300
21.43	136.28	0.298
21.45	136.36	0.296
21.47	136.45	0.294
21.48	136.54	0.292
21.50	136.62	0.290
21.52	136.71	0.288
21.53	136.79	0.287
21.55	136.88	0.285
21.57	136.96	0.284
21.58	137.05	0.282
21.60	137.13	0.281
21.62	137.22	0.280
21.63	137.30	0.278
21.65	137.39	0.277
21.67	137.47	0.276
21.68	137.55	0.275
21.70	137.64	0.275
21.72	137.72	0.273
21.73	137.81	0.273
21.75	137.89	0.272
21.77	137.97	0.271
21.78	138.06	0.271
21.80	138.14	0.270
21.82	138.23	0.269
21.83	138.31	0.269
21.85	138.40	0.268
21.87	138.48	0.268
21.88	138.56	0.267
21.90	138.65	0.267
21.92	138.73	0.266
21.93	138.82	0.266
21.95	138.90	0.266
21.97	138.98	0.266
21.98	139.07	0.265
22.00	139.15	0.265
22.02	139.23	0.265
22.03	139.32	0.264
22.05	139.40	0.264
22.07	139.48	0.264
22.08	139.57	0.264
22.10	139.65	0.263
22.12	139.74	0.263
22.13	139.82	0.263
22.15	139.90	0.263
22.17	139.99	0.263
22.18	140.07	0.263
22.20	140.15	0.262
22.22	140.24	0.262
22.23	140.32	0.262
22.25	140.40	0.262
22.27	140.49	0.262
22.28	140.57	0.262
22.30	140.65	0.261
22.32	140.74	0.261
22.33	140.82	0.261
22.35	140.90	0.261
22.37	140.99	0.261
22.38	141.07	0.261
22.40	141.16	0.261
22.42	141.24	0.260
22.43	141.32	0.260
22.45	141.41	0.260
22.47	141.49	0.260
22.48	141.57	0.260
22.50	141.66	0.260
22.52	141.74	0.260
22.53	141.82	0.259
22.55	141.91	0.259
22.57	141.99	0.259
22.58	142.07	0.259
22.60	142.16	0.259
22.62	142.24	0.259
22.63	142.32	0.259
22.65	142.41	0.259
22.67	142.49	0.259
22.68	142.57	0.259
22.70	142.66	0.258
22.72	142.74	0.258
22.73	142.82	0.258
22.75	142.91	0.258
22.77	142.99	0.258
22.78	143.07	0.258
22.80	143.16	0.258
22.82	143.24	0.258
22.83	143.33	0.258
22.85	143.41	0.258
22.87	143.49	0.258
22.88	143.58	0.258
22.90	143.66	0.257
22.92	143.74	0.257
22.93	143.83	0.257
22.95	143.91	0.257
22.97	143.99	0.257
22.98	144.08	0.257
23.00	144.16	0.257
23.02	144.24	0.257
23.03	144.33	0.257
23.05	144.41	0.257
23.07	144.49	0.256
23.08	144.58	0.256
23.10	144.66	0.256
23.12	144.74	0.256
23.13	144.83	0.256
23.15	144.91	0.256
23.17	144.99	0.256
23.18	145.08	0.256
23.20	145.16	0.256
23.22	145.24	0.256
23.23	145.33	0.256
23.25	145.41	0.255
23.27	145.49	0.255
23.28	145.58	0.255
23.30	145.66	0.255
23.32	145.75	0.255
23.33	145.83	0.255
23.35	145.91	0.255
23.37	146.00	0.255
23.38	146.08	0.255
23.40	146.16	0.255
23.42	146.25	0.254
23.43	146.33	0.254
23.45	146.41	0.254
23.47	146.50	0.254
23.48	146.58	0.254
23.50	146.66	0.254
23.52	146.75	0.254
23.53	146.83	0.254
23.55	146.91	0.254
23.57	147.00	0.253
23.58	147.08	0.253
23.60	147.16	0.253
23.62	147.25	0.253
23.63	147.33	0.253
23.65	147.42	0.253
23.67	147.50	0.253
23.68	147.58	0.253
23.70	147.67	0.253
23.72	147.75	0.253
23.73	147.83	0.252
23.75	147.92	0.252
23.77	148.00	0.252
23.78	148.08	0.252
23.80	148.17	0.252
23.82	148.25	0.252
23.83	148.33	0.252
23.85	148.42	0.252
23.87	148.50	0.252
23.88	148.58	0.251
23.90	148.67	0.251
23.92	148.75	0.251
23.93	148.83	0.251
23.95	148.92
23.97	149.00
23.98	149.08
24.00
24.00