File: Data/2025_09_11_Indium_Std_CHM343_DSC.csv
Filename,2025_09_11_Indium_Std_CHM343_DSC
Instrument name,DSC2A-00468 (192.168.1.100)
Operator,Zoom ASU Sync
rundate,9/11/2025
Sample name,2025_09_11_Indium_Std_CHM343_DSC
proceduresegments,Data Off ; Equilibrate 100.00 °C; Data On ; Ramp 10.00 °C/min to 200.00 °C; Data Off ; Isothermal 1.0 min; Data On ; Ramp 10.00 °C/min to 100.00 °C; Data Off ; Isothermal 1.0 min; Data On ; Ramp 10.00 °C/min to 200.00 °C; Data Off ; Isothermal 1.0 min; Data On ; Ramp 10.00 °C/min to 100.00 °C
[File Parameters]
Run date,9/11/2025 10:53:22 AM
Trios version,5.1.1.46572
Original File Name,
Current File Name,D:\DSC2500\CHM343\2025_09_11_Indium_Std_CHM343_DSC.tri
[Procedure]
Procedure Name,Indium_100C_200C_10Cmin
Sample Name,2025_09_11_Indium_Std_CHM343_DSC
Sample Mass,8.19 mg
Reference Sample Mass,0 mg
Pan Mass,56.76 mg
Pan Number,3
Reference Pan Mass,56.82 mg
Reference Pan Number,10
Pan Type,Tzero Aluminum Hermetic
Comments,DSC_Samples_Y1_Tray_CHM343_Sept2025 Google Sheet.
Project Name,CHM343
Operator,Zoom ASU Sync
Test,Custom
Unload Max Temperature,30
Unload Min Temperature,30
Load Max Temperature,30
Load Min Temperature,30
Stop on Gas Flow Error,Yes
[Signal List]
Signal #1,Time (min)
Signal #2,Temperature (°C)
Signal #3,Heat Flow (mW)
Signal #4,Delta T (µV)
Signal #5,Delta Tzero (µV)
Signal #6,Tzero Temperature (°C)
Signal #7,Cell Purge (mL/min)
Signal #8,Heater Temp (°C)
Signal #9,Power Delivered (W)
Signal #10,Reference Junction Temperature (°C)
Signal #11,Flange Temperature (°C)
Signal #12,Heat Flow Phase (rad)
Signal #13,Total Heat Capacity (J/°C)
Signal #14,Heat Capacity (J/°C)
[Configuration]
Company Name,ASU
Instrument Name,DSC2A-00468
Instrument Type,DSC2500
Serial Number,DSC2A-00468
IP,192.168.1.100
Location of Instrument,MRRC
DisplayType,Unknown
Sample Interval ,0.1 s/pt
Selected Heat Flow,T4P
Exotherm Direction,Down
Cell Serial,DRC2-00792
Lid Type,Standard
Cooler,RCS 90
Leave Cooler on at End of Sequence,On
Gas 2,Nitrogen
Gas Selected,Channel 1
Flow Rate,50 mL/min
Secondary Purge,On
Licensed Heat Flow,Heat Flow T4P
Modulation Licensed,Yes
[Versions]
Common IDD Version,1
Cortex Version,VER 2.10.2.31
Driver,5.0.0.6
GDM Version,1.0.3.3
TouchscreenVersion,1.0.0.16145
FEP Version,1.2.1.21
FEP Bootloader,2.0.0.5
AutoSampler Version,2.1.1.26
Auto Sampler Bootloader,2.0.0.5
FCM Version,1.1.0.3
FCM Bootloader,2.0.0.5
[Experiment Logs]
Experiment Log Entry # 1,Data On set to 0
Experiment Log Entry # 3,Equilibrate Segment 100 (C) Started
Experiment Log Entry # 5,Air Cool is off.
Experiment Log Entry # 7,Data On set to 1
Experiment Log Entry # 9,Ramp Segment 10 C/min to 200 Started
Experiment Log Entry # 11,Data On set to 0
Experiment Log Entry # 13,Isothermal Segment 1 min started
Experiment Log Entry # 15,Data On set to 1
Experiment Log Entry # 17,Ramp Segment 10 C/min to 100 Started
Experiment Log Entry # 19,Data On set to 0
Experiment Log Entry # 21,Isothermal Segment 1 min started
Experiment Log Entry # 23,Data On set to 1
Experiment Log Entry # 25,Ramp Segment 10 C/min to 200 Started
Experiment Log Entry # 27,Data On set to 0
Experiment Log Entry # 29,Isothermal Segment 1 min started
Experiment Log Entry # 31,Data On set to 1
Experiment Log Entry # 33,Ramp Segment 10 C/min to 100 Started
[Method Log]
Method Log Entry # 1,Data Off
Method Log Entry # 2,Equilibrate 100 °C
Method Log Entry # 3,Data On
Method Log Entry # 4,(Ramp 43034) Ramp 10 °C/minute to 200 °C
Method Log Entry # 5,Data Off
Method Log Entry # 6,Isothermal 1 minutes
Method Log Entry # 7,Data On
Method Log Entry # 8,(Ramp 43038) Ramp 10 °C/minute to 100 °C
Method Log Entry # 9,Data Off
Method Log Entry # 10,Isothermal 1 minutes
Method Log Entry # 11,Data On
Method Log Entry # 12,(Ramp 43042) Ramp 10 °C/minute to 200 °C
Method Log Entry # 13,Data Off
Method Log Entry # 14,Isothermal 1 minutes
Method Log Entry # 15,Data On
Method Log Entry # 16,(Ramp 43046) Ramp 10 °C/minute to 100 °C
Cell Serial,DRC2-00792
[T1 Calibration]
Slope,-0.008529666
Offset,9.636258
Initial Temperature,98.23
GUID,f8bfdadc-4977-4fdf-ba6d-0ba9134940c3
[TZero Calibration]
Date Applied,11/29/2022 4:06:13 PM
Description,From -89.059 °C to 396.009 °C at 20.000°C/min
Gas Type,Nitrogen
Pan Type,None
Source Files 1,C:\Users\yargerlab\Desktop\DSC Data\General\TZero_calibration_11_29_22_2nd(2).tri
Source Files 2,C:\Users\yargerlab\Desktop\DSC Data\General\TZero_calibration_11_29_22_2nd(3).tri
Delta T Offset,13.05235
Delta T Slope,-0.007271007
Delta T0 Offset,-13.69128
Delta T0 Slope,0.06063341
[Temperature Calibration]
Date Applied,11/29/2022 7:12:28 PM
Description,From 106.590 °C to 186.590 °C at 10.000°C/min
Gas Type,Nitrogen
Pan Type,Tzero Aluminum Hermetic
Source Files 1,C:\Users\yargerlab\Desktop\DSC Data\General\Indium(6).tri
Measured 1,157.391
Known 1,156.598
[Cell Constant Calibration]
Date Applied,11/29/2022 7:12:29 PM
Description,From 106.590 °C to 186.590 °C at 10.000°C/min
Gas Type,Nitrogen
Pan Type,Tzero Aluminum Hermetic
Source Files 1,C:\Users\yargerlab\Desktop\DSC Data\General\Indium(6).tri
T4P KCell,1.006051
Onset Slope,63.26126 mW/°C
[Direct Cp Calibration]
Date Applied,11/30/2022 11:04:51 AM
Description,From -79.983 °C to 298.409 °C at 10.000°C/min
Gas Type,Nitrogen
Pan Type,Tzero Aluminum Hermetic
Source Files 1,C:\Users\yargerlab\Desktop\DSC Data\General\Sapphire_Heat_Capacity_11_30_22.tri
[Rev Cp Calibration]
Date Applied,11/30/2022 1:58:51 PM
Description,From -79.996 °C to 292.812 °C at 3.000°C/min
Gas Type,Nitrogen
Pan Type,Tzero Aluminum Hermetic
Source Files 1,C:\Users\yargerlab\Desktop\DSC Data\General\Sapphire_MDSC_Calibration_11_30_22.tri
[step]
Ramp 10.00 °C/min to 200.00 °C
Time,Temperature,Heat Flow (Normalized)
min,°C,W/g
0.00,100.12,-0.024
0.01,100.12,-0.024
0.01,100.12,-0.024
0.02,100.12,-0.024
0.03,100.13,-0.024
0.03,100.13,-0.024
0.04,100.13,-0.024
0.05,100.14,-0.024
0.05,100.14,-0.024
0.06,100.15,-0.024
0.07,100.16,-0.024
0.07,100.17,-0.024
0.08,100.18,-0.022
0.09,100.20,-0.020
0.09,100.22,-0.016
0.10,100.24,-0.013
0.11,100.26,-0.010
0.11,100.29,-0.007
0.12,100.32,-0.004
0.13,100.36,-0.001
0.13,100.39,0.002
0.14,100.43,0.005
0.15,100.47,0.008
0.15,100.51,0.011
0.16,100.56,0.013
0.17,100.61,0.017
0.17,100.66,0.018
0.18,100.70,0.020
0.19,100.76,0.023
0.19,100.81,0.025
0.20,100.86,0.026
0.21,100.92,0.028
0.21,100.98,0.030
0.22,101.03,0.032
0.23,101.09,0.033
0.23,101.15,0.034
0.24,101.21,0.035
0.25,101.26,0.036
0.25,101.32,0.037
0.26,101.38,0.039
0.27,101.45,0.039
0.27,101.51,0.039
0.28,101.57,0.040
0.29,101.63,0.041
0.29,101.69,0.042
0.30,101.75,0.042
0.31,101.82,0.043
0.31,101.88,0.043
0.32,101.94,0.043
0.33,102.00,0.044
0.33,102.07,0.044
0.34,102.13,0.045
0.35,102.19,0.045
0.35,102.26,0.045
0.36,102.32,0.045
0.37,102.39,0.046
0.37,102.45,0.046
0.38,102.52,0.047
0.39,102.58,0.047
0.39,102.65,0.047
0.40,102.71,0.048
0.41,102.77,0.048
0.41,102.84,0.048
0.42,102.91,0.048
0.43,102.97,0.048
0.43,103.03,0.048
0.44,103.10,0.048
0.45,103.17,0.048
0.45,103.23,0.048
0.46,103.30,0.049
0.47,103.36,0.049
0.47,103.43,0.049
0.48,103.49,0.049
0.49,103.56,0.049
0.49,103.62,0.049
0.50,103.69,0.049
0.51,103.76,0.049
0.51,103.82,0.049
0.52,103.89,0.049
0.53,103.95,0.049
0.53,104.02,0.050
0.54,104.08,0.050
0.55,104.15,0.050
0.55,104.22,0.050
0.56,104.28,0.050
0.57,104.35,0.050
0.57,104.41,0.050
0.58,104.48,0.050
0.59,104.55,0.050
0.59,104.61,0.050
0.60,104.68,0.050
0.61,104.74,0.050
0.61,104.81,0.050
0.62,104.88,0.050
0.63,104.94,0.050
0.63,105.01,0.051
0.64,105.07,0.051
0.65,105.14,0.051
0.65,105.21,0.051
0.66,105.27,0.051
0.67,105.34,0.051
0.67,105.41,0.051
0.68,105.47,0.051
0.69,105.54,0.051
0.69,105.60,0.051
0.70,105.67,0.051
0.71,105.74,0.051
0.71,105.80,0.051
0.72,105.87,0.051
0.73,105.94,0.051
0.73,106.00,0.051
0.74,106.07,0.051
0.75,106.13,0.051
0.75,106.20,0.051
0.76,106.27,0.052
0.77,106.33,0.052
0.77,106.40,0.052
0.78,106.47,0.052
0.79,106.53,0.052
0.79,106.60,0.052
0.80,106.67,0.052
0.81,106.73,0.052
0.81,106.80,0.052
0.82,106.86,0.052
0.83,106.93,0.052
0.83,107.00,0.052
0.84,107.06,0.052
0.85,107.13,0.052
0.85,107.20,0.052
0.86,107.26,0.052
0.87,107.33,0.052
0.87,107.39,0.052
0.88,107.46,0.052
0.89,107.53,0.052
0.89,107.60,0.052
0.90,107.66,0.052
0.91,107.73,0.053
0.91,107.80,0.053
0.92,107.86,0.053
0.93,107.93,0.053
0.93,107.99,0.053
0.94,108.06,0.053
0.95,108.13,0.053
0.95,108.19,0.053
0.96,108.26,0.053
0.97,108.33,0.053
0.97,108.39,0.053
0.98,108.46,0.053
0.99,108.53,0.053
0.99,108.59,0.053
1.00,108.66,0.053
1.01,108.73,0.053
1.01,108.79,0.053
1.02,108.86,0.053
1.03,108.93,0.053
1.03,108.99,0.053
1.04,109.06,0.053
1.05,109.12,0.053
1.05,109.19,0.053
1.06,109.26,0.053
1.07,109.32,0.053
1.07,109.39,0.053
1.08,109.46,0.053
1.09,109.52,0.053
1.09,109.59,0.053
1.10,109.66,0.054
1.11,109.72,0.054
1.11,109.79,0.054
1.12,109.86,0.054
1.13,109.92,0.054
1.13,109.99,0.054
1.14,110.06,0.054
1.15,110.12,0.054
1.15,110.19,0.054
1.16,110.26,0.054
1.17,110.32,0.054
1.17,110.39,0.054
1.18,110.46,0.054
1.19,110.52,0.054
1.19,110.59,0.054
1.20,110.66,0.054
1.21,110.72,0.054
1.21,110.79,0.054
1.22,110.86,0.054
1.23,110.92,0.054
1.23,110.99,0.054
1.24,111.05,0.054
1.25,111.12,0.054
1.25,111.19,0.054
1.26,111.25,0.054
1.27,111.32,0.054
1.27,111.39,0.054
1.28,111.45,0.054
1.29,111.52,0.054
1.29,111.59,0.054
1.30,111.65,0.054
1.31,111.72,0.054
1.31,111.79,0.054
1.32,111.85,0.054
1.33,111.92,0.054
1.33,111.99,0.054
1.34,112.05,0.054
1.35,112.12,0.054
1.35,112.19,0.054
1.36,112.25,0.054
1.37,112.32,0.054
1.37,112.39,0.054
1.38,112.45,0.054
1.39,112.52,0.054
1.39,112.59,0.054
1.40,112.65,0.054
1.41,112.72,0.054
1.41,112.79,0.054
1.42,112.85,0.054
1.43,112.92,0.054
1.43,112.99,0.054
1.44,113.05,0.054
1.45,113.12,0.054
1.45,113.19,0.054
1.46,113.25,0.054
1.47,113.32,0.054
1.47,113.39,0.055
1.48,113.45,0.055
1.49,113.52,0.055
1.49,113.59,0.055
1.50,113.65,0.055
1.51,113.72,0.055
1.51,113.79,0.055
1.52,113.85,0.055
1.53,113.92,0.055
1.53,113.99,0.055
1.54,114.05,0.055
1.55,114.12,0.055
1.55,114.19,0.055
1.56,114.26,0.055
1.57,114.32,0.055
1.57,114.39,0.055
1.58,114.45,0.055
1.59,114.52,0.055
1.59,114.59,0.055
1.60,114.65,0.055
1.61,114.72,0.055
1.61,114.79,0.055
1.62,114.85,0.055
1.63,114.92,0.055
1.63,114.99,0.055
1.64,115.06,0.055
1.65,115.12,0.055
1.65,115.19,0.055
1.66,115.25,0.055
1.67,115.32,0.055
1.67,115.39,0.055
1.68,115.45,0.055
1.69,115.52,0.055
1.69,115.59,0.055
1.70,115.66,0.055
1.71,115.72,0.055
1.71,115.79,0.055
1.72,115.85,0.055
1.73,115.92,0.055
1.73,115.99,0.055
1.74,116.05,0.055
1.75,116.12,0.055
1.75,116.19,0.055
1.76,116.26,0.055
1.77,116.32,0.055
1.77,116.39,0.055
1.78,116.46,0.055
1.79,116.52,0.055
1.79,116.59,0.055
1.80,116.66,0.055
1.81,116.72,0.055
1.81,116.79,0.055
1.82,116.86,0.055
1.83,116.92,0.055
1.83,116.99,0.055
1.84,117.06,0.055
1.85,117.12,0.055
1.85,117.19,0.055
1.86,117.26,0.055
1.87,117.32,0.055
1.87,117.39,0.055
1.88,117.46,0.055
1.89,117.52,0.055
1.89,117.59,0.055
1.90,117.66,0.055
1.91,117.72,0.055
1.91,117.79,0.055
1.92,117.86,0.055
1.93,117.92,0.055
1.93,117.99,0.055
1.94,118.06,0.055
1.95,118.12,0.055
1.95,118.19,0.055
1.96,118.26,0.055
1.97,118.32,0.055
1.97,118.39,0.055
1.98,118.46,0.055
1.99,118.52,0.055
1.99,118.59,0.055
2.00,118.66,0.055
2.01,118.72,0.055
2.01,118.79,0.055
2.02,118.86,0.055
2.03,118.92,0.055
2.03,118.99,0.055
2.04,119.06,0.055
2.05,119.12,0.055
2.05,119.19,0.055
2.06,119.26,0.056
2.07,119.32,0.056
2.07,119.39,0.056
2.08,119.46,0.056
2.09,119.53,0.056
2.09,119.59,0.056
2.10,119.66,0.056
2.11,119.72,0.056
2.11,119.79,0.056
2.12,119.86,0.056
2.13,119.92,0.056
2.13,119.99,0.056
2.14,120.06,0.056
2.15,120.12,0.056
2.15,120.19,0.056
2.16,120.26,0.056
2.17,120.32,0.056
2.17,120.39,0.056
2.18,120.46,0.056
2.19,120.53,0.056
2.19,120.59,0.056
2.20,120.66,0.056
2.21,120.72,0.056
2.21,120.79,0.056
2.22,120.86,0.056
2.23,120.92,0.056
2.23,120.99,0.056
2.24,121.06,0.056
2.25,121.13,0.056
2.25,121.19,0.056
2.26,121.26,0.056
2.27,121.33,0.056
2.27,121.39,0.056
2.28,121.46,0.056
2.29,121.53,0.056
2.29,121.59,0.056
2.30,121.66,0.056
2.31,121.73,0.056
2.31,121.79,0.056
2.32,121.86,0.056
2.33,121.93,0.056
2.33,121.99,0.056
2.34,122.06,0.056
2.35,122.13,0.056
2.35,122.19,0.056
2.36,122.26,0.056
2.37,122.33,0.056
2.37,122.39,0.056
2.38,122.46,0.056
2.39,122.53,0.056
2.39,122.59,0.056
2.40,122.66,0.056
2.41,122.73,0.056
2.41,122.79,0.056
2.42,122.86,0.056
2.43,122.93,0.056
2.43,122.99,0.056
2.44,123.06,0.056
2.45,123.13,0.056
2.45,123.19,0.056
2.46,123.26,0.056
2.47,123.33,0.056
2.47,123.39,0.056
2.48,123.46,0.056
2.49,123.53,0.056
2.49,123.59,0.056
2.50,123.66,0.056
2.51,123.73,0.056
2.51,123.79,0.056
2.52,123.86,0.056
2.53,123.93,0.056
2.53,124.00,0.056
2.54,124.06,0.056
2.55,124.13,0.056
2.55,124.19,0.056
2.56,124.26,0.056
2.57,124.33,0.056
2.57,124.39,0.056
2.58,124.46,0.056
2.59,124.53,0.056
2.59,124.60,0.056
2.60,124.66,0.056
2.61,124.73,0.056
2.61,124.79,0.056
2.62,124.86,0.056
2.63,124.93,0.056
2.63,124.99,0.056
2.64,125.06,0.056
2.65,125.13,0.056
2.65,125.19,0.056
2.66,125.26,0.056
2.67,125.33,0.056
2.67,125.39,0.056
2.68,125.46,0.056
2.69,125.53,0.056
2.69,125.60,0.056
2.70,125.66,0.056
2.71,125.73,0.056
2.71,125.80,0.056
2.72,125.86,0.056
2.73,125.93,0.056
2.73,126.00,0.056
2.74,126.06,0.056
2.75,126.13,0.056
2.75,126.20,0.056
2.76,126.26,0.056
2.77,126.33,0.056
2.77,126.40,0.056
2.78,126.46,0.056
2.79,126.53,0.056
2.79,126.60,0.056
2.80,126.66,0.056
2.81,126.73,0.056
2.81,126.80,0.056
2.82,126.86,0.056
2.83,126.93,0.056
2.83,127.00,0.056
2.84,127.06,0.056
2.85,127.13,0.056
2.85,127.20,0.056
2.86,127.26,0.056
2.87,127.33,0.056
2.87,127.40,0.056
2.88,127.46,0.056
2.89,127.53,0.056
2.89,127.60,0.056
2.90,127.66,0.056
2.91,127.73,0.056
2.91,127.80,0.056
2.92,127.86,0.056
2.93,127.93,0.056
2.93,128.00,0.056
2.94,128.06,0.056
2.95,128.13,0.056
2.95,128.20,0.056
2.96,128.26,0.056
2.97,128.33,0.056
2.97,128.40,0.056
2.98,128.46,0.056
2.99,128.53,0.056
2.99,128.60,0.056
3.00,128.66,0.056
3.01,128.73,0.056
3.01,128.80,0.056
3.02,128.87,0.056
3.03,128.93,0.056
3.03,129.00,0.056
3.04,129.07,0.056
3.05,129.13,0.056
3.05,129.20,0.056
3.06,129.27,0.056
3.07,129.33,0.056
3.07,129.40,0.056
3.08,129.47,0.056
3.09,129.53,0.056
3.09,129.60,0.056
3.10,129.67,0.056
3.11,129.73,0.056
3.11,129.80,0.056
3.12,129.87,0.056
3.13,129.93,0.056
3.13,130.00,0.056
3.14,130.07,0.056
3.15,130.13,0.056
3.15,130.20,0.056
3.16,130.27,0.056
3.17,130.33,0.056
3.17,130.40,0.056
3.18,130.47,0.056
3.19,130.53,0.056
3.19,130.60,0.056
3.20,130.67,0.056
3.21,130.73,0.056
3.21,130.80,0.056
3.22,130.87,0.056
3.23,130.93,0.057
3.23,131.00,0.057
3.24,131.07,0.057
3.25,131.14,0.057
3.25,131.20,0.056
3.26,131.27,0.056
3.27,131.33,0.056
3.27,131.40,0.056
3.28,131.47,0.056
3.29,131.53,0.056
3.29,131.60,0.056
3.30,131.67,0.056
3.31,131.73,0.056
3.31,131.80,0.057
3.32,131.87,0.057
3.33,131.94,0.057
3.33,132.00,0.056
3.34,132.07,0.057
3.35,132.13,0.057
3.35,132.20,0.057
3.36,132.27,0.057
3.37,132.34,0.057
3.37,132.40,0.057
3.38,132.47,0.057
3.39,132.54,0.057
3.39,132.60,0.057
3.40,132.67,0.057
3.41,132.74,0.057
3.41,132.80,0.057
3.42,132.87,0.057
3.43,132.94,0.057
3.43,133.00,0.057
3.44,133.07,0.057
3.45,133.14,0.057
3.45,133.20,0.057
3.46,133.27,0.057
3.47,133.34,0.057
3.47,133.40,0.057
3.48,133.47,0.057
3.49,133.54,0.057
3.49,133.60,0.057
3.50,133.67,0.057
3.51,133.74,0.057
3.51,133.80,0.057
3.52,133.87,0.057
3.53,133.94,0.057
3.53,134.00,0.057
3.54,134.07,0.057
3.55,134.14,0.057
3.55,134.20,0.057
3.56,134.27,0.057
3.57,134.34,0.057
3.57,134.40,0.057
3.58,134.47,0.057
3.59,134.54,0.057
3.59,134.60,0.057
3.60,134.67,0.057
3.61,134.74,0.057
3.61,134.80,0.057
3.62,134.87,0.057
3.63,134.94,0.057
3.63,135.00,0.057
3.64,135.07,0.057
3.65,135.14,0.057
3.65,135.20,0.057
3.66,135.27,0.057
3.67,135.34,0.057
3.67,135.40,0.057
3.68,135.47,0.057
3.69,135.54,0.057
3.69,135.60,0.057
3.70,135.67,0.057
3.71,135.74,0.057
3.71,135.80,0.057
3.72,135.87,0.057
3.73,135.94,0.057
3.73,136.01,0.057
3.74,136.07,0.057
3.75,136.14,0.057
3.75,136.21,0.057
3.76,136.27,0.057
3.77,136.34,0.057
3.77,136.41,0.057
3.78,136.47,0.057
3.79,136.54,0.057
3.79,136.61,0.057
3.80,136.67,0.057
3.81,136.74,0.057
3.81,136.81,0.057
3.82,136.87,0.057
3.83,136.94,0.057
3.83,137.01,0.057
3.84,137.07,0.057
3.85,137.14,0.057
3.85,137.21,0.057
3.86,137.27,0.057
3.87,137.34,0.057
3.87,137.41,0.057
3.88,137.47,0.057
3.89,137.54,0.057
3.89,137.61,0.057
3.90,137.67,0.057
3.91,137.74,0.057
3.91,137.81,0.057
3.92,137.87,0.057
3.93,137.94,0.057
3.93,138.01,0.057
3.94,138.07,0.057
3.95,138.14,0.057
3.95,138.21,0.057
3.96,138.27,0.057
3.97,138.34,0.057
3.97,138.40,0.057
3.98,138.47,0.057
3.99,138.54,0.057
3.99,138.61,0.057
4.00,138.67,0.057
4.01,138.74,0.057
4.01,138.81,0.057
4.02,138.87,0.057
4.03,138.94,0.057
4.03,139.01,0.057
4.04,139.07,0.057
4.05,139.14,0.057
4.05,139.21,0.057
4.06,139.27,0.057
4.07,139.34,0.057
4.07,139.41,0.057
4.08,139.47,0.057
4.09,139.54,0.057
4.09,139.61,0.057
4.10,139.67,0.057
4.11,139.74,0.057
4.11,139.81,0.057
4.12,139.87,0.057
4.13,139.94,0.057
4.13,140.01,0.057
4.14,140.07,0.057
4.15,140.14,0.057
4.15,140.21,0.057
4.16,140.27,0.057
4.17,140.34,0.057
4.17,140.41,0.057
4.18,140.47,0.057
4.19,140.54,0.057
4.19,140.61,0.057
4.20,140.68,0.057
4.21,140.74,0.057
4.21,140.81,0.057
4.22,140.87,0.057
4.23,140.94,0.057
4.23,141.01,0.057
4.24,141.08,0.057
4.25,141.14,0.057
4.25,141.21,0.057
4.26,141.27,0.057
4.27,141.34,0.057
4.27,141.41,0.057
4.28,141.47,0.057
4.29,141.54,0.057
4.29,141.61,0.057
4.30,141.68,0.057
4.31,141.74,0.057
4.31,141.81,0.057
4.32,141.88,0.057
4.33,141.94,0.057
4.33,142.01,0.057
4.34,142.08,0.057
4.35,142.14,0.057
4.35,142.21,0.057
4.36,142.28,0.057
4.37,142.34,0.057
4.37,142.41,0.057
4.38,142.48,0.057
4.39,142.54,0.057
4.39,142.61,0.057
4.40,142.68,0.057
4.41,142.74,0.057
4.41,142.81,0.057
4.42,142.88,0.057
4.43,142.94,0.057
4.43,143.01,0.057
4.44,143.08,0.057
4.45,143.14,0.057
4.45,143.21,0.057
4.46,143.28,0.057
4.47,143.34,0.057
4.47,143.41,0.057
4.48,143.48,0.057
4.49,143.55,0.057
4.49,143.61,0.057
4.50,143.68,0.057
4.51,143.74,0.057
4.51,143.81,0.057
4.52,143.88,0.057
4.53,143.95,0.057
4.53,144.01,0.057
4.54,144.08,0.057
4.55,144.14,0.057
4.55,144.21,0.057
4.56,144.28,0.057
4.57,144.34,0.057
4.57,144.41,0.057
4.58,144.48,0.057
4.59,144.55,0.057
4.59,144.61,0.057
4.60,144.68,0.057
4.61,144.74,0.057
4.61,144.81,0.057
4.62,144.88,0.057
4.63,144.95,0.057
4.63,145.01,0.057
4.64,145.08,0.057
4.65,145.15,0.057
4.65,145.21,0.057
4.66,145.28,0.057
4.67,145.35,0.057
4.67,145.41,0.057
4.68,145.48,0.057
4.69,145.55,0.057
4.69,145.61,0.057
4.70,145.68,0.057
4.71,145.75,0.057
4.71,145.81,0.057
4.72,145.88,0.057
4.73,145.95,0.057
4.73,146.01,0.057
4.74,146.08,0.057
4.75,146.15,0.057
4.75,146.21,0.057
4.76,146.28,0.057
4.77,146.35,0.057
4.77,146.41,0.057
4.78,146.48,0.057
4.79,146.55,0.057
4.79,146.61,0.057
4.80,146.68,0.057
4.81,146.75,0.057
4.81,146.81,0.058
4.82,146.88,0.058
4.83,146.95,0.058
4.83,147.01,0.058
4.84,147.08,0.058
4.85,147.15,0.058
4.85,147.21,0.058
4.86,147.28,0.058
4.87,147.35,0.058
4.87,147.41,0.058
4.88,147.48,0.058
4.89,147.55,0.058
4.89,147.61,0.058
4.90,147.68,0.058
4.91,147.75,0.058
4.91,147.81,0.058
4.92,147.88,0.058
4.93,147.95,0.058
4.93,148.01,0.058
4.94,148.08,0.058
4.95,148.15,0.058
4.95,148.21,0.058
4.96,148.28,0.058
4.97,148.35,0.058
4.97,148.41,0.058
4.98,148.48,0.058
4.99,148.55,0.058
4.99,148.62,0.058
5.00,148.68,0.058
5.01,148.75,0.058
5.01,148.82,0.058
5.02,148.88,0.058
5.03,148.95,0.058
5.03,149.02,0.058
5.04,149.08,0.058
5.05,149.15,0.058
5.05,149.22,0.058
5.06,149.28,0.058
5.07,149.35,0.058
5.07,149.42,0.058
5.08,149.48,0.058
5.09,149.55,0.058
5.09,149.62,0.058
5.10,149.68,0.058
5.11,149.75,0.058
5.11,149.82,0.058
5.12,149.88,0.058
5.13,149.95,0.058
5.13,150.02,0.058
5.14,150.08,0.058
5.15,150.15,0.058
5.15,150.22,0.058
5.16,150.28,0.058
5.17,150.35,0.058
5.17,150.42,0.058
5.18,150.48,0.058
5.19,150.55,0.058
5.19,150.62,0.058
5.20,150.68,0.058
5.21,150.75,0.058
5.21,150.82,0.058
5.22,150.88,0.058
5.23,150.95,0.058
5.23,151.02,0.058
5.24,151.08,0.058
5.25,151.15,0.058
5.25,151.22,0.058
5.26,151.28,0.058
5.27,151.35,0.058
5.27,151.42,0.058
5.28,151.48,0.058
5.29,151.55,0.058
5.29,151.62,0.058
5.30,151.68,0.058
5.31,151.75,0.058
5.31,151.82,0.058
5.32,151.88,0.058
5.33,151.95,0.058
5.33,152.02,0.058
5.34,152.08,0.058
5.35,152.15,0.058
5.35,152.22,0.058
5.36,152.28,0.058
5.37,152.35,0.058
5.37,152.42,0.058
5.38,152.48,0.058
5.39,152.55,0.058
5.39,152.62,0.058
5.40,152.68,0.058
5.41,152.75,0.058
5.41,152.82,0.058
5.42,152.88,0.058
5.43,152.95,0.058
5.43,153.02,0.058
5.44,153.09,0.058
5.45,153.15,0.058
5.45,153.22,0.058
5.46,153.29,0.058
5.47,153.35,0.058
5.47,153.42,0.058
5.48,153.49,0.058
5.49,153.55,0.058
5.49,153.62,0.058
5.50,153.69,0.058
5.51,153.75,0.058
5.51,153.82,0.058
5.52,153.89,0.058
5.53,153.95,0.058
5.53,154.02,0.058
5.54,154.09,0.058
5.55,154.15,0.058
5.55,154.22,0.058
5.56,154.29,0.058
5.57,154.35,0.058
5.57,154.42,0.058
5.58,154.49,0.058
5.59,154.55,0.058
5.59,154.62,0.058
5.60,154.69,0.058
5.61,154.75,0.058
5.61,154.82,0.058
5.62,154.89,0.058
5.63,154.95,0.058
5.63,155.02,0.058
5.64,155.08,0.058
5.65,155.15,0.058
5.65,155.22,0.058
5.66,155.29,0.058
5.67,155.35,0.058
5.67,155.42,0.058
5.68,155.49,0.058
5.69,155.55,0.058
5.69,155.62,0.058
5.70,155.69,0.058
5.71,155.75,0.058
5.71,155.82,0.058
5.72,155.89,0.058
5.73,155.95,0.058
5.73,156.02,0.058
5.74,156.08,0.058
5.75,156.15,0.059
5.75,156.22,0.059
5.76,156.29,0.060
5.77,156.35,0.060
5.77,156.42,0.063
5.78,156.48,0.075
5.79,156.55,0.101
5.79,156.61,0.184
5.80,156.67,0.353
5.81,156.71,0.551
5.81,156.74,0.721
5.82,156.77,0.867
5.83,156.80,0.994
5.83,156.82,1.110
5.84,156.84,1.219
5.85,156.87,1.322
5.85,156.89,1.422
5.86,156.91,1.519
5.87,156.93,1.617
5.87,156.95,1.713
5.88,156.97,1.809
5.89,156.99,1.905
5.89,157.01,2.000
5.90,157.03,2.094
5.91,157.05,2.187
5.91,157.07,2.277
5.92,157.10,2.363
5.93,157.12,2.444
5.93,157.14,2.515
5.94,157.17,2.562
5.95,157.19,2.592
5.95,157.23,2.616
5.96,157.26,2.625
5.97,157.30,2.591
5.97,157.35,2.524
5.98,157.40,2.497
5.99,157.45,2.509
5.99,157.51,2.510
6.00,157.57,2.460
6.01,157.63,2.243
6.01,157.72,1.857
6.02,157.84,1.355
6.03,157.98,0.903
6.03,158.13,0.727
6.04,158.27,0.651
6.05,158.40,0.594
6.05,158.53,0.546
6.06,158.65,0.504
6.07,158.77,0.467
6.07,158.89,0.433
6.08,159.00,0.402
6.09,159.10,0.374
6.09,159.21,0.347
6.10,159.31,0.325
6.11,159.41,0.303
6.11,159.50,0.282
6.12,159.60,0.265
6.13,159.69,0.246
6.13,159.78,0.232
6.14,159.86,0.218
6.15,159.95,0.205
6.15,160.03,0.194
6.16,160.11,0.182
6.17,160.20,0.172
6.17,160.28,0.162
6.18,160.35,0.154
6.19,160.43,0.147
6.19,160.51,0.139
6.20,160.59,0.133
6.21,160.66,0.127
6.21,160.74,0.121
6.22,160.81,0.116
6.23,160.88,0.111
6.23,160.95,0.108
6.24,161.03,0.104
6.25,161.10,0.100
6.25,161.17,0.098
6.26,161.24,0.094
6.27,161.31,0.091
6.27,161.38,0.089
6.28,161.45,0.086
6.29,161.52,0.084
6.29,161.59,0.083
6.30,161.66,0.081
6.31,161.73,0.079
6.31,161.80,0.077
6.32,161.87,0.076
6.33,161.94,0.075
6.33,162.01,0.074
6.34,162.07,0.073
6.35,162.14,0.073
6.35,162.21,0.072
6.36,162.28,0.071
6.37,162.34,0.070
6.37,162.41,0.070
6.38,162.48,0.069
6.39,162.55,0.068
6.39,162.61,0.067
6.40,162.68,0.067
6.41,162.75,0.066
6.41,162.82,0.066
6.42,162.89,0.066
6.43,162.95,0.065
6.43,163.02,0.065
6.44,163.09,0.065
6.45,163.15,0.065
6.45,163.22,0.064
6.46,163.29,0.064
6.47,163.36,0.064
6.47,163.42,0.064
6.48,163.49,0.064
6.49,163.56,0.064
6.49,163.62,0.063
6.50,163.69,0.063
6.51,163.76,0.063
6.51,163.82,0.063
6.52,163.89,0.063
6.53,163.96,0.063
6.53,164.02,0.063
6.54,164.09,0.063
6.55,164.16,0.063
6.55,164.22,0.063
6.56,164.29,0.063
6.57,164.36,0.063
6.57,164.42,0.063
6.58,164.49,0.062
6.59,164.56,0.062
6.59,164.63,0.062
6.60,164.69,0.062
6.61,164.76,0.062
6.61,164.83,0.062
6.62,164.89,0.062
6.63,164.96,0.062
6.63,165.03,0.062
6.64,165.09,0.062
6.65,165.16,0.062
6.65,165.23,0.062
6.66,165.29,0.062
6.67,165.36,0.062
6.67,165.43,0.062
6.68,165.49,0.062
6.69,165.56,0.062
6.69,165.63,0.062
6.70,165.69,0.062
6.71,165.76,0.062
6.71,165.83,0.062
6.72,165.89,0.062
6.73,165.96,0.062
6.73,166.03,0.062
6.74,166.09,0.062
6.75,166.16,0.062
6.75,166.23,0.062
6.76,166.29,0.062
6.77,166.36,0.061
6.77,166.43,0.061
6.78,166.49,0.061
6.79,166.56,0.061
6.79,166.63,0.061
6.80,166.69,0.061
6.81,166.76,0.061
6.81,166.83,0.061
6.82,166.89,0.061
6.83,166.96,0.061
6.83,167.03,0.061
6.84,167.09,0.061
6.85,167.16,0.061
6.85,167.23,0.061
6.86,167.29,0.061
6.87,167.36,0.061
6.87,167.43,0.061
6.88,167.49,0.061
6.89,167.56,0.061
6.89,167.63,0.061
6.90,167.69,0.061
6.91,167.76,0.061
6.91,167.83,0.061
6.92,167.90,0.061
6.93,167.96,0.061
6.93,168.03,0.061
6.94,168.10,0.061
6.95,168.16,0.061
6.95,168.23,0.061
6.96,168.30,0.061
6.97,168.36,0.061
6.97,168.43,0.061
6.98,168.50,0.061
6.99,168.56,0.061
6.99,168.63,0.061
7.00,168.70,0.061
7.01,168.76,0.061
7.01,168.83,0.061
7.02,168.90,0.061
7.03,168.96,0.061
7.03,169.03,0.061
7.04,169.10,0.061
7.05,169.16,0.061
7.05,169.23,0.061
7.06,169.30,0.061
7.07,169.36,0.060
7.07,169.43,0.060
7.08,169.50,0.060
7.09,169.56,0.060
7.09,169.63,0.060
7.10,169.70,0.060
7.11,169.76,0.060
7.11,169.83,0.060
7.12,169.90,0.060
7.13,169.96,0.060
7.13,170.03,0.060
7.14,170.10,0.060
7.15,170.16,0.060
7.15,170.23,0.060
7.16,170.30,0.060
7.17,170.36,0.060
7.17,170.43,0.060
7.18,170.50,0.060
7.19,170.56,0.060
7.19,170.63,0.060
7.20,170.70,0.060
7.21,170.76,0.060
7.21,170.83,0.060
7.22,170.90,0.060
7.23,170.96,0.060
7.23,171.03,0.060
7.24,171.10,0.060
7.25,171.17,0.060
7.25,171.23,0.060
7.26,171.30,0.060
7.27,171.36,0.060
7.27,171.43,0.060
7.28,171.50,0.060
7.29,171.57,0.060
7.29,171.63,0.060
7.30,171.70,0.060
7.31,171.77,0.060
7.31,171.83,0.060
7.32,171.90,0.060
7.33,171.96,0.060
7.33,172.03,0.060
7.34,172.10,0.060
7.35,172.17,0.060
7.35,172.23,0.060
7.36,172.30,0.060
7.37,172.37,0.060
7.37,172.43,0.060
7.38,172.50,0.060
7.39,172.57,0.060
7.39,172.63,0.060
7.40,172.70,0.060
7.41,172.77,0.060
7.41,172.83,0.060
7.42,172.90,0.060
7.43,172.97,0.060
7.43,173.03,0.060
7.44,173.10,0.060
7.45,173.17,0.060
7.45,173.23,0.060
7.46,173.30,0.059
7.47,173.37,0.059
7.47,173.43,0.059
7.48,173.50,0.059
7.49,173.57,0.059
7.49,173.63,0.059
7.50,173.70,0.059
7.51,173.77,0.059
7.51,173.83,0.059
7.52,173.90,0.059
7.53,173.97,0.059
7.53,174.03,0.059
7.54,174.10,0.059
7.55,174.17,0.059
7.55,174.23,0.059
7.56,174.30,0.059
7.57,174.37,0.059
7.57,174.43,0.059
7.58,174.50,0.059
7.59,174.57,0.059
7.59,174.63,0.059
7.60,174.70,0.059
7.61,174.77,0.059
7.61,174.83,0.059
7.62,174.90,0.059
7.63,174.97,0.059
7.63,175.04,0.059
7.64,175.10,0.059
7.65,175.17,0.059
7.65,175.24,0.059
7.66,175.30,0.059
7.67,175.37,0.059
7.67,175.44,0.059
7.68,175.50,0.059
7.69,175.57,0.059
7.69,175.64,0.059
7.70,175.70,0.059
7.71,175.77,0.059
7.71,175.84,0.059
7.72,175.90,0.059
7.73,175.97,0.059
7.73,176.04,0.059
7.74,176.10,0.059
7.75,176.17,0.059
7.75,176.24,0.059
7.76,176.30,0.059
7.77,176.37,0.059
7.77,176.43,0.059
7.78,176.50,0.059
7.79,176.57,0.059
7.79,176.63,0.059
7.80,176.70,0.059
7.81,176.77,0.059
7.81,176.83,0.059
7.82,176.90,0.059
7.83,176.97,0.059
7.83,177.04,0.058
7.84,177.10,0.058
7.85,177.17,0.058
7.85,177.24,0.058
7.86,177.30,0.058
7.87,177.37,0.058
7.87,177.44,0.058
7.88,177.50,0.058
7.89,177.57,0.058
7.89,177.64,0.058
7.90,177.70,0.058
7.91,177.77,0.058
7.91,177.83,0.058
7.92,177.90,0.058
7.93,177.97,0.058
7.93,178.03,0.058
7.94,178.10,0.058
7.95,178.17,0.058
7.95,178.23,0.058
7.96,178.30,0.058
7.97,178.36,0.058
7.97,178.43,0.058
7.98,178.50,0.058
7.99,178.56,0.058
7.99,178.63,0.058
8.00,178.70,0.058
8.01,178.76,0.058
8.01,178.83,0.058
8.02,178.90,0.058
8.03,178.96,0.058
8.03,179.03,0.058
8.04,179.10,0.058
8.05,179.16,0.058
8.05,179.23,0.058
8.06,179.30,0.058
8.07,179.37,0.058
8.07,179.43,0.058
8.08,179.50,0.058
8.09,179.57,0.058
8.09,179.63,0.058
8.10,179.70,0.058
8.11,179.77,0.058
8.11,179.84,0.058
8.12,179.90,0.058
8.13,179.97,0.058
8.13,180.04,0.058
8.14,180.10,0.058
8.15,180.17,0.058
8.15,180.24,0.058
8.16,180.30,0.058
8.17,180.37,0.058
8.17,180.44,0.058
8.18,180.50,0.058
8.19,180.57,0.058
8.19,180.64,0.058
8.20,180.70,0.058
8.21,180.77,0.058
8.21,180.84,0.058
8.22,180.91,0.058
8.23,180.97,0.058
8.23,181.04,0.058
8.24,181.11,0.058
8.25,181.17,0.058
8.25,181.24,0.058
8.26,181.31,0.058
8.27,181.37,0.058
8.27,181.44,0.058
8.28,181.51,0.058
8.29,181.57,0.058
8.29,181.64,0.058
8.30,181.71,0.058
8.31,181.77,0.058
8.31,181.84,0.058
8.32,181.91,0.058
8.33,181.97,0.058
8.33,182.04,0.058
8.34,182.11,0.058
8.35,182.17,0.058
8.35,182.24,0.058
8.36,182.30,0.058
8.37,182.37,0.058
8.37,182.44,0.058
8.38,182.51,0.058
8.39,182.57,0.058
8.39,182.64,0.058
8.40,182.71,0.058
8.41,182.77,0.058
8.41,182.84,0.058
8.42,182.91,0.058
8.43,182.97,0.058
8.43,183.04,0.058
8.44,183.11,0.058
8.45,183.17,0.058
8.45,183.24,0.058
8.46,183.31,0.058
8.47,183.37,0.058
8.47,183.44,0.058
8.48,183.51,0.058
8.49,183.57,0.058
8.49,183.64,0.058
8.50,183.71,0.058
8.51,183.77,0.058
8.51,183.84,0.058
8.52,183.91,0.058
8.53,183.97,0.058
8.53,184.04,0.058
8.54,184.11,0.058
8.55,184.17,0.058
8.55,184.24,0.058
8.56,184.31,0.058
8.57,184.37,0.058
8.57,184.44,0.058
8.58,184.51,0.058
8.59,184.57,0.058
8.59,184.64,0.058
8.60,184.71,0.058
8.61,184.77,0.058
8.61,184.84,0.058
8.62,184.91,0.058
8.63,184.97,0.058
8.63,185.04,0.058
8.64,185.11,0.058
8.65,185.17,0.058
8.65,185.24,0.058
8.66,185.31,0.058
8.67,185.37,0.058
8.67,185.44,0.058
8.68,185.51,0.058
8.69,185.58,0.058
8.69,185.64,0.058
8.70,185.71,0.057
8.71,185.78,0.057
8.71,185.84,0.057
8.72,185.91,0.057
8.73,185.97,0.057
8.73,186.04,0.057
8.74,186.11,0.057
8.75,186.18,0.057
8.75,186.24,0.057
8.76,186.31,0.057
8.77,186.38,0.057
8.77,186.44,0.057
8.78,186.51,0.057
8.79,186.58,0.057
8.79,186.64,0.057
8.80,186.71,0.057
8.81,186.78,0.057
8.81,186.84,0.057
8.82,186.91,0.057
8.83,186.98,0.057
8.83,187.04,0.057
8.84,187.11,0.057
8.85,187.18,0.057
8.85,187.24,0.057
8.86,187.31,0.057
8.87,187.38,0.057
8.87,187.44,0.057
8.88,187.51,0.057
8.89,187.58,0.057
8.89,187.64,0.057
8.90,187.71,0.057
8.91,187.78,0.057
8.91,187.84,0.057
8.92,187.91,0.057
8.93,187.98,0.057
8.93,188.04,0.057
8.94,188.11,0.057
8.95,188.18,0.057
8.95,188.24,0.057
8.96,188.31,0.057
8.97,188.38,0.057
8.97,188.44,0.057
8.98,188.51,0.057
8.99,188.58,0.057
8.99,188.64,0.057
9.00,188.71,0.057
9.01,188.78,0.057
9.01,188.84,0.057
9.02,188.91,0.057
9.03,188.98,0.057
9.03,189.04,0.057
9.04,189.11,0.057
9.05,189.18,0.057
9.05,189.24,0.057
9.06,189.31,0.057
9.07,189.38,0.057
9.07,189.44,0.057
9.08,189.51,0.057
9.09,189.58,0.057
9.09,189.64,0.057
9.10,189.71,0.057
9.11,189.78,0.057
9.11,189.84,0.057
9.12,189.91,0.057
9.13,189.98,0.057
9.13,190.04,0.057
9.14,190.11,0.057
9.15,190.18,0.057
9.15,190.24,0.057
9.16,190.31,0.057
9.17,190.38,0.057
9.17,190.45,0.057
9.18,190.51,0.057
9.19,190.58,0.057
9.19,190.65,0.057
9.20,190.71,0.057
9.21,190.78,0.057
9.21,190.84,0.057
9.22,190.91,0.057
9.23,190.98,0.057
9.23,191.04,0.057
9.24,191.11,0.057
9.25,191.18,0.057
9.25,191.25,0.057
9.26,191.31,0.057
9.27,191.38,0.057
9.27,191.45,0.057
9.28,191.51,0.057
9.29,191.58,0.057
9.29,191.64,0.057
9.30,191.71,0.057
9.31,191.78,0.057
9.31,191.85,0.057
9.32,191.91,0.057
9.33,191.98,0.057
9.33,192.04,0.057
9.34,192.11,0.057
9.35,192.18,0.057
9.35,192.25,0.057
9.36,192.31,0.057
9.37,192.38,0.057
9.37,192.45,0.057
9.38,192.51,0.057
9.39,192.58,0.057
9.39,192.65,0.057
9.40,192.71,0.057
9.41,192.78,0.057
9.41,192.85,0.057
9.42,192.91,0.057
9.43,192.98,0.057
9.43,193.05,0.057
9.44,193.11,0.057
9.45,193.18,0.057
9.45,193.25,0.057
9.46,193.31,0.057
9.47,193.38,0.057
9.47,193.45,0.057
9.48,193.51,0.057
9.49,193.58,0.057
9.49,193.65,0.057
9.50,193.71,0.057
9.51,193.78,0.057
9.51,193.85,0.057
9.52,193.91,0.057
9.53,193.98,0.057
9.53,194.05,0.057
9.54,194.11,0.057
9.55,194.18,0.057
9.55,194.25,0.057
9.56,194.31,0.057
9.57,194.38,0.057
9.57,194.45,0.057
9.58,194.51,0.057
9.59,194.58,0.057
9.59,194.65,0.057
9.60,194.71,0.057
9.61,194.78,0.057
9.61,194.85,0.057
9.62,194.91,0.057
9.63,194.98,0.057
9.63,195.05,0.057
9.64,195.11,0.057
9.65,195.18,0.057
9.65,195.25,0.057
9.66,195.31,0.057
9.67,195.38,0.057
9.67,195.45,0.057
9.68,195.51,0.057
9.69,195.58,0.057
9.69,195.65,0.057
9.70,195.71,0.057
9.71,195.78,0.057
9.71,195.85,0.057
9.72,195.91,0.057
9.73,195.98,0.057
9.73,196.05,0.057
9.74,196.11,0.057
9.75,196.18,0.056
9.75,196.25,0.056
9.76,196.31,0.056
9.77,196.38,0.056
9.77,196.45,0.056
9.78,196.52,0.056
9.79,196.58,0.056
9.79,196.65,0.056
9.80,196.71,0.056
9.81,196.78,0.056
9.81,196.85,0.056
9.82,196.92,0.056
9.83,196.98,0.056
9.83,197.05,0.056
9.84,197.11,0.056
9.85,197.18,0.056
9.85,197.25,0.056
9.86,197.31,0.056
9.87,197.38,0.056
9.87,197.45,0.056
9.88,197.52,0.056
9.89,197.58,0.056
9.89,197.65,0.056
9.90,197.72,0.056
9.91,197.78,0.056
9.91,197.85,0.056
9.92,197.91,0.056
9.93,197.98,0.056
9.93,198.05,0.056
9.94,198.12,
9.95,198.18,
9.95,198.25,
9.96,198.32,
9.97,198.38,
9.97,198.45,
9.98,198.52,
9.99,198.58,
9.99,,
10.00,,

[step]
Ramp 10.00 °C/min to 100.00 °C
Time,Temperature,Heat Flow (Normalized)
min,°C,W/g
11.00,200.11,-0.028
11.00,200.11,-0.028
11.01,200.11,-0.028
11.02,200.11,-0.028
11.02,200.11,-0.028
11.03,200.11,-0.028
11.04,200.10,-0.028
11.04,200.10,-0.028
11.05,200.10,-0.028
11.06,200.09,-0.028
11.06,200.08,-0.028
11.07,200.07,-0.029
11.08,200.06,-0.030
11.08,200.05,-0.030
11.09,200.03,-0.033
11.10,200.01,-0.036
11.10,199.99,-0.039
11.11,199.96,-0.043
11.12,199.93,-0.046
11.12,199.90,-0.049
11.13,199.86,-0.053
11.14,199.82,-0.057
11.14,199.78,-0.060
11.15,199.74,-0.063
11.16,199.70,-0.066
11.16,199.65,-0.070
11.17,199.60,-0.073
11.18,199.55,-0.076
11.18,199.50,-0.079
11.19,199.44,-0.082
11.20,199.39,-0.084
11.20,199.34,-0.086
11.21,199.28,-0.088
11.22,199.22,-0.090
11.22,199.16,-0.092
11.23,199.10,-0.093
11.24,199.04,-0.094
11.24,198.98,-0.095
11.25,198.92,-0.096
11.26,198.86,-0.097
11.26,198.80,-0.098
11.27,198.74,-0.100
11.28,198.68,-0.101
11.28,198.62,-0.101
11.29,198.55,-0.101
11.30,198.49,-0.102
11.30,198.43,-0.102
11.31,198.36,-0.103
11.32,198.30,-0.103
11.32,198.24,-0.104
11.33,198.17,-0.104
11.34,198.11,-0.104
11.34,198.04,-0.105
11.35,197.98,-0.105
11.36,197.92,-0.105
11.36,197.85,-0.106
11.37,197.79,-0.106
11.38,197.72,-0.106
11.38,197.66,-0.106
11.39,197.59,-0.106
11.40,197.53,-0.106
11.40,197.46,-0.106
11.41,197.40,-0.106
11.42,197.33,-0.107
11.42,197.27,-0.107
11.43,197.20,-0.107
11.44,197.14,-0.107
11.44,197.07,-0.107
11.45,197.01,-0.107
11.46,196.94,-0.107
11.46,196.87,-0.107
11.47,196.81,-0.107
11.48,196.74,-0.108
11.48,196.68,-0.108
11.49,196.61,-0.108
11.50,196.55,-0.108
11.50,196.48,-0.108
11.51,196.41,-0.108
11.52,196.35,-0.108
11.52,196.28,-0.108
11.53,196.22,-0.108
11.54,196.15,-0.108
11.54,196.09,-0.108
11.55,196.02,-0.108
11.56,195.95,-0.108
11.56,195.89,-0.108
11.57,195.82,-0.108
11.58,195.76,-0.108
11.58,195.69,-0.108
11.59,195.62,-0.108
11.60,195.56,-0.108
11.60,195.49,-0.108
11.61,195.43,-0.108
11.62,195.36,-0.108
11.62,195.29,-0.108
11.63,195.23,-0.108
11.64,195.16,-0.109
11.64,195.10,-0.109
11.65,195.03,-0.109
11.66,194.97,-0.109
11.66,194.90,-0.109
11.67,194.83,-0.109
11.68,194.77,-0.109
11.68,194.70,-0.109
11.69,194.64,-0.109
11.70,194.57,-0.109
11.70,194.50,-0.109
11.71,194.44,-0.109
11.72,194.37,-0.109
11.72,194.30,-0.109
11.73,194.24,-0.109
11.74,194.17,-0.109
11.74,194.11,-0.109
11.75,194.04,-0.109
11.76,193.97,-0.109
11.76,193.91,-0.109
11.77,193.84,-0.109
11.78,193.77,-0.109
11.78,193.71,-0.109
11.79,193.64,-0.109
11.80,193.57,-0.109
11.80,193.51,-0.109
11.81,193.44,-0.109
11.82,193.38,-0.109
11.82,193.31,-0.109
11.83,193.24,-0.109
11.84,193.18,-0.109
11.84,193.11,-0.109
11.85,193.05,-0.109
11.86,192.98,-0.109
11.86,192.91,-0.109
11.87,192.85,-0.109
11.88,192.78,-0.109
11.88,192.72,-0.109
11.89,192.65,-0.109
11.90,192.58,-0.109
11.90,192.52,-0.109
11.91,192.45,-0.109
11.92,192.38,-0.109
11.92,192.32,-0.109
11.93,192.25,-0.109
11.94,192.19,-0.109
11.94,192.12,-0.109
11.95,192.05,-0.109
11.96,191.99,-0.109
11.96,191.92,-0.109
11.97,191.85,-0.109
11.98,191.79,-0.109
11.98,191.72,-0.109
11.99,191.65,-0.109
12.00,191.59,-0.109
12.00,191.52,-0.109
12.01,191.46,-0.109
12.02,191.39,-0.109
12.02,191.32,-0.109
12.03,191.26,-0.109
12.04,191.19,-0.109
12.04,191.12,-0.109
12.05,191.06,-0.109
12.06,190.99,-0.109
12.06,190.93,-0.109
12.07,190.86,-0.109
12.08,190.79,-0.109
12.08,190.73,-0.109
12.09,190.66,-0.109
12.10,190.59,-0.109
12.10,190.53,-0.109
12.11,190.46,-0.109
12.12,190.39,-0.109
12.12,190.33,-0.109
12.13,190.26,-0.109
12.14,190.19,-0.109
12.14,190.13,-0.109
12.15,190.06,-0.109
12.16,189.99,-0.109
12.16,189.93,-0.109
12.17,189.86,-0.109
12.18,189.80,-0.109
12.18,189.73,-0.109
12.19,189.66,-0.109
12.20,189.60,-0.109
12.20,189.53,-0.109
12.21,189.46,-0.109
12.22,189.40,-0.109
12.22,189.33,-0.109
12.23,189.26,-0.109
12.24,189.20,-0.109
12.24,189.13,-0.109
12.25,189.07,-0.109
12.26,189.00,-0.109
12.26,188.93,-0.109
12.27,188.87,-0.109
12.28,188.80,-0.109
12.28,188.73,-0.109
12.29,188.67,-0.109
12.30,188.60,-0.109
12.30,188.53,-0.109
12.31,188.47,-0.109
12.32,188.40,-0.109
12.32,188.34,-0.109
12.33,188.27,-0.109
12.34,188.20,-0.109
12.34,188.13,-0.109
12.35,188.07,-0.109
12.36,188.00,-0.109
12.36,187.93,-0.109
12.37,187.87,-0.109
12.38,187.80,-0.109
12.38,187.74,-0.109
12.39,187.67,-0.109
12.40,187.60,-0.109
12.40,187.54,-0.109
12.41,187.47,-0.109
12.42,187.40,-0.109
12.42,187.34,-0.109
12.43,187.27,-0.109
12.44,187.20,-0.109
12.44,187.14,-0.109
12.45,187.07,-0.109
12.46,187.00,-0.109
12.46,186.94,-0.108
12.47,186.87,-0.108
12.48,186.80,-0.108
12.48,186.74,-0.108
12.49,186.67,-0.108
12.50,186.60,-0.108
12.50,186.54,-0.108
12.51,186.47,-0.108
12.52,186.41,-0.108
12.52,186.34,-0.108
12.53,186.27,-0.108
12.54,186.21,-0.108
12.54,186.14,-0.108
12.55,186.07,-0.108
12.56,186.01,-0.108
12.56,185.94,-0.108
12.57,185.87,-0.108
12.58,185.81,-0.108
12.58,185.74,-0.108
12.59,185.67,-0.108
12.60,185.61,-0.108
12.60,185.54,-0.108
12.61,185.48,-0.108
12.62,185.41,-0.108
12.62,185.34,-0.108
12.63,185.28,-0.108
12.64,185.21,-0.108
12.64,185.14,-0.108
12.65,185.08,-0.108
12.66,185.01,-0.108
12.66,184.94,-0.108
12.67,184.88,-0.108
12.68,184.81,-0.108
12.68,184.74,-0.108
12.69,184.68,-0.108
12.70,184.61,-0.108
12.70,184.54,-0.108
12.71,184.48,-0.108
12.72,184.41,-0.108
12.72,184.34,-0.108
12.73,184.28,-0.108
12.74,184.21,-0.108
12.74,184.14,-0.108
12.75,184.08,-0.108
12.76,184.01,-0.108
12.76,183.94,-0.108
12.77,183.88,-0.108
12.78,183.81,-0.108
12.78,183.74,-0.108
12.79,183.68,-0.108
12.80,183.61,-0.108
12.80,183.55,-0.108
12.81,183.48,-0.108
12.82,183.41,-0.108
12.82,183.34,-0.108
12.83,183.28,-0.108
12.84,183.21,-0.108
12.84,183.15,-0.108
12.85,183.08,-0.108
12.86,183.01,-0.108
12.86,182.95,-0.108
12.87,182.88,-0.108
12.88,182.81,-0.108
12.88,182.75,-0.108
12.89,182.68,-0.107
12.90,182.61,-0.107
12.90,182.55,-0.107
12.91,182.48,-0.107
12.92,182.41,-0.107
12.92,182.35,-0.107
12.93,182.28,-0.107
12.94,182.21,-0.107
12.94,182.15,-0.107
12.95,182.08,-0.107
12.96,182.01,-0.107
12.96,181.95,-0.107
12.97,181.88,-0.107
12.98,181.81,-0.107
12.98,181.75,-0.107
12.99,181.68,-0.107
13.00,181.61,-0.107
13.00,181.55,-0.107
13.01,181.48,-0.107
13.02,181.41,-0.107
13.02,181.35,-0.107
13.03,181.28,-0.107
13.04,181.21,-0.107
13.04,181.15,-0.107
13.05,181.08,-0.107
13.06,181.01,-0.107
13.06,180.95,-0.107
13.07,180.88,-0.107
13.08,180.82,-0.107
13.08,180.75,-0.107
13.09,180.68,-0.107
13.10,180.61,-0.107
13.10,180.55,-0.107
13.11,180.48,-0.107
13.12,180.41,-0.107
13.12,180.35,-0.107
13.13,180.28,-0.107
13.14,180.21,-0.107
13.14,180.15,-0.107
13.15,180.08,-0.107
13.16,180.01,-0.107
13.16,179.95,-0.107
13.17,179.88,-0.107
13.18,179.82,-0.107
13.18,179.75,-0.107
13.19,179.68,-0.107
13.20,179.62,-0.107
13.20,179.55,-0.107
13.21,179.48,-0.107
13.22,179.42,-0.107
13.22,179.35,-0.107
13.23,179.28,-0.107
13.24,179.22,-0.107
13.24,179.15,-0.107
13.25,179.08,-0.107
13.26,179.02,-0.107
13.26,178.95,-0.107
13.27,178.88,-0.107
13.28,178.82,-0.107
13.28,178.75,-0.107
13.29,178.68,-0.107
13.30,178.62,-0.107
13.30,178.55,-0.107
13.31,178.48,-0.107
13.32,178.42,-0.107
13.32,178.35,-0.107
13.33,178.28,-0.107
13.34,178.22,-0.107
13.34,178.15,-0.107
13.35,178.08,-0.107
13.36,178.02,-0.107
13.36,177.95,-0.107
13.37,177.88,-0.107
13.38,177.82,-0.107
13.38,177.75,-0.107
13.39,177.68,-0.107
13.40,177.62,-0.106
13.40,177.55,-0.106
[...]
36.32,168.43,-0.105
36.32,168.37,-0.105
36.33,168.30,-0.105
36.34,168.23,-0.105
36.34,168.17,-0.105
36.35,168.10,-0.105
36.36,168.03,-0.105
36.36,167.97,-0.105
36.37,167.90,-0.105
36.38,167.83,-0.105
36.38,167.77,-0.105
36.39,167.70,-0.105
36.40,167.63,-0.105
36.40,167.57,-0.105
36.41,167.50,-0.105
36.42,167.43,-0.105
36.42,167.37,-0.105
36.43,167.30,-0.105
36.44,167.23,-0.105
36.44,167.17,-0.105
36.45,167.10,-0.105
36.46,167.04,-0.105
36.46,166.97,-0.105
36.47,166.90,-0.105
36.48,166.84,-0.105
36.48,166.77,-0.105
36.49,166.70,-0.105
36.50,166.64,-0.105
36.50,166.57,-0.105
36.51,166.50,-0.105
36.52,166.44,-0.105
36.52,166.37,-0.105
36.53,166.30,-0.105
36.54,166.24,-0.105
36.54,166.17,-0.105
36.55,166.10,-0.105
36.56,166.04,-0.105
36.56,165.97,-0.105
36.57,165.90,-0.105
36.58,165.84,-0.105
36.58,165.77,-0.105
36.59,165.70,-0.105
36.60,165.64,-0.105
36.60,165.57,-0.105
36.61,165.50,-0.105
36.62,165.44,-0.105
36.62,165.37,-0.105
36.63,165.30,-0.105
36.64,165.24,-0.105
36.64,165.17,-0.105
36.65,165.10,-0.105
36.66,165.04,-0.105
36.66,164.97,-0.105
36.67,164.91,-0.105
36.68,164.84,-0.105
36.68,164.77,-0.105
36.69,164.71,-0.105
36.70,164.64,-0.105
36.70,164.57,-0.105
36.71,164.51,-0.105
36.72,164.44,-0.105
36.72,164.37,-0.105
36.73,164.31,-0.105
36.74,164.24,-0.105
36.74,164.17,-0.105
36.75,164.11,-0.105
36.76,164.04,-0.105
36.76,163.97,-0.105
36.77,163.91,-0.105
36.78,163.84,-0.105
36.78,163.77,-0.105
36.79,163.71,-0.105
36.80,163.64,-0.105
36.80,163.57,-0.105
36.81,163.51,-0.105
36.82,163.44,-0.105
36.82,163.37,-0.105
36.83,163.31,-0.105
36.84,163.24,-0.105
36.84,163.17,-0.105
36.85,163.11,-0.105
36.86,163.04,-0.105
36.86,162.97,-0.105
36.87,162.91,-0.105
36.88,162.84,-0.105
36.88,162.77,-0.105
36.89,162.71,-0.105
36.90,162.64,-0.105
36.90,162.57,-0.105
36.91,162.51,-0.105
36.92,162.44,-0.105
36.92,162.37,-0.105
36.93,162.31,-0.105
36.94,162.24,-0.105
36.94,162.17,-0.105
36.95,162.11,-0.105
36.96,162.04,-0.105
36.96,161.97,-0.105
36.97,161.91,-0.105
36.98,161.84,-0.105
36.98,161.78,-0.105
36.99,161.71,-0.105
37.00,161.64,-0.105
37.00,161.58,-0.105
37.01,161.51,-0.105
37.02,161.44,-0.105
37.02,161.38,-0.105
37.03,161.31,-0.105
37.04,161.24,-0.105
37.04,161.17,-0.105
37.05,161.11,-0.105
37.06,161.04,-0.105
37.06,160.98,-0.105
37.07,160.91,-0.105
37.08,160.84,-0.105
37.08,160.78,-0.105
37.09,160.71,-0.105
37.10,160.64,-0.105
37.10,160.58,-0.105
37.11,160.51,-0.105
37.12,160.44,-0.105
37.12,160.38,-0.105
37.13,160.31,-0.105
37.14,160.24,-0.105
37.14,160.18,-0.105
37.15,160.11,-0.105
37.16,160.04,-0.105
37.16,159.98,-0.105
37.17,159.91,-0.105
37.18,159.84,-0.105
37.18,159.78,-0.105
37.19,159.71,-0.105
37.20,159.64,-0.105
37.20,159.58,-0.105
37.21,159.51,-0.105
37.22,159.44,-0.105
37.22,159.38,-0.105
37.23,159.31,-0.105
37.24,159.24,-0.105
37.24,159.18,-0.105
37.25,159.11,-0.105
37.26,159.04,-0.105
37.26,158.98,-0.105
37.27,158.91,-0.105
37.28,158.84,-0.105
37.28,158.78,-0.105
37.29,158.71,-0.105
37.30,158.64,-0.105
37.30,158.58,-0.105
37.31,158.51,-0.105
37.32,158.44,-0.105
37.32,158.38,-0.105
37.33,158.31,-0.105
37.34,158.24,-0.105
37.34,158.18,-0.105
37.35,158.11,-0.105
37.36,158.04,-0.105
37.36,157.98,-0.105
37.37,157.91,-0.105
37.38,157.84,-0.105
37.38,157.78,-0.105
37.39,157.71,-0.105
37.40,157.64,-0.105
37.40,157.58,-0.105
37.41,157.51,-0.105
37.42,157.44,-0.105
37.42,157.38,-0.105
37.43,157.31,-0.104
37.44,157.25,-0.104
37.44,157.18,-0.104
37.45,157.11,-0.104
37.46,157.05,-0.104
37.46,156.98,-0.104
37.47,156.91,-0.104
37.48,156.85,-0.104
37.48,156.78,-0.104
37.49,156.71,-0.104
37.50,156.65,-0.104
37.50,156.58,-0.104
37.51,156.51,-0.104
37.52,156.45,-0.104
37.52,156.38,-0.104
37.53,156.31,-0.104
37.54,156.25,-0.104
37.54,156.18,-0.105
37.55,156.11,-0.104
37.56,156.05,-0.104
37.56,155.98,-0.104
37.57,155.91,-0.104
37.58,155.85,-0.104
37.58,155.78,-0.104
37.59,155.71,-0.104
37.60,155.65,-0.104
37.60,155.58,-0.104
37.61,155.51,-0.104
37.62,155.45,-0.104
37.62,155.38,-0.104
37.63,155.31,-0.104
37.64,155.25,-0.104
37.64,155.18,-0.104
37.65,155.12,-0.104
37.66,155.05,-0.104
37.66,154.98,-0.104
37.67,154.91,-0.104
37.68,154.85,-0.104
37.68,154.78,-0.104
37.69,154.71,-0.104
37.70,154.65,-0.104
37.70,154.58,-0.126
37.71,154.52,-0.527
37.72,154.50,-2.629
37.72,154.68,-5.859
37.73,154.95,-6.851
37.74,155.12,-5.864
37.74,155.21,-5.065
37.75,155.26,-4.892
37.76,155.31,-4.916
37.76,155.35,-4.769
37.77,155.37,-4.598
37.78,155.37,-4.430
37.78,155.36,-4.351
37.79,155.34,-4.208
37.80,155.30,-3.822
37.80,155.23,-2.748
37.81,155.07,-1.324
37.82,154.88,-0.677
37.82,154.69,-0.575
37.83,154.52,-0.509
37.84,154.36,-0.464
37.84,154.20,-0.429
37.85,154.05,-0.400
37.86,153.91,-0.376
37.86,153.77,-0.353
37.87,153.64,-0.332
37.88,153.51,-0.314
37.88,153.39,-0.298
37.89,153.28,-0.282
37.90,153.16,-0.268
37.90,153.05,-0.255
37.91,152.95,-0.243
37.92,152.85,-0.231
37.92,152.75,-0.221
37.93,152.65,-0.213
37.94,152.56,-0.204
37.94,152.46,-0.196
37.95,152.38,-0.189
37.96,152.29,-0.182
37.96,152.20,-0.175
37.97,152.12,-0.170
37.98,152.03,-0.164
37.98,151.95,-0.160
37.99,151.87,-0.155
38.00,151.79,-0.151
38.00,151.71,-0.147
38.01,151.64,-0.144
38.02,151.56,-0.141
38.02,151.49,-0.138
38.03,151.41,-0.135
38.04,151.34,-0.132
38.04,151.26,-0.129
38.05,151.19,-0.128
38.06,151.12,-0.126
38.06,151.05,-0.124
38.07,150.97,-0.122
38.08,150.90,-0.121
38.08,150.83,-0.120
38.09,150.76,-0.118
38.10,150.69,-0.117
38.10,150.62,-0.117
38.11,150.55,-0.116
38.12,150.48,-0.114
38.12,150.41,-0.114
38.13,150.34,-0.113
38.14,150.28,-0.112
38.14,150.21,-0.112
38.15,150.14,-0.112
38.16,150.07,-0.111
38.16,150.00,-0.110
38.17,149.93,-0.110
38.18,149.87,-0.110
38.18,149.80,-0.110
38.19,149.73,-0.109
38.20,149.66,-0.109
38.20,149.60,-0.109
38.21,149.53,-0.108
38.22,149.46,-0.108
38.22,149.39,-0.108
38.23,149.33,-0.108
38.24,149.26,-0.107
38.24,149.19,-0.107
38.25,149.13,-0.107
38.26,149.06,-0.107
38.26,148.99,-0.106
38.27,148.92,-0.106
38.28,148.86,-0.106
38.28,148.79,-0.106
38.29,148.72,-0.106
38.30,148.66,-0.106
38.30,148.59,-0.106
38.31,148.52,-0.106
38.32,148.46,-0.106
38.32,148.39,-0.106
38.33,148.32,-0.106
38.34,148.26,-0.106
38.34,148.19,-0.106
38.35,148.12,-0.106
38.36,148.06,-0.105
38.36,147.99,-0.105
38.37,147.92,-0.105
38.38,147.86,-0.105
38.38,147.79,-0.105
38.39,147.72,-0.105
38.40,147.66,-0.105
38.40,147.59,-0.105
38.41,147.52,-0.105
38.42,147.45,-0.105
38.42,147.39,-0.105
38.43,147.32,-0.105
38.44,147.26,-0.105
38.44,147.19,-0.105
38.45,147.12,-0.105
38.46,147.05,-0.105
38.46,146.99,-0.105
38.47,146.92,-0.105
38.48,146.85,-0.105
38.48,146.79,-0.105
38.49,146.72,-0.105
38.50,146.66,-0.105
38.50,146.59,-0.105
38.51,146.52,-0.105
38.52,146.45,-0.105
38.52,146.39,-0.105
38.53,146.32,-0.105
38.54,146.26,-0.105
38.54,146.19,-0.105
38.55,146.12,-0.105
38.56,146.06,-0.105
38.56,145.99,-0.105
38.57,145.92,-0.105
38.58,145.86,-0.105
38.58,145.79,-0.105
38.59,145.72,-0.105
38.60,145.66,-0.104
38.60,145.59,-0.104
38.61,145.52,-0.104
38.62,145.46,-0.104
38.62,145.39,-0.104
38.63,145.32,-0.104
38.64,145.26,-0.104
38.64,145.19,-0.104
38.65,145.12,-0.104
38.66,145.06,-0.104
38.66,144.99,-0.104
38.67,144.92,-0.104
38.68,144.86,-0.104
38.68,144.79,-0.104
38.69,144.72,-0.104
38.70,144.66,-0.104
38.70,144.59,-0.104
38.71,144.52,-0.104
38.72,144.46,-0.104
38.72,144.39,-0.104
38.73,144.32,-0.104
38.74,144.26,-0.104
38.74,144.19,-0.104
38.75,144.12,-0.104
38.76,144.06,-0.104
38.76,143.99,-0.104
38.77,143.92,-0.104
38.78,143.86,-0.104
38.78,143.79,-0.104
38.79,143.73,-0.104
38.80,143.66,-0.104
38.80,143.59,-0.104
38.81,143.53,-0.104
38.82,143.46,-0.104
38.82,143.39,-0.104
38.83,143.32,-0.104
38.84,143.26,-0.104
38.84,143.19,-0.104
38.85,143.13,-0.104
38.86,143.06,-0.104
38.86,142.99,-0.104
38.87,142.93,-0.104
38.88,142.86,-0.104
38.88,142.79,-0.104
38.89,142.73,-0.104
38.90,142.66,-0.104
38.90,142.59,-0.104
38.91,142.53,-0.104
38.92,142.46,-0.104
38.92,142.39,-0.104
38.93,142.33,-0.104
38.94,142.26,-0.104
38.94,142.19,-0.104
38.95,142.13,-0.104
38.96,142.06,-0.104
38.96,141.99,-0.104
38.97,141.93,-0.104
38.98,141.86,-0.104
38.98,141.79,-0.104
38.99,141.73,-0.104
39.00,141.66,-0.104
39.00,141.59,-0.104
39.01,141.53,-0.104
39.02,141.46,-0.104
39.02,141.39,-0.104
39.03,141.33,-0.104
39.04,141.26,-0.104
39.04,141.19,-0.104
39.05,141.13,-0.104
39.06,141.06,-0.104
39.06,140.99,-0.104
39.07,140.93,-0.104
39.08,140.86,-0.104
39.08,140.80,-0.104
39.09,140.73,-0.104
39.10,140.66,-0.103
39.10,140.60,-0.103
39.11,140.53,-0.104
39.12,140.46,-0.103
39.12,140.40,-0.103
39.13,140.33,-0.104
39.14,140.26,-0.104
39.14,140.20,-0.103
39.15,140.13,-0.103
39.16,140.06,-0.103
39.16,140.00,-0.103
39.17,139.93,-0.103
39.18,139.86,-0.103
39.18,139.80,-0.103
39.19,139.73,-0.103
39.20,139.66,-0.103
39.20,139.60,-0.103
39.21,139.53,-0.103
39.22,139.46,-0.103
39.22,139.40,-0.103
39.23,139.33,-0.103
39.24,139.26,-0.103
39.24,139.20,-0.103
39.25,139.13,-0.103
39.26,139.06,-0.103
39.26,139.00,-0.103
39.27,138.93,-0.103
39.28,138.86,-0.103
39.28,138.80,-0.103
39.29,138.73,-0.103
39.30,138.66,-0.103
39.30,138.60,-0.103
39.31,138.53,-0.103
39.32,138.46,-0.103
39.32,138.40,-0.103
39.33,138.33,-0.103
39.34,138.26,-0.103
39.34,138.20,-0.103
39.35,138.13,-0.103
39.36,138.06,-0.103
39.36,138.00,-0.103
39.37,137.93,-0.103
39.38,137.86,-0.103
39.38,137.80,-0.103
39.39,137.73,-0.103
39.40,137.66,-0.103
39.40,137.60,-0.103
39.41,137.53,-0.103
39.42,137.47,-0.103
39.42,137.40,-0.103
39.43,137.33,-0.103
39.44,137.26,-0.103
39.44,137.20,-0.103
39.45,137.13,-0.103
39.46,137.06,-0.103
39.46,137.00,-0.103
39.47,136.93,-0.103
39.48,136.87,-0.103
39.48,136.80,-0.103
39.49,136.73,-0.103
39.50,136.66,-0.103
39.50,136.60,-0.103
39.51,136.53,-0.103
39.52,136.46,-0.103
39.52,136.40,-0.103
39.53,136.33,-0.103
39.54,136.26,-0.103
39.54,136.20,-0.103
39.55,136.13,-0.103
39.56,136.07,-0.103
39.56,136.00,-0.103
39.57,135.93,-0.103
39.58,135.86,-0.103
39.58,135.80,-0.103
39.59,135.73,-0.103
39.60,135.67,-0.103
39.60,135.60,-0.103
39.61,135.53,-0.103
39.62,135.46,-0.103
39.62,135.40,-0.103
39.63,135.33,-0.103
39.64,135.26,-0.103
39.64,135.20,-0.103
39.65,135.13,-0.103
39.66,135.07,-0.103
39.66,135.00,-0.103
39.67,134.93,-0.103
39.68,134.87,-0.103
39.68,134.80,-0.103
39.69,134.73,-0.103
39.70,134.67,-0.103
39.70,134.60,-0.103
39.71,134.53,-0.103
39.72,134.47,-0.103
39.72,134.40,-0.103
39.73,134.33,-0.103
39.74,134.27,-0.103
39.74,134.20,-0.103
39.75,134.13,-0.103
39.76,134.07,-0.103
39.76,134.00,-0.103
39.77,133.93,-0.103
39.78,133.87,-0.103
39.78,133.80,-0.103
39.79,133.73,-0.103
39.80,133.67,-0.103
39.80,133.60,-0.103
39.81,133.53,-0.103
39.82,133.47,-0.103
39.82,133.40,-0.103
39.83,133.33,-0.103
39.84,133.27,-0.103
39.84,133.20,-0.103
39.85,133.13,-0.103
39.86,133.07,-0.103
39.86,133.00,-0.103
39.87,132.93,-0.103
39.88,132.87,-0.103
39.88,132.80,-0.103
39.89,132.73,-0.103
39.90,132.67,-0.103
39.90,132.60,-0.103
39.91,132.54,-0.103
39.92,132.47,-0.103
39.92,132.40,-0.103
39.93,132.34,-0.103
39.94,132.27,-0.103
39.94,132.20,-0.103
39.95,132.14,-0.103
39.96,132.07,-0.103
39.96,132.00,-0.103
39.97,131.94,-0.103
39.98,131.87,-0.103
39.98,131.80,-0.103
39.99,131.74,-0.103
40.00,131.67,-0.103
40.00,131.60,-0.103
40.01,131.54,-0.103
40.02,131.47,-0.103
40.02,131.40,-0.103
40.03,131.34,-0.103
40.04,131.27,-0.103
40.04,131.20,-0.103
40.05,131.14,-0.103
40.06,131.07,-0.103
40.06,131.00,-0.103
40.07,130.94,-0.103
40.08,130.87,-0.103
40.08,130.80,-0.103
40.09,130.74,-0.103
40.10,130.67,-0.103
40.10,130.60,-0.103
40.11,130.54,-0.103
40.12,130.47,-0.103
40.12,130.40,-0.103
40.13,130.34,-0.103
40.14,130.27,-0.103
40.14,130.20,-0.103
40.15,130.14,-0.103
40.16,130.07,-0.103
40.16,130.00,-0.103
40.17,129.94,-0.103
40.18,129.87,-0.103
40.18,129.80,-0.103
40.19,129.74,-0.103
40.20,129.67,-0.103
40.20,129.61,-0.103
40.21,129.54,-0.103
40.22,129.47,-0.103
40.22,129.41,-0.103
40.23,129.34,-0.102
40.24,129.27,-0.103
40.24,129.21,-0.102
40.25,129.14,-0.102
40.26,129.07,-0.102
40.26,129.01,-0.102
40.27,128.94,-0.102
40.28,128.87,-0.102
40.28,128.81,-0.102
40.29,128.74,-0.102
40.30,128.67,-0.102
40.30,128.61,-0.102
40.31,128.54,-0.102
40.32,128.47,-0.102
40.32,128.41,-0.102
40.33,128.34,-0.102
40.34,128.27,-0.102
40.34,128.21,-0.102
40.35,128.14,-0.102
40.36,128.07,-0.102
40.36,128.01,-0.102
40.37,127.94,-0.102
40.38,127.87,-0.102
40.38,127.81,-0.102
40.39,127.74,-0.102
40.40,127.67,-0.102
40.40,127.61,-0.102
40.41,127.54,-0.102
40.42,127.47,-0.102
40.42,127.41,-0.102
40.43,127.34,-0.102
40.44,127.27,-0.102
40.44,127.21,-0.102
40.45,127.14,-0.102
40.46,127.07,-0.102
40.46,127.01,-0.102
40.47,126.94,-0.102
40.48,126.88,-0.102
40.48,126.81,-0.102
40.49,126.74,-0.102
40.50,126.67,-0.102
40.50,126.61,-0.102
40.51,126.54,-0.102
40.52,126.48,-0.102
40.52,126.41,-0.102
40.53,126.34,-0.102
40.54,126.27,-0.102
40.54,126.21,-0.102
40.55,126.14,-0.102
40.56,126.07,-0.102
40.56,126.01,-0.102
40.57,125.94,-0.102
40.58,125.87,-0.102
40.58,125.81,-0.102
40.59,125.74,-0.102
40.60,125.67,-0.102
40.60,125.61,-0.102
40.61,125.54,-0.102
40.62,125.48,-0.102
40.62,125.41,-0.102
40.63,125.34,-0.102
40.64,125.28,-0.102
40.64,125.21,-0.102
40.65,125.14,-0.102
40.66,125.07,-0.102
40.66,125.01,-0.102
40.67,124.94,-0.102
40.68,124.88,-0.102
40.68,124.81,-0.102
40.69,124.74,-0.102
40.70,124.68,-0.102
40.70,124.61,-0.102
40.71,124.54,-0.102
40.72,124.47,-0.102
40.72,124.41,-0.102
40.73,124.34,-0.102
40.74,124.28,-0.102
40.74,124.21,-0.102
40.75,124.14,-0.102
40.76,124.08,-0.102
40.76,124.01,-0.102
40.77,123.94,-0.102
40.78,123.87,-0.102
40.78,123.81,-0.102
40.79,123.74,-0.102
40.80,123.68,-0.102
40.80,123.61,-0.102
40.81,123.54,-0.102
40.82,123.48,-0.102
40.82,123.41,-0.102
40.83,123.34,-0.102
40.84,123.28,-0.102
40.84,123.21,-0.102
40.85,123.14,-0.102
40.86,123.08,-0.102
40.86,123.01,-0.102
40.87,122.94,-0.102
40.88,122.88,-0.102
40.88,122.81,-0.102
40.89,122.74,-0.102
40.90,122.68,-0.102
40.90,122.61,-0.102
40.91,122.54,-0.102
40.92,122.48,-0.102
40.92,122.41,-0.102
40.93,122.34,-0.102
40.94,122.28,-0.102
40.94,122.21,-0.102
40.95,122.14,-0.102
40.96,122.08,-0.102
40.96,122.01,-0.102
40.97,121.94,-0.102
40.98,121.88,-0.102
40.98,121.81,-0.102
40.99,121.74,-0.102
41.00,121.68,-0.102
41.00,121.61,-0.102
41.01,121.54,-0.102
41.02,121.48,-0.102
41.02,121.41,-0.102
41.03,121.34,-0.102
41.04,121.28,-0.102
41.04,121.21,-0.102
41.05,121.15,-0.102
41.06,121.08,-0.102
41.06,121.01,-0.102
41.07,120.95,-0.102
41.08,120.88,-0.102
41.08,120.81,-0.102
41.09,120.75,-0.102
41.10,120.68,-0.102
41.10,120.61,-0.102
41.11,120.55,-0.102
41.12,120.48,-0.102
41.12,120.41,-0.102
41.13,120.35,-0.102
41.14,120.28,-0.102
41.14,120.21,-0.102
41.15,120.15,-0.102
41.16,120.08,-0.102
41.16,120.01,-0.102
41.17,119.95,-0.102
41.18,119.88,-0.102
41.18,119.81,-0.102
41.19,119.75,-0.102
41.20,119.68,-0.102
41.20,119.61,-0.102
41.21,119.55,-0.102
41.22,119.48,-0.102
41.22,119.41,-0.102
41.23,119.35,-0.102
41.24,119.28,-0.102
41.24,119.21,-0.102
41.25,119.15,-0.101
41.26,119.08,-0.101
41.26,119.01,-0.102
41.27,118.95,-0.102
41.28,118.88,-0.102
41.28,118.81,-0.102
41.29,118.75,-0.102
41.30,118.68,-0.102
41.30,118.61,-0.101
41.31,118.55,-0.102
41.32,118.48,-0.101
41.32,118.41,-0.101
41.33,118.35,-0.101
41.34,118.28,-0.101
41.34,118.22,-0.101
41.35,118.15,-0.101
41.36,118.08,-0.101
41.36,118.01,-0.101
41.37,117.95,-0.101
41.38,117.88,-0.101
41.38,117.81,-0.101
41.39,117.75,-0.101
41.40,117.68,-0.101
41.40,117.62,-0.101
41.41,117.55,-0.101
41.42,117.48,-0.101
41.42,117.42,-0.101
41.43,117.35,-0.101
41.44,117.28,-0.101
41.44,117.22,-0.101
41.45,117.15,-0.101
41.46,117.08,-0.101
41.46,117.02,-0.101
41.47,116.95,-0.101
41.48,116.88,-0.101
41.48,116.82,-0.101
41.49,116.75,-0.101
41.50,116.68,-0.101
41.50,116.62,-0.101
41.51,116.55,-0.101
41.52,116.48,-0.101
41.52,116.42,-0.101
41.53,116.35,-0.101
41.54,116.28,-0.101
41.54,116.22,-0.101
41.55,116.15,-0.101
41.56,116.08,-0.101
41.56,116.02,-0.101
41.57,115.95,-0.101
41.58,115.88,-0.101
41.58,115.82,-0.101
41.59,115.75,-0.101
41.60,115.68,-0.101
41.60,115.62,-0.101
41.61,115.55,-0.101
41.62,115.48,-0.101
41.62,115.42,-0.101
41.63,115.35,-0.101
41.64,115.28,-0.101
41.64,115.22,-0.101
41.65,115.15,-0.101
41.66,115.08,-0.101
41.66,115.02,-0.101
41.67,114.95,-0.101
41.68,114.88,-0.101
41.68,114.82,-0.101
41.69,114.75,-0.101
41.70,114.68,-0.101
41.70,114.62,-0.101
41.71,114.55,-0.101
41.72,114.48,-0.101
41.72,114.42,-0.101
41.73,114.35,-0.101
41.74,114.28,-0.101
41.74,114.22,-0.101
41.75,114.15,-0.101
41.76,114.09,-0.101
41.76,114.02,-0.101
41.77,113.95,-0.101
41.78,113.88,-0.101
41.78,113.82,-0.101
41.79,113.75,-0.101
41.80,113.69,-0.101
41.80,113.62,-0.101
41.81,113.55,-0.101
41.82,113.49,-0.101
41.82,113.42,-0.101
41.83,113.35,-0.101
41.84,113.29,-0.101
41.84,113.22,-0.101
41.85,113.15,-0.101
41.86,113.09,-0.101
41.86,113.02,-0.101
41.87,112.95,-0.101
41.88,112.89,-0.101
41.88,112.82,-0.101
41.89,112.75,-0.101
41.90,112.69,-0.101
41.90,112.62,-0.101
41.91,112.55,-0.101
41.92,112.49,-0.101
41.92,112.42,-0.101
41.93,112.35,-0.101
41.94,112.29,-0.101
41.94,112.22,-0.101
41.95,112.15,-0.101
41.96,112.09,-0.101
41.96,112.02,-0.101
41.97,111.95,-0.101
41.98,111.89,-0.101
41.98,111.82,-0.101
41.99,111.75,-0.101
42.00,111.69,-0.101
42.00,111.62,-0.101
42.01,111.56,-0.101
42.02,111.49,-0.101
42.02,111.42,-0.101
42.03,111.36,-0.101
42.04,111.29,-0.101
42.04,111.22,-0.101
42.05,111.16,-0.101
42.06,111.09,-0.101
42.06,111.02,-0.101
42.07,110.96,-0.101
42.08,110.89,-0.101
42.08,110.82,-0.101
42.09,110.76,-0.101
42.10,110.69,-0.101
42.10,110.62,-0.101
42.11,110.56,-0.101
42.12,110.49,-0.101
42.12,110.42,-0.101
42.13,110.36,-0.101
42.14,110.29,-0.101
42.14,110.22,-0.101
42.15,110.16,-0.101
42.16,110.09,-0.101
42.16,110.02,-0.101
42.17,109.96,-0.101
42.18,109.89,-0.101
42.18,109.82,-0.101
42.19,109.76,-0.101
42.20,109.69,-0.101
42.20,109.62,-0.101
42.21,109.56,-0.101
42.22,109.49,-0.101
42.22,109.42,-0.101
42.23,109.36,-0.101
42.24,109.29,-0.101
42.24,109.22,-0.101
42.25,109.16,-0.101
42.26,109.09,-0.101
42.26,109.02,-0.101
42.27,108.96,-0.100
42.28,108.89,-0.100
42.28,108.82,-0.100
42.29,108.76,-0.100
42.30,108.69,-0.100
42.30,108.62,-0.100
42.31,108.56,-0.100
42.32,108.49,-0.100
42.32,108.43,-0.100
42.33,108.36,-0.100
42.34,108.29,-0.100
42.34,108.23,-0.100
42.35,108.16,-0.100
42.36,108.09,-0.100
42.36,108.03,-0.100
42.37,107.96,-0.100
42.38,107.89,-0.100
42.38,107.83,-0.100
42.39,107.76,-0.100
42.40,107.69,-0.100
42.40,107.62,-0.100
42.41,107.56,-0.100
42.42,107.49,-0.100
42.42,107.43,-0.100
42.43,107.36,-0.100
42.44,107.29,-0.100
42.44,107.23,-0.100
42.45,107.16,-0.100
42.46,107.09,-0.100
42.46,107.03,-0.100
42.47,106.96,-0.100
42.48,106.89,-0.100
42.48,106.83,-0.100
42.49,106.76,-0.100
42.50,106.69,-0.100
42.50,106.63,-0.100
42.51,106.56,-0.100
42.52,106.49,-0.100
42.52,106.43,-0.100
42.53,106.36,-0.100
42.54,106.29,-0.100
42.54,106.23,-0.100
42.55,106.16,-0.100
42.56,106.09,-0.100
42.56,106.03,-0.100
42.57,105.96,-0.100
42.58,105.89,-0.100
42.58,105.83,-0.100
42.59,105.76,-0.100
42.60,105.69,-0.100
42.60,105.63,-0.100
42.61,105.56,-0.100
42.62,105.50,-0.100
42.62,105.43,-0.100
42.63,105.36,-0.100
42.64,105.30,-0.100
42.64,105.23,-0.100
42.65,105.16,-0.100
42.66,105.10,-0.100
42.66,105.03,-0.100
42.67,104.96,-0.100
42.68,104.90,-0.100
42.68,104.83,-0.100
42.69,104.76,-0.100
42.70,104.70,-0.100
42.70,104.63,-0.100
42.71,104.56,-0.100
42.72,104.50,-0.100
42.72,104.43,-0.100
42.73,104.36,-0.100
42.74,104.30,-0.100
42.74,104.23,-0.100
42.75,104.16,-0.100
42.76,104.10,-0.100
42.76,104.03,-0.100
42.77,103.96,-0.100
42.78,103.90,-0.100
42.78,103.83,-0.100
42.79,103.76,-0.100
42.80,103.70,-0.100
42.80,103.63,-0.100
42.81,103.56,-0.100
42.82,103.50,-0.100
42.82,103.43,-0.100
42.83,103.36,-0.100
42.84,103.30,-0.100
42.84,103.23,-0.100
42.85,103.16,-0.100
42.86,103.10,-0.100
42.86,103.03,-0.100
42.87,102.96,-0.100
42.88,102.90,-0.100
42.88,102.83,-0.100
42.89,102.76,-0.100
42.90,102.70,-0.100
42.90,102.63,-0.100
42.91,102.56,-0.100
42.92,102.50,-0.100
42.92,102.43,-0.100
42.93,102.36,-0.100
42.94,102.30,-0.100
42.94,102.23,
42.95,102.16,
42.96,102.10,
42.96,102.03,
42.97,101.96,
42.98,101.90,
42.98,101.83,
42.99,,
42.99,,