File: Data/2025_09_11_Naphthalene_CHM343_DSC.csv
Filename,2025_09_11_Naphthalene_CHM343_DSC
Instrument name,DSC2A-00468 (192.168.1.100)
Operator,Zoom ASU Sync
rundate,9/11/2025
Sample name,2025_09_11_Naphthalene_CHM343_DSC
proceduresegments,Data Off ; Equilibrate 30.00 °C; Data On ; Ramp 10.00 °C/min to 100.00 °C; Data Off ; Isothermal 1.0 min; Data On ; Ramp 10.00 °C/min to 30.00 °C; Data Off ; Isothermal 1.0 min; Data On ; Ramp 10.00 °C/min to 100.00 °C; Data Off ; Isothermal 1.0 min; Data On ; Ramp 10.00 °C/min to 30.00 °C
[File Parameters]
Run date,9/11/2025 12:17:41 PM
Trios version,5.1.1.46572
Original File Name,
Current File Name,D:\DSC2500\CHM343\2025_09_11_Naphthalene_CHM343_DSC.tri
[Procedure]
Procedure Name,Naphthalene_30C_100C_10Cmin
Sample Name,2025_09_11_Naphthalene_CHM343_DSC
Sample Mass,5.45 mg
Reference Sample Mass,0 mg
Pan Mass,56.38 mg
Pan Number,8
Reference Pan Mass,56.19 mg
Reference Pan Number,1
Pan Type,Tzero Aluminum Hermetic
Comments,DSC_Samples_Y1_Tray_CHM343_Sept2025 Google Sheet.
Project Name,CHM343
Operator,Zoom ASU Sync
Test,Custom
Unload Max Temperature,30
Unload Min Temperature,30
Load Max Temperature,30
Load Min Temperature,30
Stop on Gas Flow Error,Yes
[Signal List]
Signal #1,Time (min)
Signal #2,Temperature (°C)
Signal #3,Heat Flow (mW)
Signal #4,Delta T (µV)
Signal #5,Delta Tzero (µV)
Signal #6,Tzero Temperature (°C)
Signal #7,Cell Purge (mL/min)
Signal #8,Heater Temp (°C)
Signal #9,Power Delivered (W)
Signal #10,Reference Junction Temperature (°C)
Signal #11,Flange Temperature (°C)
Signal #12,Heat Flow Phase (rad)
Signal #13,Total Heat Capacity (J/°C)
Signal #14,Heat Capacity (J/°C)
[Configuration]
Company Name,ASU
Instrument Name,DSC2A-00468
Instrument Type,DSC2500
Serial Number,DSC2A-00468
IP,192.168.1.100
Location of Instrument,MRRC
DisplayType,Unknown
Sample Interval ,0.1 s/pt
Selected Heat Flow,T4P
Exotherm Direction,Down
Cell Serial,DRC2-00792
Lid Type,Standard
Cooler,RCS 90
Leave Cooler on at End of Sequence,On
Gas 2,Nitrogen
Gas Selected,Channel 1
Flow Rate,50 mL/min
Secondary Purge,On
Licensed Heat Flow,Heat Flow T4P
Modulation Licensed,Yes
[Versions]
Common IDD Version,1
Cortex Version,VER 2.10.2.31
Driver,5.0.0.6
GDM Version,1.0.3.3
TouchscreenVersion,1.0.0.16145
FEP Version,1.2.1.21
FEP Bootloader,2.0.0.5
AutoSampler Version,2.1.1.26
Auto Sampler Bootloader,2.0.0.5
FCM Version,1.1.0.3
FCM Bootloader,2.0.0.5
[Experiment Logs]
Experiment Log Entry # 1,Data On set to 0
Experiment Log Entry # 3,Equilibrate Segment 30 (C) Started
Experiment Log Entry # 5,Air Cool is off.
Experiment Log Entry # 7,Data On set to 1
Experiment Log Entry # 9,Ramp Segment 10 C/min to 100 Started
Experiment Log Entry # 11,Data On set to 0
Experiment Log Entry # 13,Isothermal Segment 1 min started
Experiment Log Entry # 15,Data On set to 1
Experiment Log Entry # 17,Ramp Segment 10 C/min to 30 Started
Experiment Log Entry # 19,Data On set to 0
Experiment Log Entry # 21,Isothermal Segment 1 min started
Experiment Log Entry # 23,Data On set to 1
Experiment Log Entry # 25,Ramp Segment 10 C/min to 100 Started
Experiment Log Entry # 27,Data On set to 0
Experiment Log Entry # 29,Isothermal Segment 1 min started
Experiment Log Entry # 31,Data On set to 1
Experiment Log Entry # 33,Ramp Segment 10 C/min to 30 Started
[Method Log]
Method Log Entry # 1,Data Off
Method Log Entry # 2,Equilibrate 30 °C
Method Log Entry # 3,Data On
Method Log Entry # 4,(Ramp 53066) Ramp 10 °C/minute to 100 °C
Method Log Entry # 5,Data Off
Method Log Entry # 6,Isothermal 1 minutes
Method Log Entry # 7,Data On
Method Log Entry # 8,(Ramp 53070) Ramp 10 °C/minute to 30 °C
Method Log Entry # 9,Data Off
Method Log Entry # 10,Isothermal 1 minutes
Method Log Entry # 11,Data On
Method Log Entry # 12,(Ramp 53074) Ramp 10 °C/minute to 100 °C
Method Log Entry # 13,Data Off
Method Log Entry # 14,Isothermal 1 minutes
Method Log Entry # 15,Data On
Method Log Entry # 16,(Ramp 53078) Ramp 10 °C/minute to 30 °C
Cell Serial,DRC2-00792
[T1 Calibration]
Slope,-0.008529666
Offset,9.636258
Initial Temperature,98.23
GUID,f8bfdadc-4977-4fdf-ba6d-0ba9134940c3
[TZero Calibration]
Date Applied,11/29/2022 4:06:13 PM
Description,From -89.059 °C to 396.009 °C at 20.000°C/min
Gas Type,Nitrogen
Pan Type,None
Source Files 1,C:\Users\yargerlab\Desktop\DSC Data\General\TZero_calibration_11_29_22_2nd(2).tri
Source Files 2,C:\Users\yargerlab\Desktop\DSC Data\General\TZero_calibration_11_29_22_2nd(3).tri
Delta T Offset,13.05235
Delta T Slope,-0.007271007
Delta T0 Offset,-13.69128
Delta T0 Slope,0.06063341
[Temperature Calibration]
Date Applied,11/29/2022 7:12:28 PM
Description,From 106.590 °C to 186.590 °C at 10.000°C/min
Gas Type,Nitrogen
Pan Type,Tzero Aluminum Hermetic
Source Files 1,C:\Users\yargerlab\Desktop\DSC Data\General\Indium(6).tri
Measured 1,157.391
Known 1,156.598
[Cell Constant Calibration]
Date Applied,11/29/2022 7:12:29 PM
Description,From 106.590 °C to 186.590 °C at 10.000°C/min
Gas Type,Nitrogen
Pan Type,Tzero Aluminum Hermetic
Source Files 1,C:\Users\yargerlab\Desktop\DSC Data\General\Indium(6).tri
T4P KCell,1.006051
Onset Slope,63.26126 mW/°C
[Direct Cp Calibration]
Date Applied,11/30/2022 11:04:51 AM
Description,From -79.983 °C to 298.409 °C at 10.000°C/min
Gas Type,Nitrogen
Pan Type,Tzero Aluminum Hermetic
Source Files 1,C:\Users\yargerlab\Desktop\DSC Data\General\Sapphire_Heat_Capacity_11_30_22.tri
[Rev Cp Calibration]
Date Applied,11/30/2022 1:58:51 PM
Description,From -79.996 °C to 292.812 °C at 3.000°C/min
Gas Type,Nitrogen
Pan Type,Tzero Aluminum Hermetic
Source Files 1,C:\Users\yargerlab\Desktop\DSC Data\General\Sapphire_MDSC_Calibration_11_30_22.tri
[step]
Ramp 10.00 °C/min to 100.00 °C
Time,Temperature,Heat Flow (Normalized)
min,°C,W/g
0.00,29.94,0.023
0.01,29.95,0.022
0.01,29.95,0.021
0.01,29.95,0.020
0.02,29.96,0.019
0.03,29.96,0.019
0.03,29.97,0.018
0.03,29.97,0.017
0.04,29.98,0.017
0.05,29.99,0.016
0.05,29.99,0.015
0.05,30.00,0.014
0.06,30.01,0.013
0.07,30.02,0.011
0.07,30.03,0.009
0.08,30.04,0.008
0.08,30.06,0.006
0.08,30.07,0.005
0.09,30.09,0.004
0.09,30.11,0.003
0.10,30.13,0.002
0.11,30.15,0.002
0.11,30.18,0.002
0.12,30.20,0.003
0.12,30.23,0.003
0.13,30.26,0.004
0.13,30.29,0.005
0.14,30.32,0.008
0.14,30.35,0.014
0.14,30.38,0.022
0.15,30.42,0.028
0.16,30.45,0.033
0.16,30.49,0.038
0.16,30.53,0.043
0.17,30.56,0.049
0.18,30.60,0.054
0.18,30.64,0.060
0.19,30.68,0.064
0.19,30.72,0.070
0.19,30.76,0.076
0.20,30.80,0.081
0.21,30.84,0.086
0.21,30.88,0.089
0.21,30.92,0.094
0.22,30.96,0.097
0.23,31.00,0.102
0.23,31.05,0.106
0.24,31.09,0.109
0.24,31.13,0.114
0.24,31.18,0.117
0.25,31.22,0.120
0.26,31.26,0.123
0.26,31.31,0.127
0.26,31.35,0.130
0.27,31.40,0.132
0.28,31.44,0.136
0.28,31.49,0.139
0.29,31.53,0.142
0.29,31.58,0.144
0.30,31.62,0.147
0.30,31.67,0.149
0.30,31.72,0.150
0.31,31.76,0.152
0.31,31.81,0.156
0.32,31.86,0.158
0.33,31.90,0.160
0.33,31.95,0.162
0.34,32.00,0.163
0.34,32.05,0.165
0.35,32.09,0.167
0.35,32.14,0.170
0.35,32.19,0.172
0.36,32.24,0.173
0.36,32.28,0.174
0.37,32.33,0.175
0.38,32.38,0.177
0.38,32.43,0.179
0.39,32.48,0.180
0.39,32.52,0.180
0.40,32.57,0.181
0.40,32.62,0.182
0.40,32.67,0.184
0.41,32.72,0.186
0.41,32.77,0.187
0.42,32.82,0.187
0.43,32.86,0.187
0.43,32.91,0.189
0.44,32.96,0.190
0.44,33.01,0.190
0.45,33.06,0.190
0.45,33.11,0.191
0.45,33.16,0.193
0.46,33.21,0.194
0.46,33.26,0.195
0.47,33.31,0.195
0.48,33.35,0.196
0.48,33.40,0.196
0.49,33.45,0.196
0.49,33.50,0.197
0.50,33.55,0.197
0.50,33.60,0.198
0.50,33.65,0.198
0.51,33.70,0.199
0.51,33.75,0.199
0.52,33.80,0.199
0.53,33.85,0.199
0.53,33.90,0.200
0.53,33.95,0.200
0.54,34.00,0.200
0.55,34.05,0.200
0.55,34.09,0.201
0.55,34.14,0.202
0.56,34.19,0.202
0.57,34.24,0.202
0.57,34.29,0.203
0.58,34.34,0.203
0.58,34.39,0.203
0.58,34.44,0.203
0.59,34.49,0.203
0.60,34.54,0.204
0.60,34.59,0.204
0.60,34.64,0.204
0.61,34.69,0.204
0.62,34.74,0.204
0.62,34.79,0.204
0.63,34.84,0.204
0.63,34.89,0.205
0.63,34.94,0.205
0.64,34.99,0.205
0.65,35.04,0.205
0.65,35.09,0.205
0.65,35.14,0.205
0.66,35.19,0.206
0.67,35.24,0.206
0.67,35.29,0.206
0.68,35.34,0.206
0.68,35.39,0.206
0.68,35.44,0.206
0.69,35.49,0.206
0.70,35.54,0.206
0.70,35.58,0.207
0.70,35.63,0.207
0.71,35.68,0.207
0.72,35.74,0.207
0.72,35.79,0.207
0.73,35.83,0.207
0.73,35.88,0.207
0.73,35.93,0.207
0.74,35.98,0.207
0.75,36.03,0.207
0.75,36.08,0.207
0.75,36.13,0.207
0.76,36.18,0.207
0.77,36.23,0.208
0.77,36.28,0.208
0.78,36.33,0.208
0.78,36.38,0.208
0.78,36.43,0.208
0.79,36.48,0.208
0.80,36.53,0.208
0.80,36.58,0.208
0.80,36.63,0.208
0.81,36.68,0.208
0.82,36.73,0.208
0.82,36.78,0.208
0.83,36.83,0.209
0.83,36.88,0.209
0.83,36.93,0.209
0.84,36.98,0.209
0.85,37.03,0.209
0.85,37.08,0.209
0.85,37.13,0.209
0.86,37.18,0.209
0.87,37.23,0.209
0.87,37.28,0.209
0.88,37.33,0.209
0.88,37.38,0.209
0.88,37.43,0.210
0.89,37.48,0.210
0.90,37.53,0.210
0.90,37.58,0.210
0.90,37.63,0.210
0.91,37.68,0.210
0.92,37.73,0.210
0.92,37.78,0.210
0.93,37.83,0.210
0.93,37.88,0.210
0.93,37.93,0.210
0.94,37.98,0.210
0.95,38.03,0.210
0.95,38.08,0.210
0.95,38.13,0.210
0.96,38.18,0.210
0.97,38.23,0.210
0.97,38.28,0.210
0.98,38.33,0.211
0.98,38.38,0.211
0.98,38.43,0.211
0.99,38.48,0.211
1.00,38.53,0.211
1.00,38.58,0.211
1.00,38.63,0.211
1.01,38.68,0.211
1.02,38.73,0.211
1.02,38.78,0.211
1.03,38.83,0.211
1.03,38.88,0.211
1.03,38.93,0.211
1.04,38.98,0.211
1.05,39.03,0.211
1.05,39.08,0.211
1.05,39.13,0.211
1.06,39.18,0.211
1.07,39.23,0.212
1.07,39.28,0.212
1.08,39.33,0.212
1.08,39.38,0.212
1.08,39.43,0.212
1.09,39.48,0.212
1.09,39.53,0.212
1.10,39.58,0.212
1.11,39.63,0.212
1.11,39.68,0.212
1.12,39.73,0.212
1.12,39.78,0.212
1.13,39.83,0.212
1.13,39.88,0.212
1.13,39.93,0.212
1.14,39.97,0.212
1.14,40.03,0.212
1.15,40.07,0.212
1.16,40.13,0.212
1.16,40.18,0.212
1.17,40.22,0.212
1.17,40.28,0.213
1.18,40.33,0.213
1.18,40.38,0.213
1.18,40.42,0.213
1.19,40.47,0.213
1.19,40.53,0.213
1.20,40.57,0.213
1.21,40.62,0.213
1.21,40.68,0.213
1.22,40.72,0.213
1.22,40.77,0.213
1.23,40.83,0.213
1.23,40.87,0.213
1.23,40.92,0.213
1.24,40.97,0.213
1.24,41.02,0.213
1.25,41.07,0.213
1.26,41.13,0.213
1.26,41.17,0.213
1.27,41.22,0.213
1.27,41.27,0.214
1.28,41.32,0.214
1.28,41.37,0.214
1.28,41.42,0.214
1.29,41.47,0.214
1.29,41.52,0.214
1.30,41.57,0.214
1.31,41.62,0.214
1.31,41.67,0.214
1.32,41.72,0.214
1.32,41.77,0.214
1.33,41.82,0.214
1.33,41.87,0.214
1.33,41.92,0.214
1.34,41.98,0.214
1.34,42.02,0.214
1.35,42.07,0.214
1.36,42.12,0.214
1.36,42.17,0.214
1.37,42.22,0.214
1.37,42.27,0.214
1.38,42.32,0.214
1.38,42.37,0.214
1.38,42.42,0.215
1.39,42.47,0.215
1.39,42.52,0.215
1.40,42.57,0.215
1.41,42.62,0.215
1.41,42.67,0.215
1.42,42.72,0.215
1.42,42.77,0.215
1.43,42.82,0.215
1.43,42.87,0.215
1.43,42.92,0.215
1.44,42.97,0.215
1.44,43.02,0.215
1.45,43.07,0.215
1.46,43.12,0.215
1.46,43.17,0.215
1.47,43.22,0.215
1.47,43.27,0.215
1.48,43.32,0.215
1.48,43.38,0.215
1.48,43.42,0.215
1.49,43.47,0.215
1.49,43.52,0.215
1.50,43.57,0.215
1.51,43.62,0.216
1.51,43.67,0.216
1.52,43.72,0.216
1.52,43.77,0.216
1.53,43.82,0.216
1.53,43.87,0.216
1.53,43.92,0.216
1.54,43.97,0.216
1.54,44.02,0.216
1.55,44.07,0.216
1.56,44.12,0.216
1.56,44.17,0.216
1.57,44.22,0.216
1.57,44.27,0.216
1.58,44.32,0.216
1.58,44.37,0.216
1.58,44.42,0.216
1.59,44.47,0.216
1.59,44.52,0.216
1.60,44.57,0.216
1.61,44.62,0.216
1.61,44.67,0.216
1.62,44.72,0.216
1.62,44.77,0.216
1.63,44.82,0.216
1.63,44.87,0.217
1.63,44.92,0.217
1.64,44.97,0.217
1.64,45.02,0.217
1.65,45.07,0.217
1.66,45.12,0.217
1.66,45.17,0.217
1.67,45.22,0.217
1.67,45.27,0.217
1.68,45.32,0.217
1.68,45.37,0.217
1.68,45.42,0.217
1.69,45.47,0.217
1.69,45.52,0.217
1.70,45.57,0.217
1.71,45.62,0.217
1.71,45.67,0.217
1.72,45.72,0.217
1.72,45.77,0.217
1.73,45.82,0.217
1.73,45.87,0.217
1.73,45.92,0.217
1.74,45.97,0.217
1.74,46.02,0.218
1.75,46.07,0.218
1.76,46.12,0.218
1.76,46.17,0.218
1.77,46.22,0.218
1.77,46.27,0.218
1.78,46.32,0.218
1.78,46.37,0.218
1.78,46.42,0.218
1.79,46.47,0.218
1.79,46.52,0.218
1.80,46.57,0.218
1.81,46.62,0.218
1.81,46.67,0.218
1.82,46.72,0.218
1.82,46.77,0.218
1.83,46.82,0.218
1.83,46.87,0.218
1.83,46.92,0.218
1.84,46.97,0.218
1.84,47.02,0.218
1.85,47.07,0.218
1.86,47.12,0.218
1.86,47.17,0.219
1.87,47.22,0.219
1.87,47.27,0.219
1.88,47.32,0.219
1.88,47.37,0.219
1.88,47.42,0.219
1.89,47.47,0.219
1.89,47.52,0.219
1.90,47.57,0.219
1.91,47.62,0.219
1.91,47.67,0.219
1.92,47.72,0.219
1.92,47.77,0.219
1.93,47.82,0.219
1.93,47.87,0.219
1.93,47.92,0.219
1.94,47.98,0.219
1.94,48.02,0.219
1.95,48.07,0.219
1.96,48.12,0.219
1.96,48.17,0.219
1.97,48.22,0.219
1.97,48.27,0.220
1.98,48.32,0.220
1.98,48.37,0.220
1.98,48.42,0.220
1.99,48.47,0.220
1.99,48.52,0.220
2.00,48.57,0.220
2.01,48.63,0.220
2.01,48.68,0.220
2.02,48.73,0.220
2.02,48.77,0.220
2.03,48.82,0.220
2.03,48.87,0.220
2.03,48.92,0.220
2.04,48.97,0.220
2.04,49.02,0.220
2.05,49.08,0.220
2.06,49.13,0.220
2.06,49.18,0.220
2.07,49.22,0.220
2.07,49.28,0.220
2.08,49.33,0.220
2.08,49.38,0.221
2.08,49.43,0.221
2.09,49.47,0.221
2.09,49.52,0.221
2.10,49.58,0.221
2.11,49.63,0.221
2.11,49.68,0.221
2.12,49.72,0.221
2.12,49.77,0.221
2.13,49.83,0.221
2.13,49.88,0.221
2.14,49.93,0.221
2.14,49.97,0.221
2.14,50.02,0.221
2.15,50.07,0.221
2.16,50.13,0.221
2.16,50.18,0.221
2.16,50.23,0.221
2.17,50.27,0.221
2.18,50.33,0.221
2.18,50.38,0.221
2.19,50.43,0.221
2.19,50.48,0.221
2.19,50.52,0.221
2.20,50.58,0.221
2.21,50.63,0.221
2.21,50.68,0.221
2.21,50.73,0.222
2.22,50.77,0.222
2.23,50.83,0.222
2.23,50.88,0.222
2.24,50.93,0.222
2.24,50.98,0.222
2.24,51.02,0.222
2.25,51.08,0.222
2.26,51.13,0.222
2.26,51.18,0.222
2.26,51.23,0.222
2.27,51.27,0.222
2.28,51.33,0.222
2.28,51.38,0.222
2.29,51.42,0.222
2.29,51.48,0.222
2.29,51.52,0.222
2.30,51.57,0.222
2.31,51.63,0.222
2.31,51.68,0.222
2.31,51.72,0.222
2.32,51.78,0.222
2.33,51.83,0.222
2.33,51.88,0.223
2.34,51.93,0.223
2.34,51.97,0.223
2.34,52.03,0.223
2.35,52.07,0.223
2.36,52.12,0.223
2.36,52.17,0.223
2.36,52.22,0.223
2.37,52.27,0.223
2.38,52.32,0.223
2.38,52.38,0.223
2.39,52.42,0.223
2.39,52.48,0.223
2.39,52.52,0.223
2.40,52.57,0.223
2.41,52.63,0.223
2.41,52.68,0.223
2.41,52.72,0.223
2.42,52.78,0.223
2.43,52.83,0.223
2.43,52.88,0.223
2.44,52.93,0.223
2.44,52.98,0.223
2.44,53.03,0.224
2.45,53.08,0.224
2.46,53.13,0.224
2.46,53.18,0.224
2.46,53.23,0.224
2.47,53.28,0.224
2.48,53.33,0.224
2.48,53.38,0.224
2.49,53.43,0.224
2.49,53.48,0.224
2.49,53.53,0.224
2.50,53.58,0.224
2.51,53.63,0.224
2.51,53.68,0.224
2.51,53.73,0.224
2.52,53.78,0.224
2.53,53.83,0.224
2.53,53.88,0.224
2.54,53.93,0.224
2.54,53.98,0.224
2.54,54.03,0.224
2.55,54.08,0.224
2.56,54.13,0.224
2.56,54.18,0.225
2.56,54.23,0.225
2.57,54.28,0.225
2.58,54.33,0.225
2.58,54.38,0.225
2.59,54.43,0.225
2.59,54.48,0.225
2.59,54.53,0.225
2.60,54.58,0.225
2.61,54.63,0.225
2.61,54.68,0.225
2.61,54.73,0.225
2.62,54.78,0.225
2.63,54.83,0.225
2.63,54.88,0.225
2.64,54.93,0.225
2.64,54.98,0.225
2.64,55.03,0.225
2.65,55.08,0.225
2.66,55.13,0.225
2.66,55.18,0.225
2.66,55.23,0.225
2.67,55.28,0.225
2.68,55.33,0.226
2.68,55.38,0.226
2.69,55.43,0.226
2.69,55.48,0.226
2.69,55.53,0.226
2.70,55.58,0.226
2.71,55.63,0.226
2.71,55.68,0.226
2.71,55.73,0.226
2.72,55.78,0.226
2.73,55.83,0.226
2.73,55.88,0.226
2.74,55.93,0.226
2.74,55.98,0.226
2.74,56.03,0.226
2.75,56.08,0.226
2.76,56.13,0.226
2.76,56.18,0.226
2.76,56.23,0.226
2.77,56.28,0.226
2.78,56.33,0.226
2.78,56.38,0.226
2.79,56.43,0.227
2.79,56.48,0.227
2.79,56.53,0.227
2.80,56.58,0.227
2.81,56.63,0.227
2.81,56.68,0.227
2.81,56.73,0.227
2.82,56.78,0.227
2.83,56.83,0.227
2.83,56.88,0.227
2.84,56.93,0.227
2.84,56.98,0.227
2.84,57.03,0.227
2.85,57.08,0.227
2.86,57.13,0.227
2.86,57.18,0.227
2.86,57.23,0.227
2.87,57.28,0.227
2.88,57.33,0.227
2.88,57.38,0.227
2.89,57.43,0.227
2.89,57.48,0.227
2.89,57.53,0.227
2.90,57.58,0.228
2.91,57.63,0.228
2.91,57.68,0.228
2.91,57.73,0.228
2.92,57.78,0.228
2.93,57.83,0.228
2.93,57.88,0.228
2.94,57.93,0.228
2.94,57.98,0.228
2.94,58.03,0.228
2.95,58.08,0.228
2.96,58.13,0.228
2.96,58.18,0.228
2.96,58.23,0.228
2.97,58.28,0.228
2.98,58.33,0.228
2.98,58.38,0.228
2.99,58.43,0.228
2.99,58.48,0.228
2.99,58.53,0.229
3.00,58.58,0.229
3.01,58.63,0.229
3.01,58.68,0.229
3.01,58.73,0.229
3.02,58.78,0.229
3.03,58.83,0.229
3.03,58.88,0.229
3.04,58.93,0.229
3.04,58.98,0.229
3.04,59.03,0.229
3.05,59.08,0.229
3.06,59.13,0.229
3.06,59.18,0.229
3.06,59.23,0.229
3.07,59.28,0.229
3.08,59.33,0.229
3.08,59.38,0.229
3.09,59.43,0.229
3.09,59.48,0.229
3.09,59.53,0.229
3.10,59.58,0.229
3.11,59.63,0.229
3.11,59.68,0.229
3.11,59.73,0.229
3.12,59.78,0.230
3.13,59.83,0.230
3.13,59.88,0.230
3.14,59.93,0.230
3.14,59.98,0.230
3.14,60.03,0.230
3.15,60.08,0.230
3.16,60.13,0.230
3.16,60.18,0.230
3.16,60.23,0.230
3.17,60.28,0.230
3.18,60.33,0.230
3.18,60.38,0.230
3.19,60.43,0.230
3.19,60.48,0.230
3.19,60.53,0.230
3.20,60.59,0.230
3.21,60.63,0.230
3.21,60.68,0.230
3.21,60.73,0.230
3.22,60.79,0.230
3.23,60.83,0.230
3.23,60.89,0.230
3.24,60.93,0.230
3.24,60.98,0.231
3.24,61.03,0.231
3.25,61.08,0.231
3.26,61.13,0.231
3.26,61.18,0.231
3.26,61.23,0.231
3.27,61.29,0.231
3.28,61.34,0.231
3.28,61.39,0.231
3.29,61.43,0.231
3.29,61.48,0.231
3.29,61.53,0.231
3.30,61.58,0.231
3.31,61.63,0.231
3.31,61.68,0.231
3.31,61.74,0.231
3.32,61.78,0.231
3.33,61.83,0.231
3.33,61.89,0.231
3.34,61.93,0.231
3.34,61.99,0.231
3.34,62.03,0.231
3.35,62.08,0.231
3.36,62.13,0.231
3.36,62.18,0.231
3.36,62.24,0.231
3.37,62.29,0.232
3.38,62.34,0.232
3.38,62.39,0.232
3.39,62.44,0.232
3.39,62.48,0.232
3.39,62.53,0.232
3.40,62.58,0.232
3.41,62.64,0.232
3.41,62.69,0.232
3.41,62.74,0.232
3.42,62.79,0.232
3.43,62.83,0.232
3.43,62.89,0.232
3.44,62.93,0.232
3.44,62.99,0.232
3.44,63.04,0.232
3.45,63.09,0.232
3.46,63.13,0.232
3.46,63.19,0.232
3.46,63.24,0.232
3.47,63.28,0.232
3.48,63.34,0.232
3.48,63.39,0.232
3.49,63.44,0.233
3.49,63.49,0.233
3.49,63.54,0.233
3.50,63.59,0.233
3.51,63.64,0.233
3.51,63.69,0.233
3.51,63.74,0.233
3.52,63.79,0.233
3.53,63.84,0.233
3.53,63.89,0.233
3.54,63.94,0.233
3.54,63.99,0.233
3.54,64.04,0.233
3.55,64.09,0.233
3.56,64.14,0.233
3.56,64.19,0.233
3.56,64.24,0.233
3.57,64.29,0.233
3.58,64.34,0.233
3.58,64.39,0.233
3.59,64.44,0.233
3.59,64.49,0.234
3.59,64.54,0.234
3.60,64.59,0.234
3.61,64.64,0.234
3.61,64.69,0.234
3.61,64.74,0.234
3.62,64.79,0.234
3.63,64.84,0.234
3.63,64.89,0.234
3.64,64.94,0.234
3.64,64.99,0.234
3.64,65.04,0.234
3.65,65.09,0.234
3.66,65.14,0.234
3.66,65.19,0.234
3.66,65.24,0.234
3.67,65.29,0.234
3.68,65.34,0.234
3.68,65.39,0.234
3.69,65.44,0.234
3.69,65.49,0.234
3.69,65.54,0.234
3.70,65.59,0.235
3.71,65.64,0.235
3.71,65.69,0.235
3.71,65.74,0.235
3.72,65.79,0.235
3.73,65.84,0.235
3.73,65.89,0.235
3.74,65.94,0.235
3.74,65.99,0.235
3.74,66.04,0.235
3.75,66.09,0.235
3.76,66.14,0.235
3.76,66.19,0.235
3.76,66.24,0.235
3.77,66.29,0.235
3.78,66.34,0.235
3.78,66.39,0.235
3.79,66.44,0.235
3.79,66.49,0.235
3.79,66.54,0.236
3.80,66.59,0.236
3.81,66.64,0.236
3.81,66.69,0.236
3.81,66.74,0.236
3.82,66.79,0.236
3.83,66.84,0.236
3.83,66.89,0.236
3.84,66.94,0.236
3.84,66.99,0.236
3.84,67.04,0.236
3.85,67.09,0.236
3.86,67.14,0.236
3.86,67.19,0.236
3.86,67.24,0.236
3.87,67.29,0.236
3.88,67.34,0.236
3.88,67.39,0.236
3.89,67.44,0.236
3.89,67.49,0.236
3.89,67.54,0.237
3.90,67.59,0.237
3.91,67.64,0.237
3.91,67.69,0.237
3.91,67.74,0.237
3.92,67.79,0.237
3.93,67.84,0.237
3.93,67.89,0.237
3.94,67.94,0.237
3.94,67.99,0.237
3.94,68.04,0.237
3.95,68.09,0.237
3.96,68.14,0.237
3.96,68.19,0.237
3.96,68.24,0.237
3.97,68.29,0.237
3.98,68.34,0.237
3.98,68.39,0.237
3.99,68.44,0.238
3.99,68.49,0.238
3.99,68.54,0.238
4.00,68.59,0.238
4.01,68.64,0.238
4.01,68.69,0.238
4.01,68.74,0.238
4.02,68.79,0.238
4.03,68.84,0.238
4.03,68.89,0.238
4.04,68.94,0.238
4.04,68.99,0.238
4.04,69.04,0.238
4.05,69.09,0.238
4.06,69.14,0.238
4.06,69.19,0.238
4.06,69.24,0.238
4.07,69.29,0.238
4.08,69.34,0.238
4.08,69.39,0.238
4.09,69.44,0.239
4.09,69.49,0.239
4.09,69.54,0.239
4.10,69.59,0.239
4.11,69.64,0.239
4.11,69.69,0.239
4.11,69.74,0.239
4.12,69.79,0.239
4.13,69.84,0.239
4.13,69.89,0.239
4.14,69.94,0.239
4.14,69.99,0.239
4.14,70.04,0.239
4.15,70.09,0.239
4.16,70.14,0.239
4.16,70.19,0.239
4.16,70.24,0.239
4.17,70.29,0.239
4.18,70.34,0.240
4.18,70.39,0.240
4.19,70.44,0.240
4.19,70.49,0.240
4.19,70.54,0.240
4.20,70.59,0.240
4.21,70.64,0.240
4.21,70.69,0.240
4.21,70.74,0.240
4.22,70.79,0.240
4.23,70.84,0.240
4.23,70.89,0.240
4.24,70.94,0.240
4.24,70.99,0.240
4.24,71.04,0.240
4.25,71.09,0.240
4.26,71.14,0.240
4.26,71.19,0.241
4.26,71.24,0.241
4.27,71.29,0.241
4.28,71.34,0.241
4.28,71.39,0.241
4.29,71.44,0.241
4.29,71.49,0.241
4.30,71.54,0.241
4.30,71.59,0.241
4.30,71.64,0.241
4.31,71.69,0.241
4.31,71.74,0.241
4.32,71.79,0.241
4.33,71.84,0.241
4.33,71.89,0.241
4.34,71.94,0.241
4.34,71.99,0.241
4.35,72.04,0.242
4.35,72.09,0.242
4.35,72.14,0.242
4.36,72.19,0.242
4.36,72.24,0.242
4.37,72.29,0.242
4.38,72.34,0.242
4.38,72.39,0.242
4.39,72.44,0.242
4.39,72.49,0.242
4.40,72.54,0.242
4.40,72.59,0.242
4.40,72.64,0.242
4.41,72.70,0.242
4.41,72.74,0.242
4.42,72.79,0.242
4.43,72.85,0.242
4.43,72.89,0.243
4.44,72.95,0.243
4.44,72.99,0.243
4.45,73.05,0.243
4.45,73.10,0.243
4.45,73.15,0.243
4.46,73.20,0.243
4.46,73.25,0.243
4.47,73.30,0.243
4.48,73.34,0.243
4.48,73.40,0.243
4.49,73.44,0.243
4.49,73.49,0.243
4.50,73.55,0.243
4.50,73.59,0.243
4.50,73.64,0.244
4.51,73.70,0.244
4.51,73.75,0.244
4.52,73.80,0.244
4.53,73.85,0.244
4.53,73.90,0.244
4.54,73.95,0.244
4.54,74.00,0.244
4.55,74.05,0.244
4.55,74.10,0.244
4.55,74.15,0.244
4.56,74.20,0.244
4.56,74.25,0.244
4.57,74.30,0.244
4.58,74.35,0.244
4.58,74.40,0.244
4.59,74.45,0.244
4.59,74.50,0.244
4.60,74.55,0.245
4.60,74.60,0.245
4.60,74.65,0.245
4.61,74.70,0.245
4.61,74.75,0.245
4.62,74.80,0.245
4.63,74.85,0.245
4.63,74.90,0.245
4.64,74.95,0.245
4.64,75.00,0.245
4.65,75.05,0.245
4.65,75.10,0.245
4.65,75.15,0.245
4.66,75.20,0.245
4.66,75.25,0.246
4.67,75.30,0.246
4.68,75.35,0.246
4.68,75.40,0.246
4.69,75.45,0.246
4.69,75.50,0.246
4.70,75.55,0.246
4.70,75.60,0.246
4.70,75.65,0.246
4.71,75.70,0.246
4.71,75.75,0.246
4.72,75.80,0.246
4.73,75.85,0.246
4.73,75.90,0.247
4.74,75.95,0.247
4.74,76.00,0.247
4.75,76.05,0.247
4.75,76.10,0.247
4.75,76.15,0.247
4.76,76.20,0.247
4.76,76.25,0.247
4.77,76.30,0.247
4.78,76.35,0.247
4.78,76.40,0.247
4.79,76.45,0.247
4.79,76.50,0.247
4.80,76.55,0.248
4.80,76.60,0.248
4.80,76.65,0.248
4.81,76.70,0.248
4.81,76.75,0.248
4.82,76.80,0.248
4.83,76.85,0.248
4.83,76.90,0.248
4.84,76.95,0.248
4.84,77.00,0.248
4.85,77.05,0.248
4.85,77.10,0.248
4.85,77.15,0.249
4.86,77.20,0.249
4.86,77.25,0.249
4.87,77.30,0.249
4.88,77.35,0.249
4.88,77.40,0.249
4.89,77.45,0.249
4.89,77.50,0.250
4.90,77.55,0.250
4.90,77.60,0.250
4.90,77.65,0.250
4.91,77.70,0.251
4.91,77.75,0.251
4.92,77.80,0.252
4.93,77.85,0.254
4.93,77.90,0.255
4.94,77.95,0.256
4.94,78.00,0.260
4.95,78.05,0.264
4.95,78.10,0.268
4.95,78.15,0.272
4.96,78.20,0.277
4.96,78.24,0.282
4.97,78.29,0.287
4.98,78.34,0.295
4.98,78.39,0.304
4.99,78.44,0.313
4.99,78.49,0.324
5.00,78.54,0.336
5.00,78.59,0.349
5.00,78.63,0.364
5.01,78.68,0.378
5.01,78.73,0.395
5.02,78.78,0.412
5.03,78.82,0.430
5.03,78.87,0.452
5.04,78.91,0.476
5.04,78.96,0.502
5.05,79.00,0.529
5.05,79.05,0.563
5.05,79.09,0.600
5.06,79.14,0.638
5.06,79.18,0.676
5.07,79.22,0.717
5.08,79.26,0.764
5.08,79.30,0.814
5.09,79.34,0.868
5.09,79.38,0.931
5.10,79.42,0.994
5.10,79.45,1.061
5.10,79.49,1.136
5.11,79.52,1.221
5.11,79.55,1.311
5.12,79.58,1.401
5.13,79.61,1.493
5.13,79.64,1.591
5.14,79.67,1.697
5.14,79.69,1.815
5.15,79.72,1.948
5.15,79.74,2.092
5.15,79.76,2.247
5.16,79.77,2.399
5.16,79.79,2.546
5.17,79.80,2.682
5.18,79.81,2.810
5.18,79.82,2.926
5.19,79.84,3.034
5.19,79.85,3.133
5.20,79.86,3.216
5.20,79.87,3.293
5.20,79.89,3.374
5.21,79.90,3.480
5.21,79.92,3.606
5.22,79.93,3.729
5.23,79.94,3.836
5.23,79.95,3.940
5.24,79.96,4.052
5.24,79.98,4.169
5.25,79.99,4.280
5.25,80.00,4.374
5.25,80.01,4.455
5.26,80.02,4.531
5.26,80.04,4.610
5.27,80.05,4.702
5.28,80.07,4.815
5.28,80.08,4.948
5.29,80.09,5.089
5.29,80.10,5.210
5.30,80.11,5.298
5.30,80.12,5.373
5.30,80.14,5.460
5.31,80.15,5.577
5.31,80.16,5.705
5.32,80.17,5.813
5.33,80.18,5.895
5.33,80.20,5.978
5.34,80.21,6.078
5.34,80.22,6.175
5.35,80.24,6.253
5.35,80.25,6.330
5.35,80.27,6.423
5.36,80.28,6.540
5.36,80.29,6.653
5.37,80.31,6.734
5.38,80.32,6.795
5.38,80.34,6.875
5.39,80.35,6.961
5.39,80.37,7.036
5.40,80.39,7.093
5.40,80.41,7.140
5.40,80.43,7.170
5.41,80.45,7.198
5.41,80.47,7.202
5.42,80.50,7.173
5.43,80.53,7.115
5.43,80.57,7.040
5.44,80.61,6.938
5.44,80.65,6.824
5.45,80.70,6.694
5.45,80.75,6.530
5.45,80.81,6.353
5.46,80.88,6.244
5.46,80.94,6.211
5.47,81.00,6.210
5.48,81.06,6.202
5.48,81.12,6.158
5.49,81.18,6.084
5.49,81.25,6.014
5.50,81.31,5.928
5.50,81.38,5.754
5.50,81.45,5.508
5.51,81.53,5.274
5.51,81.62,5.104
5.52,81.70,4.962
5.53,81.79,4.805
5.53,81.88,4.630
5.54,81.97,4.469
5.54,82.06,4.305
5.55,82.16,4.131
5.55,82.25,3.943
5.55,82.35,3.753
5.56,82.45,3.576
5.56,82.55,3.428
5.57,82.65,3.288
5.58,82.75,3.151
5.58,82.85,3.027
5.59,82.95,2.913
5.59,83.05,2.796
5.60,83.15,2.660
5.60,83.25,2.490
5.60,83.35,2.276
5.61,83.46,2.049
5.61,83.56,1.857
5.62,83.67,1.716
5.63,83.78,1.611
5.63,83.88,1.525
5.64,83.98,1.452
5.64,84.08,1.386
5.65,84.17,1.326
5.65,84.27,1.270
5.65,84.36,1.220
5.66,84.45,1.172
5.66,84.54,1.127
5.67,84.62,1.083
5.68,84.71,1.043
5.68,84.79,1.006
5.69,84.87,0.968
5.69,84.95,0.933
5.70,85.03,0.901
5.70,85.10,0.871
5.70,85.18,0.841
5.71,85.25,0.812
5.71,85.32,0.784
5.72,85.39,0.758
5.73,85.46,0.733
5.73,85.53,0.711
5.74,85.60,0.691
5.74,85.67,0.669
5.75,85.74,0.643
5.75,85.80,0.624
5.75,85.87,0.612
5.76,85.93,0.599
5.76,86.00,0.578
5.77,86.06,0.559
5.78,86.12,0.545
5.78,86.18,0.532
5.79,86.24,0.519
5.79,86.30,0.506
5.80,86.36,0.495
5.80,86.42,0.483
5.80,86.48,0.472
5.81,86.54,0.461
5.81,86.60,0.451
5.82,86.66,0.442
5.83,86.71,0.434
5.83,86.77,0.426
5.84,86.83,0.417
5.84,86.88,0.410
5.85,86.94,0.403
5.85,87.00,0.397
5.85,87.05,0.390
5.86,87.11,0.383
5.86,87.16,0.377
5.87,87.22,0.372
5.88,87.27,0.367
5.88,87.33,0.362
5.89,87.38,0.357
5.89,87.43,0.352
5.90,87.49,0.348
5.90,87.54,0.343
5.90,87.59,0.339
5.91,87.65,0.336
5.91,87.70,0.332
5.92,87.75,0.329
5.93,87.81,0.327
5.93,87.86,0.324
5.94,87.91,0.320
5.94,87.96,0.317
5.95,88.01,0.314
5.95,88.07,0.313
5.95,88.12,0.310
5.96,88.17,0.309
5.96,88.22,0.306
5.97,88.27,0.303
5.98,88.33,0.301
5.98,88.38,0.300
5.99,88.43,0.298
5.99,88.48,0.296
6.00,88.53,0.296
6.00,88.58,0.294
6.00,88.63,0.292
6.01,88.69,0.291
6.01,88.74,0.291
6.02,88.79,0.289
6.03,88.84,0.287
6.03,88.89,0.287
6.04,88.94,0.286
6.04,88.99,0.284
6.05,89.04,0.284
6.05,89.09,0.284
6.05,89.14,0.284
6.06,89.19,0.282
6.06,89.25,0.281
6.07,89.30,0.280
6.08,89.35,0.280
6.08,89.40,0.279
6.09,89.45,0.279
6.09,89.50,0.278
6.10,89.55,0.278
6.10,89.60,0.278
6.10,89.65,0.278
6.11,89.70,0.277
6.11,89.75,0.276
6.12,89.80,0.275
6.13,89.85,0.274
6.13,89.90,0.274
6.14,89.95,0.274
6.14,90.00,0.274
6.15,90.05,0.274
6.15,90.10,0.274
6.15,90.15,0.274
6.16,90.20,0.273
6.16,90.25,0.273
6.17,90.30,0.273
6.18,90.35,0.273
6.18,90.40,0.273
6.19,90.45,0.273
6.19,90.50,0.272
6.20,90.56,0.272
6.20,90.61,0.272
6.20,90.66,0.272
6.21,90.71,0.272
6.21,90.76,0.272
6.22,90.81,0.272
6.23,90.86,0.272
6.23,90.91,0.272
6.24,90.96,0.272
6.24,91.01,0.271
6.25,91.06,0.271
6.25,91.11,0.271
6.25,91.16,0.271
6.26,91.21,0.271
6.26,91.26,0.271
6.27,91.31,0.271
6.28,91.36,0.271
6.28,91.41,0.271
6.29,91.46,0.271
6.29,91.51,0.271
6.30,91.56,0.271
6.30,91.61,0.271
6.30,91.66,0.270
6.31,91.71,0.270
6.31,91.76,0.270
6.32,91.81,0.270
6.33,91.86,0.270
6.33,91.91,0.270
6.34,91.96,0.270
6.34,92.01,0.270
6.35,92.06,0.270
6.35,92.11,0.270
6.35,92.16,0.270
6.36,92.21,0.270
6.36,92.26,0.270
6.37,92.31,0.270
6.38,92.36,0.270
6.38,92.41,0.270
6.39,92.46,0.270
6.39,92.51,0.270
6.40,92.56,0.270
6.40,92.61,0.270
6.40,92.66,0.269
6.41,92.71,0.269
6.41,92.76,0.269
6.42,92.81,0.269
6.43,92.86,0.269
6.43,92.91,0.269
6.44,92.96,0.269
6.44,93.01,0.269
6.45,93.06,0.269
6.45,93.11,0.269
6.45,93.16,0.269
6.46,93.21,0.269
6.46,93.26,0.269
6.47,93.31,0.269
6.48,93.36,0.269
6.48,93.41,0.269
6.49,93.46,0.269
6.49,93.51,0.269
6.50,93.56,0.269
6.50,93.61,0.269
6.50,93.66,0.269
6.51,93.71,0.269
6.51,93.76,0.269
6.52,93.81,0.269
6.53,93.86,0.269
6.53,93.91,0.269
6.54,93.96,0.269
6.54,94.01,0.269
6.55,94.06,0.269
6.55,94.11,0.269
6.55,94.16,0.269
6.56,94.21,0.269
6.56,94.26,0.269
6.57,94.31,0.269
6.58,94.36,0.269
6.58,94.41,0.269
6.59,94.46,0.269
6.59,94.51,0.269
6.60,94.56,0.269
6.60,94.61,0.269
6.60,94.66,0.269
6.61,94.71,0.269
6.61,94.76,0.269
6.62,94.81,0.269
6.63,94.86,0.268
6.63,94.91,0.268
6.64,94.96,0.268
6.64,95.01,0.268
6.65,95.06,0.268
6.65,95.11,0.268
6.65,95.16,0.268
6.66,95.21,0.268
6.66,95.26,0.268
6.67,95.31,0.268
6.68,95.36,0.268
6.68,95.41,0.268
6.69,95.46,0.268
6.69,95.51,0.268
6.70,95.56,0.268
6.70,95.61,0.268
6.70,95.66,0.268
6.71,95.71,0.268
6.71,95.76,0.268
6.72,95.82,0.268
6.73,95.87,0.268
6.73,95.92,0.268
6.74,95.97,0.268
6.74,96.01,0.268
6.75,96.06,0.268
6.75,96.12,0.268
6.75,96.17,0.268
6.76,96.22,0.268
6.76,96.26,0.268
6.77,96.31,0.268
6.78,96.37,0.268
6.78,96.42,0.268
6.79,96.47,0.268
6.79,96.52,0.268
6.80,96.57,0.268
6.80,96.62,0.268
6.80,96.67,0.268
6.81,96.72,0.268
6.81,96.77,0.268
6.82,96.82,0.268
6.83,96.87,0.268
6.83,96.92,0.268
6.84,96.97,0.269
6.84,97.02,0.269
6.85,97.07,0.269
6.85,97.12,0.269
6.85,97.17,0.269
6.86,97.22,0.269
6.86,97.27,0.269
6.87,97.32,0.269
6.88,97.37,0.269
6.88,97.42,0.269
6.89,97.47,0.269
6.89,97.52,0.269
6.90,97.57,0.269
6.90,97.62,0.269
6.90,97.67,0.269
6.91,97.72,0.269
6.91,97.77,0.269
6.92,97.82,0.269
6.93,97.87,0.269
6.93,97.92,0.269
6.94,97.97,0.269
6.94,98.02,0.269
6.95,98.07,
6.95,98.12,
6.95,98.17,
6.96,98.22,
6.96,98.27,
6.97,98.32,
6.98,98.37,
6.98,98.42,
6.99,98.47,
6.99,98.52,
7.00,,
7.00,,

[step]
Ramp 10.00 °C/min to 30.00 °C
Time,Temperature,Heat Flow (Normalized)
min,°C,W/g
8.00,100.12,-0.033
8.00,100.12,-0.033
8.01,100.12,-0.033
8.01,100.12,-0.033
8.02,100.12,-0.033
8.03,100.12,-0.033
8.03,100.12,-0.033
8.04,100.12,-0.033
8.04,100.11,-0.033
8.05,100.11,-0.034
8.05,100.11,-0.034
8.05,100.10,-0.034
8.06,100.10,-0.034
8.06,100.09,-0.034
8.07,100.08,-0.034
8.08,100.07,-0.034
8.08,100.06,-0.034
8.09,100.05,-0.035
8.09,100.04,-0.037
8.10,100.02,-0.041
8.10,100.00,-0.048
8.10,99.99,-0.054
8.11,99.96,-0.061
8.11,99.94,-0.068
8.12,99.92,-0.075
8.13,99.89,-0.083
8.13,99.87,-0.091
8.14,99.84,-0.100
8.14,99.81,-0.109
8.15,99.78,-0.118
8.15,99.75,-0.128
8.15,99.72,-0.138
8.16,99.68,-0.145
8.16,99.65,-0.154
8.17,99.61,-0.162
8.18,99.58,-0.172
8.18,99.54,-0.179
8.19,99.50,-0.186
8.19,99.47,-0.193
8.20,99.43,-0.200
8.20,99.39,-0.206
8.20,99.35,-0.212
8.21,99.31,-0.218
8.21,99.27,-0.222
8.22,99.23,-0.228
8.23,99.19,-0.233
8.23,99.15,-0.237
8.24,99.11,-0.240
8.24,99.07,-0.245
8.25,99.03,-0.250
8.25,98.98,-0.255
8.25,98.94,-0.258
8.26,98.90,-0.260
8.26,98.85,-0.263
8.27,98.81,-0.267
8.28,98.77,-0.270
8.28,98.72,-0.273
8.29,98.68,-0.276
8.29,98.63,-0.279
8.30,98.59,-0.281
8.30,98.54,-0.283
8.30,98.50,-0.286
8.31,98.45,-0.289
8.31,98.40,-0.291
8.32,98.36,-0.293
8.33,98.31,-0.296
8.33,98.27,-0.297
8.34,98.22,-0.298
8.34,98.17,-0.300
8.35,98.13,-0.302
8.35,98.08,-0.304
8.35,98.03,-0.303
8.36,97.99,-0.306
8.36,97.94,-0.308
8.37,97.89,-0.309
8.38,97.84,-0.310
8.38,97.80,-0.312
8.39,97.75,-0.312
8.39,97.70,-0.312
8.40,97.65,-0.312
8.40,97.61,-0.314
8.40,97.56,-0.316
8.41,97.51,-0.317
8.41,97.46,-0.318
8.42,97.41,-0.318
8.43,97.36,-0.319
8.43,97.32,-0.319
8.44,97.27,-0.320
8.44,97.22,-0.320
8.45,97.17,-0.321
8.45,97.12,-0.322
8.45,97.08,-0.322
8.46,97.03,-0.322
8.46,96.98,-0.322
8.47,96.93,-0.323
8.48,96.88,-0.324
8.48,96.83,-0.325
8.49,96.78,-0.325
8.49,96.73,-0.325
8.50,96.68,-0.326
8.50,96.64,-0.326
8.50,96.59,-0.326
8.51,96.54,-0.326
8.51,96.49,-0.326
8.52,96.44,-0.327
8.53,96.39,-0.327
8.53,96.34,-0.327
8.53,96.29,-0.327
8.54,96.24,-0.327
8.55,96.20,-0.328
8.55,96.15,-0.328
8.55,96.10,-0.328
8.56,96.05,-0.329
8.57,96.00,-0.329
8.57,95.95,-0.329
8.58,95.90,-0.329
8.58,95.85,-0.329
8.58,95.80,-0.329
8.59,95.75,-0.329
8.60,95.70,-0.330
8.60,95.65,-0.330
8.60,95.61,-0.330
8.61,95.56,-0.330
8.62,95.51,-0.330
8.62,95.46,-0.330
8.63,95.41,-0.330
8.63,95.36,-0.330
8.63,95.31,-0.330
8.64,95.26,-0.330
8.65,95.21,-0.330
8.65,95.16,-0.330
8.65,95.11,-0.330
8.66,95.06,-0.331
8.67,95.01,-0.331
8.67,94.96,-0.331
8.68,94.91,-0.331
8.68,94.86,-0.331
8.68,94.81,-0.331
8.69,94.76,-0.331
8.70,94.72,-0.331
8.70,94.67,-0.331
8.70,94.61,-0.331
8.71,94.57,-0.331
8.72,94.52,-0.331
8.72,94.47,-0.331
8.73,94.42,-0.331
8.73,94.37,-0.331
8.73,94.32,-0.331
8.74,94.27,-0.331
8.75,94.22,-0.331
8.75,94.17,-0.332
8.75,94.12,-0.332
8.76,94.07,-0.332
8.77,94.02,-0.332
8.77,93.97,-0.332
8.78,93.92,-0.332
8.78,93.87,-0.332
8.78,93.82,-0.332
8.79,93.77,-0.332
8.80,93.72,-0.332
8.80,93.67,-0.332
8.80,93.62,-0.332
8.81,93.57,-0.332
8.82,93.52,-0.332
8.82,93.48,-0.332
8.83,93.43,-0.332
8.83,93.38,-0.332
8.83,93.33,-0.332
8.84,93.28,-0.332
8.85,93.23,-0.332
8.85,93.18,-0.332
8.85,93.13,-0.332
8.86,93.08,-0.332
8.87,93.03,-0.332
8.87,92.98,-0.332
8.88,92.93,-0.332
8.88,92.88,-0.332
8.88,92.83,-0.332
8.89,92.78,-0.332
8.90,92.73,-0.332
8.90,92.68,-0.332
8.90,92.63,-0.332
8.91,92.58,-0.332
8.92,92.53,-0.333
8.92,92.48,-0.333
8.93,92.43,-0.333
8.93,92.38,-0.333
8.93,92.33,-0.333
8.94,92.28,-0.333
8.95,92.23,-0.333
8.95,92.18,-0.333
8.95,92.13,-0.333
8.96,92.08,-0.333
8.97,92.03,-0.333
8.97,91.98,-0.333
8.98,91.93,-0.333
8.98,91.88,-0.333
8.98,91.83,-0.333
8.99,91.79,-0.333
9.00,91.73,-0.333
9.00,91.68,-0.333
9.00,91.64,-0.333
9.01,91.59,-0.333
9.02,91.53,-0.333
9.02,91.49,-0.333
9.03,91.44,-0.333
9.03,91.39,-0.333
9.03,91.34,-0.332
9.04,91.29,-0.332
9.05,91.24,-0.332
9.05,91.19,-0.332
9.05,91.14,-0.332
9.06,91.09,-0.332
9.07,91.04,-0.332
9.07,90.99,-0.332
9.08,90.94,-0.332
9.08,90.89,-0.332
9.08,90.84,-0.332
9.09,90.79,-0.332
9.10,90.74,-0.332
9.10,90.69,-0.332
9.10,90.64,-0.332
9.11,90.59,-0.332
9.12,90.54,-0.332
9.12,90.49,-0.332
9.13,90.44,-0.332
9.13,90.39,-0.332
9.13,90.34,-0.332
9.14,90.29,-0.332
9.15,90.24,-0.332
9.15,90.19,-0.332
9.15,90.14,-0.332
9.16,90.09,-0.332
9.17,90.04,-0.332
9.17,89.99,-0.332
9.18,89.94,-0.332
9.18,89.89,-0.332
9.18,89.84,-0.332
9.19,89.79,-0.332
9.20,89.74,-0.332
9.20,89.69,-0.332
9.20,89.64,-0.332
9.21,89.59,-0.332
9.22,89.54,-0.332
9.22,89.49,-0.332
9.23,89.44,-0.332
9.23,89.39,-0.332
9.23,89.34,-0.332
9.24,89.29,-0.332
9.25,89.24,-0.332
9.25,89.19,-0.332
9.25,89.14,-0.332
9.26,89.09,-0.332
9.27,89.04,-0.331
9.27,88.99,-0.331
9.28,88.94,-0.331
9.28,88.89,-0.331
9.28,88.84,-0.331
9.29,88.79,-0.331
9.30,88.74,-0.331
9.30,88.70,-0.331
9.30,88.64,-0.331
9.31,88.60,-0.331
9.32,88.55,-0.331
9.32,88.50,-0.331
9.33,88.45,-0.331
9.33,88.40,-0.331
9.33,88.35,-0.331
9.34,88.30,-0.331
9.35,88.25,-0.331
9.35,88.20,-0.331
9.35,88.15,-0.331
9.36,88.10,-0.331
9.37,88.05,-0.331
9.37,88.00,-0.331
9.38,87.95,-0.331
9.38,87.90,-0.331
9.38,87.85,-0.331
9.39,87.80,-0.331
9.40,87.75,-0.330
9.40,87.70,-0.330
9.40,87.65,-0.330
9.41,87.60,-0.330
9.42,87.55,-0.330
9.42,87.50,-0.330
9.43,87.45,-0.330
9.43,87.40,-0.330
9.43,87.35,-0.330
9.44,87.30,-0.330
9.45,87.25,-0.330
9.45,87.20,-0.330
9.45,87.15,-0.330
9.46,87.10,-0.330
9.47,87.05,-0.330
9.47,87.00,-0.330
9.48,86.95,-0.330
9.48,86.90,-0.330
9.48,86.85,-0.330
9.49,86.80,-0.330
9.50,86.75,-0.330
9.50,86.70,-0.329
9.50,86.65,-0.329
9.51,86.60,-0.329
9.52,86.55,-0.329
9.52,86.50,-0.329
9.53,86.45,-0.329
9.53,86.40,-0.329
9.53,86.35,-0.329
9.54,86.30,-0.329
9.55,86.25,-0.329
9.55,86.20,-0.329
9.55,86.15,-0.329
9.56,86.10,-0.329
9.57,86.05,-0.329
9.57,86.00,-0.329
9.58,85.95,-0.329
9.58,85.90,-0.329
9.58,85.85,-0.329
9.59,85.80,-0.329
9.60,85.75,-0.329
9.60,85.70,-0.329
9.60,85.65,-0.329
9.61,85.60,-0.329
9.62,85.55,-0.329
9.62,85.50,-0.329
9.63,85.45,-0.329
9.63,85.40,-0.329
9.63,85.35,-0.328
9.64,85.30,-0.328
9.65,85.25,-0.328
9.65,85.20,-0.328
9.65,85.15,-0.328
9.66,85.10,-0.328
9.67,85.05,-0.328
9.67,85.00,-0.328
9.68,84.95,-0.328
9.68,84.90,-0.328
9.68,84.85,-0.328
9.69,84.80,-0.328
9.70,84.75,-0.328
9.70,84.70,-0.328
9.70,84.65,-0.328
9.71,84.60,-0.328
9.72,84.55,-0.328
9.72,84.50,-0.328
9.73,84.45,-0.328
9.73,84.40,-0.328
9.73,84.35,-0.328
9.74,84.30,-0.328
9.75,84.25,-0.328
9.75,84.20,-0.328
9.75,84.15,-0.328
9.76,84.11,-0.328
9.77,84.05,-0.328
9.77,84.00,-0.328
9.78,83.95,-0.328
9.78,83.90,-0.328
9.78,83.85,-0.327
9.79,83.80,-0.327
9.80,83.75,-0.327
9.80,83.70,-0.327
9.80,83.65,-0.327
9.81,83.60,-0.327
9.82,83.55,-0.327
9.82,83.51,-0.327
9.83,83.46,-0.327
9.83,83.40,-0.327
9.83,83.35,-0.327
9.84,83.30,-0.327
9.85,83.25,-0.327
9.85,83.21,-0.327
9.85,83.16,-0.327
9.86,83.10,-0.327
9.87,83.06,-0.327
9.87,83.01,-0.327
9.88,82.96,-0.327
9.88,82.91,-0.327
9.88,82.86,-0.327
9.89,82.81,-0.327
9.90,82.76,-0.327
9.90,82.71,-0.327
9.90,82.66,-0.327
9.91,82.61,-0.327
9.92,82.56,-0.327
9.92,82.51,-0.327
9.93,82.46,-0.327
9.93,82.41,-0.327
9.93,82.36,-0.327
9.94,82.31,-0.326
9.95,82.26,-0.326
9.95,82.21,-0.326
9.95,82.16,-0.326
9.96,82.11,-0.326
9.97,82.06,-0.326
9.97,82.01,-0.326
9.98,81.96,-0.326
9.98,81.91,-0.326
9.98,81.86,-0.326
9.99,81.81,-0.326
10.00,81.76,-0.326
10.00,81.71,-0.326
10.00,81.66,-0.326
10.01,81.61,-0.326
10.02,81.56,-0.326
10.02,81.51,-0.326
10.03,81.46,-0.326
10.03,81.41,-0.326
10.03,81.36,-0.326
10.04,81.31,-0.326
10.05,81.26,-0.326
10.05,81.21,-0.326
10.05,81.16,-0.326
10.06,81.11,-0.326
10.07,81.06,-0.326
10.07,81.01,-0.326
10.08,80.96,-0.326
10.08,80.91,-0.325
10.08,80.86,-0.325
10.09,80.81,-0.325
10.10,80.76,-0.325
10.10,80.71,-0.325
10.10,80.66,-0.325
10.11,80.61,-0.325
10.12,80.56,-0.325
10.12,80.51,-0.325
10.13,80.46,-0.325
10.13,80.41,-0.325
10.13,80.36,-0.325
10.14,80.31,-0.325
10.15,80.26,-0.325
10.15,80.21,-0.325
10.15,80.16,-0.325
10.16,80.11,-0.325
10.17,80.06,-0.325
10.17,80.01,-0.325
10.18,79.96,-0.325
10.18,79.91,-0.325
10.18,79.86,-0.325
10.19,79.81,-0.325
10.20,79.76,-0.325
10.20,79.71,-0.325
10.20,79.66,-0.325
10.21,79.61,-0.325
10.22,79.56,-0.325
10.22,79.51,-0.325
10.23,79.46,-0.325
10.23,79.41,-0.325
10.23,79.36,-0.325
10.24,79.31,-0.325
10.25,79.26,-0.325
10.25,79.21,-0.325
10.25,79.16,-0.324
10.26,79.11,-0.324
10.27,79.06,-0.324
10.27,79.01,-0.324
10.28,78.96,-0.324
10.28,78.91,-0.324
10.28,78.86,-0.324
10.29,78.81,-0.324
10.30,78.76,-0.324
10.30,78.71,-0.324
10.30,78.66,-0.324
10.31,78.61,-0.324
10.32,78.56,-0.324
10.32,78.51,-0.324
10.33,78.46,-0.324
10.33,78.41,-0.324
10.33,78.36,-0.324
10.34,78.31,-0.324
10.35,78.26,-0.324
10.35,78.21,-0.324
10.35,78.16,-0.324
10.36,78.11,-0.324
10.37,78.06,-0.324
10.37,78.01,-0.324
10.38,77.96,-0.324
10.38,77.91,-0.324
10.38,77.86,-0.324
10.39,77.81,-0.324
10.40,77.76,-0.324
10.40,77.71,-0.323
10.40,77.66,-0.323
10.41,77.61,-0.323
10.42,77.56,-0.323
10.42,77.51,-0.323
10.43,77.46,-0.323
10.43,77.41,-0.323
10.43,77.36,-0.323
10.44,77.31,-0.323
10.45,77.26,-0.323
10.45,77.21,-0.323
10.45,77.16,-0.323
10.46,77.11,-0.323
10.47,77.06,-0.323
10.47,77.01,-0.323
10.48,76.96,-0.323
10.48,76.91,-0.323
10.48,76.86,-0.323
10.49,76.81,-0.323
10.50,76.76,-0.323
10.50,76.71,-0.323
10.50,76.66,-0.323
10.51,76.61,-0.323
10.52,76.56,-0.323
10.52,76.51,-0.323
10.53,76.46,-0.323
10.53,76.41,-0.322
10.53,76.36,-0.322
10.54,76.31,-0.322
10.55,76.26,-0.322
10.55,76.21,-0.322
10.55,76.16,-0.322
10.56,76.11,-0.322
10.57,76.06,-0.322
10.57,76.01,-0.322
10.58,75.96,-0.322
10.58,75.91,-0.322
10.58,75.86,-0.322
10.59,75.81,-0.322
10.60,75.76,-0.322
10.60,75.71,-0.322
10.60,75.66,-0.322
10.61,75.61,-0.322
10.62,75.56,-0.322
10.62,75.51,-0.322
10.63,75.46,-0.322
10.63,75.41,-0.322
10.63,75.36,-0.322
10.64,75.31,-0.322
10.65,75.26,-0.322
10.65,75.21,-0.321
10.65,75.16,-0.321
10.66,75.11,-0.321
10.67,75.06,-0.321
10.67,75.01,-0.321
10.68,74.96,-0.321
10.68,74.91,-0.321
10.68,74.86,-0.321
10.69,74.81,-0.321
10.70,74.76,-0.321
10.70,74.71,-0.321
10.70,74.66,-0.321
10.71,74.61,-0.321
10.72,74.56,-0.321
10.72,74.51,-0.321
10.73,74.46,-0.321
10.73,74.41,-0.321
10.73,74.36,-0.321
10.74,74.31,-0.321
10.75,74.26,-0.321
10.75,74.21,-0.321
10.75,74.17,-0.321
10.76,74.12,-0.321
10.77,74.06,-0.321
10.77,74.02,-0.321
10.78,73.96,-0.321
10.78,73.92,-0.321
10.78,73.87,-0.320
10.79,73.81,-0.320
10.80,73.76,-0.320
10.80,73.72,-0.320
10.80,73.67,-0.320
10.81,73.61,-0.320
10.82,73.57,-0.320
10.82,73.52,-0.320
10.83,73.47,-0.320
10.83,73.42,-0.320
10.83,73.37,-0.320
10.84,73.32,-0.320
10.85,73.27,-0.320
10.85,73.22,-0.320
10.85,73.17,-0.320
[...]
25.73,84.45,-0.328
25.73,84.40,-0.328
25.73,84.35,-0.328
25.74,84.30,-0.328
25.74,84.25,-0.328
25.75,84.20,-0.327
25.76,84.15,-0.327
25.76,84.10,-0.327
25.77,84.05,-0.327
25.77,84.00,-0.327
25.78,83.95,-0.327
25.78,83.90,-0.327
25.78,83.85,-0.327
25.79,83.80,-0.327
25.79,83.75,-0.327
25.80,83.70,-0.327
25.81,83.65,-0.327
25.81,83.60,-0.327
25.82,83.55,-0.327
25.82,83.50,-0.327
25.83,83.45,-0.327
25.83,83.40,-0.327
25.83,83.35,-0.327
25.84,83.31,-0.327
25.84,83.25,-0.327
25.85,83.20,-0.327
25.86,83.16,-0.327
25.86,83.11,-0.327
25.87,83.05,-0.327
25.87,83.01,-0.327
25.88,82.96,-0.327
25.88,82.90,-0.327
25.88,82.86,-0.327
25.89,82.80,-0.327
25.89,82.75,-0.327
25.90,82.70,-0.327
25.91,82.65,-0.327
25.91,82.61,-0.327
25.92,82.56,-0.327
25.92,82.51,-0.327
25.93,82.46,-0.327
25.93,82.41,-0.326
25.93,82.36,-0.326
25.94,82.31,-0.326
25.94,82.26,-0.326
25.95,82.21,-0.326
25.96,82.16,-0.326
25.96,82.11,-0.326
25.97,82.06,-0.326
25.97,82.01,-0.326
25.98,81.96,-0.326
25.98,81.91,-0.326
25.98,81.86,-0.326
25.99,81.81,-0.326
25.99,81.76,-0.326
26.00,81.71,-0.326
26.01,81.66,-0.326
26.01,81.61,-0.326
26.02,81.56,-0.326
26.02,81.51,-0.326
26.03,81.46,-0.326
26.03,81.41,-0.326
26.03,81.36,-0.326
26.04,81.31,-0.326
26.04,81.26,-0.326
26.05,81.21,-0.326
26.06,81.16,-0.326
26.06,81.11,-0.326
26.07,81.06,-0.326
26.07,81.01,-0.326
26.08,80.96,-0.325
26.08,80.91,-0.325
26.08,80.86,-0.325
26.09,80.81,-0.325
26.09,80.76,-0.325
26.10,80.71,-0.325
26.11,80.66,-0.325
26.11,80.61,-0.325
26.12,80.56,-0.325
26.12,80.51,-0.325
26.13,80.46,-0.325
26.13,80.41,-0.325
26.13,80.36,-0.325
26.14,80.31,-0.325
26.14,80.26,-0.325
26.15,80.21,-0.325
26.16,80.16,-0.325
26.16,80.11,-0.325
26.17,80.06,-0.325
26.17,80.01,-0.325
26.18,79.96,-0.325
26.18,79.91,-0.325
26.18,79.86,-0.325
26.19,79.81,-0.325
26.19,79.76,-0.325
26.20,79.71,-0.325
26.21,79.66,-0.325
26.21,79.61,-0.325
26.22,79.56,-0.325
26.22,79.51,-0.325
26.23,79.46,-0.325
26.23,79.41,-0.325
26.23,79.36,-0.324
26.24,79.31,-0.324
26.24,79.26,-0.324
26.25,79.21,-0.324
26.26,79.16,-0.324
26.26,79.11,-0.324
26.27,79.06,-0.324
26.27,79.01,-0.324
26.28,78.96,-0.324
26.28,78.91,-0.324
26.28,78.86,-0.324
26.29,78.81,-0.324
26.29,78.76,-0.324
26.30,78.71,-0.324
26.31,78.66,-0.324
26.31,78.61,-0.324
26.32,78.56,-0.324
26.32,78.51,-0.324
26.33,78.46,-0.324
26.33,78.41,-0.324
26.33,78.36,-0.324
26.34,78.31,-0.324
26.34,78.26,-0.324
26.35,78.21,-0.324
26.36,78.16,-0.324
26.36,78.11,-0.324
26.37,78.06,-0.324
26.37,78.01,-0.324
26.38,77.96,-0.324
26.38,77.91,-0.324
26.38,77.86,-0.323
26.39,77.81,-0.323
26.39,77.76,-0.323
26.40,77.71,-0.323
26.41,77.66,-0.323
26.41,77.61,-0.323
26.42,77.56,-0.323
26.42,77.51,-0.323
26.43,77.46,-0.323
26.43,77.41,-0.323
26.43,77.36,-0.323
26.44,77.31,-0.323
26.44,77.26,-0.323
26.45,77.21,-0.323
26.46,77.16,-0.323
26.46,77.11,-0.323
26.47,77.06,-0.323
26.47,77.01,-0.323
26.48,76.96,-0.323
26.48,76.91,-0.323
26.48,76.86,-0.323
26.49,76.81,-0.323
26.49,76.76,-0.323
26.50,76.71,-0.323
26.51,76.66,-0.323
26.51,76.61,-0.323
26.52,76.56,-0.323
26.52,76.51,-0.323
26.53,76.46,-0.322
26.53,76.41,-0.322
26.53,76.36,-0.322
26.54,76.31,-0.322
26.54,76.26,-0.322
26.55,76.21,-0.322
26.56,76.16,-0.322
26.56,76.11,-0.322
26.57,76.06,-0.322
26.57,76.01,-0.322
26.58,75.96,-0.322
26.58,75.91,-0.322
26.58,75.86,-0.322
26.59,75.81,-0.322
26.59,75.76,-0.322
26.60,75.71,-0.322
26.61,75.66,-0.322
26.61,75.61,-0.322
26.62,75.56,-0.322
26.62,75.51,-0.322
26.63,75.46,-0.322
26.63,75.41,-0.322
26.63,75.36,-0.322
26.64,75.31,-0.322
26.64,75.26,-0.322
26.65,75.21,-0.321
26.66,75.16,-0.321
26.66,75.11,-0.321
26.67,75.06,-0.321
26.67,75.01,-0.321
26.68,74.96,-0.321
26.68,74.91,-0.321
26.68,74.86,-0.321
26.69,74.81,-0.321
26.69,74.76,-0.321
26.70,74.71,-0.321
26.71,74.66,-0.321
26.71,74.61,-0.321
26.72,74.56,-0.321
26.72,74.51,-0.321
26.73,74.46,-0.321
26.73,74.41,-0.321
26.73,74.36,-0.321
26.74,74.31,-0.321
26.74,74.26,-0.321
26.75,74.21,-0.321
26.76,74.16,-0.321
26.76,74.11,-0.321
26.77,74.06,-0.321
26.77,74.01,-0.321
26.78,73.96,-0.320
26.78,73.91,-0.320
26.78,73.86,-0.320
26.79,73.81,-0.320
26.79,73.76,-0.320
26.80,73.72,-0.320
26.81,73.66,-0.320
26.81,73.61,-0.320
26.82,73.56,-0.320
26.82,73.51,-0.320
26.83,73.46,-0.320
26.83,73.41,-0.320
26.83,73.37,-0.320
26.84,73.31,-0.320
26.84,73.26,-0.320
26.85,73.21,-0.320
26.86,73.16,-0.320
26.86,73.11,-0.320
26.87,73.06,-0.320
26.87,73.01,-0.320
26.88,72.96,-0.320
26.88,72.91,-0.320
26.88,72.86,-0.320
26.89,72.82,-0.320
26.89,72.76,-0.320
26.90,72.72,-0.320
26.91,72.67,-0.320
26.91,72.62,-0.319
26.92,72.57,-0.319
26.92,72.52,-0.319
26.93,72.47,-0.319
26.93,72.41,-0.319
26.93,72.36,-0.319
26.94,72.32,-0.319
26.94,72.26,-0.319
26.95,72.21,-0.319
26.96,72.17,-0.319
26.96,72.12,-0.319
26.97,72.07,-0.319
26.97,72.02,-0.319
26.98,71.97,-0.319
26.98,71.92,-0.319
26.98,71.87,-0.319
26.99,71.82,-0.319
26.99,71.77,-0.319
27.00,71.72,-0.319
27.01,71.67,-0.319
27.01,71.62,-0.319
27.02,71.57,-0.319
27.02,71.52,-0.319
27.03,71.47,-0.318
27.03,71.42,-0.318
27.03,71.37,-0.318
27.04,71.32,-0.318
27.04,71.27,-0.318
27.05,71.22,-0.318
27.06,71.17,-0.318
27.06,71.12,-0.318
27.07,71.07,-0.318
27.07,71.02,-0.318
27.08,70.97,-0.318
27.08,70.92,-0.318
27.08,70.87,-0.318
27.09,70.82,-0.318
27.09,70.77,-0.318
27.10,70.72,-0.318
27.11,70.67,-0.318
27.11,70.62,-0.318
27.12,70.57,-0.318
27.12,70.52,-0.318
27.13,70.47,-0.318
27.13,70.42,-0.318
27.13,70.37,-0.318
27.14,70.32,-0.318
27.14,70.27,-0.318
27.15,70.22,-0.318
27.16,70.17,-0.318
27.16,70.12,-0.318
27.17,70.07,-0.318
27.17,70.02,-0.318
27.18,69.97,-0.317
27.18,69.92,-0.317
27.18,69.87,-0.317
27.19,69.82,-0.317
27.19,69.77,-0.317
27.20,69.72,-0.317
27.21,69.67,-0.317
27.21,69.62,-0.317
27.22,69.57,-0.317
27.22,69.52,-0.317
27.23,69.47,-0.317
27.23,69.42,-0.317
27.23,69.37,-0.317
27.24,69.32,-0.317
27.24,69.27,-0.317
27.25,69.22,-0.317
27.26,69.17,-0.317
27.26,69.12,-0.317
27.27,69.07,-0.317
27.27,69.02,-0.317
27.28,68.97,-0.317
27.28,68.92,-0.317
27.28,68.87,-0.317
27.29,68.82,-0.317
27.29,68.77,-0.317
27.30,68.72,-0.317
27.31,68.67,-0.316
27.31,68.62,-0.316
27.32,68.57,-0.316
27.32,68.52,-0.316
27.33,68.47,-0.316
27.33,68.42,-0.316
27.33,68.37,-0.316
27.34,68.32,-0.316
27.34,68.27,-0.316
27.35,68.22,-0.316
27.36,68.17,-0.316
27.36,68.12,-0.316
27.37,68.07,-0.316
27.37,68.02,-0.316
27.38,67.97,-0.316
27.38,67.92,-0.316
27.38,67.87,-0.316
27.39,67.82,-0.316
27.39,67.77,-0.316
27.40,67.72,-0.316
27.41,67.67,-0.316
27.41,67.62,-0.316
27.42,67.57,-0.316
27.42,67.52,-0.316
27.43,67.47,-0.316
27.43,67.42,-0.316
27.43,67.37,-0.316
27.44,67.32,-0.315
27.44,67.27,-0.315
27.45,67.22,-0.315
27.46,67.17,-0.315
27.46,67.12,-0.315
27.47,67.07,-0.315
27.47,67.02,-0.315
27.48,66.97,-0.315
27.48,66.92,-0.315
27.48,66.87,-0.315
27.49,66.82,-0.315
27.49,66.77,-0.315
27.50,66.72,-0.315
27.51,66.67,-0.315
27.51,66.62,-0.315
27.52,66.57,-0.315
27.52,66.52,-0.315
27.53,66.47,-0.315
27.53,66.42,-0.315
27.53,66.37,-0.315
27.54,66.32,-0.315
27.54,66.27,-0.315
27.55,66.22,-0.315
27.56,66.17,-0.315
27.56,66.12,-0.315
27.57,66.07,-0.315
27.57,66.02,-0.315
27.58,65.97,-0.314
27.58,65.92,-0.314
27.58,65.87,-0.314
27.59,65.82,-0.314
27.59,65.77,-0.314
27.60,65.72,-0.314
27.61,65.67,-0.314
27.61,65.62,-0.314
27.62,65.57,-0.314
27.62,65.52,-0.314
27.63,65.47,-0.314
27.63,65.42,-0.314
27.63,65.37,-0.314
27.64,65.32,-0.314
27.64,65.27,-0.314
27.65,65.22,-0.314
27.66,65.17,-0.314
27.66,65.12,-0.314
27.67,65.07,-0.314
27.67,65.02,-0.314
27.68,64.97,-0.314
27.68,64.92,-0.314
27.68,64.87,-0.314
27.69,64.82,-0.314
27.69,64.77,-0.314
27.70,64.72,-0.313
27.71,64.67,-0.313
27.71,64.62,-0.313
27.72,64.57,-0.313
27.72,64.52,-0.313
27.73,64.47,-0.313
27.73,64.42,-0.313
27.73,64.37,-0.313
27.74,64.32,-0.313
27.74,64.27,-0.313
27.75,64.22,-0.313
27.76,64.17,-0.313
27.76,64.12,-0.313
27.77,64.07,-0.313
27.77,64.02,-0.313
27.78,63.97,-0.313
27.78,63.92,-0.313
27.78,63.87,-0.313
27.79,63.82,-0.313
27.79,63.77,-0.313
27.80,63.72,-0.313
27.81,63.67,-0.313
27.81,63.62,-0.313
27.82,63.57,-0.313
27.82,63.52,-0.313
27.83,63.47,-0.313
27.83,63.42,-0.313
27.83,63.37,-0.313
27.84,63.32,-0.313
27.84,63.27,-0.313
27.85,63.22,-0.312
27.86,63.17,-0.312
27.86,63.12,-0.312
27.87,63.07,-0.312
27.87,63.02,-0.312
27.88,62.97,-0.312
27.88,62.92,-0.312
27.88,62.87,-0.312
27.89,62.82,-0.312
27.89,62.77,-0.312
27.90,62.72,-0.312
27.91,62.67,-0.312
27.91,62.62,-0.312
27.92,62.57,-0.312
27.92,62.52,-0.312
27.93,62.47,-0.312
27.93,62.42,-0.312
27.93,62.38,-0.312
27.94,62.32,-0.312
27.94,62.27,-0.312
27.95,62.23,-0.312
27.96,62.18,-0.312
27.96,62.12,-0.312
27.97,62.08,-0.312
27.97,62.02,-0.312
27.98,61.97,-0.312
27.98,61.93,-0.312
27.98,61.87,-0.311
27.99,61.82,-0.311
27.99,61.78,-0.311
28.00,61.73,-0.311
28.01,61.67,-0.311
28.01,61.63,-0.311
28.02,61.58,-0.311
28.02,61.53,-0.311
28.03,61.48,-0.311
28.03,61.43,-0.311
28.03,61.38,-0.311
28.04,61.32,-0.311
28.04,61.28,-0.311
28.05,61.23,-0.311
28.06,61.18,-0.311
28.06,61.13,-0.311
28.07,61.08,-0.311
28.07,61.03,-0.311
28.08,60.98,-0.311
28.08,60.93,-0.311
28.08,60.88,-0.311
28.09,60.83,-0.311
28.09,60.78,-0.311
28.10,60.73,-0.311
28.11,60.68,-0.311
28.11,60.63,-0.311
28.12,60.58,-0.311
28.12,60.53,-0.311
28.13,60.48,-0.311
28.13,60.43,-0.310
28.13,60.38,-0.310
28.14,60.33,-0.310
28.14,60.28,-0.310
28.15,60.23,-0.310
28.16,60.18,-0.310
28.16,60.13,-0.310
28.17,60.08,-2.475
28.17,60.09,-12.737
28.18,60.83,-46.540
28.18,62.94,-81.634
28.18,65.79,-86.911
28.19,67.00,-57.606
28.19,67.28,-33.424
28.20,67.17,-20.947
28.21,66.89,-13.954
28.21,66.56,-10.179
28.22,66.20,-8.065
28.22,65.85,-6.765
28.23,65.50,-5.948
28.23,65.16,-5.325
28.23,64.83,-4.762
28.24,64.52,-4.277
28.24,64.22,-3.982
28.25,63.92,-3.765
28.26,63.64,-3.576
28.26,63.37,-3.401
28.27,63.11,-3.234
28.27,62.86,-3.078
28.28,62.62,-2.931
28.28,62.39,-2.794
28.28,62.17,-2.667
28.29,61.96,-2.548
28.29,61.75,-2.435
28.30,61.56,-2.330
28.31,61.37,-2.232
28.31,61.18,-2.140
28.32,61.01,-2.051
28.32,60.84,-1.967
28.33,60.67,-1.890
28.33,60.51,-1.816
28.33,60.36,-1.743
28.34,60.21,-1.675
28.34,60.07,-1.609
28.35,59.93,-1.548
28.36,59.80,-1.487
28.36,59.67,-1.429
28.37,59.54,-1.375
28.37,59.42,-1.325
28.38,59.30,-1.275
28.38,59.18,-1.225
28.38,59.07,-1.179
28.39,58.96,-1.138
28.39,58.86,-1.097
28.40,58.75,-1.058
28.41,58.65,-1.018
28.41,58.55,-0.983
28.42,58.46,-0.950
28.42,58.37,-0.918
28.43,58.27,-0.887
28.43,58.18,-0.856
28.43,58.10,-0.829
28.44,58.01,-0.803
28.44,57.93,-0.778
28.45,57.85,-0.753
28.46,57.76,-0.730
28.46,57.69,-0.708
28.47,57.61,-0.687
28.47,57.53,-0.667
28.48,57.46,-0.649
28.48,57.38,-0.631
28.48,57.31,-0.613
28.49,57.24,-0.597
28.49,57.17,-0.583
28.50,57.10,-0.569
28.51,57.03,-0.553
28.51,56.96,-0.541
28.52,56.90,-0.528
28.52,56.83,-0.517
28.53,56.76,-0.505
28.53,56.70,-0.492
28.53,56.64,-0.481
28.54,56.57,-0.471
28.54,56.51,-0.463
28.55,56.45,-0.454
28.56,56.39,-0.447
28.56,56.33,-0.439
28.57,56.27,-0.430
28.57,56.21,-0.422
28.58,56.15,-0.415
28.58,56.09,-0.409
28.58,56.03,-0.403
28.59,55.97,-0.397
28.59,55.92,-0.391
28.60,55.86,-0.386
28.61,55.80,-0.381
28.61,55.75,-0.375
28.62,55.69,-0.371
28.62,55.64,-0.367
28.63,55.58,-0.363
28.63,55.52,-0.357
28.63,55.47,-0.352
28.64,55.41,-0.349
28.64,55.36,-0.347
28.65,55.31,-0.344
28.66,55.25,-0.341
28.66,55.20,-0.338
28.67,55.14,-0.334
28.67,55.09,-0.331
28.68,55.04,-0.329
28.68,54.98,-0.326
28.68,54.93,-0.324
28.69,54.88,-0.322
28.69,54.83,-0.321
28.70,54.77,-0.318
28.71,54.72,-0.315
28.71,54.67,-0.312
28.72,54.61,-0.313
28.72,54.56,-0.311
28.73,54.51,-0.309
28.73,54.46,-0.308
28.73,54.41,-0.307
28.74,54.36,-0.305
28.74,54.30,-0.302
28.75,54.25,-0.300
28.76,54.20,-0.300
28.76,54.15,-0.299
28.77,54.10,-0.299
28.77,54.05,-0.299
28.78,53.99,-0.298
28.78,53.94,-0.297
28.78,53.89,-0.295
28.79,53.84,-0.294
28.79,53.79,-0.293
28.80,53.74,-0.293
28.81,53.69,-0.292
28.81,53.64,-0.292
28.82,53.59,-0.291
28.82,53.54,-0.290
28.83,53.49,-0.290
28.83,53.44,-0.289
28.83,53.39,-0.289
28.84,53.33,-0.288
28.84,53.29,-0.287
28.85,53.23,-0.287
28.86,53.18,-0.286
28.86,53.13,-0.286
28.87,53.08,-0.286
28.87,53.03,-0.286
28.88,52.98,-0.285
28.88,52.93,-0.285
28.88,52.88,-0.284
28.89,52.83,-0.284
28.89,52.78,-0.283
28.90,52.73,-0.283
28.91,52.68,-0.283
28.91,52.63,-0.283
28.92,52.58,-0.282
28.92,52.53,-0.282
28.93,52.48,-0.282
28.93,52.43,-0.282
28.93,52.38,-0.282
28.94,52.33,-0.282
28.94,52.28,-0.281
28.95,52.23,-0.281
28.96,52.18,-0.281
28.96,52.13,-0.281
28.97,52.08,-0.281
28.97,52.03,-0.281
28.98,51.98,-0.281
28.98,51.93,-0.281
28.98,51.88,-0.281
28.99,51.83,-0.280
28.99,51.78,-0.280
29.00,51.73,-0.280
29.01,51.68,-0.280
29.01,51.63,-0.280
29.02,51.58,-0.279
29.02,51.53,-0.279
29.03,51.48,-0.279
29.03,51.43,-0.279
29.03,51.38,-0.279
29.04,51.33,-0.279
29.04,51.28,-0.279
29.05,51.23,-0.279
29.06,51.18,-0.279
29.06,51.12,-0.279
29.07,51.07,-0.279
29.07,51.03,-0.279
29.08,50.98,-0.278
29.08,50.93,-0.278
29.08,50.88,-0.278
29.09,50.83,-0.278
29.09,50.78,-0.278
29.10,50.73,-0.278
29.11,50.68,-0.278
29.11,50.63,-0.278
29.12,50.58,-0.278
29.12,50.52,-0.278
29.13,50.48,-0.278
29.13,50.43,-0.277
29.13,50.38,-0.277
29.14,50.33,-0.277
29.14,50.28,-0.277
29.15,50.23,-0.277
29.16,50.18,-0.277
29.16,50.13,-0.277
29.17,50.08,-0.277
29.17,50.03,-0.277
29.18,49.98,-0.277
29.18,49.93,-0.277
29.18,49.88,-0.277
29.19,49.83,-0.276
29.19,49.78,-0.276
29.20,49.73,-0.276
29.21,49.68,-0.276
29.21,49.63,-0.276
29.22,49.58,-0.276
29.22,49.53,-0.276
29.23,49.48,-0.276
29.23,49.43,-0.276
29.23,49.38,-0.276
29.24,49.33,-0.276
29.24,49.28,-0.276
29.25,49.23,-0.276
29.26,49.18,-0.275
29.26,49.13,-0.275
29.27,49.08,-0.275
29.27,49.03,-0.275
29.28,48.98,-0.275
29.28,48.93,-0.275
29.28,48.88,-0.275
29.29,48.83,-0.275
29.29,48.78,-0.275
29.30,48.73,-0.275
29.31,48.68,-0.275
29.31,48.63,-0.275
29.32,48.58,-0.275
29.32,48.53,-0.275
29.33,48.48,-0.275
29.33,48.43,-0.274
29.33,48.38,-0.274
29.34,48.33,-0.274
29.34,48.28,-0.274
29.35,48.23,-0.274
29.36,48.18,-0.274
29.36,48.13,-0.274
29.37,48.08,-0.274
29.37,48.03,-0.274
29.38,47.98,-0.274
29.38,47.93,-0.274
29.38,47.87,-0.274
29.39,47.82,-0.274
29.39,47.78,-0.273
29.40,47.73,-0.273
29.41,47.68,-0.273
29.41,47.63,-0.273
29.42,47.58,-0.273
29.42,47.53,-0.273
29.43,47.48,-0.273
29.43,47.43,-0.273
29.43,47.38,-0.273
29.44,47.33,-0.273
29.44,47.28,-0.273
29.45,47.23,-0.273
29.46,47.18,-0.273
29.46,47.13,-0.273
29.47,47.08,-0.273
29.47,47.03,-0.272
29.48,46.98,-0.272
29.48,46.93,-0.272
29.48,46.88,-0.272
29.49,46.83,-0.272
29.49,46.78,-0.272
29.50,46.73,-0.272
29.51,46.68,-0.272
29.51,46.63,-0.272
29.52,46.58,-0.272
29.52,46.53,-0.272
29.53,46.48,-0.271
29.53,46.43,-0.271
29.53,46.38,-0.271
29.54,46.33,-0.271
29.54,46.28,-0.271
29.55,46.23,-0.271
29.56,46.18,-0.271
29.56,46.13,-0.271
29.57,46.08,-0.271
29.57,46.03,-0.271
29.58,45.98,-0.271
29.58,45.93,-0.271
29.58,45.88,-0.271
29.59,45.83,-0.270
29.59,45.78,-0.270
29.60,45.73,-0.270
29.61,45.68,-0.270
29.61,45.63,-0.270
29.62,45.58,-0.270
29.62,45.53,-0.270
29.63,45.48,-0.270
29.63,45.43,-0.270
29.63,45.38,-0.270
29.64,45.33,-0.270
29.64,45.28,-0.270
29.65,45.23,-0.270
29.66,45.18,-0.270
29.66,45.13,-0.269
29.67,45.08,-0.269
29.67,45.03,-0.269
29.68,44.98,-0.269
29.68,44.93,-0.269
29.68,44.88,-0.269
29.69,44.83,-0.269
29.69,44.78,-0.269
29.70,44.73,-0.269
29.71,44.68,-0.269
29.71,44.63,-0.269
29.72,44.58,-0.269
29.72,44.53,-0.269
29.73,44.48,-0.269
29.73,44.43,-0.269
29.73,44.38,-0.269
29.74,44.33,-0.269
29.74,44.28,-0.269
29.75,44.23,-0.269
29.76,44.18,-0.268
29.76,44.13,-0.268
29.77,44.08,-0.268
29.77,44.03,-0.268
29.78,43.98,-0.268
29.78,43.93,-0.268
29.78,43.88,-0.268
29.79,43.83,-0.268
29.79,43.78,-0.268
29.80,43.73,-0.268
29.81,43.68,-0.268
29.81,43.63,-0.268
29.82,43.58,-0.268
29.82,43.53,-0.268
29.83,43.48,-0.268
29.83,43.43,-0.268
29.83,43.38,-0.268
29.84,43.33,-0.267
29.84,43.28,-0.267
29.85,43.23,-0.267
29.86,43.18,-0.267
29.86,43.13,-0.267
29.87,43.08,-0.267
29.87,43.03,-0.267
29.88,42.98,-0.267
29.88,42.93,-0.267
29.88,42.88,-0.267
29.89,42.83,-0.267
29.89,42.78,-0.267
29.90,42.73,-0.267
29.91,42.68,-0.267
29.91,42.63,-0.267
29.92,42.58,-0.267
29.92,42.53,-0.267
29.93,42.48,-0.266
29.93,42.43,-0.266
29.93,42.38,-0.266
29.94,42.33,-0.266
29.94,42.28,-0.266
29.95,42.23,-0.266
29.96,42.18,-0.266
29.96,42.13,-0.266
29.97,42.08,-0.266
29.97,42.03,-0.266
29.98,41.98,-0.266
29.98,41.93,-0.266
29.98,41.88,-0.266
29.99,41.83,-0.266
29.99,41.78,-0.266
30.00,41.73,-0.265
30.01,41.68,-0.265
30.01,41.63,-0.265
30.02,41.58,-0.265
30.02,41.53,-0.265
30.03,41.48,-0.265
30.03,41.43,-0.265
30.03,41.38,-0.265
30.04,41.33,-0.265
30.04,41.28,-0.265
30.05,41.23,-0.265
30.06,41.18,-0.265
30.06,41.13,-0.265
30.07,41.08,-0.265
30.07,41.03,-0.265
30.08,40.98,-0.265
30.08,40.93,-0.265
30.08,40.88,-0.264
30.09,40.83,-0.264
30.09,40.78,-0.264
30.10,40.73,-0.264
30.11,40.68,-0.264
30.11,40.63,-0.264
30.12,40.58,-0.264
30.12,40.53,-0.264
30.13,40.48,-0.264
30.13,40.43,-0.264
30.13,40.38,-0.264
30.14,40.33,-0.264
30.14,40.28,-0.264
30.15,40.23,-0.264
30.16,40.18,-0.264
30.16,40.13,-0.264
30.17,40.08,-0.264
30.17,40.03,-0.264
30.18,39.98,-0.264
30.18,39.93,-0.263
30.18,39.88,-0.263
30.19,39.83,-0.263
30.19,39.78,-0.263
30.20,39.73,-0.263
30.21,39.68,-0.263
30.21,39.63,-0.263
30.22,39.58,-0.263
30.22,39.53,-0.263
30.23,39.48,-0.263
30.23,39.43,-0.263
30.23,39.38,-0.263
30.24,39.33,-0.263
30.24,39.28,-0.263
30.25,39.23,-0.263
30.26,39.18,-0.263
30.26,39.13,-0.262
30.27,39.08,-0.262
30.27,39.03,-0.262
30.28,38.98,-0.262
30.28,38.93,-0.262
30.28,38.88,-0.262
30.29,38.83,-0.262
30.29,38.78,-0.262
30.30,38.73,-0.262
30.31,38.68,-0.262
30.31,38.63,-0.262
30.32,38.58,-0.262
30.32,38.53,-0.262
30.33,38.48,-0.262
30.33,38.43,-0.262
30.33,38.38,-0.262
30.34,38.33,-0.262
30.34,38.28,-0.262
30.35,38.23,-0.262
30.36,38.18,-0.262
30.36,38.13,-0.261
30.37,38.08,-0.261
30.37,38.03,-0.261
30.38,37.98,-0.261
30.38,37.93,-0.261
30.38,37.88,-0.261
30.39,37.83,-0.261
30.39,37.78,-0.261
30.40,37.73,-0.261
30.41,37.68,-0.261
30.41,37.63,-0.261
30.42,37.58,-0.261
30.42,37.53,-0.261
30.43,37.48,-0.261
30.43,37.43,-0.261
30.43,37.38,-0.261
30.44,37.33,-0.260
30.44,37.28,-0.260
30.45,37.23,-0.260
30.46,37.18,-0.260
30.46,37.13,-0.260
30.47,37.08,-0.260
30.47,37.03,-0.260
30.48,36.98,-0.260
30.48,36.93,-0.260
30.48,36.88,-0.260
30.49,36.83,-0.260
30.49,36.78,-0.260
30.50,36.73,-0.260
30.51,36.68,-0.260
30.51,36.63,-0.260
30.52,36.58,-0.260
30.52,36.53,-0.260
30.53,36.48,-0.259
30.53,36.43,-0.259
30.53,36.38,-0.259
30.54,36.33,-0.259
30.54,36.28,-0.259
30.55,36.23,-0.259
30.56,36.18,-0.259
30.56,36.13,-0.259
30.57,36.08,-0.259
30.57,36.03,-0.259
30.58,35.98,-0.259
30.58,35.93,-0.259
30.58,35.88,-0.259
30.59,35.83,-0.259
30.59,35.78,-0.258
30.60,35.73,-0.258
30.61,35.68,-0.258
30.61,35.63,-0.258
30.62,35.58,-0.258
30.62,35.53,-0.258
30.63,35.48,-0.258
30.63,35.43,-0.258
30.63,35.38,-0.258
30.64,35.33,-0.258
30.64,35.28,-0.258
30.65,35.23,-0.258
30.66,35.19,-0.258
30.66,35.13,-0.258
30.67,35.08,-0.258
30.67,35.03,-0.257
30.68,34.98,-0.257
30.68,34.93,-0.257
30.68,34.89,-0.257
30.69,34.83,-0.257
30.69,34.78,-0.257
30.70,34.73,-0.257
30.71,34.69,-0.257
30.71,34.64,-0.257
30.72,34.58,-0.257
30.72,34.53,-0.257
30.73,34.49,-0.257
30.73,34.44,-0.257
30.73,34.39,-0.257
30.74,34.34,-0.257
30.74,34.29,-0.257
30.75,34.24,-0.257
30.76,34.18,-0.256
30.76,34.13,-0.256
30.77,34.09,-0.256
30.77,34.03,-0.256
30.78,33.99,-0.256
30.78,33.94,-0.256
30.78,33.89,-0.256
30.79,33.83,-0.256
30.79,33.78,-0.256
30.80,33.74,-0.256
30.81,33.69,-0.256
30.81,33.64,-0.256
30.82,33.59,-0.256
30.82,33.54,-0.256
30.83,33.49,-0.256
30.83,33.44,-0.256
30.83,33.38,-0.256
30.84,33.34,-0.255
30.84,33.29,-0.255
30.85,33.24,-0.255
30.86,33.19,-0.255
30.86,33.14,-0.255
30.87,33.09,-0.255
30.87,33.04,-0.255
30.88,32.99,-0.255
30.88,32.94,-0.255
30.88,32.89,-0.255
30.89,32.84,-0.255
30.89,32.79,-0.255
30.90,32.74,-0.255
30.91,32.69,-0.255
30.91,32.64,-0.255
30.92,32.59,-0.255
30.92,32.54,-0.254
30.93,32.49,-0.254
30.93,32.44,-0.254
30.93,32.39,-0.254
30.94,32.34,-0.254
30.94,32.29,
30.95,32.24,
30.96,32.19,
30.96,32.14,
30.97,32.09,
30.97,32.04,
30.98,31.99,
30.98,31.94,
30.98,31.89,
30.99,31.84,
30.99,,
31.00,,