File: Data/2025_02_13_Fructose_DSC.txt
Filename	2025_02_13_Fructose_DSC
Instrument name	DSC2A-00468 (192.168.1.100)
Operator	JLY
rundate	2/13/2025
Sample name	2025_02_13_Fructose_DSC
proceduresegments	Data Off ; Equilibrate 30.00 °C; Data On ; Ramp 5.00 °C/min to 120.00 °C
[File Parameters]
Run date	2/13/2025 5:27:40 PM
Trios version	5.1.1.46572
Original File Name
Current File Name	D:\DSC2500\CHM343\2025_02_13_Fructose_DSC.tri
[Procedure]
Procedure Name	Fructose Melting
Sample Name	2025_02_13_Fructose_DSC
Sample Mass	14.02 mg
Reference Sample Mass	0 mg
Pan Mass	53.67 mg
Pan Number	27
Reference Pan Mass	54 mg
Reference Pan Number	19
Pan Type	Tzero Aluminum Hermetic
Comments	Al Hermetic Sealed Pan, with ref Al pan
Project Name
Operator	JLY
Test	Custom
Unload Max Temperature	30
Unload Min Temperature	30
Load Max Temperature	30
Load Min Temperature	30
Stop on Gas Flow Error	Yes
[Signal List]
Signal #1	Time (min)
Signal #2	Temperature (°C)
Signal #3	Heat Flow (mW)
Signal #4	Delta T (µV)
Signal #5	Delta Tzero (µV)
Signal #6	Tzero Temperature (°C)
Signal #7	Cell Purge (mL/min)
Signal #8	Heater Temp (°C)
Signal #9	Power Delivered (W)
Signal #10	Reference Junction Temperature (°C)
Signal #11	Flange Temperature (°C)
Signal #12	Heat Flow Phase (rad)
Signal #13	Total Heat Capacity (J/°C)
Signal #14	Heat Capacity (J/°C)
[Configuration]
Company Name	ASU
Instrument Name	DSC2A-00468
Instrument Type	DSC2500
Serial Number	DSC2A-00468
IP	192.168.1.100
Location of Instrument	MRRC
DisplayType	Unknown
Sample Interval 	0.1 s/pt
Selected Heat Flow	T4P
Exotherm Direction	Down
Cell Serial	DRC2-00792
Lid Type	Standard
Cooler	RCS 90
Leave Cooler on at End of Sequence	On
Gas 2	Nitrogen
Gas Selected	Channel 1
Flow Rate	50 mL/min
Secondary Purge	On
Licensed Heat Flow	Heat Flow T4P
Modulation Licensed	Yes
[Versions]
Common IDD Version	1
Cortex Version	VER 2.10.2.31
Driver	5.0.0.6
GDM Version	1.0.3.3
TouchscreenVersion	1.0.0.16145
FEP Version	1.2.1.21
FEP Bootloader	2.0.0.5
AutoSampler Version	2.1.1.26
Auto Sampler Bootloader	2.0.0.5
FCM Version	1.1.0.3
FCM Bootloader	2.0.0.5
[Experiment Logs]
Experiment Log Entry # 1	Data On set to 0
Experiment Log Entry # 3	Equilibrate Segment 30 (C) Started
Experiment Log Entry # 5	Air Cool is off.
Experiment Log Entry # 7	Data On set to 1
Experiment Log Entry # 9	Ramp Segment 5 C/min to 120 Started
[Method Log]
Method Log Entry # 1	Data Off
Method Log Entry # 2	Equilibrate 30 °C
Method Log Entry # 3	Data On
Method Log Entry # 4	(Ramp 34586) Ramp 5 °C/minute to 120 °C
Cell Serial	DRC2-00792
[T1 Calibration]
Slope	-0.008529666
Offset	9.636258
Initial Temperature	98.23
GUID	f8bfdadc-4977-4fdf-ba6d-0ba9134940c3
[TZero Calibration]
Date Applied	11/29/2022 4:06:13 PM
Description	From -89.059 °C to 396.009 °C at 20.000°C/min
Gas Type	Nitrogen
Pan Type	None
Source Files 1	C:\Users\yargerlab\Desktop\DSC Data\General\TZero_calibration_11_29_22_2nd(2).tri
Source Files 2	C:\Users\yargerlab\Desktop\DSC Data\General\TZero_calibration_11_29_22_2nd(3).tri
Delta T Offset	13.05235
Delta T Slope	-0.007271007
Delta T0 Offset	-13.69128
Delta T0 Slope	0.06063341
[Temperature Calibration]
Date Applied	11/29/2022 7:12:28 PM
Description	From 106.590 °C to 186.590 °C at 10.000°C/min
Gas Type	Nitrogen
Pan Type	Tzero Aluminum Hermetic
Source Files 1	C:\Users\yargerlab\Desktop\DSC Data\General\Indium(6).tri
Measured 1	157.391
Known 1	156.598
[Cell Constant Calibration]
Date Applied	11/29/2022 7:12:29 PM
Description	From 106.590 °C to 186.590 °C at 10.000°C/min
Gas Type	Nitrogen
Pan Type	Tzero Aluminum Hermetic
Source Files 1	C:\Users\yargerlab\Desktop\DSC Data\General\Indium(6).tri
T4P KCell	1.006051
Onset Slope	63.26126 mW/°C
[Direct Cp Calibration]
Date Applied	11/30/2022 11:04:51 AM
Description	From -79.983 °C to 298.409 °C at 10.000°C/min
Gas Type	Nitrogen
Pan Type	Tzero Aluminum Hermetic
Source Files 1	C:\Users\yargerlab\Desktop\DSC Data\General\Sapphire_Heat_Capacity_11_30_22.tri
[Rev Cp Calibration]
Date Applied	11/30/2022 1:58:51 PM
Description	From -79.996 °C to 292.812 °C at 3.000°C/min
Gas Type	Nitrogen
Pan Type	Tzero Aluminum Hermetic
Source Files 1	C:\Users\yargerlab\Desktop\DSC Data\General\Sapphire_MDSC_Calibration_11_30_22.tri
[step]
Ramp 5.00 °C/min to 120.00 °C
Time	Temperature	Heat Flow (Normalized)
min	°C	W/g
0.00	30.08	-0.017
0.01	30.08	-0.017
0.03	30.08	-0.016
0.04	30.09	-0.015
0.05	30.09	-0.015
0.07	30.10	-0.014
0.08	30.11	-0.013
0.09	30.12	-0.013
0.11	30.15	-0.011
0.12	30.18	-0.006
0.13	30.21	-0.001
0.15	30.25	0.005
0.16	30.29	0.012
0.17	30.33	0.019
0.19	30.38	0.026
0.20	30.43	0.033
0.21	30.48	0.039
0.23	30.53	0.044
0.24	30.58	0.050
0.25	30.63	0.054
0.27	30.69	0.059
0.28	30.74	0.062
0.29	30.80	0.066
0.31	30.86	0.070
0.32	30.92	0.073
0.33	30.98	0.076
0.35	31.04	0.079
0.36	31.10	0.082
0.37	31.16	0.084
0.39	31.23	0.085
0.40	31.29	0.088
0.41	31.35	0.089
0.43	31.41	0.091
0.44	31.48	0.092
0.45	31.54	0.093
0.47	31.61	0.094
0.48	31.67	0.096
0.49	31.73	0.096
0.51	31.80	0.097
0.52	31.86	0.098
0.53	31.93	0.099
0.55	31.99	0.099
0.56	32.06	0.100
0.57	32.12	0.100
0.59	32.19	0.101
0.60	32.25	0.101
0.61	32.32	0.101
0.63	32.38	0.101
0.64	32.45	0.102
0.65	32.51	0.102
0.67	32.58	0.102
0.68	32.65	0.102
0.69	32.71	0.103
0.71	32.78	0.103
0.72	32.84	0.103
0.73	32.91	0.103
0.75	32.98	0.103
0.76	33.04	0.103
0.77	33.11	0.104
0.79	33.17	0.104
0.80	33.24	0.104
0.81	33.31	0.104
0.83	33.37	0.104
0.84	33.44	0.104
0.85	33.51	0.104
0.87	33.57	0.104
0.88	33.64	0.104
0.89	33.70	0.104
0.91	33.77	0.104
0.92	33.84	0.105
0.93	33.90	0.105
0.95	33.97	0.105
0.96	34.03	0.105
0.97	34.10	0.105
0.99	34.17	0.105
1.00	34.23	0.105
1.01	34.30	0.105
1.03	34.37	0.105
1.04	34.43	0.105
1.05	34.50	0.105
1.07	34.56	0.105
1.08	34.63	0.105
1.09	34.70	0.105
1.11	34.76	0.105
1.12	34.83	0.106
1.13	34.90	0.106
1.15	34.96	0.106
1.16	35.03	0.106
1.17	35.10	0.106
1.19	35.16	0.106
1.20	35.23	0.106
1.21	35.30	0.106
1.23	35.36	0.106
1.24	35.43	0.106
1.25	35.50	0.106
1.27	35.56	0.106
1.28	35.63	0.106
1.29	35.69	0.106
1.31	35.76	0.106
1.32	35.83	0.106
1.33	35.89	0.106
1.35	35.96	0.106
1.36	36.03	0.106
1.37	36.09	0.106
1.39	36.16	0.106
1.40	36.23	0.106
1.41	36.29	0.106
1.43	36.36	0.107
1.44	36.43	0.107
1.45	36.49	0.107
1.47	36.56	0.107
1.48	36.63	0.107
1.49	36.69	0.107
1.51	36.76	0.107
1.52	36.83	0.107
1.53	36.89	0.107
1.55	36.96	0.107
1.56	37.03	0.107
1.57	37.09	0.107
1.59	37.16	0.107
1.60	37.23	0.107
1.61	37.29	0.107
1.63	37.36	0.107
1.64	37.43	0.107
1.65	37.49	0.107
1.67	37.56	0.107
1.68	37.63	0.107
1.69	37.69	0.107
1.71	37.76	0.107
1.72	37.83	0.107
1.73	37.89	0.107
1.75	37.96	0.107
1.76	38.03	0.107
1.77	38.09	0.107
1.79	38.16	0.107
1.80	38.23	0.107
1.81	38.29	0.107
1.83	38.36	0.107
1.84	38.43	0.107
1.85	38.49	0.107
1.87	38.56	0.107
1.88	38.63	0.107
1.89	38.69	0.107
1.91	38.76	0.107
1.92	38.83	0.107
1.93	38.89	0.107
1.95	38.96	0.107
1.96	39.03	0.108
1.97	39.09	0.108
1.99	39.16	0.108
2.00	39.23	0.108
2.01	39.29	0.108
2.03	39.36	0.108
2.04	39.43	0.108
2.05	39.49	0.108
2.07	39.56	0.108
2.08	39.63	0.108
2.09	39.69	0.108
2.11	39.76	0.108
2.12	39.82	0.108
2.13	39.89	0.108
2.15	39.96	0.108
2.16	40.02	0.108
2.17	40.09	0.108
2.19	40.16	0.108
2.20	40.23	0.108
2.21	40.29	0.108
2.23	40.36	0.108
2.24	40.43	0.108
2.25	40.49	0.108
2.27	40.56	0.108
2.28	40.63	0.108
2.29	40.69	0.108
2.31	40.76	0.108
2.32	40.83	0.108
2.33	40.89	0.108
2.35	40.96	0.108
2.36	41.03	0.108
2.37	41.09	0.108
2.39	41.16	0.108
2.40	41.23	0.108
2.41	41.29	0.108
2.43	41.36	0.108
2.44	41.42	0.108
2.45	41.49	0.108
2.47	41.56	0.108
2.48	41.62	0.108
2.49	41.69	0.108
2.51	41.76	0.108
2.52	41.83	0.108
2.53	41.89	0.108
2.55	41.96	0.108
2.56	42.03	0.108
2.57	42.09	0.108
2.59	42.16	0.108
2.60	42.23	0.108
2.61	42.29	0.108
2.63	42.36	0.108
2.64	42.43	0.108
2.65	42.49	0.108
2.67	42.56	0.109
2.68	42.63	0.109
2.69	42.69	0.109
2.71	42.76	0.109
2.72	42.83	0.109
2.73	42.89	0.109
2.75	42.96	0.109
2.76	43.03	0.109
2.77	43.09	0.109
2.79	43.16	0.109
2.80	43.23	0.109
2.81	43.29	0.109
2.83	43.36	0.109
2.84	43.43	0.109
2.85	43.49	0.109
2.87	43.56	0.109
2.88	43.63	0.109
2.89	43.69	0.109
2.91	43.76	0.109
2.92	43.83	0.109
2.93	43.89	0.109
2.95	43.96	0.109
2.96	44.03	0.109
2.97	44.09	0.109
2.99	44.16	0.109
3.00	44.23	0.109
3.01	44.29	0.109
3.03	44.36	0.109
3.04	44.43	0.109
3.05	44.49	0.109
3.07	44.56	0.109
3.08	44.63	0.109
3.09	44.69	0.109
3.11	44.76	0.109
3.12	44.83	0.109
3.13	44.89	0.109
3.15	44.96	0.109
3.16	45.03	0.109
3.17	45.09	0.109
3.19	45.16	0.109
3.20	45.23	0.109
3.21	45.29	0.109
3.23	45.36	0.109
3.24	45.43	0.109
3.25	45.49	0.109
3.27	45.56	0.109
3.28	45.63	0.109
3.29	45.69	0.109
3.31	45.76	0.109
3.32	45.83	0.109
3.33	45.89	0.110
3.35	45.96	0.110
3.36	46.03	0.110
3.37	46.09	0.110
3.39	46.16	0.110
3.40	46.23	0.110
3.41	46.29	0.110
3.43	46.36	0.110
3.44	46.43	0.110
3.45	46.49	0.110
3.47	46.56	0.110
3.48	46.63	0.110
3.49	46.69	0.110
3.51	46.76	0.110
3.52	46.83	0.110
3.53	46.89	0.110
3.55	46.96	0.110
3.56	47.03	0.110
3.57	47.09	0.110
3.59	47.16	0.110
3.60	47.23	0.110
3.61	47.29	0.110
3.63	47.36	0.110
3.64	47.43	0.110
3.65	47.49	0.110
3.67	47.56	0.110
3.68	47.63	0.110
3.69	47.69	0.110
3.71	47.76	0.110
3.72	47.83	0.110
3.73	47.89	0.110
3.75	47.96	0.110
3.76	48.03	0.110
3.77	48.09	0.110
3.79	48.16	0.110
3.80	48.23	0.110
3.81	48.29	0.110
3.83	48.36	0.110
3.84	48.43	0.110
3.85	48.49	0.110
3.87	48.56	0.110
3.88	48.63	0.110
3.89	48.69	0.110
3.91	48.76	0.110
3.92	48.83	0.110
3.93	48.89	0.110
3.95	48.96	0.110
3.96	49.03	0.111
3.97	49.10	0.111
3.99	49.16	0.111
4.00	49.23	0.111
4.01	49.29	0.111
4.03	49.36	0.111
4.04	49.43	0.111
4.05	49.49	0.111
4.07	49.56	0.111
4.08	49.63	0.111
4.09	49.70	0.111
4.11	49.76	0.111
4.12	49.83	0.111
4.13	49.90	0.111
4.15	49.96	0.111
4.16	50.03	0.111
4.17	50.10	0.111
4.19	50.16	0.111
4.20	50.23	0.111
4.21	50.30	0.111
4.23	50.36	0.111
4.24	50.43	0.111
4.25	50.50	0.111
4.27	50.56	0.111
4.28	50.63	0.111
4.29	50.70	0.111
4.31	50.76	0.111
4.32	50.83	0.111
4.33	50.90	0.111
4.35	50.96	0.111
4.36	51.03	0.111
4.37	51.10	0.111
4.39	51.16	0.111
4.40	51.23	0.111
4.41	51.30	0.111
4.43	51.36	0.111
4.44	51.43	0.111
4.45	51.50	0.111
4.47	51.56	0.111
4.48	51.63	0.111
4.49	51.70	0.111
4.51	51.76	0.111
4.52	51.83	0.112
4.53	51.90	0.112
4.55	51.96	0.112
4.56	52.03	0.112
4.57	52.10	0.112
4.59	52.16	0.112
4.60	52.23	0.112
4.61	52.30	0.112
4.63	52.36	0.112
4.64	52.43	0.112
4.65	52.49	0.112
4.67	52.56	0.112
4.68	52.63	0.112
4.69	52.70	0.112
4.71	52.76	0.112
4.72	52.83	0.112
4.73	52.90	0.112
4.75	52.96	0.112
4.76	53.03	0.112
4.77	53.10	0.112
4.79	53.16	0.112
4.80	53.23	0.112
4.81	53.30	0.112
4.83	53.36	0.112
4.84	53.43	0.112
4.85	53.50	0.112
4.87	53.56	0.112
4.88	53.63	0.112
4.89	53.70	0.112
4.91	53.76	0.112
4.92	53.83	0.112
4.93	53.90	0.112
4.95	53.96	0.112
4.96	54.03	0.112
4.97	54.10	0.112
4.99	54.16	0.112
5.00	54.23	0.112
5.01	54.30	0.112
5.03	54.36	0.112
5.04	54.43	0.112
5.05	54.50	0.113
5.07	54.56	0.113
5.08	54.63	0.113
5.09	54.70	0.113
5.11	54.76	0.113
5.12	54.83	0.113
5.13	54.90	0.113
5.15	54.96	0.113
5.16	55.03	0.113
5.17	55.10	0.113
5.19	55.16	0.113
5.20	55.23	0.113
5.21	55.30	0.113
5.23	55.36	0.113
5.24	55.43	0.113
5.25	55.50	0.113
5.27	55.56	0.113
5.28	55.63	0.113
5.29	55.70	0.113
5.31	55.76	0.113
5.32	55.83	0.113
5.33	55.90	0.113
5.35	55.96	0.113
5.36	56.03	0.113
5.37	56.10	0.113
5.39	56.16	0.113
5.40	56.23	0.113
5.41	56.30	0.113
5.43	56.36	0.113
5.44	56.43	0.113
5.45	56.50	0.113
5.47	56.56	0.113
5.48	56.63	0.113
5.49	56.70	0.113
5.51	56.76	0.113
5.52	56.83	0.113
5.53	56.90	0.113
5.55	56.96	0.113
5.56	57.03	0.113
5.57	57.10	0.113
5.59	57.16	0.113
5.60	57.23	0.113
5.61	57.30	0.113
5.63	57.36	0.113
5.64	57.43	0.113
5.65	57.50	0.114
5.67	57.56	0.114
5.68	57.63	0.114
5.69	57.70	0.114
5.71	57.76	0.114
5.72	57.83	0.114
5.73	57.90	0.114
5.75	57.96	0.114
5.76	58.03	0.114
5.77	58.10	0.114
5.79	58.17	0.114
5.80	58.23	0.114
5.81	58.30	0.114
5.83	58.37	0.114
5.84	58.43	0.114
5.85	58.50	0.114
5.87	58.57	0.114
5.88	58.63	0.114
5.89	58.70	0.114
5.91	58.76	0.114
5.92	58.83	0.114
5.93	58.90	0.114
5.95	58.96	0.114
5.96	59.03	0.114
5.97	59.10	0.114
5.99	59.17	0.114
6.00	59.23	0.114
6.01	59.30	0.114
6.03	59.36	0.114
6.04	59.43	0.114
6.05	59.50	0.114
6.07	59.57	0.114
6.08	59.63	0.114
6.09	59.70	0.114
6.11	59.77	0.114
6.12	59.83	0.114
6.13	59.90	0.114
6.15	59.97	0.114
6.16	60.03	0.114
6.17	60.10	0.114
6.19	60.16	0.114
6.20	60.23	0.115
6.21	60.30	0.115
6.23	60.36	0.115
6.24	60.43	0.115
6.25	60.50	0.115
6.27	60.57	0.115
6.28	60.63	0.115
6.29	60.70	0.115
6.31	60.77	0.115
6.32	60.83	0.115
6.33	60.90	0.115
6.35	60.96	0.115
6.36	61.03	0.115
6.37	61.10	0.115
6.39	61.16	0.115
6.40	61.23	0.115
6.41	61.30	0.115
6.43	61.37	0.115
6.44	61.43	0.115
6.45	61.50	0.115
6.47	61.57	0.115
6.48	61.63	0.115
6.49	61.70	0.115
6.51	61.76	0.115
6.52	61.83	0.115
6.53	61.90	0.115
6.55	61.96	0.115
6.56	62.03	0.115
6.57	62.10	0.115
6.59	62.17	0.115
6.60	62.23	0.115
6.61	62.30	0.115
6.63	62.37	0.115
6.64	62.43	0.115
6.65	62.50	0.115
6.67	62.56	0.115
6.68	62.63	0.115
6.69	62.70	0.115
6.71	62.76	0.115
6.72	62.83	0.115
6.73	62.90	0.115
6.75	62.96	0.115
6.76	63.03	0.115
6.77	63.10	0.116
6.79	63.16	0.116
6.80	63.23	0.116
6.81	63.30	0.116
6.83	63.36	0.116
6.84	63.43	0.116
6.85	63.50	0.116
6.87	63.56	0.116
6.88	63.63	0.116
6.89	63.70	0.116
6.91	63.76	0.116
6.92	63.83	0.116
6.93	63.90	0.116
6.95	63.96	0.116
6.96	64.03	0.116
6.97	64.10	0.116
6.99	64.16	0.116
7.00	64.23	0.116
7.01	64.30	0.116
7.03	64.36	0.116
7.04	64.43	0.116
7.05	64.50	0.116
7.07	64.56	0.116
7.08	64.63	0.116
7.09	64.70	0.116
7.11	64.77	0.116
7.12	64.83	0.116
7.13	64.90	0.116
7.15	64.96	0.116
7.16	65.03	0.116
7.17	65.10	0.116
7.19	65.16	0.116
7.20	65.23	0.116
7.21	65.30	0.116
7.23	65.36	0.116
7.24	65.43	0.116
7.25	65.50	0.116
7.27	65.56	0.116
7.28	65.63	0.117
7.29	65.70	0.117
7.31	65.77	0.117
7.32	65.83	0.117
7.33	65.90	0.117
7.35	65.97	0.117
7.36	66.03	0.117
7.37	66.10	0.117
7.39	66.17	0.117
7.40	66.23	0.117
7.41	66.30	0.117
7.43	66.37	0.117
7.44	66.43	0.117
7.45	66.50	0.117
7.47	66.57	0.117
7.48	66.63	0.117
7.49	66.70	0.117
7.51	66.77	0.117
7.52	66.83	0.117
7.53	66.90	0.117
7.55	66.97	0.117
7.56	67.03	0.117
7.57	67.10	0.117
7.59	67.17	0.117
7.60	67.23	0.117
7.61	67.30	0.117
7.63	67.37	0.117
7.64	67.43	0.117
7.65	67.50	0.117
7.67	67.57	0.117
7.68	67.63	0.117
7.69	67.70	0.117
7.71	67.77	0.117
7.72	67.83	0.117
7.73	67.90	0.117
7.75	67.97	0.117
7.76	68.03	0.117
7.77	68.10	0.117
7.79	68.17	0.118
7.80	68.23	0.118
7.81	68.30	0.118
7.83	68.37	0.118
7.84	68.43	0.118
7.85	68.50	0.118
7.87	68.57	0.118
7.88	68.63	0.118
7.89	68.70	0.118
7.91	68.77	0.118
7.92	68.83	0.118
7.93	68.90	0.118
7.95	68.97	0.118
7.96	69.03	0.118
7.97	69.10	0.118
7.99	69.17	0.118
8.00	69.23	0.118
8.01	69.30	0.118
8.03	69.37	0.118
8.04	69.43	0.118
8.05	69.50	0.118
8.07	69.57	0.118
8.08	69.63	0.118
8.09	69.70	0.118
8.11	69.77	0.118
8.12	69.83	0.118
8.13	69.90	0.118
8.15	69.97	0.118
8.16	70.03	0.118
8.17	70.10	0.118
8.19	70.17	0.118
8.20	70.23	0.118
8.21	70.30	0.118
8.23	70.37	0.118
8.24	70.43	0.118
8.25	70.50	0.118
8.27	70.57	0.118
8.28	70.63	0.118
8.29	70.70	0.119
8.31	70.77	0.119
8.32	70.83	0.119
8.33	70.90	0.119
8.35	70.97	0.119
8.36	71.04	0.119
8.37	71.10	0.119
8.39	71.17	0.119
8.40	71.24	0.119
8.41	71.30	0.119
8.43	71.37	0.119
8.44	71.44	0.119
8.45	71.50	0.119
8.47	71.57	0.119
8.48	71.64	0.119
8.49	71.70	0.119
8.51	71.77	0.119
8.52	71.84	0.119
8.53	71.90	0.119
8.55	71.97	0.119
8.56	72.03	0.119
8.57	72.10	0.119
8.59	72.17	0.119
8.60	72.23	0.119
8.61	72.30	0.119
8.63	72.37	0.119
8.64	72.43	0.119
8.65	72.50	0.119
8.67	72.57	0.119
8.68	72.63	0.119
8.69	72.70	0.119
8.71	72.77	0.119
8.72	72.84	0.119
8.73	72.90	0.119
8.75	72.97	0.119
8.76	73.03	0.119
8.77	73.10	0.119
8.79	73.17	0.119
8.80	73.23	0.120
8.81	73.30	0.120
8.83	73.37	0.120
8.84	73.43	0.120
8.85	73.50	0.120
8.87	73.57	0.120
8.88	73.64	0.120
8.89	73.70	0.120
8.91	73.77	0.120
8.92	73.84	0.120
8.93	73.90	0.120
8.95	73.97	0.120
8.96	74.04	0.120
8.97	74.10	0.120
8.99	74.17	0.120
9.00	74.24	0.120
9.01	74.30	0.120
9.03	74.37	0.120
9.04	74.44	0.120
9.05	74.50	0.120
9.07	74.57	0.120
9.08	74.64	0.120
9.09	74.70	0.120
9.11	74.77	0.120
9.12	74.84	0.120
9.13	74.90	0.120
9.15	74.97	0.120
9.16	75.04	0.120
9.17	75.10	0.120
9.19	75.17	0.120
9.20	75.24	0.120
9.21	75.30	0.120
9.23	75.37	0.120
9.24	75.44	0.120
9.25	75.50	0.121
9.27	75.57	0.121
9.28	75.64	0.121
9.29	75.70	0.121
9.31	75.77	0.121
9.32	75.84	0.121
9.33	75.90	0.121
9.35	75.97	0.121
9.36	76.04	0.121
9.37	76.10	0.121
9.39	76.17	0.121
9.40	76.24	0.121
9.41	76.30	0.121
9.43	76.37	0.121
9.44	76.44	0.121
9.45	76.50	0.121
9.47	76.57	0.121
9.48	76.64	0.121
9.49	76.70	0.121
9.51	76.77	0.121
9.52	76.84	0.121
9.53	76.90	0.121
9.55	76.97	0.121
9.56	77.04	0.121
9.57	77.10	0.121
9.59	77.17	0.121
9.60	77.24	0.121
9.61	77.30	0.121
9.63	77.37	0.121
9.64	77.44	0.121
9.65	77.50	0.121
9.67	77.57	0.121
9.68	77.64	0.121
9.69	77.70	0.121
9.71	77.77	0.121
9.72	77.84	0.121
9.73	77.90	0.121
9.75	77.97	0.121
9.76	78.04	0.122
9.77	78.10	0.122
9.79	78.17	0.122
9.80	78.24	0.122
9.81	78.30	0.122
9.83	78.37	0.122
9.84	78.44	0.122
9.85	78.50	0.122
9.87	78.57	0.122
9.88	78.64	0.122
9.89	78.70	0.122
9.91	78.77	0.122
9.92	78.84	0.122
9.93	78.90	0.122
9.95	78.97	0.122
9.96	79.04	0.122
9.97	79.10	0.122
9.99	79.17	0.122
10.00	79.24	0.122
10.01	79.30	0.122
10.03	79.37	0.122
10.04	79.44	0.122
10.05	79.50	0.122
10.07	79.57	0.122
10.08	79.64	0.122
10.09	79.70	0.122
10.11	79.77	0.122
10.12	79.84	0.122
10.13	79.90	0.122
10.15	79.97	0.122
10.16	80.04	0.122
10.17	80.10	0.122
10.19	80.17	0.122
10.20	80.24	0.122
10.21	80.30	0.122
10.23	80.37	0.123
10.24	80.44	0.123
10.25	80.50	0.123
10.27	80.57	0.123
10.28	80.64	0.123
10.29	80.70	0.123
10.31	80.77	0.123
10.32	80.84	0.123
10.33	80.90	0.123
10.35	80.97	0.123
10.36	81.04	0.123
10.37	81.10	0.123
10.39	81.17	0.123
10.40	81.24	0.123
10.41	81.30	0.123
10.43	81.37	0.123
10.44	81.44	0.123
10.45	81.50	0.123
10.47	81.57	0.123
10.48	81.64	0.123
10.49	81.70	0.123
10.51	81.77	0.123
10.52	81.84	0.123
10.53	81.90	0.123
10.55	81.97	0.123
10.56	82.04	0.123
10.57	82.10	0.123
10.59	82.17	0.123
10.60	82.24	0.123
10.61	82.30	0.123
10.63	82.37	0.123
10.64	82.44	0.123
10.65	82.50	0.123
10.67	82.57	0.123
10.68	82.64	0.123
10.69	82.70	0.123
10.71	82.77	0.124
10.72	82.84	0.124
10.73	82.90	0.124
10.75	82.97	0.124
10.76	83.04	0.124
10.77	83.10	0.124
10.79	83.17	0.124
10.80	83.24	0.124
10.81	83.30	0.124
10.83	83.37	0.124
10.84	83.44	0.124
10.85	83.50	0.124
10.87	83.57	0.124
10.88	83.64	0.124
10.89	83.70	0.124
10.91	83.77	0.124
10.92	83.84	0.124
10.93	83.90	0.124
10.95	83.97	0.124
10.96	84.04	0.124
10.97	84.10	0.124
10.99	84.17	0.124
11.00	84.24	0.124
11.01	84.31	0.124
11.03	84.37	0.124
11.04	84.44	0.124
11.05	84.51	0.124
11.07	84.57	0.124
11.08	84.64	0.124
11.09	84.70	0.124
11.11	84.77	0.124
11.12	84.84	0.124
11.13	84.91	0.125
11.15	84.97	0.125
11.16	85.04	0.125
11.17	85.10	0.125
11.19	85.17	0.125
11.20	85.24	0.125
11.21	85.30	0.125
11.23	85.37	0.125
11.24	85.44	0.125
11.25	85.50	0.125
11.27	85.57	0.125
11.28	85.64	0.125
11.29	85.71	0.125
11.31	85.77	0.125
11.32	85.84	0.125
11.33	85.90	0.125
11.35	85.97	0.125
11.36	86.04	0.125
11.37	86.10	0.125
11.39	86.17	0.125
11.40	86.24	0.125
11.41	86.30	0.125
11.43	86.37	0.125
11.44	86.44	0.125
11.45	86.51	0.125
11.47	86.57	0.125
11.48	86.64	0.125
11.49	86.71	0.125
11.51	86.77	0.125
11.52	86.84	0.125
11.53	86.91	0.125
11.55	86.97	0.125
11.56	87.04	0.125
11.57	87.11	0.125
11.59	87.17	0.125
11.60	87.24	0.125
11.61	87.31	0.126
11.63	87.37	0.126
11.64	87.44	0.126
11.65	87.51	0.126
11.67	87.57	0.126
11.68	87.64	0.126
11.69	87.71	0.126
11.71	87.77	0.126
11.72	87.84	0.126
11.73	87.91	0.126
11.75	87.97	0.126
11.76	88.04	0.126
11.77	88.11	0.126
11.79	88.17	0.126
11.80	88.24	0.126
11.81	88.30	0.126
11.83	88.37	0.126
11.84	88.44	0.126
11.85	88.50	0.126
11.87	88.57	0.126
11.88	88.64	0.126
11.89	88.70	0.126
11.91	88.77	0.126
11.92	88.84	0.126
11.93	88.91	0.126
11.95	88.97	0.126
11.96	89.04	0.126
11.97	89.10	0.126
11.99	89.17	0.126
12.00	89.24	0.126
12.01	89.30	0.126
12.03	89.37	0.126
12.04	89.44	0.126
12.05	89.50	0.127
12.07	89.57	0.127
12.08	89.64	0.127
12.09	89.71	0.127
12.11	89.77	0.127
12.12	89.84	0.127
12.13	89.90	0.127
12.15	89.97	0.127
12.16	90.04	0.127
12.17	90.11	0.127
12.19	90.17	0.127
12.20	90.24	0.127
12.21	90.31	0.127
12.23	90.37	0.127
12.24	90.44	0.127
12.25	90.51	0.127
12.27	90.57	0.127
12.28	90.64	0.127
12.29	90.71	0.127
12.31	90.77	0.127
12.32	90.84	0.127
12.33	90.90	0.127
12.35	90.97	0.127
12.36	91.04	0.127
12.37	91.11	0.127
12.39	91.17	0.127
12.40	91.24	0.128
12.41	91.30	0.128
12.43	91.37	0.128
12.44	91.44	0.128
12.45	91.51	0.128
12.47	91.57	0.128
12.48	91.64	0.128
12.49	91.71	0.128
12.51	91.77	0.128
12.52	91.84	0.128
12.53	91.90	0.128
12.55	91.97	0.128
12.56	92.04	0.128
12.57	92.11	0.128
12.59	92.17	0.128
12.60	92.24	0.128
12.61	92.31	0.128
12.63	92.37	0.128
12.64	92.44	0.128
12.65	92.50	0.128
12.67	92.57	0.128
12.68	92.64	0.128
12.69	92.70	0.128
12.71	92.77	0.128
12.72	92.84	0.129
12.73	92.90	0.129
12.75	92.97	0.129
12.76	93.04	0.129
12.77	93.11	0.129
12.79	93.17	0.129
12.80	93.24	0.129
12.81	93.31	0.129
12.83	93.37	0.129
12.84	93.44	0.129
12.85	93.51	0.129
12.87	93.57	0.129
12.88	93.64	0.129
12.89	93.71	0.129
12.91	93.77	0.129
12.92	93.84	0.129
12.93	93.91	0.129
12.95	93.97	0.129
12.96	94.04	0.129
12.97	94.11	0.129
12.99	94.17	0.129
13.00	94.24	0.130
13.01	94.31	0.130
13.03	94.37	0.130
13.04	94.44	0.130
13.05	94.51	0.130
13.07	94.57	0.130
13.08	94.64	0.130
13.09	94.70	0.130
13.11	94.77	0.130
13.12	94.84	0.130
13.13	94.91	0.130
13.15	94.97	0.130
13.16	95.04	0.130
13.17	95.10	0.130
13.19	95.17	0.130
13.20	95.24	0.130
13.21	95.31	0.130
13.23	95.37	0.130
13.24	95.44	0.130
13.25	95.51	0.130
13.27	95.57	0.130
13.28	95.64	0.130
13.29	95.71	0.130
13.31	95.77	0.131
13.32	95.84	0.131
13.33	95.90	0.131
13.35	95.97	0.131
13.36	96.04	0.131
13.37	96.10	0.131
13.39	96.17	0.131
13.40	96.24	0.131
13.41	96.30	0.131
13.43	96.37	0.131
13.44	96.44	0.131
13.45	96.51	0.131
13.47	96.57	0.131
13.48	96.64	0.131
13.49	96.70	0.131
13.51	96.77	0.131
13.52	96.84	0.131
13.53	96.90	0.131
13.55	96.97	0.131
13.56	97.04	0.131
13.57	97.11	0.132
13.59	97.17	0.132
13.60	97.24	0.132
13.61	97.30	0.132
13.63	97.37	0.132
13.64	97.44	0.132
13.65	97.50	0.132
13.67	97.57	0.132
13.68	97.64	0.132
13.69	97.71	0.132
13.71	97.77	0.132
13.72	97.84	0.132
13.73	97.91	0.132
13.75	97.97	0.132
13.76	98.04	0.132
13.77	98.11	0.132
13.79	98.17	0.132
13.80	98.24	0.133
13.81	98.30	0.133
13.83	98.37	0.133
13.84	98.44	0.133
13.85	98.51	0.133
13.87	98.57	0.133
13.88	98.64	0.133
13.89	98.71	0.133
13.91	98.77	0.133
13.92	98.84	0.133
13.93	98.90	0.133
13.95	98.97	0.133
13.96	99.04	0.133
13.97	99.10	0.133
13.99	99.17	0.133
14.00	99.24	0.134
14.01	99.30	0.134
14.03	99.37	0.134
14.04	99.44	0.134
14.05	99.51	0.134
14.07	99.57	0.134
14.08	99.64	0.134
14.09	99.71	0.134
14.11	99.77	0.134
14.12	99.84	0.134
14.13	99.90	0.134
14.15	99.97	0.134
14.16	100.04	0.134
14.17	100.10	0.134
14.19	100.17	0.134
14.20	100.24	0.135
14.21	100.30	0.135
14.23	100.37	0.135
14.24	100.44	0.135
14.25	100.50	0.135
14.27	100.57	0.135
14.28	100.64	0.135
14.29	100.70	0.135
14.31	100.77	0.135
14.32	100.84	0.135
14.33	100.90	0.135
14.35	100.97	0.135
14.36	101.04	0.136
14.37	101.10	0.136
14.39	101.17	0.136
14.40	101.24	0.136
14.41	101.30	0.136
14.43	101.37	0.136
14.44	101.44	0.136
14.45	101.50	0.136
14.47	101.57	0.136
14.48	101.64	0.136
14.49	101.70	0.136
14.51	101.77	0.137
14.52	101.84	0.137
14.53	101.90	0.137
14.55	101.97	0.137
14.56	102.04	0.137
14.57	102.10	0.137
14.59	102.17	0.137
14.60	102.24	0.137
14.61	102.30	0.137
14.63	102.37	0.137
14.64	102.44	0.138
14.65	102.50	0.138
14.67	102.57	0.138
14.68	102.63	0.138
14.69	102.70	0.138
14.71	102.77	0.138
14.72	102.84	0.138
14.73	102.90	0.138
14.75	102.97	0.138
14.76	103.03	0.138
14.77	103.10	0.138
14.79	103.17	0.139
14.80	103.23	0.139
14.81	103.30	0.139
14.83	103.37	0.139
14.84	103.43	0.139
14.85	103.50	0.139
14.87	103.57	0.139
14.88	103.63	0.139
14.89	103.70	0.139
14.91	103.77	0.140
14.92	103.84	0.140
14.93	103.90	0.140
14.95	103.97	0.140
14.96	104.03	0.140
14.97	104.10	0.140
14.99	104.17	0.140
15.00	104.23	0.141
15.01	104.30	0.141
15.03	104.37	0.141
15.04	104.43	0.141
15.05	104.50	0.141
15.07	104.57	0.141
15.08	104.63	0.142
15.09	104.70	0.142
15.11	104.77	0.142
15.12	104.83	0.142
15.13	104.90	0.142
15.15	104.97	0.142
15.16	105.03	0.142
15.17	105.10	0.143
15.19	105.17	0.143
15.20	105.23	0.143
15.21	105.30	0.143
15.23	105.37	0.143
15.24	105.43	0.143
15.25	105.50	0.144
15.27	105.57	0.144
15.28	105.63	0.144
15.29	105.70	0.144
15.31	105.76	0.145
15.32	105.83	0.145
15.33	105.90	0.145
15.35	105.96	0.145
15.36	106.03	0.145
15.37	106.10	0.146
15.39	106.16	0.146
15.40	106.23	0.146
15.41	106.30	0.146
15.43	106.36	0.147
15.44	106.43	0.147
15.45	106.50	0.147
15.47	106.56	0.147
15.48	106.63	0.147
15.49	106.70	0.147
15.51	106.76	0.148
15.52	106.83	0.148
15.53	106.90	0.148
15.55	106.96	0.148
15.56	107.03	0.149
15.57	107.10	0.149
15.59	107.16	0.149
15.60	107.23	0.150
15.61	107.29	0.150
15.63	107.36	0.150
15.64	107.43	0.150
15.65	107.49	0.151
15.67	107.56	0.151
15.68	107.63	0.151
15.69	107.69	0.152
15.71	107.76	0.152
15.72	107.83	0.152
15.73	107.89	0.153
15.75	107.96	0.153
15.76	108.02	0.153
15.77	108.09	0.154
15.79	108.16	0.155
15.80	108.22	0.155
15.81	108.29	0.155
15.83	108.36	0.155
15.84	108.42	0.156
15.85	108.49	0.156
15.87	108.56	0.157
15.88	108.62	0.157
15.89	108.69	0.158
15.91	108.76	0.158
15.92	108.82	0.158
15.93	108.89	0.159
15.95	108.95	0.160
15.96	109.02	0.160
15.97	109.09	0.160
15.99	109.15	0.161
16.00	109.22	0.161
16.01	109.29	0.161
16.03	109.35	0.162
16.04	109.42	0.162
16.05	109.49	0.163
16.07	109.55	0.163
16.08	109.62	0.164
16.09	109.68	0.165
16.11	109.75	0.165
16.12	109.82	0.166
16.13	109.88	0.166
16.15	109.95	0.167
16.16	110.01	0.168
16.17	110.08	0.168
16.19	110.15	0.169
16.20	110.21	0.169
16.21	110.28	0.170
16.23	110.35	0.171
16.24	110.41	0.171
16.25	110.48	0.172
16.27	110.54	0.173
16.28	110.61	0.173
16.29	110.68	0.174
16.31	110.74	0.175
16.32	110.81	0.176
16.33	110.87	0.176
16.35	110.94	0.177
16.36	111.01	0.178
16.37	111.07	0.179
16.39	111.14	0.179
16.40	111.21	0.180
16.41	111.27	0.181
16.43	111.34	0.182
16.44	111.40	0.183
16.45	111.47	0.183
16.47	111.54	0.184
16.48	111.60	0.185
16.49	111.67	0.186
16.51	111.73	0.187
16.52	111.80	0.188
16.53	111.86	0.189
16.55	111.93	0.190
16.56	112.00	0.191
16.57	112.06	0.192
16.59	112.13	0.193
16.60	112.19	0.194
16.61	112.26	0.195
16.63	112.33	0.196
16.64	112.39	0.197
16.65	112.46	0.199
16.67	112.52	0.200
16.68	112.59	0.201
16.69	112.65	0.202
16.71	112.72	0.203
16.72	112.79	0.204
16.73	112.85	0.206
16.75	112.92	0.207
16.76	112.98	0.208
16.77	113.05	0.210
16.79	113.11	0.211
16.80	113.18	0.213
16.81	113.25	0.214
16.83	113.31	0.216
16.84	113.38	0.217
16.85	113.44	0.218
16.87	113.51	0.220
16.88	113.57	0.221
16.89	113.64	0.223
16.91	113.70	0.225
16.92	113.77	0.226
16.93	113.83	0.228
16.95	113.90	0.229
16.96	113.96	0.231
16.97	114.03	0.233
16.99	114.09	0.235
17.00	114.16	0.237
17.01	114.23	0.239
17.03	114.29	0.240
17.04	114.35	0.242
17.05	114.42	0.244
17.07	114.49	0.246
17.08	114.55	0.249
17.09	114.62	0.250
17.11	114.68	0.252
17.12	114.75	0.255
17.13	114.81	0.256
17.15	114.88	0.259
17.16	114.94	0.261
17.17	115.01	0.263
17.19	115.07	0.266
17.20	115.13	0.268
17.21	115.20	0.270
17.23	115.26	0.273
17.24	115.33	0.275
17.25	115.39	0.278
17.27	115.46	0.280
17.28	115.52	0.282
17.29	115.59	0.285
17.31	115.65	0.288
17.32	115.71	0.290
17.33	115.78	0.293
17.35	115.84	0.296
17.36	115.91	0.298
17.37	115.97	0.301
17.39	116.04	0.304
17.40	116.10	0.307
17.41	116.17	0.310
17.43	116.23	0.313
17.44	116.29	0.316
17.45	116.36	0.319
17.47	116.42	0.322
17.48	116.49	0.326
17.49	116.55	0.329
17.51	116.61	0.332
17.52	116.68	0.336
17.53	116.74	0.339
17.55	116.81	0.342
17.56	116.87	0.345
17.57	116.93	0.349
17.59	117.00	0.352
17.60	117.06	0.356
17.61	117.12	0.360
17.63	117.19	0.363
17.64	117.25	0.367
17.65	117.31	0.370
17.67	117.38	0.374
17.68	117.44	0.378
17.69	117.51	0.382
17.71	117.57	0.386
17.72	117.63	0.390
17.73	117.70	0.394
17.75	117.76	0.398
17.76	117.82	0.402
17.77	117.89	0.405
17.79	117.95	0.409
17.80	118.01	0.414
17.81	118.07	0.417
17.83	118.14	0.422
17.84	118.20	0.426
17.85	118.27	0.430
17.87	118.33	0.434
17.88	118.39	0.439
17.89	118.45	0.444
17.91	118.52	0.449
17.92	118.58	0.453
17.93	118.64	0.458
17.95	118.70
17.96	118.77
17.97	118.83
17.99	118.89
18.00
18.00