File: Data/2025_09_09_DSC_Benzoic_Acid_CHM343.csv
Filename,2025_09_09_DSC_Benzoic_Acid_CHM343
Instrument name,DSC2A-00468 (192.168.1.100)
Operator,Zoom ASU Sync
rundate,9/9/2025
Sample name,2025_09_09_DSC_Benzoic_Acid_CHM343
proceduresegments,Data Off ; Equilibrate 30.00 °C; Data On ; Ramp 10.00 °C/min to 150.00 °C; Data Off ; Isothermal 1.0 min; Data On ; Ramp 10.00 °C/min to 30.00 °C; Data Off ; Isothermal 1.0 min; Data On ; Ramp 10.00 °C/min to 150.00 °C; Data Off ; Isothermal 1.0 min; Data On ; Ramp 10.00 °C/min to 30.00 °C
[File Parameters]
Run date,9/9/2025 7:23:04 PM
Trios version,5.1.1.46572
Original File Name,
Current File Name,D:\DSC2500\CHM343\2025_09_09_DSC_Benzoic_Acid_CHM343.tri
[Procedure]
Procedure Name,Empty_n60C_250C_10Cmin_x3
Sample Name,2025_09_09_DSC_Benzoic_Acid_CHM343
Sample Mass,14.16 mg
Reference Sample Mass,0 mg
Pan Mass,56.79 mg
Pan Number,4
Reference Pan Mass,56.82 mg
Reference Pan Number,10
Pan Type,Tzero Aluminum Hermetic
Comments,DSC_Samples_Y1_Tray_CHM343_Sept2025 google sheet.
Project Name,CHM343
Operator,Zoom ASU Sync
Test,Custom
Unload Max Temperature,30
Unload Min Temperature,30
Load Max Temperature,30
Load Min Temperature,30
Stop on Gas Flow Error,Yes
[Signal List]
Signal #1,Time (min)
Signal #2,Temperature (°C)
Signal #3,Heat Flow (mW)
Signal #4,Delta T (µV)
Signal #5,Delta Tzero (µV)
Signal #6,Tzero Temperature (°C)
Signal #7,Cell Purge (mL/min)
Signal #8,Heater Temp (°C)
Signal #9,Power Delivered (W)
Signal #10,Reference Junction Temperature (°C)
Signal #11,Flange Temperature (°C)
Signal #12,Heat Flow Phase (rad)
Signal #13,Total Heat Capacity (J/°C)
Signal #14,Heat Capacity (J/°C)
[Configuration]
Company Name,ASU
Instrument Name,DSC2A-00468
Instrument Type,DSC2500
Serial Number,DSC2A-00468
IP,192.168.1.100
Location of Instrument,MRRC
DisplayType,Unknown
Sample Interval ,0.1 s/pt
Selected Heat Flow,T4P
Exotherm Direction,Down
Cell Serial,DRC2-00792
Lid Type,Standard
Cooler,RCS 90
Leave Cooler on at End of Sequence,On
Gas 2,Nitrogen
Gas Selected,Channel 1
Flow Rate,50 mL/min
Secondary Purge,On
Licensed Heat Flow,Heat Flow T4P
Modulation Licensed,Yes
[Versions]
Common IDD Version,1
Cortex Version,VER 2.10.2.31
Driver,5.0.0.6
GDM Version,1.0.3.3
TouchscreenVersion,1.0.0.16145
FEP Version,1.2.1.21
FEP Bootloader,2.0.0.5
AutoSampler Version,2.1.1.26
Auto Sampler Bootloader,2.0.0.5
FCM Version,1.1.0.3
FCM Bootloader,2.0.0.5
[Experiment Logs]
Experiment Log Entry # 1,Data On set to 0
Experiment Log Entry # 3,Equilibrate Segment 30 (C) Started
Experiment Log Entry # 5,Air Cool is off.
Experiment Log Entry # 7,Data On set to 1
Experiment Log Entry # 9,Ramp Segment 10 C/min to 150 Started
Experiment Log Entry # 11,Data On set to 0
Experiment Log Entry # 13,Isothermal Segment 1 min started
Experiment Log Entry # 15,Data On set to 1
Experiment Log Entry # 17,Ramp Segment 10 C/min to 30 Started
Experiment Log Entry # 19,Data On set to 0
Experiment Log Entry # 21,Isothermal Segment 1 min started
Experiment Log Entry # 23,Data On set to 1
Experiment Log Entry # 25,Ramp Segment 10 C/min to 150 Started
Experiment Log Entry # 27,Data On set to 0
Experiment Log Entry # 29,Isothermal Segment 1 min started
Experiment Log Entry # 31,Data On set to 1
Experiment Log Entry # 33,Ramp Segment 10 C/min to 30 Started
[Method Log]
Method Log Entry # 1,Data Off
Method Log Entry # 2,Equilibrate 30 °C
Method Log Entry # 3,Data On
Method Log Entry # 4,(Ramp 32138) Ramp 10 °C/minute to 150 °C
Method Log Entry # 5,Data Off
Method Log Entry # 6,Isothermal 1 minutes
Method Log Entry # 7,Data On
Method Log Entry # 8,(Ramp 32142) Ramp 10 °C/minute to 30 °C
Method Log Entry # 9,Data Off
Method Log Entry # 10,Isothermal 1 minutes
Method Log Entry # 11,Data On
Method Log Entry # 12,(Ramp 32146) Ramp 10 °C/minute to 150 °C
Method Log Entry # 13,Data Off
Method Log Entry # 14,Isothermal 1 minutes
Method Log Entry # 15,Data On
Method Log Entry # 16,(Ramp 32150) Ramp 10 °C/minute to 30 °C
Cell Serial,DRC2-00792
[T1 Calibration]
Slope,-0.008529666
Offset,9.636258
Initial Temperature,98.23
GUID,f8bfdadc-4977-4fdf-ba6d-0ba9134940c3
[TZero Calibration]
Date Applied,11/29/2022 4:06:13 PM
Description,From -89.059 °C to 396.009 °C at 20.000°C/min
Gas Type,Nitrogen
Pan Type,None
Source Files 1,C:\Users\yargerlab\Desktop\DSC Data\General\TZero_calibration_11_29_22_2nd(2).tri
Source Files 2,C:\Users\yargerlab\Desktop\DSC Data\General\TZero_calibration_11_29_22_2nd(3).tri
Delta T Offset,13.05235
Delta T Slope,-0.007271007
Delta T0 Offset,-13.69128
Delta T0 Slope,0.06063341
[Temperature Calibration]
Date Applied,11/29/2022 7:12:28 PM
Description,From 106.590 °C to 186.590 °C at 10.000°C/min
Gas Type,Nitrogen
Pan Type,Tzero Aluminum Hermetic
Source Files 1,C:\Users\yargerlab\Desktop\DSC Data\General\Indium(6).tri
Measured 1,157.391
Known 1,156.598
[Cell Constant Calibration]
Date Applied,11/29/2022 7:12:29 PM
Description,From 106.590 °C to 186.590 °C at 10.000°C/min
Gas Type,Nitrogen
Pan Type,Tzero Aluminum Hermetic
Source Files 1,C:\Users\yargerlab\Desktop\DSC Data\General\Indium(6).tri
T4P KCell,1.006051
Onset Slope,63.26126 mW/°C
[Direct Cp Calibration]
Date Applied,11/30/2022 11:04:51 AM
Description,From -79.983 °C to 298.409 °C at 10.000°C/min
Gas Type,Nitrogen
Pan Type,Tzero Aluminum Hermetic
Source Files 1,C:\Users\yargerlab\Desktop\DSC Data\General\Sapphire_Heat_Capacity_11_30_22.tri
[Rev Cp Calibration]
Date Applied,11/30/2022 1:58:51 PM
Description,From -79.996 °C to 292.812 °C at 3.000°C/min
Gas Type,Nitrogen
Pan Type,Tzero Aluminum Hermetic
Source Files 1,C:\Users\yargerlab\Desktop\DSC Data\General\Sapphire_MDSC_Calibration_11_30_22.tri
[step]
Ramp 10.00 °C/min to 150.00 °C
Time,Temperature,Heat Flow (Normalized)
min,°C,W/g
0.00,29.90,0.019
0.01,29.91,0.018
0.02,29.92,0.017
0.03,29.93,0.016
0.03,29.94,0.015
0.04,29.95,0.016
0.05,29.96,0.017
0.06,29.97,0.019
0.07,29.99,0.024
0.08,30.01,0.030
0.08,30.03,0.037
0.09,30.05,0.044
0.10,30.08,0.053
0.11,30.11,0.063
0.12,30.15,0.071
0.13,30.19,0.081
0.13,30.23,0.090
0.14,30.28,0.099
0.15,30.33,0.107
0.16,30.39,0.114
0.17,30.44,0.121
0.18,30.50,0.127
0.18,30.56,0.133
0.19,30.62,0.138
0.20,30.68,0.143
0.21,30.75,0.148
0.22,30.82,0.152
0.23,30.88,0.156
0.23,30.95,0.160
0.24,31.02,0.163
0.25,31.09,0.167
0.26,31.16,0.170
0.27,31.24,0.173
0.28,31.31,0.176
0.28,31.39,0.178
0.29,31.46,0.182
0.30,31.53,0.183
0.31,31.61,0.186
0.32,31.69,0.188
0.33,31.76,0.189
0.33,31.84,0.191
0.34,31.92,0.193
0.35,32.00,0.194
0.36,32.08,0.196
0.37,32.16,0.197
0.38,32.24,0.199
0.38,32.31,0.199
0.39,32.40,0.200
0.40,32.48,0.201
0.41,32.56,0.203
0.42,32.64,0.203
0.43,32.72,0.204
0.43,32.80,0.204
0.44,32.88,0.205
0.45,32.96,0.206
0.46,33.04,0.206
0.47,33.13,0.207
0.48,33.21,0.207
0.48,33.29,0.208
0.49,33.37,0.208
0.50,33.45,0.208
0.51,33.54,0.209
0.52,33.62,0.210
0.53,33.70,0.210
0.53,33.78,0.210
0.54,33.86,0.210
0.55,33.95,0.210
0.56,34.03,0.211
0.57,34.11,0.211
0.58,34.20,0.211
0.58,34.28,0.211
0.59,34.36,0.212
0.60,34.44,0.212
0.61,34.53,0.212
0.62,34.61,0.212
0.63,34.69,0.212
0.63,34.78,0.212
0.64,34.86,0.212
0.65,34.94,0.212
0.66,35.02,0.212
0.67,35.11,0.212
0.68,35.19,0.213
0.68,35.27,0.213
0.69,35.36,0.213
0.70,35.44,0.213
0.71,35.52,0.213
0.72,35.61,0.213
0.73,35.69,0.213
0.73,35.77,0.213
0.74,35.85,0.213
0.75,35.94,0.213
0.76,36.02,0.213
0.77,36.10,0.213
0.78,36.19,0.213
0.78,36.27,0.213
0.79,36.35,0.213
0.80,36.44,0.214
0.81,36.52,0.214
0.82,36.60,0.214
0.83,36.69,0.214
0.83,36.77,0.214
0.84,36.85,0.214
0.85,36.94,0.214
0.86,37.02,0.214
0.87,37.10,0.214
0.88,37.18,0.214
0.88,37.27,0.214
0.89,37.35,0.214
0.90,37.43,0.214
0.91,37.52,0.214
0.92,37.60,0.214
0.93,37.68,0.214
0.93,37.77,0.215
0.94,37.85,0.215
0.95,37.93,0.215
0.96,38.02,0.215
0.97,38.10,0.215
0.98,38.18,0.215
0.98,38.27,0.215
0.99,38.35,0.215
1.00,38.43,0.215
1.01,38.52,0.215
1.02,38.60,0.215
1.03,38.68,0.215
1.03,38.77,0.215
1.04,38.85,0.215
1.05,38.93,0.215
1.06,39.02,0.215
1.07,39.10,0.215
1.08,39.18,0.215
1.08,39.27,0.216
1.09,39.35,0.216
1.10,39.43,0.216
1.11,39.51,0.216
1.12,39.60,0.216
1.13,39.68,0.216
1.13,39.77,0.216
1.14,39.85,0.216
1.15,39.93,0.216
1.16,40.02,0.216
1.17,40.10,0.216
1.18,40.18,0.216
1.18,40.26,0.216
1.19,40.35,0.216
1.20,40.43,0.216
1.21,40.51,0.216
1.22,40.60,0.216
1.23,40.68,0.216
1.23,40.76,0.216
1.24,40.85,0.216
1.25,40.93,0.217
1.26,41.01,0.217
1.27,41.10,0.217
1.28,41.18,0.217
1.28,41.26,0.217
1.29,41.35,0.217
1.30,41.43,0.217
1.31,41.51,0.217
1.32,41.60,0.217
1.33,41.68,0.217
1.33,41.76,0.217
1.34,41.85,0.217
1.35,41.93,0.217
1.36,42.01,0.217
1.37,42.10,0.217
1.38,42.18,0.217
1.38,42.26,0.217
1.39,42.35,0.217
1.40,42.43,0.217
1.41,42.51,0.218
1.42,42.60,0.218
1.43,42.68,0.218
1.43,42.76,0.218
1.44,42.85,0.218
1.45,42.93,0.218
1.46,43.01,0.218
1.47,43.10,0.218
1.48,43.18,0.218
1.48,43.26,0.218
1.49,43.35,0.218
1.50,43.43,0.218
1.51,43.51,0.218
1.52,43.60,0.218
1.53,43.68,0.218
1.53,43.76,0.218
1.54,43.85,0.218
1.55,43.93,0.218
1.56,44.01,0.219
1.57,44.10,0.219
1.58,44.18,0.219
1.58,44.26,0.219
1.59,44.35,0.219
1.60,44.43,0.219
1.61,44.51,0.219
1.62,44.60,0.219
1.63,44.68,0.219
1.63,44.76,0.219
1.64,44.85,0.219
1.65,44.93,0.219
1.66,45.01,0.219
1.67,45.10,0.219
1.68,45.18,0.219
1.68,45.26,0.219
1.69,45.35,0.219
1.70,45.43,0.219
1.71,45.51,0.220
1.72,45.60,0.220
1.73,45.68,0.220
1.73,45.76,0.220
1.74,45.85,0.220
1.75,45.93,0.220
1.76,46.01,0.220
1.77,46.10,0.220
1.78,46.18,0.220
1.78,46.26,0.220
1.79,46.35,0.220
1.80,46.43,0.220
1.81,46.51,0.220
1.82,46.60,0.220
1.83,46.68,0.220
1.83,46.76,0.220
1.84,46.85,0.220
1.85,46.93,0.220
1.86,47.01,0.220
1.87,47.10,0.220
1.88,47.18,0.221
1.88,47.26,0.221
1.89,47.35,0.221
1.90,47.43,0.221
1.91,47.52,0.221
1.92,47.60,0.221
1.93,47.68,0.221
1.93,47.77,0.221
1.94,47.85,0.221
1.95,47.93,0.221
1.96,48.02,0.221
1.97,48.10,0.221
1.98,48.18,0.221
1.98,48.26,0.221
1.99,48.35,0.221
2.00,48.43,0.221
2.01,48.51,0.221
2.02,48.60,0.221
2.03,48.68,0.221
2.03,48.76,0.221
2.04,48.85,0.221
2.05,48.93,0.222
2.06,49.01,0.222
2.07,49.10,0.222
2.08,49.18,0.222
2.08,49.27,0.222
2.09,49.35,0.222
2.10,49.43,0.222
2.11,49.52,0.222
2.12,49.60,0.222
2.13,49.68,0.222
2.13,49.77,0.222
2.14,49.85,0.222
2.15,49.93,0.222
2.16,50.02,0.222
2.17,50.10,0.222
2.18,50.18,0.222
2.18,50.27,0.222
2.19,50.35,0.222
2.20,50.43,0.222
2.21,50.52,0.223
2.22,50.60,0.223
2.23,50.68,0.223
2.23,50.77,0.223
2.24,50.85,0.223
2.25,50.93,0.223
2.26,51.02,0.223
2.27,51.10,0.223
2.28,51.18,0.223
2.28,51.27,0.223
2.29,51.35,0.223
2.30,51.44,0.223
2.31,51.52,0.223
2.32,51.60,0.223
2.33,51.68,0.223
2.33,51.77,0.223
2.34,51.85,0.223
2.35,51.93,0.223
2.36,52.02,0.223
2.37,52.10,0.223
2.38,52.18,0.223
2.38,52.27,0.224
2.39,52.35,0.224
2.40,52.43,0.224
2.41,52.52,0.224
2.42,52.60,0.224
2.43,52.69,0.224
2.43,52.77,0.224
2.44,52.85,0.224
2.45,52.93,0.224
2.46,53.02,0.224
2.47,53.10,0.224
2.48,53.18,0.224
2.48,53.27,0.224
2.49,53.35,0.224
2.50,53.44,0.224
2.51,53.52,0.224
2.52,53.60,0.224
2.53,53.69,0.224
2.53,53.77,0.225
2.54,53.85,0.225
2.55,53.94,0.225
2.56,54.02,0.225
2.57,54.10,0.225
2.58,54.19,0.225
2.58,54.27,0.225
2.59,54.35,0.225
2.60,54.44,0.225
2.61,54.52,0.225
2.62,54.60,0.225
2.63,54.69,0.225
2.63,54.77,0.225
2.64,54.85,0.225
2.65,54.94,0.225
2.66,55.02,0.225
2.67,55.10,0.225
2.68,55.19,0.225
2.68,55.27,0.225
2.69,55.35,0.225
2.70,55.44,0.226
2.71,55.52,0.226
2.72,55.60,0.226
2.73,55.69,0.226
2.73,55.77,0.226
2.74,55.85,0.226
2.75,55.94,0.226
2.76,56.02,0.226
2.77,56.10,0.226
2.78,56.19,0.226
2.78,56.27,0.226
2.79,56.35,0.226
2.80,56.44,0.226
2.81,56.52,0.226
2.82,56.60,0.226
2.83,56.69,0.226
2.83,56.77,0.226
2.84,56.85,0.226
2.85,56.94,0.226
2.86,57.02,0.226
2.87,57.10,0.226
2.88,57.19,0.227
2.88,57.27,0.227
2.89,57.35,0.227
2.90,57.44,0.227
2.91,57.52,0.227
2.92,57.60,0.227
2.93,57.69,0.227
2.93,57.77,0.227
2.94,57.85,0.227
2.95,57.94,0.227
2.96,58.02,0.227
2.97,58.11,0.227
2.98,58.19,0.227
2.98,58.27,0.227
2.99,58.36,0.227
3.00,58.44,0.227
3.01,58.52,0.227
3.02,58.61,0.228
3.03,58.69,0.228
3.03,58.77,0.228
3.04,58.86,0.228
3.05,58.94,0.228
3.06,59.02,0.228
3.07,59.11,0.228
3.08,59.19,0.228
3.08,59.27,0.228
3.09,59.36,0.228
3.10,59.44,0.228
3.11,59.52,0.228
3.12,59.61,0.228
3.13,59.69,0.228
3.13,59.77,0.228
3.14,59.86,0.228
3.15,59.94,0.228
3.16,60.02,0.228
3.17,60.11,0.228
3.18,60.19,0.228
3.18,60.27,0.228
3.19,60.36,0.229
3.20,60.44,0.229
3.21,60.52,0.229
3.22,60.61,0.229
3.23,60.69,0.229
3.23,60.77,0.229
3.24,60.86,0.229
3.25,60.94,0.229
3.26,61.02,0.229
3.27,61.11,0.229
3.28,61.19,0.229
3.28,61.27,0.229
3.29,61.36,0.229
3.30,61.44,0.229
3.31,61.53,0.229
3.32,61.61,0.229
3.33,61.69,0.229
3.33,61.78,0.229
3.34,61.86,0.229
3.35,61.94,0.230
3.36,62.03,0.230
3.37,62.11,0.230
3.38,62.19,0.230
3.38,62.28,0.230
3.39,62.36,0.230
3.40,62.44,0.230
3.41,62.53,0.230
3.42,62.61,0.230
3.43,62.69,0.230
3.43,62.78,0.230
3.44,62.86,0.230
3.45,62.94,0.230
3.46,63.03,0.230
3.47,63.11,0.230
3.48,63.19,0.230
3.48,63.28,0.230
3.49,63.36,0.230
3.50,63.44,0.230
3.51,63.53,0.230
3.52,63.61,0.231
3.53,63.69,0.231
3.53,63.78,0.231
3.54,63.86,0.231
3.55,63.94,0.231
3.56,64.03,0.231
3.57,64.11,0.231
3.58,64.19,0.231
3.58,64.28,0.231
3.59,64.36,0.231
3.60,64.45,0.231
3.61,64.53,0.231
3.62,64.61,0.231
3.63,64.69,0.231
3.63,64.78,0.231
3.64,64.86,0.231
3.65,64.95,0.231
3.66,65.03,0.231
3.67,65.11,0.231
3.68,65.19,0.232
3.68,65.28,0.232
3.69,65.36,0.232
3.70,65.45,0.232
3.71,65.53,0.232
3.72,65.61,0.232
3.73,65.70,0.232
3.73,65.78,0.232
3.74,65.86,0.232
3.75,65.95,0.232
3.76,66.03,0.232
3.77,66.11,0.232
3.78,66.20,0.232
3.78,66.28,0.232
3.79,66.36,0.232
3.80,66.45,0.232
3.81,66.53,0.232
3.82,66.61,0.233
3.83,66.70,0.233
3.83,66.78,0.233
3.84,66.86,0.233
3.85,66.95,0.233
3.86,67.03,0.233
3.87,67.11,0.233
3.88,67.20,0.233
3.88,67.28,0.233
3.89,67.37,0.233
3.90,67.45,0.233
3.91,67.53,0.233
3.92,67.61,0.233
3.93,67.70,0.233
3.93,67.78,0.233
3.94,67.87,0.233
3.95,67.95,0.233
3.96,68.03,0.233
3.97,68.12,0.233
3.98,68.20,0.233
3.98,68.28,0.234
3.99,68.36,0.234
4.00,68.45,0.234
4.01,68.53,0.234
4.02,68.62,0.234
4.03,68.70,0.234
4.03,68.78,0.234
4.04,68.87,0.234
4.05,68.95,0.234
4.06,69.03,0.234
4.07,69.12,0.234
4.08,69.20,0.234
4.08,69.28,0.234
4.09,69.37,0.234
4.10,69.45,0.234
4.11,69.53,0.234
4.12,69.62,0.234
4.13,69.70,0.234
4.13,69.78,0.235
4.14,69.87,0.235
4.15,69.95,0.235
4.16,70.03,0.235
4.17,70.12,0.235
4.18,70.20,0.235
4.18,70.28,0.235
4.19,70.37,0.235
4.20,70.45,0.235
4.21,70.53,0.235
4.22,70.62,0.235
4.23,70.70,0.235
4.23,70.78,0.235
4.24,70.87,0.235
4.25,70.95,0.235
4.26,71.03,0.235
4.27,71.12,0.235
4.28,71.20,0.235
4.28,71.28,0.236
4.29,71.37,0.236
4.30,71.45,0.236
4.31,71.53,0.236
4.32,71.62,0.236
4.33,71.70,0.236
4.33,71.78,0.236
4.34,71.87,0.236
4.35,71.95,0.236
4.36,72.03,0.236
4.37,72.12,0.236
4.38,72.20,0.236
4.38,72.28,0.236
4.39,72.37,0.236
4.40,72.45,0.236
4.41,72.53,0.236
4.42,72.62,0.237
4.43,72.70,0.237
4.43,72.78,0.237
4.44,72.87,0.237
4.45,72.95,0.237
4.46,73.04,0.237
4.47,73.12,0.237
4.48,73.20,0.237
4.48,73.29,0.237
4.49,73.37,0.237
4.50,73.45,0.237
4.51,73.54,0.237
4.52,73.62,0.237
4.53,73.70,0.237
4.53,73.79,0.237
4.54,73.87,0.237
4.55,73.95,0.237
4.56,74.04,0.238
4.57,74.12,0.238
4.58,74.20,0.238
4.58,74.29,0.238
4.59,74.37,0.238
4.60,74.45,0.238
4.61,74.54,0.238
4.62,74.62,0.238
4.63,74.70,0.238
4.63,74.79,0.238
4.64,74.87,0.238
4.65,74.95,0.238
4.66,75.04,0.238
4.67,75.12,0.238
4.68,75.20,0.238
4.68,75.29,0.238
4.69,75.37,0.238
4.70,75.45,0.238
4.71,75.54,0.239
4.72,75.62,0.239
4.73,75.70,0.239
4.73,75.79,0.239
4.74,75.87,0.239
4.75,75.95,0.239
4.76,76.04,0.239
4.77,76.12,0.239
4.78,76.20,0.239
4.78,76.29,0.239
4.79,76.37,0.239
4.80,76.46,0.239
4.81,76.54,0.239
4.82,76.62,0.239
4.83,76.70,0.239
4.83,76.79,0.240
4.84,76.87,0.240
4.85,76.95,0.240
4.86,77.04,0.240
4.87,77.12,0.240
4.88,77.21,0.240
4.88,77.29,0.240
4.89,77.37,0.240
4.90,77.46,0.240
4.91,77.54,0.240
4.92,77.62,0.240
4.93,77.71,0.240
4.93,77.79,0.240
4.94,77.87,0.240
4.95,77.96,0.240
4.96,78.04,0.240
4.97,78.12,0.240
4.98,78.21,0.240
4.98,78.29,0.241
4.99,78.37,0.241
5.00,78.46,0.241
5.01,78.54,0.241
5.02,78.62,0.241
5.03,78.71,0.241
5.03,78.79,0.241
5.04,78.87,0.241
5.05,78.96,0.241
5.06,79.04,0.241
5.07,79.12,0.241
5.08,79.21,0.241
5.08,79.29,0.241
5.09,79.37,0.241
5.10,79.46,0.241
5.11,79.54,0.242
5.12,79.62,0.242
5.13,79.71,0.242
5.13,79.79,0.242
5.14,79.87,0.242
5.15,79.96,0.242
5.16,80.04,0.242
5.17,80.13,0.242
5.18,80.21,0.242
5.18,80.29,0.242
5.19,80.37,0.242
5.20,80.46,0.242
5.21,80.54,0.242
5.22,80.62,0.242
5.23,80.71,0.242
5.23,80.79,0.242
5.24,80.87,0.242
5.25,80.96,0.242
5.26,81.04,0.243
5.27,81.12,0.243
5.28,81.21,0.243
5.28,81.29,0.243
5.29,81.37,0.243
5.30,81.46,0.243
5.31,81.54,0.243
5.32,81.63,0.243
5.33,81.71,0.243
5.33,81.79,0.243
5.34,81.87,0.243
5.35,81.96,0.243
5.36,82.04,0.243
5.37,82.12,0.243
5.38,82.21,0.243
5.38,82.29,0.243
5.39,82.38,0.243
5.40,82.46,0.243
5.41,82.54,0.244
5.42,82.63,0.244
5.43,82.71,0.244
5.43,82.79,0.244
5.44,82.88,0.244
5.45,82.96,0.244
5.46,83.04,0.244
5.47,83.13,0.244
5.48,83.21,0.244
5.48,83.29,0.244
5.49,83.38,0.244
5.50,83.46,0.244
5.51,83.54,0.244
5.52,83.63,0.244
5.53,83.71,0.244
5.53,83.79,0.244
5.54,83.88,0.244
5.55,83.96,0.244
5.56,84.04,0.244
5.57,84.13,0.244
5.58,84.21,0.245
5.58,84.29,0.245
5.59,84.38,0.245
5.60,84.46,0.245
5.61,84.54,0.245
5.62,84.63,0.245
5.63,84.71,0.245
5.63,84.80,0.245
5.64,84.88,0.245
5.65,84.96,0.245
5.66,85.04,0.245
5.67,85.13,0.245
5.68,85.21,0.245
5.68,85.30,0.245
5.69,85.38,0.245
5.70,85.46,0.245
5.71,85.54,0.245
5.72,85.63,0.245
5.73,85.71,0.245
5.73,85.80,0.246
5.74,85.88,0.246
5.75,85.96,0.246
5.76,86.05,0.246
5.77,86.13,0.246
5.78,86.21,0.246
5.78,86.30,0.246
5.79,86.38,0.246
5.80,86.46,0.246
5.81,86.55,0.246
5.82,86.63,0.246
5.83,86.71,0.246
5.83,86.80,0.246
5.84,86.88,0.246
5.85,86.96,0.246
5.86,87.05,0.246
5.87,87.13,0.246
5.88,87.21,0.246
5.88,87.30,0.246
5.89,87.38,0.247
5.90,87.46,0.247
5.91,87.55,0.247
5.92,87.63,0.247
5.93,87.71,0.247
5.93,87.80,0.247
5.94,87.88,0.247
5.95,87.96,0.247
5.96,88.05,0.247
5.97,88.13,0.247
5.98,88.21,0.247
5.98,88.30,0.247
5.99,88.38,0.247
6.00,88.46,0.247
6.01,88.55,0.247
6.02,88.63,0.247
6.03,88.71,0.247
6.03,88.80,0.247
6.04,88.88,0.247
6.05,88.96,0.247
6.06,89.05,0.248
6.07,89.13,0.248
6.08,89.21,0.248
6.08,89.30,0.248
6.09,89.38,0.248
6.10,89.46,0.248
6.11,89.55,0.248
6.12,89.63,0.248
6.13,89.72,0.248
6.13,89.80,0.248
6.14,89.88,0.248
6.15,89.97,0.248
6.16,90.05,0.248
6.17,90.13,0.248
6.18,90.22,0.248
6.18,90.30,0.248
6.19,90.38,0.249
6.20,90.47,0.249
6.21,90.55,0.249
6.22,90.63,0.249
6.23,90.72,0.249
6.23,90.80,0.249
6.24,90.88,0.249
6.25,90.97,0.249
6.26,91.05,0.249
6.27,91.13,0.249
6.28,91.22,0.249
6.28,91.30,0.249
6.29,91.38,0.249
6.30,91.47,0.249
6.31,91.55,0.249
6.32,91.63,0.249
6.33,91.72,0.249
6.33,91.80,0.250
6.34,91.88,0.250
6.35,91.97,0.250
6.36,92.05,0.250
6.37,92.13,0.250
6.38,92.22,0.250
6.38,92.30,0.250
6.39,92.38,0.250
6.40,92.47,0.250
6.41,92.55,0.250
6.42,92.64,0.250
6.43,92.72,0.250
6.43,92.80,0.250
6.44,92.88,0.250
6.45,92.97,0.250
6.46,93.05,0.250
6.47,93.13,0.250
6.48,93.22,0.251
6.48,93.30,0.251
6.49,93.38,0.251
6.50,93.47,0.251
6.51,93.55,0.251
6.52,93.63,0.251
6.53,93.72,0.251
6.53,93.80,0.251
6.54,93.89,0.251
6.55,93.97,0.251
6.56,94.05,0.251
6.57,94.14,0.251
6.58,94.22,0.251
6.58,94.30,0.251
6.59,94.39,0.251
6.60,94.47,0.251
6.61,94.55,0.251
6.62,94.64,0.252
6.63,94.72,0.252
6.63,94.80,0.252
6.64,94.88,0.252
6.65,94.97,0.252
6.66,95.05,0.252
6.67,95.14,0.252
6.68,95.22,0.252
6.68,95.30,0.252
6.69,95.39,0.252
6.70,95.47,0.252
6.71,95.55,0.252
6.72,95.64,0.252
6.73,95.72,0.252
6.73,95.80,0.252
6.74,95.89,0.252
6.75,95.97,0.253
6.76,96.05,0.253
6.77,96.14,0.253
6.78,96.22,0.253
6.78,96.30,0.253
6.79,96.39,0.253
6.80,96.47,0.253
6.81,96.55,0.253
6.82,96.64,0.253
6.83,96.72,0.253
6.83,96.80,0.253
6.84,96.89,0.253
6.85,96.97,0.253
6.86,97.05,0.253
6.87,97.14,0.253
6.88,97.22,0.253
6.88,97.30,0.253
6.89,97.39,0.254
6.90,97.47,0.254
6.91,97.55,0.254
6.92,97.64,0.254
6.93,97.72,0.254
6.93,97.80,0.254
6.94,97.89,0.254
6.95,97.97,0.254
6.96,98.06,0.254
6.97,98.14,0.254
6.98,98.22,0.254
6.98,98.30,0.254
6.99,98.39,0.254
7.00,98.47,0.254
7.01,98.56,0.254
7.02,98.64,0.254
7.03,98.72,0.255
7.03,98.81,0.255
7.04,98.89,0.255
7.05,98.97,0.255
7.06,99.06,0.255
7.07,99.14,0.255
7.08,99.22,0.255
7.08,99.31,0.255
7.09,99.39,0.255
7.10,99.47,0.255
7.11,99.56,0.255
7.12,99.64,0.255
7.13,99.72,0.255
7.13,99.81,0.255
7.14,99.89,0.255
7.15,99.97,0.255
7.16,100.06,0.255
7.17,100.14,0.256
7.18,100.22,0.256
7.18,100.31,0.256
7.19,100.39,0.256
7.20,100.47,0.256
7.21,100.56,0.256
7.22,100.64,0.256
7.23,100.72,0.256
7.23,100.81,0.256
7.24,100.89,0.256
7.25,100.97,0.256
7.26,101.06,0.256
7.27,101.14,0.256
7.28,101.22,0.256
7.28,101.31,0.256
7.29,101.39,0.256
7.30,101.47,0.256
7.31,101.56,0.257
7.32,101.64,0.257
7.33,101.72,0.257
7.33,101.81,0.257
7.34,101.89,0.257
7.35,101.97,0.257
7.36,102.06,0.257
7.37,102.14,0.257
7.38,102.23,0.257
7.38,102.31,0.257
7.39,102.39,0.257
7.40,102.47,0.257
7.41,102.56,0.257
7.42,102.64,0.257
7.43,102.72,0.257
7.43,102.81,0.257
7.44,102.89,0.257
7.45,102.97,0.257
7.46,103.06,0.258
7.47,103.14,0.258
7.48,103.23,0.258
7.48,103.31,0.258
7.49,103.39,0.258
7.50,103.47,0.258
7.51,103.56,0.258
7.52,103.64,0.258
7.53,103.72,0.258
7.53,103.81,0.258
7.54,103.89,0.258
7.55,103.98,0.258
7.56,104.06,0.258
7.57,104.14,0.258
7.58,104.22,0.258
7.58,104.31,0.259
7.59,104.39,0.259
7.60,104.48,0.259
7.61,104.56,0.259
7.62,104.64,0.259
7.63,104.73,0.259
7.63,104.81,0.259
7.64,104.89,0.259
7.65,104.98,0.259
7.66,105.06,0.259
7.67,105.14,0.259
7.68,105.23,0.259
7.68,105.31,0.259
7.69,105.39,0.259
7.70,105.48,0.259
7.71,105.56,0.259
7.72,105.64,0.260
7.73,105.73,0.260
7.73,105.81,0.260
7.74,105.89,0.260
7.75,105.98,0.260
7.76,106.06,0.260
7.77,106.14,0.260
7.78,106.23,0.260
7.78,106.31,0.260
7.79,106.39,0.260
7.80,106.48,0.260
7.81,106.56,0.260
7.82,106.65,0.260
7.83,106.73,0.260
7.83,106.81,0.260
7.84,106.89,0.260
7.85,106.98,0.260
7.86,107.06,0.260
7.87,107.15,0.261
7.88,107.23,0.261
7.88,107.31,0.261
7.89,107.40,0.261
7.90,107.48,0.261
7.91,107.56,0.261
7.92,107.65,0.261
7.93,107.73,0.261
7.93,107.81,0.261
7.94,107.90,0.261
7.95,107.98,0.261
7.96,108.06,0.261
7.97,108.15,0.261
7.98,108.23,0.261
7.98,108.31,0.261
7.99,108.40,0.261
8.00,108.48,0.261
8.01,108.56,0.262
8.02,108.65,0.262
8.03,108.73,0.262
8.03,108.81,0.262
8.04,108.90,0.262
8.05,108.98,0.262
8.06,109.06,0.262
8.07,109.15,0.262
8.08,109.23,0.262
8.08,109.31,0.262
8.09,109.40,0.262
8.10,109.48,0.262
8.11,109.56,0.262
8.12,109.65,0.262
8.13,109.73,0.262
8.13,109.81,0.262
8.14,109.90,0.262
8.15,109.98,0.263
8.16,110.06,0.263
8.17,110.15,0.263
8.18,110.23,0.263
8.18,110.31,0.263
8.19,110.40,0.263
8.20,110.48,0.263
8.21,110.56,0.263
8.22,110.65,0.263
8.23,110.73,0.263
8.23,110.81,0.263
8.24,110.90,0.263
8.25,110.98,0.263
8.26,111.06,0.263
8.27,111.15,0.263
8.28,111.23,0.263
8.28,111.31,0.263
8.29,111.40,0.263
8.30,111.48,0.264
8.31,111.56,0.264
8.32,111.65,0.264
8.33,111.73,0.264
8.33,111.82,0.264
8.34,111.90,0.264
8.35,111.98,0.264
8.36,112.07,0.264
8.37,112.15,0.264
8.38,112.23,0.264
8.38,112.32,0.264
8.39,112.40,0.264
8.40,112.48,0.264
8.41,112.57,0.264
8.42,112.65,0.264
8.43,112.73,0.264
8.43,112.82,0.265
8.44,112.90,0.265
8.45,112.98,0.265
8.46,113.07,0.265
8.47,113.15,0.265
8.48,113.23,0.265
8.48,113.32,0.265
8.49,113.40,0.265
8.50,113.48,0.265
8.51,113.57,0.265
8.52,113.65,0.265
8.53,113.73,0.265
8.53,113.82,0.265
8.54,113.90,0.265
8.55,113.98,0.266
8.56,114.07,0.266
8.57,114.15,0.266
8.58,114.23,0.266
8.58,114.32,0.266
8.59,114.40,0.266
8.60,114.48,0.266
8.61,114.57,0.266
8.62,114.65,0.266
8.63,114.73,0.266
8.63,114.82,0.266
8.64,114.90,0.266
8.65,114.98,0.266
8.66,115.07,0.266
8.67,115.15,0.266
8.68,115.23,0.267
8.68,115.32,0.267
8.69,115.40,0.267
8.70,115.48,0.267
8.71,115.57,0.267
8.72,115.65,0.267
8.73,115.73,0.267
8.73,115.82,0.267
8.74,115.90,0.267
8.75,115.98,0.267
8.76,116.07,0.267
8.77,116.15,0.267
8.78,116.23,0.267
8.78,116.32,0.267
8.79,116.40,0.268
8.80,116.49,0.268
8.81,116.57,0.268
8.82,116.65,0.268
8.83,116.73,0.268
8.83,116.82,0.268
8.84,116.90,0.268
8.85,116.98,0.268
8.86,117.07,0.269
8.87,117.15,0.269
8.88,117.23,0.269
8.88,117.32,0.269
8.89,117.40,0.269
8.90,117.48,0.269
8.91,117.57,0.269
8.92,117.65,0.269
8.93,117.73,0.269
8.93,117.82,0.270
8.94,117.90,0.270
8.95,117.98,0.270
8.96,118.07,0.270
8.97,118.15,0.270
8.98,118.23,0.270
8.98,118.32,0.270
8.99,118.40,0.271
9.00,118.48,0.271
9.01,118.57,0.271
9.02,118.65,0.272
9.03,118.73,0.272
9.03,118.82,0.272
9.04,118.90,0.273
9.05,118.98,0.273
9.06,119.07,0.273
9.07,119.15,0.274
9.08,119.23,0.274
9.08,119.32,0.275
9.09,119.40,0.275
9.10,119.48,0.276
9.11,119.56,0.277
9.12,119.65,0.278
9.13,119.73,0.279
9.13,119.81,0.279
9.14,119.90,0.280
9.15,119.98,0.282
9.16,120.06,0.284
9.17,120.15,0.285
9.18,120.23,0.286
9.18,120.31,0.287
9.19,120.39,0.290
9.20,120.48,0.291
9.21,120.56,0.294
9.22,120.64,0.297
9.23,120.72,0.300
9.23,120.80,0.304
9.24,120.88,0.309
9.25,120.96,0.315
9.26,121.05,0.322
9.27,121.13,0.330
9.28,121.20,0.341
9.28,121.28,0.355
9.29,121.36,0.372
9.30,121.43,0.393
9.31,121.51,0.422
9.32,121.58,0.457
9.33,121.64,0.501
9.33,121.71,0.553
9.34,121.76,0.613
9.35,121.82,0.684
9.36,121.86,0.753
9.37,121.91,0.827
9.38,121.95,0.906
9.38,121.98,0.992
9.39,122.01,1.081
9.40,122.04,1.174
9.41,122.06,1.263
9.42,122.08,1.347
9.43,122.10,1.429
9.43,122.12,1.511
9.44,122.14,1.592
9.45,122.15,1.671
9.46,122.17,1.749
9.47,122.19,1.826
9.48,122.20,1.902
9.48,122.22,1.975
9.49,122.23,2.045
9.50,122.25,2.115
9.51,122.27,2.186
9.52,122.29,2.255
9.53,122.31,2.321
9.53,122.33,2.387
9.54,122.35,2.453
9.55,122.37,2.518
9.56,122.39,2.581
9.57,122.41,2.643
9.58,122.44,2.705
9.58,122.46,2.764
9.59,122.49,2.821
9.60,122.52,2.872
9.61,122.54,2.920
9.62,122.58,2.968
9.63,122.61,3.019
9.63,122.64,3.072
9.64,122.67,3.123
9.65,122.71,3.168
9.66,122.74,3.211
9.67,122.78,3.256
9.68,122.82,3.293
9.68,122.86,3.320
9.69,122.91,3.337
9.70,122.96,3.359
9.71,123.01,3.396
9.72,123.06,3.440
9.73,123.10,3.482
9.73,123.15,3.520
9.74,123.20,3.537
9.75,123.26,3.551
9.76,123.31,3.580
9.77,123.37,3.613
9.78,123.42,3.639
9.78,123.48,3.663
9.79,123.54,3.685
9.80,123.59,3.703
9.81,123.65,3.720
9.82,123.72,3.740
9.83,123.78,3.760
9.83,123.84,3.757
9.84,123.91,3.737
9.85,123.98,3.758
9.86,124.05,3.808
9.87,124.11,3.848
9.88,124.18,3.843
9.88,124.25,3.822
9.89,124.32,3.833
9.90,124.39,3.864
9.91,124.46,3.900
9.92,124.53,3.896
9.93,124.60,3.882
9.93,124.68,3.891
9.94,124.75,3.926
9.95,124.82,3.952
9.96,124.89,3.951
9.97,124.96,3.920
9.98,125.04,3.892
9.98,125.13,3.895
9.99,125.20,3.936
10.00,125.28,3.952
10.01,125.36,3.972
10.02,125.43,4.001
10.03,125.50,3.961
10.03,125.59,3.908
10.04,125.68,3.898
10.05,125.76,3.891
10.06,125.85,3.895
10.07,125.94,3.917
10.08,126.01,3.945
10.08,126.10,3.940
10.09,126.17,4.006
10.10,126.25,3.954
10.11,126.35,3.739
10.12,126.47,3.576
10.13,126.60,3.528
10.13,126.73,3.440
10.14,126.87,3.288
10.15,127.02,3.062
10.16,127.22,2.614
10.17,127.46,2.214
10.18,127.71,1.951
10.18,127.97,1.754
10.19,128.22,1.627
10.20,128.45,1.529
10.21,128.68,1.442
10.22,128.89,1.363
10.23,129.10,1.291
10.23,129.30,1.224
10.24,129.49,1.162
10.25,129.67,1.105
10.26,129.84,1.052
10.27,130.01,1.002
10.28,130.17,0.956
10.28,130.33,0.913
10.29,130.48,0.873
10.30,130.62,0.837
10.31,130.76,0.803
10.32,130.90,0.771
10.33,131.03,0.741
10.33,131.16,0.714
10.34,131.29,0.688
10.35,131.41,0.665
10.36,131.53,0.643
10.37,131.65,0.622
10.38,131.77,0.603
10.38,131.88,0.586
10.39,131.99,0.569
10.40,132.10,0.554
10.41,132.21,0.540
10.42,132.31,0.527
10.43,132.41,0.515
10.43,132.52,0.504
10.44,132.62,0.493
10.45,132.72,0.484
10.46,132.82,0.474
10.47,132.91,0.466
10.48,133.01,0.459
10.48,133.10,0.451
10.49,133.20,0.444
10.50,133.29,0.438
10.51,133.39,0.432
10.52,133.48,0.428
10.53,133.57,0.423
10.53,133.66,0.418
10.54,133.75,0.413
10.55,133.84,0.409
10.56,133.93,0.405
10.57,134.02,0.402
10.58,134.11,0.399
10.58,134.20,0.396
10.59,134.29,0.394
10.60,134.37,0.391
10.61,134.46,0.389
10.62,134.55,0.387
10.63,134.63,0.385
10.63,134.72,0.383
10.64,134.81,0.381
10.65,134.89,0.380
10.66,134.98,0.378
10.67,135.07,0.377
10.68,135.15,0.375
10.68,135.24,0.374
10.69,135.32,0.373
10.70,135.41,0.372
10.71,135.49,0.371
10.72,135.58,0.371
10.73,135.66,0.369
10.73,135.75,0.369
10.74,135.83,0.368
10.75,135.91,0.368
10.76,136.00,0.367
10.77,136.08,0.366
10.78,136.17,0.366
10.78,136.25,0.366
10.79,136.34,0.366
10.80,136.42,0.365
10.81,136.50,0.365
10.82,136.59,0.365
10.83,136.67,0.364
10.83,136.76,0.364
10.84,136.84,0.364
10.85,136.92,0.364
10.86,137.01,0.364
10.87,137.09,0.363
10.88,137.17,0.363
10.88,137.26,0.363
10.89,137.34,0.363
10.90,137.43,0.363
10.91,137.51,0.363
10.92,137.59,0.363
10.93,137.68,0.362
10.93,137.76,0.362
10.94,137.84,0.362
10.95,137.93,0.362
10.96,138.01,0.362
10.97,138.09,0.362
10.98,138.18,0.362
10.98,138.26,0.362
10.99,138.34,0.362
11.00,138.43,0.362
11.01,138.51,0.362
11.02,138.59,0.362
11.03,138.68,0.362
11.03,138.76,0.362
11.04,138.84,0.362
11.05,138.93,0.362
11.06,139.01,0.362
11.07,139.10,0.362
11.08,139.18,0.362
11.08,139.26,0.362
11.09,139.35,0.362
11.10,139.43,0.362
11.11,139.51,0.362
11.12,139.60,0.362
11.13,139.68,0.362
11.13,139.76,0.362
11.14,139.85,0.362
11.15,139.93,0.362
11.16,140.01,0.362
11.17,140.10,0.362
11.18,140.18,0.362
11.18,140.26,0.362
11.19,140.35,0.362
11.20,140.43,0.362
11.21,140.51,0.362
11.22,140.60,0.362
11.23,140.68,0.362
11.23,140.76,0.362
11.24,140.85,0.362
11.25,140.93,0.362
11.26,141.01,0.362
11.27,141.10,0.362
11.28,141.18,0.362
11.28,141.26,0.362
11.29,141.35,0.362
11.30,141.43,0.362
11.31,141.51,0.362
11.32,141.60,0.362
11.33,141.68,0.362
11.33,141.76,0.362
11.34,141.85,0.362
11.35,141.93,0.362
11.36,142.01,0.362
11.37,142.10,0.362
11.38,142.18,0.362
11.38,142.26,0.363
11.39,142.35,0.363
11.40,142.43,0.363
11.41,142.51,0.363
11.42,142.60,0.363
11.43,142.68,0.363
11.43,142.76,0.363
11.44,142.85,0.363
11.45,142.93,0.363
11.46,143.01,0.363
11.47,143.10,0.363
11.48,143.18,0.363
11.48,143.26,0.363
11.49,143.35,0.363
11.50,143.43,0.363
11.51,143.52,0.363
11.52,143.60,0.364
11.53,143.68,0.364
11.53,143.77,0.364
11.54,143.85,0.364
11.55,143.93,0.364
11.56,144.02,0.364
11.57,144.10,0.364
11.58,144.18,0.364
11.58,144.27,0.364
11.59,144.35,0.364
11.60,144.43,0.364
11.61,144.52,0.364
11.62,144.60,0.364
11.63,144.68,0.364
11.63,144.77,0.364
11.64,144.85,0.364
11.65,144.93,0.364
11.66,145.02,0.365
11.67,145.10,0.365
11.68,145.18,0.365
11.68,145.27,0.365
11.69,145.35,0.365
11.70,145.43,0.365
11.71,145.52,0.365
11.72,145.60,0.365
11.73,145.68,0.365
11.73,145.77,0.365
11.74,145.85,0.365
11.75,145.93,0.365
11.76,146.02,0.365
11.77,146.10,0.365
11.78,146.18,0.365
11.78,146.27,0.365
11.79,146.35,0.366
11.80,146.43,0.366
11.81,146.52,0.366
11.82,146.60,0.366
11.83,146.68,0.366
11.83,146.77,0.366
11.84,146.85,0.366
11.85,146.93,0.366
11.86,147.02,0.366
11.87,147.10,0.366
11.88,147.18,0.366
11.88,147.27,0.366
11.89,147.35,0.366
11.90,147.43,0.366
11.91,147.52,0.367
11.92,147.60,0.367
11.93,147.68,0.367
11.93,147.77,0.367
11.94,147.85,
11.95,147.93,
11.96,148.02,
11.97,148.10,
11.98,148.18,
11.98,148.27,
11.99,,
12.00,,

[step]
Ramp 10.00 °C/min to 30.00 °C
Time,Temperature,Heat Flow (Normalized)
min,°C,W/g
13.00,150.12,-0.014
13.01,150.12,-0.015
13.02,150.12,-0.015
13.02,150.12,-0.015
13.03,150.12,-0.015
13.04,150.12,-0.015
13.05,150.11,-0.018
13.06,150.11,-0.024
13.07,150.10,-0.030
13.07,150.09,-0.039
13.08,150.07,-0.049
13.09,150.05,-0.060
13.10,150.03,-0.074
13.11,150.01,-0.089
13.12,149.98,-0.105
13.12,149.95,-0.122
13.13,149.91,-0.138
13.14,149.87,-0.155
13.15,149.82,-0.171
13.16,149.78,-0.187
13.17,149.73,-0.202
13.17,149.67,-0.216
13.18,149.62,-0.228
13.19,149.56,-0.240
13.20,149.50,-0.251
13.21,149.45,-0.261
13.22,149.38,-0.271
13.22,149.32,-0.279
13.23,149.26,-0.287
13.24,149.19,-0.295
13.25,149.13,-0.302
13.26,149.06,-0.309
13.27,148.99,-0.314
13.27,148.92,-0.321
13.28,148.85,-0.326
13.29,148.78,-0.330
13.30,148.71,-0.335
13.31,148.63,-0.339
13.32,148.56,-0.344
13.32,148.48,-0.348
13.33,148.41,-0.351
13.34,148.34,-0.354
13.35,148.26,-0.357
13.36,148.18,-0.360
13.37,148.11,-0.362
13.37,148.03,-0.365
13.38,147.95,-0.367
13.39,147.87,-0.369
13.40,147.80,-0.371
13.41,147.72,-0.373
13.42,147.64,-0.374
13.42,147.56,-0.376
13.43,147.48,-0.378
13.44,147.40,-0.378
13.45,147.32,-0.380
13.46,147.24,-0.381
13.47,147.16,-0.382
13.47,147.08,-0.383
13.48,147.00,-0.384
13.49,146.92,-0.385
13.50,146.84,-0.386
13.51,146.76,-0.386
13.52,146.68,-0.386
13.52,146.60,-0.387
13.53,146.52,-0.388
13.54,146.44,-0.388
13.55,146.35,-0.389
13.56,146.27,-0.389
13.57,146.19,-0.390
13.57,146.11,-0.390
13.58,146.03,-0.390
13.59,145.95,-0.391
13.60,145.87,-0.392
13.61,145.78,-0.392
13.62,145.70,-0.392
13.62,145.62,-0.392
13.63,145.54,-0.392
13.64,145.46,-0.392
13.65,145.37,-0.393
13.66,145.29,-0.393
13.67,145.21,-0.393
13.67,145.13,-0.393
13.68,145.04,-0.393
13.69,144.96,-0.393
13.70,144.88,-0.393
13.71,144.80,-0.393
13.72,144.71,-0.393
13.72,144.63,-0.393
13.73,144.55,-0.393
13.74,144.47,-0.393
13.75,144.38,-0.393
13.76,144.30,-0.393
13.77,144.22,-0.394
13.77,144.14,-0.394
13.78,144.05,-0.394
13.79,143.97,-0.394
13.80,143.89,-0.394
13.81,143.81,-0.394
13.82,143.72,-0.394
13.82,143.64,-0.394
13.83,143.56,-0.394
13.84,143.47,-0.394
13.85,143.39,-0.394
13.86,143.31,-0.394
13.87,143.23,-0.394
13.87,143.14,-0.394
13.88,143.06,-0.394
13.89,142.98,-0.394
13.90,142.90,-0.394
13.91,142.81,-0.394
13.92,142.73,-0.394
13.92,142.65,-0.394
13.93,142.56,-0.394
13.94,142.48,-0.394
13.95,142.40,-0.394
13.96,142.32,-0.394
13.97,142.23,-0.394
13.97,142.15,-0.394
13.98,142.07,-0.394
13.99,141.98,-0.394
14.00,141.90,-0.394
14.01,141.82,-0.394
14.02,141.74,-0.394
14.02,141.65,-0.394
14.03,141.57,-0.394
14.04,141.49,-0.394
14.05,141.40,-0.394
14.06,141.32,-0.394
14.07,141.24,-0.394
14.07,141.15,-0.394
14.08,141.07,-0.394
14.09,140.99,-0.394
14.10,140.91,-0.394
14.11,140.82,-0.394
14.12,140.74,-0.394
14.12,140.66,-0.394
14.13,140.57,-0.394
14.14,140.49,-0.394
14.15,140.41,-0.394
14.16,140.32,-0.394
14.17,140.24,-0.394
14.17,140.16,-0.394
14.18,140.07,-0.394
14.19,139.99,-0.394
14.20,139.91,-0.393
14.21,139.83,-0.393
14.22,139.74,-0.393
14.22,139.66,-0.393
14.23,139.58,-0.393
14.24,139.49,-0.393
14.25,139.41,-0.393
14.26,139.33,-0.393
14.27,139.24,-0.393
14.27,139.16,-0.393
14.28,139.08,-0.393
14.29,138.99,-0.393
14.30,138.91,-0.393
14.31,138.83,-0.393
14.32,138.75,-0.393
14.32,138.66,-0.393
14.33,138.58,-0.393
14.34,138.50,-0.393
14.35,138.41,-0.393
14.36,138.33,-0.393
14.37,138.25,-0.393
14.37,138.16,-0.392
14.38,138.08,-0.392
14.39,138.00,-0.392
14.40,137.91,-0.392
14.41,137.83,-0.392
14.42,137.75,-0.392
14.42,137.66,-0.392
14.43,137.58,-0.392
14.44,137.50,-0.392
14.45,137.41,-0.392
14.46,137.33,-0.392
14.47,137.25,-0.392
14.47,137.16,-0.392
14.48,137.08,-0.391
14.49,137.00,-0.391
14.50,136.92,-0.391
14.51,136.83,-0.391
14.52,136.75,-0.391
14.52,136.67,-0.391
14.53,136.58,-0.391
14.54,136.50,-0.391
14.55,136.42,-0.391
14.56,136.33,-0.391
14.57,136.25,-0.391
14.57,136.17,-0.391
14.58,136.08,-0.391
14.59,136.00,-0.391
14.60,135.92,-0.391
14.61,135.83,-0.391
14.62,135.75,-0.391
14.62,135.67,-0.390
14.63,135.58,-0.390
14.64,135.50,-0.390
14.65,135.42,-0.390
14.66,135.34,-0.390
14.67,135.25,-0.390
14.67,135.17,-0.390
14.68,135.08,-0.390
14.69,135.00,-0.390
14.70,134.92,-0.390
14.71,134.84,-0.390
14.72,134.75,-0.390
14.72,134.67,-0.390
14.73,134.59,-0.390
14.74,134.50,-0.389
14.75,134.42,-0.389
14.76,134.34,-0.389
14.77,134.25,-0.389
14.77,134.17,-0.389
14.78,134.09,-0.389
14.79,134.00,-0.389
14.80,133.92,-0.389
14.81,133.84,-0.389
14.82,133.75,-0.389
14.82,133.67,-0.389
14.83,133.59,-0.389
14.84,133.50,-0.388
14.85,133.42,-0.388
14.86,133.34,-0.388
14.87,133.25,-0.388
14.87,133.17,-0.388
14.88,133.09,-0.388
14.89,133.00,-0.388
14.90,132.92,-0.388
14.91,132.84,-0.388
14.92,132.75,-0.388
14.92,132.67,-0.388
14.93,132.59,-0.388
14.94,132.50,-0.388
14.95,132.42,-0.388
14.96,132.34,-0.388
14.97,132.25,-0.387
14.97,132.17,-0.387
14.98,132.09,-0.387
14.99,132.00,-0.387
15.00,131.92,-0.387
15.01,131.84,-0.387
15.02,131.75,-0.387
15.02,131.67,-0.387
15.03,131.59,-0.387
15.04,131.50,-0.387
15.05,131.42,-0.387
15.06,131.34,-0.387
15.07,131.26,-0.387
15.07,131.17,-0.386
15.08,131.09,-0.386
15.09,131.01,-0.386
15.10,130.92,-0.386
15.11,130.84,-0.386
15.12,130.76,-0.386
15.12,130.67,-0.386
15.13,130.59,-0.386
15.14,130.51,-0.386
15.15,130.42,-0.386
15.16,130.34,-0.386
15.17,130.26,-0.385
15.17,130.17,-0.385
15.18,130.09,-0.385
15.19,130.01,-0.385
15.20,129.92,-0.385
15.21,129.84,-0.385
15.22,129.76,-0.385
15.22,129.67,-0.385
15.23,129.59,-0.385
15.24,129.51,-0.385
15.25,129.42,-0.385
15.26,129.34,-0.385
15.27,129.26,-0.385
15.27,129.17,-0.384
15.28,129.09,-0.384
15.29,129.01,-0.384
15.30,128.92,-0.384
15.31,128.84,-0.384
15.32,128.76,-0.384
15.32,128.67,-0.384
15.33,128.59,-0.384
15.34,128.51,-0.384
15.35,128.43,-0.384
15.36,128.34,-0.384
15.37,128.26,-0.384
15.37,128.17,-0.384
15.38,128.09,-0.384
15.39,128.01,-0.384
15.40,127.92,-0.384
15.41,127.84,-0.384
15.42,127.76,-0.384
15.42,127.67,-0.383
15.43,127.59,-0.383
15.44,127.50,-0.383
15.45,127.42,-0.383
15.46,127.34,-0.382
15.47,127.26,-0.382
15.47,127.17,-0.382
15.48,127.09,-0.382
15.49,127.01,-0.381
15.50,126.92,-0.381
15.51,126.84,-0.381
15.52,126.76,-0.381
15.52,126.67,-0.381
15.53,126.59,-0.381
15.54,126.51,-0.381
15.55,126.43,-0.381
15.56,126.34,-0.381
15.57,126.26,-0.381
15.57,126.18,-0.381
15.58,126.09,-0.381
15.59,126.01,-0.381
15.60,125.93,-0.381
15.61,125.84,-0.381
15.62,125.76,-0.381
15.62,125.68,-0.381
15.63,125.59,-0.381
15.64,125.51,-0.380
15.65,125.42,-0.380
15.66,125.34,-0.380
15.67,125.26,-0.380
15.67,125.18,-0.380
15.68,125.09,-0.380
15.69,125.01,-0.380
15.70,124.93,-0.380
15.71,124.84,-0.380
15.72,124.76,-0.380
15.72,124.67,-0.380
15.73,124.59,-0.380
15.74,124.51,-0.380
15.75,124.43,-0.380
15.76,124.34,-0.380
15.77,124.26,-0.380
15.77,124.18,-0.379
15.78,124.09,-0.379
15.79,124.01,-0.379
15.80,123.93,-0.379
15.81,123.84,-0.379
15.82,123.76,-0.379
15.82,123.68,-0.379
15.83,123.59,-0.379
15.84,123.51,-0.379
15.85,123.43,-0.379
15.86,123.34,-0.379
15.87,123.26,-0.379
15.87,123.18,-0.379
15.88,123.09,-0.378
15.89,123.01,-0.378
15.90,122.93,-0.378
15.91,122.84,-0.378
15.92,122.76,-0.378
15.92,122.68,-0.378
15.93,122.59,-0.378
15.94,122.51,-0.378
15.95,122.43,-0.378
15.96,122.34,-0.378
15.97,122.26,-0.378
15.97,122.18,-0.377
15.98,122.09,-0.377
15.99,122.01,-0.377
16.00,121.93,-0.377
16.01,121.84,-0.377
16.02,121.76,-0.377
16.02,121.68,-0.377
16.03,121.60,-0.377
16.04,121.51,-0.377
16.05,121.43,-0.377
16.06,121.34,-0.377
16.07,121.26,-0.377
16.07,121.18,-0.377
16.08,121.10,-0.376
16.09,121.01,-0.376
16.10,120.93,-0.376
16.11,120.85,-0.376
16.12,120.76,-0.376
16.12,120.68,-0.376
16.13,120.60,-0.376
16.14,120.51,-0.376
16.15,120.43,-0.376
16.16,120.35,-0.376
16.17,120.26,-0.376
16.17,120.18,-0.376
16.18,120.10,-0.375
16.19,120.01,-0.375
16.20,119.93,-0.375
16.21,119.85,-0.375
16.22,119.76,-0.375
16.22,119.68,-0.375
16.23,119.60,-0.375
16.24,119.51,-0.375
16.25,119.43,-0.375
16.26,119.35,-0.375
16.27,119.26,-0.375
16.27,119.18,-0.375
16.28,119.10,-0.375
16.29,119.01,-0.374
16.30,118.93,-0.374
16.31,118.85,-0.374
16.32,118.76,-0.374
16.32,118.68,-0.374
16.33,118.60,-0.374
16.34,118.51,-0.374
16.35,118.43,-0.374
16.36,118.35,-0.374
16.37,118.26,-0.374
16.37,118.18,-0.374
16.38,118.10,-0.374
16.39,118.01,-0.374
16.40,117.93,-0.374
16.41,117.85,-0.373
16.42,117.77,-0.373
16.42,117.68,-0.373
16.43,117.60,-0.373
16.44,117.52,-0.373
16.45,117.43,-0.373
16.46,117.35,-0.373
16.47,117.26,-0.373
16.47,117.18,-0.373
16.48,117.10,-0.373
16.49,117.02,-0.373
16.50,116.93,-0.373
16.51,116.85,-0.372
16.52,116.77,-0.372
16.52,116.68,-0.372
16.53,116.60,-0.372
16.54,116.52,-0.372
16.55,116.43,-0.372
16.56,116.35,-0.372
16.57,116.27,-0.372
16.57,116.18,-0.372
16.58,116.10,-0.372
16.59,116.02,-0.372
16.60,115.93,-0.372
16.61,115.85,-0.372
16.62,115.77,-0.371
16.62,115.68,-0.371
16.63,115.60,-0.371
16.64,115.52,-0.371
16.65,115.43,-0.371
16.66,115.35,-0.371
16.67,115.27,-0.371
16.67,115.18,-0.371
16.68,115.10,-0.371
16.69,115.02,-0.371
16.70,114.93,-0.371
16.71,114.85,-0.371
16.72,114.77,-0.371
16.72,114.68,-0.370
[...]
44.32,98.77,-0.355,1.894
44.33,98.69,-0.355,1.893
44.33,98.60,-0.355,1.893
44.34,98.52,-0.355,1.892
44.35,98.43,-0.355,1.892
44.36,98.35,-0.354,1.891
44.37,98.27,-0.354,1.890
44.38,98.19,-0.354,1.890
44.38,98.10,-0.354,1.890
44.39,98.02,-0.354,1.889
44.40,97.94,-0.354,1.888
44.41,97.85,-0.354,1.888
44.42,97.77,-0.354,1.888
44.43,97.69,-0.354,1.887
44.43,97.60,-0.354,1.887
44.44,97.52,-0.354,1.887
44.45,97.44,-0.354,1.887
44.46,97.35,-0.354,1.886
44.47,97.27,-0.353,1.887
44.48,97.19,-0.353,1.886
44.48,97.10,-0.353,1.885
44.49,97.02,-0.353,1.885
44.50,96.94,-0.353,1.885
44.51,96.85,-0.353,1.885
44.52,96.77,-0.353,1.884
44.53,96.69,-0.353,1.884
44.53,96.60,-0.353,1.883
44.54,96.52,-0.353,1.883
44.55,96.44,-0.353,1.882
44.56,96.35,-0.353,1.883
44.57,96.27,-0.353,1.883
44.58,96.19,-0.353,1.882
44.58,96.10,-0.353,1.882
44.59,96.02,-0.352,1.880
44.60,95.94,-0.352,1.880
44.61,95.85,-0.352,1.880
44.62,95.77,-0.352,1.880
44.63,95.69,-0.352,1.879
44.63,95.60,-0.352,1.879
44.64,95.52,-0.352,1.878
44.65,95.44,-0.352,1.878
44.66,95.35,-0.352,1.877
44.67,95.27,-0.352,1.876
44.68,95.19,-0.352,1.876
44.68,95.10,-0.352,1.876
44.69,95.02,-0.351,1.876
44.70,94.94,-0.351,1.875
44.71,94.85,-0.351,1.875
44.72,94.77,-0.351,1.874
44.73,94.69,-0.351,1.874
44.73,94.60,-0.351,1.874
44.74,94.52,-0.351,1.873
44.75,94.44,-0.351,1.874
44.76,94.35,-0.351,1.873
44.77,94.27,-0.351,1.873
44.78,94.19,-0.351,1.873
44.78,94.10,-0.351,1.872
44.79,94.02,-0.350,1.869
44.80,93.94,-0.350,1.870
44.81,93.85,-0.350,1.869
44.82,93.77,-0.350,1.869
44.83,93.69,-0.350,1.868
44.83,93.61,-0.350,1.868
44.84,93.52,-0.350,1.868
44.85,93.44,-0.350,1.867
44.86,93.36,-0.350,1.867
44.87,93.27,-0.350,1.866
44.88,93.19,-0.349,1.866
44.88,93.11,-0.349,1.866
44.89,93.02,-0.349,1.865
44.90,92.94,-0.349,1.865
44.91,92.86,-0.349,1.864
44.92,92.77,-0.349,1.864
44.93,92.69,-0.349,1.862
44.93,92.60,-0.349,1.862
44.94,92.52,-0.349,1.862
44.95,92.44,-0.349,1.862
44.96,92.36,-0.349,2.551
44.97,92.27,-0.349,-1.429
44.98,92.19,-0.349,-0.414
44.98,92.11,-0.348,-0.324
44.99,92.02,-0.348,-0.313
45.00,91.94,-0.348,-0.316
45.01,91.86,-0.348,-0.326
45.02,91.77,-0.348,-0.341
45.03,91.69,-0.348,-0.364
45.03,91.60,-0.348,-0.392
45.04,91.52,-0.348,-0.428
45.05,91.44,-0.356,-0.482
45.06,91.38,-7.283,-10.865
45.07,94.10,-48.824,-80.738
45.08,102.73,-60.066,-110.386
45.08,104.75,-28.239,-57.904
45.09,105.06,-18.917,-43.460
45.10,104.88,-14.642,-37.858
45.11,104.45,-11.905,-34.814
45.12,103.84,-9.757,-32.454
45.13,103.09,-7.687,-29.284
45.13,102.24,-6.013,-26.449
45.14,101.37,-4.950,-25.398
45.15,100.50,-4.178,-25.327
45.16,99.66,-3.632,-33.120
45.17,98.86,-3.243,15.803
45.18,98.11,-2.946,3.505
45.18,97.42,-2.707,2.304
45.19,96.76,-2.508,2.004
45.20,96.16,-2.335,1.843
45.21,95.59,-2.181,1.739
45.22,95.06,-2.042,1.670
45.23,94.56,-1.916,1.628
45.23,94.10,-1.800,1.606
45.24,93.66,-1.692,1.596
45.25,93.26,-1.590,1.593
45.26,92.87,-1.495,1.593
45.27,92.52,-1.406,1.595
45.28,92.18,-1.322,1.596
45.28,91.86,-1.244,1.597
45.29,91.56,-1.172,1.598
45.30,91.28,-1.105,1.599
45.31,91.01,-1.043,1.598
45.32,90.76,-0.984,1.597
45.33,90.51,-0.931,1.596
45.33,90.29,-0.881,1.594
45.34,90.07,-0.834,1.590
45.35,89.86,-0.792,1.588
45.36,89.66,-0.753,1.587
45.37,89.47,-0.716,1.582
45.38,89.29,-0.682,1.577
45.38,89.12,-0.651,1.574
45.39,88.95,-0.622,1.570
45.40,88.79,-0.595,1.566
45.41,88.64,-0.570,1.561
45.42,88.49,-0.547,1.555
45.43,88.35,-0.526,1.551
45.43,88.21,-0.505,1.543
45.44,88.07,-0.487,1.540
45.45,87.94,-0.470,1.534
45.46,87.82,-0.455,1.531
45.47,87.69,-0.441,1.525
45.48,87.57,-0.427,1.520
45.48,87.45,-0.415,1.514
45.49,87.34,-0.403,1.507
45.50,87.23,-0.392,1.501
45.51,87.11,-0.383,1.498
45.52,87.01,-0.374,1.494
45.53,86.90,-0.365,1.489
45.53,86.80,-0.358,1.485
45.54,86.69,-0.350,1.480
45.55,86.59,-0.344,1.475
45.56,86.49,-0.337,1.469
45.57,86.39,-0.332,1.469
45.58,86.30,-0.327,1.465
45.58,86.20,-0.322,1.461
45.59,86.10,-0.317,1.457
45.60,86.01,-0.313,1.452
45.61,85.91,-0.310,1.452
45.62,85.82,-0.305,1.444
45.63,85.73,-0.303,1.446
45.63,85.64,-0.300,1.446
45.64,85.55,-0.297,1.439
45.65,85.46,-0.295,1.438
45.66,85.37,-0.293,1.439
45.67,85.28,-0.290,1.433
45.68,85.19,-0.288,1.431
45.68,85.10,-0.286,1.429
45.69,85.01,-0.284,1.427
45.70,84.92,-0.283,1.427
45.71,84.84,-0.281,1.424
45.72,84.75,-0.280,1.425
45.73,84.66,-0.279,1.423
45.73,84.58,-0.277,1.418
45.74,84.49,-0.276,1.419
45.75,84.40,-0.275,1.417
45.76,84.32,-0.274,1.418
45.77,84.23,-0.274,1.418
45.78,84.15,-0.272,1.411
45.78,84.06,-0.271,1.412
45.79,83.98,-0.270,1.410
45.80,83.89,-0.270,1.411
45.81,83.81,-0.270,1.411
45.82,83.72,-0.269,1.409
45.83,83.64,-0.269,1.410
45.83,83.55,-0.268,1.407
45.84,83.47,-0.267,1.406
45.85,83.39,-0.267,1.405
45.86,83.30,-0.266,1.405
45.87,83.22,-0.266,1.405
45.88,83.13,-0.266,1.406
45.88,83.05,-0.266,1.404
45.89,82.96,-0.265,1.404
45.90,82.88,-0.265,1.404
45.91,82.80,-0.265,1.405
45.92,82.71,-0.265,1.405
45.93,82.63,-0.265,1.405
45.93,82.54,-0.265,1.404
45.94,82.46,-0.265,1.404
45.95,82.38,-0.264,1.404
45.96,82.29,-0.264,1.403
45.97,82.21,-0.264,1.403
45.98,82.13,-0.264,1.403
45.98,82.04,-0.264,1.403
45.99,81.96,-0.264,1.402
46.00,81.87,-0.264,1.402
46.01,81.79,-0.263,1.402
46.02,81.71,-0.263,1.401
46.03,81.62,-0.263,1.401
46.03,81.54,-0.263,1.401
46.04,81.46,-0.263,1.400
46.05,81.37,-0.263,1.401
46.06,81.29,-0.263,1.401
46.07,81.21,-0.263,1.400
46.08,81.12,-0.263,1.400
46.08,81.04,-0.263,1.400
46.09,80.96,-0.263,1.401
46.10,80.87,-0.263,1.401
46.11,80.79,-0.263,1.400
46.12,80.71,-0.263,1.400
46.13,80.62,-0.262,1.400
46.13,80.54,-0.262,1.399
46.14,80.46,-0.262,1.400
46.15,80.37,-0.262,1.399
46.16,80.29,-0.262,1.398
46.17,80.21,-0.262,1.398
46.18,80.12,-0.262,1.397
46.18,80.04,-0.262,1.397
46.19,79.96,-0.262,1.397
46.20,79.87,-0.262,1.396
46.21,79.79,-0.262,1.396
46.22,79.71,-0.262,1.396
46.23,79.62,-0.261,1.396
46.23,79.54,-0.261,1.396
46.24,79.46,-0.261,1.396
46.25,79.37,-0.261,1.395
46.26,79.29,-0.261,1.395
46.27,79.21,-0.261,1.394
46.28,79.12,-0.261,1.394
46.28,79.04,-0.261,1.394
46.29,78.96,-0.261,1.393
46.30,78.87,-0.261,1.393
46.31,78.79,-0.261,1.393
46.32,78.71,-0.261,1.393
46.33,78.62,-0.261,1.392
46.33,78.54,-0.260,1.391
46.34,78.46,-0.260,1.391
46.35,78.37,-0.260,1.391
46.36,78.29,-0.260,1.390
46.37,78.21,-0.260,1.390
46.38,78.12,-0.260,1.389
46.38,78.04,-0.260,1.389
46.39,77.96,-0.260,1.388
46.40,77.87,-0.260,1.388
46.41,77.79,-0.260,1.388
46.42,77.71,-0.260,1.387
46.43,77.63,-0.260,1.387
46.43,77.54,-0.260,1.386
46.44,77.46,-0.260,1.386
46.45,77.38,-0.260,1.386
46.46,77.29,-0.259,1.386
46.47,77.21,-0.259,1.385
46.48,77.13,-0.259,1.385
46.48,77.04,-0.259,1.384
46.49,76.96,-0.259,1.384
46.50,76.88,-0.259,1.384
46.51,76.79,-0.259,1.383
46.52,76.71,-0.259,1.382
46.53,76.63,-0.259,1.382
46.53,76.54,-0.259,1.382
46.54,76.46,-0.259,1.382
46.55,76.38,-0.259,1.381
46.56,76.29,-0.259,1.381
46.57,76.21,-0.259,1.381
46.58,76.13,-0.258,1.380
46.58,76.04,-0.258,1.380
46.59,75.96,-0.258,1.379
46.60,75.88,-0.258,1.379
46.61,75.79,-0.258,1.379
46.62,75.71,-0.258,1.378
46.63,75.63,-0.258,1.377
46.63,75.54,-0.258,1.377
46.64,75.46,-0.258,1.377
46.65,75.38,-0.258,1.377
46.66,75.29,-0.258,1.376
46.67,75.21,-0.258,1.376
46.68,75.13,-0.258,1.376
46.68,75.04,-0.258,1.375
46.69,74.96,-0.257,1.374
46.70,74.88,-0.257,1.374
46.71,74.79,-0.257,1.373
46.72,74.71,-0.257,1.373
46.73,74.63,-0.257,1.373
46.73,74.54,-0.257,1.372
46.74,74.46,-0.257,1.371
46.75,74.38,-0.257,1.371
46.76,74.29,-0.257,1.371
46.77,74.21,-0.257,1.371
46.78,74.13,-0.257,1.371
46.78,74.05,-0.257,1.370
46.79,73.96,-0.257,1.370
46.80,73.88,-0.257,1.370
46.81,73.79,-0.256,1.369
46.82,73.71,-0.256,1.369
46.83,73.63,-0.256,1.369
46.83,73.54,-0.256,1.369
46.84,73.46,-0.256,1.368
46.85,73.38,-0.256,1.368
46.86,73.29,-0.256,1.367
46.87,73.21,-0.256,1.366
46.88,73.13,-0.256,1.366
46.88,73.04,-0.256,1.366
46.89,72.96,-0.256,1.365
46.90,72.88,-0.256,1.364
46.91,72.80,-0.256,1.365
46.92,72.71,-0.256,1.364
46.93,72.63,-0.255,1.364
46.93,72.55,-0.255,1.364
46.94,72.46,-0.255,1.364
46.95,72.38,-0.255,1.364
46.96,72.29,-0.255,1.363
46.97,72.21,-0.255,1.363
46.98,72.13,-0.255,1.363
46.98,72.05,-0.255,1.362
46.99,71.96,-0.255,1.361
47.00,71.88,-0.255,1.361
47.01,71.80,-0.255,1.361
47.02,71.71,-0.255,1.360
47.03,71.63,-0.255,1.360
47.03,71.55,-0.255,1.360
47.04,71.46,-0.255,1.359
47.05,71.38,-0.255,1.359
47.06,71.30,-0.255,1.359
47.07,71.21,-0.254,1.359
47.08,71.13,-0.254,1.358
47.08,71.05,-0.254,1.358
47.09,70.96,-0.254,1.358
47.10,70.88,-0.254,1.357
47.11,70.80,-0.254,1.356
47.12,70.71,-0.254,1.356
47.13,70.63,-0.254,1.356
47.13,70.55,-0.254,1.355
47.14,70.46,-0.254,1.355
47.15,70.38,-0.254,1.354
47.16,70.30,-0.254,1.354
47.17,70.21,-0.254,1.354
47.18,70.13,-0.254,1.353
47.18,70.05,-0.253,1.353
47.19,69.96,-0.253,1.353
47.20,69.88,-0.253,1.353
47.21,69.80,-0.253,1.353
47.22,69.71,-0.253,1.352
47.23,69.63,-0.253,1.352
47.23,69.55,-0.253,1.351
47.24,69.46,-0.253,1.351
47.25,69.38,-0.253,1.351
47.26,69.30,-0.253,1.351
47.27,69.21,-0.253,1.350
47.28,69.13,-0.253,1.350
47.28,69.05,-0.253,1.350
47.29,68.96,-0.253,1.350
47.30,68.88,-0.253,1.349
47.31,68.80,-0.253,1.348
47.32,68.71,-0.252,1.347
47.33,68.63,-0.252,1.346
47.33,68.55,-0.252,1.346
47.34,68.46,-0.252,1.346
47.35,68.38,-0.252,1.346
47.36,68.30,-0.252,1.345
47.37,68.21,-0.252,1.345
47.38,68.13,-0.252,1.345
47.38,68.05,-0.252,1.345
47.39,67.96,-0.252,1.344
47.40,67.88,-0.252,1.344
47.41,67.80,-0.252,1.343
47.42,67.71,-0.251,1.343
47.43,67.63,-0.251,1.343
47.43,67.55,-0.251,1.342
47.44,67.47,-0.251,1.342
47.45,67.38,-0.251,1.342
47.46,67.30,-0.251,1.342
47.47,67.22,-0.251,1.342
47.48,67.13,-0.251,1.342
47.48,67.05,-0.251,1.341
47.49,66.97,-0.251,1.340
47.50,66.88,-0.251,1.341
47.51,66.80,-0.251,1.340
47.52,66.72,-0.251,1.340
47.53,66.63,-0.251,1.340
47.53,66.55,-0.251,1.339
47.54,66.47,-0.251,1.339
47.55,66.38,-0.250,1.339
47.56,66.30,-0.250,1.338
47.57,66.22,-0.250,1.338
47.58,66.13,-0.250,1.338
47.58,66.05,-0.250,1.337
47.59,65.97,-0.250,1.337
47.60,65.88,-0.250,1.337
47.61,65.80,-0.250,1.336
47.62,65.72,-0.250,1.336
47.63,65.63,-0.250,1.335
47.63,65.55,-0.250,1.335
47.64,65.47,-0.250,1.334
47.65,65.39,-0.249,1.334
47.66,65.30,-0.249,1.333
47.67,65.22,-0.249,1.333
47.68,65.14,-0.249,1.332
47.68,65.05,-0.249,1.332
47.69,64.97,-0.249,1.332
47.70,64.89,-0.249,1.331
47.71,64.80,-0.249,1.331
47.72,64.72,-0.249,1.330
47.73,64.64,-0.249,1.330
47.73,64.55,-0.249,1.330
47.74,64.47,-0.249,1.329
47.75,64.39,-0.249,1.329
47.76,64.30,-0.249,1.329
47.77,64.22,-0.249,1.329
47.78,64.14,-0.249,1.328
47.78,64.05,-0.249,1.328
47.79,63.97,-0.249,1.327
47.80,63.89,-0.248,1.326
47.81,63.80,-0.248,1.326
47.82,63.72,-0.248,1.326
47.83,63.64,-0.248,1.326
47.83,63.55,-0.248,1.326
47.84,63.47,-0.248,1.325
47.85,63.39,-0.248,1.325
47.86,63.30,-0.248,1.325
47.87,63.22,-0.248,1.325
47.88,63.14,-0.248,1.324
47.88,63.05,-0.248,1.324
47.89,62.97,-0.248,1.324
47.90,62.89,-0.248,1.323
47.91,62.80,-0.248,1.323
47.92,62.72,-0.248,1.323
47.93,62.64,-0.248,1.323
47.93,62.55,-0.248,1.322
47.94,62.47,-0.248,1.322
47.95,62.39,-0.247,1.321
47.96,62.30,-0.247,1.321
47.97,62.22,-0.247,1.320
47.98,62.14,-0.247,1.319
47.98,62.05,-0.247,1.319
47.99,61.97,-0.247,1.319
48.00,61.89,-0.247,1.320
48.01,61.80,-0.247,1.319
48.02,61.72,-0.247,1.318
48.03,61.64,-0.247,1.318
48.03,61.55,-0.247,1.317
48.04,61.47,-0.247,1.317
48.05,61.39,-0.247,1.316
48.06,61.30,-0.246,1.315
48.07,61.22,-0.246,1.315
48.08,61.14,-0.246,1.315
48.08,61.05,-0.246,1.315
48.09,60.97,-0.246,1.314
48.10,60.89,-0.246,1.314
48.11,60.80,-0.246,1.313
48.12,60.72,-0.246,1.313
48.13,60.64,-0.246,1.312
48.13,60.55,-0.246,1.312
48.14,60.47,-0.246,1.311
48.15,60.39,-0.246,1.311
48.16,60.30,-0.246,1.310
48.17,60.22,-0.246,1.311
48.18,60.14,-0.245,1.310
48.18,60.05,-0.245,1.310
48.19,59.97,-0.245,1.310
48.20,59.89,-0.245,1.309
48.21,59.80,-0.245,1.309
48.22,59.72,-0.245,1.308
48.23,59.64,-0.245,1.309
48.23,59.55,-0.245,1.309
48.24,59.47,-0.245,1.309
48.25,59.39,-0.245,1.308
48.26,59.30,-0.245,1.308
48.27,59.22,-0.245,1.307
48.28,59.14,-0.245,1.306
48.28,59.05,-0.244,1.305
48.29,58.97,-0.244,1.305
48.30,58.89,-0.244,1.306
48.31,58.80,-0.244,1.306
48.32,58.72,-0.244,1.305
48.33,58.64,-0.244,1.304
48.33,58.55,-0.244,1.304
48.34,58.47,-0.244,1.303
48.35,58.39,-0.244,1.303
48.36,58.30,-0.244,1.302
48.37,58.22,-0.244,1.302
48.38,58.14,-0.244,1.302
48.38,58.05,-0.244,1.301
48.39,57.97,-0.244,1.301
48.40,57.89,-0.243,1.301
48.41,57.80,-0.243,1.300
48.42,57.72,-0.243,1.300
48.43,57.64,-0.243,1.299
48.43,57.55,-0.243,1.299
48.44,57.47,-0.243,1.299
48.45,57.39,-0.243,1.298
48.46,57.30,-0.243,1.298
48.47,57.22,-0.243,1.298
48.48,57.14,-0.243,1.298
48.48,57.05,-0.243,1.297
48.49,56.97,-0.243,1.297
48.50,56.89,-0.243,1.296
48.51,56.80,-0.243,1.296
48.52,56.72,-0.243,1.296
48.53,56.64,-0.243,1.296
48.53,56.55,-0.243,1.296
48.54,56.47,-0.243,1.295
48.55,56.39,-0.242,1.295
48.56,56.30,-0.242,1.294
48.57,56.22,-0.242,1.294
48.58,56.14,-0.242,1.294
48.58,56.05,-0.242,1.294
48.59,55.97,-0.242,1.293
48.60,55.89,-0.242,1.293
48.61,55.80,-0.242,1.292
48.62,55.72,-0.242,1.292
48.63,55.64,-0.242,1.292
48.63,55.56,-0.242,1.291
48.64,55.47,-0.242,1.291
48.65,55.39,-0.242,1.291
48.66,55.30,-0.242,1.290
48.67,55.22,-0.241,1.290
48.68,55.14,-0.241,1.289
48.68,55.06,-0.241,1.289
48.69,54.97,-0.241,1.288
48.70,54.89,-0.241,1.288
48.71,54.81,-0.241,1.287
48.72,54.72,-0.241,1.287
48.73,54.64,-0.241,1.287
48.73,54.56,-0.241,1.286
48.74,54.47,-0.241,1.285
48.75,54.39,-0.241,1.284
48.76,54.31,-0.241,1.284
48.77,54.22,-0.241,1.284
48.78,54.14,-0.241,1.284
48.78,54.06,-0.240,1.284
48.79,53.97,-0.240,1.283
48.80,53.89,-0.240,1.283
48.81,53.81,-0.240,1.282
48.82,53.72,-0.240,1.282
48.83,53.64,-0.240,1.282
48.83,53.56,-0.240,1.282
48.84,53.47,-0.240,1.281
48.85,53.39,-0.240,1.281
48.86,53.31,-0.240,1.281
48.87,53.22,-0.240,1.282
48.88,53.14,-0.240,1.282
48.88,53.06,-0.240,1.282
48.89,52.97,-0.240,1.282
48.90,52.89,-0.240,1.281
48.91,52.81,-0.240,1.281
48.92,52.72,-0.240,1.280
48.93,52.64,-0.240,1.279
48.93,52.56,-0.240,1.278
48.94,52.47,-0.239,1.278
48.95,52.39,-0.239,1.277
48.96,52.31,-0.239,1.276
48.97,52.22,-0.239,1.276
48.98,52.14,-0.239,1.275
48.98,52.06,-0.239,1.275
48.99,51.97,-0.239,1.274
49.00,51.89,-0.239,1.274
49.01,51.81,-0.239,1.273
49.02,51.72,-0.239,1.273
49.03,51.64,-0.239,1.272
49.03,51.56,-0.239,1.272
49.04,51.47,-0.239,1.272
49.05,51.39,-0.238,1.272
49.06,51.31,-0.238,1.272
49.07,51.22,-0.238,1.271
49.08,51.14,-0.238,1.271
49.08,51.06,-0.238,1.270
49.09,50.98,-0.238,1.269
49.10,50.89,-0.238,1.270
49.11,50.81,-0.238,1.270
49.12,50.72,-0.238,1.269
49.13,50.64,-0.238,1.268
49.13,50.56,-0.238,1.268
49.14,50.47,-0.238,1.268
49.15,50.39,-0.238,1.267
49.16,50.31,-0.238,1.267
49.17,50.23,-0.237,1.266
49.18,50.14,-0.237,1.266
49.18,50.06,-0.237,1.266
49.19,49.98,-0.237,1.266
49.20,49.89,-0.237,1.266
49.21,49.81,-0.237,1.266
49.22,49.73,-0.237,1.265
49.23,49.64,-0.237,1.265
49.23,49.56,-0.237,1.265
49.24,49.48,-0.237,1.265
49.25,49.39,-0.237,1.265
49.26,49.31,-0.237,1.264
49.27,49.23,-0.237,1.263
49.28,49.14,-0.237,1.263
49.28,49.06,-0.237,1.263
49.29,48.98,-0.237,1.266
49.30,48.89,-0.238,1.271
49.31,48.81,-0.238,1.269
49.32,48.73,-0.238,1.269
49.33,48.64,-0.238,1.268
49.33,48.56,-0.238,1.267
49.34,48.48,-0.237,1.264
49.35,48.39,-0.237,1.263
49.36,48.31,-0.237,1.262
49.37,48.23,-0.237,1.262
49.38,48.14,-0.237,1.262
49.38,48.06,-0.236,1.260
49.39,47.98,-0.236,1.259
49.40,47.89,-0.236,1.258
49.41,47.81,-0.236,1.258
49.42,47.73,-0.236,1.258
49.43,47.64,-0.236,1.258
49.43,47.56,-0.236,1.257
49.44,47.48,-0.236,1.257
49.45,47.39,-0.236,1.256
49.46,47.31,-0.236,1.256
49.47,47.23,-0.235,1.255
49.48,47.14,-0.235,1.255
49.48,47.06,-0.235,1.255
49.49,46.98,-0.235,1.254
49.50,46.89,-0.235,1.254
49.51,46.81,-0.235,1.254
49.52,46.73,-0.235,1.253
49.53,46.65,-0.235,1.253
49.53,46.56,-0.235,1.253
49.54,46.48,-0.235,1.253
49.55,46.40,-0.235,1.252
49.56,46.31,-0.235,1.252
49.57,46.23,-0.234,1.250
49.58,46.15,-0.234,1.250
49.58,46.06,-0.234,1.250
49.59,45.98,-0.234,1.249
49.60,45.90,-0.234,1.249
49.61,45.81,-0.234,1.249
49.62,45.73,-0.234,1.249
49.63,45.65,-0.234,1.248
49.63,45.56,-0.234,1.247
49.64,45.48,-0.234,1.246
49.65,45.40,-0.234,1.246
49.66,45.31,-0.234,1.246
49.67,45.23,-0.233,1.245
49.68,45.15,-0.233,1.245
49.68,45.06,-0.233,1.244
49.69,44.98,-0.233,1.244
49.70,44.90,-0.235,1.254
49.71,44.81,-0.236,1.258
49.72,44.73,-0.236,1.257
49.73,44.65,-0.236,1.256
49.73,44.56,-0.235,1.255
49.74,44.48,-0.235,1.252
49.75,44.40,-0.234,1.249
49.76,44.31,-0.234,1.248
49.77,44.23,-0.233,1.246
49.78,44.15,-0.233,1.245
49.78,44.06,-0.233,1.244
49.79,43.98,-0.233,1.244
49.80,43.90,-0.233,1.243
49.81,43.81,-0.233,1.242
49.82,43.73,-0.233,1.241
49.83,43.65,-0.233,1.241
49.83,43.56,-0.232,1.241
49.84,43.48,-0.232,1.240
49.85,43.40,-0.232,1.239
49.86,43.31,-0.232,1.239
49.87,43.23,-0.232,1.239
49.88,43.15,-0.232,1.239
49.88,43.06,-0.232,1.239
49.89,42.98,-0.232,1.238
49.90,42.90,-0.232,1.238
49.91,42.81,-0.232,1.237
49.92,42.73,-0.232,1.237
49.93,42.65,-0.232,1.237
49.93,42.56,-0.231,1.236
49.94,42.48,-0.231,1.236
49.95,42.40,-0.231,1.242
49.96,42.31,-0.231,1.249
49.97,42.23,-0.231,1.250
49.98,42.15,-0.231,1.249
49.98,42.06,-0.231,1.248
49.99,41.98,-0.231,1.247
50.00,41.90,-0.231,1.246
50.01,41.81,-0.231,1.245
50.02,41.73,-0.231,1.245
50.03,41.65,-0.231,1.244
50.03,41.56,-0.230,1.243
50.04,41.48,-0.251,1.353
50.05,41.41,-0.349,1.883
50.06,41.34,-0.334,1.800
50.07,41.26,-0.259,1.392
50.08,41.17,-0.248,1.335
50.08,41.09,-0.244,1.315
50.09,41.00,-0.242,1.305
50.10,40.92,-0.241,1.300
50.11,40.84,-0.240,1.294
50.12,40.75,-0.240,1.291
50.13,40.67,-0.240,1.290
50.13,40.58,-0.239,1.287
50.14,40.50,-0.240,1.288
50.15,40.42,-0.239,1.278
50.16,40.33,-0.238,1.267
50.17,40.25,-0.238,1.263
50.18,40.16,-0.238,1.263
50.18,40.08,-0.238,1.265
50.19,40.00,-0.238,1.264
50.20,39.91,-0.237,1.262
50.21,39.83,-0.237,1.262
50.22,39.74,-0.237,1.263
50.23,39.66,-0.237,1.263
50.23,39.58,-0.237,1.262
50.24,39.49,-0.237,1.262
50.25,39.41,-0.237,1.263
50.26,39.33,-0.237,1.263
50.27,39.24,-0.237,1.263
50.28,39.16,-0.237,1.262
50.28,39.08,-0.237,1.263
50.29,38.99,-0.237,1.262
50.30,38.91,-0.237,1.262
50.31,38.83,-0.236,1.263
50.32,38.74,-0.236,1.263
50.33,38.66,-0.236,1.263
50.33,38.58,-0.236,1.262
50.34,38.49,-0.236,1.262
50.35,38.41,-0.236,1.262
50.36,38.33,-0.236,1.262
50.37,38.24,-0.236,1.262
50.38,38.16,-0.236,1.262
50.38,38.08,-0.236,1.262
50.39,37.99,-0.236,1.261
50.40,37.91,-0.236,1.261
50.41,37.83,-0.236,1.261
50.42,37.74,-0.236,1.261
50.43,37.66,-0.236,1.260
50.43,37.58,-0.236,1.260
50.44,37.49,-0.235,1.261
50.45,37.41,-0.235,1.260
50.46,37.33,-0.235,1.260
50.47,37.24,-0.235,1.259
50.48,37.16,-0.235,1.260
50.48,37.08,-0.235,1.259
50.49,36.99,-0.235,1.259
50.50,36.91,-0.235,1.259
50.51,36.83,-0.235,1.258
50.52,36.74,-0.235,1.258
50.53,36.66,-0.235,1.257
50.53,36.58,-0.235,1.257
50.54,36.49,-0.235,1.257
50.55,36.41,-0.235,1.257
50.56,36.33,-0.235,1.257
50.57,36.24,-0.235,1.256
50.58,36.16,-0.235,1.256
50.58,36.08,-0.235,1.256
50.59,36.00,-0.234,1.256
50.60,35.91,-0.234,1.256
50.61,35.83,-0.234,1.256
50.62,35.74,-0.234,1.254
50.63,35.66,-0.234,1.254
50.63,35.58,-0.234,1.254
50.64,35.49,-0.234,1.254
50.65,35.41,-0.234,1.253
50.66,35.33,-0.234,1.253
50.67,35.25,-0.234,1.253
50.68,35.16,-0.234,1.253
50.68,35.08,-0.234,1.253
50.69,35.00,-0.234,1.253
50.70,34.91,-0.234,1.253
50.71,34.83,-0.234,1.252
50.72,34.74,-0.234,1.252
50.73,34.66,-0.234,1.252
50.73,34.58,-0.234,1.252
50.74,34.50,-0.234,1.251
50.75,34.41,-0.233,1.251
50.76,34.33,-0.233,1.250
50.77,34.25,-0.233,1.250
50.78,34.16,-0.233,1.250
50.78,34.08,-0.233,1.250
50.79,34.00,-0.233,1.249
50.80,33.91,-0.233,1.249
50.81,33.83,-0.233,1.249
50.82,33.75,-0.233,1.249
50.83,33.66,-0.233,1.248
50.83,33.58,-0.233,1.248
50.84,33.50,-0.233,1.248
50.85,33.41,-0.233,1.247
50.86,33.33,-0.233,1.247
50.87,33.25,-0.233,1.246
50.88,33.16,-0.233,1.246
50.88,33.08,-0.233,
50.89,32.99,-0.233,
50.90,32.91,-0.233,
50.91,32.83,-0.233,
50.92,32.75,-0.233,
50.93,32.66,-0.232,
50.93,32.58,-0.232,
50.94,32.50,,
50.95,32.41,,
50.96,32.33,,
50.97,32.25,,
50.98,32.16,,
50.98,32.08,,
50.99,,,
51.00,,,